Workbook
Name \2: #REF!
Name \A: #REF!
Name \B: #REF!
Name \C: #REF!
Name \d: #N/A
Name \H: #REF!
Name \I: #REF!
Name \KWS123: #N/A
Name \l: #REF!
Name \M: #REF!
Name \N: #REF!
Name \P: #REF!
Name \q: #N/A
Name \R: #REF!
Name \t: #N/A
Name \U: #REF!
Name \V: #REF!
Name \z: #REF!
Name _: #REF!
Name _________________________________________________________dol12: #REF!
Name _________________________________________________________in18900: #REF!
Name _________________________________________________________iv19000: #REF!
Name ________________________________________________________dol12: #REF!
Name ________________________________________________________dol6: #REF!
Name ________________________________________________________in18900: #REF!
Name ________________________________________________________iv19000: #REF!
Name _______________________________________________________dol12: #REF!
Name _______________________________________________________dol6: #REF!
Name _______________________________________________________in18900: #REF!
Name _______________________________________________________iv19000: #REF!
Name ______________________________________________________dol12: #REF!
Name ______________________________________________________dol6: #REF!
Name _____________________________________________________dol12: #REF!
Name _____________________________________________________dol6: #REF!
Name _____________________________________________________in18900: #REF!
Name _____________________________________________________iv19000: #REF!
Name ____________________________________________________dol12: #REF!
Name ____________________________________________________dol6: #REF!
Name ____________________________________________________in18900: #REF!
Name ____________________________________________________iv19000: #REF!
Name ___________________________________________________dol12: #REF!
Name ___________________________________________________dol6: #REF!
Name ___________________________________________________in18900: #REF!
Name ___________________________________________________iv19000: #REF!
Name __________________________________________________dol12: #REF!
Name __________________________________________________dol6: #REF!
Name __________________________________________________in18900: #REF!
Name __________________________________________________iv19000: #REF!
Name _________________________________________________dol6: #REF!
Name _________________________________________________in18900: #REF!
Name _________________________________________________iv19000: #REF!
Name ________________________________________________dol12: #REF!
Name ________________________________________________in18900: #REF!
Name ________________________________________________iv19000: #REF!
Name _______________________________________________dol12: #REF!
Name _______________________________________________dol6: #REF!
Name _______________________________________________in18900: #REF!
Name _______________________________________________iv19000: #REF!
Name ______________________________________________dol12: #REF!
Name ______________________________________________dol6: #REF!

Sheet NKTL DPR PGCIL
B2: KEC INTERNATIONAL LIMITED
B3: DAILY PROGRESS REPORT : SUBMISSION STATUS AS ON | G3: ='NKTL DPR'!J1 -> 46034
B4: Name of the Project: | C4: TW02: 400kV M/c Navasari-Kala Transmission Line.
B5: NOA Ref.No: | C5: 5002002222/Tower/DOM/A02-CC CS -3/NOA-II/WR2-400010
B7: ROUTE ALIGNMENT PROGRESS SUMMARY
B8: TOTAL QTY (Tentative) | C8: COMPLETED UP TO PREV MONTH | D8: COMP. IN CURRENT MONTH | E8: CUMULATIVE | F8: BAL.QTY
B9: ='NKTL DPR'!E11 -> 8.572 | C9: =B9 -> 8.572 | D9: 0 | E9: =C9 -> 8.572 | F9: =B9-C9 -> 0
B10: SOIL INVESTIGATION PROGRESS SUMMARY
B11: TOTAL QTY (Tentative) | C11: COMPLETED UP TO PREV MONTH | D11: COMP. IN CURRENT MONTH | E11: CUMULATIVE | F11: BAL.QTY
B12: 14 | C12: 10 | D12: 0 | E12: =C12 -> 10 | F12: =B12-C12 -> 4
B13: DETAILED SURVEY PROGRESS SUMMARY
B14: TOTAL QTY (Tentative) | C14: COMPLETED UP TO PREV MONTH | D14: COMP. IN CURRENT MONTH | E14: CUMULATIVE | F14: BAL.QTY
B15: =B9 -> 8.572 | C15: =C9 -> 8.572 | D15: 0 | E15: =E9 -> 8.572 | F15: =F9 -> 0
B16: CHECK SURVEY PROGRESS SUMMARY
B17: TOTAL QTY (Tentative) | C17: COMPLETED UP TO PREV MONTH | D17: COMP. IN CURRENT MONTH | E17: CUMULATIVE | F17: BAL.QTY
B18: =B15 -> 8.572 | C18: =C15 -> 8.572 | D18: 0 | E18: =C18 -> 8.572 | F18: =F15 -> 0
B19: FOUNDATION PROGRESS SUMMARY
B20: TOTAL QTY (Tentative) | C20: COMPLETED UP TO PREV MONTH | D20: COMP. IN CURRENT MONTH | E20: CUMULATIVE | F20: BAL.QTY
B21: 37 | C21: 23 | D21: 2 | E21: =D21+C21 -> 25 | F21: =B21-E21 -> 12
B22: EARTHING PROGRESS SUMMARY
B23: TOTAL QTY | C23: COMPLETED UP TO PREV MONTH | D23: COMP. IN CURRENT MONTH | E23: CUMULATIVE | F23: BAL.QTY
B24: 37 | C24: 5 | D24: 0 | E24: 5 | F24: 32
B25: TOWER ERECTION PROGRESS SUMMARY
B26: TOTAL QTY | C26: COMPLETED UP TO PREV MONTH | D26: COMP. IN CURRENT MONTH | E26: CUMULATIVE | F26: BAL.QTY
B27: 37 | C27: 0 | D27: 0 | E27: 0 | F27: 37
B28: STRINGING PROGRESS SUMMARY
B29: TOTAL QTY | C29: COMPLETED UP TO PREV MONTH | D29: COMP. IN CURRENT MONTH | E29: CUMULATIVE | F29: BAL.QTY(KM)
B30: =B18 -> 8.572 | C30: 0 | D30: 0 | E30: 0 | F30: =B30-E30 -> 8.572
B31: OPGW STRINGING PROGRESS SUMMARY
B32: TOTAL QTY | C32: COMPLETED UP TO PREV MONTH | D32: COMP. IN CURRENT MONTH | E32: CUMULATIVE | F32: BAL.QTY
B33: =B30 -> 8.572 | C33: 0 | D33: 0 | E33: 0 | F33: =B33-E33 -> 8.572

Sheet Visual Chart NKTL
A1: Name of Line :- TW02: 400KV D/C Navsari-Kala Transmission Line.
A2: Agency: M/S KEC International Limited | W2: Date:- | X2: ='NKTL DPR'!J1 -> 46034
A3: LEGENDS | N3: ABSTRACT
N4: Sl.No | O4: Type of Work | Q4: Unit | R4: Scope | S4: ROW | T4: Drawing Req. | U4: Comp. | V4: Balance | W4: WIP | X4: Front Available | Y4: Remark
B5: Erection Progress | F5: 220 KV Line X-Ing | K5: National Highway Crossing | N5: 01 | O5: Tower Foundation | Q5: Nos. | R5: 29 | S5: 4 | U5: ='NKTL DPR'!O14-U7 -> 22 | V5: =R5-U5 -> 7 | W5: 2 | X5: 1
B6: Foundation Progress
B7: Excavation Progress | K7: Stringing Progress | N7: 02 | O7: Monopole Foundation | Q7: Nos. | R7: 8 | S7: 1 | U7: 3 | V7: =R7-U7 -> 5 | W7: 1 | X7: 1 | Y7: 2 waterlogged
F8: 132 KV Line X-Ing
K9: Stringing Complete | N9: 03 | O9: Tower Erection | Q9: Nos. | R9: 29 | T9: 0 | U9: 0 | V9: =S9-U9 -> 0
F11: 66 KV Line X-Ing | K11: Railway Crossing. | N11: 04 | O11: Monopole Erection. | Q11: Nos. | R11: 8 | T11: 0 | U11: 0 | V11: =S11-U11 -> 0
B13: Erection Completed | I13: ::::::::::: | K13: Gas Pipe Line | N13: 05 | O13: Stringing | Q13: Km. | R13: 8.572 | T13: 0 | U13: 0 | V13: =S13-U13 -> 0
B14: Foundation Completed | F14: Earthing
B15: Excavation Completed | K15: River Crossing
A19: . | C19: 275.478 | D19: 17 | E19: 192.959 | F19: 4 | G19: 229.775 | H19: 14 | I19: 263.916 | K19: 253.672 | L19: 3 | M19: 266.296 | N19: 5 | O19: 325.859 | P19: 9 | Q19: 143.609 | R19: 6 | S19: 203.188 | T19: 7 | U19: 110.476 | V19: 8 | W19: 90.61 | X19: 2 | Y19: 155.951
B20: DRY | D20: WFR | F20: DRY | L20: DFR | N20: DFR | P20: WFR | R20: DFR | T20: WFR | V20: WFR | X20: DFR
B21: 67/3(New) | D21: 67/4 | F21: 68/0 | H21: 69/0 | J21: 70/0 | L21: 70/1 | N21: 70A/0 | P21: 71/0 | R21: 72/0 | T21: 72A/0 | V21: 72B/0 | X21: 72B/1
B22: QD60+9 | D22: QDD60+9 | F22: DD60-3 | H22: PDD+9 | J22: PDD+6 | L22: DD60-3 | N22: DD60-3 | P22: DC2-3 | R22: DD60-3 | T22: DDH+0 | V22: DDH+0 | X22: DD60-3
S23: 400KV Crossing
A24: DAMAN SECTION
A28: . | B28: 1 | C28: 295.706 | E28: 169.148 | G28: 320.246 | H28: 1 | I28: 218.016 | J28: 21 | K28: 214.693 | L28: 16 | M28: 319.855 | N28: 13 | O28: 195.031 | P28: 23 | Q28: 253.495 | R28: 18 | S28: =374.687/2 -> 187.3435 | T28: 11 | U28: =374.687/2 -> 187.3435 | W28: 250.188 | X28: ROW-01 | Y28: 367.454
B29: DFR | L29: WET | N29: WFR | P29: WFR | R29: WFR | T29: WFR | V29: HR
B30: 73/0 | D30: 74/0 | F30: 75/0 | H30: 75A/0 | J30: 75B/0 | L30: 75C/0 | N30: 76/0 | P30: 77/0 | R30: 77A/0 | T30: 77B/0 | V30: 78/0 | X30: 78A/0
B31: DD60+3 | D31: PDD+9 | F31: PDD+21 | G31: 66KV Crossing | H31: PDD+9 | J31: PDD+6 | L31: DD60+0 | N31: DD45+0 | P31: DD60+0 | R31: DD60+0 | T31: DD60+0 | V31: QDD60+12 | X31: QDD60+12
F32: (With Auxiliary X-arm) | H32: Truncated | V32: 4MRC | W32: 66 & 220KV Crossing | X32: 4MRC
B33: 3
A34: DAMAN SECTION
L37: 66 & 220KV Line Crossing | N37: ROW-03 | O37: 614.493 | P37: 15
L38: Daman Ganga River Crossing | P38: WET
N39: 84L/0 | P39: 85L/0
L40: FALSE | N40: QDS+0 | O40: 66KV | P40: QDS+0
B44: 25 | C44: 241.759 | D44: ROW-02 | E44: 138.29 | F44: 22 | G44: 158.822 | H44: 20 | I44: 354.232 | J44: 10 | K44: 281.34 | L44: 19 | M44: 369.337 | N44: ROW-04 | O44: 614.493 | P44: 2 | Q44: 275.996 | R44: 12 | S44: 321.281 | T44: 3 | U44: 312.662
F45: PS | H45: WFR | J45: WET | L45: WET | P45: WET | R45: WET | T45: WET | V45: WET
B46: 79/0 | D46: 80/0 | F46: 80A/0 | H46: 81/0 | J46: 82/0 | L46: 83/0 | N46: 84/0 | P46: 85/0 | R46: 85/1 | T46: 86/0 | V46: 76/0(New)
B47: PDD+6 | D47: PDD+6 | F47: DD60+0 | H47: DB2+0 | J47: DD60+0 | L47: DD60+0 | N47: QDS+0 | P47: QDS+0 | R47: QDD60+0 | T47: QDD60+9 | V47: QD60+BB
D48: ROW | H48: 1MRC
C50: SH Crossing | N50: ROW-05 | O50: 614.493 | P50: 24 | U50: Proposed Coastal Highway
P51: WET
N52: 84R/0 | P52: 85R/0
N53: QDS+0 | O53: 220KV | P53: QDS+0
A55: DAMAN SECTION

Sheet NKTL DPR
A1: Project Code | E1: TA 310 | I1: Date:- | J1: 46034 | K1: LOA Start Date | M1: 44784 | O1: President - T&D | Q1: Ganesh Srinivasan
A2: Project Name | E2: TW02: 400kV M/c Navasari-Kala Transmission Line. | O2: Chief Executive - T&D | Q2: Rajinder Gupta
A3: Client Name | E3: Power Grid Corporation of India Limited (PGCIL) | I3: LOA Value | J3: Amndt-11 | K3: LOA End Date | M3: 45240 | O3: Vice President | Q3: Arun Felbin R
A4: LOAValue / LE Value | E4: Ex-Work Price component | I4: =2083623222/10000000 -> 208.36232 | J4: =2425046924/10000000 -> 242.50469 | O4: Regional Manager | Q4: Nitin Bendale
E5: Local Transportation, In-transit insurance, loading-unloading Charges etc. (CR) | I5: =31806198/10000000 -> 3.1806198 | J5: =42274925/10000000 -> 4.2274925 | K5: Time Extn | M5: 46112 | O5: Chief Manager
E6: Installation Charges (CR) | I6: =741209972/10000000 -> 74.120997 | J6: =1247376651/10000000 -> 124.73767 | O6: Project Manager | Q6: Vivek Kumar Gupta
E7: Total Contract Value ( CR) | I7: =SUM(I4:I6) -> 285.66394 | J7: =SUM(J4:J6) -> 371.46985 | O7: Planning Engineer | Q7: Dillip Kumar Jena
A8: Progress Status of TW02: 400kV D/c Navasari-Kala Transmission Line.
A9: Activity | C9: Unit | D9: LOA Qty. | E9: Final Estimated Quantity | F9: Cumulative L2 till Dec-2025 | G9: Cumulative Progress till Dec'2025 | H9: Balance | I9: L2 for Jan'26 | J9: Plan for Jan'2026 | K9: Today's Progress | L9: Progress till for Jan'2026 | M9: WIP | N9: Gangs at Present | O9: Cumulative Progress till date | P9: Balance Work | Q9: Remarks
A10: Survey
A11: Route Alignment | C11: KM | D11: 8.572 | E11: =D11 -> 8.572 | F11: 0 | G11: =E11 -> 8.572 | H11: 0 | I11: 0 | J11: 0 | K11: 0 | L11: 0 | M11: 0 | N11: 0 | O11: =L11+G11 -> 8.572 | P11: =E11-O11 -> 0
A12: Detailed Survey | C12: KM | D12: 8.572 | E12: =D12 -> 8.572 | F12: 0 | G12: =E12 -> 8.572 | H12: 0 | I12: 0 | J12: 0 | K12: 0 | L12: 0 | M12: 0 | N12: 0 | O12: =L12+G12 -> 8.572 | P12: =E12-O12 -> 0
A13: Check Survey | C13: KM | D13: 8.572 | E13: =D13 -> 8.572 | F13: 0 | G13: =E13 -> 8.572 | H13: 0 | I13: 0 | J13: 0 | K13: 0 | L13: 0 | M13: 0 | N13: 0 | O13: =L13+G13 -> 8.572 | P13: =E13-O13 -> 0
A14: Foundation | C14: Nos | D14: 37 | E14: 37 | F14: 0 | G14: 23 | H14: =E14-G14 -> 14 | I14: 0 | J14: 5 | L14: 2 | M14: 3 | N14: 3 | O14: =L14+G14 -> 25 | P14: =E14-O14 -> 12
A15: Earthing-Pipe | C15: Nos | D15: 7 | E15: 7 | F15: 0 | G15: 2 | H15: =E15-G15 -> 5 | I15: 0 | K15: 0 | O15: =L15+G15 -> 2 | P15: =E15-O15 -> 5
A16: Earthing-CP/SE/CE | C16: Nos | D16: 30 | E16: 30 | F16: 0 | G16: 8 | H16: =E16-G16 -> 22 | I16: 0 | J16: 5 | K16: 0 | O16: =L16+G16 -> 8 | P16: =E16-O16 -> 22
A17: Tower Erection | C17: Nos | D17: 37 | E17: 37 | F17: 0 | G17: 0 | H17: =E17-G17 -> 37 | I17: 0 | J17: 6 | L17: 0 | O17: =L17+G17 -> 0 | P17: =E17-O17 -> 37
A18: Tack welding | C18: Nos | D18: 134 | E18: 8.822 | F18: 134 | G18: =35+17 -> 52 | H18: =E18-G18 -> -43.178 | I18: 0 | J18: 0 | K18: 0 | M18: 1 | N18: 1 | O18: =L18+G18 -> 52 | P18: =D18-O18 -> 82
A19: Stringing | C19: KM | D19: =D13 -> 8.572 | E19: =E13 -> 8.572 | F19: 0 | G19: 0 | H19: =E19-G19 -> 8.572 | I19: 0 | J19: 0 | L19: 0 | O19: =L19+G19 -> 0 | P19: =E19-O19 -> 8.572
A20: Paying Out | C20: KM | D20: 52.39 | E20: 52.876 | F20: 52.39 | G20: 15.15814 | H20: =F20-G20 -> 37.23186 | O20: =L20+G20 -> 15.15814 | P20: 50.853
A21: Final Sag | C21: KM | D21: 52.39 | E21: 52.876 | F21: 52.39 | G21: 15.15814 | H21: =E21-G21 -> 37.71786 | O21: =L21+G21 -> 15.15814 | P21: 50.853
A22: OPGW | C22: KM | D22: 8.572 | E22: 8.572 | F22: 0 | G22: 0 | H22: =E22-G22 -> 8.572 | O22: =L22+G22 -> 0 | P22: =E22-L22 -> 8.572
A23: Foundation | S23: Excavation | T23: Steel | U23: Approval Letter Reff Date-27/08/2025
A24: SL No. | B24: Loc. No. | C24: T.0.T | D24: Tower Configuration. | E24: Classification | F24: Classification date. | G24: Start Date | H24: RCC Qty | I24: PCC Qty. | J24: Status | N24: End Date | O24: Gang Name | P24: Gang | Q24: Manpower | R24: Remarks
A25: 1 | B25: 67/4 | C25: QDD60+9 | D25: Danube Tower | E25: WFR | F25: 45946 | G25: 45976 | H25: 125.96 | I25: 8.53 | J25: Foundation Completed. | N25: 45984 | O25: Maa Bhawani Const.
A26: =A25+1 -> 2 | B26: 68/0 | C26: DD60-3 | D26: Narrow base DC Tower. | E26: DRY | F26: 45780 | G26: 45782 | H26: 63.39 | I26: 5.55 | J26: Foundation Completed. | N26: 45815 | O26: Maa Bhawani Const. | S26: 435.35 | T26: 3.613 | U26: WRTS-II/Valsad TLC/NMTL/195, Date-27/08/2025
A27: =A26+1 -> 3 | B27: 69/0 | C27: PDD+9 | D27: Monopole, 3.8 mtr dia caisson Foundation. | G27: 45923 | H27: 148 | I27: 0 | J27: Foundation Completed. | N27: 45970 | O27: Harshiv Project Pvt Ltd.
A28: =A27+1 -> 4 | B28: 70/0 | C28: PDD+6 | D28: Monopole,1.2mtr dia 08Nos Pile Foundation | J28: Yet to start. | O28: Harshiv Project Pvt Ltd. | R28: Front availability -01
A29: =A28+1 -> 5 | B29: 70/1 | C29: DD60-3 | D29: Narrow base DC Tower. | E29: DFR | F29: 45804 | G29: =F29 -> 45804 | H29: 62.68 | I29: 5.45 | J29: Foundation Completed. | N29: 45810 | O29: Maa Bhawani Const. | S29: 321.78 | T29: 3.556 | U29: WRTS-II/Valsad TLC/NMTL/195, Date-27/08/2025
A30: =A29+1 -> 6 | B30: 70A/0 | C30: DD60-3 | D30: Narrow base DC Tower. | E30: DFR | F30: 45811 | G30: 45817 | H30: 62.68 | I30: 5.45 | J30: Foundation Completed. | N30: 45822 | O30: Maa Bhawani Const. | S30: 321.78 | T30: 3.556 | U30: WRTS-II/Valsad TLC/NMTL/195, Date-27/08/2025
A31: =A30+1 -> 7 | B31: 71/0 | C31: DC2-3 | D31: Narrow base DC Tower. | E31: WFR | F31: 45874 | G31: 45877 | H31: 46.37 | I31: 5.26 | J31: Foundation Completed. | N31: 45903 | O31: Maa Bhawani Const. | S31: 317.14 | T31: 2.854
A32: =A31+1 -> 8 | B32: 72/0 | C32: DD60-3 | D32: Narrow base DC Tower. | E32: DFR | F32: 45873 | G32: 45873 | H32: 62.68 | I32: 5.45 | J32: Foundation Completed. | N32: 45883 | O32: Maa Bhawani Const. | S32: 321.78 | T32: 3.556 | U32: WRTS-II/Valsad TLC/NMTL/195, Date-27/08/2025
A33: =A32+1 -> 9 | B33: 72A/0 | C33: DDH+0 | D33: Dwarf Tower | E33: WFR | F33: 45864 | G33: 45868 | H33: 47.11 | I33: 4.27 | J33: Foundation Completed. | N33: 45890 | O33: Maa Bhawani Const. | S33: 252.83 | T33: 3.607 | U33: WRTS-II/Valsad TLC/NMTL/195, Date-27/08/2025
A34: =A33+1 -> 10 | B34: 72B/0 | C34: DDH+0 | D34: Dwarf Tower | E34: WFR | F34: 45874 | G34: 45890 | H34: 47.11 | I34: 4.27 | J34: Foundation Completed. | N34: 45898 | O34: Maa Bhawani Const.
A35: =A34+1 -> 11 | B35: 72B/1 | C35: DD60-3 | D35: Narrow base DC Tower. | E35: DFR | F35: 45799 | G35: 45799 | H35: 62.68 | I35: 5.45 | J35: Foundation Completed. | N35: 45807 | O35: Maa Bhawani Const. | S35: 321.78 | T35: 3.556 | U35: WRTS-II/Valsad TLC/NMTL/195, Date-27/08/2025
A36: =A35+1 -> 12 | B36: 73/0 | C36: DD60+3 | D36: Narrow base DC Tower. | E36: DFR | F36: 45778 | G36: 45778 | H36: 69.72 | I36: 6.18 | J36: Foundation Completed. | N36: 45805 | O36: Maa Bhawani Const. | S36: 369.37 | T36: 4.067 | U36: WRTS-II/Valsad TLC/NMTL/195, Date-27/08/2025
A37: =+A36+1 -> 13 | B37: 76/0 | C37: DD45+0 | D37: Narrow base DC Tower. | E37: WFR | F37: 45953 | G37: 45954 | H37: 61.71 | I37: 6.61 | J37: Foundation Completed. | N37: 45965 | O37: Maa Bhawani Const.
A38: 14 | B38: 74/0 | C38: PDD+9 | D38: Monopole, Open Cast Foundation | E38: HR | G38: 45993 | J38: Excavation, RQD testing, and soil investigation tests completed. Location waterlogged. | O38: Maa Bhawani Const.
A39: =A38+1 -> 15 | B39: 75/0 | C39: PDD+18 | D39: Monopole, Open Cast Foundation | E39: HR | G39: 45998 | J39: RQD testing completed; excavation work stopped due to waterlogging at location.. | O39: Maa Bhawani Const.
A40: =A39+1 -> 16 | B40: 75A/0 | C40: PDD+9 | D40: Monopole,1.2mtr dia 08Nos Pile Foundation | E40: Pile | G40: 21/12/205 | J40: P1, P3, P4, P5, P6 & P7 completed; P2 boring Work in progress.(14.5mtr completed). Casting plan for tomorrow. | N40: WIP-1 | O40: Harshiv Project Pvt Ltd. | P40: Gang-1 | Q40: 11 | R40: =N40 -> WIP-1
...

Sheet Sheet2
A3: Count of Classification | B3: Column Labels
A4: Row Labels | B4: DFR | C4: DRY | D4: PS | E4: WBC | F4: WET | G4: WET PADDY | H4: WFR | I4: WFR(3M RC) | J4: WFR,3M RC | K4: Grand Total
A5: QA+0 | B5: 2 | C5: 7 | F5: 3 | H5: 1 | K5: 13
A6: QA+3 | B6: 2 | C6: 2 | F6: 3 | H6: 3 | K6: 10
A7: QA+6 | B7: 2 | C7: 7 | F7: 4 | H7: 1 | K7: 14
A8: QA+9 | B8: 3 | C8: 3 | F8: 11 | G8: 1 | K8: 18
A9: QB1+0 | F9: 1 | K9: 1
A10: QB1+6 | F10: 1 | H10: 1 | K10: 2
A11: QB2+0 | B11: 1 | C11: 1 | K11: 2
A12: QB2+3 | F12: 1 | K12: 1
A13: QB2+6 | C13: 1 | F13: 1 | K13: 2
A14: QC1+0 | B14: 1 | F14: 2 | K14: 3
A15: QC1+3 | F15: 1 | H15: 1 | K15: 2
A16: QC1+9 | F16: 1 | H16: 1 | K16: 2
A17: QC2+0 | F17: 1 | H17: 1 | K17: 2
A18: QC2+18 | B18: 1 | F18: 3 | K18: 4
A19: QC2+25 | F19: 1 | K19: 1
A20: QC2+3 | F20: 1 | K20: 1
A21: QC2+9 | F21: 1 | K21: 1
A22: QCT1+3 | J22: 1 | K22: 1
A23: QD45+0 | F23: 3 | K23: 3
A24: QD45+3 | B24: 1 | D24: 1 | F24: 3 | K24: 5
A25: QD45+6 | C25: 1 | F25: 2 | K25: 3
A26: QD45+9 | F26: 2 | I26: 1 | K26: 3
A27: QD60+0 | B27: 1 | F27: 1 | K27: 2
A28: QD60+18 | B28: 1 | F28: 1 | K28: 2
A29: QD60+25 | B29: 1 | F29: 4 | H29: 1 | K29: 6
A30: QD60+3 | F30: 1 | I30: 1 | K30: 2
A31: QD60+3 RC | E31: 1 | K31: 1
A32: QD60+6 | F32: 2 | K32: 2
A33: QD60+9 | B33: 2 | D33: 1 | F33: 2 | K33: 5
A34: Grand Total | B34: 18 | C34: 22 | D34: 2 | E34: 1 | F34: 57 | G34: 1 | H34: 10 | I34: 2 | J34: 1 | K34: 114

Sheet Sheet1
B2: Row Labels | C2: DFR | D2: DRY | E2: PS | F2: WBC | G2: WET | H2: WET PADDY | I2: WFR | J2: WFR(3M RC) | K2: WFR,3M RC | L2: Grand Total
B3: QA+0 | C3: 2 | D3: 7 | G3: 3 | I3: 1 | L3: 13
B4: QA+3 | C4: 2 | D4: 2 | G4: 3 | I4: 3 | L4: 10
B5: QA+6 | C5: 2 | D5: 7 | G5: 4 | I5: 1 | L5: 14
B6: QA+9 | C6: 3 | D6: 3 | G6: 11 | H6: 1 | L6: 18
B7: QB1+0 | G7: 1 | L7: 1
B8: QB1+6 | G8: 1 | I8: 1 | L8: 2
B9: QB2+0 | C9: 1 | D9: 1 | L9: 2
B10: QB2+3 | G10: 1 | L10: 1
B11: QB2+6 | D11: 1 | G11: 1 | L11: 2
B12: QC1+0 | C12: 1 | G12: 2 | L12: 3
B13: QC1+3 | G13: 1 | I13: 1 | L13: 2
B14: QC1+9 | G14: 1 | I14: 1 | L14: 2
B15: QC2+0 | G15: 1 | I15: 1 | L15: 2
B16: QC2+18 | C16: 1 | G16: 3 | L16: 4
B17: QC2+25 | G17: 1 | L17: 1
B18: QC2+3 | G18: 1 | L18: 1
B19: QC2+9 | G19: 1 | L19: 1
B20: QCT1+3 | K20: 1 | L20: 1
B21: QD45+0 | G21: 3 | L21: 3
B22: QD45+3 | C22: 1 | E22: 1 | G22: 3 | L22: 5
B23: QD45+6 | D23: 1 | G23: 2 | L23: 3
B24: QD45+9 | G24: 2 | J24: 1 | L24: 3
B25: QD60+0 | C25: 1 | G25: 1 | L25: 2
B26: QD60+18 | C26: 1 | G26: 1 | L26: 2
B27: QD60+25 | C27: 1 | G27: 4 | I27: 1 | L27: 6
B28: QD60+3 | G28: 1 | J28: 1 | L28: 2
B29: QD60+3 RC | F29: 1 | L29: 1
B30: QD60+6 | G30: 2 | L30: 2
B31: QD60+9 | C31: 2 | E31: 1 | G31: 2 | L31: 5
B32: Grand Total | C32: 18 | D32: 22 | E32: 2 | F32: 1 | G32: 57 | H32: 1 | I32: 10 | J32: 2 | K32: 1 | L32: 114

Sheet Visual Chart-Old
A1: 1 | B1: VISUAL CHART
A2: =A1+1 -> 2 | B2: Name of Line :- TW02: 400KV M/C Navsari-Magarwada Transmission Line.
A3: =A2+1 -> 3 | B3: Agency: M/S KEC International Limited | X3: Date:- | Y3: ='NKTL DPR'!J1 -> 46034
A4: =A3+1 -> 4 | B4: LEGENDS | P4: ABSTRACT | AG4: Name of Line :- TW02: 400KV M/C Navsari-Magarwada Transmission Line. | AQ4: Date | AR4: 45419
A5: =A4+1 -> 5 | P5: Sl.No | Q5: Type of Work | S5: Unit | T5: Scope | U5: L2 Till Date | V5: Completion | W5: Balance | X5: WIP | Y5: ROW | Z5: Front Available | AG5: Sl.No | AH5: Type of Work | AJ5: Unit | AK5: Scope | AL5: L2 Till Date | AM5: Completion | AN5: Balance | AO5: WIP | AP5: ROW | AQ5: Gang | AR5: Front Available
A6: =A5+1 -> 6 | C6: Erection Progress | P6: 01 | Q6: Foundation | S6: Nos. | T6: 152 | U6: 134 | V6: ='NKTL DPR'!O14 -> 25 | W6: =T6-V6 -> 127 | X6: 2 | Y6: =W6-X6-Z6 -> 123 | Z6: 2 | AG6: 01 | AH6: Foundation | AJ6: Nos. | AK6: 151 | AL6: 134 | AM6: 118 | AN6: 33 | AO6: 6 | AP6: 26 | AQ6: 6 | AR6: 1
A7: =A6+1 -> 7 | C7: Foundation Progress | L7: National Highway Crossing
A8: =A7+1 -> 8 | C8: Excavation Progress | P8: 02 | Q8: Erection | S8: Nos. | T8: 152 | U8: 134 | V8: ='NKTL DPR'!O17 -> 0 | W8: =T8-V8 -> 152 | X8: 2 | Y8: =W8-X8-Z8 -> 149 | Z8: 1 | AG8: 02 | AH8: Erection | AJ8: Nos. | AK8: 151 | AL8: 134 | AM8: 68 | AN8: 83 | AO8: 5 | AP8: 38 | AQ8: 6
A9: =A8+1 -> 9 | L9: Stringing Progress
A10: =A9+1 -> 10 | P10: 03 | Q10: Stringing | S10: Km. | T10: 52.821033 | U10: 52.39 | V10: ='NKTL DPR'!O19 -> 0 | W10: =T10-V10 -> 52.821033 | X10: ='NKTL DPR'!M19 -> 0 | AG10: 03 | AH10: Stringing | AJ10: Km. | AK10: 52.816 | AL10: 39 | AM10: 0 | AN10: 52.816 | AO10: 2 | AQ10: 4
A11: =A10+1 -> 11 | C11: Earthing | L11: Stringing Complete
A12: =A11+1 -> 12 | G12: 220 KV Line X-Ing
A13: =A12+1 -> 13 | L13: Railway Crossing.
A14: =A13+1 -> 14 | C14: Erection Completed
A15: =A14+1 -> 15 | C15: Foundation Completed | G15: 132 KV Line X-Ing
A16: =A15+1 -> 16 | C16: Excavation Completed | J16: ::::::::::: | L16: Gas Pipe Line
A17: =A16+1 -> 17 | G17: 66 KV Line X-Ing
A18: =A17+1 -> 18 | J18: .
A19: =A18+1 -> 19 | E19: 1 | G19: =E19+1 -> 2 | I19: =G19+1 -> 3 | K19: =I19+1 -> 4 | M19: =K19+1 -> 5 | O19: =M19+1 -> 6 | Q19: =O19+1 -> 7 | S19: =Q19+1 -> 8 | U19: =S19+1 -> 9 | W19: =U19+1 -> 10 | Y19: =W19+1 -> 11
A20: =A19+1 -> 20 | AA20: Span Length | AB20: No of Tower
A21: =A20+1 -> 21
A22: =A21+1 -> 22 | B22: . | C22: 1 | D22: 184.716 | E22: =C22+1 -> 2 | F22: 365 | G22: =E22+1 -> 3 | H22: 370 | I22: =G22+1 -> 4 | J22: 392 | K22: =I22+1 -> 5 | L22: 387 | M22: =K22+1 -> 6 | N22: 426 | O22: =M22+1 -> 7 | P22: 402 | Q22: =O22+1 -> 8 | R22: 424 | S22: =Q22+1 -> 9 | T22: 394.831 | U22: =S22+1 -> 10 | V22: 292.868 | W22: =U22+1 -> 11 | X22: 428 | Y22: =W22+1 -> 12 | Z22: 392 | AA22: 4458.419 | AB22: 12
A23: =A22+1 -> 23 | C23: WBC | E23: WET | G23: WET | I23: WET | K23: DRY | M23: WET | O23: WET | Q23: WET | S23: DFR | U23: DFR | W23: DFR | Y23: DFR
A24: =A23+1 -> 24 | C24: 19/0 | E24: 20/0 | G24: 20/1 | I24: 20/2 | K24: 20/3 | M24: 20/4 | O24: 20/5 | Q24: 20/6 | S24: 20/7 | U24: 21/0 | W24: 22/0 | Y24: 22/1
A25: =A24+1 -> 25 | C25: QD60+3 | E25: QD45+6 | G25: QA+6 | I25: QA+6 | K25: QCT+0 | M25: QA+0 | O25: QA+9 | Q25: QA+9 | S25: QA+3 | U25: QD60+9 | W25: QD60+9 | Y25: QA+6
A26: =A25+1 -> 26 | C26: RC-3M | D26: SH | K26: TP-01 | V26: Railway
A27: =A26+1 -> 27 | C27: 3
A28: =A27+1 -> 28 | B28: 0 | C28: NAVSARI SECTION | R28: VALSAD SECTION
A29: 30 | B29: 1 | D29: 184.716 | F29: 365 | H29: 370 | J29: 392 | L29: 387 | N29: 426 | P29: 402 | R29: 424 | T29: 394.831 | V29: 292.868 | X29: 428 | Z29: 392
A30: 31 | B30: 2
A31: 32 | B31: 3 | C31: 19/0 | E31: 20/0 | G31: 20/1 | I31: 20/2 | K31: 20/3 | M31: 20/4 | O31: 20/5 | Q31: 20/6 | S31: 20/7 | U31: 21/0 | W31: 22/0 | Y31: 22/1
A32: 33 | B32: 4 | C32: QD60+3 | E32: QD45+6 | G32: QA+6 | I32: QA+6 | K32: QCT+0 | M32: QA+0 | O32: QA+9 | Q32: QA+9 | S32: QA+3 | U32: QD60+9 | W32: QD60+9 | Y32: QA+6
A33: 34 | B33: 5 | C33: =C29=C22 -> FALSE | D33: =D29=D22 -> TRUE | E33: =E29=E22 -> FALSE | F33: =F29=F22 -> TRUE | G33: =G29=G22 -> FALSE | H33: =H29=H22 -> TRUE | I33: =I29=I22 -> FALSE | J33: =J29=J22 -> TRUE | ... Z33: =Z29=Z22 -> TRUE
A34: 35 | B34: 6 | C34: =C30=C23 -> FALSE | D34: =D30=D23 -> TRUE | E34: =E30=E23 -> FALSE | F34: =F30=F23 -> TRUE | G34: =G30=G23 -> FALSE | H34: =H30=H23 -> TRUE | I34: =I30=I23 -> FALSE | J34: =J30=J23 -> TRUE | ... V34: =V30=V23 -> TRUE | X34: =X30=X23 -> TRUE | Y34: =Y30=Y23 -> FALSE | Z34: =Z30=Z23 -> TRUE
A35: 36 | B35: 7 | C35: =C31=C24 -> TRUE | D35: =D31=D24 -> TRUE | E35: =E31=E24 -> TRUE | F35: =F31=F24 -> TRUE | G35: =G31=G24 -> TRUE | H35: =H31=H24 -> TRUE | I35: =I31=I24 -> TRUE | J35: =J31=J24 -> TRUE | ... Z35: =Z31=Z24 -> TRUE
A36: 37 | B36: 8 | C36: =C32=C25 -> TRUE | D36: =D32=D25 -> TRUE | E36: =E32=E25 -> TRUE | F36: =F32=F25 -> TRUE | G36: =G32=G25 -> TRUE | H36: =H32=H25 -> TRUE | I36: =I32=I25 -> TRUE | J36: =J32=J25 -> TRUE | ... Z36: =Z32=Z25 -> TRUE
A37: 38 | B37: 9
A38: 39 | B38: 10
A39: =A38+1 -> 40 | C39: =Y19+1 -> 12 | E39: =C39+1 -> 13 | G39: =E39+1 -> 14 | I39: =G39+1 -> 15 | M39: =I39+1 -> 16 | O39: =M39+1 -> 17 | Q39: =O39+1 -> 18 | S39: =Q39+1 -> 19 | U39: =S39+1 -> 20 | W39: =U39+1 -> 21 | Y39: =W39+1 -> 22
A40: =A39+1 -> 41
...

Sheet Location wise status
A1: Name of the Line:-400kV D/c Navasari-Kala Transmission Line.
A2: Status Summary: | F2: Tower | G2: Monopole | I2: Date:- | J2: 46029
A3: Total Locations: | D3: 37 | F3: 29 | G3: 8
A4: Completed: | D4: 23 | F4: 21 | G4: 2
A5: Balance: | D5: =D3-D4 -> 14 | F5: 8 | G5: 6
A6: Work in Progress (WIP): | D6: 4 | F6: 0 | G6: 4
A7: Work front Available:- | D7: 2 | F7: 1 | G7: 1
A8: ROW Pending: | D8: 8 | F8: 7 | G8: 1
A9: Sl. No. | B9: Loc. No. | C9: T.O.T | D9: Tower configuration | E9: Balance Location status | F9: Start Date | G9: End Date | H9: Foundation Gang | I9: Present Status | J9: Remark.
A10: 1 | B10: 70/0 | C10: PDD+6 | D10: Monopole,1.2mtr dia 08Nos Pile Foundation | E10: Yet to start. | F10: 46039 | G10: 46065 | H10: Harshiv Project Pvt Ltd. | J10: Start of Pile-17/01/2026 End-31/02/2026, Pile cap completion-10/02/2026. Chimney 12/02/2026 Subject to steel supply Revised Amendment to be submitted-12/01/2025
A11: =A10+1 -> 2 | B11: 74/0 | C11: PDD+9 | D11: Monopole, Open Cast Foundation | E11: Excavation, RQD testing, and soil investigation test completed Date-05/01/2026 | H11: Maa Bhawani Const. | I11: WIP-1 | J11: (05/01/2026 )Soil investigation Report to be submitted-13/01/2026, drawing to be provided by 17/01/2026.
A12: =A11+1 -> 3 | B12: 75/0 | C12: PDD+18 | D12: Monopole, Open Cast Foundation | E12: Excavation WIP. | F12: 45998 | G12: 46063 | H12: Maa Bhawani Const. | I12: WIP‑2 | J12: Excavation to be completed-15/01/2026, Anchoring to be completed-30/01/2026, Steel binding to be completed-05/03/2025, Raft Casting to be completed -07/02/2026, Chimney to be completed-10/02/2026.
A13: =A12+1 -> 4 | B13: 75A/0 | C13: PDD+9 | D13: Monopole,1.2mtr dia 08Nos Pile Foundation | E13: P1, P3, P5, and P7 completed; P4 boring completed up to 14.5 m depth. Casing Plan for tomorrow. | F13: 46009 | G13: 46053 | H13: Harshiv Project Pvt Ltd. | I13: WIP-3 | J13: End of Pile -16/01/2026, Pile Cap completion-26/01/2026. Chimney Completion-30/01/2026
A14: =A13+1 -> 5 | B14: 78/0 | C14: QDD60+12 | D14: Danube Tower | E14: HR classification approval Date-06/01/2026, Yet to start | F14: 46030 | H14: Maa Bhawani Const. | J14: Excavation to be completed-24/01/2026, Anchoring to be completed-30/01/2026, Steel binding to be completed-02/02/2025, Raft Casting to be completed -04/02/2026, Chimney to be completed-10/02/2026.
A15: =A14+1 -> 6 | B15: 78A/0 | C15: QDD60+12 | D15: Danube Tower | E15: Work stopped due to ROW issues (effective from 11/09/2025 | H15: Maa Bhawani Const. | I15: ROW‑1 | J15: ROW Clearance to be provided-09/01/2026.
A16: =A15+1 -> 7 | B16: 79/0 | C16: PDD+6 | D16: Monopole, 3.8 mtr dia caisson Foundation. | E16: Bolt fixing work in progress; casting planned for tomorrow. | F16: 46022 | G16: 46030 | H16: Harshiv Project Pvt Ltd. | I16: WIP-4 | J16: Location to be completed-08/01/2026.
A17: =A16+1 -> 8 | B17: 80/0 | C17: PDD+6 | D17: Monopole, 3.8 mtr dia caisson Foundation. | E17: Work stopped due to ROW issues (effective from 11/09/2025 | H17: Maa Bhawani Const. | I17: ROW‑2 | J17: ROW Clearance to be provided-09/01/2026.
A18: =A17+1 -> 9 | B18: 84L/0 | C18: QDS+0 | D18: River Crossing Tower | E18: Work stopped due to ROW issues (effective from 11/12/2025 | H18: Maa Bhawani Const. | I18: ROW‑3 | J18: ROW Clearance to be provided-09/01/2026.
A19: =A18+1 -> 10 | B19: 84/0 | C19: QDS+0 | D19: River Crossing Tower | E19: Work stopped due to ROW issues (effective from 11/12/2025 | H19: Maa Bhawani Const. | I19: ROW‑4 | J19: ROW Clearance to be provided-09/01/2026.
A20: =A19+1 -> 11 | B20: 84R/0 | C20: QDS+0 | D20: River Crossing Tower | E20: Work stopped due to ROW issues (effective from 11/12/2025 | H20: Maa Bhawani Const. | I20: ROW‑5 | J20: ROW Clearance to be provided-09/01/2026.
A21: =A20+1 -> 12 | B21: 85/0 | C21: QDS+0 | D21: River Crossing Tower | E21: Work stopped due to ROW issues (effective from 12/11/2025). 02 Pit Excavation completed, then backfilling by land landowner. | H21: Maa Bhawani Const. | I21: ROW‑6 | J21: ROW Clearance to be provided-09/01/2026.
A22: =A21+1 -> 13 | B22: 85R/0 | C22: QDS+0 | D22: River Crossing Tower | E22: Work stopped due to ROW issues (effective from 12/11/2025). (Only 02 chiminy casting Balance) | H22: Maa Bhawani Const. | I22: ROW‑7 | J22: ROW Clearance to be provided-09/01/2026.
A23: =A22+1 -> 14 | B23: 86/0 | C23: QDD60+9 | D23: Danube Tower | E23: Work stopped due to ROW issues (effective from 12/11/2025).(Excavation & PCC Completed.) | H23: Maa Bhawani Const. | I23: ROW‑8 | J23: ROW Clearance to be provided-09/01/2026.

Sheet Survey Status
A1: Survey Status for 400Kv M/C New Navsari to Magarwada Transmission Line. | P1: Date | Q1: ='NKTL DPR'!J1 -> 46034
A2: Sl. No. | B2: Section | C2: Detail Survey | J2: Check Survey
C3: Complited | D3: Submitted Kms with Date | F3: Revised | G3: Approved with Date | I3: Revised | J3: Complited | K3: Submitted Kms with Date | M3: Revised | N3: Approved with Date | P3: Revised | Q3: Remarks | S3: Detailed Survey Status
B4: 8.882 | C4: =SUBTOTAL(9,C5:C14) -> 8.822 | D4: =SUBTOTAL(9,D5:D14) -> 8.822 | E4: Date | F4: Date | G4: =SUBTOTAL(9,G5:G14) -> 7.212 | H4: Date | I4: Date | J4: =SUBTOTAL(9,J5:J14) -> 8.822 | K4: Date | M4: Date | N4: =SUBTOTAL(9,N5:N14) -> 0 | P4: Date | S4: AP-19/0 | T4: TO | U4: AP-28/0 | V4: = | W4: 8.564 | X4: Approved 15.10.2022
A5: 1 | B5: 67/3-76/0 | C5: 8.822 | D5: =C5 -> 8.822 | E5: 45733 | G5: 7.212 | H5: 21.03.2025 | J5: =C5 -> 8.822 | K5: 7.583 | L5: 45744 | S5: AP-38/0 | T5: TO | U5: AP-44/0 | V5: = | W5: 11.051 | X5: Approved
A6: 2 | S6: AP-44/0 | T6: TO | U6: 52/0 | V6: = | W6: 4.087 | X6: Approved
A7: 3 | S7: AP-52/0 | T7: TO | U7: AP-76/0 | V7: = | W7: 16.089 | X7: Approved
A8: 4 | S8: Total | W8: =SUM(W4:W7) -> 39.791
A9: 5
A10: 6 | S10: AP34/0 to 35/0 Check Survey Pending.
A11: 7
A12: 8
A13: 9
A14: 10
B15: Total | C15: =SUBTOTAL(9,C5:C14) -> 8.822 | D15: =SUBTOTAL(9,D5:D14) -> 8.822 | G15: =SUBTOTAL(9,G5:G14) -> 7.212 | I15: 0 | J15: =SUBTOTAL(9,J5:J14) -> 8.822 | K15: =SUBTOTAL(9,K5:K14) -> 7.583 | N15: =SUBTOTAL(9,N5:N14) -> 0

Sheet Soil investigation
A1: Soil Investigation Letter Ref No.
A2: Ref.WRTS-II/Valsad TLC/NMTL Date-09/02/2025
A3: Ref.WRTS-II/Valsad TLC/NMTL Date-17/02/2025
A5: SL. No | B5: Loc.No | C5: Type of Tower | D5: RC | E5: Tower Structure | F5: Depth | G5: Start Date | H5: End Date | I5: Status | J5: REMARKS
A6: =A5+1 -> #VALUE! | B6: 79/0 | C6: PDD+6 | E6: Monopole | F6: 20 | G6: 45707 | H6: 45710 | I6: Completed
A7: =A6+1 -> #VALUE! | B7: 78A/0 | C7: QDD60+9 | D7: 4 | E7: Danube Tower | F7: 20 | G7: 45711 | H7: 45712 | I7: Completed
A8: =A7+1 -> #VALUE! | B8: 75/0 | C8: PDD+18 | E8: MonoPole (with AUX Arm) | F8: 20 | G8: 45715 | H8: =G8+2 -> 45717 | I8: Completed
A9: =A8+1 -> #VALUE! | B9: 74/0 | C9: PDD+9 | E9: Monopole | F9: 20 | G9: 45718 | H9: =G9+2 -> 45720 | I9: Completed
A10: =A9+1 -> #VALUE! | B10: 78/0 | C10: QDD60+9 | D10: 4 | E10: Danube Tower | F10: 20 | G10: 45713 | H10: 45727 | I10: Completed
A11: =A10+1 -> #VALUE! | B11: 75A/0 | C11: PDD+9 | E11: Monopole | F11: 20 | G11: 45726 | H11: 45736 | I11: Completed
A12: =A11+1 -> #VALUE! | B12: 80/0 | C12: PDD+6 | E12: Monopole | F12: 20 | G12: 45706 | H12: 45737 | I12: Completed
A13: =A12+1 -> #VALUE! | B13: 75B/0 | C13: PDD+3 | E13: Monopole | F13: 20 | G13: 45738 | H13: 45741 | I13: Completed
A14: =A13+1 -> #VALUE! | B14: 70/0 | C14: PDD+6 | E14: Monopole | F14: 20 | G14: 45796 | H14: 45799 | I14: Completed
A15: 1 | B15: 69/0 | C15: PDD+9 | E15: Monopole | F15: 20 | G15: 45815 | H15: 45816 | I15: Completed
A16: =A15+1 -> 2 | B16: 78/0 | C16: QDD60+12 | D16: 4 | E16: Danube Tower | F16: 10 | G16: 45973 | H16: 45975 | I16: Completed
A17: =A16+1 -> 3 | B17: 77/0 | C17: DD60+0 | E17: Narrow Base DC Tower | F17: 10 | G17: 45976 | H17: 45979 | I17: Completed
A18: =A17+1 -> 4 | B18: 80A/0 | C18: DD60+0 | E18: Narrow Base DC Tower | I18: Pending
A19: =A18+1 -> 5 | B19: 84/1 | C19: QDD60+9 | D19: 5 | E19: Danube Tower | F19: 40 | I19: Pending | J19: Location changed as check survey.
A20: =A19+1 -> 6 | B20: 85/0 | C20: DD60+0 | E20: Narrow Base DC Tower | F20: 40 | I20: Pending

Sheet Crossing Details
A1: CROSSINGS PROPOSAL STATUS
A2: Transmission Line Tower Package-TW02 400KV D/C Navsari - Kala Transmission line.( Twin HTLS)
A3: Power Line Crossings
A4: Sl. No. | B4: Section | D4: NAME OF CROSSING | E4: Check Survey Status | F4: Date of Submission | G4: Status of proposal | H4: Approving Authority | I4: Exp. date of Approval | J4: Remarks
A5: 1 | B5: 72A/0 | C5: 72B/0 | D5: 400KV M/C Navsari - Magarawada - Kala Transmission line. | E5: Approved | F5: 45841 | G5: Under Process | H5: PGCIL
A6: 2 | B6: 75/0 | C6: 75A/0 | D6: 66KV D/C Dalwada -Dabhel transmission line. | E6: Approved | F6: 45857 | G6: Under Process | H6: GETCO
A7: 3 | B7: 78/0 | C7: 78A/0 | D7: 220KV D/C Magarwada -Ringanwada Transmission line. | E7: Approved | F7: 45908 | G7: Under Process | H7: PGCIL
A8: 4 | B8: 78/0 | C8: 78A/0 | D8: 66KV D/C Ringanwada-Varkund Transmission line. | E8: Approved | F8: 45908 | G8: Under Process | H8: GETCO
A9: 5 | B9: 84/0 | C9: 85/0 | D9: 220KV D/C Magarwada -Ringanwada Transmission line. | E9: Approved | F9: 45865 | G9: Under Process | H9: PGCIL
A10: 6 | B10: 84/0 | C10: 85/0 | D10: 66KV D/C Ringanwada-Varkund Transmission line.(Tap to Magarwada-Varkund line.) | E10: Approved | F10: 45865 | G10: Under Process | H10: GETCO
A11: Total | B11: =COUNTA(B5:B10) -> 6 | F11: =COUNTA(F5:F10) -> 6
A13: SH Crossing
A14: Sl. No. | B14: FROM (AP) | C14: TO (AP) | D14: NAME OF CROSSING | E14: Type of Crossing | F14: Date of Submission | G14: Status of proposal | H14: Approving Authority | I14: Exp. date of Approval | J14: Remarks
A15: 1 | B15: 79/0 | C15: 80/0 | D15: State high way | E15: SH-185 | G15: NA
A16: Gas Pipe line
A17: Sl. No. | B17: FROM (AP) | C17: TO (AP) | D17: NAME OF CROSSING | E17: Type of Crossing | F17: Date of Submission | G17: Status of proposal | H17: Approving Authority | I17: Exp. date of Approval | J17: Remarks
A18: 1 | B18: 81/0 | C18: 82/0 | G18: NA
A19: PROPOSED COASTAL HIGHWAY
A20: Sl. No. | B20: FROM (AP) | C20: TO (AP) | D20: NAME OF CROSSING | E20: Type of Crossing | F20: Date of Submission | G20: Status of proposal | H20: Approving Authority | I20: Exp. date of Approval | J20: Remarks
A21: 1 | B21: 86/0 | C21: 76/0 | D21: Proposed Costal Highway | G21: NA
A22: River Crossing
A23: Sl. No. | B23: FROM (AP) | C23: TO (AP) | D23: NAME OF CROSSING | E23: Type of Crossing | F23: Date of Submission | G23: Status of proposal | H23: Approving Authority | I23: Exp. date of Approval | J23: Remarks
A24: 1 | B24: 84/0 | C24: 85/0 | D24: Daman Ganga River | E24: River | G24: NA
A25: Aviation
A26: Sl. No. | B26: NAME OF CROSSINGS | F26: Date of Submission | G26: Status of proposal | H26: Approving Authority | I26: Exp. date of Approval | J26: Remarks
A27: 1 | B27: PTCC | F27: 45908
A28: 2 | B28: Civil Aviation | F28: 45890
A29: 3 | B29: Defense Aviation | F29: 45890

Sheet Line Scenario
E3: Line Scenario for M/c 400KV New Navsari to Magarwada & 400KV Navsari to Kala transmission line.
M5: From MC location 76/0 to 76/0, 8.75kM Navsari to Kala work balance otherwise all work completed.
A7: Kala Substation | B7: From CommonPoint 79/0 to Kala Sustation scope by M/s Bajaj | O7: From CommonPoint 19/0 to Navsari Sustation scope by M/s Bajaj | Q7: Navsari Substation
H8: D/C Navsari - Magarwada (8.822KM)
B9: D/c Navsari to Kala
E10: Loc-79/0 | G10: Loc-76/0 | K10: Loc-67/3 | N10: Loc-19/0
F11: M/C Navsari-Magarwada | L11: M/C Navsari-Magarwada
C13: Magarwada Substation | H13: D/C Navsari- Kala (8.75KM)
F16: From Common Point 19/0 to Magarwda Substation Gantry scope by MS KEC.

Sheet Sheet3
B2: TA310 | C2: 400 KV M/C NKTL | E2: Unit | F2: Total Project Volume | G2: Compltd. As on Apr'25 | H2: Bal. as on 01.05.25 | I2: Executed for the month of May'25 | J2: Executed for the month of Jun'25 | K2: Bal. as on 01.07.2025 | L2: Remarks
B3: Proj. code | C3: Project Name | D3: Foundation | E3: Nos. | F3: 34 | G3: =F3 -> 34 | H3: =G3 -> 34 | I3: 2 | J3: 3 | K3: =H3-I3-J3 -> 29 | L3: Workforce demobilization was necessitated by the unavailability of work fronts and unfavorable weather conditions
E4: Cum | F4: 2429 | G4: =F4 -> 2429 | H4: =G4 -> 2429 | I4: 144.03 | J4: 205.2 | K4: =H4-I4-J4 -> 2079.77
D5: Erection | E5: Nos. | F5: 34 | G5: =F5 -> 34 | H5: =G5 -> 34 | I5: 0 | J5: 0 | K5: =H5-I5-J5 -> 34 | L5: No. of gangs
E6: MT | F6: 879.19 | G6: =F6 -> 879.19 | H6: =G6 -> 879.19 | I6: 0 | J6: 0 | K6: =H6-I6-J6 -> 879.19
D7: Stringing (RS) | E7: Kms. | F7: 8.822 | G7: =F7 -> 8.822 | H7: =G7 -> 8.822 | I7: 0 | J7: 0 | K7: =H7-I7-J7 -> 8.822 | L7: TSE & Manual gangs
D8: Stringing (FS) | E8: Kms. | F8: 8.822 | G8: =F8 -> 8.822 | H8: =G8 -> 8.822 | I8: 0 | J8: 0 | K8: =H8-I8-J8 -> 8.822

Sheet Supply Status
A1: 400KV Navsari To Kala Transmission status, Supply Status:- | L1: ='NKTL DPR'!J1 -> 46034
A2: Description | C2: Line Qty. | D2: Spare Qty | E2: NKTL Req. | F2: Total Req. | G2: Damage Qty. | H2: Received Qty. | I2: Total Issue Qty. | J2: Balance Qty Available at Store. | K2: Balance Qty Required. | L2: Remark
A3: Conductor | B3: TWIN HTLS MOOSE CONDUCTOR | C3: 1265.3631 | D3: 40 | E3: 103.902 | F3: =D3+C3+E3 -> 1409.2651 | H3: =1309984/1000 -> 1309.984 | I3: 1191.92 | J3: =H3-I3 -> 118.064
A4: OPGW | B4: 24 FIBRE (DWSM) OPGW FIBRE OPTIC CABLE | C4: 99.116856 | D4: 4 | E4: =8.57 -> 8.57 | F4: =D4+C4+E4 -> 111.68686 | H4: 111 | I4: 99.589 | J4: =H4-I4 -> 11.411
A5: Composite long rod Insulators | B5: 120kN | C5: 1040 | D5: 117 | E5: 117 | F5: =D5+C5+E5 -> 1274 | G5: 68 | H5: 1249 | I5: 1098 | J5: =H5-I5-G5 -> 83 | K5: =(F5-I5-J5) -> 93 | L5: Req
B6: 160kN | C6: 3792 | D6: 271 | E6: 816 | F6: =D6+C6+E6 -> 4879 | G6: 108 | H6: 4267 | I6: 4618 | J6: =H6-I6-G6-650 -> -1109 | K6: =(F6-I6-J6) -> 1370 | L6: Req
A7: Hardware Fittings | B7: Twin HTLS Conductor-Single "I" Suspension String(without clamps) | C7: 738 | D7: 19 | E7: 0 | F7: =D7+C7+E7 -> 757 | G7: 53 | H7: 851 | I7: 719 | J7: =H7-I7-G7 -> 79 | K7: =(F7-I7-J7) -> -41
B8: Twin HTLS Conductor-Single I Suspension String(Pilot) (without clamps)(1x120KN) | C8: 302 | D8: 5 | E8: 117 | F8: =D8+C8+E8 -> 424 | H8: 305 | I8: =281+24 -> 305 | J8: =H8-I8-G8 -> 0 | K8: =(F8-I8-J8) -> 119 | L8: Req
B9: Twin HTLS Conductor-Double TensionString (without clamps) | C9: 1896 | D9: 27 | E9: 408 | F9: =D9+C9+E9 -> 2331 | G9: 15 | H9: 2025 | I9: 1892 | J9: =H9-I9-G9 -> 118 | K9: =(F9-I9-J9) -> 321 | L9: Req
B10: Twin HTLS Conductor-Single Tension String(without clamps) | C10: 4 | D10: 1 | E10: 0 | F10: =D10+C10+E10 -> 5 | H10: 9 | I10: 8 | J10: =H10-I10 -> 1 | K10: =(F10-I10-J10) -> -4
B11: Suspension clamp suitable for suspension insulator string | C11: 1500 | D11: 240 | E11: 0 | F11: =D11+C11+E11 -> 1740 | H11: 1872 | I11: 400 | J11: =H11-I11-G11 -> 1472 | K11: =(F11-I11-J11) -> -132
B12: Deadend clamp suitable for tension insulator string | C12: 3792 | D12: 192 | E12: 816 | F12: =D12+C12+E12 -> 4800 | H12: 4188 | I12: 3848 | J12: =H12-I12 -> 340 | K12: =(F12-I12-J12) -> 612 | L12: Req
B13: Suspension clamp suitable for suspension Pilot insulator string | C13: 604 | D13: 24 | E13: 234 | F13: =D13+C13+E13 -> 862 | G13: 25 | H13: 640 | I13: 610 | J13: =H13-I13-G13 -> 5 | K13: =(F13-I13-J13) -> 247 | L13: Req
A14: Conductor Accessories for HTLS Moose | B14: MSCJ | C14: 54 | D14: 50 | E14: 0 | F14: =D14+C14+E14 -> 104 | H14: 782 | I14: 359 | J14: =H14-I14 -> 423 | K14: =(F14-I14-J14) -> -678
B15: Repair Sleeve | C15: 15 | D15: 50 | E15: 0 | F15: =D15+C15+E15 -> 65 | H15: 294 | I15: 114 | J15: =H15-I15 -> 180 | K15: =(F15-I15-J15) -> -229
B16: T- connector | C16: 13 | E16: 0 | F16: =D16+C16+E16 -> 13 | G16: 13 | H16: 128 | I16: 24 | J16: =H16-I16-G16 -> 91 | K16: =(F16-I16-J16) -> -102
B17: Spacer Damper for TWIN Moose conductor | C17: 10074 | D17: 1008 | E17: 888 | F17: =D17+C17+E17 -> 11970 | H17: 12264 | I17: 10319 | J17: =H17-I17 -> 1945 | K17: =(F17-I17-J17) -> -294
B18: Rigid spacer for TWIN Moose conductor | C18: 3378 | D18: 72 | E18: 731 | F18: =D18+C18+E18 -> 4181 | H18: 3504 | I18: 3273 | J18: =H18-I18 -> 231 | K18: =(F18-I18-J18) -> 677 | L18: Req
