Workbook
Name \0: #REF!
Name \0: #REF!
Name \2: #REF!
Name \2: #REF!
Name \3: #REF!
Name \4: #REF!
Name \A: #REF!
Name \A: #REF!
Name \A: #REF!
Name \A_1: "#REF!"
Name \a1: #REF!
Name \B: #REF!
Name \B: #REF!
Name \B: #REF!
Name \C: #REF!
Name \C: #REF!
Name \c1: #REF!
Name \d: #N/A
Name \E: #REF!
Name \f: #REF!
Name \g: #REF!
Name \H: #REF!
Name \H: #REF!
Name \I: #REF!
Name \j: #REF!
Name \k: #REF!
Name \KWS123: #N/A
Name \l: #REF!
Name \l: #REF!
Name \M: #REF!
Name \N: #REF!
Name \P: #REF!
Name \q: #N/A
Name \R: #REF!
Name \R: #REF!
Name \S: #REF!
Name \t: #N/A
Name \U: #REF!
Name \U: #REF!
Name \V: #REF!
Name \z: #REF!
Name _: #REF!
Name _________________________________________________________dol12: #REF!
Name _________________________________________________________in18900: #REF!
Name _________________________________________________________iv19000: #REF!
Name ________________________________________________________dol12: #REF!
Name ________________________________________________________dol6: #REF!
Name ________________________________________________________in18900: #REF!
Name ________________________________________________________iv19000: #REF!
Name _______________________________________________________dol12: #REF!
Name _______________________________________________________dol6: #REF!
Name _______________________________________________________in18900: #REF!
Name _______________________________________________________iv19000: #REF!
Name ______________________________________________________dol12: #REF!
Name ______________________________________________________dol6: #REF!
Name _____________________________________________________dol12: #REF!
Name _____________________________________________________dol6: #REF!
Name _____________________________________________________in18900: #REF!
Name _____________________________________________________iv19000: #REF!
Name ____________________________________________________dol12: #REF!

Sheet DPR_TA-413 
B2: LINE NAME- : 765 KV D/C BIKANER III - NEEMRANA II TL02
B3: CLIENT-POWERGRID BIKANER NEEMRANA TRANSMISSION LIMITED (POWER GRID CORPORATION OF INDIA)
B4: DAILY PROGRESS REPORT (TA-413)
B5: NOA Date :- 12-March-2024 | F5: Completion Date :- 11-December-2025 | K5: Date :-23 Nov 2025.
B6: SUPPLY VALUE = 331.89 Cr. | F6: SERVICE VALUE = 58.06 Cr. | K6: F&I VALUE = 6.86 Cr.
B7: PARTICULARS | C7: UOM | D7: Total | E7: Comp | F7: Balance | G7: 45962 | I7: WIP | J7: Cumulative | K7: 45992 | L7: =K7+31 -> 46023 | M7: Remarks
D8: Qty | E8: Till | F8: as on | G8: Plan | H8: Actual | K8: Plan | L8: Plan
E9: 45931 | F9: 1 Nov'25
B10: Detail Survey | C10: KM | D10: 117.85085 | E10: 117.85085 | F10: =D10-E10 -> 0 | J10: =E10+H10 -> 117.85085
B11: Check Survey | C11: KM | D11: 117.85085 | E11: 117.85085 | F11: =D11-E11 -> 0 | J11: =E11+H11 -> 117.85085
B12: Stub Supply | C12: SET | D12: 313 | E12: 313 | F12: =D12-E12 -> 0 | J12: =E12+H12 -> 313
B13: FOUNDATION | C13: NOS | D13: 313 | E13: 313 | F13: =D13-E13 -> 0 | J13: =E13+H13 -> 313
B14: No of Gangs | J14: =E14+H14 -> 0
B15: Tower Supply | C15: SETS | D15: 306 | E15: 306 | F15: =D15-E15 -> 0 | J15: =E15+H15 -> 306
B16: TOWER ERECTION | C16: NOS | D16: 306 | E16: =221+36 -> 257 | F16: =D16-E16 -> 49 | G16: 49 | H16: 16 | I16: 12 | J16: =E16+H16 -> 273 | M16: 2 Gang shifted to TA 512 | O16: =D16-J16 -> 33 | P16: =O16-10 -> 23
B17: No of Gangs | G17: 15 | H17: 11 | I17: 11 | J17: =E17+H17 -> 11
B18: AL-59 Zebra Conductor | C18: KM | D18: 4285.056 | E18: 4094.985 | F18: =D18-E18 -> 190.071 | J18: =E18+H18 -> 4094.985
B19: G S Earthwire 7/3.66mm size | C19: KM | D19: 121.471 | E19: 113.92 | F19: =D19-E19 -> 7.551 | J19: =E19+H19 -> 113.92 | M19: Balance Supply 08 KM
B20: Insulator Supply | C20: EA | D20: 11844 | E20: 10480 | F20: =D20-E20 -> 1364 | J20: =E20+H20 -> 10480 | M20: Balance Supply 160KN- 116 Balance Supply 210KN- 1248
B21: Hardware Fittings Supply | C21: % | D21: 1 | E21: 1 | F21: =D21-E21 -> 0 | J21: =E21+H21 -> 1
B22: Stringing | C22: KM | D22: 117.85085 | E22: =21.495+4.922 -> 26.417 | F22: =D22-E22 -> 91.433851 | G22: 20 | I22: 5.321 | J22: =E22+H22 -> 26.417 | K22: 35 | L22: 36.432567 | M22: Section AP6 to AP7: All Phase Conductor paying out & Rough sag completed
B23: TSE - Section | C23: No | D23: 37 | E23: 7 | F23: =D23-E23 -> 30 | G23: 7 | I23: 1 | J23: =E23+H23 -> 7 | K23: 12 | L23: 11
B24: Manual - Section | C24: No | D24: 23 | E24: 1 | F24: =D24-E24 -> 22 | G24: 3 | I24: 1 | J24: =E24+H24 -> 1 | K24: 15 | L24: 4
B25: No of Gangs | G25: 2 | I25: 1 | J25: 2 | K25: 4 | L25: 5
B26: OPGW Stringing | C26: KM | D26: 117.85085 | E26: =13.612+4.6 -> 18.212 | F26: =D26-E26 -> 99.638851 | G26: 30 | J26: =E26+H26 -> 18.212 | K26: 30 | L26: 40
B27: No of Gangs | G27: 2 | J27: 1 | K27: 2 | L27: 3

Sheet Visual Chart
B1: KEC INTERNATIONAL LIMITED
B2: TA413 : 765 KV D/C Bikaner III - Neemrana II TL02 | V2: Visual Chart | AQ2: 45976
C4: S. No. | E4: Description | I4: UOM | K4: Total qty | M4: Completed | P4: Balance | T4: Power Line Crossing | AC4: Stringing U/P | AL4: Stringing completed
C5: 1 | E5: Foundation | I5: Nos | K5: 313 | M5: 313 | P5: =K5-M5 -> 0 | AC5: Tack Welding U/P | AL5: Tack Welding completed
C6: 2 | E6: Earthing | I6: Nos | K6: 306 | M6: 292 | P6: =K6-M6 -> 14 | T6: NH / SH Crossing | AC6: Erection U/P | AJ6: 4 | AL6: Erection completed
C7: 3 | E7: Tower Erection | I7: Nos | K7: 306 | M7: ='DPR_TA-413 '!J16 -> 273 | P7: =K7-M7 -> 33 | AA7: 1 | AC7: Foundation U/P | AL7: Foundation completed
C8: 4 | E8: Rough Sag | I8: KM | K8: 117.85085 | M8: ='DPR_TA-413 '!J22 -> 26.417 | P8: =K8-M8 -> 91.433851 | T8: Railway Crossing | AJ8: 3
C9: 5 | E9: Final Sag | I9: KM | K9: 117.85085 | M9: =M8 -> 26.417 | P9: =K9-M9 -> 91.433851 | AA9: 1 | AC9: Excavation U/P | AJ9: 2 | AL9: Excavation completed
T10: Canal | AL10: Earthing completed
Q12: =O12+1 -> 1 | S12: 2 | U12: =S12+1 -> 3 | W12: =U12+1 -> 4 | Y12: =W12+1 -> 5 | AA12: =Y12+1 -> 6 | AC12: =AA12+1 -> 7 | AE12: =AC12+1 -> 8 | AG12: =AE12+1 -> 9 | AI12: =AG12+1 -> 10 | AK12: =AI12+1 -> 11 | AM12: =AK12+1 -> 12 | AO12: =AM12+1 -> 13 | AQ12: =AO12+1 -> 14 | AS12: =AQ12+1 -> 15
D13: Hold | O13: Gantry | Q13: 1/0 | S13: 2A/0 | U13: 2A/1 | W13: 2A/2 | Y13: 2A/3 | AA13: 2A/4 | AC13: 2A/5 | AE13: 2A/6 | AG13: 3A/0 | AI13: 3A/1 | AK13: 3A/2 | AM13: 3A/3 | AO13: 3A/4 | AQ13: 3A/5 | AS13: 3A/6
D15: Foundation ROW
K16: Bikaner III Gantry | P16: 150 | Q16: 3 | R16: 290.21 | S16: 3 | T16: =VLOOKUP(S13,'Location Summary'!$G$2:$H$604,2,FALSE) -> 378 | U16: 3 | V16: =VLOOKUP(U13,'Location Summary'!$G$2:$H$604,2,FALSE) -> 381 | W16: 3 | X16: =VLOOKUP(W13,'Location Summary'!$G$2:$H$604,2,FALSE) -> 419 | Y16: 3 | Z16: =VLOOKUP(Y13,'Location Summary'!$G$2:$H$604,2,FALSE) -> 422 | AA16: 3 | AB16: =VLOOKUP(AA13,'Location Summary'!$G$2:$H$604,2,FALSE) -> 399 | AC16: 3 | AD16: =VLOOKUP(AC13,'Location Summary'!$G$2:$H$604,2,FALSE) -> 423 | AE16: 3 | AF16: =VLOOKUP(AE13,'Location Summary'!$G$2:$H$604,2,FALSE) -> 414.992 | AG16: 3 | AH16: =VLOOKUP(AG13,'Location Summary'!$G$2:$H$604,2,FALSE) -> 409 | AI16: 3 | AJ16: =VLOOKUP(AI13,'Location Summary'!$G$2:$H$604,2,FALSE) -> 402 | AK16: 3 | AL16: =VLOOKUP(AK13,'Location Summary'!$G$2:$H$604,2,FALSE) -> 409 | AM16: 3 | AN16: =VLOOKUP(AM13,'Location Summary'!$G$2:$H$604,2,FALSE) -> 337 | AO16: 3 | AP16: =VLOOKUP(AO13,'Location Summary'!$G$2:$H$604,2,FALSE) -> 365 | AQ16: 3 | AR16: =VLOOKUP(AQ13,'Location Summary'!$G$2:$H$604,2,FALSE) -> 378 | AS16: 3 | AT16: =VLOOKUP(AS13,'Location Summary'!$G$2:$H$604,2,FALSE) -> 391.467
D17: Erection ROW | Q17: 2 | S17: 2 | U17: 2 | W17: 2 | Y17: 2 | AA17: 2 | AC17: 2 | AE17: 2 | AG17: 2 | AI17: 2 | AK17: 2 | AM17: 2 | AO17: 2 | AQ17: 2 | AS17: 2
O18: Gantry | Q18: =VLOOKUP(Q13,'Location Summary'!$C$2:$J$604,2,FALSE) -> DD60+0 | S18: =VLOOKUP(S13,'Location Summary'!$C$2:$J$604,2,FALSE) -> DD45+0 | U18: =VLOOKUP(U13,'Location Summary'!$C$2:$J$604,2,FALSE) -> DA+0 | W18: =VLOOKUP(W13,'Location Summary'!$C$2:$J$604,2,FALSE) -> DA+3 | Y18: =VLOOKUP(Y13,'Location Summary'!$C$2:$J$604,2,FALSE) -> DA+3 | AA18: =VLOOKUP(AA13,'Location Summary'!$C$2:$J$604,2,FALSE) -> DA+3 | AC18: =VLOOKUP(AC13,'Location Summary'!$C$2:$J$604,2,FALSE) -> DA+3 | AE18: =VLOOKUP(AE13,'Location Summary'!$C$2:$J$604,2,FALSE) -> DA+6 | AG18: =VLOOKUP(AG13,'Location Summary'!$C$2:$J$604,2,FALSE) -> DD45+3 | AI18: =VLOOKUP(AI13,'Location Summary'!$C$2:$J$604,2,FALSE) -> DA+3 | AK18: =VLOOKUP(AK13,'Location Summary'!$C$2:$J$604,2,FALSE) -> DA+3 | AM18: =VLOOKUP(AM13,'Location Summary'!$C$2:$J$604,2,FALSE) -> DA+0 | AO18: =VLOOKUP(AO13,'Location Summary'!$C$2:$J$604,2,FALSE) -> DA+0 | AQ18: =VLOOKUP(AQ13,'Location Summary'!$C$2:$J$604,2,FALSE) -> DA+3 | AS18: =VLOOKUP(AS13,'Location Summary'!$C$2:$J$604,2,FALSE) -> DA+0
S19: ROW
C20: =AS12+1 -> 16 | E20: =C20+1 -> 17 | G20: =E20+1 -> 18 | I20: =G20+1 -> 19 | K20: =I20+1 -> 20 | M20: =K20+1 -> 21 | O20: =M20+1 -> 22 | Q20: =O20+1 -> 23 | S20: =Q20+1 -> 24 | U20: =S20+1 -> 25 | W20: =U20+1 -> 26 | Y20: =W20+1 -> 27 | AA20: =Y20+1 -> 28 | AC20: =AA20+1 -> 29 | AE20: =AC20+1 -> 30 | AG20: =AE20+1 -> 31 | AI20: =AG20+1 -> 32 | AK20: =AI20+1 -> 33 | AM20: =AK20+1 -> 34 | AO20: =AM20+1 -> 35 | AQ20: =AO20+1 -> 36 | AS20: =AQ20+1 -> 37
C21: 3B/0 | E21: 3B/1 | G21: 3B/2 | I21: 3B/3 | K21: 4/0 | M21: 4/5 | O21: 4A/0 | Q21: 4A/1 | S21: 4A/2 | U21: 4A/3 | W21: 4A/4 | Y21: 4A/5 | AA21: 4A/6 | AC21: 5/0 | AE21: 5/1 | AG21: 5/2 | AI21: 5/3 | AK21: 5/4 | AM21: 5/5 | AO21: 5/6 | AQ21: 5/7 | AS21: 5/8
C24: 3 | D24: =VLOOKUP(C21,'Location Summary'!$G$2:$H$604,2,FALSE) -> 356 | E24: 3 | F24: =VLOOKUP(E21,'Location Summary'!$G$2:$H$604,2,FALSE) -> 439 | G24: 3 | H24: =VLOOKUP(G21,'Location Summary'!$G$2:$H$604,2,FALSE) -> 377 | I24: 3 | J24: =VLOOKUP(I21,'Location Summary'!$G$2:$H$604,2,FALSE) -> 455.07 | K24: 3 | L24: =VLOOKUP(K21,'Location Summary'!$G$2:$H$604,2,FALSE) -> 344.163 | M24: 3 | N24: =VLOOKUP(M21,'Location Summary'!$G$2:$H$604,2,FALSE) -> 365 | O24: 3 | P24: =VLOOKUP(O21,'Location Summary'!$G$2:$H$604,2,FALSE) -> 340 | Q24: 3 | R24: =VLOOKUP(Q21,'Location Summary'!$G$2:$H$604,2,FALSE) -> 419.999 | S24: 3 | T24: =VLOOKUP(S21,'Location Summary'!$G$2:$H$604,2,FALSE) -> 415 | U24: 3 | V24: =VLOOKUP(U21,'Location Summary'!$G$2:$H$604,2,FALSE) -> 365 | W24: 3 | X24: =VLOOKUP(W21,'Location Summary'!$G$2:$H$604,2,FALSE) -> 330 | Y24: 3 | Z24: =VLOOKUP(Y21,'Location Summary'!$G$2:$H$604,2,FALSE) -> 457 | AA24: 3 | AB24: =VLOOKUP(AA21,'Location Summary'!$G$2:$H$604,2,FALSE) -> 354.612 | AC24: 3 | AD24: =VLOOKUP(AC21,'Location Summary'!$G$2:$H$604,2,FALSE) -> 428.389 | AE24: 3 | AF24: =VLOOKUP(AE21,'Location Summary'!$G$2:$H$604,2,FALSE) -> 340 | AG24: 3 | AH24: =VLOOKUP(AG21,'Location Summary'!$G$2:$H$604,2,FALSE) -> 375 | AI24: 3 | AJ24: =VLOOKUP(AI21,'Location Summary'!$G$2:$H$604,2,FALSE) -> 365 | AK24: 3 | AL24: =VLOOKUP(AK21,'Location Summary'!$G$2:$H$604,2,FALSE) -> 460 | AM24: 3 | AN24: =VLOOKUP(AM21,'Location Summary'!$G$2:$H$604,2,FALSE) -> 380 | AO24: 3 | AP24: =VLOOKUP(AO21,'Location Summary'!$G$2:$H$604,2,FALSE) -> 410 | AQ24: 3 | AR24: =VLOOKUP(AQ21,'Location Summary'!$G$2:$H$604,2,FALSE) -> 400 | AS24: 3 | AT24: =VLOOKUP(AS21,'Location Summary'!$G$2:$H$604,2,FALSE) -> 420
C25: 2 | E25: 2 | G25: 2 | I25: 2 | K25: 2 | M25: 2 | O25: 2 | Q25: 2 | S25: 2 | U25: 2 | W25: 2 | Y25: 2 | AA25: 2 | AC25: 2 | AE25: 2 | AG25: 2 | AI25: 2 | AK25: 2 | AM25: 2 | AO25: 2 | AQ25: 2 | AS25: 2
C26: =VLOOKUP(C21,'Location Summary'!$C$2:$J$604,2,FALSE) -> DB1+9 | E26: =VLOOKUP(E21,'Location Summary'!$C$2:$J$604,2,FALSE) -> DA+3 | G26: =VLOOKUP(G21,'Location Summary'!$C$2:$J$604,2,FALSE) -> DA+9 | I26: =VLOOKUP(I21,'Location Summary'!$C$2:$J$604,2,FALSE) -> DA+6 | K26: =VLOOKUP(K21,'Location Summary'!$C$2:$J$604,2,FALSE) -> DB2+9 | M26: =VLOOKUP(M21,'Location Summary'!$C$2:$J$604,2,FALSE) -> DA+6 | O26: =VLOOKUP(O21,'Location Summary'!$C$2:$J$604,2,FALSE) -> DB1+3 | Q26: =VLOOKUP(Q21,'Location Summary'!$C$2:$J$604,2,FALSE) -> DA+6 | S26: =VLOOKUP(S21,'Location Summary'!$C$2:$J$604,2,FALSE) -> DA+6 | U26: =VLOOKUP(U21,'Location Summary'!$C$2:$J$604,2,FALSE) -> DA+9 | W26: =VLOOKUP(W21,'Location Summary'!$C$2:$J$604,2,FALSE) -> DA+6 | Y26: =VLOOKUP(Y21,'Location Summary'!$C$2:$J$604,2,FALSE) -> DA+9 | AA26: =VLOOKUP(AA21,'Location Summary'!$C$2:$J$604,2,FALSE) -> DA+9 | AC26: =VLOOKUP(AC21,'Location Summary'!$C$2:$J$604,2,FALSE) -> DB1+6 | AE26: =VLOOKUP(AE21,'Location Summary'!$C$2:$J$604,2,FALSE) -> DA+6 | AG26: =VLOOKUP(AG21,'Location Summary'!$C$2:$J$604,2,FALSE) -> DA+9 | AI26: =VLOOKUP(AI21,'Location Summary'!$C$2:$J$604,2,FALSE) -> DA+9 | AK26: =VLOOKUP(AK21,'Location Summary'!$C$2:$J$604,2,FALSE) -> DA-1.5 | AM26: =VLOOKUP(AM21,'Location Summary'!$C$2:$J$604,2,FALSE) -> DA+6 | AO26: =VLOOKUP(AO21,'Location Summary'!$C$2:$J$604,2,FALSE) -> DA+3 | AQ26: =VLOOKUP(AQ21,'Location Summary'!$C$2:$J$604,2,FALSE) -> DA+9 | AS26: =VLOOKUP(AS21,'Location Summary'!$C$2:$J$604,2,FALSE) -> DA+6
C28: =AS20+1 -> 38 | E28: =C28+1 -> 39 | G28: =E28+1 -> 40 | I28: =G28+1 -> 41 | K28: =I28+1 -> 42 | M28: =K28+1 -> 43 | O28: =M28+1 -> 44 | Q28: =O28+1 -> 45 | S28: =Q28+1 -> 46 | U28: =S28+1 -> 47 | W28: =U28+1 -> 48 | Y28: =W28+1 -> 49 | AA28: =Y28+1 -> 50 | AC28: =AA28+1 -> 51 | AE28: =AC28+1 -> 52 | AG28: =AE28+1 -> 53 | AI28: =AG28+1 -> 54 | AK28: =AI28+1 -> 55 | AM28: =AK28+1 -> 56 | AO28: =AM28+1 -> 57 | AQ28: =AO28+1 -> 58 | AS28: =AQ28+1 -> 59
C29: 5/9 | E29: 5/10 | G29: 5A/0 | I29: 6/0 | K29: 6/1 | M29: 6/2 | O29: 6/3 | Q29: 6/4 | S29: 6/5 | U29: 6/6 | W29: 6/7 | Y29: 6/8 | AA29: 6/9 | AC29: 6/10 | AE29: 6/11 | AG29: 6/12 | AI29: 7/0 | AK29: 7/1 | AM29: 7/2 | AO29: 7/3 | AQ29: 7/4 | AS29: 7/5
C32: 3 | D32: =VLOOKUP(C29,'Location Summary'!$G$2:$H$604,2,FALSE) -> 345 | E32: 3 | F32: =VLOOKUP(E29,'Location Summary'!$G$2:$H$604,2,FALSE) -> 495 | G32: 3 | H32: =VLOOKUP(G29,'Location Summary'!$G$2:$H$604,2,FALSE) -> 419.48 | I32: 3 | J32: =VLOOKUP(I29,'Location Summary'!$G$2:$H$604,2,FALSE) -> 350.52 | K32: 3 | L32: =VLOOKUP(K29,'Location Summary'!$G$2:$H$604,2,FALSE) -> 445 | M32: 3 | N32: =VLOOKUP(M29,'Location Summary'!$G$2:$H$604,2,FALSE) -> 390 | O32: 3 | P32: =VLOOKUP(O29,'Location Summary'!$G$2:$H$604,2,FALSE) -> 350 | Q32: 3 | R32: =VLOOKUP(Q29,'Location Summary'!$G$2:$H$604,2,FALSE) -> 490 | S32: 3 | T32: =VLOOKUP(S29,'Location Summary'!$G$2:$H$604,2,FALSE) -> 350 | U32: 3 | V32: =VLOOKUP(U29,'Location Summary'!$G$2:$H$604,2,FALSE) -> 347 | W32: 3 | X32: =VLOOKUP(W29,'Location Summary'!$G$2:$H$604,2,FALSE) -> 373 | Y32: 3 | Z32: =VLOOKUP(Y29,'Location Summary'!$G$2:$H$604,2,FALSE) -> 380 | AA32: 3 | AB32: =VLOOKUP(AA29,'Location Summary'!$G$2:$H$604,2,FALSE) -> 335 | AC32: 3 | AD32: =VLOOKUP(AC29,'Location Summary'!$G$2:$H$604,2,FALSE) -> 315 | AE32: 3 | AF32: =VLOOKUP(AE29,'Location Summary'!$G$2:$H$604,2,FALSE) -> 410 | AG32: 3 | AH32: =VLOOKUP(AG29,'Location Summary'!$G$2:$H$604,2,FALSE) -> 365.716 | AI32: 3 | AJ32: =VLOOKUP(AI29,'Location Summary'!$G$2:$H$604,2,FALSE) -> 319.284 | AK32: 3 | AL32: =VLOOKUP(AK29,'Location Summary'!$G$2:$H$604,2,FALSE) -> 465 | AM32: 3 | AN32: =VLOOKUP(AM29,'Location Summary'!$G$2:$H$604,2,FALSE) -> 375 | AO32: 3 | AP32: =VLOOKUP(AO29,'Location Summary'!$G$2:$H$604,2,FALSE) -> 355 | AQ32: 3 | AR32: =VLOOKUP(AQ29,'Location Summary'!$G$2:$H$604,2,FALSE) -> 420 | AS32: 3 | AT32: =VLOOKUP(AS29,'Location Summary'!$G$2:$H$604,2,FALSE) -> 315
C33: 2 | E33: 2 | G33: 2 | I33: 2 | K33: 2 | M33: 2 | O33: 2 | Q33: 2 | S33: 2 | U33: 2 | W33: 2 | Y33: 2 | AA33: 2 | AC33: 2 | AE33: 2 | AG33: 2 | AI33: 2 | AK33: 2 | AM33: 2 | AO33: 2 | AQ33: 2 | AS33: 2
C34: =VLOOKUP(C29,'Location Summary'!$C$2:$J$604,2,FALSE) -> DA+6 | E34: =VLOOKUP(E29,'Location Summary'!$C$2:$J$604,2,FALSE) -> DA+9 | G34: =VLOOKUP(G29,'Location Summary'!$C$2:$J$604,2,FALSE) -> DB1+12 | I34: =VLOOKUP(I29,'Location Summary'!$C$2:$J$604,2,FALSE) -> DB1+9 | K34: =VLOOKUP(K29,'Location Summary'!$C$2:$J$604,2,FALSE) -> DA+9 | M34: =VLOOKUP(M29,'Location Summary'!$C$2:$J$604,2,FALSE) -> DA+6 | O34: =VLOOKUP(O29,'Location Summary'!$C$2:$J$604,2,FALSE) -> DA+3 | Q34: =VLOOKUP(Q29,'Location Summary'!$C$2:$J$604,2,FALSE) -> DA+9 | S34: =VLOOKUP(S29,'Location Summary'!$C$2:$J$604,2,FALSE) -> DA+9 | U34: =VLOOKUP(U29,'Location Summary'!$C$2:$J$604,2,FALSE) -> DA-3 | W34: =VLOOKUP(W29,'Location Summary'!$C$2:$J$604,2,FALSE) -> DA+1.5 | Y34: =VLOOKUP(Y29,'Location Summary'!$C$2:$J$604,2,FALSE) -> DA+3 | AA34: =VLOOKUP(AA29,'Location Summary'!$C$2:$J$604,2,FALSE) -> DA+6 | AC34: =VLOOKUP(AC29,'Location Summary'!$C$2:$J$604,2,FALSE) -> DA+1.5 | AE34: =VLOOKUP(AE29,'Location Summary'!$C$2:$J$604,2,FALSE) -> DA-1.5 | AG34: =VLOOKUP(AG29,'Location Summary'!$C$2:$J$604,2,FALSE) -> DA+1.5 | AI34: =VLOOKUP(AI29,'Location Summary'!$C$2:$J$604,2,FALSE) -> DB2+0 | AK34: =VLOOKUP(AK29,'Location Summary'!$C$2:$J$604,2,FALSE) -> DA-3 | AM34: =VLOOKUP(AM29,'Location Summary'!$C$2:$J$604,2,FALSE) -> DA+6 | AO34: =VLOOKUP(AO29,'Location Summary'!$C$2:$J$604,2,FALSE) -> DA+9 | AQ34: =VLOOKUP(AQ29,'Location Summary'!$C$2:$J$604,2,FALSE) -> DA+6 | AS34: =VLOOKUP(AS29,'Location Summary'!$C$2:$J$604,2,FALSE) -> DA+6
C36: =AS28+1 -> 60 | E36: =C36+1 -> 61 | G36: =E36+1 -> 62 | I36: =G36+1 -> 63 | K36: =I36+1 -> 64 | M36: =K36+1 -> 65 | O36: =M36+1 -> 66 | Q36: =O36+1 -> 67 | S36: =Q36+1 -> 68 | U36: =S36+1 -> 69 | W36: =U36+1 -> 70 | Y36: =W36+1 -> 71 | AA36: =Y36+1 -> 72 | AC36: =AA36+1 -> 73 | AE36: =AC36+1 -> 74 | AG36: =AE36+1 -> 75 | AI36: =AG36+1 -> 76 | AK36: =AI36+1 -> 77 | AM36: =AK36+1 -> 78 | AO36: =AM36+1 -> 79 | AQ36: =AO36+1 -> 80 | AS36: =AQ36+1 -> 81
C37: 7/6 | E37: 7A/0 | G37: 7A/1 | I37: 7A/2 | K37: 7A/3 | M37: 7A/4 | O37: 7A/5 | Q37: 8/0 | S37: 8/1 | U37: 8/2 | W37: 8/3 | Y37: 8/4 | AA37: 8/5 | AC37: 8/6 | AE37: 8/7 | AG37: 8/8 | AI37: 8/9 | AK37: 8/10 | AM37: 8/11 | AO37: 8A/0 | AQ37: 9/0 | AS37: 9/1
C40: 3 | D40: =VLOOKUP(C37,'Location Summary'!$G$2:$H$604,2,FALSE) -> 450 | E40: 3 | F40: =VLOOKUP(E37,'Location Summary'!$G$2:$H$604,2,FALSE) -> 435 | G40: 3 | H40: =VLOOKUP(G37,'Location Summary'!$G$2:$H$604,2,FALSE) -> 385 | I40: 3 | J40: =VLOOKUP(I37,'Location Summary'!$G$2:$H$604,2,FALSE) -> 390 | K40: 3 | L40: =VLOOKUP(K37,'Location Summary'!$G$2:$H$604,2,FALSE) -> 405 | M40: 3 | N40: =VLOOKUP(M37,'Location Summary'!$G$2:$H$604,2,FALSE) -> 390 | O40: 3 | P40: =VLOOKUP(O37,'Location Summary'!$G$2:$H$604,2,FALSE) -> 429.77 | Q40: 3 | R40: =VLOOKUP(Q37,'Location Summary'!$G$2:$H$604,2,FALSE) -> 350 | S40: 3 | T40: =VLOOKUP(S37,'Location Summary'!$G$2:$H$604,2,FALSE) -> 330 | U40: 3 | V40: =VLOOKUP(U37,'Location Summary'!$G$2:$H$604,2,FALSE) -> 390 | W40: 3 | X40: =VLOOKUP(W37,'Location Summary'!$G$2:$H$604,2,FALSE) -> 400 | Y40: 3 | Z40: =VLOOKUP(Y37,'Location Summary'!$G$2:$H$604,2,FALSE) -> 345 | AA40: 3 | AB40: =VLOOKUP(AA37,'Location Summary'!$G$2:$H$604,2,FALSE) -> 350 | AC40: 3 | AD40: =VLOOKUP(AC37,'Location Summary'!$G$2:$H$604,2,FALSE) -> 335 | AE40: 3 | AF40: =VLOOKUP(AE37,'Location Summary'!$G$2:$H$604,2,FALSE) -> 415 | AG40: 3 | AH40: =VLOOKUP(AG37,'Location Summary'!$G$2:$H$604,2,FALSE) -> 375 | AI40: 3 | AJ40: =VLOOKUP(AI37,'Location Summary'!$G$2:$H$604,2,FALSE) -> 375 | AK40: 3 | AL40: =VLOOKUP(AK37,'Location Summary'!$G$2:$H$604,2,FALSE) -> 375 | AM40: 3 | AN40: =VLOOKUP(AM37,'Location Summary'!$G$2:$H$604,2,FALSE) -> 415 | AO40: 3 | AP40: =VLOOKUP(AO37,'Location Summary'!$G$2:$H$604,2,FALSE) -> 466.629 | AQ40: 3 | AR40: =VLOOKUP(AQ37,'Location Summary'!$G$2:$H$604,2,FALSE) -> 418.372 | AS40: 3 | AT40: =VLOOKUP(AS37,'Location Summary'!$G$2:$H$604,2,FALSE) -> 410
C41: 2 | E41: 2 | G41: 2 | I41: 2 | K41: 2 | M41: 2 | O41: 2 | Q41: 2 | S41: 2 | U41: 2 | W41: 2 | Y41: 2 | AA41: 2 | AC41: 2 | AE41: 2 | AG41: 2 | AI41: 2 | AK41: 2 | AM41: 2 | AO41: 2 | AQ41: 2 | AS41: 2
C42: =VLOOKUP(C37,'Location Summary'!$C$2:$J$604,2,FALSE) -> DA-1.5 | E42: =VLOOKUP(E37,'Location Summary'!$C$2:$J$604,2,FALSE) -> DB1+6 | G42: =VLOOKUP(G37,'Location Summary'!$C$2:$J$604,2,FALSE) -> DA+1.5 | I42: =VLOOKUP(I37,'Location Summary'!$C$2:$J$604,2,FALSE) -> DA+3 | K42: =VLOOKUP(K37,'Location Summary'!$C$2:$J$604,2,FALSE) -> DA+3 | M42: =VLOOKUP(M37,'Location Summary'!$C$2:$J$604,2,FALSE) -> DA+3 | O42: =VLOOKUP(O37,'Location Summary'!$C$2:$J$604,2,FALSE) -> DA+3 | Q42: =VLOOKUP(Q37,'Location Summary'!$C$2:$J$604,2,FALSE) -> DB1+0 | S42: =VLOOKUP(S37,'Location Summary'!$C$2:$J$604,2,FALSE) -> DA-3 | U42: =VLOOKUP(U37,'Location Summary'!$C$2:$J$604,2,FALSE) -> DA+6 | W42: =VLOOKUP(W37,'Location Summary'!$C$2:$J$604,2,FALSE) -> DA+9 | Y42: =VLOOKUP(Y37,'Location Summary'!$C$2:$J$604,2,FALSE) -> DA+6 | AA42: =VLOOKUP(AA37,'Location Summary'!$C$2:$J$604,2,FALSE) -> DA+9 | AC42: =VLOOKUP(AC37,'Location Summary'!$C$2:$J$604,2,FALSE) -> DA+3 | AE42: =VLOOKUP(AE37,'Location Summary'!$C$2:$J$604,2,FALSE) -> DA+3 | AG42: =VLOOKUP(AG37,'Location Summary'!$C$2:$J$604,2,FALSE) -> DA+9 | AI42: =VLOOKUP(AI37,'Location Summary'!$C$2:$J$604,2,FALSE) -> DA+3 | AK42: =VLOOKUP(AK37,'Location Summary'!$C$2:$J$604,2,FALSE) -> DA+0 | AM42: =VLOOKUP(AM37,'Location Summary'!$C$2:$J$604,2,FALSE) -> DA+9 | AO42: =VLOOKUP(AO37,'Location Summary'!$C$2:$J$604,2,FALSE) -> DB1+12 | AQ42: =VLOOKUP(AQ37,'Location Summary'!$C$2:$J$604,2,FALSE) -> DB1+12 | AS42: =VLOOKUP(AS37,'Location Summary'!$C$2:$J$604,2,FALSE) -> DA+3
C44: =AS36+1 -> 82 | E44: =C44+1 -> 83 | G44: =E44+1 -> 84 | I44: =G44+1 -> 85 | K44: =I44+1 -> 86 | M44: =K44+1 -> 87 | O44: =M44+1 -> 88 | Q44: =O44+1 -> 89 | S44: =Q44+1 -> 90 | U44: =S44+1 -> 91 | W44: =U44+1 -> 92 | Y44: =W44+1 -> 93 | AA44: =Y44+1 -> 94 | AC44: =AA44+1 -> 95 | AE44: =AC44+1 -> 96 | AG44: =AE44+1 -> 97 | AI44: =AG44+1 -> 98 | AK44: =AI44+1 -> 99 | AM44: =AK44+1 -> 100 | AO44: =AM44+1 -> 101 | AQ44: =AO44+1 -> 102 | AS44: =AQ44+1 -> 103
C45: 9/2 | E45: 9/3 | G45: 9/4 | I45: 9/5 | K45: 9/6 | M45: 9/7 | O45: 9/8 | Q45: 9/9 | S45: 9/10 | U45: 9/11 | W45: 10/0 | Y45: 10/1 | AA45: 10/2 | AC45: 11/0 | AE45: 12/0 | AG45: 13/0 | AI45: 13A/0 | AK45: 14/0 | AM45: 15/0 | AO45: 15/1 | AQ45: 15/2 | AS45: 15/3
AF46: 132kV | AL46: 400kV
C48: 3 | D48: =VLOOKUP(C45,'Location Summary'!$G$2:$H$604,2,FALSE) -> 395 | E48: 3 | F48: =VLOOKUP(E45,'Location Summary'!$G$2:$H$604,2,FALSE) -> 395 | G48: 3 | H48: =VLOOKUP(G45,'Location Summary'!$G$2:$H$604,2,FALSE) -> 425 | I48: 3 | J48: =VLOOKUP(I45,'Location Summary'!$G$2:$H$604,2,FALSE) -> 415 | K48: 3 | L48: =VLOOKUP(K45,'Location Summary'!$G$2:$H$604,2,FALSE) -> 405 | M48: 3 | N48: =VLOOKUP(M45,'Location Summary'!$G$2:$H$604,2,FALSE) -> 435 | O48: 3 | P48: =VLOOKUP(O45,'Location Summary'!$G$2:$H$604,2,FALSE) -> 405 | Q48: 3 | R48: =VLOOKUP(Q45,'Location Summary'!$G$2:$H$604,2,FALSE) -> 435 | S48: 3 | T48: =VLOOKUP(S45,'Location Summary'!$G$2:$H$604,2,FALSE) -> 395 | U48: 3 | V48: =VLOOKUP(U45,'Location Summary'!$G$2:$H$604,2,FALSE) -> 431.548 | W48: 3 | X48: =VLOOKUP(W45,'Location Summary'!$G$2:$H$604,2,FALSE) -> 363.452 | Y48: 3 | Z48: =VLOOKUP(Y45,'Location Summary'!$G$2:$H$604,2,FALSE) -> 295 | AA48: 3 | AB48: =VLOOKUP(AA45,'Location Summary'!$G$2:$H$604,2,FALSE) -> 345.731 | AC48: 3 | AD48: =VLOOKUP(AC45,'Location Summary'!$G$2:$H$604,2,FALSE) -> 242.893 | AE48: 3 | AF48: =VLOOKUP(AE45,'Location Summary'!$G$2:$H$604,2,FALSE) -> 329.728 | AG48: 3 | AH48: =VLOOKUP(AG45,'Location Summary'!$G$2:$H$604,2,FALSE) -> 416.878 | AI48: 3 | AJ48: =VLOOKUP(AI45,'Location Summary'!$G$2:$H$604,2,FALSE) -> 480.269 | AK48: 3 | AL48: =VLOOKUP(AK45,'Location Summary'!$G$2:$H$604,2,FALSE) -> 223.816 | AM48: 3 | AN48: =VLOOKUP(AM45,'Location Summary'!$G$2:$H$604,2,FALSE) -> 405.915 | AO48: 3 | AP48: =VLOOKUP(AO45,'Location Summary'!$G$2:$H$604,2,FALSE) -> 405 | AQ48: 3 | AR48: =VLOOKUP(AQ45,'Location Summary'!$G$2:$H$604,2,FALSE) -> 420 | AS48: 3 | AT48: =VLOOKUP(AS45,'Location Summary'!$G$2:$H$604,2,FALSE) -> 415
C49: 2 | E49: 2 | G49: 2 | I49: 2 | K49: 2 | M49: 2 | O49: 2 | Q49: 2 | S49: 2 | U49: 2 | W49: 2 | Y49: 2 | AA49: 2 | AC49: 2 | AE49: 2 | AG49: 2 | AI49: 2 | AK49: 2 | AM49: 2 | AO49: 2 | AQ49: 2 | AS49: 2
C50: =VLOOKUP(C45,'Location Summary'!$C$2:$J$604,2,FALSE) -> DA+3 | E50: =VLOOKUP(E45,'Location Summary'!$C$2:$J$604,2,FALSE) -> DA+0 | G50: =VLOOKUP(G45,'Location Summary'!$C$2:$J$604,2,FALSE) -> DA+6 | I50: =VLOOKUP(I45,'Location Summary'!$C$2:$J$604,2,FALSE) -> DA+3 | K50: =VLOOKUP(K45,'Location Summary'!$C$2:$J$604,2,FALSE) -> DA+3 | M50: =VLOOKUP(M45,'Location Summary'!$C$2:$J$604,2,FALSE) -> DA+9 | O50: =VLOOKUP(O45,'Location Summary'!$C$2:$J$604,2,FALSE) -> DA+0 | Q50: =VLOOKUP(Q45,'Location Summary'!$C$2:$J$604,2,FALSE) -> DA+0 | S50: =VLOOKUP(S45,'Location Summary'!$C$2:$J$604,2,FALSE) -> DA+3 | U50: =VLOOKUP(U45,'Location Summary'!$C$2:$J$604,2,FALSE) -> DA+3 | W50: =VLOOKUP(W45,'Location Summary'!$C$2:$J$604,2,FALSE) -> DB1+6 | Y50: =VLOOKUP(Y45,'Location Summary'!$C$2:$J$604,2,FALSE) -> DA+3 | AA50: =VLOOKUP(AA45,'Location Summary'!$C$2:$J$604,2,FALSE) -> DA+3 | AC50: =VLOOKUP(AC45,'Location Summary'!$C$2:$J$604,2,FALSE) -> DD45+0 | AE50: =VLOOKUP(AE45,'Location Summary'!$C$2:$J$604,2,FALSE) -> DB1+9 | AG50: =VLOOKUP(AG45,'Location Summary'!$C$2:$J$604,2,FALSE) -> DD60+9 | AI50: =VLOOKUP(AI45,'Location Summary'!$C$2:$J$604,2,FALSE) -> DB1+9 | AK50: =VLOOKUP(AK45,'Location Summary'!$C$2:$J$604,2,FALSE) -> DD60+18 | AM50: =VLOOKUP(AM45,'Location Summary'!$C$2:$J$604,2,FALSE) -> DD60+25 | AO50: =VLOOKUP(AO45,'Location Summary'!$C$2:$J$604,2,FALSE) -> DA+6 | AQ50: =VLOOKUP(AQ45,'Location Summary'!$C$2:$J$604,2,FALSE) -> DA+3 | AS50: =VLOOKUP(AS45,'Location Summary'!$C$2:$J$604,2,FALSE) -> DA+3
AC51: NH-62 | AJ51: RC 4 Leg
C52: =AS44+1 -> 104 | E52: =C52+1 -> 105 | G52: =E52+1 -> 106 | I52: =G52+1 -> 107 | K52: =I52+1 -> 108 | M52: =K52+1 -> 109 | O52: =M52+1 -> 110 | Q52: =O52+1 -> 111 | S52: =Q52+1 -> 112 | U52: =S52+1 -> 113 | W52: =U52+1 -> 114 | Y52: =W52+1 -> 115 | AA52: =Y52+1 -> 116 | AC52: =AA52+1 -> 117 | AE52: =AC52+1 -> 118 | AG52: =AE52+1 -> 119 | AI52: =AG52+1 -> 120 | AK52: =AI52+1 -> 121 | AM52: =AK52+1 -> 122 | AO52: =AM52+1 -> 123 | AQ52: =AO52+1 -> 124 | AS52: =AQ52+1 -> 125
C53: 15/4 | E53: 15/5 | G53: 15/6 | I53: 15/7 | K53: 15/8 | M53: 15/9 | O53: 15/10 | Q53: 15/11 | S53: 15/12 | U53: 16/0 | W53: 17/0 | Y53: 18/0 | AA53: 18/1 | AC53: 18/2 | AE53: 18/3 | AG53: 18/4 | AI53: 18/5 | AK53: 18/6 | AM53: 18/7 | AO53: 19/0 | AQ53: 20/0 | AS53: 20/1
...

Sheet Erection Compiled
A1: =[79]Earthing!A1 -> KEC International Limited
A2: =[79]Earthing!A2 -> TA413 : 765 KV D/C Bikaner III - Neemrana II TL02
A3: Details of Erection | H3: =SUBTOTAL(9,H5:H261) -> 11483.7 | I3: =SUBTOTAL(9,I5:I261) -> 1069.918 | K3: 45965
A4: CUMM. SR.NO | B4: MONTH SR.NO. | C4: Location No | D4: Type of Tower | E4: Starting Date | F4: Completion date | G4: Gang name | H4: Tower Weight | I4: Revenue | J4: Name of Supervisor | K4: Status | L4: Prop. Name
A5: 1 | B5: 1 | C5: 29A/2 | D5: DA+6 | E5: 45547 | F5: 45556 | G5: Bhagwan construction | H5: 43.804424 | I5: 4.0811881 | J5: Manoj Kumar Gupta | K5: Completed
A6: =A5+1 -> 2 | B6: 2 | C6: 29/5 | D6: DA+0 | E6: 45556 | F6: 45562 | G6: Bhagwan construction | H6: 36.159756 | I6: 3.3689466 | J6: Manoj Kumar Gupta | K6: Completed
A7: =A6+1 -> 3 | B7: 1 | C7: 29/3 | D7: DA+0 | E7: 45563 | F7: 45568 | G7: Bhagwan construction | H7: 36.159756 | I7: 3.3689466 | J7: Manoj Kumar Gupta | K7: Completed
A8: =A7+1 -> 4 | B8: 2 | C8: 29/4 | D8: DA+3 | E8: 45568 | F8: 45573 | G8: Bhagwan construction | H8: 37.931088 | I8: 3.5339788 | J8: Manoj Kumar Gupta | K8: Completed
A9: =A8+1 -> 5 | B9: 3 | C9: 29A/6 | D9: DA+9 | E9: 45568 | F9: 45579 | G9: Bhagwan construction | H9: 45.697022 | I9: 4.2575184 | J9: Manoj Kumar Gupta | K9: Completed
A10: =A9+1 -> 6 | B10: 4 | C10: 30/1 | D10: DA+0 | E10: 45574 | F10: 45582 | G10: Bhagwan construction | H10: 36.159756 | I10: 3.3689466 | J10: Kartik Mahto | K10: Completed
A11: =A10+1 -> 7 | B11: 5 | C11: 29A/1 | D11: DA+6 | E11: 45579 | F11: 45590 | G11: Bhagwan construction | H11: 43.804424 | I11: 4.0811881 | J11: Manoj Kumar Gupta | K11: Completed
A12: =A11+1 -> 8 | B12: 1 | C12: 34/8 | D12: DA+0 | E12: 45608 | F12: 45620 | G12: Vasu dev singh-1 | H12: 36.159756 | I12: 3.3689466 | J12: Raju Mahto | K12: Completed
A13: =A12+1 -> 9 | B13: 2 | C13: 34/12 | D13: DA+3 | E13: 45610 | F13: 45621 | G13: Vasu dev singh-2 | H13: 37.931088 | I13: 3.5339788 | J13: Mustak | K13: Completed
A14: =A13+1 -> 10 | B14: 1 | C14: 34/4 | D14: DA+6 | E14: 45621 | F14: 45630 | G14: Vasu dev singh-1 | H14: 43.804424 | I14: 4.0811881 | J14: Raju Mahto | K14: Completed
A15: =A14+1 -> 11 | B15: 2 | C15: 34/7 | D15: DA+0 | E15: 45622 | F15: 45638 | G15: Vasu dev singh-2 | H15: 36.159756 | I15: 3.3689466 | J15: Raju Mahto | K15: Completed
A16: =A15+1 -> 12 | B16: 3 | C16: 34/3 | D16: DA+1.5 | E16: 45631 | F16: 45642 | G16: Vasu dev singh-1 | H16: 37.138324 | I16: 3.4601182 | J16: Manoj Kumar Gupta | K16: Completed
A17: =A16+1 -> 13 | B17: 4 | C17: 8/1 | D17: DA-3 | E17: 45633 | F17: 45642 | G17: Punam Devi-2 | H17: 34.78981 | I17: 3.2413109 | J17: Sanjay Kumar | K17: Completed
... A20: =A19+1 -> 16 | B20: 7 | C20: 7A/5 | D20: DA+3 | E20: 45643 | F20: 45650 | G20: Punam Devi-2 | H20: 37.931088 | I20: 3.5339788 | J20: Sanjay Kumar | K20: Completed
A21: =A20+1 -> 17 | B21: 8 | C21: 36A/1 | D21: DA+3 | E21: 45639 | F21: 45651 | G21: Punam Devi-3 | H21: 37.931088 | I21: 3.5339788 | J21: Haridas | K21: Completed | L21: Sachinder
A22: =A21+1 -> 18 | B22: 9 | C22: 7/1 | D22: DA-3 | E22: 45641 | F22: 45652 | G22: Punam Devi-1 | H22: 34.78981 | I22: 3.2413109 | J22: Raju Mahto | K22: Completed | L22: Hazari Yadav
A23: =A22+1 -> 19 | B23: 10 | C23: 35/8 | D23: DA+6 | E23: 45649 | F23: 45654 | G23: Punam Devi-2 | H23: 43.804424 | I23: 4.0811881 | J23: Kartik Mahto | K23: Completed | L23: Gulshan Kumar
A24: =A23+1 -> 20 | B24: 11 | C24: 34/5 | D24: DA+9 | E24: 45643 | F24: 45655 | G24: Vasu dev singh-1 | H24: 45.697022 | I24: 4.2575184 | J24: Manoj Kumar Gupta | K24: Completed | L24: Pawan
A25: =A24+1 -> 21 | B25: 12 | C25: 34/10 | D25: DA-3 | E25: 45648 | F25: 45655 | G25: Vasu dev singh-2 | H25: 34.78981 | I25: 3.2413109 | J25: Mustak & Abul | K25: Completed | L25: Praveen Kumar
A26: =A25+1 -> 22 | B26: 13 | C26: 7A/4 | D26: DA+3 | E26: 45650 | F26: 45657 | G26: Punam Devi-2 | H26: 37.931088 | I26: 3.5339788 | J26: Raju Mahto | K26: Completed | L26: Dharmendra Das
A27: =A26+1 -> 23 | B27: 1 | C27: 7/2 | D27: DA+6 | E27: 45653 | F27: 45660 | G27: Punam Devi-1 | H27: 43.804424 | I27: 4.0811881 | J27: Gangadin sahoo | K27: Completed | L27: Hazari Yadav
A28: =A27+1 -> 24 | B28: 2 | C28: 35/11 | D28: DA+3 | E28: 45650 | F28: 45660 | G28: Punam Devi-3 | H28: 37.931088 | I28: 3.5339788 | J28: Haridas | K28: Completed | L28: Sachinder
A29: =A28+1 -> 25 | B29: 3 | C29: 35/6 | D29: DA+6 | E29: 45655 | F29: 45662 | G29: Punam Devi-2 | H29: 43.804424 | I29: 4.0811881 | J29: Kartik Mahto | K29: Completed | L29: Gulshan Kumar
A30: =A29+1 -> 26 | B30: 4 | C30: 34/11 | D30: DA+1.5 | E30: 45656 | F30: 45664 | G30: Vasu dev singh-2 | H30: 37.138324 | I30: 3.4601182 | J30: Mustak & Abul | K30: Completed | L30: Praveen Kumar
A31: =A30+1 -> 27 | B31: 5 | C31: 7A/3 | D31: DA+3 | E31: 45658 | F31: 45665 | G31: Punam Devi-2 | H31: 37.931088 | I31: 3.5339788 | J31: Raju Mahto | K31: Completed | L31: Dharmendra Das
A32: =A31+1 -> 28 | B32: 6 | C32: 34/6 | D32: DA+3 | E32: 45656 | F32: 45666 | G32: Vasu dev singh-1 | H32: 37.931088 | I32: 3.5339788 | J32: Manoj Kumar Gupta | K32: Completed | L32: Pawan
... A105: =A104+1 -> 101 | B105: 8 | C105: 39/6 | D105: DA+1.5 | E105: 45756 | F105: 45765 | G105: Punam Devi-1 | H105: 37.138324 | I105: 3.4601182 | J105: Haridas | K105: Completed | L105: Gulshan Kumar
A106: 102 | B106: 9 | C106: 40/6 | D106: DA+9 | E106: 45761 | F106: 45769 | G106: Punam Devi-3 | H106: 45.697022 | I106: 4.2575184 | J106: Haridas | K106: Completed | L106: Mithilesh
A107: 103 | B107: 10 | C107: 36A/0 | D107: DB1+9 | E107: 45765 | F107: 45777 | G107: Punam Devi-2 | H107: 66.780901 | I107: 6.2218697 | J107: Raju Mahto | K107: Completed | L107: Gopal Muni
A108: 104 | B108: 11 | C108: 40/0 | D108: DB1+6 | E108: 45765 | F108: 45777 | G108: Punam Devi-1 | H108: 65.027779 | I108: 6.0585341 | J108: Haridas | K108: Completed | L108: Gulshan Kumar
A109: 105 | B109: 1 | C109: 32/6 | D109: DA+9 | E109: 45844 | F109: 45853 | G109: Punam Kumari | H109: 45.697022 | I109: 4.2575184 | J109: Manoj Gupta | K109: Completed
A110: 106 | B110: 2 | C110: 32/1 | D110: DA+6 | E110: 45843 | F110: 45855 | G110: Amit Kumar Singh | H110: 43.804424 | I110: 4.0811881 | J110: Raju Mahto | K110: Completed
A111: =A110+1 -> 107 | B111: 3 | C111: 7/3 | D111: DA+9 | E111: 45847 | F111: 45859 | G111: Pritam Enterprises | H111: 45.697022 | I111: 4.2575184 | J111: Sanjay Kumar | K111: Completed
A112: =A111+1 -> 108 | B112: 4 | C112: 32/5 | D112: DA+9 | E112: 45854 | F112: 45863 | G112: Punam Kumari | H112: 45.697022 | I112: 4.2575184 | J112: Manoj Gupta | K112: Completed
A113: =A112+1 -> 109 | B113: 5 | C113: 6/1 | D113: DA+9 | E113: 45854 | F113: 45864 | G113: Jwala Singh-1 | H113: 45.697022 | I113: 4.2575184 | J113: Aman Singh | K113: Completed
A114: =A113+1 -> 110 | B114: 6 | C114: 32/2 | D114: DA+9 | E114: 45856 | F114: 45864 | G114: Amit Kumar Singh | H114: 45.697022 | I114: 4.2575184 | J114: Suraj Kumar | K114: Completed
...

Sheet Stringing Compiled
A1: Number of TSE | D1: 37
A2: Number of Manual | D2: 23
A3: S.no | B3: From AP | C3: To AP | D3: Span (M) | E3: Method | F3: No. of Locations for end twr) | G3: Section Readiness | H3: P/O Starting Date | I3: P/O Completion Date | J3: P/O | K3: F/S Starting Date | L3: F/S/ Completion Date | M3: Length | N3: Status | O3: Gang Name | P3: Hindrance | Q3: Remarks
A4: 1 | B4: 34/0 | C4: 35/0 | D4: 4898.588 | E4: TSE | F4: 13 | G4: Ready | H4: 45709 | I4: 45714 | J4: =D4 -> 4898.588 | K4: =I4+1 -> 45715 | L4: 45720 | M4: =D4 -> 4898.588 | N4: Completed | O4: SK Infratech
A5: =A4+1 -> 2 | B5: 37A/0 | C5: 38/0 | D5: 2583.589 | E5: TSE | F5: 7 | G5: Ready | H5: 45733 | I5: 45736 | J5: =D5 -> 2583.589 | K5: =I5+1 -> 45737 | L5: 45763 | M5: =D5 -> 2583.589 | N5: Completed | O5: SK Infratech
A6: =A5+1 -> 3 | B6: 38/0 | C6: 39/0 | D6: 4163.677 | E6: TSE | F6: 11 | G6: Ready | H6: 45745 | I6: 45752 | J6: =D6 -> 4163.677 | K6: =I6+1 -> 45753 | L6: 45763 | M6: =D6 -> 4163.677 | N6: Completed | O6: SK Infratech
A7: =A6+1 -> 4 | B7: =C6 -> 39/0 | C7: 40/0 | D7: 4716.811 | E7: TSE | F7: 12 | G7: Ready | H7: 45772 | I7: 45776 | J7: =D7 -> 4716.811 | K7: =I7+1 -> 45777 | L7: 45777 | M7: =D7 -> 4716.811 | N7: Completed | O7: SK Infratech
A8: =A7+1 -> 5 | B8: 7/0 | C8: 7A/0 | D8: 2699.284 | E8: TSE | F8: 7 | G8: Ready | H8: 45896 | I8: 45904 | J8: =D8 -> 2699.284 | K8: =I8+1 -> 45905 | L8: 45918 | M8: =D8 -> 2699.284 | N8: Completed | O8: Rahim Khan
A9: =A8+1 -> 6 | B9: =C8 -> 7A/0 | C9: 8/0 | D9: 2434.77 | E9: TSE | F9: 6 | G9: Ready | H9: 45912 | I9: 45916 | J9: =D9 -> 2434.77 | K9: =I9+1 -> 45917 | L9: 45925 | M9: =D9 -> 2434.77 | N9: Completed | O9: Rahim Khan
A10: =A9+1 -> 7 | B10: =C9 -> 8/0 | C10: 8A/0 | D10: 4455 | E10: TSE | F10: 12 | G10: Ready | H10: 45935 | I10: 45945 | J10: =D10 -> 4455 | K10: =I10+1 -> 45946 | L10: 45952 | M10: =D10 -> 4455 | N10: Completed | O10: Rahim Khan
A11: =A10+1 -> 8 | B11: =C10 -> 8A/0 | C11: 9/0 | D11: 466.629 | E11: Manual | F11: 1 | G11: Ready | H11: 45933 | I11: 45935 | J11: =D11 -> 466.629 | K11: =I11+1 -> 45936 | L11: 45957 | M11: =D11 -> 466.629 | N11: Completed | O11: Rahim Khan
A12: =A11+1 -> 9 | B12: 5/0 | C12: 5A/0 | D12: 4418.389 | E12: TSE | F12: 11 | G12: Ready | J12: =D12 -> 4418.389 | N12: WIP | Q12: Insulator Hoisting wip - 5/10
A13: =A12+1 -> 10 | B13: 5A/0 | C13: 6/0 | D13: 419.48 | E13: Manual | F13: 1 | G13: Ready | H13: 45966 | I13: 45970 | J13: =D13 -> 419.48 | N13: WIP | O13: Rahim Khan | Q13: Rough sag completed
A14: =A13+1 -> 11 | B14: 6/0 | C14: 7/0 | D14: 4901.236 | E14: TSE | F14: 13 | G14: Ready | H14: 45980 | I14: 45984 | J14: =D14 -> 4901.236 | K14: 45985 | N14: WIP | O14: Rahim Khan | Q14: All phase Conductor paying out & Rough sag completed
A15: =A14+1 -> 12 | B15: 32/0 | C15: 32A/0 | D15: 3283.51 | E15: TSE | F15: 8 | G15: Ready | J15: =D15 -> 3283.51 | N15: WIP | O15: Tanjira Bibi | Q15: Loc NO Insulator Hoisting pending 32/0,32/1,32/2
A16: =A15+1 -> 13 | B16: 32A/0 | C16: 33/0 | D16: 840.439 | E16: TSE | F16: 2 | G16: Ready | J16: =D16 -> 840.439 | N16: WIP | O16: Tanjira Bibi | Q16: Loc no 32A/1 Insulator hoisting pending due to ROW
A17: =A16+1 -> 14 | B17: 33/0 | C17: 34/0 | D17: 4049.764 | E17: TSE | F17: 10 | G17: Ready | J17: =D17 -> 4049.764 | N17: WIP | O17: Tanjira Bibi | Q17: Loc no 33/5 Insulator hoisting pending ROW
A18: =A17+1 -> 15 | B18: GY | C18: 1/0 | D18: 150.014 | E18: Manual | F18: 1 | G18: Not Ready | J18: =D18 -> 150.014
A19: =A18+1 -> 16 | B19: 1/0 | C19: 2A/0 | D19: 290.21 | E19: Manual | F19: 1 | G19: Not Ready | J19: =D19 -> 290.21
A20: =A19+1 -> 17 | B20: 2A/0 | C20: 3A/0 | D20: 2836.992 | E20: TSE | F20: 7 | G20: Ready | J20: =D20 -> 2836.992
A21: =A20+1 -> 18 | B21: 3A/0 | C21: 3B/0 | D21: 2691.467 | E21: TSE | F21: 7 | G21: Ready | J21: =D21 -> 2691.467
A22: =A21+1 -> 19 | B22: 3B/0 | C22: 4/0 | D22: 1627.07 | E22: TSE | F22: 4 | G22: Ready | J22: =D22 -> 1627.07
A23: =A22+1 -> 20 | B23: 4/0 | C23: 4A/0 | D23: 709.163 | E23: TSE | F23: 2 | G23: Ready | J23: =D23 -> 709.163
A24: =A23+1 -> 21 | B24: 4A/0 | C24: 5/0 | D24: 2681.611 | E24: TSE | F24: 7 | G24: Ready | J24: =D24 -> 2681.611
A25: =A24+1 -> 22 | B25: 9/0 | C25: 10/0 | D25: 4964.92 | E25: TSE | F25: 12 | G25: Not Ready | J25: =D25 -> 4964.92
A26: =A25+1 -> 23 | B26: 10/0 | C26: 11/0 | D26: 1004.183 | E26: TSE | F26: 3 | G26: Not Ready | J26: =D26 -> 1004.183
A27: =A26+1 -> 24 | B27: 11/0 | C27: 12/0 | D27: 242.893 | E27: Manual | F27: 1 | G27: Not Ready | J27: =D27 -> 242.893
A28: =A27+1 -> 25 | B28: 12/0 | C28: 13/0 | D28: 329.728 | E28: Manual | F28: 1 | G28: Not Ready | J28: =D28 -> 329.728
A29: =A28+1 -> 26 | B29: 13/0 | C29: 13A/0 | D29: 416.878 | E29: Manual | F29: 1 | G29: Not Ready | J29: =D29 -> 416.878
... A58: =A57+1 -> 55 | B58: 42/0 | C58: 42/3 | D58: 1258.998 | E58: TSE | F58: 3 | G58: Ready | J58: =D58 -> 1258.998
A59: =A58+1 -> 56 | B59: =C58 -> 42/3 | C59: 43/0 | D59: 424.891 | E59: Manual | F59: 1 | G59: Not Ready | J59: =D59 -> 424.891
A60: =A59+1 -> 57 | B60: =C59 -> 43/0 | C60: 43/5 | D60: 1851.866 | E60: TSE | F60: 5 | G60: Not Ready | J60: =D60 -> 1851.866
A61: =A60+1 -> 58 | B61: =C60 -> 43/5 | C61: 44/0 | D61: 1584.546 | E61: TSE | F61: 4 | G61: Not Ready | J61: =D61 -> 1584.546
A62: =A61+1 -> 59 | B62: =C61 -> 44/0 | C62: 45/0 | D62: 2383.155 | E62: TSE | F62: 6 | G62: Ready | J62: =D62 -> 2383.155
A63: =A62+1 -> 60 | B63: =C62 -> 45/0 | C63: 46/0 | D63: 208.53 | E63: Manual | F63: 1 | G63: Ready | J63: =D63 -> 208.53
D64: =SUM(D4:D63) -> 117850.83 | F64: =SUM(F4:F63) -> 306

Sheet Project Details
A1: Project Code | B1: Project Name | C1: Client Name | D1: NOA Start Date | E1: LOA End Date | F1: Planning Engineer | G1: PCH | H1: Regional Manager | I1: Project Manger | J1: Section Incharge | K1: Engineer/Supervisor
A2: TA 413 | B2: 765kv D/C Bikaner II to Neemrana II TL-02 | C2: PGCIL | D2: 45363 | E2: 46002 | F2: Mr. Santosh Mishra | G2: Mr. Sanjay Gupta | H2: Mr. Tushar Grover | I2: Mr. Anil Kumar Sharma | J2: Surendra Kumar Patel | K2: Rudra Prasad
J3: Kartik Jhorar | K3: Aman Kumar Singh
J4: Shuvam Gupta | K4: Manoj Gupta
J5: Govind Bhardwaj | K5: Raju Mahto
K6: Khublal Mahto
K7: Sushil Kumar
K8: Haridashn
K9: Manoj Kumar chaudhary
K10: Nabirul Islam
K11: Sanjay Kumar
K12: Rahul Ravidas
K13: Narayan Mahto
K14: Kamal Ravidas
K15: Manirul Islam
K16: Tarique Anwar
K17: Raju Prasad
K18: Abhay Ojha

Sheet Location Summary
A1: Over all Tower Location details
A2: S. No. | B2: No of | C2: Location | D2: Type of | F2: RC | H2: Span | I2: Cumm. | J2: DS Status as on | K2: =COUNTIFS(K4:K616,K140) -> 306 | L2: =COUNTIFS(L4:L616,L140) -> 298 | M2: =COUNTIFS(M4:M617,M322) -> 270 | N2: =COUNTIFS(N4:N602,N322) -> 107 | O2: =SUBTOTAL(3,O4:O604) -> 26 | P2: Remarks
B3: AP | C3: Tower No. | D3: Tower | H3: Length (m) | I3: Span (km) | J3: 45962 | K3: Foundation | L3: Earthing | M3: Tower Erection | N3: Tack welding | O3: SPT
A4: 0 | C4: Gantry | D4: Gantry | I4: 0
G5: =C4 -> Gantry | H5: 150.014
A6: =SUBTOTAL(103,$C$4:C8) -> 3 | B6: AP-1 | C6: 1/0 | D6: DD60+0 | E6: T | I6: =ROUND(H5/1000,4) -> 0.15 | J6: Approved | K6: Completed | L6: Completed | M6: Completed
G7: =C6 -> 1/0 | H7: 290.21
A8: =SUBTOTAL(103,$C$6:C8) -> 2 | B8: AP-2A | C8: 2A/0 | D8: DD45+0 | E8: T | I8: =ROUND(H7/1000,4)+I6 -> 0.4402 | J8: Approved | K8: Completed | L8: Completed
G9: =C8 -> 2A/0 | H9: 378
A10: =SUBTOTAL(103,$C$5:C11) -> 3 | B10: AP-3 | C10: 2A/1 | D10: DA+0 | I10: =ROUND(H9/1000,4)+I8 -> 0.8182 | J10: Approved | K10: Completed | L10: Completed | M10: Completed
G11: =C10 -> 2A/1 | H11: 381
A12: =SUBTOTAL(103,$C$6:C12) -> 4 | C12: 2A/2 | D12: DA+3 | I12: =ROUND(H11/1000,4)+I10 -> 1.1992 | J12: Approved | K12: Completed | L12: Completed | M12: Completed
G13: =C12 -> 2A/2 | H13: 419
A14: =SUBTOTAL(103,$C$6:C14) -> 5 | C14: 2A/3 | D14: DA+3 | I14: =ROUND(H13/1000,4)+I12 -> 1.6182 | J14: Approved | K14: Completed | L14: Completed | M14: Completed
G15: =C14 -> 2A/3 | H15: 422
A16: =SUBTOTAL(103,$C$6:C16) -> 6 | C16: 2A/4 | D16: DA+3 | I16: =ROUND(H15/1000,4)+I14 -> 2.0402 | J16: Approved | K16: Completed | L16: Completed | M16: Completed
G17: =C16 -> 2A/4 | H17: 399
A18: =SUBTOTAL(103,$C$6:C18) -> 7 | C18: 2A/5 | D18: DA+3 | I18: =ROUND(H17/1000,4)+I16 -> 2.4392 | J18: Approved | K18: Completed | L18: Completed | M18: Completed
G19: =C18 -> 2A/5 | H19: 423
A20: =SUBTOTAL(103,$C$6:C20) -> 8 | C20: 2A/6 | D20: DA+6 | I20: =ROUND(H19/1000,4)+I18 -> 2.8622 | J20: Approved | K20: Completed | L20: Completed | M20: Completed
G21: =C20 -> 2A/6 | H21: 414.992
A22: =SUBTOTAL(103,$C$6:C22) -> 9 | C22: 3A/0 | D22: DD45+3 | E22: T | I22: =ROUND(H21/1000,4)+I20 -> 3.2772 | J22: Approved | K22: Completed | L22: Completed | M22: Completed
G23: =C22 -> 3A/0 | H23: 409
A24: =SUBTOTAL(103,$C$6:C24) -> 10 | C24: 3A/1 | D24: DA+3 | I24: =ROUND(H23/1000,4)+I22 -> 3.6862 | J24: Approved | K24: Completed | L24: Completed | M24: Completed
G25: =C24 -> 3A/1 | H25: 402
A26: =SUBTOTAL(103,$C$6:C26) -> 11 | C26: 3A/2 | D26: DA+3 | I26: =ROUND(H25/1000,4)+I24 -> 4.0882 | J26: Approved | K26: Completed | L26: Completed | M26: Completed
G27: =C26 -> 3A/2 | H27: 409
A28: =SUBTOTAL(103,$C$6:C28) -> 12 | C28: 3A/3 | D28: DA+0 | I28: =ROUND(H27/1000,4)+I26 -> 4.4972 | J28: Approved | K28: Completed | L28: Completed | M28: Completed | O28: Completed | U28: =280-6 -> 274
G29: =C28 -> 3A/3 | H29: 337
A30: =SUBTOTAL(103,$C$6:C30) -> 13 | C30: 3A/4 | D30: DA+0 | I30: =ROUND(H29/1000,4)+I28 -> 4.8342 | J30: Approved | K30: Completed | L30: Completed | M30: Completed
G31: =C30 -> 3A/4 | H31: 365
A32: =SUBTOTAL(103,$C$6:C32) -> 14 | C32: 3A/5 | D32: DA+3 | I32: =ROUND(H31/1000,4)+I30 -> 5.1992 | J32: Approved | K32: Completed | L32: Completed | M32: Completed
G33: =C32 -> 3A/5 | H33: 378
A34: =SUBTOTAL(103,$C$6:C34) -> 15 | B34: AP-4 | C34: 3A/6 | D34: DA+0 | I34: =ROUND(H33/1000,4)+I32 -> 5.5772 | J34: Approved | K34: Completed | L34: Completed | M34: Completed
G35: =C34 -> 3A/6 | H35: 391.467
A36: =SUBTOTAL(103,$C$6:C36) -> 16 | C36: 3B/0 | D36: DB1+9 | I36: =ROUND(H35/1000,4)+I34 -> 5.9687 | J36: Approved | K36: Completed | L36: Completed | M36: Completed
G37: =C36 -> 3B/0 | H37: 356
A38: =SUBTOTAL(103,$C$6:C38) -> 17 | C38: 3B/1 | D38: DA+3 | I38: =ROUND(H37/1000,4)+I36 -> 6.3247 | J38: Approved | K38: Completed | L38: Completed | M38: Completed
G39: =C38 -> 3B/1 | H39: 439
A40: =SUBTOTAL(103,$C$6:C40) -> 18 | C40: 3B/2 | D40: DA+9 | I40: =ROUND(H39/1000,4)+I38 -> 6.7637 | J40: Approved | K40: Completed | L40: Completed | M40: Completed
...
