Workbook
Name \A: #REF!
Name \A: #REF!
Name \aa: #REF!
Name \aa: #REF!
Name \B: #REF!
Name \B: #REF!
Name \C: #REF!
Name \C: #REF!
Name \DFC: #REF!
Name \DFC: #REF!
Name \E: #REF!
Name \E: #REF!
Name \H: #REF!
Name \H: #REF!
Name \jmns: #REF!
Name \jmns: #REF!
Name \L: #REF!
Name \L: #REF!
Name \LK: #REF!
Name \LK: #REF!
Name \LKM: #REF!
Name \LKM: #REF!
Name \M: #REF!
Name \M: #REF!
Name \N: #REF!
Name \N: #REF!
Name \P: #REF!
Name \P: #REF!
Name \Q: #REF!
Name \Q: #REF!
Name \R: #REF!
Name \R: #REF!
Name \S: #REF!
Name \S: #REF!
Name \Sv: #REF!
Name \Sv: #REF!
Name \U: #REF!
Name \U: #REF!
Name \V: #REF!
Name \V: #REF!
Name \x: #REF!
Name \x: #REF!
Name \z: #REF!
Name \z: #REF!
Name _: #REF!
Name _: #REF!
Name _______xlnm.Print_Titles_2: ('[1]OPGW Quantity summary'!$A$1:$C$65536,'[1]OPGW Quantity summary'!$A$1:$IV$8)
Name _______xlnm.Print_Titles_3: (#REF!,#REF!)
Name _______xlnm.Print_Titles_3: (#REF!,#REF!)
Name ______xlnm.Print_Titles_2: ('[1]OPGW Quantity summary'!$A$1:$C$65536,'[1]OPGW Quantity summary'!$A$1:$IV$8)
Name ______xlnm.Print_Titles_3: (#REF!,#REF!)
Name ______xlnm.Print_Titles_3: (#REF!,#REF!)
Name _____xlnm.Print_Titles_2: ('[1]OPGW Quantity summary'!$A$1:$C$65536,'[1]OPGW Quantity summary'!$A$1:$IV$8)
Name _____xlnm.Print_Titles_3: (#REF!,#REF!)
Name _____xlnm.Print_Titles_3: (#REF!,#REF!)
Name ____a1: #REF!
Name ____a1: #REF!
Name ____Ki1: #REF!
Name ____Ki1: #REF!
Name ____Ki2: #REF!

Sheet 765KV TA 414 VNTL
B1: Project Code | C1: TA 414 | D1: Date | F1: =TODAY()-1 -> 46029 | H1: President-T&D | I1: Mr. Ganesh Srinivasan
B2: Project Name | C2: 765KV D/C HEXA VATAMAN - NAVSARI TL (PKG 04) | F2: NOA Start Date | G2: 45363 | H2: PCH | I2: Mr. Arun Felbin
B3: Client Name | C3: Powergrid Vataman Transmission Ltd | F3: LOA End Date | G3: 46002 | H3: Regional Manager | I3: Mr. Nitin Bandale
B4: Revised End Date | C4: 46153 | F4: Planning Engineer | G4: Nishant Giri | H4: Project Manger | I4: Mr. Vivek Kumar Gupta
A5: \
A6: Check Survey
A7: Activity | B7: Unit | C7: Final Est. Qty | D7: L2 till Last Month | E7: Submitted till Last Month | F7: Approved till Last Month | G7: Balance to Submit | H7: Balance to Approve | I7: L2 Submission Plan for Current Month | J7: Progress For Month | K7: Approved till Current Month | L7: Remarks
A8: Rout Alignment | B8: km | C8: 127.854 | D8: =C8 -> 127.854 | E8: =D8 -> 127.854 | F8: =E8 -> 127.854 | K8: =F8+J8 -> 127.854 | L8: Completed
A9: Detailed Survey | B9: km | C9: =C8 -> 127.854 | D9: =C9 -> 127.854 | E9: =D9 -> 127.854 | F9: =E9 -> 127.854 | K9: =E9+J9 -> 127.854 | L9: Completed
A10: Check Survey | B10: km | C10: =C9 -> 127.854 | D10: =C10 -> 127.854 | E10: =D10 -> 127.854 | F10: =E10 -> 127.854 | K10: =E10+J10 -> 127.854 | L10: Completed
A12: Progress Status
A13: Activity | B13: Final Estimated Quantity | C13: Cumulative L2 till Last Month (Dec'25) | D13: Cumulative Progress till Last Month(Dec'25) | E13: L2 for present Month | F13: Plan for the Month | G13: Today's Progress | H13: Progress till Date for the Month | I13: L2 till Current Month | J13: Completed till Date | K13: Balance Work | L13: Under Progress | M13: Gangs at Present | N13: Remarks
A14: Soil Investigation | B14: 28 | D14: =C14 -> 0 | E14: 0 | F14: 0 | I14: =C14+E14 -> 0 | J14: =D14+H14 -> 0 | K14: =B14-J14 -> 28 | N14: Completed.
A15: Foundation | B15: 351 | C15: 340 | D15: 181 | E15: 0 | F15: 100 | G15: ='VNTL - KEC'!G11 -> 1 | H15: ='VNTL - KEC'!H11 -> 8 | I15: =C15+E15 -> 340 | J15: =D15+H15 -> 189 | K15: =B15-J15 -> 162 | L15: ='VNTL - KEC'!K11 -> 26 | M15: ='VNTL - KEC'!L11 -> 25
A16: Earthing | B16: 351 | C16: 340 | D16: 155 | E16: 0 | F16: 100 | I16: =C16+E16 -> 340 | J16: =D16+H16 -> 155 | K16: =B16-J16 -> 196
A17: Tower Erection | B17: 351 | C17: 340 | D17: 28 | E17: 0 | F17: 60 | G17: ='VNTL - KEC'!G14 -> 0 | H17: ='VNTL - KEC'!H14 -> 8 | I17: =C17+E17 -> 340 | J17: =D17+H17 -> 36 | K17: =B17-J17 -> 315 | L17: ='VNTL - KEC'!K14 -> 18 | M17: ='VNTL - KEC'!L14 -> 18
A18: Tack welding | B18: 351 | C18: 340 | E18: 0 | F18: 30 | I18: =C18+E18 -> 340 | J18: =D18+H18 -> 0 | K18: =B18-J18 -> 351
A19: Stringing(Km) | B19: 127.854 | C19: 130 | E19: 0 | F19: 5.7 | I19: =C19+E19 -> 130 | J19: =D19+H19 -> 0 | K19: =B19-J19 -> 127.854

Sheet Project Details
A1: Project Code | B1: Project Name | C1: Client Name | D1: NOA Start Date | E1: LOA End Date | F1: Planning Engineer | G1: PCH | H1: Regional Manager | I1: Project Manager | J1: Section Incharge | K1: Supervisor
A2: TA 414 | B2: 765kV D/C VATAMAN NAVSARI TL04 | C2: Powergrid Vataman Transmission Limited | D2: 45363 | E2: 46002 | F2: Mr. Nishant Giri | G2: Mr Arun Felbin | H2: Mr. Nitin Ashok Bendale | I2: Mr Vivek Kumar Gupta | J2: Mr. Vivekanand Bera | K2: Mr. Noton Ghosh
J3: Mr. Vipin Chandra Deshmukh | K3: Mr. Kalicharan Patel
K4: Mr. Ishwar Mahto
K5: Mr. Raju Mahto
K6: Mr. Shankar Mahto
K7: Mr. Daulat Mahto
K8: Mr. Atul kumar
K9: Mr. Himanshu Behera
K10: Mr. Shubendhu Kumar Sahoo
K11: Mr. Hareshkumar Hirabhai Patel

Sheet VNTL - KEC
A1: KEC INTERNATIONAL LIMITED | M1: =TODAY()-1 -> 46029
A2: Name of Client: Powergrid Vataman Transmission Limited
A3: Name of Line:Tl-04 , 765 kV D/C Vataman - Navsari Transmission Line
A4: NOA Ref. No.: CC/T/W/-TW/DOM/A06/23/05757/NOA-2/24-103439/02, Dt.12.03.24
A5: Sr No. | B5: Activity | C5: Estimated Quantity | D5: Cumm. Progress up to till last Month (DEC'25) | E5: Target as per L2 Schedule Cummulative (upto Jan'26) | F5: L3 Plan for the month (Jan'26 ) | G5: Today's Progress | H5: Progress in this month | I5: Cumm. Progress till date | J5: Cumm. Balance | K5: WIP | L5: No of Gangs | M5: Remark
A6: 1 | B6: Route Alignment (Km) | C6: 127.83 | D6: 127.83 | E6: 130 | I6: =D6+H6 -> 127.83 | J6: =C6-I6 -> 0
A7: 2 | B7: Detailed Survey (Km) | C7: 127.85407 | D7: =C7 -> 127.85407 | E7: 130 | I7: =D7+H7 -> 127.85407 | J7: =C7-I7 -> 0
A8: 3 | B8: Profiling (Km) | C8: 127.85407 | D8: =C8 -> 127.85407 | E8: 130 | I8: =D8+H8 -> 127.85407 | J8: =C8-I8 -> 0
A9: 4 | B9: Check Survey (Km) | C9: 127.85407 | D9: =D8 -> 127.85407 | E9: 130 | I9: =D9+H9 -> 127.85407 | J9: =C9-I9 -> 0
A10: 5 | B10: Soil Investigation (Nos.) | C10: 28 | D10: 28 | I10: =D10+H10 -> 28 | J10: =C10-I10 -> 0
A11: 6 | B11: Excavation | C11: 351 | D11: 181 | E11: 340 | F11: 100 | G11: 1 | H11: 8 | I11: =D11+H11 -> 189 | J11: =C11-I11 -> 162 | K11: 26 | L11: 25
A12: 7 | B12: Foundation (Nos.) | C12: 351 | D12: 181 | E12: 340 | F12: 100 | G12: 1 | H12: 8 | I12: =D12+H12 -> 189 | J12: =C12-I12 -> 162 | K12: 26 | L12: 25
A13: 8 | B13: Earthing (Nos.) | C13: 351 | D13: 155 | E13: 340 | F13: 100 | G13: 0 | H13: 1 | I13: =D13+H13 -> 156 | J13: =C13-I13 -> 195
A14: 9 | B14: Tower Erection (Nos) | C14: 351 | D14: 28 | E14: 340 | F14: 60 | G14: 0 | H14: 8 | I14: =D14+H14 -> 36 | J14: =C14-I14 -> 315 | K14: 18 | L14: 18
A15: 10 | B15: Tack Welding | C15: 351 | D15: 0 | E15: 340 | I15: =D15+H15 -> 0 | J15: =C15-I15 -> 351
A16: 11 | B16: Stringing (Km) | C16: 127.85407 | E16: 130 | F16: 5.7 | I16: =D16+H16 -> 0 | J16: =C16-I16 -> 127.85407
A17: a) | B17: Paying Out | C17: 127.85407 | E17: 130 | I17: =D17+H17 -> 0 | J17: =C17-I17 -> 127.85407
A18: b) | B18: Final Sag | C18: 127.85407 | E18: 130 | I18: =D18+H18 -> 0 | J18: =C18-I18 -> 127.85407
A19: 12 | B19: OPGW (Km) | C19: 127.85407 | E19: 130 | I19: =D19+H19 -> 0 | J19: =C19-I19 -> 127.85407

Sheet DPR Sheet
B2: KEC INTERNATIONAL LIMITED
B3: DAILY PROGRESS REPORT : SUBMISSION STATUS AS ON | G3: =+'VNTL - KEC'!M1 -> 46029
B4: Name of the Project: | D4: Tl-04 , 765 kV D/C Vataman - Navsari Transmission Line
B5: Contract No. & Date : | D5: CC/T/W/-TW/DOM/A06/23/05757/NOA-2/24-103439/02, Dt.12.03.24
B7: ROUTE ALIGNMENT PROGRESS SUMMARY
B8: TOTAL QTY (Tentative) | C8: COMPLETED UP TO PREV MONTH | D8: COMP. IN CURRENT MONTH | E8: CUMULATIVE | F8: BAL.QTY
B9: ='VNTL - KEC'!C7 -> 127.85407 | C9: ='VNTL - KEC'!D6 -> 127.83 | D9: ='VNTL - KEC'!F6 -> 0 | E9: ='VNTL - KEC'!I6 -> 127.83 | F9: ='VNTL - KEC'!J6 -> 0
B10: SOIL INVESTIGATION PROGRESS SUMMARY
B11: TOTAL QTY (Tentative) | C11: COMPLETED UP TO PREV MONTH | D11: COMP. IN CURRENT MONTH | E11: CUMULATIVE | F11: BAL.QTY
B12: ='VNTL - KEC'!C10 -> 28 | C12: ='VNTL - KEC'!D10 -> 28 | D12: ='VNTL - KEC'!H10 -> 0 | E12: ='VNTL - KEC'!I10 -> 28 | F12: ='VNTL - KEC'!J10 -> 0
B13: DETAILED SURVEY PROGRESS SUMMARY
B14: TOTAL QTY (Tentative) | C14: COMPLETED UP TO PREV MONTH | D14: COMP. IN CURRENT MONTH | E14: CUMULATIVE | F14: BAL.QTY
B15: ='VNTL - KEC'!C7 -> 127.85407 | C15: ='VNTL - KEC'!D7 -> 127.85407 | D15: ='VNTL - KEC'!H7 -> 0 | E15: ='VNTL - KEC'!I7 -> 127.85407 | F15: ='VNTL - KEC'!J7 -> 0
B16: CHECK SURVEY PROGRESS SUMMARY
B17: TOTAL QTY (Tentative) | C17: COMPLETED UP TO PREV MONTH | D17: COMP. IN CURRENT MONTH | E17: CUMULATIVE | F17: BAL.QTY
B18: ='VNTL - KEC'!C9 -> 127.85407 | C18: ='VNTL - KEC'!D9 -> 127.85407 | D18: ='VNTL - KEC'!H9 -> 0 | E18: ='VNTL - KEC'!I9 -> 127.85407 | F18: ='VNTL - KEC'!J9 -> 0
B19: FOUNDATION PROGRESS SUMMARY
B20: TOTAL QTY (Tentative) | C20: COMPLETED UP TO PREV MONTH | D20: COMP. IN CURRENT MONTH | E20: CUMULATIVE | F20: BAL.QTY
B21: ='VNTL - KEC'!C12 -> 351 | C21: ='VNTL - KEC'!D12 -> 181 | D21: ='VNTL - KEC'!H12 -> 8 | E21: ='VNTL - KEC'!I12 -> 189 | F21: ='VNTL - KEC'!J12 -> 162
B22: EARTHING PROGRESS SUMMARY
B23: TOTAL QTY | C23: COMPLETED UP TO PREV MONTH | D23: COMP. IN CURRENT MONTH | E23: CUMULATIVE | F23: BAL.QTY
B24: ='VNTL - KEC'!C13 -> 351 | C24: ='VNTL - KEC'!D13 -> 155 | D24: ='VNTL - KEC'!H13 -> 1 | E24: ='VNTL - KEC'!I13 -> 156 | F24: ='VNTL - KEC'!J13 -> 195
B25: TOWER ERECTION PROGRESS SUMMARY
B26: TOTAL QTY | C26: COMPLETED UP TO PREV MONTH | D26: COMP. IN CURRENT MONTH | E26: CUMULATIVE | F26: BAL.QTY
B27: ='VNTL - KEC'!C14 -> 351 | C27: ='VNTL - KEC'!D14 -> 28 | D27: ='VNTL - KEC'!H14 -> 8 | E27: ='VNTL - KEC'!I14 -> 36 | F27: ='VNTL - KEC'!J14 -> 315
B28: STRINGING PROGRESS SUMMARY
B29: TOTAL QTY | C29: COMPLETED UP TO PREV MONTH | D29: COMP. IN CURRENT MONTH | E29: CUMULATIVE | F29: BAL.QTY(KM)
B30: ='VNTL - KEC'!C16 -> 127.85407 | C30: 0 | D30: 0 | E30: 0 | F30: =B30-E30 -> 127.85407
B31: OPGW STRINGING PROGRESS SUMMARY
B32: TOTAL QTY | C32: COMPLETED UP TO PREV MONTH | D32: COMP. IN CURRENT MONTH | E32: CUMULATIVE | F32: BAL.QTY
B33: ='VNTL - KEC'!C18 -> 127.85407 | C33: 0 | D33: 0 | E33: 0 | F33: =B33-E33 -> 127.85407

Sheet FDN
A1: VNTL Foundation
A2: Sl. No. | B2: Location No. | C2: Tower Type | D2: Classification | E2: Concreting Volume in M3 | F2: Starting Date | G2: Todays Status | H2: Cumulative Status | I2: Completion Date | J2: Remarks | K2: Gang name | L2: Earthing Status | M2: Earthing Completion Date
A3: 1 | B3: 241/2 | C3: =VLOOKUP(B3,Sheet4!$A:$B,2,FALSE) -> DA+0 | D3: Wet | F3: 45427 | H3: Completed | I3: 45437 | K3: Suraj Construction | L3: Completed | M3: =I3+1 -> 45438
A4: =A3+1 -> 2 | B4: 241/0 | C4: =VLOOKUP(B4,Sheet4!$A:$B,2,FALSE) -> DD60+0 | D4: Wet Paddy | F4: 45433 | H4: Completed | I4: 45442 | K4: Suraj Construction | L4: Completed | M4: =I4+1 -> 45443
A5: =A4+1 -> 3 | B5: 118/0 | C5: =VLOOKUP(B5,Sheet4!$A:$B,2,FALSE) -> DB2+0 | D5: Wet | F5: 45555 | H5: Completed | I5: 45596 | K5: Anya Infra
A6: =A5+1 -> 4 | B6: 120/3 | C6: =VLOOKUP(B6,Sheet4!$A:$B,2,FALSE) -> DA+6 | D6: Wet Paddy | F6: 45600 | H6: Completed | I6: 45608 | K6: Anya Infra
A7: =A6+1 -> 5 | B7: 121/5 | C7: =VLOOKUP(B7,Sheet4!$A:$B,2,FALSE) -> DA-3 | D7: Wet | F7: 45598 | H7: Completed | I7: 45615 | K7: Adhyey Brothers
A8: =A7+1 -> 6 | B8: 120/2 | C8: =VLOOKUP(B8,Sheet4!$A:$B,2,FALSE) -> DA+0 | D8: wet | F8: 45605 | H8: Completed | I8: 45618 | K8: Anya Infra
A9: =A8+1 -> 7 | B9: 121/4 | C9: =VLOOKUP(B9,Sheet4!$A:$B,2,FALSE) -> DA+0 | D9: Wet | F9: 45615 | H9: Completed | I9: 45625 | K9: Adhyey Brothers
A10: =A9+1 -> 8 | B10: 121/2 | C10: =VLOOKUP(B10,Sheet4!$A:$B,2,FALSE) -> DA+9 | D10: Wet | F10: 45627 | H10: Completed | I10: 45633 | K10: Adhyey Brothers
A11: =A10+1 -> 9 | B11: 119/0 | C11: =VLOOKUP(B11,Sheet4!$A:$B,2,FALSE) -> DD60+0 | D11: Wet | F11: 45629 | H11: Completed | I11: 45642 | K11: Himanshi Agency | L11: Completed | M11: =I11+1 -> 45643
A12: =A11+1 -> 10 | B12: 121/3 | C12: =VLOOKUP(B12,Sheet4!$A:$B,2,FALSE) -> DA+0 | D12: Wet | F12: 45635 | H12: Completed | I12: 45647 | K12: Adhya Enterprises
A13: =A12+1 -> 11 | B13: 120/5 | C13: =VLOOKUP(B13,Sheet4!$A:$B,2,FALSE) -> DA-3 | D13: Wet | F13: 45626 | H13: Completed | I13: 45648 | K13: APR Associates
A14: =A13+1 -> 12 | B14: 120/0 | C14: =VLOOKUP(B14,Sheet4!$A:$B,2,FALSE) -> DD60+3 | D14: Wet | F14: 45634 | H14: Completed | I14: 45648 | K14: Himanshi Agency
A15: =A14+1 -> 13 | B15: 244/6 | C15: =VLOOKUP(B15,Sheet4!$A:$B,2,FALSE) -> DA+3 | D15: Wet | F15: 45639 | H15: Completed | I15: 45649 | K15: Unnati Construction | L15: Completed | M15: =I15+1 -> 45650
A16: =A15+1 -> 14 | B16: 145/4 | C16: =VLOOKUP(B16,Sheet4!$A:$B,2,FALSE) -> DA+0 | D16: Wet | F16: 45637 | H16: Completed | I16: 45653 | K16: Integer Infratech Pvt Ltd
A17: =A16+1 -> 15 | B17: 249/1 | C17: =VLOOKUP(B17,Sheet4!$A:$B,2,FALSE) -> DA+9 | D17: Wet Paddy | F17: 45645 | H17: Completed | I17: 45653 | K17: Neelkant Infra Project | L17: Completed | M17: =I17+1 -> 45654
A18: =A17+1 -> 16 | B18: 119/2 | C18: =VLOOKUP(B18,Sheet4!$A:$B,2,FALSE) -> DA-3 | D18: Wet Paddy | F18: 45637 | H18: Completed | I18: 45654 | K18: Himanshi Agency | L18: Completed | M18: =I18+1 -> 45655
A19: =A18+1 -> 17 | B19: 119/3 | C19: =VLOOKUP(B19,Sheet4!$A:$B,2,FALSE) -> DA+9 | D19: Wet | F19: 45647 | H19: Completed | I19: 45656 | K19: Himanshi Agency | L19: Completed | M19: =I19+1 -> 45657
A20: =A19+1 -> 18 | B20: 121/6 | C20: =VLOOKUP(B20,Sheet4!$A:$B,2,FALSE) -> DA+0 | D20: Wet | F20: 45643 | H20: Completed | I20: 45657 | K20: Arya Enterprises | L20: Completed | M20: =I20+1 -> 45658
A21: =A20+1 -> 19 | B21: 249/0 | C21: =VLOOKUP(B21,Sheet4!$A:$B,2,FALSE) -> DD60+3 | D21: Wet Paddy | F21: 45652 | H21: Completed | I21: 45659 | K21: Unnati Construction | L21: Completed | M21: =I21+1 -> 45660
A22: =A21+1 -> 20 | B22: 249/2 | C22: =VLOOKUP(B22,Sheet4!$A:$B,2,FALSE) -> DA+3 | D22: Wet | F22: 45654 | H22: Completed | I22: 45660 | K22: Neelkant Infra Project | L22: Completed | M22: =I22+1 -> 45661
A23: =A22+1 -> 21 | B23: 120/6 | C23: =VLOOKUP(B23,Sheet4!$A:$B,2,FALSE) -> DA+0 | D23: Wet Paddy | F23: 45631 | H23: Completed | I23: 45661 | K23: APR Associates
A24: =A23+1 -> 22 | B24: 137/2 | C24: =VLOOKUP(B24,Sheet4!$A:$B,2,FALSE) -> DA-3 | D24: WET | F24: 45653 | H24: Completed | I24: 45667 | K24: Adhya Brother
A25: =A24+1 -> 23 | B25: 121/1 | C25: =VLOOKUP(B25,Sheet4!$A:$B,2,FALSE) -> DB1+25 | D25: WPS | F25: 45660 | H25: Completed | I25: 45667 | K25: Himanshi Agency | L25: Completed | M25: =I25+1 -> 45668
A26: =A25+1 -> 24 | B26: 121/7 | C26: =VLOOKUP(B26,Sheet4!$A:$B,2,FALSE) -> DB1+0 | D26: Wet | F26: 45650 | H26: Completed | I26: 45669 | K26: Arya Enterprises | L26: Completed | M26: =I26+1 -> 45670
A27: =A26+1 -> 25 | B27: 145/3 | C27: =VLOOKUP(B27,Sheet4!$A:$B,2,FALSE) -> DA-3 | D27: FS | F27: 45656 | H27: Completed | I27: 45670 | K27: Integer Infratech Pvt Ltd | L27: Completed
A28: =A27+1 -> 26 | B28: 120/7 | C28: =VLOOKUP(B28,Sheet4!$A:$B,2,FALSE) -> DA+3 | D28: WPS | F28: 45667 | H28: Completed | I28: 45671 | K28: Himanshi Agency | L28: Completed | M28: =I28+1 -> 45672
A29: =A28+1 -> 27 | B29: 244/5 | C29: =VLOOKUP(B29,Sheet4!$A:$B,2,FALSE) -> DA+0 | D29: PS | F29: 45664 | H29: Completed | I29: 45673 | K29: Neelkant Infra Project | L29: Completed | M29: =I29+1 -> 45674
A30: =A29+1 -> 28 | B30: 250/0 | C30: =VLOOKUP(B30,Sheet4!$A:$B,2,FALSE) -> DD45+3 | D30: PS | F30: 45664 | H30: Completed | I30: 45677 | K30: =K24 -> Adhya Brother | L30: Completed | M30: =I30+1 -> 45678
A31: =A30+1 -> 29 | B31: 121/8 | C31: =VLOOKUP(B31,Sheet4!$A:$B,2,FALSE) -> DA+0 | D31: WET | F31: 45667 | H31: Completed | I31: 45677 | K31: Arya Enterprises | L31: Completed | M31: =I31+1 -> 45678
A32: =A31+1 -> 30 | B32: 252/3 | C32: =VLOOKUP(B32,Sheet4!$A:$B,2,FALSE) -> DA+6 | D32: WET | F32: 45674 | H32: Completed | I32: 45679 | K32: Neelkant Infra Project | L32: Completed | M32: =I32+1 -> 45680
A33: =A32+1 -> 31 | B33: 136/1 | C33: =VLOOKUP(B33,Sheet4!$A:$B,2,FALSE) -> DB1+9 | D33: WPS | F33: 45676 | H33: Completed | I33: 45681 | K33: Himanshi Agency | L33: Completed | M33: =I33+1 -> 45682
A34: =A33+1 -> 32 | B34: 145/2 | C34: =VLOOKUP(B34,Sheet4!$A:$B,2,FALSE) -> DA+0 | D34: WET | F34: 45672 | H34: Completed | I34: 45683 | K34: Integer Infratech Pvt Ltd | L34: Completed | M34: =I34+1 -> 45684
A35: =A34+1 -> 33 | B35: 250A/2 | C35: =VLOOKUP(B35,Sheet4!$A:$B,2,FALSE) -> DA+0 | D35: WET | F35: 45677 | H35: Completed | I35: 45685 | K35: Unnati Construction | L35: Completed | M35: =I35+1 -> 45686
A36: =A35+1 -> 34 | B36: 252/0 | C36: =VLOOKUP(B36,Sheet4!$A:$B,2,FALSE) -> DB2+0 | D36: WET | F36: 45679 | H36: Completed | I36: 45688 | K36: Neelkant Infra Project | L36: Completed | M36: =I36+1 -> 45689
A37: =A36+1 -> 35 | B37: 248/2 | C37: =VLOOKUP(B37,Sheet4!$A:$B,2,FALSE) -> DA+6 | D37: Wet | F37: 45686 | H37: Completed | I37: 45691 | K37: Unnati Construction | L37: Completed | M37: =I37+1 -> 45692
A38: =A37+1 -> 36 | B38: 141/4 | C38: =VLOOKUP(B38,Sheet4!$A:$B,2,FALSE) -> DA-3 | D38: WET | F38: 45684 | H38: Completed | I38: 45692 | K38: Himanshi Agency | L38: Completed
A39: =A38+1 -> 37 | B39: 241/4 | C39: =VLOOKUP(B39,Sheet4!$A:$B,2,FALSE) -> DA+3 | D39: Wet | F39: 45686 | H39: Completed | I39: 45692 | K39: Unnati Construction | L39: Completed | M39: =I39+1 -> 45693
A40: =A39+1 -> 38 | B40: 121/10 | C40: =VLOOKUP(B40,Sheet4!$A:$B,2,FALSE) -> DA+0 | D40: Wet | F40: 45685 | H40: Completed | I40: 45692 | K40: Arya Enterprises | L40: Completed | M40: =I40+1 -> 45693
...

Sheet Sheet5
B7: 127/1
B8: 135/0
B9: 139/1
B10: 139/2
B11: 139/3
B12: 140/0
B13: 167/0
B14: 173/0
B15: 174/0
B16: 174/2
B17: 178/2
B18: 179/0
... B77: 199/0

Sheet Sheet3
A1: A
A2: 127/2 | D2: =_xlfn.CONCAT(A2,A3,A4,A5,A6,A7,A8,A9,A10,A11,A12,A13,A14,A15,A16,A17,A18,A19,A20,A21,A22,A23,A24,A25,A26) -> 127/2128/0135/0139/0139/2141/1141/2145/5145/6148/3161/0166/0175/1182/0183/0183/1183/3194/0214/3214/6217/4225/3244/0244/2250/2
A3: 128/0
A4: 135/0
A5: 139/0 | D5: 127/2128/0135/0139/0139/2141/1141/2145/5145/6148/3161/0166/0175/1182/0183/0183/1183/3194/0214/3214/6217/4225/3244/0244/2250/2
A6: 139/2
A7: 141/1
A8: 141/2
A9: 145/5
A10: 145/6
A11: 148/3
A12: 161/0
A13: 166/0
A14: 175/1
A15: 182/0
A16: 183/0
A17: 183/1
... A26: 250/2

Sheet Sheet1
A2: District | B2: Till Dec'24 | C2: Jan'25 | D2: Feb'25 | E2: Mar'25 | F2: Apr'25 | G2: May'25
A3: Bharuch | B3: 14 | C3: 9 | D3: 14 | E3: 4 | F3: 1
A4: Surat | E4: 4 | F4: 17 | G4: 4
A5: Navsari | B5: 4 | C5: 7 | D5: 6 | E5: 2

Sheet Erection Compiled
A2: VNTL Tower Erection
A3: Sl. No. | B3: Location Number | C3: Type of Tower | D3: Starting Date | E3: Tower Weight (MT) | F3: Status | G3: Completion Date | H3: Gang Name | I3: Manpower | J3: Hindarnce Days | K3: Remarks | L3: Tackweldng Status | M3: Tackwelding start date | N3: Tackwelding Completion date | O3: Sub Contractor name
A4: 1 | B4: 117/2 | C4: =VLOOKUP(B4,Sheet4!$A:$B,2,FALSE) -> DA+6 | D4: 45888 | E4: 44.727 | F4: Tower Erection Completed | G4: 45897 | H4: M/S Sakkurddin | I4: 32
A5: =A4+1 -> 2 | B5: 118/0 | C5: =VLOOKUP(B5,Sheet4!$A:$B,2,FALSE) -> DB2+0 | D5: 45808 | E5: 54.405 | F5: Tower Erection Completed | G5: 45823 | H5: M/s MGR | I5: 24
A6: =A5+1 -> 3 | B6: 119/0 | C6: =VLOOKUP(B6,Sheet4!$A:$B,2,FALSE) -> DD60+0 | D6: 45879 | E6: 80.243 | F6: Tower Erection Completed | G6: 45899 | H6: M/S Midhun | I6: 42
A7: =A6+1 -> 4 | B7: 119/2 | C7: =VLOOKUP(B7,Sheet4!$A:$B,2,FALSE) -> DA-3 | D7: 45876 | E7: 36.043 | F7: Tower Erection Completed | G7: 45883 | H7: M/S Sakkurddin | I7: 32
A8: =A7+1 -> 5 | B8: 119/3 | C8: =VLOOKUP(B8,Sheet4!$A:$B,2,FALSE) -> DA+9 | D8: 45864 | E8: 46.622 | F8: Tower Erection Completed | G8: 45874 | H8: M/S Sakkurddin | I8: 32
A9: =A8+1 -> 6 | B9: 120/7 | C9: =VLOOKUP(B9,Sheet4!$A:$B,2,FALSE) -> DA+3 | D9: 46019 | E9: =37.729 -> 37.729 | F9: Bottom Section U/P | H9: Subhash | I9: 26
A10: =A9+1 -> 7 | B10: 120/2 | C10: =VLOOKUP(B10,Sheet4!$A:$B,2,FALSE) -> DA+0 | D10: 45810 | E10: =37.729 -> 37.729 | F10: Tower Erection Completed | G10: 45815 | H10: M/S Rahul | I10: 26
A11: =A10+1 -> 8 | B11: 120/3 | C11: =VLOOKUP(B11,Sheet4!$A:$B,2,FALSE) -> DA+6 | D11: 45817 | E11: 44.727 | F11: Tower Erection Completed | G11: 45822 | H11: M/S Rahul | I11: 26
A12: =A11+1 -> 9 | B12: 120/4 | C12: =VLOOKUP(B12,Sheet4!$A:$B,2,FALSE) -> DA+0 | D12: 46019 | E12: 34.70456 | F12: Tower Erection Completed | G12: 46024 | H12: Subhash | I12: 26
A13: =A12+1 -> 10 | B13: 120/5 | C13: =VLOOKUP(B13,Sheet4!$A:$B,2,FALSE) -> DA-3 | D13: 45999 | E13: 36.043 | F13: Tower Erection Completed | G13: 46018 | H13: Subhash Kumar | I13: 26
A14: =A13+1 -> 11 | B14: 120/6 | C14: =VLOOKUP(B14,Sheet4!$A:$B,2,FALSE) -> DA+0 | D14: 45824 | E14: =37.729 -> 37.729 | F14: Tower Erection Completed | G14: 45837 | H14: M/S Rahul | I14: 26
A15: =A14+1 -> 12 | B15: 121/10 | C15: =VLOOKUP(B15,Sheet4!$A:$B,2,FALSE) -> DA+0 | D15: 45908 | E15: =37.729 -> 37.729 | F15: Tower Erection Completed | G15: 45918 | H15: M/S Sakkurddin | I15: 32
A16: =A15+1 -> 13 | B16: 121/2 | C16: =VLOOKUP(B16,Sheet4!$A:$B,2,FALSE) -> DA+9 | D16: 46021 | E16: 45.041904 | F16: Material Segregation U/P | H16: Modina India 2 | I16: 20
A17: =A16+1 -> 14 | B17: 121/4 | C17: =VLOOKUP(B17,Sheet4!$A:$B,2,FALSE) -> DA+0 | D17: 45378 | E17: =37.729 -> 37.729 | F17: Tower Erection Completed | G17: 45748 | H17: M/S Gauri Shankar | I17: 28
A18: =A17+1 -> 15 | B18: 121/7 | C18: =VLOOKUP(B18,Sheet4!$A:$B,2,FALSE) -> DB1+0 | D18: 45915 | E18: 55.045 | F18: Tower Erection Completed | G18: 45931 | H18: M/S Midhun | I18: 42
A19: =A18+1 -> 16 | B19: 126/1 | C19: =VLOOKUP(B19,Sheet4!$A:$B,2,FALSE) -> DA+3 | D19: 46021 | E19: 38.03774 | F19: 1st Section U/P | H19: Modina India 3 | I19: 23
A20: =A19+1 -> 17 | B20: 131/2 | C20: =VLOOKUP(B20,Sheet4!$A:$B,2,FALSE) -> DA+0 | D20: 46006 | E20: =37.729 -> 37.729 | F20: Tower Erection Completed | G20: 46011 | H20: Rahul Kumar | I20: 33
A21: =A20+1 -> 18 | B21: 132/0 | C21: =VLOOKUP(B21,Sheet4!$A:$B,2,FALSE) -> DB2+0 | D21: 45999 | F21: Tower Erection Completed | G21: 46006 | H21: Rahul Kumar | I21: 22
A22: =A21+1 -> 19 | B22: 136/1 | C22: =VLOOKUP(B22,Sheet4!$A:$B,2,FALSE) -> DB1+9 | D22: 46011 | E22: 62.945718 | F22: Tower Erection Completed | G22: 46019 | H22: Rahul Kumar | I22: 24
A23: =A22+1 -> 20 | B23: 137/2 | C23: =VLOOKUP(B23,Sheet4!$A:$B,2,FALSE) -> DA-3 | D23: 46019 | E23: 34.705 | F23: Tower Erection Completed | G23: 46026 | H23: Rahul Kumar
A24: =A23+1 -> 21 | B24: 141/1 | C24: =VLOOKUP(B24,Sheet4!$A:$B,2,FALSE) -> DA+0 | D24: 46016 | E24: =37.729 -> 37.729 | F24: Tower Erection Completed | G24: 46022 | H24: Srvan Kumar | I24: 18
A25: =A24+1 -> 22 | B25: 141/2 | C25: =VLOOKUP(B25,Sheet4!$A:$B,2,FALSE) -> DA+0 | D25: 46024 | E25: 34.70456 | F25: Tower Erection Completed | G25: 46026 | H25: Srvan Kumar ( Dhirendra Kumar Verma) | I25: 18
A26: =A25+1 -> 23 | B26: 141/6 | C26: =VLOOKUP(B26,Sheet4!$A:$B,2,FALSE) -> DA+3 | D26: 45995 | E26: 38.03774 | F26: Tower Erection Completed | G26: 46010 | H26: Chitra Construction | I26: 23
A27: =A26+1 -> 24 | B27: 137/0 | C27: =VLOOKUP(B27,Sheet4!$A:$B,2,FALSE) -> DB2+3 | D27: 46026 | F27: 1st Section U/P | H27: Rahul Kumar | I27: 24
A28: =A27+1 -> 25 | B28: 145/5 | C28: =VLOOKUP(B28,Sheet4!$A:$B,2,FALSE) -> DA+3 | D28: 46019 | E28: 38.03774 | F28: Tower Erection Completed | G28: 46026 | H28: Anannya Traders | I28: 35
A29: =A28+1 -> 26 | B29: 148/2 | C29: =VLOOKUP(B29,Sheet4!$A:$B,2,FALSE) -> DA+0 | D29: 45997 | E29: =37.729 -> 37.729 | F29: Tower Erection Completed | G29: 46011 | H29: Zakir Hussain | I29: 25
A30: =A29+1 -> 27 | B30: 148/4 | C30: =VLOOKUP(B30,Sheet4!$A:$B,2,FALSE) -> DA+3 | D30: 46011 | E30: 38.03774 | F30: Tower Erection Completed | G30: 46028 | H30: Jabir Hussian | I30: 21
A31: =A30+1 -> 28 | B31: 175/1 | C31: =VLOOKUP(B31,Sheet4!$A:$B,2,FALSE) -> DB1+9 | D31: 46019 | E31: 62.945732 | F31: Tower Erection Completed | G31: 46028 | H31: Sakila Khatun | I31: 35
A32: =A31+1 -> 29 | B32: 176/0 | C32: =VLOOKUP(B32,Sheet4!$A:$B,2,FALSE) -> DD45+0 | D32: 46012 | E32: 69.287262 | F32: Tower Erection Completed | G32: 46019 | H32: Sakhila Khatun | I32: 23
A33: =A32+1 -> 30 | B33: 179/1 | C33: =VLOOKUP(B33,Sheet4!$A:$B,2,FALSE) -> DA+3 | D33: 45999 | E33: 38.03774 | F33: Tower Erection Completed | G33: 46003 | H33: Sakhila Khatun | I33: 24
A34: =A33+1 -> 31 | B34: 141/3 | C34: =VLOOKUP(B34,Sheet4!$A:$B,2,FALSE) -> DA+0 | D34: 46026 | E34: =37.729 -> 37.729 | F34: Bottom Section U/P | H34: DK Construction (sarvan Kumar) | I34: 18
A35: =A34+1 -> 32 | B35: 142/0 | C35: =VLOOKUP(B35,Sheet4!$A:$B,2,FALSE) -> DC1+9 | D35: 46010 | E35: 74.438854 | F35: Bottom Section U/P | H35: Chitra Construction | I35: 23
A36: =A35+1 -> 33 | B36: 180/5 | C36: =VLOOKUP(B36,Sheet4!$A:$B,2,FALSE) -> DA+3 | D36: 46008 | E36: 38.03774 | F36: Tower Erection Completed | G36: 46020 | H36: Md. Emdadul Hoque | I36: 19
A37: =A36+1 -> 34 | B37: 145/6 | C37: =VLOOKUP(B37,Sheet4!$A:$B,2,FALSE) -> DA+3 | D37: 46026 | E37: 38.03774 | F37: 2nd Section U/P | H37: Anannya Traders | I37: 35
A38: =A37+1 -> 35 | B38: 187/0 | C38: =VLOOKUP(B38,Sheet4!$A:$B,2,FALSE) -> DC1+0 | D38: 46002 | E38: 61.551158 | F38: Tower Erection Completed | G38: 46011 | H38: Sakhila Khatun | I38: 35
A39: =A38+1 -> 36 | B39: 241/0 | C39: =VLOOKUP(B39,Sheet4!$A:$B,2,FALSE) -> DD60+0 | D39: 45902 | E39: 80.243 | F39: Tower Erection Completed | G39: 45915 | H39: M/S Israul Hoque | I39: 38
A40: =A39+1 -> 37 | B40: 241/4 | C40: =VLOOKUP(B40,Sheet4!$A:$B,2,FALSE) -> DA+3 | D40: 45997 | E40: 38.03774 | F40: Tower Erection Completed | G40: 46010 | H40: Sk Samirul | I40: 23
A41: =A40+1 -> 38 | B41: 243/0 | C41: =VLOOKUP(B41,Sheet4!$A:$B,2,FALSE) -> DD60+3 | D41: 45991 | E41: 84.299 | F41: Tower Erection Completed | G41: 46016 | H41: Anjum Construction | I41: 22
...

Sheet Sheet4
C3: 117/1 | D3: 117/2 | E3: 118/0 | F3: 119/0 | G3: 119/1 | H3: 119/2 | I3: 119/3 | J3: 120/0 | K3: 120/1 | L3: 120/2 | M3: 120/3 | N3: 120/4 | O3: 120/5 | P3: 120/6 | Q3: 120/7 | R3: 121/0 | S3: 121/1 | T3: 121/2 | U3: 121/3 | V3: 121/4 | W3: 121/5 | X3: 121/6 | Y3: 121/7 | Z3: 121/8 | AA3: 121/9 | AB3: 121/10 | AC3: 121/11 | AD3: 124/0 | AE3: 124/1 | AF3: 124/2 | AG3: 124/3 | AH3: 125/0 | AI3: 125/1 | AJ3: 125/2 | AK3: 126/0 | AL3: 126/1 | AM3: 126/2 | AN3: 126/3 | AO3: 127/0 | AP3: 127/1 | AQ3: 127/2 | AR3: 128/0 | AS3: 129/0 | AT3: 130/0 | AU3: 131/0 | AV3: 131/1 | AW3: 131/2 | AX3: 131/3 | AY3: 131/4 | AZ3: 131/5 | BA3: 132/0 | BB3: 132/1 | BC3: 132/2 | BD3: 132/3 | BE3: 133/0 | BF3: 133/1 | BG3: 133/2 | BH3: 133/3 | BI3: 133/4 | BJ3: 134/0 | BK3: 135/0 | BL3: 136/0 | BM3: 136/1 | BN3: 137/0 | BO3: 137/1 | BP3: 137/2 | BQ3: 138/0 | BR3: 139/0 | BS3: 139/1 | BT3: 139/2 | BU3: 139/3 | BV3: 140/0 | BW3: 141/0 | BX3: 141/1 | BY3: 141/2 | BZ3: 141/3 | CA3: 141/4 | CB3: 141/5 | CC3: 141/6 | CD3: 142/0 | CE3: 143/0 | CF3: 144/0 | CG3: 145/0 | CH3: 145/1 | CI3: 145/2 | CJ3: 145/3 | CK3: 145/4 | CL3: 145/5 | CM3: 145/6 | CN3: 145/7 | CO3: 147/0 | CP3: 148/0 | CQ3: 148/1 | CR3: 148/2 | CS3: 148/3 | CT3: 148/4 | CU3: 148/5 | CV3: 149/0 | CW3: 150/0 | CX3: 150/1 | CY3: 151/0 | CZ3: 151A/0 | DA3: 152/0 | DB3: 153/0 | DC3: 153/1 | DD3: 153/2 | DE3: 153A/0 | DF3: 154/0 | DG3: 155/0 | DH3: 156/0 | DI3: 156/1 | DJ3: 157/0 | DK3: 158/0 | DL3: 159/0 | DM3: 160/0 | DN3: 161/0 | DO3: 162/0 | DP3: 163/0 | DQ3: 163/1 | DR3: 164/0 | DS3: 165/0 | DT3: 165/1 | DU3: 165/2 | DV3: 165/3 | DW3: 165/4 | DX3: 165/5 | DY3: 165/6 | DZ3: 165/7 | EA3: 166/0 | EB3: 167/0 | EC3: 168/0 | ED3: 169/0 | EE3: 170/0 | EF3: 171/0 | EG3: 172/0 | EH3: 172/1 | EI3: 173/0 | EJ3: 174/0 | EK3: 174/1 | EL3: 174/2 | EM3: 174/3 | EN3: 174/4 | EO3: 174/5 | EP3: 174/6 | EQ3: 175/0 | ER3: 175/1 | ES3: 176/0 | ET3: 176/1 | EU3: 176/2 | EV3: 177/0 | EW3: 178/0 | EX3: 178/1 | EY3: 178/2 | EZ3: 178/3 | FA3: 179/0 | FB3: 179/1 | FC3: 179/2 | FD3: 179/3 | FE3: 180/0 | FF3: 180/1 | FG3: 180/2 | FH3: 180/3 | FI3: 180/4 | FJ3: 180/5 | FK3: 180/6 | FL3: 180/7 | FM3: 182/0 | FN3: 183/0 | FO3: 183/1 | FP3: 183/2 | FQ3: 183/3 | FR3: 184/0 | FS3: 185/0 | FT3: 186/0 | FU3: 187/0 | FV3: 188/0 | FW3: 189/0 | FX3: 189/1 | FY3: 190/0 | FZ3: 191/0 | GA3: 191/1 | GB3: 192/0 | GC3: 193/0 | GD3: 194/0 | GE3: 194/1 | GF3: 195/0 | GG3: 196/0 | GH3: 196/1 | GI3: 196/2 | GJ3: 197/0 | GK3: 197/1 | GL3: 197/2 | GM3: 198/0 | GN3: 199/0 | GO3: 199/1 | GP3: 199/2 | GQ3: 200/0 | GR3: 200/1 | GS3: 201/0 | GT3: 202/0 | GU3: 203/0 | GV3: 203/1 | GW3: 204/0 | GX3: 205/0 | GY3: 205/1 | GZ3: 205/2 | HA3: 206/0 | HB3: 206/1 | HC3: 207/0 | HD3: 208/0 | HE3: 209/0 | HF3: 209/1 | HG3: 209/2 | HH3: 210/0 | HI3: 211/0 | HJ3: 211/1 | HK3: 211/2 | HL3: 211/3 | HM3: 211/4 | HN3: 211/5 | HO3: 212/0 | HP3: 213/0 | HQ3: 214/0 | HR3: 214/1 | HS3: 214/2 | HT3: 214/3 | HU3: 214/4 | HV3: 214/5 | HW3: 214/6 | HX3: 214/7 | HY3: 215/0 | HZ3: 216/0 | IA3: 216/1 | IB3: 216/2 | IC3: 216/3 | ID3: 217/0 | IE3: 217/1 | IF3: 217/2 | IG3: 217/3 | IH3: 217/4 | II3: 217/5 | IJ3: 218/0 | IK3: 219/0 | IL3: 219/1 | IM3: 220/0 | IN3: 220/1 | IO3: 221/0 | IP3: 222/0 | IQ3: 223/0 | IR3: 223/1 | IS3: 223/2 | IT3: 223/3 | IU3: 224/0 | IV3: 224/1 | IW3: 224/2 | IX3: 225/0 | IY3: 225/1 | IZ3: 225/2 | JA3: 225/3 | JB3: 225/4 | JC3: 225/5 | JD3: 225/6 | JE3: 225/7 | JF3: 226/0 | JG3: 226/1 | JH3: 226/2 | JI3: 226/3 | JJ3: 227/0 | JK3: 227/1 | JL3: 227/2 | JM3: 228/0 | JN3: 228/1 | JO3: 229/0 | JP3: 229/1 | JQ3: 229A/0 | JR3: 229B/0 | JS3: 230/0 | JT3: 230/1 | JU3: 230A/0 | JV3: 231/0 | JW3: 232/0 | JX3: 232/1 | JY3: 232/2 | JZ3: 232/3 | KA3: 232/4 | KB3: 233/0 | KC3: 234/0 | KD3: 235/0 | KE3: 235/1 | KF3: 235/2 | KG3: 235/3 | KH3: 235/4 | KI3: 236/0 | KJ3: 237/0 | KK3: 238/0 | KL3: 239/0 | KM3: 239/1 | KN3: 240/0 | KO3: 240/1 | KP3: 241/0 | KQ3: 241/1 | KR3: 241/2 | KS3: 241/3 | KT3: 241/4 | KU3: 242/0 | KV3: 243/0 | KW3: 243/1 | KX3: 243/2 | KY3: 243/3 | KZ3: 244/0 | LA3: 244/1 | LB3: 244/2 | LC3: 244/3 | LD3: 244/4 | LE3: 244/5 | LF3: 244/6 | LG3: 245/0 | LH3: 245/1 | LI3: 246/0 | LJ3: 247/0 | LK3: 248/0 | LL3: 248/1 | LM3: 248/2 | LN3: 249/0 | LO3: 249/1 | LP3: 249/2 | LQ3: 249/3 | LR3: 250/0 | LS3: 250/1 | LT3: 250/2 | LU3: 250/3 | LV3: 250A/0 | LW3: 250A/1 | LX3: 250A/2 | LY3: 251/0 | LZ3: 251/1 | MA3: 252/0 | MB3: 252/1 | MC3: 252/2 | MD3: 252/3 | ME3: 252/4 | MF3: 252/5 | MG3: 253/0 | MH3: 254/0 | MI3: 254/1 | MJ3: 255/0 | MK3: 255/1 | ML3: 256/0 | MM3: 256/1 | MN3: 257/0 | MO3: 258/0
C4: DA-3 | D4: DA+6 | E4: DB2+0 | F4: DD60+0 | G4: DA-3 | H4: DA-3 | I4: DA+9 | J4: DD60+3 | K4: DA-3 | L4: DA+0 | M4: DA+6 | N4: DA+0 | O4: DA-3 | P4: DA+0 | Q4: DA+3 | R4: DB2+9 | S4: DB1+25 | T4: DA+9 | U4: DA+0 | V4: DA+0 | W4: DA-3 | X4: DA+0 | Y4: DB1+0 | Z4: DA+0 | AA4: DA+0 | AB4: DA+0 | AC4: DA+9 | AD4: DD45+3 | AE4: DA-3 | AF4: DA+0 | AG4: DA+0 | AH4: DC2+3 | AI4: DA+9 | AJ4: DA+9 | AK4: DD45+3 | AL4: DA+3 | AM4: DA+0 | AN4: DA+0 | AO4: DB2+0 | AP4: DA-3 | AQ4: DB1+9 | AR4: DD60+25 (2MRC) | AS4: DD45+25 (15.87MRC) | AT4: DD45+25 (11.9MRC) | AU4: DD60+9 (7MRC) | AV4: DA+3 | AW4: DA+0 | AX4: DA+3 | AY4: DA-3 | AZ4: DA-3 | BA4: DB2+0 | BB4: DA-3 | BC4: DA-3 | BD4: DA-3 | BE4: DC1+0 | BF4: DA+0 | BG4: DB1+0 | BH4: DB1+0 | BI4: DA+3 | BJ4: DD45+0 | BK4: DD60+3 | BL4: DD60+6 | BM4: DB1+9 | BN4: DB2+3 | BO4: DA+6 | BP4: DA-3 | BQ4: DC2+6 | BR4: DD45+6 | BS4: DA+6 | BT4: DB2+0 | BU4: DB1+0 | BV4: DD60+25 | BW4: DD60+25 | BX4: DA+0 | BY4: DA+0 | BZ4: DA+0 | CA4: DA-3 | CB4: DA-3 | CC4: DA+3 | CD4: DC1+9 | CE4: DD60+18 | CF4: DD60+18 | CG4: DD45+9 | CH4: DA+0 | CI4: DA+0 | CJ4: DA-3 | CK4: DA+0 | CL4: DA+3 | CM4: DA+3 | CN4: DB1+0 | CO4: DD60+25 | CP4: DD60+25 | CQ4: DA+3 | CR4: DA+0 | CS4: DA+6 | CT4: DA+3 | CU4: DB1+3 | CV4: DD60+25 | CW4: DD60+25 | CX4: DB1+0 | CY4: DD60+6 | CZ4: DD60+18 | DA4: DD60+3 | DB4: DD60+3 | DC4: DA+3 | DD4: DA+0 | DE4: DD45+9 | DF4: DD60+9 | DG4: DD60+18 | DH4: DD45+18 | DI4: DB2+9 | DJ4: DD60+41 | DK4: DD60+41 | DL4: DD60+9 (2MRC) | DM4: DC2+0 | DN4: DB1+3 | DO4: DD60+25 | DP4: DD60+30 | DQ4: DB1+6 | DR4: DC2+6 | DS4: DB1+25 | DT4: DA+9 | DU4: DA+6 | DV4: DA+6 | DW4: DA-3 | DX4: DA-3 | DY4: DCT+0 | DZ4: DA+0 | EA4: DD60+0 | EB4: DD60+9 | EC4: DD60+30 | ED4: DD60+25 | EE4: DD60+6 | EF4: DB1+18 | EG4: DD45+9 | EH4: DA+9 | EI4: DC2+18 | EJ4: DD60+9 (2MRC) | EK4: DA+3 | EL4: DA+0 | EM4: DA+0 | EN4: DA+0 | EO4: DA+0 | EP4: DA+3 | EQ4: DC2+6 | ER4: DB1+9 | ES4: DD45+0 | ET4: DA+0 | EU4: DA-3 | EV4: DD60+6 | EW4: DD60+6 | EX4: DA+0 | EY4: DA+0 | EZ4: DA-3 | FA4: DB1+0 | FB4: DA+3 | FC4: DA+3 (A,B 1.5 RC) | FD4: DA+0 | FE4: DD45+0LE (3 Leg)+1.5LE (1 Leg) & (B1MRC & C0.5MRS) | FF4: DA+3 | FG4: DB1+3 | FH4: DA+9 | FI4: DA-3 | FJ4: DA+3 | FK4: DA+0 | FL4: DA+0 | FM4: DD45+0 | FN4: DD60+0 | FO4: DA+0 | FP4: DA+0 | FQ4: DA+3 | FR4: DB1+18 | FS4: DD45+25 | FT4: DC1+18 | FU4: DC1+0 | FV4: DD60+35 | FW4: DD60+35 | FX4: DA+9 | FY4: DD60+9 | FZ4: DD60+9 | GA4: DB1+3 | GB4: DC2+9 | GC4: DD60+30 | GD4: DD60+30 | GE4: DB1+9 | GF4: DC1+18 | GG4: DB2+18 | GH4: DA+9 | GI4: DA+3 | GJ4: DB1+0 | GK4: DA-3 | GL4: DA-3 | GM4: DD60+6 | GN4: DD60+6 | GO4: DA+3 | GP4: DA+6 | GQ4: DC2+0 | GR4: DA+6 | GS4: DC1+9 | GT4: DC1+18 | GU4: DC1+18 | GV4: DB1+0 | GW4: DD60+25 (2MRC) | GX4: DD60+25 (3MRC) | GY4: DB2+9 | GZ4: DA+9 | HA4: DC2+0 | HB4: DB1+6 | HC4: DD60+25 | HD4: DD45+35 | HE4: DD60+9 | HF4: DA+0 | HG4: DA-3 | HH4: DB2+9 (2MRC) | HI4: DB2+9 | HJ4: DA-3 | HK4: DA+0 | HL4: DA+9 | HM4: DA-3 | HN4: DB1+9 | HO4: DD45+30 (2MRC) | HP4: DD60+35 | HQ4: DD60+25 | HR4: DA+6 | HS4: DA-3 | HT4: DA-3 | HU4: DA-3 | HV4: DA+0 | HW4: DA+3 | HX4: DA+3 | HY4: DD60+3 | HZ4: DD60+3 | IA4: DA+9 (2MRC) | IB4: DB1+18 (2MRC) | IC4: DA+9 | ID4: DC2+9 | IE4: DA+3 | IF4: DA+0 | IG4: DA+9 | IH4: DA+9 | II4: DA+0 | IJ4: DD60+3 | IK4: DD45+3 | IL4: DA+9 | IM4: DD45+0 | IN4: DA+6 | IO4: DD60+18 | IP4: DD60+25 | IQ4: DC1+6 | IR4: DA+0 | IS4: DA+0 | IT4: DA-3 | IU4: DC1+0 | IV4: DA+3 | IW4: DB1+6 | IX4: DB2+0 | IY4: DA+9 | IZ4: DA-3 | JA4: DA-3 | JB4: DA+3 | JC4: DA+0 | JD4: DA+0 | JE4: DA+6 | JF4: DB2+3 | JG4: DA+6 | JH4: DA+0 | JI4: DA+0 | JJ4: DD45+0 | JK4: DA+6 | JL4: DA+3 | JM4: DD45+0 | JN4: DA+0 | JO4: DD45+0 | JP4: DA+9 | JQ4: DB1+25 | JR4: DB2+25 | JS4: DC1+6 | JT4: DA+9 | JU4: DD45+0 | JV4: DB1+0 | JW4: DB1+0 | JX4: DA+0 | JY4: DA+0 | JZ4: DA+0 | KA4: DA+3 | KB4: DC1+0 | KC4: DD60+18 | KD4: DD60+9 (2MRC) | KE4: DA+9 | KF4: DA+0 | KG4: DA+0 | KH4: DA+3 | KI4: DB2+18 | KJ4: DB1+25 (2MRC) | KK4: DC1+25 | KL4: DD45+0 | KM4: DA+0 | KN4: DB2+0 | KO4: DA+3 | KP4: DD60+0 | KQ4: DA+0 | KR4: DA+0 | KS4: DA+0 | KT4: DA+3 | KU4: DD60+3 | KV4: DD60+3 | KW4: DA+0 | KX4: DA+0 | KY4: DA+0 | KZ4: DD45+0 | LA4: DA+0 | LB4: DA+0 | LC4: DA+3 | LD4: DA+3 | LE4: DA+0 | LF4: DA+3 | LG4: DD45+0 | LH4: DA+0 | LI4: DD45+9 | LJ4: DD60+35 (2MRC) | LK4: DD60+35 (2MRC) | LL4: DB1+9 | LM4: DA+6 | LN4: DD60+3 | LO4: DA+9 | LP4: DA+3 | LQ4: DA+3 | LR4: DD45+3 | LS4: DA+9 (1MRC) | LT4: DA+0 | LU4: DA+9 | LV4: DB1+3 (3MRC) | LW4: DA+6 | LX4: DA+0 | LY4: DD45+0 | LZ4: DA+6 (1MRC) | MA4: DB2+0 | MB4: DA+0 | MC4: DA+3 | MD4: DA+6 | ME4: DA+0 | MF4: DB1+9 | MG4: DD45+35 (2MRC) | MH4: DD45+35 (2MRC) | MI4: DB1+9 | MJ4: DD60+0 | MK4: DA+0 | ML4: DD60+0 | MM4: DA+9 | MN4: DC1+9 | MO4: DD60+0 (1.5MRC)
A9: Loc No | B9: Tower Type
A11: 117/1 | B11: DA-3
A12: 117/2 | B12: DA+6
A13: 118/0 | B13: DB2+0
A14: 119/0 | B14: DD60+0
A15: 119/1 | B15: DA-3
A16: 119/2 | B16: DA-3
A17: 119/3 | B17: DA+9
A18: 120/0 | B18: DD60+3
A19: 120/1 | B19: DA-3
A20: 120/2 | B20: DA+0
A21: 120/3 | B21: DA+6
... A361: 258/0 | B361: DD60+0 (1.5MRC)

Sheet String
A1: VNTL Stringing
A2: Sr. No. | B2: Section | C2: length | D2: Manual/TSE | E2: Engaged Date | F2: Paying Out | H2: Final Sag | J2: P/O Completed | K2: F/S Completed | L2: Stringing Status As on Today | M2: Cumulative Status | N2: Sub Contractor name | O2: Manpower | P2: Hindarnce Days | Q2: Remarks
F3: Start Date | G3: End Date | H3: Start Date | I3: End Date

Sheet Visual chart 1 
A1: Visual Chart | AH1: =TODAY()-1 -> 46029
A2: Name of the Line : | E2: 765 kV D/C Vataman - Navsari Transmission Line | X2: Completed
A3: Name of Project: | E3: Powergrid Vataman Transmission Limited | X3: DS (Aprd) | Y3: CS (Aprd) | Z3: SOIL INVSTGN | AA3: FOUNDATION | AD3: TOWER ERECTION | AH3: TW | AI3: TIG & PUN | AJ3: STR P/O | AK3: STR F/S | AL3: OPGW STR
A4: Name of Contractor: | E4: KEC International Limited
AA5: TOTAL | AB5: COMP. | AC5: BAL. | AD5: EAR | AE5: TOTAL | AF5: COMP. | AG5: BAL.
A6: PROGRESS AT A GLANCE : | L6: CROSSING PROPOSAL STATUS :
A8: Sl. No. | B8: Activity | E8: UoM | F8: Total Qty | H8: Completed Till Date | J8: Balance | L8: Sl. No. | M8: Type of Crossing | Q8: No. of X-ing | S8: Approved | U8: Balance
A10: 1 | B10: Detailed Survey | E10: Kms | F10: ='VNTL - KEC'!C7 -> 127.85407 | H10: ='VNTL - KEC'!I7 -> 127.85407 | J10: =F10-H10 -> 0 | L10: 1 | M10: Powerline X-ing | Q10: 48 | S10: 43 | U10: =Q10-S10 -> 5
A11: 2 | B11: Check Survey | E11: Kms | F11: ='VNTL - KEC'!C9 -> 127.85407 | H11: ='VNTL - KEC'!I9 -> 127.85407 | J11: =F11-H11 -> 0 | L11: TRUE | M11: 66 kV | Q11: 18 | S11: 17 | U11: =Q11-S11 -> 1
A12: 3 | B12: Soil Investigation | E12: Nos. | F12: ='VNTL - KEC'!C10 -> 28 | H12: ='VNTL - KEC'!I10 -> 28 | J12: =F12-H12 -> 0 | L12: TRUE | M12: 132 kV | Q12: 2 | S12: 2 | U12: =Q12-S12 -> 0
A13: 4 | B13: Foundation | E13: Nos. | F13: ='VNTL - KEC'!C12 -> 351 | H13: ='VNTL - KEC'!I12 -> 189 | J13: =F13-H13 -> 162 | L13: TRUE | M13: 220 kV | Q13: 15 | S13: 13 | U13: =Q13-S13 -> 2
A14: 5 | B14: Earthing | E14: Nos. | F14: =F13 -> 351 | H14: ='VNTL - KEC'!I13 -> 156 | J14: =F14-H14 -> 195 | L14: TRUE | M14: 400 kV &765 kV | Q14: 13 | S14: 11 | U14: =Q14-S14 -> 2
A15: 6 | B15: Erection | E15: Nos. | F15: =F14 -> 351 | H15: ='VNTL - KEC'!I14 -> 36 | J15: =F15-H15 -> 315 | L15: 2 | M15: =[101]Summary!$C$13 -> RLY X-ING | Q15: 4 | S15: 2 | U15: =Q15-S15 -> 2
A16: 7 | B16: Tack Welding | E16: Nos. | F16: =F15 -> 351 | L16: 3 | M16: =[101]Summary!$C$14 -> NH X-ING | Q16: 3 | S16: 3 | U16: =Q16-S16 -> 0
A17: 8 | B17: Stringing (P/O) | E17: Kms | F17: =F11 -> 127.85407 | L17: 4 | M17: =[101]Summary!$C$15 -> Bullet Train | Q17: 2 | S17: 2 | U17: =Q17-S17 -> 0
A18: 9 | B18: Stringing (F/S) | E18: Kms | F18: =F17 -> 127.85407 | L18: 5 | M18: =[101]Summary!$C$16 -> Express-way | Q18: 4 | S18: 4 | U18: =Q18-S18 -> 0
A19: 10 | B19: OPGW Stringing | E19: Kms | F19: =F18 -> 127.85407 | L19: 6 | M19: =[101]Summary!$C$17 -> GAS PIPELINE | Q19: 6 | U19: =Q19-S19 -> 6
X20: =V28/1000 -> 3.516 | Y20: =X20 -> 3.516 | AA20: 9 | AB20: 9 | AC20: =AA20-AB20 -> 0 | AD20: 7 | AE20: 9 | AF20: 5 | AG20: =AE20-AF20 -> 4
B21: BHARUCH DISTRICT FROM 117/0 - 148/0, 92 Locations (Length 34.264 Kms)
B24: 117/0 | D24: 117/1 | F24: 117/2 | H24: 118/0 | J24: 119/0 | L24: 119/1 | N24: 119/2 | P24: 119/3 | R24: 120/0 | T24: 120/1
B28: KPIL Tower | C28: 347 | E28: 352 | G28: 443.762 | I28: 243.824 | K28: 339.414 | M28: 316 | O28: 408 | Q28: 358.181 | S28: 358.819 | U28: 349 | V28: =SUM(C28:U28) -> 3516
D31: =HLOOKUP(D24,Sheet4!$C$3:$MO$4,2,FALSE) -> DA-3 | F31: =HLOOKUP(F24,Sheet4!$C$3:$MO$4,2,FALSE) -> DA+6 | H31: =HLOOKUP(H24,Sheet4!$C$3:$MO$4,2,FALSE) -> DB2+0 | J31: =HLOOKUP(J24,Sheet4!$C$3:$MO$4,2,FALSE) -> DD60+0 | L31: =HLOOKUP(L24,Sheet4!$C$3:$MO$4,2,FALSE) -> DA-3 | N31: =HLOOKUP(N24,Sheet4!$C$3:$MO$4,2,FALSE) -> DA-3 | P31: =HLOOKUP(P24,Sheet4!$C$3:$MO$4,2,FALSE) -> DA+9 | R31: =HLOOKUP(R24,Sheet4!$C$3:$MO$4,2,FALSE) -> DD60+3 | T31: =HLOOKUP(T24,Sheet4!$C$3:$MO$4,2,FALSE) -> DA-3
D33: Material Shifted | X33: =V41/1000 -> 3.631 | Y33: =X33 -> 3.631 | AA33: 10 | AB33: 10 | AC33: =AA33-AB33 -> 0 | AD33: 4 | AE33: 10 | AF33: 5 | AG33: =AE33-AF33 -> 5
B37: 120/2 | D37: 120/3 | F37: 120/4 | H37: 120/5 | J37: 120/6 | L37: 120/7 | N37: 121/0 | P37: 121/1 | R37: 121/2 | T37: 121/3
C41: 400 | E41: 428 | G41: 368 | I41: 359 | K41: 277 | M41: 321.859 | O41: 276.141 | Q41: 433 | S41: 384 | U41: 384 | V41: =SUM(C41:U41) -> 3631
B44: =HLOOKUP(B37,Sheet4!$C$3:$MO$4,2,FALSE) -> DA+0 | D44: =HLOOKUP(D37,Sheet4!$C$3:$MO$4,2,FALSE) -> DA+6 | F44: =HLOOKUP(F37,Sheet4!$C$3:$MO$4,2,FALSE) -> DA+0 | H44: =HLOOKUP(H37,Sheet4!$C$3:$MO$4,2,FALSE) -> DA-3 | J44: =HLOOKUP(J37,Sheet4!$C$3:$MO$4,2,FALSE) -> DA+0 | L44: =HLOOKUP(L37,Sheet4!$C$3:$MO$4,2,FALSE) -> DA+3 | N44: =HLOOKUP(N37,Sheet4!$C$3:$MO$4,2,FALSE) -> DB2+9 | P44: =HLOOKUP(P37,Sheet4!$C$3:$MO$4,2,FALSE) -> DB1+25 | R44: =HLOOKUP(R37,Sheet4!$C$3:$MO$4,2,FALSE) -> DA+9 | T44: =HLOOKUP(T37,Sheet4!$C$3:$MO$4,2,FALSE) -> DA+0
H46: Material Shifted | X46: =V54/1000 -> 3.717 | Y46: =X46 -> 3.717 | AA46: 10 | AB46: 9 | AC46: =AA46-AB46 -> 1 | AD46: 7 | AE46: 10 | AF46: 3 | AG46: =AE46-AF46 -> 7
B50: 121/4 | D50: 121/5 | F50: 121/6 | H50: 121/7 | J50: 121/8 | L50: 121/9 | N50: 121/10 | P50: 121/11 | R50: 124/0 | T50: 124/1
C54: 343 | E54: 352 | G54: 388 | I54: 368 | K54: 386 | M54: 397 | O54: 390 | Q54: 396.394 | S54: 334.606 | U54: 362 | V54: =SUM(C54:U54) -> 3717
B57: =HLOOKUP(B50,Sheet4!$C$3:$MO$4,2,FALSE) -> DA+0 | D57: =HLOOKUP(D50,Sheet4!$C$3:$MO$4,2,FALSE) -> DA-3 | F57: =HLOOKUP(F50,Sheet4!$C$3:$MO$4,2,FALSE) -> DA+0 | H57: =HLOOKUP(H50,Sheet4!$C$3:$MO$4,2,FALSE) -> DB1+0 | J57: =HLOOKUP(J50,Sheet4!$C$3:$MO$4,2,FALSE) -> DA+0 | L57: =HLOOKUP(L50,Sheet4!$C$3:$MO$4,2,FALSE) -> DA+0 | N57: =HLOOKUP(N50,Sheet4!$C$3:$MO$4,2,FALSE) -> DA+0 | P57: =HLOOKUP(P50,Sheet4!$C$3:$MO$4,2,FALSE) -> DA+9 | R57: =HLOOKUP(R50,Sheet4!$C$3:$MO$4,2,FALSE) -> DD45+3 | T57: =HLOOKUP(T50,Sheet4!$C$3:$MO$4,2,FALSE) -> DA-3
X59: =V67/1000 -> 3.95614 | Y59: =X59 -> 3.95614 | AA59: 10 | AB59: 5 | AC59: =AA59-AB59 -> 5 | AD59: 3 | AE59: 10 | AF59: 0 | AG59: =AE59-AF59 -> 10
B63: 124/2 | D63: 124/3 | F63: 125/0 | H63: 125/1 | J63: 125/2 | L63: 126/0 | N63: 126/1 | P63: 126/2 | R63: 126/3 | T63: 127/0
C67: 378 | E67: 397.983 | G67: 459.017 | I67: 383 | K67: 446.914 | M67: 411.086 | O67: 404 | Q67: 397 | S67: 372.138 | U67: 307.002 | V67: =SUM(C67:U67) -> 3956.14
B70: =HLOOKUP(B63,Sheet4!$C$3:$MO$4,2,FALSE) -> DA+0 | D70: =HLOOKUP(D63,Sheet4!$C$3:$MO$4,2,FALSE) -> DA+0 | F70: =HLOOKUP(F63,Sheet4!$C$3:$MO$4,2,FALSE) -> DC2+3 | H70: =HLOOKUP(H63,Sheet4!$C$3:$MO$4,2,FALSE) -> DA+9 | J70: =HLOOKUP(J63,Sheet4!$C$3:$MO$4,2,FALSE) -> DA+9 | L70: =HLOOKUP(L63,Sheet4!$C$3:$MO$4,2,FALSE) -> DD45+3 | N70: =HLOOKUP(N63,Sheet4!$C$3:$MO$4,2,FALSE) -> DA+3 | P70: =HLOOKUP(P63,Sheet4!$C$3:$MO$4,2,FALSE) -> DA+0 | R70: =HLOOKUP(R63,Sheet4!$C$3:$MO$4,2,FALSE) -> DA+0 | T70: =HLOOKUP(T63,Sheet4!$C$3:$MO$4,2,FALSE) -> DB2+0
X72: =V80/1000 -> 4.40124 | Y72: =X72 -> 4.40124 | AA72: 10 | AB72: 4 | AC72: =AA72-AB72 -> 6 | AD72: 1 | AE72: 10 | AF72: 1 | AG72: =AE72-AF72 -> 9
B76: 127/1 | D76: 127/2 | F76: 128/0 | H76: 129/0 | J76: 130/0 | L76: 131/0 | N76: 131/1 | P76: 131/2 | R76: 131/3 | T76: 131/4
C80: 402.977 | E80: 339.134 | G80: 619.999 | I80: 620.058 | K80: 535.071 | M80: 437.001 | O80: 396 | Q80: 416 | S80: 351 | U80: 284 | V80: =SUM(C80:U80) -> 4401.24
B83: =HLOOKUP(B76,Sheet4!$C$3:$MO$4,2,FALSE) -> DA-3 | D83: =HLOOKUP(D76,Sheet4!$C$3:$MO$4,2,FALSE) -> DB1+9 | F83: =HLOOKUP(F76,Sheet4!$C$3:$MO$4,2,FALSE) -> DD60+25 (2MRC) | H83: =HLOOKUP(H76,Sheet4!$C$3:$MO$4,2,FALSE) -> DD45+25 (15.87MRC) | J83: =HLOOKUP(J76,Sheet4!$C$3:$MO$4,2,FALSE) -> DD45+25 (11.9MRC) | L83: =HLOOKUP(L76,Sheet4!$C$3:$MO$4,2,FALSE) -> DD60+9 (7MRC) | N83: =HLOOKUP(N76,Sheet4!$C$3:$MO$4,2,FALSE) -> DA+3 | P83: =HLOOKUP(P76,Sheet4!$C$3:$MO$4,2,FALSE) -> DA+0 | R83: =HLOOKUP(R76,Sheet4!$C$3:$MO$4,2,FALSE) -> DA+3 | T83: =HLOOKUP(T76,Sheet4!$C$3:$MO$4,2,FALSE) -> DA-3
X85: =V93/1000 -> 3.386003 | Y85: =X85 -> 3.386003 | AA85: 10 | AB85: 2 | AC85: =AA85-AB85 -> 8 | AE85: 10 | AF85: 1 | AG85: =AE85-AF85 -> 9
B89: 131/5 | D89: 132/0 | F89: 132/1 | H89: 132/2 | J89: 132/3 | L89: 133/0 | N89: 133/1 | P89: 133/2 | R89: 133/3 | T89: 133/4
...

Sheet Crossing
A1: 765KV D/C HEXA VATAMAN - NAVSARI TL -04 - CROSSING STATUS
A2: Sl No | B2: AP NO | C2: Towe Type | D2: AP No | E2: Tower Type | F2: Type of Crossings | G2: Span Length | H2: LINE OWNER | I2: Line Name | J2: Nos. | K2: Work Portion | L2: Status | M2: Submitted to Client for Review | N2: Proposal Submitted (Y/N) | O2: Inspection Status (Y/N) | P2: Remarks
A3: 1 | B3: 118/0 | C3: =VLOOKUP(B3,'[102]Tower Schedule'!$C:$AB,4,FALSE) -> DB2+0 | D3: 119/0 | E3: =VLOOKUP(D3,'[102]Tower Schedule'!$C:$AB,4,FALSE) -> DD60+0 | F3: Power Line | G3: 243.824 | H3: GETCO | I3: 66 KV S/C NANDEWAR-WAGRA LINE (H FRAME) | J3: 1 | K3: Bharuch | L3: Submitted | M3: 45483 | N3: Y | O3: Y | P3: Approved
A4: =A3+1 -> 2 | B4: 119/3 | C4: =VLOOKUP(B4,'[102]Tower Schedule'!$C:$AB,4,FALSE) -> DA+9 | D4: 120/0 | E4: =VLOOKUP(D4,'[102]Tower Schedule'!$C:$AB,4,FALSE) -> DD60+3 | F4: Power Line | G4: 358.181 | H4: GETCO | I4: 66 KV D/C BHARUCH B TO VAGRA TAP VILAGAT LINE | J4: 1 | K4: Bharuch | L4: Submitted | M4: 45488 | N4: Y | O4: Y | P4: Approved
A5: =A4+1 -> 3 | B5: 121/0 | C5: =VLOOKUP(B5,'[102]Tower Schedule'!$C:$AB,4,FALSE) -> DB2+9 | D5: 121/1 | E5: =VLOOKUP(D5,'[102]Tower Schedule'!$C:$AB,4,FALSE) -> DB1+25 | F5: Power Line | G5: 276.141 | H5: GETCO | I5: 220 kv D/C VAGRA- THAM TSS LINE (U/C) | J5: 1 | K5: Bharuch | L5: Submitted | M5: 45547 | N5: Y | O5: Y | P5: Approved
A6: =A5+1 -> 4 | B6: 121/11 | C6: =VLOOKUP(B6,'[102]Tower Schedule'!$C:$AB,4,FALSE) -> DA+9 | D6: 124/0 | E6: =VLOOKUP(D6,'[102]Tower Schedule'!$C:$AB,4,FALSE) -> DD45+3 | F6: Power Line | G6: 396.394 | H6: GETCO | I6: 66 KV D/C Vilayat - Kukarwada Line | J6: 1 | K6: Bharuch | L6: Submitted | M6: 45488 | N6: Y | O6: Y | P6: Approved
A7: =A6+1 -> 5 | B7: 136/1 | C7: =VLOOKUP(B7,'[102]Tower Schedule'!$C:$AB,4,FALSE) -> DB1+9 | D7: 137/0 | E7: =VLOOKUP(D7,'[102]Tower Schedule'!$C:$AB,4,FALSE) -> DB2+3 | F7: Power Line | G7: 455.963 | H7: GETCO | I7: 66 KV S/C Hansot Robban Line | J7: 1 | K7: Bharuch | L7: Submitted | M7: 45547 | N7: Y | O7: Y | P7: Approved
A8: =A7+1 -> 6 | B8: 140/0 | C8: =VLOOKUP(B8,'[102]Tower Schedule'!$C:$AB,4,FALSE) -> DD60+25 | D8: 141/0 | E8: =VLOOKUP(D8,'[102]Tower Schedule'!$C:$AB,4,FALSE) -> DD60+25 | F8: Power Line | G8: 171.929 | H8: ESSAR | I8: 400 KV D/C HZR-GDR | J8: 1 | K8: Bharuch | L8: Submitted | M8: 45619 | N8: Y | O8: Y | P8: Approved
A9: =A8+1 -> 7 | B9: 141/6 | C9: =VLOOKUP(B9,'[102]Tower Schedule'!$C:$AB,4,FALSE) -> DA+3 | D9: 142/0 | E9: =VLOOKUP(D9,'[102]Tower Schedule'!$C:$AB,4,FALSE) -> DC1+9 | F9: Power Line | G9: 452.63 | H9: GETCO | I9: 66 KV S/C Panoli-Hansot | J9: 1 | K9: Bharuch | L9: Submitted | M9: 45483 | N9: Y | O9: Y | P9: Approved
A10: =A9+1 -> 8 | B10: 147/0 | C10: =VLOOKUP(B10,'[102]Tower Schedule'!$C:$AB,4,FALSE) -> DD60+25 | D10: 148/0 | E10: =VLOOKUP(D10,'[102]Tower Schedule'!$C:$AB,4,FALSE) -> DD60+25 | F10: Power Line | G10: 251.645 | H10: GETCO | I10: 400 KV D/C KOSAMBA - CHORANIA | J10: 1 | K10: Bharuch | L10: Submitted | M10: 45483 | N10: Y | O10: Y | P10: Approved
A11: =A10+1 -> 9 | B11: 149/0 | C11: =VLOOKUP(B11,'[102]Tower Schedule'!$C:$AB,4,FALSE) -> DD60+25 | D11: 150/0 | E11: =VLOOKUP(D11,'[102]Tower Schedule'!$C:$AB,4,FALSE) -> DD60+25 | F11: Power Line | G11: 258.002 | H11: TORRENT | I11: 400 KV D/C DGEN-NAVASARI | J11: 1 | K11: Surat | L11: Submitted | M11: 45488 | N11: Y | O11: Y | P11: Approved
A12: =A11+1 -> 10 | B12: 155/0 | C12: =VLOOKUP(B12,'[102]Tower Schedule'!$C:$AB,4,FALSE) -> DC1+18 | D12: 156/0 | E12: =VLOOKUP(D12,'[102]Tower Schedule'!$C:$AB,4,FALSE) -> DD45+18 | F12: Power Line | G12: 257.341 | H12: POWERGRID | I12: 220 KV D/C KWS-HAL | J12: 1 | K12: Surat | L12: Submitted | M12: 45488 | N12: Y | O12: Y | P12: IN RHQ (PGCIL)
A13: =A12+1 -> 11 | B13: 157/0 | C13: =VLOOKUP(B13,'[102]Tower Schedule'!$C:$AB,4,FALSE) -> #N/A | D13: 158/0 | E13: =VLOOKUP(D13,'[102]Tower Schedule'!$C:$AB,4,FALSE) -> #N/A | F13: Power Line | G13: 279.356 | H13: POWERGRID | I13: 765 KV D/C AHMEDABAD-NAVSARI | J13: 1 | K13: Surat | L13: Submitted | M13: 45488 | N13: Y | O13: Y | P13: Approved
A14: =A13+1 -> 12 | B14: 159/0 | C14: =VLOOKUP(B14,'[102]Tower Schedule'!$C:$AB,4,FALSE) -> #N/A | D14: 160/0 | E14: =VLOOKUP(D14,'[102]Tower Schedule'!$C:$AB,4,FALSE) -> DC2+0 | F14: Power Line | G14: 410.872 | H14: GETCO | I14: 66 KV S/C DINODA-KHARCH | J14: 1 | K14: Surat | L14: Submitted | M14: 45488 | N14: Y | O14: Y | P14: Approved
A15: =A14+1 -> 13 | B15: 162/0 | C15: =VLOOKUP(B15,'[102]Tower Schedule'!$C:$AB,4,FALSE) -> DD60+25 | D15: 163/0 | E15: =VLOOKUP(D15,'[102]Tower Schedule'!$C:$AB,4,FALSE) -> DD60+30 | F15: Power Line | G15: 328.496 | H15: TORRENT | I15: 400 KV D/C DGEN-NAVASARI | J15: 1 | K15: Surat | L15: Submitted | M15: 45488 | N15: Y | O15: Y | P15: Approved
... A35: =A34+1 -> 33 | B35: 210/0 | C35: =VLOOKUP(B35,'[102]Tower Schedule'!$C:$AB,4,FALSE) -> DB2+9+2MRC | D35: 211/0 | E35: =VLOOKUP(D35,'[102]Tower Schedule'!$C:$AB,4,FALSE) -> DB2+9 | F35: Power Line | G35: 397.662 | H35: GETCO | I35: 66 KV D/C Mota Madhi | J35: 1 | K35: Surat | L35: Submitted | M35: 45518 | N35: Y | O35: Y | P35: Approved
A36: =A35+1 -> 34 | B36: 210/0 | C36: =VLOOKUP(B36,'[102]Tower Schedule'!$C:$AB,4,FALSE) -> DB2+9+2MRC | D36: 211/0 | E36: =VLOOKUP(D36,'[102]Tower Schedule'!$C:$AB,4,FALSE) -> DB2+9 | F36: Power Line | H36: GETCO | I36: 66 KV D/C MOTA-Moti Fadoo | J36: 1 | K36: Surat | L36: Submitted | M36: 45518 | N36: Y | O36: Y | P36: Approved
A37: =A36+1 -> 35 | B37: 212/0 | C37: =VLOOKUP(B37,'[102]Tower Schedule'!$C:$AB,4,FALSE) -> DD45+9 | D37: 213/0 | E37: =VLOOKUP(D37,'[102]Tower Schedule'!$C:$AB,4,FALSE) -> DD60+35 | F37: Power Line | G37: 378.221 | H37: GETCO | I37: 220kV D/C MOTA - AMBHETA TRANSMISSION LINE | J37: 1 | K37: Surat | L37: Submitted | M37: 45516 | N37: Y | O37: Y | P37: Approved
A38: =A37+1 -> 36 | B38: 213/0 | C38: =VLOOKUP(B38,'[102]Tower Schedule'!$C:$AB,4,FALSE) -> DD60+35 | D38: 214/0 | E38: =VLOOKUP(D38,'[102]Tower Schedule'!$C:$AB,4,FALSE) -> DD60+30 | F38: Power Line | G38: 325.229 | H38: POWERGRID | I38: 400 KV D/C KAKARPAR - NAVSARI TRANSMISSION LINE | J38: 1 | K38: Surat | L38: Submitted | M38: 45516 | N38: Y | O38: Y | P38: IN CORPORATE (PGCIL)
A39: =A38+1 -> 37 | B39: 216/1 | C39: =VLOOKUP(B39,'[102]Tower Schedule'!$C:$AB,4,FALSE) -> DA+0 | D39: 216/2 | E39: =VLOOKUP(D39,'[102]Tower Schedule'!$C:$AB,4,FALSE) -> DA+0 | F39: Power Line | G39: 388 | H39: GETCO | I39: 66 KV KORODAR- AFVA LINE H FEAM | J39: 1 | K39: Surat | L39: Submitted | M39: 45516 | N39: Y | O39: Y | P39: Approved
A40: =A39+1 -> 38 | B40: 217/0 | C40: =VLOOKUP(B40,'[102]Tower Schedule'!$C:$AB,4,FALSE) -> DC2+9 | D40: 217/1 | E40: =VLOOKUP(D40,'[102]Tower Schedule'!$C:$AB,4,FALSE) -> DA+3 | F40: Power Line | G40: 398.005 | H40: GETCO | I40: 66 KV D/C LINE MOTA TO SARWAN TRANSMISSION LINE | J40: 1 | K40: Surat | L40: Submitted | M40: 45516 | N40: Y | O40: Y | P40: IN GETCO CORPORATE
A41: =A40+1 -> 39 | B41: 221/0 | C41: =VLOOKUP(B41,'[102]Tower Schedule'!$C:$AB,4,FALSE) -> DD60+30 | D41: 222/0 | E41: =VLOOKUP(D41,'[102]Tower Schedule'!$C:$AB,4,FALSE) -> DD60+25 | F41: Power Line | G41: 213.017 | H41: PGCIL | I41: 400 KV D/C NAV-BSR | J41: 1 | K41: Surat | L41: Submitted | M41: 45761 | N41: Y | O41: Y | P41: Approved
A42: =A41+1 -> 40 | B42: 229/0 | C42: =VLOOKUP(B42,'[102]Tower Schedule'!$C:$AB,4,FALSE) -> DD45+0 | D42: 230/0 | E42: =VLOOKUP(D42,'[102]Tower Schedule'!$C:$AB,4,FALSE) -> DC1+6 | F42: Power Line | G42: 179.981 | H42: GETCO | I42: 220 KV D/C Nav-Popda/Nav-Talangpur | J42: 1 | K42: Navsari | L42: Submitted | M42: 45761 | N42: Y | O42: Y | P42: Approved
A43: =A42+1 -> 41 | B43: 234/0 | C43: =VLOOKUP(B43,'[102]Tower Schedule'!$C:$AB,4,FALSE) -> DD60+18 | D43: 235/0 | E43: =VLOOKUP(D43,'[102]Tower Schedule'!$C:$AB,4,FALSE) -> DD60+9 | F43: Power Line | G43: 313.955 | H43: POWERGRID | I43: 220 KV D/C NAVSARI-NAVSARI LINE | J43: 1 | K43: Navsari | L43: Submitted | M43: 45520 | N43: Y | O43: Y | P43: Approved
A44: =A43+1 -> 42 | B44: 236/0 | C44: =VLOOKUP(B44,'[102]Tower Schedule'!$C:$AB,4,FALSE) -> DB+18 | D44: 237/0 | E44: =VLOOKUP(D44,'[102]Tower Schedule'!$C:$AB,4,FALSE) -> DB+25 | F44: Power Line | G44: 200.821 | H44: GETCO | I44: 132 KV S/C NAVSARI - POPDA CKT-1 LINE | J44: 1 | K44: Navsari | L44: Submitted | M44: 45480 | N44: Y | O44: Y | P44: Approved
A45: =A44+1 -> 43 | B45: 236/0 | C45: =VLOOKUP(B45,'[102]Tower Schedule'!$C:$AB,4,FALSE) -> DB+18 | D45: 237/0 | E45: =VLOOKUP(D45,'[102]Tower Schedule'!$C:$AB,4,FALSE) -> DB+25 | F45: Power Line | H45: GETCO | I45: 66 KV D/C NAV-EKL & TAVDI-VESSMA LINE | J45: 1 | K45: Navsari | L45: Submitted | M45: 45480 | N45: Y | O45: Y | P45: Approved
A46: =A45+1 -> 44 | B46: 237/0 | C46: =VLOOKUP(B46,'[102]Tower Schedule'!$C:$AB,4,FALSE) -> DB+25 | D46: 238/0 | E46: =VLOOKUP(D46,'[102]Tower Schedule'!$C:$AB,4,FALSE) -> DC+25 | F46: Power Line | G46: 202.277 | H46: GETCO | I46: 132 KV S/C NAV-POPDA CKT-2 LINE | J46: 1 | K46: Navsari | L46: Submitted | M46: 45480 | N46: Y | O46: Y | P46: Approved
A47: =A46+1 -> 45 | B47: 247/0 | C47: =VLOOKUP(B47,'[102]Tower Schedule'!$C:$AB,4,FALSE) -> DD60+35 | D47: 248/0 | E47: =VLOOKUP(D47,'[102]Tower Schedule'!$C:$AB,4,FALSE) -> DD60+35 | F47: Power Line | G47: 286.451 | H47: POWERGRD | I47: 765 KV D/C AHMEDABAD-NAVSARI | J47: 1 | K47: Navsari | L47: Submitted | M47: 45629 | N47: Y | O47: Y | P47: Approved
A48: =A47+1 -> 46 | B48: 250/3 | C48: =VLOOKUP(B48,'[102]Tower Schedule'!$C:$AB,4,FALSE) -> DA+9 | D48: 250A/0 | E48: =VLOOKUP(D48,'[102]Tower Schedule'!$C:$AB,4,FALSE) -> DB1+3(RC+2) | F48: Power Line | G48: 382.952 | H48: GETCO | I48: 66 KV D/C Talangpur-Mangrol line | J48: 1 | K48: Navsari | L48: Submitted | M48: 45667 | N48: Y | O48: Y | P48: Approved
A49: =A48+1 -> 47 | B49: 253/0 | C49: =VLOOKUP(B49,'[102]Tower Schedule'!$C:$AB,4,FALSE) -> DD45+35 | D49: 254/0 | E49: =VLOOKUP(D49,'[102]Tower Schedule'!$C:$AB,4,FALSE) -> DD45+35 | F49: Power Line | G49: 304.46 | H49: GETCO | I49: LILO OF 220 KV TALANGPORE (SACHIN)-NAVSARI LINE AND TALANGPORE (SACHIN)-VAV LINE AT 765 KV NAVSARI(NEW)S/S OF ISTS | J49: 1 | K49: Navsari | L49: Submitted | M49: 45730 | N49: Y | O49: Y | P49: Approved
A50: =A49+1 -> 48 | B50: 256/1 | C50: =VLOOKUP(B50,'[102]Tower Schedule'!$C:$AB,4,FALSE) -> DA+9 | D50: 257/0 | E50: =VLOOKUP(D50,'[102]Tower Schedule'!$C:$AB,4,FALSE) -> DB2+9 | F50: Power Line | G50: 272.781 | H50: GETCO | I50: 66 KV D/C Mangrol-Ubarhat Line | J50: 1 | K50: Navsari | L50: Submitted | M50: 45480 | N50: Y | O50: Y | P50: Approved
A51: =A50+1 -> 49 | B51: 152/0 | C51: =VLOOKUP(B51,'[102]Tower Schedule'!$C:$AB,4,FALSE) -> DD60+3 | D51: 153/0 | E51: =VLOOKUP(D51,'[102]Tower Schedule'!$C:$AB,4,FALSE) -> DD60+3 | F51: Railway | G51: 297.024 | H51: IR | I51: RAILWAY LINE KOSAMBA-HATURAN | J51: 1 | K51: Navsari | L51: Submitted | M51: 45560
A52: =A51+1 -> 50 | B52: 166/0 | C52: =VLOOKUP(B52,'[102]Tower Schedule'!$C:$AB,4,FALSE) -> DD60+0 | D52: 167/0 | E52: =VLOOKUP(D52,'[102]Tower Schedule'!$C:$AB,4,FALSE) -> DD60+9 | F52: Railway | G52: 274.311 | H52: IR | I52: RAILWAY LINE NOT IN USE | J52: 1 | K52: Navsari | L52: Submitted | M52: 45556 | N52: Y | O52: Y
A53: =A52+1 -> 51 | B53: 215/0 | C53: =VLOOKUP(B53,'[102]Tower Schedule'!$C:$AB,4,FALSE) -> DD60+3 | D53: 216/0 | E53: =VLOOKUP(D53,'[102]Tower Schedule'!$C:$AB,4,FALSE) -> DD60+3 | F53: Railway | G53: 231.411 | H53: IR | I53: RAILWAY LINE BARDOLI-GANGADHARA | J53: 1 | K53: Navsari | L53: Submitted | M53: 45591 | N53: Y | O53: Y | P53: Approved
A54: =A53+1 -> 52 | B54: 242/0 | C54: =VLOOKUP(B54,'[102]Tower Schedule'!$C:$AB,4,FALSE) -> DD60+3 | D54: 243/0 | E54: =VLOOKUP(D54,'[102]Tower Schedule'!$C:$AB,4,FALSE) -> DD60+3 | F54: Railway | G54: 280.015 | H54: IR | I54: RAILWAY LINE NAVSARI-MAROLI | J54: 1 | K54: Navsari | L54: Submitted | M54: 45547 | N54: Y | O54: Y | P54: Approved
A55: =A54+1 -> 53 | B55: 234/0 | C55: =VLOOKUP(B55,'[102]Tower Schedule'!$C:$AB,4,FALSE) -> DD60+18 | D55: 235/0 | E55: =VLOOKUP(D55,'[102]Tower Schedule'!$C:$AB,4,FALSE) -> DD60+9 | F55: Bullet Train | H55: NHSRL | I55: BULLET TRAIN | J55: 1 | K55: Navsari | L55: Submitted | M55: 45546 | N55: Y | O55: Y | P55: Approved
A56: =A55+1 -> 54 | B56: 143/0 | C56: =VLOOKUP(B56,'[102]Tower Schedule'!$C:$AB,4,FALSE) -> DD60+25 | D56: 144/0 | E56: =VLOOKUP(D56,'[102]Tower Schedule'!$C:$AB,4,FALSE) -> DD60+25 | F56: Bullet Train | G56: 252.547 | H56: NHSRL | I56: BULLET TRAIN | J56: 1 | K56: Bharuch | L56: Submitted | M56: 45551 | N56: Y | O56: Y | P56: Approved
A57: =A56+1 -> 55 | B57: 133/2 | C57: =VLOOKUP(B57,'[102]Tower Schedule'!$C:$AB,4,FALSE) -> DB1+0 | D57: 133/3 | E57: =VLOOKUP(D57,'[102]Tower Schedule'!$C:$AB,4,FALSE) -> DB1+0 | F57: NH | G57: 250 | H57: NH | I57: NH 64 ( Delhi - Mumbai ) | J57: 1 | K57: Bharuch | L57: Submitted | M57: 45539 | N57: Y | O57: Y | P57: Approved
A58: =A57+1 -> 56 | B58: 218/0 | C58: =VLOOKUP(B58,'[102]Tower Schedule'!$C:$AB,4,FALSE) -> DD60+3 | D58: 219/0 | E58: =VLOOKUP(D58,'[102]Tower Schedule'!$C:$AB,4,FALSE) -> DD45+3 | F58: NH | G58: 239.469 | H58: NH | I58: NH 53 | J58: 1 | K58: Surat | L58: Submitted | M58: 45766 | N58: Y | O58: Y | P58: Approved
A59: =A58+1 -> 57 | B59: 231/0 | C59: =VLOOKUP(B59,'[102]Tower Schedule'!$C:$AB,4,FALSE) -> DB1+0 | D59: 232/0 | E59: =VLOOKUP(D59,'[102]Tower Schedule'!$C:$AB,4,FALSE) -> DB1+0 | F59: NH | G59: 246.982 | H59: NH | I59: NH 48 | J59: 1 | K59: Navsari | L59: Submitted | M59: 45765 | N59: Y | O59: Y | P59: Approved
...

Sheet Sheet2
A3: Hotline Stringing total KM : 17.112 Km
A5: Sl NO | B5: Description | C5: Dec'25 | D5: Jan'25 | E5: Feb'25 | F5: Mar'25 | G5: Apr'25 | H5: May'25 | I5: June'25
A6: 1 | B6: Hotline Stringing | C6: =17.112/7 -> 2.4445714 | D6: =17.112/7 -> 2.4445714 | E6: =17.112/7 -> 2.4445714 | F6: =17.112/7 -> 2.4445714 | G6: =17.112/7 -> 2.4445714 | H6: =17.112/7 -> 2.4445714 | I6: =17.112/7 -> 2.4445714

Sheet Soil Inv.
A1: VNTL PROJECT - SOIL INVESTIGATION LOCATIONS
A2: Sl. No. | B2: Loc. No. | C2: TOT | D2: RC | E2: Status | F2: Classification | G2: Approval Letter Status
A3: 1 | B3: 121/0 | C3: DB2+9 | E3: Done | F3: WBC | G3: Approved
A4: 2 | B4: 129/0 | C4: DD45+25 | E4: Done | F4: PILE | G4: Approved
A5: 3 | B5: 130/0 | C5: DD45+25 | E5: Done | F5: PILE | G5: Approved
A6: 4 | B6: 131/0 | C6: DD60+9 | D6: 7 | E6: Done | F6: Sandy Dry Soil | G6: Approved
A7: 5 | B7: 135/0 | C7: DD60+0 | E7: Done | F7: 2 Mtr WBC & 1.5 Mtr FS | G7: Approved
A8: 6 | B8: 140/0 | C8: DD60+25 | E8: Done | F8: WBC | G8: Approved
A9: 7 | B9: 144/0 | C9: DD60+25 | E9: Done | F9: WBC | G9: Approved
A10: 8 | B10: 147/0 | C10: DD60+25 | E10: Done | F10: WBC | G10: Approved
A11: 9 | B11: 150/0 | C11: DD60+25 | E11: Done | F11: WBC | G11: Approved
A12: 10 | B12: 153/0 | C12: DD60+3 | E12: Done | F12: WBC | G12: Approved
A13: 11 | B13: 158/0 | C13: DD60+43 | D13: 1 | E13: Done | F13: WBC | G13: Approved
A14: 12 | B14: 162/0 | C14: DD60+25 | E14: Done | F14: WBC | G14: Approved
A15: 13 | B15: 166/0 | C15: DD60+0 | E15: Done | F15: WBC | G15: Approved
A16: 14 | B16: 169/0 | C16: DD60+25 | E16: Done | F16: WBC | G16: Approved
A17: 15 | B17: 178/0 | C17: DD60+6 | E17: Done | F17: WBC | G17: Approved
A18: 16 | B18: 182/0 | C18: DD45+0 | E18: Done | F18: WBC | G18: Approved
A19: 17 | B19: 191/0 | C19: DD60+9 | E19: Done | F19: 2 Mtr WBC & 1.5 Mtr Normal Dry | G19: Approved
A20: 18 | B20: 194/0 | C20: DD60+25 | E20: Done | F20: WBC | G20: Approved
A21: 19 | B21: 198/0 | C21: DD60+6 | E21: Done | F21: WBC | G21: Approved
A22: 20 | B22: 205/0 | C22: DD60+25 | E22: Done | F22: WBC | G22: Approved
A23: 21 | B23: 214/0 | C23: DD60+30 | E23: Done | F23: WBC | G23: Approved
A24: 22 | B24: 216/0 | C24: DD60+3 | E24: Done | F24: WBC | G24: Approved
A25: 23 | B25: 219/0 | C25: DD45+3 | E25: Done | F25: WBC | G25: Approved
... A27: 25 | B27: 232/0 | C27: DB1+0 | E27: Done | F27: WBC | G27: Approved
A28: 26 | B28: 235/0 | C28: DD60+9 | D28: 2 | E28: Done | F28: WBC | G28: Approved
A29: 27 | B29: 243/0 | C29: DD60+3 | E29: Done | F29: WBC | G29: Approved
A30: 28 | B30: 248/0 | C30: DD60+35 | D30: 2 | E30: Done | F30: WBC | G30: Approved

Sheet Survey Anx
A1: TL- 04 765 kV D/C Vataman-Navsari Transmission Line
