Workbook
Name \0: #REF!
Name \A: #REF!
Name \B: #REF!
Name \C: #REF!
Name \c1: #REF!
Name \D: #REF!
Name \g: #REF!
Name \H: #REF!
Name \i: #REF!
Name \M: #REF!
Name \N: #REF!
Name \P: #REF!
Name \R: #REF!
Name \S: #REF!
Name \U: #REF!
Name \V: #REF!
Name \z: #REF!
Name _: "tcap"
Name __________________________b111121: '[1]PACK (B)'!#REF!
Name _________________________b111121: '[1]PACK (B)'!#REF!
Name ________________________b111121: '[1]PACK (B)'!#REF!
Name _______________________b111121: '[1]PACK (B)'!#REF!
Name ______________________b111121: '[1]PACK (B)'!#REF!
Name ______________________TAB1: [2]TABLES!$A$2:$C$16
Name _____________________b111121: '[1]PACK (B)'!#REF!
Name _____________________TAB1: [2]TABLES!$A$2:$C$16
Name ____________________b111121: '[1]PACK (B)'!#REF!
Name ____________________TAB1: [2]TABLES!$A$2:$C$16
Name ___________________b111121: '[1]PACK (B)'!#REF!
Name ___________________TAB1: [2]TABLES!$A$2:$C$16
Name __________________b111121: '[1]PACK (B)'!#REF!
Name __________________TAB1: [5]TABLES!$A$2:$C$16
Name _________________b111121: '[1]PACK (B)'!#REF!
Name _________________TAB1: [6]TABLES!$A$2:$C$16
Name ________________b111121: '[1]PACK (B)'!#REF!
Name ________________TAB1: [6]TABLES!$A$2:$C$16
Name _______________b111121: '[1]PACK (B)'!#REF!
Name _______________TAB1: [6]TABLES!$A$2:$C$16
Name ______________b111121: '[1]PACK (B)'!#REF!
Name ______________TAB1: [6]TABLES!$A$2:$C$16
Name _____________A65537: #REF!
Name _____________b111121: '[1]PACK (B)'!#REF!
Name _____________TAB1: [6]TABLES!$A$2:$C$16
Name ____________A655600: #REF!
Name ____________b111121: '[1]PACK (B)'!#REF!
Name ____________drg1: #REF!
Name ____________TAB1: [6]TABLES!$A$2:$C$16
Name ___________A65537: #REF!
Name ___________A655600: #REF!
Name ___________a655601: #REF!
Name ___________b111121: '[1]PACK (B)'!#REF!
Name ___________Ki1: [7]grid!$C$182
Name ___________Ki2: [7]grid!$C$191
Name ___________TAB1: [6]TABLES!$A$2:$C$16
Name __________A65537: #REF!
Name __________A655600: #REF!
Name __________a655601: #REF!
Name __________a999999: #REF!
Name __________b111121: '[1]PACK (B)'!#REF!
Name __________drg1: #REF!

Sheet DPR-Summary
B2: LINE NAME- 765 kV D/C HEXA BEAWAR MANDSAUR TRANSMISSION LINE
B3: CLIENT-POWERGRID BEAWAR MANDSAUR TRANSMISSION LIMITED
B4: DAILY PROGRESS REPORT (TA-505)
B5: NOA Date :- 22-July-2024 | F5: Completion Date :- 21-June-2026 | K5: Date:- 31th March 2026.
B6: SUPPLY VALUE = 458.32 Cr. | F6: SERVICE VALUE = 94.23 Cr. | K6: F&I VALUE = 9.48 Cr.
B7: PARTICULARS | C7: UOM | D7: Total | E7: Comp | F7: Balance | G7: March'26 | I7: WIP | J7: Cumulative | K7: April'26 | L7: May'26 | M7: Remarks
D8: Qty | E8: Till | F8: as on | G8: Plan | H8: Actual | K8: Plan | L8: Plan
E9: 46054 | F9: 1st Feb-26
B10: Detail Survey | C10: KM | D10: 139.6 | E10: 139.6 | F10: =D10-E10 -> 0
B11: Check Survey | C11: KM | D11: 139.6 | E11: 139.6 | F11: =D11-E11 -> 0
B12: Stub Supply | C12: SET | D12: 379 | E12: 371 | F12: =D12-E12 -> 8 | H12: 0 | J12: =E12+H12 -> 371
B13: FOUNDATION | C13: NOS | D13: 379 | E13: 356 | F13: =D13-E13 -> 23 | G13: 15 | H13: =J13-E13 -> 8 | I13: 7 | J13: =Foundation!I9 -> 364 | K13: 8 | M13: 10 Locations are under severe RoW.
B14: No of Gangs | G14: 2
B15: Tower Supply | C15: SETS | D15: 379 | E15: 359 | F15: =D15-E15 -> 20 | J15: =E15+H15 -> 359
B16: TOWER ERECTION | C16: NOS | D16: 379 | E16: 300 | F16: =D16-E16 -> 79 | G16: 26 | H16: =J16-E16 -> 21 | I16: 7 | J16: =Foundation!I13 -> 321 | K16: 50
B17: No of Gangs | G17: 7
B18: AL59 Zebra Conductor Supply | C18: KM | D18: 4970.6 | E18: 4090 | F18: =D18-E18 -> 880.6 | J18: =E18+H18 -> 4090
B19: Earthwire Supply | C19: KM | D19: 138 | E19: 138 | F19: =D19-E19 -> 0 | J19: =E19+H19 -> 138
B20: Insulator Supply | C20: EA | D20: 16332 | E20: 12823 | F20: =D20-E20 -> 3509 | H20: =1600+1089 -> 2689 | J20: =E20+H20 -> 15512
B21: Hardware Fittings Supply | C21: % | D21: 1 | E21: 0.9 | F21: =D21-E21 -> 0.1 | J21: 0.9
B22: Stringing (Final Sag) | C22: KM | D22: 139.6 | E22: 6.55 | F22: =D22-E22 -> 133.05 | G22: 20 | H22: ='Stringing Compiled'!Q236-'DPR-Summary'!E22 -> 6.489 | J22: =E22+H22 -> 13.039 | K22: 30
B23: Stringing (Rough Sag) | C23: KM | D23: 139.6 | E23: 6.55 | F23: =D23-E23 -> 133.05 | G23: 20 | H23: =H22+0.967 -> 7.456 | J23: =J22+0.967 -> 14.006 | K23: 30
B24: TSE Gangs | G24: 1
B25: Manual Gangs | G25: 1
B26: Revetment | C26: CUM
B27: Gang

Sheet Sheet1
B1: TYPE OF TOWERS | C1: NO OF TOWERS
B2: DA+0 DFR | C2: 24
B3: DA+0 DRY | C3: 13
B4: DA+0 WET | C4: 4
B5: DA+0 WFR | C5: 18
B6: DA+3/6/9 DRY | C6: 11
B7: DA+3/6/9 DFR | C7: 25
B8: DA+3/6/9 WET | C8: 5
B9: DA+3/6/9 WFR | C9: 17
B10: TOTAL DA TYPE | C10: =SUM(C2:C9) -> 117
B11: DB1+0 DRY | C11: 2
B12: DB1+3/6/9 DFR | C12: 1
B13: DB1+3/6/9 WET | C13: 2
B14: DB2+0 DFR | C14: 2
B15: DB2+0 DRY | C15: 1
B16: DB2+0 WFR | C16: 1
B17: TOTAL DB TYPE | C17: =SUM(C11:C16) -> 9
B18: DC1+0 DFR | C18: 1
B19: DC1+0 WFR | C19: 1
B20: DC1+3/6/9 DFR | C20: 1
B21: DC2+0 WET | C21: 1
B22: DC2+3/6/9 DFR | C22: 1
B23: DC2+3/6/9 DRY | C23: 1
B24: DC2+3/6/9 WFR | C24: 1
B25: TOTAL DC TYPE | C25: =SUM(C18:C24) -> 7
B26: DD45+0 DFR | C26: 2
B27: DD45+9 DFR | C27: 1
B28: DD45+9 WFR | C28: 1
B29: DD60+18 DFR | C29: 1
B30: DD60+9 WFR | C30: 2
B31: TOTAL DD TYPE | C31: =SUM(C26:C30) -> 7
B32: TOTAL TOWERS | C32: =C31+C25+C17+C10 -> 140

Sheet Project Details
A1: Project Code | B1: Project Name | C1: Client Name | D1: NOA Start Date | E1: LOA End Date | F1: Planning Engineer | G1: PCH | H1: Regional Manager | I1: Project Manger | J1: Section Incharge | K1: Supervisor
A2: TA 505 | B2: 765 Kv D/C Beawar-Mandsaur T/L | C2: PBMTL | D2: 22-07-2024 | E2: 21-06-2026 | F2: Mr. Partha Pratim Pal | G2: Mr. Nabajit Baruah | H2: Mr. Nabajit Baruah | I2: Mr. Sushil Kr Tiwari | J2: Mr.Deepak Anand | K2: Nunuchand Mahto
J3: Mr.Bapan Mandal | K3: Birkha Subba
J4: Mr.Panneri Satish | K4: Dilip Kumar
J5: Mr. Varun Mishra | K5: Teklal Mahato
K6: Munid Meena
K7: Mortuj Ali
K8: Devdas Malik
K9: Jayprakash Nishad
K10: Kumar Singh
K11: K. Sanjeevan
K12: Mridul Baruah
K13: Binda Shah
K14: Prasanta Sahana
K15: Lalit Sahoo
K16: Mahendra Narnaware
K17: Ramprasad
... K22: Rajkumar S

Sheet Sheet5
A1: Loc NO | B1: TOT | C1: Classification | D1: Type of Earthing
A2: 100/0 | B2: DD45+0 | C2: WET | D2: Pipe Type
A3: 101/0 | B3: DC1+3 | C3: DFR | D3: Counter Poise
A4: 101/1 | B4: DA+3 | C4: WFR | D4: Counter Poise
A5: 101/2 | B5: DA+9 | C5: WFR | D5: Counter Poise
A6: 101/3 | B6: DA+3 | C6: WFR | D6: Counter Poise
A7: 101/4 | B7: DA+6 | C7: WFR | D7: Counter Poise
A8: 101/5 | B8: DA+0 | C8: WFR | D8: Counter Poise
A9: 101/6 | B9: DA+3 | C9: WFR | D9: Counter Poise
A10: 101/7 | B10: DA+3 | C10: WFR | D10: Counter Poise
A11: 101/8 | B11: DA-3 | C11: DRY | D11: Pipe Type
A12: 102/0 | B12: DC2+3 | C12: DRY | D12: Pipe Type
... A91: 99/8 | B91: DA+6 | C91: WET | D91: Pipe Type

Sheet Foundation
B1: 765 kV D/C BEAWAR MANDSAUR TRANSMISSION LINE
B2: PROGRESS SUMMARY DETAIL
B3: NOA Date: 22-July-2024 | I3: Completion Date : 21-June-2026 | M3: Date : 27-05-25
B4: SUPPLY VALUE = 458 Cr. | I4: SERVICE VALUE = 94.23 Cr. | M4: F&I VALUE = 9.48 Cr. | S4: =458+94.23+9.48 -> 561.71
B5: Sr. No. | C5: Activity | E5: UOM | G5: Total Qty. | H5: L2 Qty. | I5: Completed | J5: Balance | K5: Submitted | L5: WIP | M5: Remarks
B6: 1 | C6: Details Survey | E6: Kms | G6: 136.705 | H6: 126 | I6: =87.055+32.269+7 -> 126.324 | J6: =G6-I6 -> 10.381 | K6: =17.381-7 -> 10.381
B7: 2 | C7: Check Survey | E7: Kms | G7: 136.705 | H7: 126 | I7: =69.41+32.269+7 -> 108.679 | J7: =G7-I7 -> 28.026
B8: 3 | C8: Soil Testing | E8: Nos | G8: 34 | H8: 34
B9: 4 | C9: Foundation | E9: Nos | G9: 371 | H9: 165 | I9: =S27 -> 364 | J9: =G9-I9 -> 7 | L9: =COUNTIF($S$28:$S$1154, "WIP") -> 0
C10: Gang | E10: Nos | I10: 13
C11: Manpower | E11: Nos
B12: 5 | C12: Earthing | E12: Nos | G12: 346 | I12: 94 | J12: =G12-I12 -> 252
B13: 6 | C13: Erection | E13: Nos | G13: =G9 -> 371 | H13: 98 | I13: ='Erection Compiled'!I5 -> 321 | J13: =G13-I13 -> 50 | L13: =COUNTIF('Erection Compiled'!I6:I393,"WIP") -> 0
C14: Gang | E14: Nos | I14: 4
C15: Manpower | E15: Nos
B16: 7 | C16: Stringing | E16: Nos | G16: =G7 -> 136.705 | H16: 0 | I16: 0 | J16: =G16-I16 -> 136.705
C17: Gang | E17: Nos
C18: Manpower | E18: Nos
B20: Issue : i. DS - pending for approval ii. CS - pending for approval
B21: Supply : Stub : DA : 177 Set, DB : 21 Set, DC : 16 Set, DD45 : 9 Set, DD60 : 13 set Earthing : CP : 84 Set, Pipe : 40 Nos, Rod : 40 Nos Tower : DA BB=107 Set,+0M=52, +3M=35,+6M=19, +9M=3, -1.5=6, -3=14
B23: KEC INTERNATIONAL LIMITED
B24: FOUNDATION DETAIL OF 765KV D/C BEAWAR-MANDSAUR TR LINE
B25: Sr. No | C25: Loc No. | D25: Type of Tower | E25: TOF | F25: Region | G25: Selector | H25: Cement (Bags) | K25: Conc Vol | M25: Excv Vol(m3) | N25: R/F (KG) | O25: Wt of Stub(MT) | P25: Rev(Inr) | Q25: Month of Execution | R25: Sub Contractor | S25: Status | T25: Excavation | V25: Casting | X25: Remarks if any
H26: RCC | I26: PCC | J26: Toal Cement | K26: M 20(m3) | L26: M 10(m3) | T26: Start | U26: Completion | V26: Start | W26: Completion
B27: Total = | H27: =SUM(H28:H432) -> 140369.9 | I27: =SUM(I28:I432) -> 7232.2692 | J27: =SUM(J28:J432) -> 115017.55 | K27: =SUM(K28:K432) -> 17533.203 | L27: =SUM(L28:L432) -> 1623.063 | M27: =SUM(M28:M432) -> 106606.56 | N27: =SUM(N28:N432) -> 1168820.4 | O27: =SUM(O28:O432) -> 440.96251 | P27: =SUM(P28:P432) -> 3.0707497e+08 | S27: =COUNTIF(S28:S599,"Complete") -> 364
C28: 101/2 | D28: DA+9 | E28: WFR | F28: RAJ | G28: DA+9 WFR | H28: 383 | I28: 20 | J28: 403 | K28: 47.77 | L28: 4.46 | M28: 264.87 | N28: 2353 | O28: 0.866276 | P28: 1126247.4 | Q28: 45566 | R28: RST | S28: Complete | T28: 45546 | U28: 45561 | V28: 45567 | W28: 45571 | Y28: 1
C29: 100/0 | D29: DD45+0 | E29: WET | F29: RAJ | H29: =K29*8 -> 1239.68 | I29: =L29*4.4 -> 70.18 | J29: =SUM(H29:I29) -> 1309.86 | K29: 154.96 | L29: 15.95 | M29: 1192.7 | N29: 15096 | O29: 2.495 | Q29: 45944 | R29: Sumit Const/Om Prakash | S29: Complete | W29: 45946
C30: 101/0 | D30: DC1+3 | E30: DFR | F30: RAJ | H30: =K30*8 -> 614.16 | I30: =L30*4.4 -> 27.984 | J30: =SUM(H30:I30) -> 642.144 | K30: 76.77 | L30: 6.36 | M30: 388.74 | N30: 3855 | O30: 2.348757 | P30: 1765261 | Q30: 45791 | R30: Sumit Const/Om Prakash | S30: Complete | W30: 45808
C31: 101/1 | D31: DA+3 | E31: WFR | F31: RAJ | G31: DA+9 WFR | H31: 383 | I31: 20 | J31: 403 | K31: 47.77 | L31: 4.46 | M31: 264.87 | N31: 2353 | O31: 0.866276 | P31: 1126247.4 | Q31: 45597 | R31: RST | S31: Complete | T31: 45598 | U31: 45604 | V31: 45609 | W31: 45610 | Y31: 2
C32: 101/3 | D32: DA+3 | E32: WFR | F32: RAJ | G32: DA+9 WFR | H32: 383 | I32: 20 | J32: 403 | K32: 47.77 | L32: 4.46 | M32: 264.87 | N32: 2353 | O32: 0.866276 | P32: 1126247.4 | Q32: 45566 | R32: RST | S32: Complete | T32: 45566 | U32: 45571 | V32: 45573 | W32: 45576 | Y32: 1
C33: 101/4 | D33: DA+6 | E33: WFR | F33: RAJ | G33: DA+9 WFR | H33: 383 | I33: 20 | J33: 403 | K33: 47.77 | L33: 4.46 | M33: 264.87 | N33: 2353 | O33: 0.866276 | P33: 1126247.4 | Q33: 45566 | R33: RST | S33: Complete | T33: 45551 | U33: 45556 | V33: 45584 | W33: 45586 | Y33: 1
C34: 101/5 | D34: DA+0 | E34: WFR | F34: RAJ | G34: DA+0 WFR | H34: 333 | I34: 19 | J34: 352 | K34: 41.54 | L34: 4.23 | M34: 250.46 | N34: 1909 | O34: 0.866276 | P34: 984923.64 | Q34: 45566 | R34: RST | S34: Complete | T34: 45557 | U34: 45561 | V34: 45588 | W34: 45590 | Y34: 1
C35: 101/6 | D35: DA+3 | E35: WFR | F35: RAJ | G35: DA+9 WFR | H35: 383 | I35: 20 | J35: 403 | K35: 47.77 | L35: 4.46 | M35: 264.87 | N35: 2353 | O35: 0.866276 | P35: 1126247.4 | Q35: 45597 | R35: RST | S35: Complete | T35: 45589 | U35: 45591 | V35: 45595 | W35: 45598 | Y35: 1
C36: 101/7 | D36: DA+3 | E36: WFR | F36: RAJ | G36: DA+9 WFR | H36: 383 | I36: 20 | J36: 403 | K36: 47.77 | L36: 4.46 | M36: 264.87 | N36: 2353 | O36: 0.866276 | P36: 1126247.4 | Q36: 45597 | R36: RST | S36: Complete | T36: 45606 | U36: 45610 | V36: 45613 | W36: 45614 | Y36: 2
C37: 101/8 | D37: DA-3 | E37: DRY | F37: RAJ | G37: DA+0 DRY | H37: 236 | I37: 13 | J37: 249 | K37: 29.49 | L37: 2.86 | M37: 233.05 | N37: 1526 | O37: 0.866276 | P37: 645061.95 | Q37: 45597 | R37: RST | S37: Complete | T37: 45593 | U37: 45598 | V37: 45603 | W37: 45604 | Y37: 2
C38: 102/0 | D38: DC2+3 | E38: DRY | F38: RAJ | G38: DC2+9 DRY | H38: 856 | I38: 38 | J38: 894 | K38: 106.91 | L38: 8.53 | M38: 653.08 | N38: 5502 | O38: 2.348757 | P38: 2257063.8 | Q38: 45627 | R38: RST | S38: Complete | T38: 45618 | U38: 45621 | V38: 45637 | W38: 45640 | Y38: 3
C39: 103/0 | D39: DC1+6 | E39: DFR | F39: RAJ | H39: =K39*8 -> 614.16 | I39: =L39*4.4 -> 27.984 | J39: =SUM(H39:I39) -> 642.144 | K39: 76.77 | L39: 6.36 | M39: 388.74 | N39: 3855 | O39: 2.348757 | P39: 1765261 | Q39: 45789 | R39: Sumit Const/Om Prakash | S39: Complete | W39: 45799
C40: 103/1 | D40: DA+0 | E40: DRY | F40: RAJ | H40: 236 | I40: 13 | J40: 249 | K40: 29.49 | L40: 2.86 | M40: 233.05 | N40: 1526 | O40: 0.866276 | P40: 645061.95 | Q40: 45784 | R40: Sumit Const/Om Prakash | S40: Complete | W40: 45788
C41: 103/2 | D41: DA+0 | E41: DRY | F41: RAJ | H41: 236 | I41: 13 | J41: 249 | K41: 29.49 | L41: 2.86 | M41: 233.05 | N41: 1526 | O41: 0.866276 | P41: 645061.95 | Q41: 45780 | R41: Sumit Const/Om Prakash | S41: Complete | W41: 45790
B42: 45 | C42: 103/3 | D42: DA+0 | E42: DFR | F42: RAJ | H42: 221 | I42: 12 | J42: 233 | K42: 27.61 | L42: 2.61 | M42: 146.96 | N42: 1450 | O42: 0.866276 | P42: 650458.11 | Q42: 45780 | R42: Sumit Const/Om Prakash | S42: Complete | W42: 45785
...

Sheet Erection Compiled
N3: Date : 24-03-2026
B4: Sr. No | C4: Location No. | D4: Tower Type | E4: Tower Weight | F4: Rev(Inr) | G4: Month of Execution | H4: Gang Name | I4: Status | J4: Starting Date | K4: Completion Date | L4: No of Compl. Days | M4: Region | N4: Remarks
E5: =SUM(E6:E393) -> 15243.412 | F5: =SUM(F6:F393) -> 1.6676293e+08 | I5: =COUNTIF(I6:I393,"Completed") -> 321
B6: 1 | C6: 101/2 | D6: DA+9 | E6: 45.697022 | F6: =E6*10940 -> 499925.42 | G6: 45658 | H6: Jwala Singh | I6: Completed | J6: 45671 | K6: 45676 | L6: =K6-J6 -> 5 | M6: Raj
B7: 2 | C7: 101/1 | D7: DA+3 | E7: 37.931088 | F7: =E7*10940 -> 414966.1 | G7: 45658 | H7: Jwala Singh | I7: Completed | J7: 45678 | K7: 45681 | L7: =K7-J7 -> 3 | M7: Raj
B8: 3 | C8: 101/3 | D8: DA+3 | E8: 37.931088 | F8: =E8*10940 -> 414966.1 | G8: 45658 | H8: Jwala Singh | I8: Completed | J8: 45681 | K8: 45684 | L8: =K8-J8 -> 3 | M8: Raj
B9: 4 | C9: 101/4 | D9: DA+6 | E9: 43.804424 | F9: =E9*10940 -> 479220.4 | G9: 45658 | H9: Jwala Singh | I9: Completed | J9: 45684 | K9: 45688 | L9: =K9-J9 -> 4 | M9: Raj
B10: 5 | C10: 101/5 | D10: DA+0 | E10: 36.159756 | F10: =E10*10940 -> 395587.73 | G10: 45689 | H10: Jwala Singh | I10: Completed | J10: 45689 | K10: 45692 | L10: =K10-J10 -> 3 | M10: Raj
B11: 6 | C11: 101/6 | D11: DA+3 | E11: 37.931088 | F11: =E11*10940 -> 414966.1 | G11: 45689 | H11: Jwala Singh | I11: Completed | J11: 45693 | K11: 45696 | L11: =K11-J11 -> 3 | M11: Raj
B12: 7 | C12: 101/7 | D12: DA+3 | E12: 37.931088 | F12: =E12*10940 -> 414966.1 | G12: 45689 | H12: Jwala Singh | I12: Completed | J12: 45697 | K12: 45700 | L12: =K12-J12 -> 3 | M12: Raj
B13: 8 | C13: 101/8 | D13: DA-3 | E13: 34.78981 | F13: =E13*10940 -> 380600.52 | G13: 45689 | H13: Jwala Singh | I13: Completed | J13: 45701 | K13: 45703 | L13: =K13-J13 -> 2 | M13: Raj
B14: 9 | C14: 110/7 | D14: DA+3 | E14: 37.931088 | F14: =E14*10940 -> 414966.1 | G14: 45689 | H14: Jwala Singh | I14: Completed | J14: 45705 | K14: 45708 | L14: =K14-J14 -> 3 | M14: Raj
B15: 10 | C15: 110/5 | D15: DA+3 | E15: 37.931088 | F15: =E15*10940 -> 414966.1 | G15: 45689 | H15: Jwala Singh | I15: Completed | J15: 45709 | K15: 45712 | L15: =K15-J15 -> 3 | M15: Raj
B16: 11 | C16: 109/2 | D16: DA-1.5 | E16: 35.602 | F16: =E16*10940 -> 389485.88 | G16: 45689 | H16: Jwala Singh | I16: Completed | J16: 45713 | K16: 45716 | L16: =K16-J16 -> 3 | M16: Raj
B17: 12 | C17: 109/1 | D17: DA-1.5 | E17: 35.602 | F17: =E17*10940 -> 389485.88 | G17: 45717 | H17: Jwala Singh | I17: Completed | J17: 45717 | K17: 45720 | L17: =K17-J17 -> 3 | M17: Raj
... B83: 78 | C83: 147A/3 | D83: DA+6 | E83: 43.804424 | F83: =E83*10940 -> 479220.4 | G83: 45809 | H83: Jwala Singh-2 | I83: Completed | J83: 45819 | K83: 45823 | L83: =K83-J83 -> 4 | M83: Raj
B84: 79 | C84: 147/1 | D84: DA+9 | E84: 45.697022 | F84: =E84*10940 -> 499925.42 | G84: 45839 | H84: Eagle Enterprises/Paramand | I84: Completed | J84: 45834 | K84: 45850 | L84: =K84-J84 -> 16 | M84: Raj | N84: JWALA SINGH COMPLETED THE LOCS.
B85: 80 | C85: 156/4 | D85: DA-3 | E85: 34.79 | F85: =E85*10940 -> 380602.6 | G85: 45809 | H85: Gokul/Rajwanshi | I85: Completed | J85: 45824 | K85: 45830 | L85: =K85-J85 -> 6 | M85: Raj
B86: 81 | C86: 152A/9 | D86: DA+6 | E86: 43.804424 | F86: =E86*10940 -> 479220.4 | G86: 45809 | H86: Jwala Singh | I86: Completed | J86: 45825 | K86: 45833 | L86: =K86-J86 -> 8 | M86: Raj
B87: 82 | C87: 154/2 | D87: DA-3 | E87: 34.79 | F87: =E87*10940 -> 380602.6 | G87: 45809 | H87: Gokul/Rajwanshi | I87: Completed | J87: 45832 | K87: 45838 | L87: =K87-J87 -> 6 | M87: Raj
B88: 83 | C88: 150/4 | D88: DA+6 | E88: 43.804424 | F88: =E88*10940 -> 479220.4 | G88: 45809 | H88: Jwala Singh | I88: Completed | J88: 45835 | K88: 45838 | L88: =K88-J88 -> 3 | M88: Raj
B89: 84 | C89: 154/1 | D89: DA-1.5 | E89: 35.602 | F89: =E89*10940 -> 389485.88 | G89: 45839 | H89: Gokul/Rajwanshi | I89: Completed | J89: 45839 | K89: 45845 | L89: =K89-J89 -> 6 | M89: Raj
B90: 85 | C90: 150/2 | D90: DA+3 | E90: 37.931088 | F90: =E90*10940 -> 414966.1 | G90: 45839 | H90: Jwala Singh | I90: Completed | J90: 45839 | K90: 45844 | L90: =K90-J90 -> 5 | M90: Raj
B91: 86 | C91: 150/1 | D91: DA+6 | E91: 43.804424 | F91: =E91*10940 -> 479220.4 | G91: 45839 | H91: Jwala Singh | I91: Completed | J91: 45845 | K91: 45855 | L91: =K91-J91 -> 10 | M91: Raj
B92: 87 | C92: 154/3 | D92: DA-3 | E92: 34.79 | F92: =E92*10940 -> 380602.6 | G92: 45839 | H92: Gokul/Rajwanshi | I92: Completed | J92: 45846 | K92: 45852 | L92: =K92-J92 -> 6 | M92: Raj
B93: 88 | C93: 103/7 | D93: DA+6 | E93: 43.804424 | F93: =E93*10940 -> 479220.4 | G93: 45839 | H93: Gokul/Rajwanshi | I93: Completed | J93: 45853 | K93: 45862 | L93: =K93-J93 -> 9 | M93: Raj
B94: 89 | C94: 150/0 | D94: DC1+0 | E94: 62.444 | F94: =E94*10940 -> 683137.36 | G94: 45839 | H94: Jwala Singh | I94: Completed | J94: 45856 | K94: 45866 | L94: =K94-J94 -> 10 | M94: Raj
B95: 90 | C95: 103/8 | D95: DA+3 | E95: 37.931088 | F95: =E95*10940 -> 414966.1 | G95: 45839 | H95: Gokul/Rajwanshi | I95: Completed | J95: 45863 | K95: 45869 | L95: =K95-J95 -> 6 | M95: Raj
B96: 91 | C96: 127/0 | D96: DD45+0 | E96: 73.245 | F96: =E96*10940 -> 801300.3 | G96: 45870 | H96: Shila Devi | I96: Completed | J96: 45870 | K96: 45885 | L96: =K96-J96 -> 15 | M96: Raj
... B229: 224 | C229: 164/4 | D229: DA+0 | E229: 36.159756 | F229: =E229*10940 -> 395587.73 | G229: 45992 | H229: Jagannaath Saw (MP) | I229: Completed | J229: 46009 | K229: 46015 | L229: =K229-J229 -> 6 | M229: MP
B230: 225 | C230: 171/10 | D230: DA+0 | E230: 36.159756 | F230: =E230*10940 -> 395587.73 | M230: MP | N230: RoW
B231: 226 | C231: 152A/6 | D231: DA+0 | E231: 36.159756 | F231: =E231*10940 -> 395587.73 | G231: 45992 | H231: Shila Devi | I231: Completed | J231: 46011 | K231: 46015 | L231: =K231-J231 -> 4 | M231: Raj
B232: 227 | C232: 169/9 | D232: DA-3 | E232: 34.79 | F232: =E232*10940 -> 380602.6 | G232: 45992 | H232: Deglal Mahato (MP) | I232: Completed | J232: 46011 | K232: 46018 | L232: =K232-J232 -> 7 | M232: MP
B233: 228 | C233: 177/1 | D233: DA+3 | E233: 37.931 | F233: =E233*10940 -> 414965.14 | G233: 45992 | H233: Jwala Singh 2 | I233: Completed | J233: 46012 | K233: 46018 | L233: =K233-J233 -> 6 | M233: MP
B234: 229 | C234: 181/1 | D234: DA+0 | E234: 36.159756 | F234: =E234*10940 -> 395587.73 | G234: 45992 | H234: Gokul Sarkar (MP) | I234: Completed | J234: 46012 | K234: 46017 | L234: =K234-J234 -> 5 | M234: MP
B235: 230 | C235: 179/5 | D235: DA-3 | E235: 34.79 | F235: =E235*10940 -> 380602.6 | G235: 45992 | H235: Gokul Sarkar (MP)-2 | I235: Completed | J235: 46012 | K235: 46019 | L235: =K235-J235 -> 7 | M235: MP
B236: 231 | C236: 173/0 | D236: DB2+0 | E236: 59.501 | F236: =E236*10940 -> 650940.94 | G236: 45992 | H236: Crane Erc.Team (MP) | I236: Completed | J236: 46013 | K236: 46021 | L236: =K236-J236 -> 8 | M236: MP
B237: 232 | C237: 123/0 | D237: DD60+6 | E237: 97.17 | F237: =E237*10940 -> 1063039.8 | G237: 46023 | H237: Deglal Mahato | I237: Completed | J237: 46013 | K237: 46026 | L237: =K237-J237 -> 13 | M237: Raj
B238: 233 | C238: 99/7 | D238: DA+0 | E238: 36.159756 | F238: =E238*10940 -> 395587.73 | G238: 45992 | H238: Jwala Singh | I238: Completed | J238: 46013 | K238: 46017 | L238: =K238-J238 -> 4 | M238: Raj
B239: 234 | C239: 152A/7 | D239: DA+6 | E239: 43.804424 | F239: =E239*10940 -> 479220.4 | G239: 45992 | H239: Shila Devi | I239: Completed | J239: 46016 | K239: 46022 | L239: =K239-J239 -> 6 | M239: Raj
...

Sheet Balance Erc-RAJ
A1: Balance Erection Status (Rajasthan)
A2: SL No | B2: Loc No | C2: TOT | D2: Tower Availability | E2: Current Status | F2: Remarks
A3: 1 | B3: 99/1 | C3: DA+6 | D3: NO | E3: Erectable | F3: Tower Parts not available-Supply in PGCIL Scope.
A4: 2 | B4: 99/2 | C4: DA+6 | D4: NO | E4: Erectable
A5: 3 | B5: 99/3 | C5: DA+0 | D5: NO | E5: Erectable
A6: 4 | B6: 99/4 | C6: DA+0 | D6: NO | E6: Erectable
A7: 5 | B7: 99/5 | C7: DA+0 | D7: NO | E7: Erectable
A8: 6 | B8: 99/6 | C8: DA+0 | D8: NO | E8: Erectable
A9: 7 | B9: 99/7 | C9: DA+6 | D9: YES | E9: WIP
A10: 8 | B10: 103/9 | C10: DA+3 | D10: Yes | E10: Planned
A11: 9 | B11: 110/0 | C11: DC2+3 | E11: Water logged
A12: 10 | B12: 118/0 | C12: DD60+6 | D12: NO | F12: Tower Parts availability-Last Week of November-25.
A13: 11 | B13: 122/0 | C13: DD60+3 | D13: Yes | E13: Planned
A14: 12 | B14: 132/0 | C14: DD60+6 | D14: NO | F14: Tower Parts availability-Last Week of November-25.
A15: 13 | B15: 135/3 | C15: DA+9 | D15: Yes | E15: Water logged
A16: 14 | B16: 140/0 | C16: DC1+9 | D16: Yes | E16: Planned
A17: 15 | B17: 141/0 | C17: DD45+0 | D17: Yes | E17: Planned | F17: Approach Issue.
A18: 16 | B18: 142/0 | C18: DD45+3 | D18: Yes | E18: 11 Kv Line shifting required
A19: 17 | B19: 144A/2 | C19: DA+3 | D19: Yes | E19: Opium Planted
A20: 18 | B20: 147/0 | C20: DB2+6 | D20: Yes | E20: Chia Planted | F20: Land Owner objection
A21: 19 | B21: 148/0 | C21: DD60+6 | D21: NO | F21: Tower Parts availability-Last Week of November-25.
A22: 20 | B22: 149B/1 | C22: DB2+15 | D22: NO | F22: Tower Parts availability-December-25.
A23: 21 | B23: 149B/4 | C23: DA+0 | D23: Yes | E23: WIP
A24: 22 | B24: 151/0 | C24: DD45+3 | D24: Yes | E24: Garlic Planted
A25: 23 | B25: 152/1 | C25: DA+6 | D25: Yes | E25: Opium Planted
A26: 24 | B26: 152/2 | C26: DA+0 | D26: Yes | E26: Opium Planted | F26: Managable
A27: 25 | B27: 152/3 | C27: DA-1.5 | D27: Yes | E27: Opium Planted
A28: 26 | B28: 152A/0 | C28: DB1+0 | D28: Yes | E28: Planned
A29: 27 | B29: 152A/6 | C29: DA+0 | D29: Yes | E29: Planned | F29: 33 kV Line SD required
A30: 28 | B30: 152A/7 | C30: DA+6 | D30: Yes | E30: Planned | F30: 33 kV Line SD required
A31: 29 | B31: 152A/10 | C31: DA+0 | D31: Yes | E31: Planned | F31: 33 kV Line SD required
A32: 30 | B32: 152A/11 | C32: DA-1.5 | D32: Yes | E32: Opium Planted
A33: 31 | B33: 152A/12 | C33: DA-3 | D33: Yes | E33: Opium Planted
A34: 32 | B34: 154/4 | C34: DA+3 | D34: Yes | E34: Planned
A35: 33 | B35: 155/0 | C35: DC2+0 | D35: Yes | E35: Opium Planted in adjacent land
A36: 34 | B36: 155/1 | C36: DA+0 | D36: Yes | E36: Approach Issue
A37: 35 | B37: 155/2 | C37: DA+3 | D37: Yes | E37: Approach Issue/Opium
A38: 36 | B38: 156/3 | C38: DA+0 | D38: Yes | E38: ROW | F38: Compensation Issue

Sheet ERC ROW-MP
A1: Balance Erection Status (MP)
A2: SL No | B2: Loc No | C2: TOT | D2: Tower Availability | E2: Current Status | F2: Remarks
A3: 1 | B3: 159/3 | C3: DA+0 | D3: Yes | E3: Shutdown Issue
A4: 2 | B4: 161/1 | C4: DA+3 | D4: Yes | E4: Opium Planted
A5: 3 | B5: 161/5 | C5: DA+6
A6: 4 | B6: 164/2 | C6: DA+0 | D6: Yes | E6: Shutdown Issue
A7: 5 | B7: 164/3 | C7: DA+3
A8: 6 | B8: 164/4 | C8: DA+0 | D8: Yes | E8: Shutdown Issue
A9: 7 | B9: 164/6 | C9: DA+3
A10: 8 | B10: 164/7 | C10: DA+3
A11: 9 | B11: 165/1 | C11: DA+6 | D11: Yes | E11: Line Shifting Reqd
A12: 10 | B12: 165/2 | C12: DA+0 | D12: Yes | E12: Shutdown Issue
A13: 11 | B13: 165/3 | C13: DA+0 | D13: Yes | E13: Opium Planted
A14: 12 | B14: 165/4 | C14: DA-3 | D14: Yes | E14: Approach Issue
A15: 13 | B15: 165/5 | C15: DA-3 | D15: Yes | E15: Approach Issue
A16: 14 | B16: 166/2 | C16: DA+0 | D16: Yes | E16: Compensation Issue
A17: 15 | B17: 166/3 | C17: DA+0 | D17: Yes | E17: Opium Planted
A18: 16 | B18: 166/4 | C18: DA+3
A19: 17 | B19: 168/0 | C19: DC2+0 | D19: Yes | E19: Opium Planted
A20: 18 | B20: 169/0 | C20: DC1+3
A21: 19 | B21: 170/2 | C21: DA+0
A22: 20 | B22: 170/3 | C22: DA+0 | D22: Yes | E22: Opium Planted
A23: 21 | B23: 170/4 | C23: DA-3 | D23: Yes | E23: ROW | F23: Tower Erectable after Crop Harvesting.
A24: 22 | B24: 170/5 | C24: DA+0
A25: 23 | B25: 170/6 | C25: DA-3 | D25: Yes | E25: ROW | F25: Tower Erectable after Crop Harvesting.
A26: 24 | B26: 170/9 | C26: DA+0 | D26: Yes | E26: Opium Planted
A27: 25 | B27: 170/10 | C27: DA+0 | D27: Yes | E27: Opium Planted
A28: 26 | B28: 171/0 | C28: DB1+0 | D28: No | E28: Approach Issue
A29: 27 | B29: 171/1 | C29: DA-3 | D29: Yes | E29: Opium Planted
A30: 28 | B30: 171/2 | C30: DA+0 | D30: Yes | E30: Opium Planted
A31: 29 | B31: 171/3 | C31: DA+0 | D31: Yes | E31: ROW | F31: Tower Erectable after Crop Harvesting.
A32: 30 | B32: 171/4 | C32: DA+0 | D32: Yes | E32: ROW | F32: Tower Erectable after Crop Harvesting.
A33: 31 | B33: 171/6 | C33: DA+0
A34: 32 | B34: 171/7 | C34: DA+0
A35: 33 | B35: 171/8 | C35: DA-3
A36: 34 | B36: 171/9 | C36: DA+0
A37: 35 | B37: 171/10 | C37: DA+0
A38: 36 | B38: 172/0 | C38: DB1+0
A39: 37 | B39: 172/1 | C39: DA-3
A40: 38 | B40: 172/4 | C40: DA+0
...

Sheet Stringing Compiled
D2: Number of TSE | E2: 1
A4: S.no | B4: Sec | C4: From AP | D4: To AP | E4: Span (M) | F4: Method | G4: Section Readiness | H4: Insulator Hoisting | I4: P/O Starting Date | J4: P/O Completion Date | K4: P/O | L4: F/S Starting Date | M4: F/S/ Completion Date | N4: Jumpering | O4: Spacering | P4: Clipping | Q4: Length | R4: Status | S4: Gang Name | T4: Gang Strength | U4: Number of Fitters | V4: Hindrance | W4: Remarks
A5: 1 | B5: 100/0 To 101/0 | C5: 100/0 | D5: 101/0 | E5: 419 | F5: Manual | G5: Ready | H5: Done | I5: 46042 | J5: 46047 | K5: Done | L5: 46058 | M5: 46060 | Q5: =E5 -> 419 | R5: Done | S5: Alimuddin | T5: 30
A6: 2 | B6: 101/0 To 102/0 | C6: 101/0 | D6: 102/0 | E6: 3470 | F6: TSE | G6: Ready | H6: Done | I6: 46049 | J6: 46055 | K6: Done | L6: 46063 | M6: 46068 | Q6: =E6 -> 3470 | R6: Done | S6: Alimuddin | T6: 30
A7: 3 | B7: 102/0 To 103/0 | C7: 102/0 | D7: 103/0 | E7: 461 | F7: Manual | G7: Ready | H7: Done | I7: 46061 | J7: 46065 | K7: Done | L7: 46071 | M7: 46075 | Q7: =E7 -> 461 | R7: Done | S7: Alimuddin | T7: 30
A8: 4 | B8: 103/0 To 103/5A | C8: 103/0 | D8: 103/5A | E8: 2200 | F8: TSE | G8: Ready | H8: Done | I8: 46069 | J8: 46075 | K8: Done | L8: 46079 | M8: 46081 | Q8: 2200 | R8: Done | S8: Alimuddin | T8: 30
A9: 5 | B9: 103/5A To 103/6A | C9: 103/5A | D9: 103/6A | E9: 567 | F9: TSE | G9: Ready | H9: Done | I9: 46077 | J9: 46079 | K9: Done | L9: 46093 | M9: 46097 | Q9: 567 | R9: Done | S9: Alimuddin | T9: 30
A10: 6 | B10: 103/6A To 104/0 | C10: 103/6A | D10: 104/0 | E10: 1403 | F10: TSE | G10: Ready | H10: Done | I10: 46093 | J10: 46097 | K10: Done | L10: 46098 | M10: 46101 | Q10: 1403 | R10: Done | S10: Alimuddin | T10: 30
A11: 7 | B11: 104/0 To 105/0 | C11: 104/0 | D11: 105/0 | E11: 967 | F11: TSE | G11: Ready | H11: Done | I11: 46087 | J11: 46063 | K11: Done | S11: Alimuddin | T11: 30
A12: 8 | B12: 111/0 To 112/0 | C12: 111/0 | D12: 112/0 | E12: 1954 | F12: TSE | G12: Ready | H12: Done | I12: 46109 | J12: 46110 | K12: Done | L12: 46110 | M12: 46112 | Q12: 1954 | R12: Done | S12: Alimuddin | T12: 30
A13: 9 | B13: 113/0 To 114/0 | C13: 113/0 | D13: 114/0 | E13: 2565 | F13: TSE | G13: Ready | H13: Done | I13: 46106 | J13: 46108 | K13: Done | L13: 46109 | M13: 46112 | Q13: 2565 | R13: Done | S13: Sanwaririya Enterprises | T13: 27
A14: 10 | B14: 114/0 To 115/0 | C14: 114/0 | D14: 115/0 | E14: 4304 | F14: TSE | G14: Ready | H14: Done | S14: Sanwaririya Enterprises | T14: 27
D236: Total | E236: =SUM(E5:E234)/1000 -> 18.31 | Q236: =SUM(Q5:Q235)/1000 -> 13.039

Sheet Visual Chart
M2: V I S U A L C H A R T
B5: DATE : | D5: 46110
B6: Name of Line : | E6: 765 KV D/C HEXA BEAWAR MANDSAUR T/L
B7: Project Code: | F7: TA505
B8: Name of Executing Agency: | F8: M/s. KEC INTERNATIONAL LTD.
AG9: FDN | AH9: Ear | AI9: ERE | AJ9: TW | AK9: STR
V10: COMMON TOWER
V11: 99/0 | X11: 99/1 | Z11: 99/2 | AB11: 99/3 | AD11: 99/4 | AG11: 4 | AH11: 0 | AI11: 4
Z12: 1 | AB12: 1
V13: 1 | X13: 2 | Z13: 3 | AB13: 4 | AD13: 1
S14: BAJEL PART | U14: 0 | V14: BAJEL | W14: 360 | Y14: 420 | AA14: 410 | AC14: 382
V16: 0 | X16: 0 | Z16: 0 | AB16: 0 | AD16: 0
V17: DB2+0 | X17: DA+6 | Z17: DA+6 | AB17: DA+0 | AD17: DA+0
U19: RAJASTHAN REGION
O21: =+LEFT(O28,1) -> D | Q21: =+LEFT(Q28,1) -> D | U21: =+LEFT(U28,1) -> D | W21: =+LEFT(W28,1) -> D | Y21: =+LEFT(Y28,1) -> D | AA21: =+LEFT(AA28,1) -> D | AC21: =+LEFT(AC28,1) -> D | AE21: =+LEFT(AE28,1) -> D
C22: 99/5 | E22: 99/6 | G22: 99/7 | I22: 99/8 | K22: 100/0 | M22: 101/0 | O22: 101/1 | Q22: 101/2 | S22: 101/3 | U22: 101/4 | W22: 101/5 | Y22: 101/6 | AA22: 101/7 | AC22: 101/8 | AE22: 102/0
G23: 1 | I23: 1 | O23: 1 | Q23: 1 | S23: 1 | U23: 1 | W23: 1 | Y23: 1 | AA23: 1 | AC23: 1
C24: 1 | E24: 2 | G24: 3 | I24: 4 | K24: 1 | M24: 2 | O24: 3 | Q24: 4 | S24: 5 | U24: 6 | W24: 7 | Y24: 8 | AA24: 9 | AC24: 10 | AE24: 11
B25: 338 | D25: 370 | F25: 380 | H25: 400 | J25: 418 | L25: 418.579 | N25: 425 | O25: Completed | P25: 312 | Q25: Completed | R25: 381 | S25: Completed | T25: 455 | U25: Completed | V25: 376 | W25: Completed | X25: 401 | Y25: Completed | Z25: 428 | AA25: Completed | AB25: 357 | AC25: Completed | AD25: 335.158 | AE25: Completed | AG25: 15 | AH25: 10 | AI25: 15 | AJ25: 8 | AK25: =L25+N25+P25+R25+T25+V25+X25+Z25+AB25+AD25 -> 3888.737
C27: 0 | E27: 0 | G27: 0 | I27: 0 | K27: 0 | M27: 0 | O27: Completed | Q27: Completed | S27: Completed | U27: Completed | W27: Completed | Y27: Completed | AA27: Completed | AC27: Completed | AE27: Completed
C28: DA+0 | E28: DA+0 | G28: DA+0 | I28: DA+6 | K28: DD45+0 | M28: DC1+3 | O28: DA+3 | Q28: DA+9 | S28: DA+3 | U28: DA+6 | W28: DA+0 | Y28: DA+3 | AA28: DA+3 | AC28: DA-3 | AE28: DC2+3
O29: WFR | Q29: WFR | S29: WFR | U29: WFR | W29: WFR | Y29: WFR | AA29: WFR | AC29: DRY | AE29: DRY
B31: RAJASTHAN REGION
M32: RC
C33: 103/0 | E33: 103/1 | G33: 103/2 | I33: 103/3 | K33: 103/4 | M33: 103/5 | O33: 103/5A | Q33: 103/5A1 | S33: 103/6A | U33: 103/7 | W33: 103/8 | Y33: 103/9 | AA33: 104/0 | AC33: 104/1 | AE33: 104/2
C34: 0 | E34: 0 | G34: 0 | I34: 0 | K34: 0 | M34: 0 | O34: 0 | S34: 0 | W34: 0 | Y34: 0 | AA34: 0 | AC34: 0 | AE34: 0
A35: 11 | C35: 12 | E35: 13 | G35: 14 | I35: 15 | K35: 16 | M35: 17 | O35: 18 | S35: 19 | U35: 20 | W35: 21 | Y35: 22 | AA35: 23 | AC35: 24 | AE35: 25
B36: 461.164 | D36: 373 | F36: 334.67 | H36: 321.15 | J36: 391 | L36: 388 | N36: 392 | P36: 293 | R36: 274 | T36: 218 | U36: Completed | V36: 422 | X36: 339 | Z36: 423.633 | AA36: Completed | AB36: 335.192 | AC36: Completed | AD36: 326.577 | AE36: Completed | AG36: 15 | AH36: 8 | AI36: 15 | AJ36: 3 | AK36: =B36+D36+F36+H36+J36+L36+N36+P36+R36+T36+V36+X36+Z36 -> 4630.617
E38: 0 | G38: 0 | K38: 0 | M38: X | U38: Completed | W38: 0 | Y38: 0 | AA38: Completed | AC38: 0 | AE38: Completed
C39: DC1+6 | E39: DA+0 | G39: DA+0 | I39: DA+0 | K39: DA+0 | M39: DA+3 | O39: DD60+0 | Q39: DA-3 | S39: DD45+0 | U39: DA+6 | W39: DA+3 | Y39: DA+3 | AA39: DD45+3 | AC39: DA-3 | AE39: DA-3
M40: Benching | S40: Benching | U40: DFR | AA40: DFR | AC40: DFR | AE40: WET
B42: RAJASTHAN REGION
C43: HR | H43: GAS PIPE LINE
C44: 105/0 | E44: 105/1 | G44: 106/0 | I44: 108/0 | K44: 108/1 | M44: 108/2 | O44: 108/3 | Q44: 108/4 | S44: 109/0 | U44: 109/1 | W44: 109/2 | Y44: 109/3 | AA44: 109/4 | AC44: 110/0
C45: 0 | E45: 0 | G45: 0 | I45: 0 | K45: 0 | M45: 0 | O45: 0 | Q45: 0 | S45: 0 | U45: 1 | W45: 1 | Y45: 0 | AA45: 0 | AC45: 0
A46: 25 | C46: 26 | E46: 27 | G46: 28 | I46: 29 | K46: 30 | M46: 31 | O46: 32 | Q46: 33 | S46: 34 | U46: 35 | W46: 36 | Y46: 37 | AA46: 38 | AC46: 39
B47: 304.947 | C47: Completed | D47: 379.11 | E47: Completed | F47: 375.442 | H47: 212.418 | J47: 326.001 | K47: Completed | L47: 332 | M47: Completed | N47: 285 | O47: Completed | P47: 345 | Q47: Completed | R47: 380.282 | S47: Completed | T47: 384.998 | U47: Completed | V47: 360 | W47: Completed | X47: 378 | Y47: Completed | Z47: 387 | AA47: Completed | AB47: 439.322 | AC47: Completed | AG47: 14 | AH47: 11 | AI47: 14 | AJ47: 9
C49: 0 | E49: Completed | G49: 0 | I49: 0 | K49: Completed | M49: Completed | O49: Completed | Q49: Completed | S49: Completed | U49: Completed | W49: Completed | Y49: Completed | AA49: Completed | AC49: Completed
C50: DC1+0 | E50: DA+0 | G50: DD60+0 | I50: DD45+0 | K50: DA-3 | M50: DA-3 | O50: DA-3 | Q50: DA+0 | S50: DC1+0 | U50: DA-1.5 | W50: DA-1.5 | Y50: DA+0 | AA50: DA+3 | AC50: DC2+3
C51: WFR | E51: WFR | K51: DFR | M51: WET | O51: WET | Q51: WFR | S51: DFR | U51: WFR | W51: WFR | Y51: WFR | AA51: WFR | AC51: WFR
...

Sheet Erection Productivity
B2: Project Code | C2: Project Name | D2: SPOC | E2: Apr'25 | G2: May'25 | I2: Jun'25 | K2: Jul'25 | M2: Aug'25 | O2: Sep'25 | Q2: Oct'25 | S2: Nov'25 | U2: Dec'25 | W2: Jan'26 | Y2: Feb'26
B3: TA-505 | C3: PGCIL_Part-D - TL02_for 765kV TL Beawar | D3: Partha Pratim Pal | E3: Plan | F3: Actual | G3: Plan | H3: Actual | I3: Plan | J3: Actual | K3: Plan | L3: Actual | M3: Plan | N3: Actual | O3: Plan | P3: Actual | Q3: Plan | R3: Actual | S3: Plan | T3: Actual | U3: Plan | V3: Actual | W3: Plan | X3: Actual | Y3: Plan | Z3: Actual
E4: (in MT) | F4: (in MT) | G4: (in MT) | H4: (in MT) | I4: (in MT) | J4: (in MT) | K4: (in MT) | L4: (in MT) | M4: (in MT) | N4: (in MT) | O4: (in MT) | P4: (in MT) | Q4: (in MT) | R4: (in MT) | S4: (in MT) | T4: (in MT) | U4: (in MT) | V4: (in MT) | W4: (in MT) | X4: (in MT) | Y4: (in MT) | Z4: (in MT)
E5: 1352 | F5: 698 | G5: 1742 | H5: 922 | I5: 1188 | J5: 641 | K5: 752 | L5: 379 | M5: 770 | N5: 435 | O5: 2414 | P5: 1533 | Q5: 2482 | R5: 1491 | S5: 3021 | T5: 1502 | U5: 3205 | V5: 2344 | W5: 2616 | X5: 2039 | Y5: 1975 | Z5: 1258

Sheet Earthing Status
B1: 765 kV D/C BEAWAR MANDSAUR TRANSMISSION LINE
B2: PROGRESS SUMMARY DETAIL
B3: NOA Date: 22-July-2024 | K3: Completion Date : 21-June-2026 | O3: Date : 27-05-25
B4: SUPPLY VALUE = 458 Cr. | K4: SERVICE VALUE = 94.23 Cr. | O4: F&I VALUE = 9.48 Cr. | V4: =458+94.23+9.48 -> 561.71
B5: Sr. No. | C5: Activity | E5: UOM | G5: Total Qty. | J5: L2 Qty. | K5: Completed | L5: Balance | M5: Submitted | N5: WIP | O5: Remarks
B6: 1 | C6: Details Survey | E6: Kms | G6: 136.705 | J6: 126 | K6: =87.055+32.269+7 -> 126.324 | L6: =G6-K6 -> 10.381 | M6: =17.381-7 -> 10.381
B7: 2 | C7: Check Survey | E7: Kms | G7: 136.705 | J7: 126 | K7: =69.41+32.269+7 -> 108.679 | L7: =G7-K7 -> 28.026
B8: 3 | C8: Soil Testing | E8: Nos | G8: 34 | J8: 34
B9: 4 | C9: Foundation | E9: Nos | G9: 371 | J9: 165 | K9: =V27 -> 355 | L9: =G9-K9 -> 16 | N9: =COUNTIF($V$28:$V$1176, "WIP") -> 0
C10: Gang | E10: Nos | K10: 13
C11: Manpower | E11: Nos
B12: 5 | C12: Earthing | E12: Nos | G12: 346 | K12: 94 | L12: =G12-K12 -> 252
B13: 6 | C13: Erection | E13: Nos | G13: =G9 -> 371 | J13: 98 | K13: ='Erection Compiled'!I5 -> 321 | L13: =G13-K13 -> 50 | N13: =COUNTIF('Erection Compiled'!I6:I393,"WIP") -> 0
C14: Gang | E14: Nos | K14: 4
C15: Manpower | E15: Nos
B16: 7 | C16: Stringing | E16: Nos | G16: =G7 -> 136.705 | J16: 0 | K16: 0 | L16: =G16-K16 -> 136.705
C17: Gang | E17: Nos
C18: Manpower | E18: Nos
B20: Issue : i. DS - pending for approval ii. CS - pending for approval
B21: Supply : Stub : DA : 177 Set, DB : 21 Set, DC : 16 Set, DD45 : 9 Set, DD60 : 13 set Earthing : CP : 84 Set, Pipe : 40 Nos, Rod : 40 Nos Tower : DA BB=107 Set,+0M=52, +3M=35,+6M=19, +9M=3, -1.5=6, -3=14
B23: KEC INTERNATIONAL LIMITED
B24: FOUNDATION DETAIL OF 765KV D/C BEAWAR-MANDSAUR TR LINE
B25: Sr. No | C25: Loc No. | D25: Type of Tower | E25: TOF | F25: Region | G25: Earthing Status | H25: Type of Earthing (Pipe Type/CP) | I25: JMC Status | J25: Cement (Bags) | M25: Conc Vol | O25: Excv Vol(m3) | P25: R/F (KG) | Q25: Wt of Stub(MT) | R25: Rev(Inr) | S25: Earthing Vendor | T25: Month of Execution | U25: Foundation Sub Contractor | V25: Foundation Status | W25: Excavation | Y25: Foundation | Z25: Foundation completion | AA25: Remarks if any
J26: RCC | K26: PCC | L26: Toal Cement | M26: M 20(m3) | N26: M 10(m3) | W26: Start | X26: Completion | Y26: Start
B27: Total = | J27: =SUM(J28:J454) -> 125897.63 | K27: =SUM(K28:K454) -> 6532.0004 | L27: =SUM(L28:L454) -> 132429.63 | M27: =SUM(M28:M454) -> 15724.169 | N27: =SUM(N28:N454) -> 1463.911 | O27: =SUM(O28:O454) -> 96505.589 | P27: =SUM(P28:P454) -> 1032821.9 | Q27: =SUM(Q28:Q454) -> 395.43251 | R27: =SUM(R28:R454) -> 3.0707497e+08 | V27: =COUNTIF(V28:V621,"Complete") -> 355
C28: 101/2 | D28: DA+9 | E28: WFR | F28: RAJ | G28: Done | H28: CP | J28: 383 | K28: 20 | L28: 403 | M28: 47.77 | N28: 4.46 | O28: 264.87 | P28: 2353 | Q28: 0.866276 | R28: 1126247.4 | T28: 45566 | U28: RST | V28: Complete | W28: 45546 | X28: 45561 | Y28: 45567 | Z28: 45571 | AB28: 1
C29: 100/0 | D29: DD45+0 | E29: WET | F29: RAJ | G29: Done | H29: Pipe Type | J29: =M29*8 -> 1239.68 | K29: =N29*4.4 -> 70.18 | L29: =SUM(J29:K29) -> 1309.86 | M29: 154.96 | N29: 15.95 | O29: 1192.7 | P29: 15096 | Q29: 2.495 | T29: 45944 | U29: Sumit Const/Om Prakash | V29: Complete | Z29: 45946
C30: 101/0 | D30: DC1+3 | E30: DFR | F30: RAJ | G30: Done | H30: CP | J30: =M30*8 -> 614.16 | K30: =N30*4.4 -> 27.984 | L30: =SUM(J30:K30) -> 642.144 | M30: 76.77 | N30: 6.36 | O30: 388.74 | P30: 3855 | Q30: 2.348757 | R30: 1765261 | T30: 45791 | U30: Sumit Const/Om Prakash | V30: Complete | Z30: 45808
C31: 101/1 | D31: DA+3 | E31: WFR | F31: RAJ | G31: Done | H31: CP | J31: 383 | K31: 20 | L31: 403 | M31: 47.77 | N31: 4.46 | O31: 264.87 | P31: 2353 | Q31: 0.866276 | R31: 1126247.4 | T31: 45597 | U31: RST | V31: Complete | W31: 45598 | X31: 45604 | Y31: 45609 | Z31: 45610 | AB31: 2
C32: 101/3 | D32: DA+3 | E32: WFR | F32: RAJ | G32: Done | H32: CP | J32: 383 | K32: 20 | L32: 403 | M32: 47.77 | N32: 4.46 | O32: 264.87 | P32: 2353 | Q32: 0.866276 | R32: 1126247.4 | T32: 45566 | U32: RST | V32: Complete | W32: 45566 | X32: 45571 | Y32: 45573 | Z32: 45576 | AB32: 1
C33: 101/4 | D33: DA+6 | E33: WFR | F33: RAJ | G33: Done | H33: CP | J33: 383 | K33: 20 | L33: 403 | M33: 47.77 | N33: 4.46 | O33: 264.87 | P33: 2353 | Q33: 0.866276 | R33: 1126247.4 | T33: 45566 | U33: RST | V33: Complete | W33: 45551 | X33: 45556 | Y33: 45584 | Z33: 45586 | AB33: 1
C34: 101/5 | D34: DA+0 | E34: WFR | F34: RAJ | G34: Done | H34: CP | J34: 333 | K34: 19 | L34: 352 | M34: 41.54 | N34: 4.23 | O34: 250.46 | P34: 1909 | Q34: 0.866276 | R34: 984923.64 | T34: 45566 | U34: RST | V34: Complete | W34: 45557 | X34: 45561 | Y34: 45588 | Z34: 45590 | AB34: 1
C35: 101/6 | D35: DA+3 | E35: WFR | F35: RAJ | G35: Done | H35: CP | J35: 383 | K35: 20 | L35: 403 | M35: 47.77 | N35: 4.46 | O35: 264.87 | P35: 2353 | Q35: 0.866276 | R35: 1126247.4 | T35: 45597 | U35: RST | V35: Complete | W35: 45589 | X35: 45591 | Y35: 45595 | Z35: 45598 | AB35: 1
C36: 101/7 | D36: DA+3 | E36: WFR | F36: RAJ | G36: Done | H36: CP | J36: 383 | K36: 20 | L36: 403 | M36: 47.77 | N36: 4.46 | O36: 264.87 | P36: 2353 | Q36: 0.866276 | R36: 1126247.4 | T36: 45597 | U36: RST | V36: Complete | W36: 45606 | X36: 45610 | Y36: 45613 | Z36: 45614 | AB36: 2
C37: 101/8 | D37: DA-3 | E37: DRY | F37: RAJ | G37: Done | H37: Pipe Type | J37: 236 | K37: 13 | L37: 249 | M37: 29.49 | N37: 2.86 | O37: 233.05 | P37: 1526 | Q37: 0.866276 | R37: 645061.95 | T37: 45597 | U37: RST | V37: Complete | W37: 45593 | X37: 45598 | Y37: 45603 | Z37: 45604 | AB37: 2
C38: 102/0 | D38: DC2+3 | E38: DRY | F38: RAJ | G38: Done | H38: Pipe Type | J38: 856 | K38: 38 | L38: 894 | M38: 106.91 | N38: 8.53 | O38: 653.08 | P38: 5502 | Q38: 2.348757 | R38: 2257063.8 | T38: 45627 | U38: RST | V38: Complete | W38: 45618 | X38: 45621 | Y38: 45637 | Z38: 45640 | AB38: 3
C39: 103/0 | D39: DC1+6 | E39: DFR | F39: RAJ | G39: Done | H39: CP | I39: Done | J39: =M39*8 -> 614.16 | K39: =N39*4.4 -> 27.984 | L39: =SUM(J39:K39) -> 642.144 | M39: 76.77 | N39: 6.36 | O39: 388.74 | P39: 3855 | Q39: 2.348757 | R39: 1765261 | T39: 45789 | U39: Sumit Const/Om Prakash | V39: Complete | Z39: 45799
C40: 103/1 | D40: DA+0 | E40: DRY | F40: RAJ | J40: 236 | K40: 13 | L40: 249 | M40: 29.49 | N40: 2.86 | O40: 233.05 | P40: 1526 | Q40: 0.866276 | R40: 645061.95 | T40: 45784 | U40: Sumit Const/Om Prakash | V40: Complete | Z40: 45788
C41: 103/2 | D41: DA+0 | E41: DRY | F41: RAJ | J41: 236 | K41: 13 | L41: 249 | M41: 29.49 | N41: 2.86 | O41: 233.05 | P41: 1526 | Q41: 0.866276 | R41: 645061.95 | T41: 45780 | U41: Sumit Const/Om Prakash | V41: Complete | Z41: 45790
B42: 45 | C42: 103/3 | D42: DA+0 | E42: DFR | F42: RAJ | G42: Done | H42: CP | I42: Done | J42: 221 | K42: 12 | L42: 233 | M42: 27.61 | N42: 2.61 | O42: 146.96 | P42: 1450 | Q42: 0.866276 | R42: 650458.11 | T42: 45780 | U42: Sumit Const/Om Prakash | V42: Complete | Z42: 45785
...

Sheet Sheet4
M2: V I S U A L C H A R T
B5: DATE : | D5: 45981
B6: Name of Line : | E6: 765 KV D/C HEXA BEAWAR MANDSAUR T/L
B7: Project Code: | F7: TA505
B8: Name of Executing Agency: | F8: M/s. KEC INTERNATIONAL LTD.
AG9: FDN | AH9: Ear | AI9: ERE | AJ9: STR
V10: COMMON TOWER
V11: 99/0 | X11: 99/1 | Z11: 99/2 | AB11: 99/3 | AD11: 99/4 | AG11: 4 | AH11: 0 | AI11: 0
Z12: 1 | AB12: 1
V13: 1 | X13: 2 | Z13: 3 | AB13: 4 | AD13: 1
S14: BAJEL PART | U14: 0 | V14: BAJEL | W14: 360 | Y14: 420 | AA14: 410 | AC14: 382
V16: 0 | X16: 0 | Z16: 0 | AB16: 0 | AD16: 0
V17: DB2+0 | X17: DA+6 | Z17: DA+6 | AB17: DA+0 | AD17: DA+0
U19: RAJASTHAN REGION
O21: =+LEFT(O28,1) -> D | Q21: =+LEFT(Q28,1) -> D | U21: =+LEFT(U28,1) -> D | W21: =+LEFT(W28,1) -> D | Y21: =+LEFT(Y28,1) -> D | AA21: =+LEFT(AA28,1) -> D | AC21: =+LEFT(AC28,1) -> D | AE21: =+LEFT(AE28,1) -> D
C22: 99/5 | E22: 99/6 | G22: 99/7 | I22: 99/8 | K22: 100/0 | M22: 101/0 | O22: 101/1 | Q22: 101/2 | S22: 101/3 | U22: 101/4 | W22: 101/5 | Y22: 101/6 | AA22: 101/7 | AC22: 101/8 | AE22: 102/0
G23: 1 | I23: 1 | O23: 1 | Q23: 1 | S23: 1 | U23: 1 | W23: 1 | Y23: 1 | AA23: 1 | AC23: 1
C24: 1 | E24: 2 | G24: 3 | I24: 4 | K24: 1 | M24: 2 | O24: 3 | Q24: 4 | S24: 5 | U24: 6 | W24: 7 | Y24: 8 | AA24: 9 | AC24: 10 | AE24: 11
B25: 338 | D25: 370 | F25: 380 | H25: 400 | J25: 418 | L25: 418.579 | N25: 425 | O25: Completed | P25: 312 | Q25: Completed | R25: 381 | S25: Completed | T25: 455 | U25: Completed | V25: 376 | W25: Completed | X25: 401 | Y25: Completed | Z25: 428 | AA25: Completed | AB25: 357 | AC25: Completed | AD25: 335.158 | AE25: Completed | AG25: 15 | AH25: 5 | AI25: 10
C27: 0 | E27: 0 | G27: 0 | I27: 0 | K27: 0 | M27: 0 | O27: 0 | Q27: 0 | S27: 0 | U27: 0 | W27: Completed | Y27: Completed | AA27: Completed | AC27: Completed | AE27: Completed
C28: DA+0 | E28: DA+0 | G28: DA+0 | I28: DA+6 | K28: DD45+0 | M28: DC1+3 | O28: DA+3 | Q28: DA+9 | S28: DA+3 | U28: DA+6 | W28: DA+0 | Y28: DA+3 | AA28: DA+3 | AC28: DA-3 | AE28: DC2+3
O29: WFR | Q29: WFR | S29: WFR | U29: WFR | W29: WFR | Y29: WFR | AA29: WFR | AC29: DRY | AE29: DRY
B31: RAJASTHAN REGION
M32: RC
C33: 103/0 | E33: 103/1 | G33: 103/2 | I33: 103/3 | K33: 103/4 | M33: 103/5 | O33: 103/5A | Q33: 103/5A1 | S33: 103/6A | U33: 103/7 | W33: 103/8 | Y33: 103/9 | AA33: 104/0 | AC33: 104/1 | AE33: 104/2
C34: 0 | E34: 0 | G34: 0 | I34: 0 | K34: 0 | M34: 0 | O34: 0 | S34: 0 | W34: 0 | Y34: 0 | AA34: 0 | AC34: 0 | AE34: 0
A35: 11 | C35: 12 | E35: 13 | G35: 14 | I35: 15 | K35: 16 | M35: 17 | O35: 18 | S35: 19 | U35: 20 | W35: 21 | Y35: 22 | AA35: 23 | AC35: 24 | AE35: 25
B36: 461.164 | D36: 373 | F36: 334.67 | H36: 321.15 | J36: 391 | L36: 388 | N36: 392 | P36: 293 | R36: 274 | T36: 218 | U36: Completed | V36: 422 | X36: 339 | Z36: 423.633 | AA36: Completed | AB36: 335.192 | AC36: Completed | AD36: 326.577 | AE36: Completed | AG36: 15 | AH36: 3 | AI36: 13
E38: 0 | G38: 0 | K38: 0 | M38: X | U38: Completed | W38: 0 | Y38: 0 | AA38: Completed | AC38: 0 | AE38: Completed
C39: DC1+6 | E39: DA+0 | G39: DA+0 | I39: DA+0 | K39: DA+0 | M39: DA+3 | O39: DD60+0 | Q39: DA-3 | S39: DD45+0 | U39: DA+6 | W39: DA+3 | Y39: DA+3 | AA39: DD45+3 | AC39: DA-3 | AE39: DA-3
M40: Benching | S40: Benching | U40: DFR | AA40: DFR | AC40: DFR | AE40: WET
B42: RAJASTHAN REGION
C43: HR | H43: GAS PIPE LINE
C44: 105/0 | E44: 105/1 | G44: 106/0 | I44: 108/0 | K44: 108/1 | M44: 108/2 | O44: 108/3 | Q44: 108/4 | S44: 109/0 | U44: 109/1 | W44: 109/2 | Y44: 109/3 | AA44: 109/4 | AC44: 110/0
C45: 0 | E45: 0 | G45: 0 | I45: 0 | K45: 0 | M45: 0 | O45: 0 | Q45: 0 | S45: 0 | U45: 1 | W45: 1 | Y45: 0 | AA45: 0 | AC45: 0
A46: 25 | C46: 26 | E46: 27 | G46: 28 | I46: 29 | K46: 30 | M46: 31 | O46: 32 | Q46: 33 | S46: 34 | U46: 35 | W46: 36 | Y46: 37 | AA46: 38 | AC46: 39
B47: 304.947 | C47: Completed | D47: 379.11 | E47: Completed | F47: 375.442 | H47: 212.418 | J47: 326.001 | K47: Completed | L47: 332 | M47: Completed | N47: 285 | O47: Completed | P47: 345 | Q47: Completed | R47: 380.282 | S47: Completed | T47: 384.998 | U47: Completed | V47: 360 | W47: Completed | X47: 378 | Y47: Completed | Z47: 387 | AA47: Completed | AB47: 439.322 | AC47: Completed | AG47: 14 | AH47: 11 | AI47: 13
C49: 0 | E49: Completed | G49: 0 | I49: 0 | K49: Completed | M49: Completed | O49: Completed | Q49: Completed | S49: Completed | U49: Completed | W49: Completed | Y49: Completed | AA49: Completed | AC49: Completed
C50: DC1+0 | E50: DA+0 | G50: DD60+0 | I50: DD45+0 | K50: DA-3 | M50: DA-3 | O50: DA-3 | Q50: DA+0 | S50: DC1+0 | U50: DA-1.5 | W50: DA-1.5 | Y50: DA+0 | AA50: DA+3 | AC50: DC2+3
C51: WFR | E51: WFR | K51: DFR | M51: WET | O51: WET | Q51: WFR | S51: DFR | U51: WFR | W51: WFR | Y51: WFR | AA51: WFR | AC51: WFR
...

Sheet Sheet3
A1: SL | B1: Loc No | C1: TOT | D1: SL | E1: Loc No | F1: TOT | H1: SL | I1: Loc No | J1: TOT
A2: 1 | B2: 103/5 | C2: DA+0 | D2: 1 | E2: 126/1 | F2: DA+9 (RC) | H2: 1 | I2: 178/2 | J2: DA+6
A3: 2 | B3: 99/4 | C3: DA+0 | D3: 2 | E3: 149B/1 | F3: DB2+15 | H3: 2 | I3: 165/0 | J3: DB1+6
A4: 3 | B4: 99/5 | C4: DA+0 | D4: 3 | E4: 149B/2 | F4: DA+6 | H4: 3 | I4: 168/0 | J4: DC2+0
A5: 4 | B5: 99/3 | C5: DA+0 | D5: 4 | E5: 100/0 | F5: DD45+0 | H5: 4 | I5: 180/0 | J5: DC2+15
A6: 5 | B6: 99/2 | C6: DA+6 | D6: 5 | E6: 155/0 | F6: DC2+0 | H6: 5 | I6: 178/4 | J6: DA-3
A7: 6 | B7: 99/1 | C7: DA+6 | D7: 6 | E7: 99/8 | F7: DA+6 | H7: 6 | I7: 178/5 | J7: DA+0
A8: 7 | B8: 99/7 | C8: DA+0 | D8: 7 | E8: 149B/4 | F8: DA+0 (RC) | H8: 7 | I8: 179/1 | J8: DA+3
A9: 8 | B9: 103/9 | C9: DA+3 | D9: 8 | E9: 99/6 | F9: DA+0 | H9: 8 | I9: 179/6 | J9: DA+0
A10: 9 | B10: 169/0 | C10: DC1+3 | H10: 9 | I10: 145/0 | J10: DD60+18
A11: 10 | B11: 169/9 | C11: DA-3 | H11: 10 | I11: 114/4 | J11: DA+3
A12: 11 | B12: 175/2 | C12: DA+0 | H12: 11 | I12: 179/4 | J12: DA-3
A13: 12 | B13: 138/0 | C13: DB1+3 | H13: 12 | I13: 149B/3 | J13: DA+3 (RC)
A14: 13 | B14: 149B/0 | C14: DB1+25 | H14: 13 | I14: 179/2 | J14: DA+3
A15: 14 | B15: 122/0 | C15: DD60+3 | H15: 14 | I15: 154/4 | J15: DA+3
A16: 15 | B16: 123/0 | C16: DD60+6
A17: 16 | B17: 181/2 | C17: DA-3
A18: 17 | B18: 179/9 | C18: DA+3
A19: 18 | B19: 181/5 | C19: DA-3
A20: 19 | B20: 181/4 | C20: DA-3
A21: 20 | B21: 153/0 | C21: DB1+6
A22: 21 | B22: 154/0 | C22: DB2+9
A23: 22 | B23: 156/2 | C23: DA+3

Sheet Sheet2
