Workbook
Name \0: #REF!
Name \A: #REF!
Name \B: #REF!
Name \C: #REF!
Name \c1: #REF!
Name \D: #REF!
Name \g: #REF!
Name \H: #REF!
Name \i: #REF!
Name \M: #REF!
Name \N: #REF!
Name \P: #REF!
Name \R: #REF!
Name \S: #REF!
Name \U: #REF!
Name \V: #REF!
Name \z: #REF!
Name _: "tcap"
Name __________________________b111121: '[1]PACK (B)'!#REF!
Name _________________________b111121: '[1]PACK (B)'!#REF!
Name ________________________b111121: '[1]PACK (B)'!#REF!
Name _______________________b111121: '[1]PACK (B)'!#REF!
Name ______________________b111121: '[1]PACK (B)'!#REF!
Name ______________________TAB1: [2]TABLES!$A$2:$C$16
Name _____________________b111121: '[1]PACK (B)'!#REF!
Name _____________________TAB1: [2]TABLES!$A$2:$C$16
Name ____________________b111121: '[1]PACK (B)'!#REF!
Name ____________________TAB1: [2]TABLES!$A$2:$C$16
Name ___________________b111121: '[1]PACK (B)'!#REF!
Name ___________________TAB1: [2]TABLES!$A$2:$C$16
Name __________________b111121: '[1]PACK (B)'!#REF!
Name __________________TAB1: [5]TABLES!$A$2:$C$16
Name _________________b111121: '[1]PACK (B)'!#REF!
Name _________________TAB1: [6]TABLES!$A$2:$C$16
Name ________________b111121: '[1]PACK (B)'!#REF!
Name ________________TAB1: [6]TABLES!$A$2:$C$16
Name _______________b111121: '[1]PACK (B)'!#REF!
Name _______________TAB1: [6]TABLES!$A$2:$C$16
Name ______________b111121: '[1]PACK (B)'!#REF!
Name ______________TAB1: [6]TABLES!$A$2:$C$16
Name _____________A65537: #REF!
Name _____________b111121: '[1]PACK (B)'!#REF!
Name _____________TAB1: [6]TABLES!$A$2:$C$16
Name ____________A655600: #REF!
Name ____________b111121: '[1]PACK (B)'!#REF!
Name ____________drg1: #REF!
Name ____________TAB1: [6]TABLES!$A$2:$C$16
Name ___________A65537: #REF!
Name ___________A655600: #REF!
Name ___________a655601: #REF!
Name ___________b111121: '[1]PACK (B)'!#REF!
Name ___________Ki1: [7]grid!$C$182
Name ___________Ki2: [7]grid!$C$191
Name ___________TAB1: [6]TABLES!$A$2:$C$16
Name __________A65537: #REF!
Name __________A655600: #REF!
Name __________a655601: #REF!
Name __________a999999: #REF!
Name __________b111121: '[1]PACK (B)'!#REF!
Name __________drg1: #REF!

Sheet DPR-Summary
B2: LINE NAME- 765 kV D/C HEXA BEAWAR MANDSAUR TRANSMISSION LINE
B3: CLIENT-POWERGRID BEAWAR MANDSAUR TRANSMISSION LIMITED
B4: DAILY PROGRESS REPORT (TA-505)
B5: NOA Date :- 22-July-2024 | F5: Schedule Completion Date :- 21-June-2026 | K5: Date:- 21th June 2026.
B6: SUPPLY VALUE = 458.32 Cr. | F6: SERVICE VALUE = 94.23 Cr. | K6: F&I VALUE = 9.48 Cr.
B7: PARTICULARS | C7: UOM | D7: Total | E7: Comp | F7: Balance | G7: June'26 | I7: WIP | J7: Cumulative | K7: July'26 | L7: Aug'26 | M7: Remarks
D8: Qty | E8: Till | F8: as on | G8: Plan | H8: Actual | K8: Plan | L8: Plan
E9: 46173 | F9: 1st June-26
B10: Detail Survey | C10: KM | D10: 139.6 | E10: 139.6 | F10: =D10-E10 -> 0
B11: Check Survey | C11: KM | D11: 139.6 | E11: 139.6 | F11: =D11-E11 -> 0
B12: Stub Supply | C12: SET | D12: 379 | E12: 371 | F12: =D12-E12 -> 8 | H12: 0 | J12: =E12+H12 -> 371
B13: FOUNDATION | C13: NOS | D13: 379 | E13: 375 | F13: =D13-E13 -> 4 | G13: 4 | H13: 2 | I13: 2 | J13: =Foundation!I9 -> 377 | M13: Earthing-263/376.
B14: No of Gangs | G14: 1
B15: Tower Supply | C15: SETS | D15: 379 | E15: 361 | F15: =D15-E15 -> 18 | J15: =E15+H15 -> 361
B16: TOWER ERECTION | C16: NOS | D16: 379 | E16: 357 | F16: =D16-E16 -> 22 | G16: 7 | H16: =J16-E16 -> 5 | I16: 1 | J16: ='Erection Compiled'!I5 -> 362 | M16: Tack Welding Completed- 171/362, Gangs Engaged-3.
B17: No of Gangs | G17: 1
B18: AL59 Zebra Conductor Supply | C18: KM | D18: 4970.6 | E18: 4881 | F18: =D18-E18 -> 89.6 | J18: =E18+H18 -> 4881
B19: Earthwire Supply | C19: KM | D19: 138 | E19: 138 | F19: =D19-E19 -> 0 | J19: =E19+H19 -> 138
B20: Insulator Supply | C20: EA | D20: 16332 | E20: 15512 | F20: =D20-E20 -> 820 | J20: =E20+H20 -> 15512
B21: Hardware Fittings Supply | C21: % | D21: 1 | E21: 0.95 | F21: =D21-E21 -> 0.05 | J21: 0.95
B22: Stringing (Final Sag) | C22: KM | D22: 139.6 | E22: 15.462 | F22: =D22-E22 -> 124.138 | G22: 23.008 | H22: ='Stringing Compiled'!R235-'DPR-Summary'!E22 -> 9.751 | J22: =E22+H22 -> 25.213
B23: Stringing (Rough Sag) | C23: KM | D23: 139.6 | E23: 16.429 | F23: =D23-E23 -> 123.171 | G23: 23 | H23: 13.264 | J23: 28.726 | M23: 117/0-118/0= Hot line work Completed
B24: TSE Gangs | G24: 3
B25: Manual Gangs | G25: 1
B26: Revetment | C26: CUM
B27: Gang

Sheet Sheet1
B1: TYPE OF TOWERS | C1: NO OF TOWERS
B2: DA+0 DFR | C2: 24
B3: DA+0 DRY | C3: 13
B4: DA+0 WET | C4: 4
B5: DA+0 WFR | C5: 18
B6: DA+3/6/9 DRY | C6: 11
B7: DA+3/6/9 DFR | C7: 25
B8: DA+3/6/9 WET | C8: 5
B9: DA+3/6/9 WFR | C9: 17
B10: TOTAL DA TYPE | C10: =SUM(C2:C9) -> 117
B11: DB1+0 DRY | C11: 2
B12: DB1+3/6/9 DFR | C12: 1
B13: DB1+3/6/9 WET | C13: 2
B14: DB2+0 DFR | C14: 2
B15: DB2+0 DRY | C15: 1
B16: DB2+0 WFR | C16: 1
B17: TOTAL DB TYPE | C17: =SUM(C11:C16) -> 9
B18: DC1+0 DFR | C18: 1
B19: DC1+0 WFR | C19: 1
B20: DC1+3/6/9 DFR | C20: 1
B21: DC2+0 WET | C21: 1
B22: DC2+3/6/9 DFR | C22: 1
B23: DC2+3/6/9 DRY | C23: 1
B24: DC2+3/6/9 WFR | C24: 1
B25: TOTAL DC TYPE | C25: =SUM(C18:C24) -> 7
B26: DD45+0 DFR | C26: 2
B27: DD45+9 DFR | C27: 1
B28: DD45+9 WFR | C28: 1
B29: DD60+18 DFR | C29: 1
B30: DD60+9 WFR | C30: 2
B31: TOTAL DD TYPE | C31: =SUM(C26:C30) -> 7
B32: TOTAL TOWERS | C32: =C31+C25+C17+C10 -> 140

Sheet Project Details
A1: Project Code | B1: Project Name | C1: Client Name | D1: NOA Start Date | E1: LOA End Date | F1: Planning Engineer | G1: PCH | H1: Regional Manager | I1: Project Manger | J1: Section Incharge | K1: Supervisor
A2: TA 505 | B2: 765 Kv D/C Beawar-Mandsaur T/L | C2: PBMTL | D2: 22-07-2024 | E2: 21-06-2026 | G2: Mr. Nabajit Baruah | H2: Mr. Nabajit Baruah | I2: Mr. Sushil Kr Tiwari | J2: Mr.Deepak Anand | K2: Nunuchand Mahto
J3: Mr.Bapan Mandal | K3: Birkha Subba
J4: Mr.Panneri Satish | K4: Dilip Kumar
J5: Mr. Varun Mishra | K5: Teklal Mahato
K6: Muneem Meena
K7: Mortuj Ali
K8: Devdas Malik
K9: Jayprakash Nishad
K10: Kumar Singh
K11: K. Sanjeevan
K12: Mridul Baruah
K13: Binda Shah
K14: Prasanta Sahana
K15: Lalit Sahoo
K16: Mahendra Narnaware
K17: Ramprasad
... K19: Rajkumar S

Sheet Sheet5
A1: Loc NO | B1: TOT | C1: Classification | D1: Type of Earthing
A2: 100/0 | B2: DD45+0 | C2: WET | D2: Pipe Type
A3: 101/0 | B3: DC1+3 | C3: DFR | D3: Counter Poise
A4: 101/1 | B4: DA+3 | C4: WFR | D4: Counter Poise
A5: 101/2 | B5: DA+9 | C5: WFR | D5: Counter Poise
A6: 101/3 | B6: DA+3 | C6: WFR | D6: Counter Poise
A7: 101/4 | B7: DA+6 | C7: WFR | D7: Counter Poise
A8: 101/5 | B8: DA+0 | C8: WFR | D8: Counter Poise
A9: 101/6 | B9: DA+3 | C9: WFR | D9: Counter Poise
A10: 101/7 | B10: DA+3 | C10: WFR | D10: Counter Poise
A11: 101/8 | B11: DA-3 | C11: DRY | D11: Pipe Type
A12: 102/0 | B12: DC2+3 | C12: DRY | D12: Pipe Type
... A91: 99/8 | B91: DA+6 | C91: WET | D91: Pipe Type

Sheet Foundation
B1: 765 kV D/C BEAWAR MANDSAUR TRANSMISSION LINE
B2: PROGRESS SUMMARY DETAIL
B3: NOA Date: 22-July-2024 | I3: Completion Date : 21-June-2026 | M3: Date : 27-05-25
B4: SUPPLY VALUE = 458 Cr. | I4: SERVICE VALUE = 94.23 Cr. | M4: F&I VALUE = 9.48 Cr. | S4: =458+94.23+9.48 -> 561.71
B5: Sr. No. | C5: Activity | E5: UOM | G5: Total Qty. | H5: L2 Qty. | I5: Completed | J5: Balance | K5: Submitted | L5: WIP | M5: Remarks
B6: 1 | C6: Details Survey | E6: Kms | G6: 136.705 | H6: 126 | I6: =87.055+32.269+7 -> 126.324 | J6: =G6-I6 -> 10.381 | K6: =17.381-7 -> 10.381
B7: 2 | C7: Check Survey | E7: Kms | G7: 136.705 | H7: 126 | I7: =69.41+32.269+7 -> 108.679 | J7: =G7-I7 -> 28.026
B8: 3 | C8: Soil Testing | E8: Nos | G8: 34 | H8: 34
B9: 4 | C9: Foundation | E9: Nos | G9: 371 | H9: 165 | I9: =S27 -> 377 | J9: =G9-I9 -> -6 | L9: =COUNTIF($S$28:$S$1145, "WIP") -> 2
C10: Gang | E10: Nos | I10: 13
C11: Manpower | E11: Nos
B12: 5 | C12: Earthing | E12: Nos | G12: 346 | I12: 94 | J12: =G12-I12 -> 252
B13: 6 | C13: Erection | E13: Nos | G13: =G9 -> 371 | H13: 98 | I13: ='Erection Compiled'!I6 -> Completed | J13: =G13-I13 -> #VALUE! | L13: =COUNTIF('Erection Compiled'!I7:I391,"WIP") -> 0
C14: Gang | E14: Nos | I14: 4
C15: Manpower | E15: Nos
B16: 7 | C16: Stringing | E16: Nos | G16: =G7 -> 136.705 | H16: 0 | I16: 0 | J16: =G16-I16 -> 136.705
C17: Gang | E17: Nos
C18: Manpower | E18: Nos
B20: Issue : i. DS - pending for approval ii. CS - pending for approval
B21: Supply : Stub : DA : 177 Set, DB : 21 Set, DC : 16 Set, DD45 : 9 Set, DD60 : 13 set Earthing : CP : 84 Set, Pipe : 40 Nos, Rod : 40 Nos Tower : DA BB=107 Set,+0M=52, +3M=35,+6M=19, +9M=3, -1.5=6, -3=14
B23: KEC INTERNATIONAL LIMITED
B24: FOUNDATION DETAIL OF 765KV D/C BEAWAR-MANDSAUR TR LINE
B25: Sr. No | C25: Loc No. | D25: Type of Tower | E25: TOF | F25: Region | G25: Selector | H25: Cement (Bags) | K25: Conc Vol | M25: Excv Vol(m3) | N25: R/F (KG) | O25: Wt of Stub(MT) | P25: Rev(Inr) | Q25: Month of Execution | R25: Sub Contractor | S25: Status | T25: Excavation | V25: Casting | X25: Remarks if any
H26: RCC | I26: PCC | J26: Toal Cement | K26: M 20(m3) | L26: M 10(m3) | T26: Start | U26: Completion | V26: Start | W26: Completion
B27: Total = | H27: =SUM(H28:H423) -> 151243.1 | I27: =SUM(I28:I423) -> 7715.9052 | J27: =SUM(J28:J423) -> 158959.01 | K27: =SUM(K28:K423) -> 18892.338 | L27: =SUM(L28:L423) -> 1732.863 | M27: =SUM(M28:M423) -> 113304.29 | N27: =SUM(N28:N423) -> 1260369.6 | O27: =SUM(O28:O423) -> 1345.597 | P27: =SUM(P28:P423) -> 3.0707497e+08 | S27: =COUNTIF(S28:S590,"Complete") -> 377
B28: 1 | C28: 101/2 | D28: DA+9 | E28: WFR | F28: RAJ | G28: DA+9 WFR | H28: 383 | I28: 20 | J28: 403 | K28: 47.77 | L28: 4.46 | M28: 264.87 | N28: 2353 | O28: 0.866276 | P28: 1126247.4 | Q28: 45566 | R28: RST | S28: Complete | T28: 45546 | U28: 45561 | V28: 45567 | W28: 45571
B29: 2 | C29: 100/0 | D29: DD45+0 | E29: WET | F29: RAJ | H29: =K29*8 -> 1239.68 | I29: =L29*4.4 -> 70.18 | J29: =SUM(H29:I29) -> 1309.86 | K29: 154.96 | L29: 15.95 | M29: 1192.7 | N29: 15096 | O29: 2.495 | Q29: 45944 | R29: Sumit Const/Om Prakash | S29: Complete | W29: 45946
B30: 3 | C30: 101/0 | D30: DC1+3 | E30: DFR | F30: RAJ | H30: =K30*8 -> 614.16 | I30: =L30*4.4 -> 27.984 | J30: =SUM(H30:I30) -> 642.144 | K30: 76.77 | L30: 6.36 | M30: 388.74 | N30: 3855 | O30: 2.348757 | P30: 1765261 | Q30: 45791 | R30: Sumit Const/Om Prakash | S30: Complete | W30: 45808
B31: 4 | C31: 101/1 | D31: DA+3 | E31: WFR | F31: RAJ | G31: DA+9 WFR | H31: 383 | I31: 20 | J31: 403 | K31: 47.77 | L31: 4.46 | M31: 264.87 | N31: 2353 | O31: 0.866276 | P31: 1126247.4 | Q31: 45597 | R31: RST | S31: Complete | T31: 45598 | U31: 45604 | V31: 45609 | W31: 45610
B32: 5 | C32: 101/3 | D32: DA+3 | E32: WFR | F32: RAJ | G32: DA+9 WFR | H32: 383 | I32: 20 | J32: 403 | K32: 47.77 | L32: 4.46 | M32: 264.87 | N32: 2353 | O32: 0.866276 | P32: 1126247.4 | Q32: 45566 | R32: RST | S32: Complete | T32: 45566 | U32: 45571 | V32: 45573 | W32: 45576
B33: 6 | C33: 101/4 | D33: DA+6 | E33: WFR | F33: RAJ | G33: DA+9 WFR | H33: 383 | I33: 20 | J33: 403 | K33: 47.77 | L33: 4.46 | M33: 264.87 | N33: 2353 | O33: 0.866276 | P33: 1126247.4 | Q33: 45566 | R33: RST | S33: Complete | T33: 45551 | U33: 45556 | V33: 45584 | W33: 45586
B34: 7 | C34: 101/5 | D34: DA+0 | E34: WFR | F34: RAJ | G34: DA+0 WFR | H34: 333 | I34: 19 | J34: 352 | K34: 41.54 | L34: 4.23 | M34: 250.46 | N34: 1909 | O34: 0.866276 | P34: 984923.64 | Q34: 45566 | R34: RST | S34: Complete | T34: 45557 | U34: 45561 | V34: 45588 | W34: 45590
B35: 8 | C35: 101/6 | D35: DA+3 | E35: WFR | F35: RAJ | G35: DA+9 WFR | H35: 383 | I35: 20 | J35: 403 | K35: 47.77 | L35: 4.46 | M35: 264.87 | N35: 2353 | O35: 0.866276 | P35: 1126247.4 | Q35: 45597 | R35: RST | S35: Complete | T35: 45589 | U35: 45591 | V35: 45595 | W35: 45598
B36: 9 | C36: 101/7 | D36: DA+3 | E36: WFR | F36: RAJ | G36: DA+9 WFR | H36: 383 | I36: 20 | J36: 403 | K36: 47.77 | L36: 4.46 | M36: 264.87 | N36: 2353 | O36: 0.866276 | P36: 1126247.4 | Q36: 45597 | R36: RST | S36: Complete | T36: 45606 | U36: 45610 | V36: 45613 | W36: 45614
B37: 10 | C37: 101/8 | D37: DA-3 | E37: DRY | F37: RAJ | G37: DA+0 DRY | H37: 236 | I37: 13 | J37: 249 | K37: 29.49 | L37: 2.86 | M37: 233.05 | N37: 1526 | O37: 0.866276 | P37: 645061.95 | Q37: 45597 | R37: RST | S37: Complete | T37: 45593 | U37: 45598 | V37: 45603 | W37: 45604
B38: 11 | C38: 102/0 | D38: DC2+3 | E38: DRY | F38: RAJ | G38: DC2+9 DRY | H38: 856 | I38: 38 | J38: 894 | K38: 106.91 | L38: 8.53 | M38: 653.08 | N38: 5502 | O38: 2.348757 | P38: 2257063.8 | Q38: 45627 | R38: RST | S38: Complete | T38: 45618 | U38: 45621 | V38: 45637 | W38: 45640
B39: 12 | C39: 103/0 | D39: DC1+6 | E39: DFR | F39: RAJ | H39: =K39*8 -> 614.16 | I39: =L39*4.4 -> 27.984 | J39: =SUM(H39:I39) -> 642.144 | K39: 76.77 | L39: 6.36 | M39: 388.74 | N39: 3855 | O39: 2.348757 | P39: 1765261 | Q39: 45789 | R39: Sumit Const/Om Prakash | S39: Complete | W39: 45799
B40: 13 | C40: 103/1 | D40: DA+0 | E40: DRY | F40: RAJ | H40: 236 | I40: 13 | J40: 249 | K40: 29.49 | L40: 2.86 | M40: 233.05 | N40: 1526 | O40: 0.866276 | P40: 645061.95 | Q40: 45784 | R40: Sumit Const/Om Prakash | S40: Complete | W40: 45788
B41: 14 | C41: 103/2 | D41: DA+0 | E41: DRY | F41: RAJ | H41: 236 | I41: 13 | J41: 249 | K41: 29.49 | L41: 2.86 | M41: 233.05 | N41: 1526 | O41: 0.866276 | P41: 645061.95 | Q41: 45780 | R41: Sumit Const/Om Prakash | S41: Complete | W41: 45790
B42: 15 | C42: 103/3 | D42: DA+0 | E42: DFR | F42: RAJ | H42: 221 | I42: 12 | J42: 233 | K42: 27.61 | L42: 2.61 | M42: 146.96 | N42: 1450 | O42: 0.866276 | P42: 650458.11 | Q42: 45780 | R42: Sumit Const/Om Prakash | S42: Complete | W42: 45785
...

Sheet Balance Erc-RAJ
A1: Balance Erection Status (Rajasthan)
A2: SL No | B2: Loc No | C2: TOT | D2: Tower Availability | E2: Current Status | F2: Remarks
A3: 1 | B3: 99/1 | C3: DA+6 | D3: NO | E3: Erectable | F3: Tower Parts not available-Supply in PGCIL Scope.
A4: 2 | B4: 99/2 | C4: DA+6 | D4: NO | E4: Erectable
A5: 3 | B5: 99/3 | C5: DA+0 | D5: NO | E5: Erectable
A6: 4 | B6: 99/4 | C6: DA+0 | D6: NO | E6: Erectable
A7: 5 | B7: 99/5 | C7: DA+0 | D7: NO | E7: Erectable
A8: 6 | B8: 99/6 | C8: DA+0 | D8: NO | E8: Erectable
A9: 7 | B9: 99/7 | C9: DA+6 | D9: YES | E9: WIP
A10: 8 | B10: 103/9 | C10: DA+3 | D10: Yes | E10: Planned
A11: 9 | B11: 110/0 | C11: DC2+3 | E11: Water logged
A12: 10 | B12: 118/0 | C12: DD60+6 | D12: NO | F12: Tower Parts availability-Last Week of November-25.
A13: 11 | B13: 122/0 | C13: DD60+3 | D13: Yes | E13: Planned
A14: 12 | B14: 132/0 | C14: DD60+6 | D14: NO | F14: Tower Parts availability-Last Week of November-25.
A15: 13 | B15: 135/3 | C15: DA+9 | D15: Yes | E15: Water logged
A16: 14 | B16: 140/0 | C16: DC1+9 | D16: Yes | E16: Planned
A17: 15 | B17: 141/0 | C17: DD45+0 | D17: Yes | E17: Planned | F17: Approach Issue.
A18: 16 | B18: 142/0 | C18: DD45+3 | D18: Yes | E18: 11 Kv Line shifting required
A19: 17 | B19: 144A/2 | C19: DA+3 | D19: Yes | E19: Opium Planted
A20: 18 | B20: 147/0 | C20: DB2+6 | D20: Yes | E20: Chia Planted | F20: Land Owner objection
A21: 19 | B21: 148/0 | C21: DD60+6 | D21: NO | F21: Tower Parts availability-Last Week of November-25.
A22: 20 | B22: 149B/1 | C22: DB2+15 | D22: NO | F22: Tower Parts availability-December-25.
A23: 21 | B23: 149B/4 | C23: DA+0 | D23: Yes | E23: WIP
A24: 22 | B24: 151/0 | C24: DD45+3 | D24: Yes | E24: Garlic Planted
A25: 23 | B25: 152/1 | C25: DA+6 | D25: Yes | E25: Opium Planted
A26: 24 | B26: 152/2 | C26: DA+0 | D26: Yes | E26: Opium Planted | F26: Managable
A27: 25 | B27: 152/3 | C27: DA-1.5 | D27: Yes | E27: Opium Planted
A28: 26 | B28: 152A/0 | C28: DB1+0 | D28: Yes | E28: Planned
A29: 27 | B29: 152A/6 | C29: DA+0 | D29: Yes | E29: Planned | F29: 33 kV Line SD required
A30: 28 | B30: 152A/7 | C30: DA+6 | D30: Yes | E30: Planned | F30: 33 kV Line SD required
A31: 29 | B31: 152A/10 | C31: DA+0 | D31: Yes | E31: Planned | F31: 33 kV Line SD required
A32: 30 | B32: 152A/11 | C32: DA-1.5 | D32: Yes | E32: Opium Planted
A33: 31 | B33: 152A/12 | C33: DA-3 | D33: Yes | E33: Opium Planted
A34: 32 | B34: 154/4 | C34: DA+3 | D34: Yes | E34: Planned
A35: 33 | B35: 155/0 | C35: DC2+0 | D35: Yes | E35: Opium Planted in adjacent land
A36: 34 | B36: 155/1 | C36: DA+0 | D36: Yes | E36: Approach Issue
A37: 35 | B37: 155/2 | C37: DA+3 | D37: Yes | E37: Approach Issue/Opium
A38: 36 | B38: 156/3 | C38: DA+0 | D38: Yes | E38: ROW | F38: Compensation Issue

Sheet ERC ROW-MP
A1: Balance Erection Status (MP)
A2: SL No | B2: Loc No | C2: TOT | D2: Tower Availability | E2: Current Status | F2: Remarks
A3: 1 | B3: 159/3 | C3: DA+0 | D3: Yes | E3: Shutdown Issue
A4: 2 | B4: 161/1 | C4: DA+3 | D4: Yes | E4: Opium Planted
A5: 3 | B5: 161/5 | C5: DA+6
A6: 4 | B6: 164/2 | C6: DA+0 | D6: Yes | E6: Shutdown Issue
A7: 5 | B7: 164/3 | C7: DA+3
A8: 6 | B8: 164/4 | C8: DA+0 | D8: Yes | E8: Shutdown Issue
A9: 7 | B9: 164/6 | C9: DA+3
A10: 8 | B10: 164/7 | C10: DA+3
A11: 9 | B11: 165/1 | C11: DA+6 | D11: Yes | E11: Line Shifting Reqd
A12: 10 | B12: 165/2 | C12: DA+0 | D12: Yes | E12: Shutdown Issue
A13: 11 | B13: 165/3 | C13: DA+0 | D13: Yes | E13: Opium Planted
A14: 12 | B14: 165/4 | C14: DA-3 | D14: Yes | E14: Approach Issue
A15: 13 | B15: 165/5 | C15: DA-3 | D15: Yes | E15: Approach Issue
A16: 14 | B16: 166/2 | C16: DA+0 | D16: Yes | E16: Compensation Issue
A17: 15 | B17: 166/3 | C17: DA+0 | D17: Yes | E17: Opium Planted
A18: 16 | B18: 166/4 | C18: DA+3
A19: 17 | B19: 168/0 | C19: DC2+0 | D19: Yes | E19: Opium Planted
A20: 18 | B20: 169/0 | C20: DC1+3
A21: 19 | B21: 170/2 | C21: DA+0
A22: 20 | B22: 170/3 | C22: DA+0 | D22: Yes | E22: Opium Planted
A23: 21 | B23: 170/4 | C23: DA-3 | D23: Yes | E23: ROW | F23: Tower Erectable after Crop Harvesting.
A24: 22 | B24: 170/5 | C24: DA+0
A25: 23 | B25: 170/6 | C25: DA-3 | D25: Yes | E25: ROW | F25: Tower Erectable after Crop Harvesting.
A26: 24 | B26: 170/9 | C26: DA+0 | D26: Yes | E26: Opium Planted
A27: 25 | B27: 170/10 | C27: DA+0 | D27: Yes | E27: Opium Planted
A28: 26 | B28: 171/0 | C28: DB1+0 | D28: No | E28: Approach Issue
A29: 27 | B29: 171/1 | C29: DA-3 | D29: Yes | E29: Opium Planted
A30: 28 | B30: 171/2 | C30: DA+0 | D30: Yes | E30: Opium Planted
A31: 29 | B31: 171/3 | C31: DA+0 | D31: Yes | E31: ROW | F31: Tower Erectable after Crop Harvesting.
A32: 30 | B32: 171/4 | C32: DA+0 | D32: Yes | E32: ROW | F32: Tower Erectable after Crop Harvesting.
A33: 31 | B33: 171/6 | C33: DA+0
A34: 32 | B34: 171/7 | C34: DA+0
A35: 33 | B35: 171/8 | C35: DA-3
A36: 34 | B36: 171/9 | C36: DA+0
A37: 35 | B37: 171/10 | C37: DA+0
A38: 36 | B38: 172/0 | C38: DB1+0
A39: 37 | B39: 172/1 | C39: DA-3
A40: 38 | B40: 172/4 | C40: DA+0
...

Sheet Erection Compiled
O3: 46164
B4: Sr. No | C4: Location No. | D4: Tower Type | E4: Tower Weight | F4: Rev(Inr) | G4: Month of Execution | H4: Gang Name | I4: Status | J4: Starting Date | K4: Completion Date | L4: No of Compl. Days | M4: Region | N4: Tower Tightening | O4: Remarks
E5: =SUM(E6:E392) -> 16909.501 | I5: =COUNTIF(I6:I1636,"Completed") -> 362 | N5: =COUNTIF(N6:N1636,"OK") -> 177
B6: 1 | C6: 101/2 | D6: DA+9 | E6: 45.697022 | F6: =E6*10940 -> 499925.42 | G6: 45658 | H6: Jwala Singh | I6: Completed | J6: 45671 | K6: 45676 | L6: =K6-J6 -> 5 | M6: Raj | N6: OK
B7: 2 | C7: 101/1 | D7: DA+3 | E7: 37.931088 | F7: =E7*10940 -> 414966.1 | G7: 45658 | H7: Jwala Singh | I7: Completed | J7: 45678 | K7: 45681 | L7: =K7-J7 -> 3 | M7: Raj | N7: OK
B8: 3 | C8: 101/3 | D8: DA+3 | E8: 37.931088 | F8: =E8*10940 -> 414966.1 | G8: 45658 | H8: Jwala Singh | I8: Completed | J8: 45681 | K8: 45684 | L8: =K8-J8 -> 3 | M8: Raj | N8: OK
B9: 4 | C9: 101/4 | D9: DA+6 | E9: 43.804424 | F9: =E9*10940 -> 479220.4 | G9: 45658 | H9: Jwala Singh | I9: Completed | J9: 45684 | K9: 45688 | L9: =K9-J9 -> 4 | M9: Raj | N9: OK
B10: 5 | C10: 101/5 | D10: DA+0 | E10: 36.159756 | F10: =E10*10940 -> 395587.73 | G10: 45689 | H10: Jwala Singh | I10: Completed | J10: 45689 | K10: 45692 | L10: =K10-J10 -> 3 | M10: Raj | N10: OK
B11: 6 | C11: 101/6 | D11: DA+3 | E11: 37.931088 | F11: =E11*10940 -> 414966.1 | G11: 45689 | H11: Jwala Singh | I11: Completed | J11: 45693 | K11: 45696 | L11: =K11-J11 -> 3 | M11: Raj | N11: OK
B12: 7 | C12: 101/7 | D12: DA+3 | E12: 37.931088 | F12: =E12*10940 -> 414966.1 | G12: 45689 | H12: Jwala Singh | I12: Completed | J12: 45697 | K12: 45700 | L12: =K12-J12 -> 3 | M12: Raj | N12: OK
B13: 8 | C13: 101/8 | D13: DA-3 | E13: 34.78981 | F13: =E13*10940 -> 380600.52 | G13: 45689 | H13: Jwala Singh | I13: Completed | J13: 45701 | K13: 45703 | L13: =K13-J13 -> 2 | M13: Raj | N13: OK
B14: 9 | C14: 110/7 | D14: DA+3 | E14: 37.931088 | F14: =E14*10940 -> 414966.1 | G14: 45689 | H14: Jwala Singh | I14: Completed | J14: 45705 | K14: 45708 | L14: =K14-J14 -> 3 | M14: Raj | N14: OK
B15: 10 | C15: 110/5 | D15: DA+3 | E15: 37.931088 | F15: =E15*10940 -> 414966.1 | G15: 45689 | H15: Jwala Singh | I15: Completed | J15: 45709 | K15: 45712 | L15: =K15-J15 -> 3 | M15: Raj | N15: OK
B16: 11 | C16: 109/2 | D16: DA-1.5 | E16: 35.602 | F16: =E16*10940 -> 389485.88 | G16: 45689 | H16: Jwala Singh | I16: Completed | J16: 45713 | K16: 45716 | L16: =K16-J16 -> 3 | M16: Raj | N16: OK
B17: 12 | C17: 109/1 | D17: DA-1.5 | E17: 35.602 | F17: =E17*10940 -> 389485.88 | G17: 45717 | H17: Jwala Singh | I17: Completed | J17: 45717 | K17: 45720 | L17: =K17-J17 -> 3 | M17: Raj | N17: OK
... B43: 38 | C43: 104/2 | D43: DA-3 | E43: 34.79 | F43: =E43*10940 -> 380602.6 | G43: 45748 | H43: Jwala Singh | I43: Completed | J43: 45769 | K43: 45772 | L43: =K43-J43 -> 3 | M43: Raj | N43: OK
B44: 39 | C44: 159/1 | D44: DA+0 | E44: 36.159756 | F44: =E44*10940 -> 395587.73 | G44: 45778 | H44: Paramanand | I44: Completed | J44: 45769 | K44: 45785 | L44: =K44-J44 -> 16 | M44: MP
B45: 40 | C45: 120/2 | D45: DA-1.5 | E45: 35.602 | F45: =E45*10940 -> 389485.88 | G45: 45748 | H45: Jwala Singh-2 | I45: Completed | J45: 45769 | K45: 45774 | L45: =K45-J45 -> 5 | M45: Raj | N45: OK
B46: 41 | C46: 114/1 | D46: DA+3 | E46: 37.931088 | F46: =E46*10940 -> 414966.1 | G46: 45748 | H46: Gokul/Rajwanshi | I46: Completed | J46: 45772 | K46: 45777 | L46: =K46-J46 -> 5 | M46: Raj | N46: OK
B47: 42 | C47: 113/6 | D47: DA+6 | E47: 43.804424 | F47: =E47*10940 -> 479220.4 | G47: 45778 | H47: Eagle Enterprises/Paramand | I47: Completed | J47: 45771 | K47: 45779 | L47: =K47-J47 -> 8 | M47: Raj | N47: OK
B48: 43 | C48: 105/1 | D48: DA+0 | E48: 36.159756 | F48: =E48*10940 -> 395587.73 | G48: 45748 | H48: Jwala Singh | I48: Completed | J48: 45773 | K48: 45776 | L48: =K48-J48 -> 3 | M48: Raj | N48: OK
B49: 44 | C49: 120/1 | D49: DA+0 | E49: 36.159756 | F49: =E49*10940 -> 395587.73 | G49: 45778 | H49: Jwala Singh-2 | I49: Completed | J49: 45774 | K49: 45779 | L49: =K49-J49 -> 5 | M49: Raj | N49: OK
B50: 45 | C50: 111/4 | D50: DA+9 | E50: 45.697022 | F50: =E50*10940 -> 499925.42 | G50: 45778 | H50: Jwala Singh | I50: Completed | J50: 45777 | K50: 45783 | L50: =K50-J50 -> 6 | M50: Raj | N50: OK
B51: 46 | C51: 116/2 | D51: DA+3 | E51: 37.931088 | F51: =E51*10940 -> 414966.1 | G51: 45778 | H51: Gokul/Rajwanshi | I51: Completed | J51: 45779 | K51: 45785 | L51: =K51-J51 -> 6 | M51: Raj | N51: OK
B52: 47 | C52: 120/3 | D52: DA+9 | E52: 45.697022 | F52: =E52*10940 -> 499925.42 | G52: 45778 | H52: Jwala Singh-2 | I52: Completed | J52: 45779 | K52: 45784 | L52: =K52-J52 -> 5 | M52: Raj | N52: OK
B53: 48 | C53: 111/1 | D53: DA+3 | E53: 37.931088 | F53: =E53*10940 -> 414966.1 | G53: 45778 | H53: Eagle Enterprises/Paramand | I53: Completed | J53: 45779 | K53: 45786 | L53: =K53-J53 -> 7 | M53: Raj | N53: OK
B54: 49 | C54: 111/3 | D54: DA+0 | E54: 36.159756 | F54: =E54*10940 -> 395587.73 | G54: 45778 | H54: Jwala Singh | I54: Completed | J54: 45783 | K54: 45788 | L54: =K54-J54 -> 5 | M54: Raj | N54: OK
B55: 50 | C55: 127/2 | D55: DA+0 | E55: 36.159756 | F55: =E55*10940 -> 395587.73 | G55: 45778 | H55: Jwala Singh-2 | I55: Completed | J55: 45785 | K55: 45789 | L55: =K55-J55 -> 4 | M55: Raj | N55: OK
B56: 51 | C56: 116/1 | D56: DA+3 | E56: 37.931088 | F56: =E56*10940 -> 414966.1 | G56: 45778 | H56: Gokul/Rajwanshi | I56: Completed | J56: 45785 | K56: 45792 | L56: =K56-J56 -> 7 | M56: Raj | N56: OK
B57: 52 | C57: 160/5 | D57: DA+0 | E57: 36.159756 | F57: =E57*10940 -> 395587.73 | G57: 45778 | H57: Paramanand-1 | I57: Completed | J57: 45785 | K57: 45800 | L57: =K57-J57 -> 15 | M57: MP
B58: 53 | C58: 161/4 | D58: DA+0 | E58: 36.159756 | F58: =E58*10940 -> 395587.73 | G58: 45778 | H58: Paramanand-2 | I58: Completed | J58: 45785 | K58: 45804 | L58: =K58-J58 -> 19 | M58: MP
B59: 54 | C59: 111/2 | D59: DA+3 | E59: 37.931088 | F59: =E59*10940 -> 414966.1 | G59: 45778 | H59: Eagle Enterprises/Paramand | I59: Completed | J59: 45786 | K59: 45795 | L59: =K59-J59 -> 9 | M59: Raj | N59: OK
B60: 55 | C60: 152A/3 | D60: DA+3 | E60: 37.931088 | F60: =E60*10940 -> 414966.1 | G60: 45778 | H60: Jwala Singh | I60: Completed | J60: 45791 | K60: 45793 | L60: =K60-J60 -> 2 | M60: Raj | N60: OK
B61: 56 | C61: 127/1 | D61: DA+0 | E61: 36.159756 | F61: =E61*10940 -> 395587.73 | G61: 45778 | H61: Jwala Singh-2 | I61: Completed | J61: 45790 | K61: 45793 | L61: =K61-J61 -> 3 | M61: Raj | N61: OK
B62: 57 | C62: 154/5 | D62: DA+0 | E62: 36.159756 | F62: =E62*10940 -> 395587.73 | G62: 45778 | H62: Gokul/Rajwanshi | I62: Completed | J62: 45793 | K62: 45799 | L62: =K62-J62 -> 6 | M62: Raj
B63: 58 | C63: 152A/1 | D63: DA-1.5 | E63: 35.602 | F63: =E63*10940 -> 389485.88 | G63: 45778 | H63: Jwala Singh | I63: Completed | J63: 45794 | K63: 45798 | L63: =K63-J63 -> 4 | M63: Raj
B64: 59 | C64: 129A/3 | D64: DA+0 | E64: 36.159756 | F64: =E64*10940 -> 395587.73 | G64: 45809 | H64: Eagle Enterprises/Paramand | I64: Completed | J64: 45796 | K64: 45815 | L64: =K64-J64 -> 19 | M64: Raj
B65: 60 | C65: 126/4 | D65: DA+9 | E65: 45.697022 | F65: =E65*10940 -> 499925.42 | G65: 45778 | H65: Jwala Singh-2 | I65: Completed | J65: 45794 | K65: 45799 | L65: =K65-J65 -> 5 | M65: Raj | N65: OK
B66: 61 | C66: 152A/2 | D66: DA+0 | E66: 36.159756 | F66: =E66*10940 -> 395587.73 | G66: 45778 | H66: Jwala Singh | I66: Completed | J66: 45799 | K66: 45803 | L66: =K66-J66 -> 4 | M66: Raj | N66: OK
B67: 62 | C67: 155/3 | D67: DA+0 | E67: 36.159756 | F67: =E67*10940 -> 395587.73 | G67: 45778 | H67: Gokul/Rajwanshi | I67: Completed | J67: 45800 | K67: 45804 | L67: =K67-J67 -> 4 | M67: Raj
...

Sheet Stringing Compiled
D2: Number of TSE | E2: 1
A4: S.no | B4: Sec | C4: From AP | D4: To AP | E4: Span (M) | F4: Towers in Section | G4: Method | H4: Section Readiness | I4: Insulator Hoisting | J4: P/O Starting Date | K4: P/O Completion Date | L4: P/O | M4: F/S Starting Date | N4: F/S/ Completion Date | O4: Jumpering | P4: Spacering | Q4: Clipping | R4: Length | S4: Status | T4: Gang Name | U4: Gang Strength | V4: Number of Fitters | W4: Hindrance | X4: Remarks
A5: 1 | B5: 100/0 To 101/0 | C5: 100/0 | D5: 101/0 | E5: 419 | F5: 100/0, 101/0 | G5: Manual | H5: Ready | I5: Done | J5: 46042 | K5: 46047 | L5: Done | M5: 46058 | N5: 46060 | R5: =E5 -> 419 | S5: Done | T5: Alimuddin | U5: 30
A6: 2 | B6: 101/0 To 102/0 | C6: 101/0 | D6: 102/0 | E6: 3470 | F6: 101/0,101/1, 101/2, 101/3, 101/4, 101/5, 101/6, 101/7, 101/8 & 102/0 | G6: TSE | H6: Ready | I6: Done | J6: 46049 | K6: 46055 | L6: Done | M6: 46063 | N6: 46068 | R6: =E6 -> 3470 | S6: Done | T6: Alimuddin | U6: 30
A7: 3 | B7: 102/0 To 103/0 | C7: 102/0 | D7: 103/0 | E7: 461 | F7: 102/0 & 103/0 | G7: Manual | H7: Ready | I7: Done | J7: 46061 | K7: 46065 | L7: Done | M7: 46071 | N7: 46075 | R7: =E7 -> 461 | S7: Done | T7: Alimuddin | U7: 30
A8: 4 | B8: 103/0 To 103/5A | C8: 103/0 | D8: 103/5A | E8: 2200 | F8: 103/0, 103/1, 103/2, 103/4, 103/5 & 103/5A | G8: TSE | H8: Ready | I8: Done | J8: 46069 | K8: 46075 | L8: Done | M8: 46079 | N8: 46081 | R8: 2200 | S8: Done | T8: Alimuddin | U8: 30
A9: 5 | B9: 103/5A To 103/6A | C9: 103/5A | D9: 103/6A | E9: 567 | F9: 103/5A,103/5A1 & 103/6A | G9: TSE | H9: Ready | I9: Done | J9: 46077 | K9: 46079 | L9: Done | M9: 46093 | N9: 46097 | R9: 567 | S9: Done | T9: Alimuddin | U9: 30
A10: 6 | B10: 103/6A To 104/0 | C10: 103/6A | D10: 104/0 | E10: 1403 | F10: 103/6A ,103/7, 103/8, 103/9 & 104/0. | G10: TSE | H10: Ready | I10: Done | J10: 46093 | K10: 46097 | L10: Done | M10: 46098 | N10: 46101 | R10: 1403 | S10: Done | T10: Alimuddin | U10: 30
A11: 7 | B11: 104/0 To 105/0 | C11: 104/0 | D11: 105/0 | E11: 967 | F11: 104/0, 104/1, 104/2 & 105/0 | G11: TSE | H11: Ready | I11: Done | J11: 46088 | K11: 46063 | L11: Done | M11: 46124 | N11: 46129 | R11: 967 | S11: Done | T11: Alimuddin | U11: 30
A12: 8 | B12: 111/0 To 112/0 | C12: 111/0 | D12: 112/0 | E12: 1954 | F12: 111/0, 111/1, 111/2, 111/3, 111/4 & 112/0 | G12: TSE | H12: Ready | I12: Done | J12: 46109 | K12: 46110 | L12: Done | M12: 46110 | N12: 46112 | R12: 1954 | S12: Done | T12: Alimuddin | U12: 30
A13: 9 | B13: 113/0 To 114/0 | C13: 113/0 | D13: 114/0 | E13: 2565 | F13: 113/0, 113/1, 113/2 , 113/3, 113/4, 113/5, 113/6 & 114/0 | G13: TSE | H13: Ready | I13: Done | J13: 46106 | K13: 46108 | L13: Done | M13: 46109 | N13: 46112 | R13: 2565 | S13: Done | T13: Jahangir Alam | U13: 38
A14: 10 | B14: 114/0 To 115/0 | C14: 114/0 | D14: 115/0 | E14: 4304 | F14: 114/0, 114/1, 114/2, 114/3, 114/4, 114/5, 114/6, 114/7, 114/8, 114/9, 114/10 & 115/0 | G14: TSE | H14: Ready | I14: Done | J14: 46164 | K14: 46178 | L14: Done | M14: 46179 | N14: 46182 | R14: 4304 | S14: Done | T14: Jahangir Alam | U14: 38
A15: 11 | B15: 110A/0 To 111/0 | C15: 110A/0 | D15: 111/0 | E15: 1230 | F15: 110A/0 , 110A/1, 110A/2 & 111/0. | G15: TSE | H15: Ready | I15: Done | J15: 46156 | K15: 46160 | L15: Done | M15: 46167 | N15: 46171 | R15: 1230 | S15: Done | T15: Alimuddin | U15: 35
A16: 12 | B16: 110/0 To 110A/0 | C16: 110/0 | D16: 110A/0 | E16: 3860 | F16: 110/0,110/1,110/2,110/2,110/3,110/3,110/4,110/5,110/6,110/7,110/8,110A/0 | G16: TSE | H16: Ready | I16: Done | J16: 46181 | K16: 46185 | L16: Done | M16: 46186 | N16: 46189 | R16: 3860 | S16: Done | T16: Nasiruddin | U16: 25
A17: 13 | B17: 112/0 To 113/0 | C17: 112/0 | D17: 113/0 | E17: 226 | F17: 112/0, 113/0 | G17: Hot Line | H17: Ready | I17: Done | J17: 46166 | K17: 46172 | L17: Done | M17: 46166 | N17: 46172 | R17: 226 | S17: Done | T17: Ram Singh | U17: 25
A18: 14 | B18: 126/0 To 127/0 | C18: 126/0 | D18: 127/0 | E18: 1957
A19: 15 | B19: 127/0 To 128/0 | C19: 127/0 | D19: 128/0 | E19: 1441
A20: 16 | B20: 108/0 To 109/0 | C20: 108/0 | D20: 109/0 | E20: 1668
A21: 17 | B21: 109/0 To 110/0 | C21: 109/0 | D21: 110/0 | E21: 1949 | F21: 109/0,109/1,109/2,109/3,109/4, 110/0 | G21: TSE | H21: Ready | I21: Done | J21: 46191 | T21: Nasiruddin | U21: 50
A22: 18 | B22: 115/0 To 116/0 | C22: 115/0 | D22: 116/0 | E22: 200 | F22: 115/0,116/0 | G22: Hot Line | H22: Ready | I22: Done | J22: 46174 | K22: 46185 | L22: Done | M22: 46174 | N22: 46185 | R22: 200 | S22: Done | T22: Ram Singh | U22: 25
A23: 19 | B23: 105/0 To 106/0 | C23: 105/0 | D23: 106/0 | E23: 754
A24: 20 | B24: 106/0 To 108/0 | C24: 106/0 | D24: 108/0 | E24: 212
A25: 21 | B25: 117/0 To 118/0 | C25: 117/0 | D25: 118/0 | E25: 240 | F25: 117/0 ,118/0 | G25: Hot Line | H25: Ready | I25: Done | J25: 46188 | K25: 46192 | L25: Done | M25: 46188 | N25: 46192 | R25: 240 | S25: Done | T25: Ram Singh | U25: 41
A26: 22 | B26: 147/0 To 147A/0 | C26: 147/0 | D26: 147A/0
A27: 23 | B27: 147A/0 To148/0 | C27: 147A/0 | D27: 148/0
A28: 24 | B28: 175/0 To 176/0 | C28: 175/0 | D28: 176/0
A29: 25 | B29: 176/0 To 177/0 | C29: 176/0 | D29: 177/0 | E29: 1564 | F29: 176/0,176/1, 176/2,176/3,177/0 | G29: TSE | H29: Ready | I29: Done | J29: 46192 | T29: Sk infra | U29: 22
A30: 26 | B30: 177/0 To 178/0 | C30: 177/0 | D30: 178/0 | H30: Ready | I30: Done
A31: 27 | B31: 116/0 To 117/0 | C31: 116/0 | D31: 117/0 | E31: 1147 | F31: 116/0,116/1, 116//2 117/0 | G31: TSE | H31: Ready | I31: Done | J31: 46185 | K31: 46188 | L31: Done | M31: 46189 | N31: 46192 | R31: 1147 | S31: Done | T31: Jahangir Alam | U31: 38
A32: 28 | B32: 120/0 To 121/0 | C32: 120/0 | D32: 121/0 | E32: 1593 | F32: 120/0,121/0 | G32: TSE | H32: Ready | I32: Done | T32: Jahangir Alam | U32: 38
A33: 29 | B33: 119/0 To 120/0 | C33: 119/0 | D33: 120/0 | E33: 193 | F33: 119/0,120/0 | G33: Hot Line | H33: Ready | I33: Done | T33: Ram Singh | U33: 41
A34: 30 | B34: 118/0 To 119/0 | C34: 118/0 | D34: 119/0 | E34: 421 | F34: 118/0, 119/0 | G34: Manual | H34: Ready | I34: Done | J34: 46194 | M34: 46194 | T34: Ram Singh | U34: 41
A35: 31
A36: 32
A37: 33
D235: Total | E235: =SUM(E5:E233)/1000 -> 36.965 | R235: =SUM(R5:R234)/1000 -> 25.213

Sheet Visual Chart
M2: V I S U A L C H A R T
B5: DATE : | D5: 46189
B6: Name of Line : | E6: 765 KV D/C HEXA BEAWAR MANDSAUR T/L
B7: Project Code: | F7: TA505
B8: Name of Executing Agency: | F8: M/s. KEC INTERNATIONAL LTD.
AG9: FDN | AH9: Ear | AI9: ERE | AJ9: TW | AK9: STR
V10: COMMON TOWER
V11: 99/0 | X11: 99/1 | Z11: 99/2 | AB11: 99/3 | AD11: 99/4 | AG11: 4 | AH11: 0 | AI11: 4
Z12: 1 | AB12: 1
V13: 1 | X13: 2 | Z13: 3 | AB13: 4 | AD13: 1
S14: BAJEL PART | U14: 0 | V14: BAJEL | W14: 360 | X14: OK | Y14: 420 | Z14: OK | AA14: 410 | AB14: OK | AC14: 382 | AD14: OK
V16: 0 | X16: 0 | Z16: 0 | AB16: 0 | AD16: 0
V17: DB2+0 | X17: DA+6 | Z17: DA+6 | AB17: DA+0 | AD17: DA+0
U19: RAJASTHAN REGION
O21: =+LEFT(O28,1) -> D | Q21: =+LEFT(Q28,1) -> D | U21: =+LEFT(U28,1) -> D | W21: =+LEFT(W28,1) -> D | Y21: =+LEFT(Y28,1) -> D | AA21: =+LEFT(AA28,1) -> D | AC21: =+LEFT(AC28,1) -> D | AE21: =+LEFT(AE28,1) -> D
C22: 99/5 | E22: 99/6 | G22: 99/7 | I22: 99/8 | K22: 100/0 | M22: 101/0 | O22: 101/1 | Q22: 101/2 | S22: 101/3 | U22: 101/4 | W22: 101/5 | Y22: 101/6 | AA22: 101/7 | AC22: 101/8 | AE22: 102/0
G23: 1 | I23: 1 | O23: 1 | Q23: 1 | S23: 1 | U23: 1 | W23: 1 | Y23: 1 | AA23: 1 | AC23: 1
C24: 1 | E24: 2 | G24: 3 | I24: 4 | K24: 1 | M24: 2 | O24: 3 | Q24: 4 | S24: 5 | U24: 6 | W24: 7 | Y24: 8 | AA24: 9 | AC24: 10 | AE24: 11
B25: 338 | C25: OK | D25: 370 | E25: OK | F25: 380 | G25: OK | H25: 400 | I25: OK | J25: 418 | K25: OK | L25: 418.579 | M25: OK | N25: 425 | O25: OK | P25: 312 | Q25: OK | R25: 381 | S25: OK | T25: 455 | U25: OK | V25: 376 | W25: OK | X25: 401 | Y25: OK | Z25: 428 | AA25: OK | AB25: 357 | AC25: OK | AD25: 335.158 | AE25: OK | AG25: 15 | AH25: 11 | AI25: 15 | AJ25: 11 | AK25: =(L25+AK21L25+N25+P25+R25+T25+V25+X25+Z25+AB25+AD25) -> #NAME?
C27: 0 | E27: 0 | G27: 0 | I27: 0 | M27: 0 | O27: Completed | Q27: Completed | S27: Completed | U27: Completed | W27: Completed | Y27: Completed | AA27: Completed | AC27: Completed | AE27: Completed
C28: DA+0 | E28: DA+0 | G28: DA+0 | I28: DA+6 | K28: DD45+0 | M28: DC1+3 | O28: DA+3 | Q28: DA+9 | S28: DA+3 | U28: DA+6 | W28: DA+0 | Y28: DA+3 | AA28: DA+3 | AC28: DA-3 | AE28: DC2+3
O29: WFR | Q29: WFR | S29: WFR | U29: WFR | W29: WFR | Y29: WFR | AA29: WFR | AC29: DRY | AE29: DRY
B31: RAJASTHAN REGION
M32: RC
C33: 103/0 | E33: 103/1 | G33: 103/2 | I33: 103/3 | K33: 103/4 | M33: 103/5 | O33: 103/5A | Q33: 103/5A1 | S33: 103/6A | U33: 103/7 | W33: 103/8 | Y33: 103/9 | AA33: 104/0 | AC33: 104/1 | AE33: 104/2
C34: 0 | E34: 0 | G34: 0 | I34: 0 | K34: 0 | M34: 0 | O34: 0 | S34: 0 | W34: 0 | Y34: 0 | AA34: 0 | AC34: 0 | AE34: 0
A35: 11 | C35: 12 | E35: 13 | G35: 14 | I35: 15 | K35: 16 | M35: 17 | O35: 18 | S35: 19 | U35: 20 | W35: 21 | Y35: 22 | AA35: 23 | AC35: 24 | AE35: 25
B36: 461.164 | C36: OK | D36: 373 | E36: OK | F36: 334.67 | G36: OK | H36: 321.15 | I36: OK | J36: 391 | K36: OK | L36: 388 | M36: OK | N36: 392 | O36: OK | P36: 293 | Q36: OK | R36: 274 | S36: OK | T36: 218 | U36: OK | V36: 422 | W36: OK | X36: 339 | Y36: OK | Z36: 423.633 | AA36: OK | AB36: 335.192 | AC36: OK | AD36: 326.577 | AE36: OK | AG36: 15 | AH36: 15 | AI36: 15 | AJ36: 15 | AK36: =+B36+D36+F36+H36+J36+L36+N36+P36+R36+T36+V36+X36+Z36+AB36+AD36 -> 5292.386
M38: X | U38: Completed | AA38: Completed | AE38: Completed
C39: DC1+6 | E39: DA+0 | G39: DA+0 | I39: DA+0 | K39: DA+0 | M39: DA+3 | O39: DD60+0 | Q39: DA-3 | S39: DD45+0 | U39: DA+6 | W39: DA+3 | Y39: DA+3 | AA39: DD45+3 | AC39: DA-3 | AE39: DA-3
M40: Benching | S40: Benching | U40: DFR | AA40: DFR | AC40: DFR | AE40: WET
B42: RAJASTHAN REGION
C43: HR | H43: GAS PIPE LINE
C44: 105/0 | E44: 105/1 | G44: 106/0 | I44: 108/0 | K44: 108/1 | M44: 108/2 | O44: 108/3 | Q44: 108/4 | S44: 109/0 | U44: 109/1 | W44: 109/2 | Y44: 109/3 | AA44: 109/4 | AC44: 110/0
C45: 0 | E45: 0 | G45: 0 | I45: 0 | K45: 0 | M45: 0 | O45: 0 | Q45: 0 | S45: 0 | U45: 1 | W45: 1 | Y45: 0 | AA45: 0 | AC45: 0
A46: 25 | C46: 26 | E46: 27 | G46: 28 | I46: 29 | K46: 30 | M46: 31 | O46: 32 | Q46: 33 | S46: 34 | U46: 35 | W46: 36 | Y46: 37 | AA46: 38 | AC46: 39
B47: 304.947 | C47: OK | D47: 379.11 | E47: OK | F47: 375.442 | G47: OK | H47: 212.418 | I47: OK | J47: 326.001 | K47: OK | L47: 332 | M47: OK | N47: 285 | O47: OK | P47: 345 | Q47: OK | R47: 380.282 | S47: OK | T47: 384.998 | U47: OK | V47: 360 | W47: OK | X47: 378 | Y47: OK | Z47: 387 | AA47: OK | AB47: 439.322 | AC47: OK | AG47: 14 | AH47: 14 | AI47: 14 | AJ47: 10 | AK47: =+B47 -> 304.947
E49: Completed | K49: Completed | M49: Completed | O49: Completed | Q49: Completed | S49: Completed | U49: Completed | W49: Completed | Y49: Completed | AA49: Completed | AC49: Completed
C50: DC1+0 | E50: DA+0 | G50: DD60+0 | I50: DD45+0 | K50: DA-3 | M50: DA-3 | O50: DA-3 | Q50: DA+0 | S50: DC1+0 | U50: DA-1.5 | W50: DA-1.5 | Y50: DA+0 | AA50: DA+3 | AC50: DC2+3
C51: WFR | E51: WFR | K51: DFR | M51: WET | O51: WET | Q51: WFR | S51: DFR | U51: WFR | W51: WFR | Y51: WFR | AA51: WFR | AC51: WFR
...

Sheet Erection Productivity
B2: Project Code | C2: Project Name | D2: SPOC | E2: Apr'25 | G2: May'25 | I2: Jun'25 | K2: Jul'25 | M2: Aug'25 | O2: Sep'25 | Q2: Oct'25 | S2: Nov'25 | U2: Dec'25 | W2: Jan'26 | Y2: Feb'26 | AA2: Mar'26
B3: TA-505 | C3: PGCIL_Part-D - TL02_for 765kV TL Beawar | D3: Partha Pratim Pal | E3: Plan | F3: Actual | G3: Plan | H3: Actual | I3: Plan | J3: Actual | K3: Plan | L3: Actual | M3: Plan | N3: Actual | O3: Plan | P3: Actual | Q3: Plan | R3: Actual | S3: Plan | T3: Actual | U3: Plan | V3: Actual | W3: Plan | X3: Actual | Y3: Plan | Z3: Actual | AA3: Plan | AB3: Actual
E4: (in MT) | F4: (in MT) | G4: (in MT) | H4: (in MT) | I4: (in MT) | J4: (in MT) | K4: (in MT) | L4: (in MT) | M4: (in MT) | N4: (in MT) | O4: (in MT) | P4: (in MT) | Q4: (in MT) | R4: (in MT) | S4: (in MT) | T4: (in MT) | U4: (in MT) | V4: (in MT) | W4: (in MT) | X4: (in MT) | Y4: (in MT) | Z4: (in MT) | AA4: (in MT) | AB4: (in MT)
E5: 1352 | F5: 698 | G5: 1742 | H5: 922 | I5: 1188 | J5: 641 | K5: 752 | L5: 379 | M5: 770 | N5: 435 | O5: 2414 | P5: 1533 | Q5: 2482 | R5: 1491 | S5: 3021 | T5: 1502 | U5: 3205 | V5: 2344 | W5: 2616 | X5: 2039 | Y5: 1975 | Z5: 1258 | AA5: 1232 | AB5: 1001

Sheet Earthing Status
B1: 765 kV D/C BEAWAR MANDSAUR TRANSMISSION LINE
B2: PROGRESS SUMMARY DETAIL
B3: NOA Date: 22-July-2024 | K3: Completion Date : 21-June-2026 | O3: Date : 27-05-25
B4: SUPPLY VALUE = 458 Cr. | K4: SERVICE VALUE = 94.23 Cr. | O4: F&I VALUE = 9.48 Cr. | V4: =458+94.23+9.48 -> 561.71
B5: Sr. No. | C5: Activity | E5: UOM | G5: Total Qty. | J5: L2 Qty. | K5: Completed | L5: Balance | M5: Submitted | N5: WIP | O5: Remarks
B6: 1 | C6: Details Survey | E6: Kms | G6: 136.705 | J6: 126 | K6: =87.055+32.269+7 -> 126.324 | L6: =G6-K6 -> 10.381 | M6: =17.381-7 -> 10.381
B7: 2 | C7: Check Survey | E7: Kms | G7: 136.705 | J7: 126 | K7: =69.41+32.269+7 -> 108.679 | L7: =G7-K7 -> 28.026
B8: 3 | C8: Soil Testing | E8: Nos | G8: 34 | J8: 34
B9: 4 | C9: Foundation | E9: Nos | G9: 371 | J9: 165 | K9: =V27 -> 355 | L9: =G9-K9 -> 16 | N9: =COUNTIF($V$28:$V$1176, "WIP") -> 0
C10: Gang | E10: Nos | K10: 13
C11: Manpower | E11: Nos
B12: 5 | C12: Earthing | E12: Nos | G12: 346 | K12: 94 | L12: =G12-K12 -> 252
B13: 6 | C13: Erection | E13: Nos | G13: =G9 -> 371 | J13: 98 | K13: ='Erection Compiled'!I6 -> Completed | L13: =G13-K13 -> #VALUE! | N13: =COUNTIF('Erection Compiled'!I7:I391,"WIP") -> 0
C14: Gang | E14: Nos | K14: 4
C15: Manpower | E15: Nos
B16: 7 | C16: Stringing | E16: Nos | G16: =G7 -> 136.705 | J16: 0 | K16: 0 | L16: =G16-K16 -> 136.705
C17: Gang | E17: Nos
C18: Manpower | E18: Nos
B20: Issue : i. DS - pending for approval ii. CS - pending for approval
B21: Supply : Stub : DA : 177 Set, DB : 21 Set, DC : 16 Set, DD45 : 9 Set, DD60 : 13 set Earthing : CP : 84 Set, Pipe : 40 Nos, Rod : 40 Nos Tower : DA BB=107 Set,+0M=52, +3M=35,+6M=19, +9M=3, -1.5=6, -3=14
B23: KEC INTERNATIONAL LIMITED
B24: FOUNDATION DETAIL OF 765KV D/C BEAWAR-MANDSAUR TR LINE
B25: Sr. No | C25: Loc No. | D25: Type of Tower | E25: TOF | F25: Region | G25: Earthing Status | H25: Type of Earthing (Pipe Type/CP) | I25: JMC Status | J25: Cement (Bags) | M25: Conc Vol | O25: Excv Vol(m3) | P25: R/F (KG) | Q25: Wt of Stub(MT) | R25: Rev(Inr) | S25: Earthing Vendor | T25: Month of Execution | U25: Foundation Sub Contractor | V25: Foundation Status | W25: Excavation | Y25: Foundation | Z25: Foundation completion | AA25: Remarks if any
J26: RCC | K26: PCC | L26: Toal Cement | M26: M 20(m3) | N26: M 10(m3) | W26: Start | X26: Completion | Y26: Start
B27: Total = | J27: =SUM(J28:J454) -> 125897.63 | K27: =SUM(K28:K454) -> 6532.0004 | L27: =SUM(L28:L454) -> 132429.63 | M27: =SUM(M28:M454) -> 15724.169 | N27: =SUM(N28:N454) -> 1463.911 | O27: =SUM(O28:O454) -> 96505.589 | P27: =SUM(P28:P454) -> 1032821.9 | Q27: =SUM(Q28:Q454) -> 395.43251 | R27: =SUM(R28:R454) -> 3.0707497e+08 | V27: =COUNTIF(V28:V621,"Complete") -> 355
C28: 101/2 | D28: DA+9 | E28: WFR | F28: RAJ | G28: Done | H28: CP | J28: 383 | K28: 20 | L28: 403 | M28: 47.77 | N28: 4.46 | O28: 264.87 | P28: 2353 | Q28: 0.866276 | R28: 1126247.4 | T28: 45566 | U28: RST | V28: Complete | W28: 45546 | X28: 45561 | Y28: 45567 | Z28: 45571 | AB28: 1
C29: 100/0 | D29: DD45+0 | E29: WET | F29: RAJ | G29: Done | H29: Pipe Type | J29: =M29*8 -> 1239.68 | K29: =N29*4.4 -> 70.18 | L29: =SUM(J29:K29) -> 1309.86 | M29: 154.96 | N29: 15.95 | O29: 1192.7 | P29: 15096 | Q29: 2.495 | T29: 45944 | U29: Sumit Const/Om Prakash | V29: Complete | Z29: 45946
C30: 101/0 | D30: DC1+3 | E30: DFR | F30: RAJ | G30: Done | H30: CP | J30: =M30*8 -> 614.16 | K30: =N30*4.4 -> 27.984 | L30: =SUM(J30:K30) -> 642.144 | M30: 76.77 | N30: 6.36 | O30: 388.74 | P30: 3855 | Q30: 2.348757 | R30: 1765261 | T30: 45791 | U30: Sumit Const/Om Prakash | V30: Complete | Z30: 45808
C31: 101/1 | D31: DA+3 | E31: WFR | F31: RAJ | G31: Done | H31: CP | J31: 383 | K31: 20 | L31: 403 | M31: 47.77 | N31: 4.46 | O31: 264.87 | P31: 2353 | Q31: 0.866276 | R31: 1126247.4 | T31: 45597 | U31: RST | V31: Complete | W31: 45598 | X31: 45604 | Y31: 45609 | Z31: 45610 | AB31: 2
C32: 101/3 | D32: DA+3 | E32: WFR | F32: RAJ | G32: Done | H32: CP | J32: 383 | K32: 20 | L32: 403 | M32: 47.77 | N32: 4.46 | O32: 264.87 | P32: 2353 | Q32: 0.866276 | R32: 1126247.4 | T32: 45566 | U32: RST | V32: Complete | W32: 45566 | X32: 45571 | Y32: 45573 | Z32: 45576 | AB32: 1
C33: 101/4 | D33: DA+6 | E33: WFR | F33: RAJ | G33: Done | H33: CP | J33: 383 | K33: 20 | L33: 403 | M33: 47.77 | N33: 4.46 | O33: 264.87 | P33: 2353 | Q33: 0.866276 | R33: 1126247.4 | T33: 45566 | U33: RST | V33: Complete | W33: 45551 | X33: 45556 | Y33: 45584 | Z33: 45586 | AB33: 1
C34: 101/5 | D34: DA+0 | E34: WFR | F34: RAJ | G34: Done | H34: CP | J34: 333 | K34: 19 | L34: 352 | M34: 41.54 | N34: 4.23 | O34: 250.46 | P34: 1909 | Q34: 0.866276 | R34: 984923.64 | T34: 45566 | U34: RST | V34: Complete | W34: 45557 | X34: 45561 | Y34: 45588 | Z34: 45590 | AB34: 1
C35: 101/6 | D35: DA+3 | E35: WFR | F35: RAJ | G35: Done | H35: CP | J35: 383 | K35: 20 | L35: 403 | M35: 47.77 | N35: 4.46 | O35: 264.87 | P35: 2353 | Q35: 0.866276 | R35: 1126247.4 | T35: 45597 | U35: RST | V35: Complete | W35: 45589 | X35: 45591 | Y35: 45595 | Z35: 45598 | AB35: 1
C36: 101/7 | D36: DA+3 | E36: WFR | F36: RAJ | G36: Done | H36: CP | J36: 383 | K36: 20 | L36: 403 | M36: 47.77 | N36: 4.46 | O36: 264.87 | P36: 2353 | Q36: 0.866276 | R36: 1126247.4 | T36: 45597 | U36: RST | V36: Complete | W36: 45606 | X36: 45610 | Y36: 45613 | Z36: 45614 | AB36: 2
C37: 101/8 | D37: DA-3 | E37: DRY | F37: RAJ | G37: Done | H37: Pipe Type | J37: 236 | K37: 13 | L37: 249 | M37: 29.49 | N37: 2.86 | O37: 233.05 | P37: 1526 | Q37: 0.866276 | R37: 645061.95 | T37: 45597 | U37: RST | V37: Complete | W37: 45593 | X37: 45598 | Y37: 45603 | Z37: 45604 | AB37: 2
C38: 102/0 | D38: DC2+3 | E38: DRY | F38: RAJ | G38: Done | H38: Pipe Type | J38: 856 | K38: 38 | L38: 894 | M38: 106.91 | N38: 8.53 | O38: 653.08 | P38: 5502 | Q38: 2.348757 | R38: 2257063.8 | T38: 45627 | U38: RST | V38: Complete | W38: 45618 | X38: 45621 | Y38: 45637 | Z38: 45640 | AB38: 3
C39: 103/0 | D39: DC1+6 | E39: DFR | F39: RAJ | G39: Done | H39: CP | I39: Done | J39: =M39*8 -> 614.16 | K39: =N39*4.4 -> 27.984 | L39: =SUM(J39:K39) -> 642.144 | M39: 76.77 | N39: 6.36 | O39: 388.74 | P39: 3855 | Q39: 2.348757 | R39: 1765261 | T39: 45789 | U39: Sumit Const/Om Prakash | V39: Complete | Z39: 45799
C40: 103/1 | D40: DA+0 | E40: DRY | F40: RAJ | J40: 236 | K40: 13 | L40: 249 | M40: 29.49 | N40: 2.86 | O40: 233.05 | P40: 1526 | Q40: 0.866276 | R40: 645061.95 | T40: 45784 | U40: Sumit Const/Om Prakash | V40: Complete | Z40: 45788
C41: 103/2 | D41: DA+0 | E41: DRY | F41: RAJ | J41: 236 | K41: 13 | L41: 249 | M41: 29.49 | N41: 2.86 | O41: 233.05 | P41: 1526 | Q41: 0.866276 | R41: 645061.95 | T41: 45780 | U41: Sumit Const/Om Prakash | V41: Complete | Z41: 45790
B42: 45 | C42: 103/3 | D42: DA+0 | E42: DFR | F42: RAJ | G42: Done | H42: CP | I42: Done | J42: 221 | K42: 12 | L42: 233 | M42: 27.61 | N42: 2.61 | O42: 146.96 | P42: 1450 | Q42: 0.866276 | R42: 650458.11 | T42: 45780 | U42: Sumit Const/Om Prakash | V42: Complete | Z42: 45785
...

Sheet Sheet4
M2: V I S U A L C H A R T
B5: DATE : | D5: 45981
B6: Name of Line : | E6: 765 KV D/C HEXA BEAWAR MANDSAUR T/L
B7: Project Code: | F7: TA505
B8: Name of Executing Agency: | F8: M/s. KEC INTERNATIONAL LTD.
AG9: FDN | AH9: Ear | AI9: ERE | AJ9: STR
V10: COMMON TOWER
V11: 99/0 | X11: 99/1 | Z11: 99/2 | AB11: 99/3 | AD11: 99/4 | AG11: 4 | AH11: 0 | AI11: 0
Z12: 1 | AB12: 1
V13: 1 | X13: 2 | Z13: 3 | AB13: 4 | AD13: 1
S14: BAJEL PART | U14: 0 | V14: BAJEL | W14: 360 | Y14: 420 | AA14: 410 | AC14: 382
V16: 0 | X16: 0 | Z16: 0 | AB16: 0 | AD16: 0
V17: DB2+0 | X17: DA+6 | Z17: DA+6 | AB17: DA+0 | AD17: DA+0
U19: RAJASTHAN REGION
O21: =+LEFT(O28,1) -> D | Q21: =+LEFT(Q28,1) -> D | U21: =+LEFT(U28,1) -> D | W21: =+LEFT(W28,1) -> D | Y21: =+LEFT(Y28,1) -> D | AA21: =+LEFT(AA28,1) -> D | AC21: =+LEFT(AC28,1) -> D | AE21: =+LEFT(AE28,1) -> D
C22: 99/5 | E22: 99/6 | G22: 99/7 | I22: 99/8 | K22: 100/0 | M22: 101/0 | O22: 101/1 | Q22: 101/2 | S22: 101/3 | U22: 101/4 | W22: 101/5 | Y22: 101/6 | AA22: 101/7 | AC22: 101/8 | AE22: 102/0
G23: 1 | I23: 1 | O23: 1 | Q23: 1 | S23: 1 | U23: 1 | W23: 1 | Y23: 1 | AA23: 1 | AC23: 1
C24: 1 | E24: 2 | G24: 3 | I24: 4 | K24: 1 | M24: 2 | O24: 3 | Q24: 4 | S24: 5 | U24: 6 | W24: 7 | Y24: 8 | AA24: 9 | AC24: 10 | AE24: 11
B25: 338 | D25: 370 | F25: 380 | H25: 400 | J25: 418 | L25: 418.579 | N25: 425 | O25: Completed | P25: 312 | Q25: Completed | R25: 381 | S25: Completed | T25: 455 | U25: Completed | V25: 376 | W25: Completed | X25: 401 | Y25: Completed | Z25: 428 | AA25: Completed | AB25: 357 | AC25: Completed | AD25: 335.158 | AE25: Completed | AG25: 15 | AH25: 5 | AI25: 10
C27: 0 | E27: 0 | G27: 0 | I27: 0 | K27: 0 | M27: 0 | O27: 0 | Q27: 0 | S27: 0 | U27: 0 | W27: Completed | Y27: Completed | AA27: Completed | AC27: Completed | AE27: Completed
C28: DA+0 | E28: DA+0 | G28: DA+0 | I28: DA+6 | K28: DD45+0 | M28: DC1+3 | O28: DA+3 | Q28: DA+9 | S28: DA+3 | U28: DA+6 | W28: DA+0 | Y28: DA+3 | AA28: DA+3 | AC28: DA-3 | AE28: DC2+3
O29: WFR | Q29: WFR | S29: WFR | U29: WFR | W29: WFR | Y29: WFR | AA29: WFR | AC29: DRY | AE29: DRY
B31: RAJASTHAN REGION
M32: RC
C33: 103/0 | E33: 103/1 | G33: 103/2 | I33: 103/3 | K33: 103/4 | M33: 103/5 | O33: 103/5A | Q33: 103/5A1 | S33: 103/6A | U33: 103/7 | W33: 103/8 | Y33: 103/9 | AA33: 104/0 | AC33: 104/1 | AE33: 104/2
C34: 0 | E34: 0 | G34: 0 | I34: 0 | K34: 0 | M34: 0 | O34: 0 | S34: 0 | W34: 0 | Y34: 0 | AA34: 0 | AC34: 0 | AE34: 0
A35: 11 | C35: 12 | E35: 13 | G35: 14 | I35: 15 | K35: 16 | M35: 17 | O35: 18 | S35: 19 | U35: 20 | W35: 21 | Y35: 22 | AA35: 23 | AC35: 24 | AE35: 25
B36: 461.164 | D36: 373 | F36: 334.67 | H36: 321.15 | J36: 391 | L36: 388 | N36: 392 | P36: 293 | R36: 274 | T36: 218 | U36: Completed | V36: 422 | X36: 339 | Z36: 423.633 | AA36: Completed | AB36: 335.192 | AC36: Completed | AD36: 326.577 | AE36: Completed | AG36: 15 | AH36: 3 | AI36: 13
E38: 0 | G38: 0 | K38: 0 | M38: X | U38: Completed | W38: 0 | Y38: 0 | AA38: Completed | AC38: 0 | AE38: Completed
C39: DC1+6 | E39: DA+0 | G39: DA+0 | I39: DA+0 | K39: DA+0 | M39: DA+3 | O39: DD60+0 | Q39: DA-3 | S39: DD45+0 | U39: DA+6 | W39: DA+3 | Y39: DA+3 | AA39: DD45+3 | AC39: DA-3 | AE39: DA-3
M40: Benching | S40: Benching | U40: DFR | AA40: DFR | AC40: DFR | AE40: WET
B42: RAJASTHAN REGION
C43: HR | H43: GAS PIPE LINE
C44: 105/0 | E44: 105/1 | G44: 106/0 | I44: 108/0 | K44: 108/1 | M44: 108/2 | O44: 108/3 | Q44: 108/4 | S44: 109/0 | U44: 109/1 | W44: 109/2 | Y44: 109/3 | AA44: 109/4 | AC44: 110/0
C45: 0 | E45: 0 | G45: 0 | I45: 0 | K45: 0 | M45: 0 | O45: 0 | Q45: 0 | S45: 0 | U45: 1 | W45: 1 | Y45: 0 | AA45: 0 | AC45: 0
A46: 25 | C46: 26 | E46: 27 | G46: 28 | I46: 29 | K46: 30 | M46: 31 | O46: 32 | Q46: 33 | S46: 34 | U46: 35 | W46: 36 | Y46: 37 | AA46: 38 | AC46: 39
B47: 304.947 | C47: Completed | D47: 379.11 | E47: Completed | F47: 375.442 | H47: 212.418 | J47: 326.001 | K47: Completed | L47: 332 | M47: Completed | N47: 285 | O47: Completed | P47: 345 | Q47: Completed | R47: 380.282 | S47: Completed | T47: 384.998 | U47: Completed | V47: 360 | W47: Completed | X47: 378 | Y47: Completed | Z47: 387 | AA47: Completed | AB47: 439.322 | AC47: Completed | AG47: 14 | AH47: 11 | AI47: 13
C49: 0 | E49: Completed | G49: 0 | I49: 0 | K49: Completed | M49: Completed | O49: Completed | Q49: Completed | S49: Completed | U49: Completed | W49: Completed | Y49: Completed | AA49: Completed | AC49: Completed
C50: DC1+0 | E50: DA+0 | G50: DD60+0 | I50: DD45+0 | K50: DA-3 | M50: DA-3 | O50: DA-3 | Q50: DA+0 | S50: DC1+0 | U50: DA-1.5 | W50: DA-1.5 | Y50: DA+0 | AA50: DA+3 | AC50: DC2+3
C51: WFR | E51: WFR | K51: DFR | M51: WET | O51: WET | Q51: WFR | S51: DFR | U51: WFR | W51: WFR | Y51: WFR | AA51: WFR | AC51: WFR
...

Sheet Sheet3
A1: SL | B1: Loc No | C1: TOT | D1: SL | E1: Loc No | F1: TOT | H1: SL | I1: Loc No | J1: TOT
A2: 1 | B2: 103/5 | C2: DA+0 | D2: 1 | E2: 126/1 | F2: DA+9 (RC) | H2: 1 | I2: 178/2 | J2: DA+6
A3: 2 | B3: 99/4 | C3: DA+0 | D3: 2 | E3: 149B/1 | F3: DB2+15 | H3: 2 | I3: 165/0 | J3: DB1+6
A4: 3 | B4: 99/5 | C4: DA+0 | D4: 3 | E4: 149B/2 | F4: DA+6 | H4: 3 | I4: 168/0 | J4: DC2+0
A5: 4 | B5: 99/3 | C5: DA+0 | D5: 4 | E5: 100/0 | F5: DD45+0 | H5: 4 | I5: 180/0 | J5: DC2+15
A6: 5 | B6: 99/2 | C6: DA+6 | D6: 5 | E6: 155/0 | F6: DC2+0 | H6: 5 | I6: 178/4 | J6: DA-3
A7: 6 | B7: 99/1 | C7: DA+6 | D7: 6 | E7: 99/8 | F7: DA+6 | H7: 6 | I7: 178/5 | J7: DA+0
A8: 7 | B8: 99/7 | C8: DA+0 | D8: 7 | E8: 149B/4 | F8: DA+0 (RC) | H8: 7 | I8: 179/1 | J8: DA+3
A9: 8 | B9: 103/9 | C9: DA+3 | D9: 8 | E9: 99/6 | F9: DA+0 | H9: 8 | I9: 179/6 | J9: DA+0
A10: 9 | B10: 169/0 | C10: DC1+3 | H10: 9 | I10: 145/0 | J10: DD60+18
A11: 10 | B11: 169/9 | C11: DA-3 | H11: 10 | I11: 114/4 | J11: DA+3
A12: 11 | B12: 175/2 | C12: DA+0 | H12: 11 | I12: 179/4 | J12: DA-3
A13: 12 | B13: 138/0 | C13: DB1+3 | H13: 12 | I13: 149B/3 | J13: DA+3 (RC)
A14: 13 | B14: 149B/0 | C14: DB1+25 | H14: 13 | I14: 179/2 | J14: DA+3
A15: 14 | B15: 122/0 | C15: DD60+3 | H15: 14 | I15: 154/4 | J15: DA+3
A16: 15 | B16: 123/0 | C16: DD60+6
A17: 16 | B17: 181/2 | C17: DA-3
A18: 17 | B18: 179/9 | C18: DA+3
A19: 18 | B19: 181/5 | C19: DA-3
A20: 19 | B20: 181/4 | C20: DA-3
A21: 20 | B21: 153/0 | C21: DB1+6
A22: 21 | B22: 154/0 | C22: DB2+9
A23: 22 | B23: 156/2 | C23: DA+3

Sheet Sheet2
