Workbook
Name _: #REF!
Name _________________________________________________________dol12: #REF!
Name _________________________________________________________in18900: #REF!
Name _________________________________________________________iv19000: #REF!
Name ________________________________________________________dol12: #REF!
Name ________________________________________________________dol6: #REF!
Name ________________________________________________________in18900: #REF!
Name ________________________________________________________iv19000: #REF!
Name _______________________________________________________dol12: #REF!
Name _______________________________________________________dol6: #REF!
Name _______________________________________________________in18900: #REF!
Name _______________________________________________________iv19000: #REF!
Name ______________________________________________________dol12: #REF!
Name ______________________________________________________dol6: #REF!
Name _____________________________________________________dol12: #REF!
Name _____________________________________________________dol6: #REF!
Name _____________________________________________________in18900: #REF!
Name _____________________________________________________iv19000: #REF!
Name ____________________________________________________dol12: #REF!
Name ____________________________________________________dol6: #REF!
Name ____________________________________________________in18900: #REF!
Name ____________________________________________________iv19000: #REF!
Name ___________________________________________________dol12: #REF!
Name ___________________________________________________dol6: #REF!
Name ___________________________________________________in18900: #REF!
Name ___________________________________________________iv19000: #REF!
Name __________________________________________________dol12: #REF!
Name __________________________________________________dol6: #REF!
Name __________________________________________________in18900: #REF!
Name __________________________________________________iv19000: #REF!
Name _________________________________________________dol6: #REF!
Name _________________________________________________in18900: #REF!
Name _________________________________________________iv19000: #REF!
Name ________________________________________________dol12: #REF!
Name ________________________________________________in18900: #REF!
Name ________________________________________________iv19000: #REF!
Name _______________________________________________dol12: #REF!
Name _______________________________________________dol6: #REF!
Name _______________________________________________in18900: #REF!
Name _______________________________________________iv19000: #REF!
Name ______________________________________________dol12: #REF!
Name ______________________________________________dol6: #REF!
Name ______________________________________________IDA1: #REF!
Name ______________________________________________in18900: #REF!
Name ______________________________________________iv19000: #REF!
Name ______________________________________________xlnm.Print_Area_1: #REF!
Name ______________________________________________xlnm.Print_Area_2: #REF!
Name ______________________________________________xlnm.Print_Titles_1: #REF!
Name ______________________________________________xlnm.Print_Titles_2: (#REF!,#REF!)
Name _____________________________________________dol12: #REF!
Name _____________________________________________dol6: #REF!
Name _____________________________________________IDA1: #REF!
Name _____________________________________________in18900: #REF!
Name _____________________________________________iv19000: #REF!
Name ____________________________________________dol12: #REF!
Name ____________________________________________dol6: #REF!
Name ____________________________________________IDA1: #REF!
Name ____________________________________________in18900: #REF!
Name ____________________________________________iv19000: #REF!
Name ____________________________________________xlnm.Print_Area_1: #REF!

Sheet Summary S
A1: KEC International Limited
A2: Supply Status | J2: =TODAY()-1 -> 46132
A3: Name of Line _ 765 kV Bikaner-IV PS – Siwani (2nd) line - Part-I
A4: Sr. No. | B4: Item Description | C4: Finalized Vendor | D4: Unit | E4: Start Date as per Approved L2 Schedule | F4: FInish Date as per Approved L2 Schedule | G4: Total Qty as per LOA | H4: Received Till Date | I4: Balance | J4: Remarks
A5: 1 | B5: Tower Stub | C5: KEC | D5: Nos. | E5: 45708 | F5: 45955 | G5: 315 | H5: 319 | I5: =G5-H5 -> -4
A6: 2 | B6: Tower Earthing | C6: KEC | D6: Nos. | E6: 45708 | F6: 45955 | G6: 315 | H6: 319 | I6: =G6-H6 -> -4
A7: 3 | B7: Tower Structure | C7: KEC | D7: Nos. | E7: 45757 | F7: 46101 | G7: 315 | H7: 298 | I7: =G7-H7 -> 17 | J7: DA+0/+3/+6/+9/-1.5/-3 Extn - 51/71/54/44/18/12 Nos. DB1+0/+3/+6/+9 Extn - 9/3/1/2 Nos. DB2+0/+3/+6/+9 Extn - 6/3/1/1 Nos. DC1+0/+3/+6 Extn - 3/1/1Nos. DC2+0/+3/+9 Extn - 3/1/1 Nos. DC2+0 - 1 Nos.(TP Tower) DD1+0/+9 Extn - 2/2 Nos. DD2+0/+3/+18/+25/+35 Extn - 1/1/1/1/2 Nos. (12937.29 MT received)
A8: 4 | B8: Conductor | C8: KEC Cables | D8: Km | E8: 45853 | F8: 46193 | G8: 4398 | H8: 3562.626 | I8: =G8-H8 -> 835.374
A9: 5 | B9: Insulator | C9: Aditya Birla | D9: Nos. | E9: 45853 | F9: 46193 | G9: =6366+5906 -> 12272 | H9: 0 | I9: =G9-H9 -> 12272
A10: 6 | B10: H/w Fittings | C10: Tag | D10: % | E10: 45853 | F10: 46193 | G10: 1 | H10: 0 | I10: =G10-H10 -> 1
A11: 7 | B11: OPGW Cable | C11: Apar Industries | D11: Km | E11: 45981 | F11: 46162 | G11: 127 | H11: 0 | I11: =G11-H11 -> 127

Sheet Supply Status
A1: SUPPLY STATUS AS PER BOQ
A2: Name of Line _ 765 kV Bikaner-IV PS – Siwani (2nd) line - Part-I
A3: Agency: KEC INTERNATIONAL Limited
A4: Status as on | K4: =TODAY()-1 -> 46132
A5: Sl. No. | B5: Activity Description | C5: Item Description | D5: Supplier | E5: Unit | F5: Total Quantity | G5: Supplies as per L2 | H5: Actual as on date | I5: Balance | J5: Present status of balance supplies | K5: Expected date of supply
A6: 1 | B6: EARTHING OF TOWERS | C6: Supply of Pipe Type Earthing | D6: KEC | E6: EA | F6: 297 | H6: 319 | I6: =F6-H6 -> -22
A7: 2 | B7: EARTHING OF TOWERS | C7: Supply of Counterpoise type earthing (120 mlength) | D7: KEC | E7: EA | F7: 15 | I7: =F7-H7 -> 15
A8: 3 | B8: EARTHING OF TOWERS | C8: ROD TYPE EARTHING | D8: KEC | E8: EA | F8: 297 | H8: 319 | I8: =F8-H8 -> -22
A9: 4 | B9: EARTHING OF TOWERS | C9: Supply of Shieldwire EarthingincludingPG clamps, downlead clampsbutexcluding Earthwire bits for Pipetypeearthing | D9: KEC | E9: EA | F9: 14 | I9: =F9-H9 -> 14
A10: 5 | B10: EARTHING OF TOWERS | C10: Supply of Shieldwire Earthing Counterpoise (4X30M) Type including PGclamps, downlead clamps but excluding Earthwire bits. | D10: KEC | E10: EA | F10: 3 | I10: =F10-H10 -> 3
A11: 6 | B11: EARTHING OF TOWERS | C11: Counterpoise type (280 m length) | D11: KEC | E11: EA | F11: 3 | I11: =F11-H11 -> 3
A12: 7 | B12: TOWER ACCESSORIES | C12: Danger Plate for 765kV | D12: KEC | E12: EA | F12: 315 | I12: =F12-H12 -> 315
A13: 8 | B13: TOWER ACCESSORIES | C13: Number Plate for 765kV | D13: KEC | E13: EA | F13: 315 | I13: =F13-H13 -> 315
A14: 9 | B14: TOWER ACCESSORIES | C14: Phase Plate (Set of three) | D14: KEC | E14: SET | F14: 630 | I14: =F14-H14 -> 630
A15: 10 | B15: TOWER ACCESSORIES | C15: Circuit Plate (Set of two) | D15: KEC | E15: SET | F15: 315 | I15: =F15-H15 -> 315
A16: 11 | B16: TOWER ACCESSORIES | C16: Supply of Anti-Climbing Devices ofBarbedWire Type | D16: KEC | E16: SET | F16: 315 | I16: =F16-H16 -> 315
A17: 12 | B17: TOWER ACCESSORIES | C17: Bird Guard (Set of Three) | D17: KEC | E17: SET | F17: 510 | I17: =F17-H17 -> 510
A18: 13 | B18: CONDUCTOR | C18: AL59 ZEBRA CONDUCTOR (KM) | D18: KEC Cables | E18: KM | F18: 4398 | H18: 3562.626 | I18: =F18-H18 -> 835.374
A19: 14 | B19: Earthwire | C19: 7/3.66 G.S. EARTHWIRE | D19: Nirmal Wires | E19: KM | F19: 122 | H19: 86 | I19: =F19-H19 -> 36
A20: 15 | B20: HARDWARE FITTINGS | C20: Hardware Fittings for 765kV AC with Hexagonal Zebra Conductor-Double ISuspension String | D20: TAG | E20: SET | F20: 1530 | H20: 1298 | I20: =F20-H20 -> 232
A21: 16 | B21: HARDWARE FITTINGS | C21: Hardware Fittings for 765kV AC with Hexagonal Zebra Conductor-Single ISuspension String (Pilot) | D21: TAG | E21: SET | F21: 94 | H21: 85 | I21: =F21-H21 -> 9
A22: 17 | B22: HARDWARE FITTINGS | C22: Hardware Fittings for 765kV AC with Hexagonal ZebraConductor-Quadruple Tension String | D22: TAG | E22: SET | F22: 732 | H22: 633 | I22: =F22-H22 -> 99
A23: 18 | B23: HARDWARE FITTINGS | C23: Hardware Fittings for 765kV AC with Hexagonal Zebra Conductor-SingleTension String | D23: TAG | E23: SET | F23: 4 | I23: =F23-H23 -> 4
A24: 19 | B24: HARDWARE FITTINGS | C24: Hardware Fittings for 765kV AC with Hexagonal Zebra Conductor-Double ISuspension String | D24: TAG | E24: SET | F24: 25 | I24: =F24-H24 -> 25
A25: 20 | B25: HARDWARE FITTINGS | C25: Hardware Fittings for 765kV AC with Hexagonal Zebra Conductor-Single ISuspension String (Pilot) | D25: TAG | E25: SET | F25: 5 | I25: =F25-H25 -> 5
A26: 21 | B26: HARDWARE FITTINGS | C26: Hardware Fittings for 765kV AC with Hexagonal ZebraConductor-Quadruple Tension String | D26: TAG | E26: SET | F26: 10 | I26: =F26-H26 -> 10
A27: 22 | B27: HARDWARE FITTINGS | C27: Hardware Fittings for 765kV AC with Hexagonal Zebra Conductor-SingleTension String | D27: TAG | E27: SET | F27: 1 | I27: =F27-H27 -> 1
A28: 23 | B28: CONDUCTOR ACCESSORIES | C28: MID SPAN COMPRESSION JOINT FOR AL59 ZEBRA CONDUCTOR | D28: TAG | E28: EA | F28: 2199 | H28: 1880 | I28: =F28-H28 -> 319
A29: 24 | B29: CONDUCTOR ACCESSORIES | C29: REPAIR SLEEVE FOR AL59 ZEBRA CONDUCTOR | D29: TAG | E29: EA | F29: 733 | H29: 632 | I29: =F29-H29 -> 101
A30: 25 | B30: CONDUCTOR ACCESSORIES | C30: T-CONNECTOR-765KV AC WITH AL59 HEXA ZEBRA | D30: TAG | E30: EA | F30: 96 | H30: 91 | I30: =F30-H30 -> 5
A31: 26 | B31: CONDUCTOR ACCESSORIES | C31: PREFORMED RETAINING ROD TYPE SPACER DAMPER SUITABLE FOR HEXA AL59ZEBRA CONDUCTOR | D31: TAG | E31: EA | F31: 13230 | H31: 11280 | I31: =F31-H31 -> 1950
A32: 27 | B32: CONDUCTOR ACCESSORIES | C32: HEXAGONAL RIGID SPACER-765KV AC WITH AL59 HEX ZEBRA | D32: TAG | E32: EA | F32: 1800 | H32: 1540 | I32: =F32-H32 -> 260
A33: 28 | B33: CONDUCTOR ACCESSORIES | C33: MID SPAN COMPRESSION JOINT FOR AL59 ZEBRA CONDUCTOR | D33: TAG | E33: EA | F33: 10 | I33: =F33-H33 -> 10
A34: 29 | B34: CONDUCTOR ACCESSORIES | C34: REPAIR SLEEVE FOR AL59 ZEBRA CONDUCTOR | D34: TAG | E34: EA | F34: 10 | I34: =F34-H34 -> 10
A35: 30 | B35: CONDUCTOR ACCESSORIES | C35: T-CONNECTOR-765KV AC WITH AL59 HEXA ZEBRA | D35: TAG | E35: EA | F35: 10 | I35: =F35-H35 -> 10
A36: 31 | B36: CONDUCTOR ACCESSORIES | C36: PREFORMED RETAINING ROD TYPE SPACER DAMPER SUITABLE FOR HEXA AL59ZEBRA CONDUCTOR | D36: TAG | E36: EA | F36: 40 | I36: =F36-H36 -> 40
A37: 32 | B37: CONDUCTOR ACCESSORIES | C37: HEXAGONAL RIGID SPACER-765KV AC WITH AL59 HEX ZEBRA | D37: TAG | E37: EA | F37: 10 | I37: =F37-H37 -> 10
A38: 33 | B38: Earthwire Accessories | C38: Mid Span Compression Joint -7/3.66mmEarth Wire | D38: TAG | E38: EA | F38: 67 | H38: 59 | I38: =F38-H38 -> 8
A39: 34 | B39: Earthwire Accessories | C39: FLEXIBLE AL BOND-7/3.66MM E/W | D39: TAG | E39: EA | F39: 377 | H39: 305 | I39: =F39-H39 -> 72
A40: 35 | B40: Earthwire Accessories | C40: Vibration damper -7/3.66mm Earth Wire | D40: TAG | E40: EA | F40: 754 | H40: 647 | I40: =F40-H40 -> 107
...

Sheet Summary E
A1: KEC International Limited | M1: =TODAY()-1 -> 46132
A3: Name of Client: Bikaner B Power Transmission Limited
A4: Name of Line: 765 kV D/C Bikaner IV PS to Siwani II (Part-01) TL
A5: NOA No. CC/T/W-TW/DOM/A00/24/09582/NOA-1 & 2/25-10174/01 & 02, Dated 03/01/2025
A6: Office : Hansera, Lunkaransar
A7: S.No. | B7: Activity | C7: LOA Qty | D7: Estimated Quantity | E7: Cumm. Progress up to Last Month (Mar'26) | F7: Target as per L2 Schedule Cummulative (upto Mar'26) | G7: Month's Plan as per L2 Schedule | H7: Progress of Month | I7: Today | J7: Cumulative Progress Till Date | K7: Balance | L7: No of Gangs/MP | M7: Remarks
A8: 1 | B8: Route Alignment (Km) | C8: 120.944 | D8: 124.568 | E8: 124.568 | F8: 124.568 | G8: =D8-E8 -> 0 | H8: 0 | I8: 0 | J8: =E8+H8 -> 124.568 | K8: =D8-J8 -> 0
A9: 2 | B9: Detailed Survey (Km) | C9: 120.944 | D9: 124.568 | E9: 124.568 | F9: 124.568 | G9: =D9-E9 -> 0 | H9: 0 | I9: 0 | J9: =E9+H9 -> 124.568 | K9: =D9-J9 -> 0
A10: 3 | B10: Profiling (Km) | C10: =C9 -> 120.944 | D10: 124.568 | E10: 124.568 | F10: 124.568 | G10: =D10-E10 -> 0 | H10: 0 | I10: 0 | J10: =E10+H10 -> 124.568 | K10: =D10-J10 -> 0
A11: 4 | B11: Check Survey (Km) | C11: 120.944 | D11: 124.568 | E11: 124.568 | F11: 124.568 | G11: 0 | H11: 0 | I11: 0 | J11: =E11+H11 -> 124.568 | K11: =D11-J11 -> 0
A12: 5 | B12: Land Scheduling (Km) | C12: 120.944 | D12: =D11 -> 124.568 | E12: 123.174 | F12: 0 | G12: 0 | H12: 0 | I12: 0 | J12: =E12+H12 -> 123.174 | K12: =D12-J12 -> 1.394 | M12: Approved ROW Corridor - 123.174 Km Tower Base - 315 Nos.
A13: 6 | B13: Soil Investigation (Nos.) | C13: 28 | D13: 28 | E13: 28 | F13: 0 | G13: 0 | H13: 0 | I13: 0 | J13: =E13+H13 -> 28 | K13: =D13-J13 -> 0
A14: 7 | B14: Excavation | C14: 315 | D14: 319 | E14: 296 | F14: 242 | G14: 30 | H14: 6 | I14: 0 | J14: =E14+H14 -> 302 | K14: =D14-J14 -> 17
A15: 8 | B15: Foundation (Nos.) | C15: 315 | D15: 319 | E15: 294 | F15: 242 | G15: 30 | H15: 4 | J15: =E15+H15 -> 298 | K15: =D15-J15 -> 21 | L15: 02/24
A16: 9 | B16: Earthing (Nos.) | C16: 315 | D16: 319 | E16: 269 | F16: 237 | G16: 25 | I16: 0 | J16: =E16+H16 -> 269 | K16: =D16-J16 -> 50
A17: 10 | B17: Tower Erection (Nos) | C17: 315 | D17: 319 | E17: 198 | F17: 180 | G17: 30 | H17: 12 | I17: 0 | J17: =E17+H17 -> 210 | K17: =D17-J17 -> 109 | L17: 02/60
A18: 11 | B18: Tack Welding | C18: 315 | D18: 319 | E18: 16 | F18: 0 | G18: 0 | H18: 24 | I18: 0 | J18: =E18+H18 -> 40 | K18: =D18-J18 -> 279
A19: 12 | B19: Stringing (Km) | C19: 120.944 | D19: 124.568 | E19: 0 | F19: 48 | G19: 12 | H19: 0 | I19: 0 | J19: =E19+H19 -> 0 | K19: =D19-J19 -> 124.568
A20: 13 | B20: Paying Out | C20: 120.944 | D20: 124.568 | E20: 0 | F20: 0 | G20: 0 | H20: 0 | I20: 0 | J20: =E20+H20 -> 0 | K20: =D20-J20 -> 124.568
A21: 14 | B21: Final Sag | C21: 120.944 | D21: 124.568 | E21: 0 | F21: 0 | G21: 0 | H21: 0 | I21: 0 | J21: =E21+H21 -> 0 | K21: =+D21-J21 -> 124.568
A22: 15 | B22: OPGW (Km) | C22: 120.944 | D22: 124.568 | E22: 0 | F22: 0 | G22: 10 | H22: 0 | J22: =E22+H22 -> 0 | K22: =+D22-J22 -> 124.568

Sheet DPR Sheet 
B1: ='Summary E'!A1 -> KEC International Limited
B2: DAILY PROGRESS REPORT : STATUS AS ON | G2: ='Summary E'!M1 -> 46132
B3: Name of the Project: | D3: 765 kV D/C Bikaner IV PS to Siwani II (Part-01) TL
B4: Contract No. & Date : | D4: CC/T/W-TW/DOM/A00/24/09582/CA-1&2/25-100174/01 & 02 Dtd. 21.01.2025
B5: ROUTE ALIGNMENT PROGRESS SUMMARY
B6: TOTAL QTY (Tentative) | C6: COMPLETED UP TO PREV MONTH | D6: COMP. IN CURRENT MONTH | E6: CUMULATIVE | F6: BAL.QTY
B7: ='Summary E'!D8 -> 124.568 | C7: ='Summary E'!E8 -> 124.568 | D7: 0 | E7: =C7+D7 -> 124.568 | F7: =B7-E7 -> 0
B8: DETAILED SURVEY PROGRESS SUMMARY
B9: TOTAL QTY (Tentative) | C9: COMPLETED UP TO PREV MONTH | D9: COMP. IN CURRENT MONTH | E9: CUMULATIVE | F9: BAL.QTY
B10: ='Summary E'!D9 -> 124.568 | C10: ='Summary E'!E9 -> 124.568 | D10: ='Summary E'!H9+'Summary E'!I9 -> 0 | E10: =C10+D10 -> 124.568 | F10: =B10-E10 -> 0
B11: CHECK SURVEY PROGRESS SUMMARY
B12: TOTAL QTY (Tentative) | C12: COMPLETED UP TO PREV MONTH | D12: COMP. IN CURRENT MONTH | E12: CUMULATIVE | F12: BAL.QTY
B13: ='Summary E'!D11 -> 124.568 | C13: ='Summary E'!E11 -> 124.568 | D13: ='Summary E'!I11+'Summary E'!H11 -> 0 | E13: =C13+D13 -> 124.568 | F13: =B13-E13 -> 0
B14: FOUNDATION PROGRESS SUMMARY
B15: TOTAL QTY (Tentative) | C15: COMPLETED UP TO PREV MONTH | D15: COMP. IN CURRENT MONTH | E15: CUMULATIVE | F15: BAL.QTY
B16: ='Summary E'!D15 -> 319 | C16: ='Summary E'!E15 -> 294 | D16: ='Summary E'!H15 -> 4 | E16: =C16+D16 -> 298 | F16: =B16-E16 -> 21
B17: EARTHING PROGRESS SUMMARY
B18: TOTAL QTY | C18: COMPLETED UP TO PREV MONTH | D18: COMP. IN CURRENT MONTH | E18: CUMULATIVE | F18: BAL.QTY
B19: ='Summary E'!D16 -> 319 | C19: ='Summary E'!E16 -> 269 | F19: =+B19-E19 -> 319
B20: TOWER ERECTION PROGRESS SUMMARY
B21: TOTAL QTY | C21: COMPLETED UP TO PREV MONTH | D21: COMP. IN CURRENT MONTH | E21: CUMULATIVE | F21: BAL.QTY
B22: ='Summary E'!D17 -> 319 | C22: ='Summary E'!E17 -> 198 | D22: 0 | E22: 0 | F22: =B22-E22 -> 319
B23: STRINGING PROGRESS SUMMARY
B24: TOTAL QTY | C24: COMPLETED UP TO PREV MONTH | D24: COMP. IN CURRENT MONTH | E24: CUMULATIVE | F24: BAL.QTY(KM)
B25: ='Summary E'!D19 -> 124.568 | C25: ='Summary E'!E19 -> 0 | D25: 0 | E25: =C25+D25 -> 0 | F25: =B25-E25 -> 124.568
B26: OPGW STRINGING PROGRESS SUMMARY
B27: TOTAL QTY | C27: COMPLETED UP TO PREV MONTH | D27: COMP. IN CURRENT MONTH | E27: CUMULATIVE | F27: BAL.QTY
B28: ='Summary E'!D22 -> 124.568 | C28: ='Summary E'!E22 -> 0 | D28: ='Summary E'!H22+'Summary E'!I22 -> 0 | E28: =C28+D28 -> 0 | F28: =+B28-E28 -> 124.568
B29: TACK WELDING PROGRESS SUMMARY
B30: TOTAL QTY | C30: COMPLETED UP TO PREV MONTH | D30: COMP. IN CURRENT MONTH | E30: CUMULATIVE | F30: BAL.QTY
B31: ='Summary E'!D18 -> 319 | C31: ='Summary E'!E18 -> 16 | D31: ='Summary E'!H18+'Summary E'!I18 -> 24 | E31: 0 | F31: =B31-E31 -> 319
B32: SHIELD WIRE EARTHING PROGRESS SUMMARY
B33: TOTAL QTY | C33: COMPLETED UP TO PREV MONTH | D33: COMP. IN CURRENT MONTH | E33: CUMULATIVE | F33: BAL.QTY
F34: =B34-E34 -> 0

Sheet DS
A1: =CS!A1:G1 -> KEC International Limited
A2: =CS!A2:G2 -> 765 kV D/C Bikaner IV PS to Siwani II (Part-01) TL
A3: Detailed Survey | G3: ='Summary E'!M1 -> 46132
A4: Sl.No. | B4: SPAN | D4: Detail Survey Section Length (Km) | E4: Submitted For Approval | F4: Approved Date | G4: Remarks
B5: From Section | C5: To Section
A6: 1 | B6: AP8 | C6: AP19 | D6: 16.984 | E6: 45700 | F6: 45701 | G6: Approved
A7: =A6+1 -> 2 | B7: AP6 | C7: AP8 | D7: 9.313 | E7: 45709 | F7: 45710 | G7: Approved
A8: =A7+1 -> 3 | B8: AP4 | C8: AP6 | D8: 11.121 | E8: 45726 | F8: 45731 | G8: Approved
A9: =A8+1 -> 4 | B9: AP28 | C9: AP29 | D9: 3.179 | E9: 45726 | F9: 45731 | G9: Approved
A10: =A9+1 -> 5 | B10: AP19 | C10: AP28 | D10: 11.409 | E10: 45727 | F10: 45731 | G10: Approved
A11: =A10+1 -> 6 | B11: AP29 | C11: AP32 | D11: 28.482 | E11: 45727 | F11: 45731 | G11: Approved
A12: =A11+1 -> 7 | B12: AP32 | C12: AP35 | D12: 11.16 | E12: 45749 | F12: 45750 | G12: Approved
A13: =A12+1 -> 8 | B13: AP36 | C13: AP44 | D13: 14.759 | E13: 45749 | F13: 45750 | G13: Approved
A14: =A13+1 -> 9 | B14: AP35 | C14: AP36 | D14: 4.095 | E14: 45821 | F14: 45832 | G14: Approved
A15: =A14+1 -> 10 | B15: AP1A | C15: AP4 | D15: 11.446 | E15: 45821 | F15: 45828 | G15: Approved
A16: =A15+1 -> 11 | B16: AP44 | C16: AP47 | D16: 1.483 | G16: Approved
A17: =A16+1 -> 12 | B17: GSS Gantry | C17: AP1A | G17: Hold By Power Grid
A18: =A17+1 -> 13
A19: =A18+1 -> 14
A20: =A19+1 -> 15
A21: Total | D21: =SUBTOTAL(9,D6:D20) -> 123.431

Sheet CS
A1: ='Tack Welding'!A1:I1 -> KEC International Limited
A2: ='Tack Welding'!A2:I2 -> 765 kV D/C Bikaner IV PS to Siwani II (Part-01) TL
A3: Check Survey | G3: ='Summary E'!M1 -> 46132
A4: Sl.No. | B4: SPAN | D4: Section Length (Km) | E4: Submitted for Approval on Dated | F4: Approved on Dated | G4: Remarks
B5: From Section | C5: To Section
A6: 1 | B6: AP8 | C6: AP10 | D6: 5.532 | E6: 45700 | F6: 45701 | G6: Approved
A7: =A6+1 -> 2 | B7: AP6 | C7: AP8 | D7: 9.313 | E7: 45719 | F7: 45713 | G7: Approved
A8: =A7+1 -> 3 | B8: AP10 | C8: AP19 | D8: 11.452 | E8: 45719 | F8: 45713 | G8: Approved
A9: =A8+1 -> 4 | B9: AP4 | C9: AP6 | D9: 11.121 | E9: 45726 | F9: 45731 | G9: Approved
A10: =A9+1 -> 5 | B10: AP28 | C10: AP29 | D10: 3.179 | E10: 45726 | F10: 45731 | G10: Approved
A11: =A10+1 -> 6 | B11: AP19 | C11: AP20 | D11: 3.224 | E11: 45726 | F11: 45731 | G11: Approved
A12: =A11+1 -> 7 | B12: AP20 | C12: AP28 | D12: 8.185 | E12: 45733 | F12: 45734 | G12: Approved
A13: =A12+1 -> 8 | B13: AP29 | C13: AP31 | D13: 17.041 | E13: 45736 | F13: 45737 | G13: Approved
A14: =A13+1 -> 9 | B14: AP31 | C14: AP32 | D14: 11.441 | E14: 45763 | F14: 45764 | G14: Approved
A15: =A14+1 -> 10 | B15: AP1A | C15: AP4 | D15: 11.446 | G15: Approved
A16: =A15+1 -> 11 | B16: AP34 | C16: AP44 | D16: 23.386 | G16: Approved
A17: =A16+1 -> 12 | B17: AP32 | C17: AP34 | D17: 6.628 | G17: Approved
A18: =A17+1 -> 13 | B18: AP44 | C18: AP47 | D18: 1.483 | G18: Approved
A19: =A18+1 -> 14 | B19: GSS Gantry | C19: AP1A | G19: Hold By Power Grid
A20: =A19+1 -> 15
A21: Total | D21: =SUM(D6:D20) -> 123.431

Sheet Hindrance Record
A1: Hindrance Record
C2: Balance >> | D2: =319-COUNTIF($D$4:$D$322,"Completed") -> 21 | E2: =COUNTIF($E$4:$E$322,"ROW") -> 4 | M2: =319-COUNTIF($M$4:$M$322,"Completed") -> 109 | N2: =COUNTIF($N$4:$N$322,"ROW") -> 43
A3: Sr. No | B3: Loc No | C3: Tower Type | D3: Foundation Status | E3: Hindrance During Foundation Work | F3: Start Date | G3: End Date | H3: Effected Days | I3: Farmer Name | J3: Village Name | K3: Contact No. | M3: Tower Erection Status | N3: Hindrance During Tower Erection Work | O3: Start Date | P3: End Date | Q3: Effected Days | R3: Farmer Name | S3: Village Name | T3: Contact No.
A4: 1 | B4: 1/0 | C4: DD60+3 | H4: =G4-F4 -> 0 | Q4: =P4-O4 -> 0
A5: =A4+1 -> 2 | B5: 1/1 | C5: DB1+18 | H5: =G5-F5 -> 0 | Q5: =P5-O5 -> 0
A6: =A5+1 -> 3 | B6: 1/2 | C6: DA+0 | H6: =G6-F6 -> 0 | Q6: =P6-O6 -> 0
A7: =A6+1 -> 4 | B7: 1A/0 | C7: DD45+0 | H7: =G7-F7 -> 0 | Q7: =P7-O7 -> 0
A8: =A7+1 -> 5 | B8: 1A/1 | C8: DA-1.5 | D8: Completed | H8: =G8-F8 -> 0 | M8: Completed | Q8: =P8-O8 -> 0
A9: =A8+1 -> 6 | B9: 1A/2 | C9: DA-1.5 | D9: Completed | H9: =G9-F9 -> 0 | M9: Completed | Q9: =P9-O9 -> 0
A10: =A9+1 -> 7 | B10: 1A/3 | C10: DA-3 | D10: Completed | H10: =G10-F10 -> 0 | N10: ROW | O10: 46068 | Q10: =P10-O10 -> -46068
A11: =A10+1 -> 8 | B11: 2/0 | C11: DD60+3 | D11: Completed | E11: Resolved | F11: 46025 | G11: 46029 | H11: =G11-F11 -> 4 | N11: ROW | O11: 46068 | Q11: =P11-O11 -> -46068
A12: =A11+1 -> 9 | B12: 2/1 | C12: DA+6 | D12: Completed | E12: Resolved | F12: 45863 | G12: 45877 | H12: =G12-F12 -> 14 | N12: ROW | O12: 46068 | Q12: =P12-O12 -> -46068
A13: =A12+1 -> 10 | B13: 2/2 | C13: DA+9 | D13: Completed | H13: =G13-F13 -> 0 | M13: Completed | Q13: =P13-O13 -> 0
A14: =A13+1 -> 11 | B14: 2/3 | C14: DA+9 | D14: Completed | E14: Resolved | F14: 45863 | G14: 46021 | H14: =G14-F14 -> 158 | M14: Completed | N14: Resolved | O14: 46091 | P14: 46100 | Q14: =P14-O14 -> 9
A15: =A14+1 -> 12 | B15: 2/4 | C15: DA+9 | D15: Completed | H15: =G15-F15 -> 0 | M15: Completed | Q15: =P15-O15 -> 0
A16: =A15+1 -> 13 | B16: 2/5 | C16: DA+0 | D16: Completed | H16: =G16-F16 -> 0 | M16: Completed | Q16: =P16-O16 -> 0
A17: =A16+1 -> 14 | B17: 2/6 | C17: DA+9 | D17: Completed | H17: =G17-F17 -> 0 | M17: Completed | N17: Resolved | O17: 46068 | P17: 46091 | Q17: =P17-O17 -> 23
A18: =A17+1 -> 15 | B18: 2A/0 | C18: DB2+3 | D18: Completed | H18: =G18-F18 -> 0 | N18: ROW | O18: 46068 | Q18: =P18-O18 -> -46068
A19: =A18+1 -> 16 | B19: 2A/1 | C19: DA+9 | D19: Completed | H19: =G19-F19 -> 0 | N19: ROW | O19: 46068 | Q19: =P19-O19 -> -46068
A20: =A19+1 -> 17 | B20: 2A/2 | C20: DA-1.5 | D20: Completed | H20: =G20-F20 -> 0 | N20: ROW | O20: 46068 | Q20: =P20-O20 -> -46068
A21: =A20+1 -> 18 | B21: 2A/3 | C21: DA+3 | D21: Completed | H21: =G21-F21 -> 0 | Q21: =P21-O21 -> 0
A22: =A21+1 -> 19 | B22: 2A/4 | C22: DA+9 | D22: Completed | H22: =G22-F22 -> 0 | M22: Completed | N22: Resolved | O22: 46068 | P22: 46117 | Q22: =P22-O22 -> 49
A23: =A22+1 -> 20 | B23: 2A/5 | C23: DA+9 | D23: Completed | H23: =G23-F23 -> 0 | N23: ROW | O23: 46068 | Q23: =P23-O23 -> -46068
A24: =A23+1 -> 21 | B24: 3/0 | C24: DC2+9 | D24: Completed | H24: =G24-F24 -> 0 | Q24: =P24-O24 -> 0
A25: =A24+1 -> 22 | B25: 3/1 | C25: DB1+9 | D25: Completed | H25: =G25-F25 -> 0 | Q25: =P25-O25 -> 0
A26: =A25+1 -> 23 | B26: 3/2 | C26: DA+9 | D26: Completed | H26: =G26-F26 -> 0 | N26: ROW | O26: 46068 | Q26: =P26-O26 -> -46068
A27: =A26+1 -> 24 | B27: 3/3 | C27: DA+9 | D27: Completed | H27: =G27-F27 -> 0 | M27: Completed | Q27: =P27-O27 -> 0
A28: =A27+1 -> 25 | B28: 3/4 | C28: DA-1.5 | D28: Completed | H28: =G28-F28 -> 0 | M28: Completed | Q28: =P28-O28 -> 0
A29: =A28+1 -> 26 | B29: 3/5 | C29: DA+6 | D29: Completed | H29: =G29-F29 -> 0 | M29: Completed | Q29: =P29-O29 -> 0
A30: =A29+1 -> 27 | B30: 3/6 | C30: DA+3 | D30: Completed | H30: =G30-F30 -> 0 | M30: Completed | Q30: =P30-O30 -> 0
A31: =A30+1 -> 28 | B31: 3/7 | C31: DA+3 | D31: Completed | H31: =G31-F31 -> 0 | M31: Completed | Q31: =P31-O31 -> 0
A32: =A31+1 -> 29 | B32: 3A/0 | C32: DD45+0 | D32: Completed | H32: =G32-F32 -> 0 | M32: Completed | Q32: =P32-O32 -> 0
A33: =A32+1 -> 30 | B33: 3A/1 | C33: DA+0 | D33: Completed | H33: =G33-F33 -> 0 | M33: Completed | Q33: =P33-O33 -> 0
A34: =A33+1 -> 31 | B34: 3A/2 | C34: DA-1.5 | D34: Completed | H34: =G34-F34 -> 0 | M34: Completed | Q34: =P34-O34 -> 0
A35: =A34+1 -> 32 | B35: 3A/3 | C35: DA-1.5 | D35: Completed | H35: =G35-F35 -> 0 | M35: Completed | Q35: =P35-O35 -> 0
A36: =A35+1 -> 33 | B36: 4/0 | C36: DB2+0 | D36: Completed | H36: =G36-F36 -> 0 | M36: Completed | Q36: =P36-O36 -> 0
A37: =A36+1 -> 34 | B37: 4/1 | C37: DA-3 | D37: Completed | E37: Resolved | F37: 45882 | G37: 46002 | H37: =G37-F37 -> 120 | N37: ROW | O37: 46068 | Q37: =P37-O37 -> -46068
A38: =A37+1 -> 35 | B38: 4/2 | C38: DA+6 | D38: Completed | H38: =G38-F38 -> 0 | N38: ROW | O38: 46068 | Q38: =P38-O38 -> -46068
A39: =A38+1 -> 36 | B39: 4/3 | C39: DA-3 | D39: Completed | H39: =G39-F39 -> 0 | N39: ROW | O39: 46068 | Q39: =P39-O39 -> -46068
A40: =A39+1 -> 37 | B40: 4/4 | C40: DA+9 | D40: Completed | E40: Resolved | F40: 45882 | G40: 45995 | H40: =G40-F40 -> 113 | M40: Completed | Q40: =P40-O40 -> 0
...

Sheet Earthing
A1: KEC International Limited
A2: 765 kV D/C Bikaner IV PS to Siwani II (Part-01) TL
A3: Details of Earthing | L3: ='Summary E'!M1 -> 46132
A4: Sr. No. | B4: Month | C4: Month Sr. No. | D4: Loc. No. | E4: Type of Tower | F4: Type of Classification | G4: Start | H4: Complete | I4: Name of the Contractor | J4: Name of Supervisor | K4: PGCIL Person /Quest | L4: Remarks
A5: 1 | B5: June'25 | C5: 1 | D5: 8/1 | E5: =VLOOKUP(D5,'TS Gantry - AP44'!$C$8:$D$638,2,0) -> DA-1.5 | F5: =VLOOKUP($D5,Foundation!$D$5:$F$379,3,FALSE) -> Sandy | G5: 45834 | H5: 45834 | I5: M/s. Sanjay Construction | J5: Saddam
A6: 2 | B6: June'25 | C6: 2 | D6: 8/2 | E6: =VLOOKUP(D6,'TS Gantry - AP44'!$C$8:$D$638,2,0) -> DA+3 | F6: =VLOOKUP($D6,Foundation!$D$5:$F$379,3,FALSE) -> Sandy | G6: 45834 | H6: 45834 | I6: M/s. Sanjay Construction | J6: Saddam
A7: 3 | B7: June'25 | C7: 3 | D7: 8/3 | E7: =VLOOKUP(D7,'TS Gantry - AP44'!$C$8:$D$638,2,0) -> DA+6 | F7: =VLOOKUP($D7,Foundation!$D$5:$F$379,3,FALSE) -> Sandy | G7: 45834 | H7: 45834 | I7: M/s. Sanjay Construction | J7: Saddam
A8: 4 | B8: June'25 | C8: 4 | D8: 8/4 | E8: =VLOOKUP(D8,'TS Gantry - AP44'!$C$8:$D$638,2,0) -> DA+3 | F8: =VLOOKUP($D8,Foundation!$D$5:$F$379,3,FALSE) -> Sandy | G8: 45834 | H8: 45834 | I8: M/s. Sanjay Construction | J8: Saddam
A9: 5 | B9: June'25 | C9: 5 | D9: 8/5 | E9: =VLOOKUP(D9,'TS Gantry - AP44'!$C$8:$D$638,2,0) -> DA+0 | F9: =VLOOKUP($D9,Foundation!$D$5:$F$379,3,FALSE) -> Sandy | G9: 45835 | H9: 45835 | I9: M/s. Sanjay Construction | J9: Saddam
A10: 6 | B10: June'25 | C10: 6 | D10: 8/6 | E10: =VLOOKUP(D10,'TS Gantry - AP44'!$C$8:$D$638,2,0) -> DA+0 | F10: =VLOOKUP($D10,Foundation!$D$5:$F$379,3,FALSE) -> Sandy | G10: 45835 | H10: 45835 | I10: M/s. Sanjay Construction | J10: Saddam
A11: 7 | B11: June'25 | C11: 7 | D11: 8/7 | E11: =VLOOKUP(D11,'TS Gantry - AP44'!$C$8:$D$638,2,0) -> DA+3 | F11: =VLOOKUP($D11,Foundation!$D$5:$F$379,3,FALSE) -> Sandy | G11: 45835 | H11: 45835 | I11: M/s. Sanjay Construction | J11: Saddam
A12: 8 | B12: June'25 | C12: 8 | D12: 8/8 | E12: =VLOOKUP(D12,'TS Gantry - AP44'!$C$8:$D$638,2,0) -> DA+0 | F12: =VLOOKUP($D12,Foundation!$D$5:$F$379,3,FALSE) -> Sandy | G12: 45835 | H12: 45835 | I12: M/s. Sanjay Construction | J12: Saddam
A13: 9 | B13: June'25 | C13: 9 | D13: 7/7 | E13: =VLOOKUP(D13,'TS Gantry - AP44'!$C$8:$D$638,2,0) -> DA-1.5 | F13: =VLOOKUP($D13,Foundation!$D$5:$F$379,3,FALSE) -> Sandy | G13: 45836 | H13: 45836 | I13: M/s. Sanjay Construction | J13: Saddam
A14: 10 | B14: June'25 | C14: 10 | D14: 7/8 | E14: =VLOOKUP(D14,'TS Gantry - AP44'!$C$8:$D$638,2,0) -> DA+3 | F14: =VLOOKUP($D14,Foundation!$D$5:$F$379,3,FALSE) -> Sandy | G14: 45836 | H14: 45836 | I14: M/s. Sanjay Construction | J14: Saddam
A15: 11 | B15: June'25 | C15: 11 | D15: 7/9 | E15: =VLOOKUP(D15,'TS Gantry - AP44'!$C$8:$D$638,2,0) -> DA+3 | F15: =VLOOKUP($D15,Foundation!$D$5:$F$379,3,FALSE) -> Sandy | G15: 45836 | H15: 45836 | I15: M/s. Sanjay Construction | J15: Saddam
A16: 12 | B16: June'25 | C16: 12 | D16: 7/10 | E16: =VLOOKUP(D16,'TS Gantry - AP44'!$C$8:$D$638,2,0) -> DA+0 | F16: =VLOOKUP($D16,Foundation!$D$5:$F$379,3,FALSE) -> Sandy | G16: 45836 | H16: 45836 | I16: M/s. Sanjay Construction | J16: Saddam
... A273: 269 | B273: Jan'26 | C273: 89 | D273: 43/0 | E273: =VLOOKUP(D273,'TS Gantry - AP44'!$C$8:$D$638,2,0) -> DC1+0 | F273: =VLOOKUP($D273,Foundation!$D$5:$F$379,3,FALSE) -> Sandy | G273: 46054 | H273: 46054 | I273: M/s. Sanjay Construction | J273: Ramshankar
A274: 270 | C274: 90
A275: 271 | C275: 91
A276: 272 | C276: 92
A277: 273 | C277: 93
A278: 274 | C278: 94
A279: 275 | C279: 95
A280: 276 | C280: 96
A281: 277 | C281: 97
A282: 278 | C282: 98
A283: 279 | C283: 99
A284: 280 | C284: 100
A285: 281 | C285: 101
... A319: 315 | C319: 135

Sheet Foundation
A1: ='Summary E'!A1 -> KEC International Limited
A2: ='DPR Sheet '!D3 -> 765 kV D/C Bikaner IV PS to Siwani II (Part-01) TL
A3: Details of Foundation | T3: ='Summary E'!M1 -> 46132
A4: Sr. No. | B4: Month | C4: Month Sr. No. | D4: Loc. No. | E4: Type of Tower | F4: Type of Classification | G4: Start | H4: Completed | I4: Name of the Contractor | J4: Name of Supervisor | K4: State | L4: Village | M4: Tehsil | N4: District | O4: ROW Status (Yes/No) | P4: Action Taken for ROW (To Be Filled By POWERGRID) | Q4: Start Date | R4: End Date | S4: PGCIL Person /Quest | T4: Remarks
A5: 1 | B5: Feb'25 | C5: 1 | D5: 8/1 | E5: =VLOOKUP(D5,'TS Gantry - AP44'!$C$8:$D$638,2,0) -> DA-1.5 | F5: Sandy | G5: 45700 | H5: 45711 | I5: M/s. Sanwariya Technical Developers | J5: Monu Kumar | K5: Rajasthan | L5: =VLOOKUP(D5,'TS Gantry - AP44'!$C$8:$X$638,22,FALSE) -> DOODIMUKLERA | M5: =VLOOKUP(D5,'TS Gantry - AP44'!$C$8:$Y$638,23,FALSE) -> LUNKARANSAR | N5: =VLOOKUP(D5,'TS Gantry - AP44'!$C$8:$Z$638,24,FALSE) -> BIKANER
A6: 2 | B6: Feb'25 | C6: 2 | D6: 8/3 | E6: =VLOOKUP(D6,'TS Gantry - AP44'!$C$8:$D$638,2,0) -> DA+6 | F6: Sandy | G6: 45705 | H6: 45714 | I6: M/s. Sanwariya Technical Developers | J6: Monu Kumar | K6: Rajasthan | L6: =VLOOKUP(D6,'TS Gantry - AP44'!$C$8:$X$638,22,FALSE) -> JAISAN | M6: =VLOOKUP(D6,'TS Gantry - AP44'!$C$8:$Y$638,23,FALSE) -> LUNKARANSAR | N6: =VLOOKUP(D6,'TS Gantry - AP44'!$C$8:$Z$638,24,FALSE) -> BIKANER
A7: 3 | B7: Feb'25 | C7: 3 | D7: 8/6 | E7: =VLOOKUP(D7,'TS Gantry - AP44'!$C$8:$D$638,2,0) -> DA+0 | F7: Sandy | G7: 45708 | H7: 45716 | I7: M/s. MS Construction | J7: Sher Singh Rana | K7: Rajasthan | L7: =VLOOKUP(D7,'TS Gantry - AP44'!$C$8:$X$638,22,FALSE) -> SADHERAN | M7: =VLOOKUP(D7,'TS Gantry - AP44'!$C$8:$Y$638,23,FALSE) -> LUNKARANSAR | N7: =VLOOKUP(D7,'TS Gantry - AP44'!$C$8:$Z$638,24,FALSE) -> BIKANER
A8: 4 | B8: Mar'25 | C8: 1 | D8: 8/5 | E8: =VLOOKUP(D8,'TS Gantry - AP44'!$C$8:$D$638,2,0) -> DA+0 | F8: Sandy | G8: 45715 | H8: 45721 | I8: M/s. MS Construction | J8: Sher Singh Rana | K8: Rajasthan | L8: =VLOOKUP(D8,'TS Gantry - AP44'!$C$8:$X$638,22,FALSE) -> SADHERAN | M8: =VLOOKUP(D8,'TS Gantry - AP44'!$C$8:$Y$638,23,FALSE) -> LUNKARANSAR | N8: =VLOOKUP(D8,'TS Gantry - AP44'!$C$8:$Z$638,24,FALSE) -> BIKANER
A9: 5 | B9: Mar'25 | C9: 2 | D9: 8/2 | E9: =VLOOKUP(D9,'TS Gantry - AP44'!$C$8:$D$638,2,0) -> DA+3 | F9: Sandy | G9: 45717 | H9: 45721 | I9: M/s. Sanwariya Technical Developers | J9: Monu Kumar | K9: Rajasthan | L9: =VLOOKUP(D9,'TS Gantry - AP44'!$C$8:$X$638,22,FALSE) -> JAISAN | M9: =VLOOKUP(D9,'TS Gantry - AP44'!$C$8:$Y$638,23,FALSE) -> LUNKARANSAR | N9: =VLOOKUP(D9,'TS Gantry - AP44'!$C$8:$Z$638,24,FALSE) -> BIKANER
A10: 6 | B10: Mar'25 | C10: 3 | D10: 12/1 | E10: =VLOOKUP(D10,'TS Gantry - AP44'!$C$8:$D$638,2,0) -> DA+3 | F10: Sandy | G10: 45717 | H10: 45723 | I10: M/s. Choudhari Construction | J10: Jagdamba Prasad | K10: Rajasthan | L10: =VLOOKUP(D10,'TS Gantry - AP44'!$C$8:$X$638,22,FALSE) -> HANSHERA | M10: =VLOOKUP(D10,'TS Gantry - AP44'!$C$8:$Y$638,23,FALSE) -> LUNKARANSAR | N10: =VLOOKUP(D10,'TS Gantry - AP44'!$C$8:$Z$638,24,FALSE) -> BIKANER
A11: 7 | B11: Mar'25 | C11: 4 | D11: 8/4 | E11: =VLOOKUP(D11,'TS Gantry - AP44'!$C$8:$D$638,2,0) -> DA+3 | F11: Sandy | G11: 45721 | H11: 45726 | I11: M/s. Sanwariya Technical Developers | J11: Sher Singh Rana | K11: Rajasthan | L11: =VLOOKUP(D11,'TS Gantry - AP44'!$C$8:$X$638,22,FALSE) -> SADHERAN | M11: =VLOOKUP(D11,'TS Gantry - AP44'!$C$8:$Y$638,23,FALSE) -> LUNKARANSAR | N11: =VLOOKUP(D11,'TS Gantry - AP44'!$C$8:$Z$638,24,FALSE) -> BIKANER
A12: 8 | B12: Mar'25 | C12: 5 | D12: 12/2 | E12: =VLOOKUP(D12,'TS Gantry - AP44'!$C$8:$D$638,2,0) -> DA-1.5 | F12: Sandy | G12: 45721 | H12: 45726 | I12: M/s. Choudhari Construction | J12: Jagdamba Prasad | K12: Rajasthan | L12: =VLOOKUP(D12,'TS Gantry - AP44'!$C$8:$X$638,22,FALSE) -> HANSHERA | M12: =VLOOKUP(D12,'TS Gantry - AP44'!$C$8:$Y$638,23,FALSE) -> LUNKARANSAR | N12: =VLOOKUP(D12,'TS Gantry - AP44'!$C$8:$Z$638,24,FALSE) -> BIKANER
A13: 9 | B13: Mar'25 | C13: 6 | D13: 8/8 | E13: =VLOOKUP(D13,'TS Gantry - AP44'!$C$8:$D$638,2,0) -> DA+0 | F13: Sandy | G13: 45721 | H13: 45726 | I13: M/s. MS Construction | J13: Sher Singh Rana | K13: Rajasthan | L13: =VLOOKUP(D13,'TS Gantry - AP44'!$C$8:$X$638,22,FALSE) -> DHEERERAN | M13: =VLOOKUP(D13,'TS Gantry - AP44'!$C$8:$Y$638,23,FALSE) -> LUNKARANSAR | N13: =VLOOKUP(D13,'TS Gantry - AP44'!$C$8:$Z$638,24,FALSE) -> BIKANER
A14: 10 | B14: Mar'25 | C14: 7 | D14: 12/3 | E14: =VLOOKUP(D14,'TS Gantry - AP44'!$C$8:$D$638,2,0) -> DA+9 | F14: Sandy | G14: 45721 | H14: 45726 | I14: M/s. Choudhari Construction | J14: Narayan Mohoto | K14: Rajasthan | L14: =VLOOKUP(D14,'TS Gantry - AP44'!$C$8:$X$638,22,FALSE) -> HANSHERA | M14: =VLOOKUP(D14,'TS Gantry - AP44'!$C$8:$Y$638,23,FALSE) -> LUNKARANSAR | N14: =VLOOKUP(D14,'TS Gantry - AP44'!$C$8:$Z$638,24,FALSE) -> BIKANER
A15: 11 | B15: Mar'25 | C15: 8 | D15: 6/7 | E15: =VLOOKUP(D15,'TS Gantry - AP44'!$C$8:$D$638,2,0) -> DA+0 | F15: Sandy | G15: 45724 | H15: 45731 | I15: M/s. ProteK Infra | J15: Sher Singh Rana | K15: Rajasthan | L15: =VLOOKUP(D15,'TS Gantry - AP44'!$C$8:$X$638,22,FALSE) -> SODHWALI | M15: =VLOOKUP(D15,'TS Gantry - AP44'!$C$8:$Y$638,23,FALSE) -> LUNKARANSAR | N15: =VLOOKUP(D15,'TS Gantry - AP44'!$C$8:$Z$638,24,FALSE) -> BIKANER
A16: 12 | B16: Mar'25 | C16: 9 | D16: 7/6 | E16: =VLOOKUP(D16,'TS Gantry - AP44'!$C$8:$D$638,2,0) -> DA+0 | F16: Sandy | G16: 45726 | H16: 45733 | I16: M/s. Sanwariya Technical Developers | J16: Sujit Choudhary | K16: Rajasthan | L16: =VLOOKUP(D16,'TS Gantry - AP44'!$C$8:$X$638,22,FALSE) -> DUDIWALI | M16: =VLOOKUP(D16,'TS Gantry - AP44'!$C$8:$Y$638,23,FALSE) -> LUNKARANSAR | N16: =VLOOKUP(D16,'TS Gantry - AP44'!$C$8:$Z$638,24,FALSE) -> BIKANER
... A186: 182 | B186: Sep'25 | C186: 14 | D186: 36/5 | E186: =VLOOKUP(D186,'TS Gantry - AP44'!$C$8:$D$638,2,0) -> DA+6 | F186: Sandy | G186: 45918 | H186: 45921 | I186: M/s. Karni Kripa Construction Company | J186: Rohit Sharma | K186: Rajasthan | L186: =VLOOKUP(D186,'TS Gantry - AP44'!$C$8:$X$638,22,FALSE) -> MALAKSAR | M186: =VLOOKUP(D186,'TS Gantry - AP44'!$C$8:$Y$638,23,FALSE) -> SARDARSHAHAR | N186: =VLOOKUP(D186,'TS Gantry - AP44'!$C$8:$Z$638,24,FALSE) -> CHURU
A187: 183 | B187: Sep'25 | C187: 15 | D187: 4/8 | E187: =VLOOKUP(D187,'TS Gantry - AP44'!$C$8:$D$638,2,0) -> DA+9 | F187: Sandy | G187: 45918 | H187: 45922 | I187: M/s. Shree Shyam Construction | J187: Ankur Gogoi | K187: Rajasthan | L187: =VLOOKUP(D187,'TS Gantry - AP44'!$C$8:$X$638,22,FALSE) -> RAJASAR BHATIYAN | M187: =VLOOKUP(D187,'TS Gantry - AP44'!$C$8:$Y$638,23,FALSE) -> CHHATARGARH | N187: =VLOOKUP(D187,'TS Gantry - AP44'!$C$8:$Z$638,24,FALSE) -> BIKANER | O187: Yes | Q187: 45882 | R187: 45918
A188: 184 | B188: Sep'25 | C188: 16 | D188: 13/0 | E188: =VLOOKUP(D188,'TS Gantry - AP44'!$C$8:$D$638,2,0) -> DC1+3 | F188: Sandy | G188: 45919 | H188: 45923 | I188: M/s. Sanwariya Technical Developers | J188: Anshu Kumar | K188: Rajasthan | L188: =VLOOKUP(D188,'TS Gantry - AP44'!$C$8:$X$638,22,FALSE) -> HANSHERA | M188: =VLOOKUP(D188,'TS Gantry - AP44'!$C$8:$Y$638,23,FALSE) -> LUNKARANSAR | N188: =VLOOKUP(D188,'TS Gantry - AP44'!$C$8:$Z$638,24,FALSE) -> BIKANER
A189: 185 | B189: Sep'25 | C189: 17 | D189: 4/9 | E189: =VLOOKUP(D189,'TS Gantry - AP44'!$C$8:$D$638,2,0) -> DA+3 | F189: Sandy | G189: 45923 | H189: 45925 | I189: M/s. Shree Shyam Construction | J189: Anshu Kumar | K189: Rajasthan | L189: =VLOOKUP(D189,'TS Gantry - AP44'!$C$8:$X$638,22,FALSE) -> RAJASAR BHATIYAN | M189: =VLOOKUP(D189,'TS Gantry - AP44'!$C$8:$Y$638,23,FALSE) -> CHHATARGARH | N189: =VLOOKUP(D189,'TS Gantry - AP44'!$C$8:$Z$638,24,FALSE) -> BIKANER
A190: 186 | B190: Sep'25 | C190: 18 | D190: 36/4 | E190: =VLOOKUP(D190,'TS Gantry - AP44'!$C$8:$D$638,2,0) -> DA+9 | F190: Sandy | G190: 45923 | H190: 45926 | I190: M/s. Karni Kripa Construction Company | J190: Rohit Sharma | K190: Rajasthan | L190: =VLOOKUP(D190,'TS Gantry - AP44'!$C$8:$X$638,22,FALSE) -> MALAKSAR | M190: =VLOOKUP(D190,'TS Gantry - AP44'!$C$8:$Y$638,23,FALSE) -> SARDARSHAHAR | N190: =VLOOKUP(D190,'TS Gantry - AP44'!$C$8:$Z$638,24,FALSE) -> CHURU
A191: 187 | B191: Sep'25 | C191: 19 | D191: 36/3 | E191: =VLOOKUP(D191,'TS Gantry - AP44'!$C$8:$D$638,2,0) -> DA+9 | F191: Sandy | G191: 45926 | H191: 45929 | I191: M/s. Karni Kripa Construction Company | J191: Rohit Sharma | K191: Rajasthan | L191: =VLOOKUP(D191,'TS Gantry - AP44'!$C$8:$X$638,22,FALSE) -> MALAKSAR | M191: =VLOOKUP(D191,'TS Gantry - AP44'!$C$8:$Y$638,23,FALSE) -> SARDARSHAHAR | N191: =VLOOKUP(D191,'TS Gantry - AP44'!$C$8:$Z$638,24,FALSE) -> CHURU
A192: 188 | B192: Sep'25 | C192: 20 | D192: 29/19 | E192: =VLOOKUP(D192,'TS Gantry - AP44'!$C$8:$D$638,2,0) -> DA+3 | F192: Sandy | G192: 45924 | H192: 45931 | I192: M/s. Om Mahadev | J192: Saddam Maliya | K192: Rajasthan | L192: =VLOOKUP(D192,'TS Gantry - AP44'!$C$8:$X$638,22,FALSE) -> GARABDESAR | M192: =VLOOKUP(D192,'TS Gantry - AP44'!$C$8:$Y$638,23,FALSE) -> LUNKARANSAR | N192: =VLOOKUP(D192,'TS Gantry - AP44'!$C$8:$Z$638,24,FALSE) -> BIKANER | O192: Yes | Q192: 45870 | R192: 45924
A193: 189 | B193: Sep'25 | C193: 21 | D193: 4/10 | E193: =VLOOKUP(D193,'TS Gantry - AP44'!$C$8:$D$638,2,0) -> DA-1.5 | F193: Sandy | G193: 45927 | H193: 45931 | I193: M/s. Shree Shyam Construction | J193: Anshu Kumar | K193: Rajasthan | L193: =VLOOKUP(D193,'TS Gantry - AP44'!$C$8:$X$638,22,FALSE) -> MAKADASAR | M193: =VLOOKUP(D193,'TS Gantry - AP44'!$C$8:$Y$638,23,FALSE) -> CHHATARGARH | N193: =VLOOKUP(D193,'TS Gantry - AP44'!$C$8:$Z$638,24,FALSE) -> BIKANER
A194: 190 | B194: Oct'25 | C194: 1 | D194: 34/9 | E194: =VLOOKUP(D194,'TS Gantry - AP44'!$C$8:$D$638,2,0) -> DA+9 | F194: Sandy | G194: 45928 | H194: 45934 | I194: M/s. Kuri Construction Company | J194: Chetram | K194: Rajasthan | L194: =VLOOKUP(D194,'TS Gantry - AP44'!$C$8:$X$638,22,FALSE) -> LODSAR | M194: =VLOOKUP(D194,'TS Gantry - AP44'!$C$8:$Y$638,23,FALSE) -> SARDARSHAHAR | N194: =VLOOKUP(D194,'TS Gantry - AP44'!$C$8:$Z$638,24,FALSE) -> CHURU
A195: 191 | B195: Oct'25 | C195: 2 | D195: 37/0 | E195: =VLOOKUP(D195,'TS Gantry - AP44'!$C$8:$D$638,2,0) -> DB1+0 | F195: Sandy | G195: 45929 | H195: 45934 | I195: M/s. Karni Kripa Construction Company | J195: Rohit Sharma | K195: Rajasthan | L195: =VLOOKUP(D195,'TS Gantry - AP44'!$C$8:$X$638,22,FALSE) -> HALASAR | M195: =VLOOKUP(D195,'TS Gantry - AP44'!$C$8:$Y$638,23,FALSE) -> SARDARSHAHAR | N195: =VLOOKUP(D195,'TS Gantry - AP44'!$C$8:$Z$638,24,FALSE) -> CHURU
A196: 192 | B196: Oct'25 | C196: 3 | D196: 4/7 | E196: =VLOOKUP(D196,'TS Gantry - AP44'!$C$8:$D$638,2,0) -> DB1+0 | F196: Sandy | G196: 45934 | H196: 45939 | I196: M/s. Shree Shyam Construction | J196: Anshu Kumar | K196: Rajasthan | L196: =VLOOKUP(D196,'TS Gantry - AP44'!$C$8:$X$638,22,FALSE) -> RAJASAR BHATIYAN | M196: =VLOOKUP(D196,'TS Gantry - AP44'!$C$8:$Y$638,23,FALSE) -> CHHATARGARH | N196: =VLOOKUP(D196,'TS Gantry - AP44'!$C$8:$Z$638,24,FALSE) -> BIKANER | O196: Yes | Q196: 45882 | R196: 45934
A197: 193 | B197: Oct'25 | C197: 4 | D197: 36/2 | E197: =VLOOKUP(D197,'TS Gantry - AP44'!$C$8:$D$638,2,0) -> DA+9 | F197: Sandy | G197: 45934 | H197: 45942 | I197: M/s. Karni Kripa Construction Company | J197: Rohit Sharma | K197: Rajasthan | L197: =VLOOKUP(D197,'TS Gantry - AP44'!$C$8:$X$638,22,FALSE) -> MALAKSAR | M197: =VLOOKUP(D197,'TS Gantry - AP44'!$C$8:$Y$638,23,FALSE) -> SARDARSHAHAR | N197: =VLOOKUP(D197,'TS Gantry - AP44'!$C$8:$Z$638,24,FALSE) -> CHURU | O197: Yes | Q197: 45896 | R197: 45926
A198: 194 | B198: Oct'25 | C198: 5 | D198: 34/10 | E198: =VLOOKUP(D198,'TS Gantry - AP44'!$C$8:$D$638,2,0) -> DA+9 | F198: Sandy | G198: 45934 | H198: 45942 | I198: M/s. Kuri Construction Company | J198: Chetram | K198: Rajasthan | L198: =VLOOKUP(D198,'TS Gantry - AP44'!$C$8:$X$638,22,FALSE) -> NAHARSARA | M198: =VLOOKUP(D198,'TS Gantry - AP44'!$C$8:$Y$638,23,FALSE) -> SARDARSHAHAR | N198: =VLOOKUP(D198,'TS Gantry - AP44'!$C$8:$Z$638,24,FALSE) -> CHURU
A199: 195 | B199: Oct'25 | C199: 6 | D199: 20/4 | E199: =VLOOKUP(D199,'TS Gantry - AP44'!$C$8:$D$638,2,0) -> DA+0 | F199: Sandy | G199: 45939 | H199: 45942 | I199: M/s. Sanwariya Technical Developers | J199: Sher Singh Rana | K199: Rajasthan | L199: =VLOOKUP(D199,'TS Gantry - AP44'!$C$8:$X$638,22,FALSE) -> KALKAL MUKLERA | M199: =VLOOKUP(D199,'TS Gantry - AP44'!$C$8:$Y$638,23,FALSE) -> LUNKARANSAR | N199: =VLOOKUP(D199,'TS Gantry - AP44'!$C$8:$Z$638,24,FALSE) -> BIKANER | O199: Yes | Q199: 45733 | R199: 45926
A200: 196 | B200: Oct'25 | C200: 7 | D200: 37/2 | E200: =VLOOKUP(D200,'TS Gantry - AP44'!$C$8:$D$638,2,0) -> DA+3 | F200: Sandy | G200: 45943 | H200: 45946 | I200: M/s. Karni Kripa Construction Company | J200: Rohit Sharma | K200: Rajasthan | L200: =VLOOKUP(D200,'TS Gantry - AP44'!$C$8:$X$638,22,FALSE) -> HALASAR | M200: =VLOOKUP(D200,'TS Gantry - AP44'!$C$8:$Y$638,23,FALSE) -> SARDARSHAHAR | N200: =VLOOKUP(D200,'TS Gantry - AP44'!$C$8:$Z$638,24,FALSE) -> CHURU
A201: 197 | B201: Oct'25 | C201: 8 | D201: 30/0 | E201: =VLOOKUP(D201,'TS Gantry - AP44'!$C$8:$D$638,2,0) -> DB2+0 | F201: Sandy | G201: 45934 | H201: 45947 | I201: M/s. Om Mahadev | J201: Saddam Maliya | K201: Rajasthan | L201: =VLOOKUP(D201,'TS Gantry - AP44'!$C$8:$X$638,22,FALSE) -> RAJPURA HUDAAN | M201: =VLOOKUP(D201,'TS Gantry - AP44'!$C$8:$Y$638,23,FALSE) -> LUNKARANSAR | N201: =VLOOKUP(D201,'TS Gantry - AP44'!$C$8:$Z$638,24,FALSE) -> BIKANER | O201: Yes | Q201: 45870 | R201: 45934
A202: 198 | B202: Oct'25 | C202: 9 | D202: 18/2 | E202: =VLOOKUP(D202,'TS Gantry - AP44'!$C$8:$D$638,2,0) -> DA+3 | F202: Sandy | G202: 45944 | H202: 45947 | I202: M/s. Sanwariya Technical Developers | J202: Ankur Gogoi | K202: Rajasthan | L202: =VLOOKUP(D202,'TS Gantry - AP44'!$C$8:$X$638,22,FALSE) -> SURANA | M202: =VLOOKUP(D202,'TS Gantry - AP44'!$C$8:$Y$638,23,FALSE) -> LUNKARANSAR | N202: =VLOOKUP(D202,'TS Gantry - AP44'!$C$8:$Z$638,24,FALSE) -> BIKANER | O202: Yes
A203: 199 | B203: Oct'25 | C203: 10 | D203: 37/3 | E203: =VLOOKUP(D203,'TS Gantry - AP44'!$C$8:$D$638,2,0) -> DA+3 | F203: Sandy | G203: 45946 | H203: 45948 | I203: M/s. Karni Kripa Construction Company | J203: Rohit Sharma | K203: Rajasthan | L203: =VLOOKUP(D203,'TS Gantry - AP44'!$C$8:$X$638,22,FALSE) -> HALASAR | M203: =VLOOKUP(D203,'TS Gantry - AP44'!$C$8:$Y$638,23,FALSE) -> SARDARSHAHAR | N203: =VLOOKUP(D203,'TS Gantry - AP44'!$C$8:$Z$638,24,FALSE) -> CHURU
A204: 200 | B204: Oct'25 | C204: 11 | D204: 31/17 | E204: =VLOOKUP(D204,'TS Gantry - AP44'!$C$8:$D$638,2,0) -> DA+9 | F204: Sandy | G204: 45942 | H204: 45949 | I204: M/s. Choudhari Construction | J204: Raghu Kr. Mahto | K204: Rajasthan | L204: =VLOOKUP(D204,'TS Gantry - AP44'!$C$8:$X$638,22,FALSE) -> KANWALASAR | M204: =VLOOKUP(D204,'TS Gantry - AP44'!$C$8:$Y$638,23,FALSE) -> SARDARSHAHAR | N204: =VLOOKUP(D204,'TS Gantry - AP44'!$C$8:$Z$638,24,FALSE) -> CHURU
A205: 201 | B205: Oct'25 | C205: 12 | D205: 3/1 | E205: =VLOOKUP(D205,'TS Gantry - AP44'!$C$8:$D$638,2,0) -> DB1+9 | F205: Sandy | G205: 45940 | H205: 45953 | I205: M/s. Shree Shyam Construction | J205: Deepak Kr. Mahto | K205: Rajasthan | L205: =VLOOKUP(D205,'TS Gantry - AP44'!$C$8:$X$638,22,FALSE) -> AMBARAN | M205: =VLOOKUP(D205,'TS Gantry - AP44'!$C$8:$Y$638,23,FALSE) -> CHHATARGARH | N205: =VLOOKUP(D205,'TS Gantry - AP44'!$C$8:$Z$638,24,FALSE) -> BIKANER
A206: 202 | B206: Oct'25 | C206: 13 | D206: 29/13 | E206: =VLOOKUP(D206,'TS Gantry - AP44'!$C$8:$D$638,2,0) -> DA+0 | F206: Sandy | G206: 45918 | H206: 45955 | I206: M/s. Om Mahadev | J206: Saddam Maliya | K206: Rajasthan | L206: =VLOOKUP(D206,'TS Gantry - AP44'!$C$8:$X$638,22,FALSE) -> KALOO | M206: =VLOOKUP(D206,'TS Gantry - AP44'!$C$8:$Y$638,23,FALSE) -> LUNKARANSAR | N206: =VLOOKUP(D206,'TS Gantry - AP44'!$C$8:$Z$638,24,FALSE) -> BIKANER | O206: Yes | Q206: 45870 | R206: 45946
A207: 203 | B207: Oct'25 | C207: 14 | D207: 35/0 | E207: =VLOOKUP(D207,'TS Gantry - AP44'!$C$8:$D$638,2,0) -> DB1+9 | F207: Sandy | G207: 45943 | H207: 45955 | I207: M/s. Kuri Construction Company | J207: Narayan Kr. Mahto | K207: Rajasthan | L207: =VLOOKUP(D207,'TS Gantry - AP44'!$C$8:$X$638,22,FALSE) -> NAHARSARA | M207: =VLOOKUP(D207,'TS Gantry - AP44'!$C$8:$Y$638,23,FALSE) -> SARDARSHAHAR | N207: =VLOOKUP(D207,'TS Gantry - AP44'!$C$8:$Z$638,24,FALSE) -> CHURU
A208: 204 | B208: Oct'25 | C208: 15 | D208: 31/18 | E208: =VLOOKUP(D208,'TS Gantry - AP44'!$C$8:$D$638,2,0) -> DB1+9 | F208: Sandy | G208: 45948 | H208: 45956 | I208: M/s. Choudhari Construction | J208: Raghu Kr. Mahto | K208: Rajasthan | L208: =VLOOKUP(D208,'TS Gantry - AP44'!$C$8:$X$638,22,FALSE) -> DHEERASAR | M208: =VLOOKUP(D208,'TS Gantry - AP44'!$C$8:$Y$638,23,FALSE) -> SARDARSHAHAR | N208: =VLOOKUP(D208,'TS Gantry - AP44'!$C$8:$Z$638,24,FALSE) -> CHURU
A209: 205 | B209: Oct'25 | C209: 16 | D209: 37/4 | E209: =VLOOKUP(D209,'TS Gantry - AP44'!$C$8:$D$638,2,0) -> DA+3 | F209: Sandy | G209: 45953 | H209: 45956 | I209: M/s. Karni Kripa Construction Company | J209: Rohit Sharma | K209: Rajasthan | L209: =VLOOKUP(D209,'TS Gantry - AP44'!$C$8:$X$638,22,FALSE) -> HALASAR | M209: =VLOOKUP(D209,'TS Gantry - AP44'!$C$8:$Y$638,23,FALSE) -> SARDARSHAHAR | N209: =VLOOKUP(D209,'TS Gantry - AP44'!$C$8:$Z$638,24,FALSE) -> CHURU
...

Sheet Erection Compiled
A1: KEC International Limited
A2: 765 kV D/C Bikaner IV PS to Siwani II (Part-01) TL
A3: Details of Erection | T3: ='Summary E'!M1 -> 46132
A4: Sr. No. | B4: Month | C4: Month Sr. No. | D4: Location No. | E4: Type of Tower | F4: Tower Weight | G4: Starting Date | H4: Completion Date | I4: Gang Name | J4: Name of Supervisor | K4: State | L4: Village | M4: Tehsil | N4: District | O4: ROW Status (Yes/No) | P4: Action Taken for ROW (To Be Filled By POWERGRID) | Q4: Start Date | R4: End Date | S4: PGCIL Person /Quest | T4: Remarks
A5: 1 | B5: Aug'25 | C5: 1 | D5: 8/3 | E5: =VLOOKUP(D5,'TS Gantry - AP44'!$C$8:$D$646,2,0) -> DA+6 | F5: 43.804 | G5: 45863 | H5: 45879 | I5: M/s. Kavya Enterprises | J5: Narayan Mahto | K5: Rajasthan | L5: =VLOOKUP(D5,'TS Gantry - AP44'!$C$8:$X$638,22,FALSE) -> JAISAN | M5: =VLOOKUP(D5,'TS Gantry - AP44'!$C$8:$Y$638,23,FALSE) -> LUNKARANSAR | N5: =VLOOKUP(D5,'TS Gantry - AP44'!$C$8:$Z$638,24,FALSE) -> BIKANER
A6: =A5+1 -> 2 | B6: Aug'25 | C6: 2 | D6: 8/8 | E6: =VLOOKUP(D6,'TS Gantry - AP44'!$C$8:$D$646,2,0) -> DA+0 | F6: 36.16 | G6: 45880 | H6: 45889 | I6: M/s. Kavya Enterprises | J6: Narayan Mahto | K6: Rajasthan | L6: =VLOOKUP(D6,'TS Gantry - AP44'!$C$8:$X$638,22,FALSE) -> DHEERERAN | M6: =VLOOKUP(D6,'TS Gantry - AP44'!$C$8:$Y$638,23,FALSE) -> LUNKARANSAR | N6: =VLOOKUP(D6,'TS Gantry - AP44'!$C$8:$Z$638,24,FALSE) -> BIKANER
A7: =A6+1 -> 3 | B7: Aug'25 | C7: 3 | D7: 7/9 | E7: =VLOOKUP(D7,'TS Gantry - AP44'!$C$8:$D$646,2,0) -> DA+3 | F7: 37.931 | G7: 45882 | H7: 45889 | I7: M/s. Punam Kumari | J7: Choturam Meena | K7: Rajasthan | L7: =VLOOKUP(D7,'TS Gantry - AP44'!$C$8:$X$638,22,FALSE) -> DUDIWALI | M7: =VLOOKUP(D7,'TS Gantry - AP44'!$C$8:$Y$638,23,FALSE) -> LUNKARANSAR | N7: =VLOOKUP(D7,'TS Gantry - AP44'!$C$8:$Z$638,24,FALSE) -> BIKANER
A8: =A7+1 -> 4 | B8: Aug'25 | C8: 4 | D8: 18/5 | E8: =VLOOKUP(D8,'TS Gantry - AP44'!$C$8:$D$646,2,0) -> DA+0 | F8: 36.16 | G8: 45887 | H8: 45894 | I8: M/s. Jwala Singh | J8: Monu Kumar | K8: Rajasthan | L8: =VLOOKUP(D8,'TS Gantry - AP44'!$C$8:$X$638,22,FALSE) -> SURANA | M8: =VLOOKUP(D8,'TS Gantry - AP44'!$C$8:$Y$638,23,FALSE) -> LUNKARANSAR | N8: =VLOOKUP(D8,'TS Gantry - AP44'!$C$8:$Z$638,24,FALSE) -> BIKANER
A9: =A8+1 -> 5 | B9: Aug'25 | C9: 5 | D9: 7/8 | E9: =VLOOKUP(D9,'TS Gantry - AP44'!$C$8:$D$646,2,0) -> DA+3 | F9: 37.931 | G9: 45890 | H9: 45895 | I9: M/s. Punam Kumari | J9: Ajhar Ali | K9: Rajasthan | L9: =VLOOKUP(D9,'TS Gantry - AP44'!$C$8:$X$638,22,FALSE) -> DUDIWALI | M9: =VLOOKUP(D9,'TS Gantry - AP44'!$C$8:$Y$638,23,FALSE) -> LUNKARANSAR | N9: =VLOOKUP(D9,'TS Gantry - AP44'!$C$8:$Z$638,24,FALSE) -> BIKANER
A10: =A9+1 -> 6 | B10: Aug'25 | C10: 6 | D10: 8/7 | E10: =VLOOKUP(D10,'TS Gantry - AP44'!$C$8:$D$646,2,0) -> DA+3 | F10: 37.931 | G10: 45890 | H10: 45896 | I10: M/s. Kavya Enterprises | J10: Narayan Mahto | K10: Rajasthan | L10: =VLOOKUP(D10,'TS Gantry - AP44'!$C$8:$X$638,22,FALSE) -> DHEERERAN | M10: =VLOOKUP(D10,'TS Gantry - AP44'!$C$8:$Y$638,23,FALSE) -> LUNKARANSAR | N10: =VLOOKUP(D10,'TS Gantry - AP44'!$C$8:$Z$638,24,FALSE) -> BIKANER
A11: =A10+1 -> 7 | B11: Sep'25 | C11: 1 | D11: 6/1 | E11: =VLOOKUP(D11,'TS Gantry - AP44'!$C$8:$D$646,2,0) -> DA+3 | F11: 37.931 | G11: 45890 | H11: 45901 | I11: M/s. Punam Kumari | J11: Choturam Meena | K11: Rajasthan | L11: =VLOOKUP(D11,'TS Gantry - AP44'!$C$8:$X$638,22,FALSE) -> BINJHARWALI | M11: =VLOOKUP(D11,'TS Gantry - AP44'!$C$8:$Y$638,23,FALSE) -> LUNKARANSAR | N11: =VLOOKUP(D11,'TS Gantry - AP44'!$C$8:$Z$638,24,FALSE) -> BIKANER
A12: =A11+1 -> 8 | B12: Sep'25 | C12: 2 | D12: 7/6 | E12: =VLOOKUP(D12,'TS Gantry - AP44'!$C$8:$D$646,2,0) -> DA+0 | F12: 36.16 | G12: 45895 | H12: 45901 | I12: M/s. Punam Kumari | J12: Ajhar Ali | K12: Rajasthan | L12: =VLOOKUP(D12,'TS Gantry - AP44'!$C$8:$X$638,22,FALSE) -> DUDIWALI | M12: =VLOOKUP(D12,'TS Gantry - AP44'!$C$8:$Y$638,23,FALSE) -> LUNKARANSAR | N12: =VLOOKUP(D12,'TS Gantry - AP44'!$C$8:$Z$638,24,FALSE) -> BIKANER
A13: =A12+1 -> 9 | B13: Sep'25 | C13: 3 | D13: 19/1 | E13: =VLOOKUP(D13,'TS Gantry - AP44'!$C$8:$D$646,2,0) -> DA+3 | F13: 37.931 | G13: 45895 | H13: 45903 | I13: M/s. Jwala Singh | J13: Sonu Kumar | K13: Rajasthan | L13: =VLOOKUP(D13,'TS Gantry - AP44'!$C$8:$X$638,22,FALSE) -> SURANA | M13: =VLOOKUP(D13,'TS Gantry - AP44'!$C$8:$Y$638,23,FALSE) -> LUNKARANSAR | N13: =VLOOKUP(D13,'TS Gantry - AP44'!$C$8:$Z$638,24,FALSE) -> BIKANER | O13: Yes | Q13: 45899 | R13: 45901
A14: =A13+1 -> 10 | B14: Sep'25 | C14: 4 | D14: 8/6 | E14: =VLOOKUP(D14,'TS Gantry - AP44'!$C$8:$D$646,2,0) -> DA+0 | F14: 36.16 | G14: 45896 | H14: 45903 | I14: M/s. Kavya Enterprises | J14: Narayan Mahto | K14: Rajasthan | L14: =VLOOKUP(D14,'TS Gantry - AP44'!$C$8:$X$638,22,FALSE) -> SADHERAN | M14: =VLOOKUP(D14,'TS Gantry - AP44'!$C$8:$Y$638,23,FALSE) -> LUNKARANSAR | N14: =VLOOKUP(D14,'TS Gantry - AP44'!$C$8:$Z$638,24,FALSE) -> BIKANER
A15: =A14+1 -> 11 | B15: Sep'25 | C15: 5 | D15: 19/5 | E15: =VLOOKUP(D15,'TS Gantry - AP44'!$C$8:$D$646,2,0) -> DA+3 | F15: 37.931 | G15: 45900 | H15: 45907 | I15: M/s. Jwala Singh | J15: Sonu Kumar | K15: Rajasthan | L15: =VLOOKUP(D15,'TS Gantry - AP44'!$C$8:$X$638,22,FALSE) -> KAKARICHCHHA | M15: =VLOOKUP(D15,'TS Gantry - AP44'!$C$8:$Y$638,23,FALSE) -> LUNKARANSAR | N15: =VLOOKUP(D15,'TS Gantry - AP44'!$C$8:$Z$638,24,FALSE) -> BIKANER
A16: =A15+1 -> 12 | B16: Sep'25 | C16: 6 | D16: 8/5 | E16: =VLOOKUP(D16,'TS Gantry - AP44'!$C$8:$D$646,2,0) -> DA+0 | F16: 36.16 | G16: 45904 | H16: 45910 | I16: M/s. Kavya Enterprises | J16: Narayan Mahto | K16: Rajasthan | L16: =VLOOKUP(D16,'TS Gantry - AP44'!$C$8:$X$638,22,FALSE) -> SADHERAN | M16: =VLOOKUP(D16,'TS Gantry - AP44'!$C$8:$Y$638,23,FALSE) -> LUNKARANSAR | N16: =VLOOKUP(D16,'TS Gantry - AP44'!$C$8:$Z$638,24,FALSE) -> BIKANER
A17: =A16+1 -> 13 | B17: Sep'25 | C17: 7 | D17: 7/1 | E17: =VLOOKUP(D17,'TS Gantry - AP44'!$C$8:$D$646,2,0) -> DA+6 | F17: 43.804 | G17: 45902 | H17: 45911 | I17: M/s. Punam Kumari | J17: Ajhar Ali | K17: Rajasthan | L17: =VLOOKUP(D17,'TS Gantry - AP44'!$C$8:$X$638,22,FALSE) -> SODHWALI | M17: =VLOOKUP(D17,'TS Gantry - AP44'!$C$8:$Y$638,23,FALSE) -> LUNKARANSAR | N17: =VLOOKUP(D17,'TS Gantry - AP44'!$C$8:$Z$638,24,FALSE) -> BIKANER | O17: Yes | Q17: 45903 | R17: 45904
A18: =A17+1 -> 14 | B18: Sep'25 | C18: 8 | D18: 31/2 | E18: =VLOOKUP(D18,'TS Gantry - AP44'!$C$8:$D$646,2,0) -> DA+3 | F18: 37.931 | G18: 45902 | H18: 45912 | I18: M/s. Punam Kumari | J18: Raj Kishor | K18: Rajasthan | L18: =VLOOKUP(D18,'TS Gantry - AP44'!$C$8:$X$638,22,FALSE) -> KAGASAR | M18: =VLOOKUP(D18,'TS Gantry - AP44'!$C$8:$Y$638,23,FALSE) -> LUNKARANSAR | N18: =VLOOKUP(D18,'TS Gantry - AP44'!$C$8:$Z$638,24,FALSE) -> BIKANER
A19: =A18+1 -> 15 | B19: Sep'25 | C19: 9 | D19: 19/4 | E19: =VLOOKUP(D19,'TS Gantry - AP44'!$C$8:$D$646,2,0) -> DA+9 | F19: 45.697 | G19: 45908 | H19: 45913 | I19: M/s. Jwala Singh | J19: Mahendra | K19: Rajasthan | L19: =VLOOKUP(D19,'TS Gantry - AP44'!$C$8:$X$638,22,FALSE) -> KAKARICHCHHA | M19: =VLOOKUP(D19,'TS Gantry - AP44'!$C$8:$Y$638,23,FALSE) -> LUNKARANSAR | N19: =VLOOKUP(D19,'TS Gantry - AP44'!$C$8:$Z$638,24,FALSE) -> BIKANER
A20: =A19+1 -> 16 | B20: Sep'25 | C20: 10 | D20: 7/4 | E20: =VLOOKUP(D20,'TS Gantry - AP44'!$C$8:$D$646,2,0) -> DA+0 | F20: 36.16 | G20: 45912 | H20: 45916 | I20: M/s. Punam Kumari | J20: Dhiraj Kumar | K20: Rajasthan | L20: =VLOOKUP(D20,'TS Gantry - AP44'!$C$8:$X$638,22,FALSE) -> DUDIWALI | M20: =VLOOKUP(D20,'TS Gantry - AP44'!$C$8:$Y$638,23,FALSE) -> LUNKARANSAR | N20: =VLOOKUP(D20,'TS Gantry - AP44'!$C$8:$Z$638,24,FALSE) -> BIKANER
A21: =A20+1 -> 17 | B21: Sep'25 | C21: 11 | D21: 9/2 | E21: =VLOOKUP(D21,'TS Gantry - AP44'!$C$8:$D$646,2,0) -> DA+6 | F21: 43.804 | G21: 45911 | H21: 45919 | I21: M/s. Kavya Enterprises | J21: Narayan Mahto | K21: Rajasthan | L21: =VLOOKUP(D21,'TS Gantry - AP44'!$C$8:$X$638,22,FALSE) -> DHEERERAN | M21: =VLOOKUP(D21,'TS Gantry - AP44'!$C$8:$Y$638,23,FALSE) -> LUNKARANSAR | N21: =VLOOKUP(D21,'TS Gantry - AP44'!$C$8:$Z$638,24,FALSE) -> BIKANER
A22: =A21+1 -> 18 | B22: Sep'25 | C22: 12 | D22: 31/1 | E22: =VLOOKUP(D22,'TS Gantry - AP44'!$C$8:$D$646,2,0) -> DA+3 | F22: 37.931 | G22: 45913 | H22: 45920 | I22: M/s. Punam Kumari | J22: Raj Kishor | K22: Rajasthan | L22: =VLOOKUP(D22,'TS Gantry - AP44'!$C$8:$X$638,22,FALSE) -> CHHATASAR | M22: =VLOOKUP(D22,'TS Gantry - AP44'!$C$8:$Y$638,23,FALSE) -> LUNKARANSAR | N22: =VLOOKUP(D22,'TS Gantry - AP44'!$C$8:$Z$638,24,FALSE) -> BIKANER
A23: =A22+1 -> 19 | B23: Sep'25 | C23: 13 | D23: 19/7 | E23: =VLOOKUP(D23,'TS Gantry - AP44'!$C$8:$D$646,2,0) -> DA+6 | F23: 43.804 | G23: 45914 | H23: 45922 | I23: M/s. Jwala Singh | J23: Mahendra | K23: Rajasthan | L23: =VLOOKUP(D23,'TS Gantry - AP44'!$C$8:$X$638,22,FALSE) -> KAKARICHCHHA | M23: =VLOOKUP(D23,'TS Gantry - AP44'!$C$8:$Y$638,23,FALSE) -> LUNKARANSAR | N23: =VLOOKUP(D23,'TS Gantry - AP44'!$C$8:$Z$638,24,FALSE) -> BIKANER
A24: =A23+1 -> 20 | B24: Sep'25 | C24: 14 | D24: 7/3 | E24: =VLOOKUP(D24,'TS Gantry - AP44'!$C$8:$D$646,2,0) -> DA+0 | F24: 36.16 | G24: 45918 | H24: 45923 | I24: M/s. Punam Kumari | J24: Dhiraj Kumar | K24: Rajasthan | L24: =VLOOKUP(D24,'TS Gantry - AP44'!$C$8:$X$638,22,FALSE) -> SODHWALI | M24: =VLOOKUP(D24,'TS Gantry - AP44'!$C$8:$Y$638,23,FALSE) -> LUNKARANSAR | N24: =VLOOKUP(D24,'TS Gantry - AP44'!$C$8:$Z$638,24,FALSE) -> BIKANER
A25: =A24+1 -> 21 | B25: Sep'25 | C25: 15 | D25: 9/3 | E25: =VLOOKUP(D25,'TS Gantry - AP44'!$C$8:$D$646,2,0) -> DA+0 | F25: 36.16 | G25: 45920 | H25: 45924 | I25: M/s. Kavya Enterprises | J25: Narayan Mahto | K25: Rajasthan | L25: =VLOOKUP(D25,'TS Gantry - AP44'!$C$8:$X$638,22,FALSE) -> DHEERERAN | M25: =VLOOKUP(D25,'TS Gantry - AP44'!$C$8:$Y$638,23,FALSE) -> LUNKARANSAR | N25: =VLOOKUP(D25,'TS Gantry - AP44'!$C$8:$Z$638,24,FALSE) -> BIKANER
A26: =A25+1 -> 22 | B26: Sep'25 | C26: 16 | D26: 30/18 | E26: =VLOOKUP(D26,'TS Gantry - AP44'!$C$8:$D$646,2,0) -> DA+0 | F26: 36.16 | G26: 45921 | H26: 45927 | I26: M/s. Punam Kumari | J26: Raj Kishor | K26: Rajasthan | L26: =VLOOKUP(D26,'TS Gantry - AP44'!$C$8:$X$638,22,FALSE) -> CHHATASAR | M26: =VLOOKUP(D26,'TS Gantry - AP44'!$C$8:$Y$638,23,FALSE) -> LUNKARANSAR | N26: =VLOOKUP(D26,'TS Gantry - AP44'!$C$8:$Z$638,24,FALSE) -> BIKANER
A27: =A26+1 -> 23 | B27: Sep'25 | C27: 17 | D27: 19/6 | E27: =VLOOKUP(D27,'TS Gantry - AP44'!$C$8:$D$646,2,0) -> DA+3 | F27: 37.931 | G27: 45923 | H27: 45927 | I27: M/s. Jwala Singh | J27: Mahendra | K27: Rajasthan | L27: =VLOOKUP(D27,'TS Gantry - AP44'!$C$8:$X$638,22,FALSE) -> KAKARICHCHHA | M27: =VLOOKUP(D27,'TS Gantry - AP44'!$C$8:$Y$638,23,FALSE) -> LUNKARANSAR | N27: =VLOOKUP(D27,'TS Gantry - AP44'!$C$8:$Z$638,24,FALSE) -> BIKANER
A28: =A27+1 -> 24 | B28: Oct'25 | C28: 1 | D28: 28/1 | E28: =VLOOKUP(D28,'TS Gantry - AP44'!$C$8:$D$646,2,0) -> DA+6 | F28: 43.804 | G28: 45924 | H28: 45933 | I28: M/s. Punam Kumari | J28: Dhiraj Kumar | K28: Rajasthan | L28: =VLOOKUP(D28,'TS Gantry - AP44'!$C$8:$X$638,22,FALSE) -> UCHHRANGDESAR | M28: =VLOOKUP(D28,'TS Gantry - AP44'!$C$8:$Y$638,23,FALSE) -> LUNKARANSAR | N28: =VLOOKUP(D28,'TS Gantry - AP44'!$C$8:$Z$638,24,FALSE) -> BIKANER | O28: Yes | Q28: 45911 | R28: 45924
A29: =A28+1 -> 25 | B29: Oct'25 | C29: 2 | D29: 30/7 | E29: =VLOOKUP(D29,'TS Gantry - AP44'!$C$8:$D$646,2,0) -> DA+3 | F29: 37.931 | G29: 45928 | H29: 45934 | I29: M/s. Punam Kumari | J29: Raj Kishor | K29: Rajasthan | L29: =VLOOKUP(D29,'TS Gantry - AP44'!$C$8:$X$638,22,FALSE) -> CHHATASAR | M29: =VLOOKUP(D29,'TS Gantry - AP44'!$C$8:$Y$638,23,FALSE) -> LUNKARANSAR | N29: =VLOOKUP(D29,'TS Gantry - AP44'!$C$8:$Z$638,24,FALSE) -> BIKANER | O29: Yes | Q29: 45911 | R29: 45926
A30: =A29+1 -> 26 | B30: Oct'25 | C30: 3 | D30: 20/1 | E30: =VLOOKUP(D30,'TS Gantry - AP44'!$C$8:$D$646,2,0) -> DA+6 | F30: 43.804 | G30: 45928 | H30: 45934 | I30: M/s. Jwala Singh | J30: Mahendra | K30: Rajasthan | L30: =VLOOKUP(D30,'TS Gantry - AP44'!$C$8:$X$638,22,FALSE) -> KALKAL MUKLERA | M30: =VLOOKUP(D30,'TS Gantry - AP44'!$C$8:$Y$638,23,FALSE) -> LUNKARANSAR | N30: =VLOOKUP(D30,'TS Gantry - AP44'!$C$8:$Z$638,24,FALSE) -> BIKANER
A31: =A30+1 -> 27 | B31: Oct'25 | C31: 4 | D31: 28/5 | E31: =VLOOKUP(D31,'TS Gantry - AP44'!$C$8:$D$646,2,0) -> DA+0 | F31: 36.16 | G31: 45933 | H31: 45938 | I31: M/s. Punam Kumari | J31: Dhiraj Kumar | K31: Rajasthan | L31: =VLOOKUP(D31,'TS Gantry - AP44'!$C$8:$X$638,22,FALSE) -> KALOO | M31: =VLOOKUP(D31,'TS Gantry - AP44'!$C$8:$Y$638,23,FALSE) -> LUNKARANSAR | N31: =VLOOKUP(D31,'TS Gantry - AP44'!$C$8:$Z$638,24,FALSE) -> BIKANER | O31: Yes | Q31: 45911 | R31: 45933
A32: =A31+1 -> 28 | B32: Oct'25 | C32: 5 | D32: 9/0 | E32: =VLOOKUP(D32,'TS Gantry - AP44'!$C$8:$D$646,2,0) -> DB1+0 | F32: 55.451 | G32: 45925 | H32: 45939 | I32: M/s. Kavya Enterprises | J32: Narayan Mahto | K32: Rajasthan | L32: =VLOOKUP(D32,'TS Gantry - AP44'!$C$8:$X$638,22,FALSE) -> DHEERERAN | M32: =VLOOKUP(D32,'TS Gantry - AP44'!$C$8:$Y$638,23,FALSE) -> LUNKARANSAR | N32: =VLOOKUP(D32,'TS Gantry - AP44'!$C$8:$Z$638,24,FALSE) -> BIKANER
