Workbook
Name __________________________b111121: #REF!
Name __________________________b111121: #REF!
Name _________________________b111121: #REF!
Name _________________________b111121: #REF!
Name ________________________b111121: #REF!
Name ________________________b111121: #REF!
Name _______________________b111121: #REF!
Name _______________________b111121: #REF!
Name ______________________b111121: #REF!
Name ______________________b111121: #REF!
Name ______________________TAB1: #REF!
Name _____________________b111121: #REF!
Name _____________________b111121: #REF!
Name _____________________TAB1: #REF!
Name ____________________b111121: #REF!
Name ____________________b111121: #REF!
Name ____________________KEY3: #REF!
Name ____________________KEY3: #REF!
Name ____________________TAB1: #REF!
Name ___________________b111121: #REF!
Name ___________________b111121: #REF!
Name ___________________KEY3: #REF!
Name ___________________KEY3: #REF!
Name ___________________TAB1: #REF!
Name __________________b111121: #REF!
Name __________________b111121: #REF!
Name __________________KEY3: #REF!
Name __________________KEY3: #REF!
Name __________________TAB1: #REF!
Name _________________b111121: #REF!
Name _________________b111121: #REF!
Name _________________KEY3: #REF!
Name _________________KEY3: #REF!
Name _________________TAB1: #REF!
Name ________________b111121: #REF!
Name ________________b111121: #REF!
Name ________________KEY3: #REF!
Name ________________KEY3: #REF!
Name ________________TAB1: #REF!
Name _______________b111121: #REF!
Name _______________b111121: #REF!
Name _______________KEY3: #REF!
Name _______________KEY3: #REF!
Name _______________TAB1: #REF!
Name ______________b111121: #REF!
Name ______________b111121: #REF!
Name ______________TAB1: #REF!
Name _____________A65537: #REF!
Name _____________A65537: #REF!
Name _____________b111121: #REF!
Name _____________b111121: #REF!
Name _____________TAB1: #REF!
Name ____________A655600: #REF!
Name ____________A655600: #REF!
Name ____________b111121: #REF!
Name ____________b111121: #REF!
Name ____________KEY3: #REF!
Name ____________KEY3: #REF!
Name ____________TAB1: #REF!
Name ___________A65537: #REF!

Sheet Visual Chart 
B1: VISUAL PROGRESS CHART
B2: TL-02 765 KV D/C Kurnool IV - Bidar Transmission Line
B3: Foundation (Nos.):- | D3: =H15 -> 0 | E3: / 297 | F3: Erection (Nos.):- | I3: / 297 | J3: Earthing (Nos.):- | M3: / 297 | N3: Rough Sag (Kms):- | Q3: 113.292 | R3: Final Sag (Kms):- | U3: 113.292 | V3: Date:- | W3: ='Master Sheet'!H2 -> 46116
B4: COMPLETION CHART | C4: -3 | D4: +0 | E4: +3 | F4: +6 | G4: +9 | H4: Total | I4: Line Qty
J5: ERECTION | P5: Rough Sag | R5: SH / NH Road Crossing
J6: WIP | V6: River
B7: DA | H7: =SUM(C7:G7) -> 0 | K7: Type | M7: Angle Tower | R7: Gas Pipeline
B8: DB1 | H8: =SUM(C8:G8) -> 0 | J8: FOUNDATION
B9: DB2 | H9: =SUM(C9:G9) -> 0 | O9: Final Sag
B10: DC1 | H10: =SUM(C10:G10) -> 0
B11: DC2 | H11: =SUM(C11:G11) -> 0 | S11: Railway
B12: DCT | H12: =SUM(C12:G12) -> 0 | Q12: WIP
B13: DD45 | H13: =SUM(C13:G13) -> 0 | J13: Section Tower | K13: SC | S13: Crossing | V13: 110-800 KV
B14: DD60 | H14: =SUM(C14:G14) -> 0 | J14: TP | K14: TT | M14: Earthing | P14: OPGW | V14: Line
B15: Total Completed Foundations | H15: =SUM(H7:H14) -> 0 | I15: =SUM(I7:I14) -> 0
AB16: 110kv OHTL
AA18: SH -122
C19: 411 | E19: 432 | G19: 408 | I19: 433 | K19: 409 | M19: 432 | O19: 375 | Q19: 414 | S19: 403 | U19: 406 | W19: 319 | Y19: 384
B21: 48/0 | D21: 48/1 | F21: 48/2 | H21: 48/3 | J21: 48/4 | L21: 48/5 | N21: 48/6 | P21: 48/7 | R21: 49/0 | T21: 49/1 | V21: 49/2 | X21: 49/3
B22: 3DB1+0 | D22: 3DA+6 | F22: 3DA+0 | H22: 3DA+6 | J22: 3DA+3 | L22: 3DA+3 | N22: 3DA+3 | P22: 3DA+6 | R22: 3DC1+3 | T22: 3DA+0 | V22: 3DA+0 | X22: 3DA+0
C25: 385 | E25: 409 | G25: 369 | I25: 350 | K25: 395 | M25: 412 | O25: 366 | Q25: 383 | S25: 300 | U25: 393 | W25: 414 | Y25: 412
B27: 49/4 | D27: 49/5 | F27: 49/6 | H27: 49/7 | J27: 49/8 | L27: 49/9 | N27: 49/10 | P27: 49/11 | R27: 50/0 | T27: 50/1 | V27: 50/2 | X27: 50/3
B28: 3DA+0 | D28: 3DA+6 | F28: 3DA+0 | H28: 3DA+0 | J28: 3DA+0 | L28: 3DA+0 | N28: 3DA+0 | P28: 3DA+0 | R28: 3DC2+0 | T28: 3DA+0 | V28: 3DA+0 | X28: 3DA+3
C32: 377 | E32: 369 | G32: 369 | I32: 403 | K32: 374 | M32: 416 | O32: 424 | Q32: 401 | S32: 437 | U32: 369 | W32: 361 | Y32: 458
B34: 51/0 | D34: 51/1 | F34: 51/2 | H34: 51/3 | J34: 51/4 | L34: 51/5 | N34: 51/6 | P34: 51/7 | R34: 51/8 | T34: 51/9 | V34: 51/10 | X34: 52/0
B35: 3DC2+0 | D35: 3DA+3 | F35: 3DA+0 | H35: 3DA+0 | J35: 3DA+0 | L35: 3DA+0 | N35: 3DA+3 | P35: 3DA+3 | R35: 3DA+3 | T35: 3DA+3 | V35: 3DA+0 | X35: 3DB2+0
X36: RWY Xing | Y36: TDR-VBD
C39: 355 | E39: 347 | G39: 430 | I39: 408 | K39: 402 | M39: 411 | O39: 397 | Q39: 404 | S39: 398 | U39: 430 | W39: 320 | Y39: 230
B41: 52/1 | D41: 52/2 | F41: 52/3 | H41: 52/4 | J41: 53/0 | L41: 53/1 | N41: 53/2 | P41: 53/3 | R41: 53/4 | T41: 53/5 | V41: 53/6 | X41: 54/0
B42: 3DA+9 | D42: 3DA+0 | F42: 3DA+0 | H42: 3DA+0 | J42: 3DB2+3 | L42: 3DA+3 | N42: 3DA+0 | P42: 3DA+3 | R42: 3DA+3 | T42: 3DA+0 | V42: 3DA+3 | X42: 3DD60+0
C46: 339 | E46: 365 | G46: 409 | I46: 343 | K46: 352 | M46: 419 | O46: 410 | Q46: 413 | S46: 407 | U46: 352 | W46: 405 | Y46: 393
B48: 55/0 | D48: 55/1 | F48: 55/2 | H48: 55/3 | J48: 56/0 | L48: 56/1 | N48: 56/2 | P48: 56/3 | R48: 56/4 | T48: 56/5 | V48: 56/6 | X48: 56/7
B49: 3DD60+0 | D49: 3DA+0 | F49: 3DA+0 | H49: 3DA+0 | J49: 3DC1+0 | L49: 3DA+3 | N49: 3DA+3 | P49: 3DA+0 | R49: 3DA+3 | T49: 3DA+3 | V49: 3DA+0 | X49: 3DA+0
M50: 220KV D/C OHTL
M51: TDR-GBL
C53: 439 | E53: 398 | G53: 445 | I53: 355 | K53: 447 | M53: 215 | O53: 498 | Q53: 325 | S53: 388 | U53: 381 | W53: 349 | Y53: 373
B55: 56/8 | D55: 56/9 | F55: 56/10 | H55: 56/11 | J55: 56/12 | L55: 57/0 | N55: 58/0 | P55: 58/1 | R55: 58/2 | T55: 58/3 | V55: 59/0 | X55: 59/1
B56: 3DA+0 | D56: 3DA+6 | F56: 3DA+0 | H56: 3DA+0 | J56: 3DA+0 | L56: 3DC1+9 | N56: 3DB2+6 | P56: 3DA+6 | R56: 3DA+0 | T56: 3DA+3 | X56: 3DA+0
C60: 386 | E60: 429 | G60: 377 | I60: 405 | K60: 425 | M60: 344 | O60: 399 | Q60: 439 | S60: 403 | U60: 480 | W60: 535 | Y60: 389
B62: 59/2 | D62: 59/3 | F62: 59/4 | H62: 59/5 | J62: 60/0 | L62: 60/1 | N62: 60/2 | P62: 60/3 | R62: 60/4 | T62: 60/5 | V62: 60/6 | X62: 60/7
...

Sheet Master Sheet
C2: Project Code | D2: TA-601 | G2: Date as on | H2: 46116 | I2: SBU Head | J2: Mr. Rajinder Gupta
C3: Project Name | D3: 765kV D/C Kurnool IV - Bidar trnasmission line (Part II) | G3: LOA Start Date | H3: 13.05.2025 | I3: PCH | J3: Mr. Arun Felbin R
C4: Client Name | D4: POWERGRID KURNOOL IV TRANSMISSION LIMITED | G4: LOA End Date | H4: 12.04.2027 | I4: Regional Manager | J4: Mr. Ajith Kumar MG
C5: Duration | D5: 23 Months | G5: Planning Engineer | H5: Mr. Siddhesh Bhoyar | I5: Chief Manger | J5: Mr. Senthil Jayaraman
B8: Survey Status
B9: Activity | C9: Unit | D9: Final Est. Qty | E9: L2 till Last Month | F9: Completed till Last Month | G9: Approved till Last Month | H9: Balance to Submit | I9: Plan for Current Month | J9: Balance to Approve | K9: L2 Submission Plan for Current Month | L9: Approved till Current Month | M9: Remarks
B10: Detailed Survey | C10: kms | D10: 113.286 | E10: 113.286 | F10: 113.286 | G10: 113.286 | H10: 0 | I10: 0 | J10: 0 | K10: 0 | L10: 113.286
B11: Check Survey | C11: kms | D11: 113.286 | E11: 113.286 | F11: 113.286 | G11: 106.439 | H11: =E11-F11 -> 0 | I11: =F11-G11 -> 6.847 | J11: =I11 -> 6.847 | K11: 0 | L11: 106.439
B14: Foundation Status
B15: Activity | C15: Scope Quantity | D15: Cumulative L2 till Last Month | E15: Cumulative Progress till Last Month | F15: L2 for present Month | G15: Plan for the Month | H15: Today's Progress | I15: Progress for Current Month | J15: L2 till Current Month | K15: Completed till Date | L15: Balance Work | M15: Under Progress | N15: Gangs at Present | O15: Remarks
B16: Foundation | C16: 292 | D16: 212 | E16: 101 | F16: 40 | G16: 40 | H16: 0 | I16: 0 | J16: 252 | K16: =E16+I16 -> 101 | L16: =292-K16 -> 191 | M16: 2 | N16: 2
B17: Earthing | C17: 292 | D17: 212 | E17: 67 | F17: 40 | G17: 40 | H17: 0 | I17: 0 | J17: =J16 -> 252 | K17: =E17+I17 -> 67 | L17: =C17-K17 -> 225
B18: Tower Erection | C18: 292 | D18: 155 | E18: 66 | F18: 35 | G18: 15 | H18: 1 | I18: 2 | J18: 190 | K18: =E18+I18 -> 68 | L18: =C18-K18 -> 224 | M18: 2 | N18: 2
B19: Stringing -R/S | C19: 113.286 | D19: 7 | E19: 0 | F19: 10 | G19: 0 | H19: 0 | I19: 0 | J19: 17 | K19: =E19+I19 -> 0 | L19: =C19-K19 -> 113.286
B20: Stringing -F/S | C20: 113.286 | D20: 7 | E20: 0 | F20: 10 | G20: 0 | H20: 0 | I20: 0 | J20: 17 | K20: =E20+I20 -> 0 | L20: =C20-K20 -> 113.286
B21: OPGW | C21: 113.286 | D21: 7 | E21: 0 | F21: 10 | G21: 0 | H21: 0 | I21: 0 | J21: 17 | K21: =E21+I21 -> 0 | L21: =C21-K21 -> 113.286
B22: NH Crossing | C22: 3 | L22: =C22-K22 -> 3
B23: SH Crossing | C23: 1 | L23: =C23-K23 -> 1
B24: Railway crossing | C24: 2 | L24: =C24-K24 -> 2
B25: Power Line Crossing | C25: 6 | L25: =C25-K25 -> 6
B27: WIP - Foundations | C27: Pit A | D27: Pit B | E27: Pit C | F27: Pit D | G27: Gang | K27: WIP - Erection | L27: Tower | M27: Gang | N27: Status
B28: 50/0 | C28: Prop Set | D28: Excavation | E28: Steel Binding | F28: Excavation | G28: VEER TEJA | K28: 100/8 | L28: DA+0 | M28: TNR INFRA | N28: Completed
B29: 60/0 | C29: RCC (F&B) | D29: RCC (F&B) | E29: RCC (F&B) | F29: Steel | G29: Shri Harshini | K29: 53/5 | L29: DA+0 | M29: NASIRUDDIN | N29: 2nd Section Completed
B33: Supply Status
B34: Activity | C34: Unit | D34: Final Est. Qty | E34: L2 till Last Month | F34: Received till Last Month | G34: Balance | H34: L2 Plan for Current Month | I34: Plan for Current Month | J34: Progress for the Month | K34: Received till Current Month | L34: Gap between Supply & Cumm.L2 | M34: Remarks
B35: Stub | C35: Set | D35: 292 | E35: 292 | F35: 235 | G35: =D35-F35 -> 57 | H35: 0 | I35: 0 | J35: 0 | K35: =F35+J35 -> 235 | L35: =E35+H35-K35 -> 57
B36: Tower | C36: No's | D36: 292 | E36: 230 | F36: 221 | G36: =D36-F36 -> 71 | H36: 0 | I36: 0 | J36: 0 | K36: =F36+J36 -> 221 | L36: =E36+H36-K36 -> 9
B37: AL59 Conductor | C37: kms | D37: 4314 | E37: 2700 | F37: 2870.615 | G37: =D37-F37 -> 1443.385 | H37: 300 | I37: 300 | J37: 0 | K37: =F37-J37 -> 2870.615 | L37: =E37+H37-K37 -> 129.385 | M37: 964 Drums Received
B39: Support Required :
B40: 1) 2.5 Km Stretch Hold for LILO.
B41: 2) RC Stub Drawings Required- DB,DC,DD45,DD60 (1MRC,2MRC,3MRC)
B42: 3) RC Foundation Drawings Required- DB,DC,DD45,DD60 (1MRC,2MRC,3MRC)

Sheet Progress Sheet 
B2: Survey Status
B3: Activity | C3: Unit | D3: Final Est. Qty | E3: L2 till Last Month | G3: Completed till Last Month | H3: Approved till Last Month | I3: Balance to Submit | J3: Balance to Approve | K3: L2 Submission Plan for Current Month | L3: Progress For Month | M3: Approved till Current Month | N3: Remarks
B4: Detailed Survey | C4: kms | D4: ='Master Sheet'!D10 -> 113.286 | E4: ='Master Sheet'!E10 -> 113.286 | G4: 113.286 | H4: ='Master Sheet'!G10 -> 113.286 | I4: ='Master Sheet'!H10 -> 0 | J4: ='Master Sheet'!J10 -> 0 | K4: ='Master Sheet'!K10 -> 0 | L4: ='Master Sheet'!I10 -> 0 | M4: ='Master Sheet'!L10 -> 113.286
B5: Check Survey | C5: kms | D5: ='Master Sheet'!D11 -> 113.286 | E5: ='Master Sheet'!E11 -> 113.286 | G5: ='Master Sheet'!F11 -> 113.286 | H5: ='Master Sheet'!G11 -> 106.439 | I5: ='Master Sheet'!H11 -> 0 | J5: ='Master Sheet'!J11 -> 6.847 | K5: 20 | L5: ='Master Sheet'!I11 -> 6.847 | M5: ='Master Sheet'!L11 -> 106.439
B7: PROGRESS - Check Survey
B8: S.No | C8: Section | E8: Length | G8: Check survey status
L10: =COUNTIFS($I$13:$L$130,"Foundation Completed.") -> 101
B11: PROGRESS - FDN & EREC
B12: S.No | C12: Location No. | D12: Tower Type | E12: Classification | F12: ROW cleared date | G12: Start Date | H12: Conc Volume | I12: Foundation Status | M12: End Date | N12: Gang Name | O12: Erection Status | P12: Gang Strength | Q12: Remarks
B13: 1 | C13: 81/2 | D13: DA+3 | E13: DFR | F13: =G13 -> 45854 | G13: 45854 | H13: 26.43 | I13: Foundation completed. | M13: 45876 | N13: MARC | P13: 10
B14: =B13+1 -> 2 | C14: 82/1 | D14: DA+0 | E14: WC | F14: 45848 | G14: 45849 | H14: 22.4 | I14: Foundation completed. | M14: 45891 | N14: MARC | P14: 10
B15: =B14+1 -> 3 | C15: 81/1 | D15: DA+0 | E15: DFR | F15: =ROW!D6 -> 0 | G15: 45892 | H15: 23.27 | I15: Foundation completed. | M15: 45913 | N15: MARC | P15: 10
B16: =B15+1 -> 4 | C16: 80/5 | D16: DA+0 | E16: DRY | F16: 45898 | G16: 45902 | H16: 21.96 | I16: Foundation completed. | M16: 45918 | N16: MARC | P16: 10
B17: =B16+1 -> 5 | C17: 80/1 | D17: DA+6 | E17: WFR | F17: 45897 | G17: 45898 | H17: 36.66 | I17: Foundation completed. | M17: 45940 | N17: MARC | P17: 10
B18: =B17+1 -> 6 | C18: 59/5 | D18: DA+0 | E18: DRY | F18: 45930 | G18: 45938 | H18: 21.96 | I18: Foundation completed. | M18: 45949 | N18: SHRIARSHINI | P18: 10
B19: =B18+1 -> 7 | C19: 84/3 | D19: DA+0 | E19: DRY | F19: 45919 | G19: 45940 | H19: 21.96 | I19: Foundation completed. | M19: 45949 | N19: SHIVRATHIRI BALRAJ | P19: 10
B20: =B19+1 -> 8 | C20: 59/4 | D20: DA+6 | E20: DRY | F20: 45933 | G20: 45938 | H20: 25.04 | I20: Foundation completed. | M20: 45951 | N20: SHRIARSHINI | P20: 20
B21: =B20+1 -> 9 | C21: 84/4 | D21: DA+0 | E21: DRY | F21: 45925 | G21: 45941 | H21: 21.96 | I21: Foundation completed. | M21: 45954 | N21: SHIVRATHIRI BALRAJ | P21: 10
B22: =B21+1 -> 10 | C22: 60/2 | D22: DA+0 | E22: DFR | G22: 45944 | H22: 23.27 | I22: Foundation completed. | M22: 45955 | N22: SHRIARSHINI | P22: 20
B23: =B22+1 -> 11 | C23: 80/4 | D23: DA+3 | E23: WFR | F23: 45919 | G23: 45923 | H23: 36.66 | I23: Foundation completed. | M23: 45957 | N23: MARC | P23: 10
B24: =B23+1 -> 12 | C24: 77/4 | D24: DA+0 | E24: DRY | F24: 45916 | G24: 45917 | H24: 21.96 | I24: Foundation completed. | M24: 45961 | N24: SHIVRATHIRI BALRAJ | P24: 10
B25: =B24+1 -> 13 | C25: 77/10 | D25: DA+3 | E25: DRY | G25: 45957 | H25: 25.04 | I25: Foundation completed. | M25: 45966 | N25: SHIVRATHIRI BALRAJ | P25: 10
B26: =B25+1 -> 14 | C26: 59/2 | D26: DA+0 | E26: DRY | G26: 45959 | H26: 21.96 | I26: Foundation completed. | M26: 45969 | N26: SHRIARSHINI | P26: 15
B27: =B26+1 -> 15 | C27: 77/7 | D27: DA+0 | E27: DFR | G27: 45963 | H27: 23.27 | I27: Foundation completed. | M27: 45970 | N27: SHIVRATHIRI BALRAJ | P27: 10
B28: =B27+1 -> 16 | C28: 77/8 | D28: DA+0 | E28: DFR | G28: 45963 | H28: 23.27 | I28: Foundation completed. | M28: 45974 | N28: MARC | P28: 10
B29: =B28+1 -> 17 | C29: 60/3 | D29: DA+6 | E29: DRY | G29: 45953 | H29: 25.04 | I29: Foundation completed. | M29: 45976 | N29: SHRIARSHINI | P29: 15
B30: =B29+1 -> 18 | C30: 77/3 | D30: DA+0 | E30: DFR | G30: 45968 | H30: 23.27 | I30: Foundation completed. | M30: 45980 | N30: MARC | P30: 10
B31: =B30+1 -> 19 | C31: 60/8 | D31: DA+3 | E31: DFR | G31: 45973 | H31: 26.43 | I31: Foundation completed. | M31: 45984 | N31: SHRIARSHINI | P31: 10
B32: =B31+1 -> 20 | C32: 77/1 | D32: DA+0 | E32: DRY | G32: 45968 | H32: 21.96 | I32: Foundation completed. | M32: 45986 | N32: MARC | P32: 10
B33: =B32+1 -> 21 | C33: 59/1 | D33: DA+0 | E33: DFR | G33: 45984 | H33: 23.27 | I33: Foundation completed. | M33: 45990 | N33: SHRIARSHINI | P33: 10
B34: =B33+1 -> 22 | C34: 77/2 | D34: DA+0 | E34: DRY | G34: 45979 | H34: 21.96 | I34: Foundation completed. | M34: 45991 | N34: MARC | P34: 10
B35: =B34+1 -> 23 | C35: 58/2 | D35: DA+0 | E35: DRY | G35: 45988 | H35: 21.96 | I35: Foundation completed. | M35: 45994 | N35: SHRIARSHINI | P35: 16
B36: =B35+1 -> 24 | C36: 58/1 | D36: DA+6 | E36: DRY | G36: 45992 | H36: 25.04 | I36: Foundation completed. | M36: 45999 | N36: SHRIARSHINI | P36: 16
... B112: =B111+1 -> 100 | C112: 51/2 | D112: DA+0 | E112: DFR | G112: 46102 | H112: 23.27 | I112: Foundation Completed. | M112: 46108 | N112: SHRIARSHINI | P112: 20
B113: =B112+1 -> 101 | C113: 53/3 | D113: DA+3 | E113: WET | H113: 38.98 | I113: Foundation Completed. | M113: 46112 | N113: SHRIARSHINI | P113: 20
B114: =B113+1 -> 102 | C114: 84/2 | D114: DA+0 | I114: WIP: Excavation Hard Rock Encounted | N114: BALAJI INFRA
B115: =B114+1 -> 103 | C115: 60/1 | D115: DA+0 | I115: Trial Pit Excavated, Hard Rock encounted | N115: SHRIARSHINI-2 | P115: 15
B116: =B115+1 -> 104 | C116: 101/4 | D116: DA+0 | G116: 46052 | I116: WIP: Excavated | M116: WIP | N116: VKP TRADERS | P116: 11
B117: =B116+1 -> 105 | C117: 85/0 | D117: DB1+0 | G117: 46067 | I117: WIP: Pit Marking | M117: WIP | N117: MARC | P117: 18
B118: =B117+1 -> 106 | C118: 50/0 | D118: 3DC2+0 | E118: WFR | G118: 46077 | I118: WIP: PCC, Steel Binding | M118: WIP | N118: VEER TEJA CONSTRUCTION | P118: 10
...

Sheet ROW
A1: TL-02 765kV Kurnool IV - Bidar line
A2: Foundation
A3: Sr. No. | B3: Location no. | C3: Type of tower | D3: ISSUE
A4: 1 | B4: 50/0 | C4: DC2+0
A5: =A4+1 -> 2 | B5: 51/1 | C5: DA+3
A6: =A5+1 -> 3 | B6: 51/0 | C6: DC2+0
A7: =A6+1 -> 4 | B7: 51/5 | C7: DA+0
A8: =A7+1 -> 5 | B8: 52/2 | C8: DA+0
A9: =A8+1 -> 6 | B9: 52/3 | C9: DA+0
A10: =A9+1 -> 7 | B10: 52/4 | C10: DA+0
A11: =A10+1 -> 8 | B11: 53/0 | C11: DB1+3
A12: =A11+1 -> 9 | B12: 85/3 | C12: DA+0
A13: =A12+1 -> 10 | B13: 85/4 | C13: DA+0

Sheet SUPPLY
B1: Supply Status - Stubs & Towers
B2: Stub Details
B3: SL No | C3: Description | D3: Unit | E3: Line Qty | F3: Received | G3: Balance
B4: 1 | C4: 3DA Stub | D4: Set | F4: 181
B5: 2 | C5: 3DB Stub | D5: Set | F5: 27
B6: 3 | C6: 3DC Stub | D6: Set | F6: 17
B7: 4 | C7: 3D45 Stub | D7: Set | F7: 6
B8: 5 | C8: 3D60 Stub | D8: Set | F8: 4
C9: Total | D9: Set | E9: =SUM(E4:E8) -> 0 | F9: =SUM(F4:F8) -> 235 | G9: =SUM(G4:G8) -> 0 | H9: =SUM(H4:H8) -> 0 | I9: =SUM(I4:I8) -> 0
B11: Tower Details
B12: SL No | C12: Tower Type | D12: Description | E12: Line Qty | F12: Received | G12: Balance | J12: Remarks
B13: 1 | C13: 3DA Type | D13: Basic body | F13: 169
D14: +0m BE | F14: 129
D15: +3m BE | F15: 40
D16: +6m BE | F16: 18
D17: +9m BE | F17: 12
B18: 2 | C18: 3DB Type | D18: Basic body | F18: 31
D19: +0m BE | F19: 27
D20: +3m BE | F20: 0
D21: +6m BE | F21: 0
D22: +9m BE | F22: 7
B23: 3 | C23: 3DC Type | D23: Basic body | F23: 21
D24: +0m BE | F24: 18
D25: +3m BE | F25: 3
D26: +6m BE | F26: 0
D27: +9m BE | F27: 3
B28: 4 | C28: 3DD45 Type | D28: Basic body
D29: +0m BE
D30: +3m BE
D31: +6m BE
D32: +9m BE
B33: 5 | C33: 3DD60 Type | D33: Basic body
D34: +0m BE
D35: +3m BE
D36: +6m BE
D37: +9m BE
D39: Total | F39: =SUM(F13+F18+F23) -> 221
B44: Activity | C44: Unit | D44: Final Est. Qty | E44: L2 till Last Month | F44: Received till Last Month | G44: Balance | H44: L2 Plan for Current Month | I44: Plan for Current Month | J44: Progress for the Month | K44: Received till Current Month | L44: Gap between Suppy & Cumm.L2 | M44: Remarks
B45: Stub | C45: Set | D45: ='Master Sheet'!D35 -> 292 | E45: ='Master Sheet'!E35 -> 292 | F45: ='Master Sheet'!F35 -> 235 | G45: ='Master Sheet'!G35 -> 57 | H45: ='Master Sheet'!H35 -> 0 | I45: ='Master Sheet'!I35 -> 0 | J45: ='Master Sheet'!J35 -> 0 | K45: ='Master Sheet'!K35 -> 235 | L45: ='Master Sheet'!L34 -> Gap between Supply & Cumm.L2
B46: Tower | C46: No's | D46: ='Master Sheet'!D36 -> 292 | E46: ='Master Sheet'!E36 -> 230 | F46: ='Master Sheet'!F36 -> 221 | G46: ='Master Sheet'!G36 -> 71 | H46: ='Master Sheet'!H36 -> 0 | I46: ='Master Sheet'!I36 -> 0 | J46: ='Master Sheet'!J36 -> 0 | K46: ='Master Sheet'!K36 -> 221 | L46: ='Master Sheet'!L35 -> 57
...

Sheet Erection Compiled
A2: SL No. | B2: Location No. | C2: Tower Type | D2: Classification | E2: Start Date | F2: MT | G2: Status | H2: End Date | I2: Gang Name | J2: Gang Strength
A3: 1 | B3: 56/7 | C3: DA+0 | D3: DFR | E3: 46006 | F3: 35.089 | G3: Erection Completed. | H3: 46011 | I3: NASIRUDDIN | J3: 35
A4: =A3+1 -> 2 | B4: 59/2 | C4: DA+0 | D4: DRY | E4: 46013 | F4: 35.089 | G4: Erection Completed. | H4: 46018 | I4: NASIRUDDIN | J4: 35
A5: =A4+1 -> 3 | B5: 77/3 | C5: DA+0 | D5: DFR | E5: 46013 | F5: 35.089 | G5: Erection Completed. | H5: 46022 | I5: CRANE | J5: 49
A6: =A5+1 -> 4 | B6: 58/2 | C6: DA+0 | D6: DRY | E6: 46016 | F6: 35.089 | G6: Erection Completed. | H6: 46032 | I6: NASIRUDDIN | J6: 35
A7: =A6+1 -> 5 | B7: 77/2 | C7: DA+0 | D7: DRY | E7: 46016 | F7: 35.089 | G7: Erection Completed. | H7: 46030 | I7: CRANE | J7: 49
A8: =A7+1 -> 6 | B8: 58/1 | C8: DA+6 | D8: DRY | E8: 46024 | F8: 41.88 | G8: Erection Completed. | H8: 46032 | I8: NASIRUDDIN | J8: 35
A9: =A8+1 -> 7 | B9: 77/1 | C9: DA+0 | D9: DRY | E9: 46023 | F9: 35.089 | G9: Erection Completed. | H9: 46035 | I9: CRANE | J9: 49
A10: =A9+1 -> 8 | B10: 58/3 | C10: DA+0 | D10: DRY | E10: 46031 | F10: 35.089 | G10: Erection Completed. | H10: 46036 | I10: NASIRUDDIN | J10: 35
A11: =A10+1 -> 9 | B11: 77/4 | C11: DA+0 | D11: DRY | E11: 46029 | F11: 35.089 | G11: Erection Completed. | H11: 46038 | I11: DK VERMA | J11: 21
A12: =A11+1 -> 10 | B12: 82/1 | C12: DA+0 | D12: WC | E12: 46033 | F12: 35.089 | G12: Erection Completed. | H12: 46038 | I12: SHAKILA KHATUN | J12: 31
A13: =A12+1 -> 11 | B13: 80/5 | C13: DA+0 | D13: DFRY | E13: 46037 | F13: 35.089 | G13: Erection Completed. | H13: 46042 | I13: SHAKILA KHATUN | J13: 31
A14: =A13+1 -> 12 | B14: 59/4 | C14: DA+6 | D14: DRY | E14: 46037 | F14: 41.88 | G14: Erection Completed. | H14: 46043 | I14: NASIRUDDIN | J14: 35
A15: =A14+1 -> 13 | B15: 77/7 | C15: DA+0 | D15: DFR | E15: 46039 | F15: 35.089 | G15: Erection Completed. | H15: 46043 | I15: DK VERMA | J15: 21
... A70: =A69+1 -> 68 | B70: 100/8 | C70: DA+0 | D70: DFR | E70: 46111 | F70: 35.089 | G70: Erection Completed. | H70: 46085 | I70: TNR INFA | J70: 24

Sheet X-ing Details 
B2: CROSSINGS PROPOSAL STATUS : 765 KV D/C Kurnool IV - Bidar TL (Part-2)
B6: Crossing Type | C6: 132 KV | D6: 220kV | E6: SH-Xing | F6: NH-Xing | G6: Railway-Xing | H6: Total
B7: Total Nos | C7: 4 | D7: 2 | E7: 1 | F7: 3 | G7: 2 | H7: 12
B8: Submitted Till Date | C8: 4 | D8: 2 | E8: 0 | F8: 3 | G8: 2 | H8: =C8+D8+F8+G8 -> 11
B9: Approved Till Date | C9: 0 | D9: 0 | E9: 0 | F9: 0 | G9: 0 | H9: 0
B10: Balance to Execute | C10: =C7-C8 -> 0 | D10: =D7-D8 -> 0 | E10: =E7-E8 -> 1 | F10: =F7-F8 -> 0 | G10: =G7-G8 -> 0 | H10: 0
B12: Crossings Details
B13: Sl. No. | C13: FROM (AP) | D13: TO (AP) | E13: Name of the Line | F13: NAME OF CROSSING | G13: Date of First Submission | H13: Joint Inspection Status | I13: Provisional approval status
B14: 1 | C14: AP54 | D14: AP55 | E14: Railway crossing (Tandur - Vikarabad) | F14: Railway crossing | G14: 45987
B15: =B14+1 -> 2 | C15: AP57 | D15: AP58 | E15: 220kV D/C transmission line Tandur - Gachibowli (HYD) | F15: Power line | G15: 45946
B16: =B15+1 -> 3 | C16: AP61 | D16: AP62 | E16: NATIONAL HIGHWAY-163 (Kodangal - Hyderabad) | F16: National highway crossing | G16: 45989
B17: =B16+1 -> 4 | C17: AP71 | D17: AP72 | E17: 132kV D/C transmission line Tandur - Mahabubnagar | F17: Power line | G17: 45944
B18: =B17+1 -> 5 | C18: AP74 | D18: AP75 | E18: NATIONAL HIGHWAY-167N (Kodangal - Kosgi) | F18: National highway crossing | G18: 45989
B19: =B18+1 -> 6 | C19: AP76 | D19: AP77 | E19: 220kV D/C transmission line Kosgi - Pargi | F19: Power line | G19: 45946
B20: =B19+1 -> 7 | C20: AP88 | D20: AP89 | E20: 132kV S/C transmission line Maddur - Mahabubnagar | F20: Power line | G20: 45946
B21: =B20+1 -> 8 | C21: AP95 | D21: AP96 | E21: 132kV S/C transmission line Maddur - Makthal | F21: Power line | G21: 45946
B22: =B21+1 -> 9 | C22: AP98 | D22: AP99 | E22: STATE HIGHWAY-22 (Narayanpet - Marikal) | F22: State highway crossing | G22: Not Required
B23: =B22+1 -> 10 | C23: AP106 | D23: AP107 | E23: Railway crossing (Raichur - Makthal) | F23: Railway crossing | G23: 45988
B24: =B23+1 -> 11 | C24: AP109 | D24: AP110 | E24: 132kV S/C transmission line Makthal - Krishna Railway junction | F24: Power line | G24: 08.12.2025
B25: =B24+1 -> 12 | C25: AP110 | D25: AP111 | E25: NATIONAL HIGHWAY-167N (Raichur - Marikal) | F25: National highway crossing | G25: 08.12.2025

Sheet Visual Chart
A1: VISUAL PROGRESS CHART
A2: 765 kV DC Kurnool IV - Bidar Transmission Line (TL-02)
B3: Foundation (Nos.):- | D3: 101 | E3: /292 | F3: Erection (Nos.):- | H3: 68 | I3: /292 | J3: Earthing (Nos.):- | L3: 67 | M3: /292 | N3: Rough Sag (Kms):- | P3: 0 / | Q3: 113.292 | R3: Final Sag (Kms):- | T3: 0 / | U3: 113.292 | V3: Date:- | W3: =TODAY() -> 46117
B4: COMPLETION CHART | C4: Unit | D4: +0 | E4: +3 | F4: +6 | G4: +9 | H4: Total | I4: Line Qty
J5: ERECTION | P5: Rough Sag | R5: SH / NH Road Crossing
J6: WIP | V6: River
B7: DA | C7: Nos | D7: 136 | E7: 47 | F7: 21 | G7: 12 | H7: =SUM(D7:G7) -> 216 | I7: =H7 -> 216 | J7: FOUNDATION | K7: Type | M7: Angle Tower | R7: Gas Pipeline
B8: DB1 | C8: Nos | D8: 8 | E8: 2 | F8: 1 | G8: 9 | H8: =SUM(D8:G8) -> 20 | I8: =H8 -> 20
B9: DB2 | C9: Nos | D9: 11 | E9: 2 | F9: 4 | G9: 1 | H9: =SUM(D9:G9) -> 18 | I9: =H9 -> 18 | O9: Final Sag
B10: DC1 | C10: Nos | D10: 10 | E10: 2 | F10: 1 | G10: 4 | H10: =SUM(D10:G10) -> 17 | I10: =H10 -> 17
B11: DC2 | C11: Nos | D11: 3 | E11: 3 | F11: 1 | G11: 0 | H11: =SUM(D11:G11) -> 7 | I11: =H11 -> 7 | S11: Railway
B12: DCT | C12: Nos | D12: 0 | E12: 0 | F12: 0 | G12: 0 | H12: =SUM(D12:G12) -> 0 | I12: =H12 -> 0 | Q12: WIP | S12: Crossing
B13: DD45 | C13: Nos | D13: 3 | E13: 1 | F13: 1 | G13: 4 | H13: =SUM(D13:G13) -> 9 | I13: =H13 -> 9 | J13: Section Tower | K13: SC | V13: 110kV - 800kV | Z13: Foundation | AA13: Erection | AB13: Earthing
B14: DD60 | C14: Nos | D14: 2 | E14: 2 | F14: 0 | G14: 1 | H14: =SUM(D14:G14) -> 5 | I14: =H14 -> 5 | J14: TP | K14: TT | M14: Earthing | P14: OPGW | V14: Line
B15: Total Completed Foundations | H15: 101 | I15: =292-H15 -> 191
B16: Wind Zone - 3 [AP48 - AP111] | Z16: =SUM(Z18:Z254) -> 101 | AA16: =SUM(AA18:AA254) -> 68 | AB16: =SUM(AB18:AB254) -> 67
A18: COMMON TOWER (TL-1&2) | AD18: DS | AE18: CS | AF18: SI | AG18: FDN | AH18: EAR | AI18: ERN | AJ18: TW | AK18: PO | AL18: FS | AM18: OPGW
AC19: TOTAL | AD19: =(C21+E21+G21+I21+K21+M21+O21+Q21+S21+U21+W21+Y21)/1000 -> 4.83244 | AE19: =(C21+E21+G21+I21+K21+M21+O21+Q21+S21+U21+W21+Y21)/1000 -> 4.83244 | AG19: 12 | AH19: 12 | AI19: 12 | AJ19: 12 | AL19: =(C21+E21+G21+I21+K21+M21+O21+Q21+S21+U21+W21+Y21)/1000 -> 4.83244
AC20: COMPLETED | AG20: =B21+D21+F21 -> 0
C21: 411 | E21: 432 | G21: 411 | I21: 432 | K21: 411 | M21: 432 | O21: 411 | Q21: 374.437 | S21: 376.003 | U21: 405 | W21: 340 | Y21: 397 | AC21: BALANCE
B23: AP48/0 | D23: 48/1 | F23: 48/2 | H23: 48/3 | J23: 48/4 | L23: 48/5 | N23: 48/6 | P23: 48/7 | R23: AP49/0 | T23: 49/1 | V23: 49/2 | X23: 49/3
B24: DB1+0 | D24: 3DA+6 | F24: 3DA+0 | H24: 3DA+6 | J24: 3DA+3 | L24: 3DA+3 | N24: 3DA+3 | P24: 3DA+3 | Q24: =(Q21+O21+M21+K21+I21+G21+E21+C21)/1000 -> 3.314437 | R24: 3DC1+0 | T24: 3DA+0 | V24: 3DA+0 | X24: 3DA+0
V25: RC Removed
H27: Trail pit | L27: Trail pit
C30: 399 | E30: 393 | G30: 370 | I30: 350 | K30: 395 | M30: 413 | N30: VEER TEJA | O30: 366 | P30: VEER TEJA | Q30: 377.77 | R30: VEER TEJA | S30: 300 | T30: SRI HARSH-1 | U30: 393 | V30: SRI HARSH-1 | W30: 415 | X30: SRI HARSH-1 | Y30: 411 | Z30: 5 | AB30: 3
B32: 49/4 | D32: 49/5 | F32: 49/6 | H32: 49/7 | J32: 49/8 | L32: 49/9 | N32: 49/10 | P32: 49/11 | R32: AP50/0 | T32: 50/1 | V32: 50/2 | X32: 50/3
B33: 3DA+0 | D33: 3DA+3 | F33: 3DA+0 | H33: 3DA+0 | J33: 3DA+0 | L33: 3DA+0 | N33: 3DA+0 | P33: 3DA+0 | Q33: =(S21+U21+W21+Y21+Q30+O30+M30+K30+I30+G30+E30+C30)/1000 -> 4.581773 | R33: 3DC2+0 | T33: 3DA+0 | V33: 3DA+0 | X33: 3DA+3 | Y33: =(S30+U30+W30+Y30)/1000 -> 1.519
D34: RC Removed | F34: RC Removed | H34: RC Removed | J34: RC Removed
C39: 378 | E39: 370 | F39: SRI HARSH-1 | G39: 370 | I39: 404 | K39: 374 | M39: 416 | N39: SRI HARSH-1 | O39: 425 | P39: SRI HARSH-1 | Q39: 411 | R39: SRI HARSH-1 | S39: 427 | T39: SRI HARSH-1 | U39: 370 | V39: SRI HARSH-1 | W39: 356 | X39: SRI HARSHI-1 | Y39: 459
Z40: 7 | AA40: 2 | AB40: 6
B41: AP51/0 | D41: 51/1 | F41: 51/2 | H41: 51/3 | J41: 51/4 | L41: 51/5 | N41: 51/6 | P41: 51/7 | R41: 51/8 | T41: 51/9 | V41: 51/10 | X41: AP52/0
B42: 3DC2+0 | D42: 3DA+3 | F42: 3DA+0 | H42: 3DA+0 | J42: 3DA+0 | L42: 3DA+0 | N42: 3DA+3 | P42: 3DA+3 | R42: 3DA+0 | T42: 3DA+3 | V42: 3DA+0 | W42: =(C39+E39+G39+I39+K39+M39+O39+Q39+S39+U39+W39)/1000 -> 4.301 | X42: 3DB2+0
N43: RC Removed | P43: RC Removed | R43: RC Removed
B48: SRI HARSH-1 | C48: 355 | E48: 348 | G48: 434 | I48: 401 | J48: SRI HARSH-1 | K48: 400 | L48: SRI HARSH-1 | M48: 413 | N48: SRI HARSH-1 | O48: 406 | P48: SRI HARSH-1 | Q48: 390 | R48: SRI HARSH-1 | S48: 390 | T48: SRI HARSH-1 | U48: 430 | W48: 332 | Y48: 229.642
Z49: 6 | AA49: 3 | AB49: 3
B50: 52/1 | D50: 52/2 | F50: 52/3 | H50: 52/4 | J50: AP53/0 | L50: 53/1 | N50: 53/2 | P50: 53/3 | R50: 53/4 | T50: 53/5 | V50: 53/6 | X50: AP54/0
B51: 3DA+9 | D51: 3DA+0 | F51: 3DA+0 | H51: 3DA+0 | I51: =(Y39+C48+E48+G48+I48)/1000 -> 1.997 | J51: 3DB1+3 | L51: 3DA+3 | N51: 3DA+0 | P51: 3DA+3 | R51: 3DA+0 | T51: 3DA+0 | V51: 3DA+3 | W51: =(K48+M48+O48+Q48+S48+U48+W48)/1000 -> 2.761 | X51: 3DD60+0 | Y51: =Y48/1000 -> 0.229642
D52: RC Removed | H52: RC Removed | P52: RC Removed | V52: RC Removed | X52: Rly X-ing
C57: 339 | D57: SRI HARSH-1 | E57: 365 | G57: 409 | H57: SRI HARSH-1 | I57: 340.462 | K57: 352 | L57: SRI HARSH-1 | M57: 419 | N57: SRI HARSH-1 | O57: 410 | P57: SRI HARSH-1 | Q57: 413 | R57: SRI HARSH-1 | S57: 407 | T57: RC | U57: 351 | V57: SRI HARSH-1 | W57: 405 | X57: SRI HARSH-1 | Y57: 393
Z58: 8 | AA58: 7 | AB58: 7
...

Sheet Stringing Compiled
A1: S.no | B1: Sec | C1: From AP | D1: To AP | E1: Span (M) | F1: Method | G1: Section Readiness | H1: Insulator Hoisting | I1: P/O Starting Date | J1: P/O Completion Date | K1: P/O | L1: F/S Starting Date | M1: F/S/ Completion Date | N1: Jumpering | O1: Spacering | P1: Clipping | Q1: Length | R1: Status | S1: Gang Name | T1: Gang Strength | U1: Number of Fitters | V1: Hindrance | W1: Remarks
