Workbook
Name __________________________b111121: #REF!
Name __________________________b111121: #REF!
Name _________________________b111121: #REF!
Name _________________________b111121: #REF!
Name ________________________b111121: #REF!
Name ________________________b111121: #REF!
Name _______________________b111121: #REF!
Name _______________________b111121: #REF!
Name ______________________b111121: #REF!
Name ______________________b111121: #REF!
Name ______________________TAB1: #REF!
Name _____________________b111121: #REF!
Name _____________________b111121: #REF!
Name _____________________TAB1: #REF!
Name ____________________b111121: #REF!
Name ____________________b111121: #REF!
Name ____________________KEY3: #REF!
Name ____________________KEY3: #REF!
Name ____________________TAB1: #REF!
Name ___________________b111121: #REF!
Name ___________________b111121: #REF!
Name ___________________KEY3: #REF!
Name ___________________KEY3: #REF!
Name ___________________TAB1: #REF!
Name __________________b111121: #REF!
Name __________________b111121: #REF!
Name __________________KEY3: #REF!
Name __________________KEY3: #REF!
Name __________________TAB1: #REF!
Name _________________b111121: #REF!
Name _________________b111121: #REF!
Name _________________KEY3: #REF!
Name _________________KEY3: #REF!
Name _________________TAB1: #REF!
Name ________________b111121: #REF!
Name ________________b111121: #REF!
Name ________________KEY3: #REF!
Name ________________KEY3: #REF!
Name ________________TAB1: #REF!
Name _______________b111121: #REF!
Name _______________b111121: #REF!
Name _______________KEY3: #REF!
Name _______________KEY3: #REF!
Name _______________TAB1: #REF!
Name ______________b111121: #REF!
Name ______________b111121: #REF!
Name ______________TAB1: #REF!
Name _____________A65537: #REF!
Name _____________A65537: #REF!
Name _____________b111121: #REF!
Name _____________b111121: #REF!
Name _____________TAB1: #REF!
Name ____________A655600: #REF!
Name ____________A655600: #REF!
Name ____________b111121: #REF!
Name ____________b111121: #REF!
Name ____________KEY3: #REF!
Name ____________KEY3: #REF!
Name ____________TAB1: #REF!
Name ___________A65537: #REF!

Sheet Visual Chart 
B1: VISUAL PROGRESS CHART
B2: TL-02 765 KV D/C Kurnool IV - Bidar Transmission Line
B3: Foundation (Nos.):- | D3: =H15 -> 0 | E3: / 297 | F3: Erection (Nos.):- | I3: / 297 | J3: Earthing (Nos.):- | M3: / 297 | N3: Rough Sag (Kms):- | Q3: 113.292 | R3: Final Sag (Kms):- | U3: 113.292 | V3: Date:- | W3: ='Master Sheet'!H2 -> 08.01.2026
B4: COMPLETION CHART | C4: -3 | D4: +0 | E4: +3 | F4: +6 | G4: +9 | H4: Total | I4: Line Qty
J5: ERECTION | P5: Rough Sag | R5: SH / NH Road Crossing
J6: WIP | V6: River
B7: DA | H7: =SUM(C7:G7) -> 0 | K7: Type | M7: Angle Tower | R7: Gas Pipeline
B8: DB1 | H8: =SUM(C8:G8) -> 0 | J8: FOUNDATION
B9: DB2 | H9: =SUM(C9:G9) -> 0 | O9: Final Sag
B10: DC1 | H10: =SUM(C10:G10) -> 0
B11: DC2 | H11: =SUM(C11:G11) -> 0 | S11: Railway
B12: DCT | H12: =SUM(C12:G12) -> 0 | Q12: WIP
B13: DD45 | H13: =SUM(C13:G13) -> 0 | J13: Section Tower | K13: SC | S13: Crossing | V13: 110-800 KV
B14: DD60 | H14: =SUM(C14:G14) -> 0 | J14: TP | K14: TT | M14: Earthing | P14: OPGW | V14: Line
B15: Total Completed Foundations | H15: =SUM(H7:H14) -> 0 | I15: =SUM(I7:I14) -> 0
AB16: 110kv OHTL
AA18: SH -122
C19: 411 | E19: 432 | G19: 408 | I19: 433 | K19: 409 | M19: 432 | O19: 375 | Q19: 414 | S19: 403 | U19: 406 | W19: 319 | Y19: 384
B21: 48/0 | D21: 48/1 | F21: 48/2 | H21: 48/3 | J21: 48/4 | L21: 48/5 | N21: 48/6 | P21: 48/7 | R21: 49/0 | T21: 49/1 | V21: 49/2 | X21: 49/3
B22: 3DB1+0 | D22: 3DA+6 | F22: 3DA+0 | H22: 3DA+6 | J22: 3DA+3 | L22: 3DA+3 | N22: 3DA+3 | P22: 3DA+6 | R22: 3DC1+3 | T22: 3DA+0 | V22: 3DA+0 | X22: 3DA+0
C25: 385 | E25: 409 | G25: 369 | I25: 350 | K25: 395 | M25: 412 | O25: 366 | Q25: 383 | S25: 300 | U25: 393 | W25: 414 | Y25: 412
B27: 49/4 | D27: 49/5 | F27: 49/6 | H27: 49/7 | J27: 49/8 | L27: 49/9 | N27: 49/10 | P27: 49/11 | R27: 50/0 | T27: 50/1 | V27: 50/2 | X27: 50/3
B28: 3DA+0 | D28: 3DA+6 | F28: 3DA+0 | H28: 3DA+0 | J28: 3DA+0 | L28: 3DA+0 | N28: 3DA+0 | P28: 3DA+0 | R28: 3DC2+0 | T28: 3DA+0 | V28: 3DA+0 | X28: 3DA+3
C32: 377 | E32: 369 | G32: 369 | I32: 403 | K32: 374 | M32: 416 | O32: 424 | Q32: 401 | S32: 437 | U32: 369 | W32: 361 | Y32: 458
B34: 51/0 | D34: 51/1 | F34: 51/2 | H34: 51/3 | J34: 51/4 | L34: 51/5 | N34: 51/6 | P34: 51/7 | R34: 51/8 | T34: 51/9 | V34: 51/10 | X34: 52/0
B35: 3DC2+0 | D35: 3DA+3 | F35: 3DA+0 | H35: 3DA+0 | J35: 3DA+0 | L35: 3DA+0 | N35: 3DA+3 | P35: 3DA+3 | R35: 3DA+3 | T35: 3DA+3 | V35: 3DA+0 | X35: 3DB2+0
X36: RWY Xing | Y36: TDR-VBD
C39: 355 | E39: 347 | G39: 430 | I39: 408 | K39: 402 | M39: 411 | O39: 397 | Q39: 404 | S39: 398 | U39: 430 | W39: 320 | Y39: 230
B41: 52/1 | D41: 52/2 | F41: 52/3 | H41: 52/4 | J41: 53/0 | L41: 53/1 | N41: 53/2 | P41: 53/3 | R41: 53/4 | T41: 53/5 | V41: 53/6 | X41: 54/0
B42: 3DA+9 | D42: 3DA+0 | F42: 3DA+0 | H42: 3DA+0 | J42: 3DB2+3 | L42: 3DA+3 | N42: 3DA+0 | P42: 3DA+3 | R42: 3DA+3 | T42: 3DA+0 | V42: 3DA+3 | X42: 3DD60+0
C46: 339 | E46: 365 | G46: 409 | I46: 343 | K46: 352 | M46: 419 | O46: 410 | Q46: 413 | S46: 407 | U46: 352 | W46: 405 | Y46: 393
B48: 55/0 | D48: 55/1 | F48: 55/2 | H48: 55/3 | J48: 56/0 | L48: 56/1 | N48: 56/2 | P48: 56/3 | R48: 56/4 | T48: 56/5 | V48: 56/6 | X48: 56/7
B49: 3DD60+0 | D49: 3DA+0 | F49: 3DA+0 | H49: 3DA+0 | J49: 3DC1+0 | L49: 3DA+3 | N49: 3DA+3 | P49: 3DA+0 | R49: 3DA+3 | T49: 3DA+3 | V49: 3DA+0 | X49: 3DA+0
M50: 220KV D/C OHTL
M51: TDR-GBL
C53: 439 | E53: 398 | G53: 445 | I53: 355 | K53: 447 | M53: 215 | O53: 498 | Q53: 325 | S53: 388 | U53: 381 | W53: 349 | Y53: 373
B55: 56/8 | D55: 56/9 | F55: 56/10 | H55: 56/11 | J55: 56/12 | L55: 57/0 | N55: 58/0 | P55: 58/1 | R55: 58/2 | T55: 58/3 | V55: 59/0 | X55: 59/1
B56: 3DA+0 | D56: 3DA+6 | F56: 3DA+0 | H56: 3DA+0 | J56: 3DA+0 | L56: 3DC1+9 | N56: 3DB2+6 | P56: 3DA+6 | R56: 3DA+0 | T56: 3DA+3 | X56: 3DA+0
C60: 386 | E60: 429 | G60: 377 | I60: 405 | K60: 425 | M60: 344 | O60: 399 | Q60: 439 | S60: 403 | U60: 480 | W60: 535 | Y60: 389
B62: 59/2 | D62: 59/3 | F62: 59/4 | H62: 59/5 | J62: 60/0 | L62: 60/1 | N62: 60/2 | P62: 60/3 | R62: 60/4 | T62: 60/5 | V62: 60/6 | X62: 60/7
...

Sheet Master Sheet
C2: Project Code | D2: TA-601 | G2: Date as on | H2: 08.01.2026 | I2: SBU Head | J2: Mr. Rajinder Gupta
C3: Project Name | D3: 765kV D/C Kurnool IV - Bidar trnasmission line (Part II) | G3: LOA Start Date | H3: 13.05.2025 | I3: PCH | J3: Mr. Arun Felbin
C4: Client Name | D4: POWERGRID KURNOOL IV TRANSMISSION LIMITED | G4: LOA End Date | H4: 12.04.2027 | I4: Regional Manager | J4: Mr. Ajith Kumar MG
C5: Duration | D5: 23 Months | G5: Planning Engineer | H5: Mr. Siddhesh Bhoyar | I5: Chief Manger | J5: Mr. Senthil Jayaraman
B8: Survey Status
B9: Activity | C9: Unit | D9: Final Est. Qty | E9: L2 till Last Month | F9: Completed till Last Month | G9: Approved till Last Month | H9: Balance to Submit | I9: Progress For Month | J9: Balance to Approve | K9: L2 Submission Plan for Current Month | L9: Approved till Current Month | M9: Remarks
B10: Detailed Survey | C10: kms | D10: 113.286 | E10: 0 | F10: 113.286 | G10: 109.04 | H10: 0 | I10: 0 | J10: 4.25 | K10: 0 | L10: =G10+I10 -> 109.04
B11: Check Survey | C11: kms | D11: 113.286 | E11: 110 | F11: 111.745 | G11: 96.901 | H11: 9.448 | I11: 0 | J11: 16.385 | K11: 8.6 | L11: 96.901
B12: .
B14: Activity | C14: Scope Quantity | D14: Cumulative L2 till Last Month | E14: Cumulative Progress till Last Month | F14: L2 for present Month | G14: Plan for the Month | H14: Today's Progress | I14: Progress till Date for the Month | J14: L2 till Current Month | K14: Completed till Date | L14: Balance Work | M14: Under Progress | N14: Gangs at Present | O14: Remarks
B15: Foundation | C15: 292 | D15: 92 | E15: 42 | F15: 40 | G15: 50 | H15: 1 | I15: 4 | J15: 132 | K15: 46 | L15: =C15-K15 -> 246 | M15: 6 | N15: 5 | O15: 1) 56/9 - Pit A,B,C,D PCC Completed. 2) 83/0 - Excavation Completed. 3) 84/1 - Pit C,D Prop Setting Completed. 4) 84/5 - Foundation Completed.
B16: Earthing | C16: 292 | D16: =D15 -> 92 | E16: 10 | F16: =F15 -> 40 | G16: =G15 -> 50 | H16: 0 | I16: 5 | J16: =J15 -> 132 | K16: 15 | L16: =C16-K16 -> 277
B17: Tower Erection | C17: 292 | D17: 50 | E17: 3 | F17: 35 | G17: 30 | H17: 1 | I17: 2 | J17: 85 | K17: 5 | L17: =C17-K17 -> 287 | M17: 2 | N17: 2 | O17: 1) 77/2 - Erection Completed. 2) 77/1 - Bottom Section Completed. 3) 58/1 - Cage2 WIP.
B18: Stringing -R/S | C18: 113.286 | D18: 0 | E18: 0 | F18: 0 | G18: 0 | H18: 0 | I18: 0 | J18: 0 | K18: =E18+I18 -> 0 | L18: =C18-K18 -> 113.286
B19: Stringing -F/S | C19: 113.286 | D19: 0 | E19: 0 | F19: 0 | G19: 0 | H19: 0 | I19: 0 | J19: 0 | K19: =E19+I19 -> 0 | L19: =C19-K19 -> 113.286
B20: OPGW | C20: 113.286 | D20: 0 | E20: 0 | F20: 0 | G20: 0 | H20: 0 | I20: 0 | J20: 0 | K20: =E20+I20 -> 0 | L20: =C20-K20 -> 113.286
B21: NH Crossing | C21: 3 | L21: =C21-K21 -> 3
B22: SH Crossing | C22: 1 | L22: =C22-K22 -> 1
B23: Railway crossing | C23: 2 | L23: =C23-K23 -> 2
B24: Power Line Crossing | C24: 6 | L24: =C24-K24 -> 6
H26: Foundation Gangs at Site: | I26: 1) MARC Contractors Ltd - 83/0 ( WIP) | L26: 4) BALAJI INFRA - 84/5, 84/1, 85/2 (WIP)
I27: 2) SHRIARSHINI CONSTRUCTIONS - 56/9, 59/0 (WIP) | L27: 5) SAI SREE VARSHINI - 100/1, 100/2
I28: 3) VKP Traders - 101/1, 101/2 (WIP)
B29: Supply Status
B30: Activity | C30: Unit | D30: Final Est. Qty | E30: L2 till Last Month | F30: Received till Last Month | G30: Balance | H30: L2 Plan for Current Month | I30: Plan for Current Month | J30: Progress for the Month | K30: Received till Current Month | L30: Gap between Supply & Cumm.L2 | M30: Remarks
B31: Stub | C31: Set | D31: 292 | E31: 260 | F31: 132 | G31: =D31-F31 -> 160 | H31: 56 | I31: 0 | J31: 0 | K31: =F31+J31 -> 132 | L31: =E31+H31-K31 -> 184
B32: Tower | C32: No's | D32: 292 | E32: 160 | F32: 160 | G32: =D32-F32 -> 132 | H32: 0 | I32: 0 | J32: 0 | K32: 160 | L32: =E32+H32-K32 -> 0
B33: Conductor | C33: kms | D33: 4314 | E33: 1700 | F33: 1931.873 | G33: =D33-F33 -> 2382.127 | H33: 400 | I33: 400 | J33: =K33-F33 -> 163.577 | K33: 2095.45 | L33: =E33+H33-K33 -> 4.55 | M33: AL59 Conductor 2095.45 Km/704 Drums Received.
B35: Support Required :
B36: 1) DA Type RC Foundation Drawings (1MRC,2MRC,3MRC)
B37: 2) RC Stub Drawings Required- DB,DC,DD45,DD60 (1MRC,2MRC,3MRC)
B38: 3) RC Foundation Drawings Required- DB,DC,DD45,DD60 (1MRC,2MRC,3MRC)

Sheet Progress Sheet 
B2: Survey Status
B3: Activity | C3: Unit | D3: Final Est. Qty | E3: L2 till Last Month | G3: Completed till Last Month | H3: Approved till Last Month | I3: Balance to Submit | J3: Balance to Approve | K3: L2 Submission Plan for Current Month | L3: Progress For Month | M3: Approved till Current Month | N3: Remarks
B4: Detailed Survey | C4: kms | D4: ='Master Sheet'!D10 -> 113.286 | E4: ='Master Sheet'!E10 -> 0 | G4: 113.286 | H4: ='Master Sheet'!G10 -> 109.04 | I4: ='Master Sheet'!H10 -> 0 | J4: ='Master Sheet'!J10 -> 4.25 | K4: ='Master Sheet'!K10 -> 0 | L4: ='Master Sheet'!I10 -> 0 | M4: ='Master Sheet'!L10 -> 109.04
B5: Check Survey | C5: kms | D5: ='Master Sheet'!D11 -> 113.286 | E5: ='Master Sheet'!E11 -> 110 | G5: ='Master Sheet'!F11 -> 111.745 | H5: ='Master Sheet'!G11 -> 96.901 | I5: ='Master Sheet'!H11 -> 9.448 | J5: ='Master Sheet'!J11 -> 16.385 | K5: 20 | L5: ='Master Sheet'!I11 -> 0 | M5: ='Master Sheet'!L11 -> 96.901
B7: PROGRESS - Check Survey
B8: S.No | C8: Section | E8: Length | G8: Check survey status
B11: PROGRESS - FDN & EREC
B12: S.No | C12: Location No. | D12: Tower Type | E12: Classification | F12: ROW cleared date | G12: Start Date | H12: Conc Volume | I12: Foundation Status | M12: End Date | N12: Gang Name | O12: Erection Status | P12: Gang Strength | Q12: Remarks
B13: 1 | C13: 82/1 | D13: DA+0 | E13: WC | F13: 45848 | G13: 45849 | H13: 22.4 | I13: Foundation completed. | M13: 45891 | N13: MARC | P13: 10
B14: 2 | C14: 81/2 | D14: DA+3 | E14: DFR | F14: =G14 -> 45854 | G14: 45854 | H14: 26.43 | I14: Foundation completed. | M14: 45876 | N14: MARC | P14: 10
B15: 3 | C15: 81/1 | D15: DA+0 | E15: DFR | F15: =ROW!D6 -> 45881 | G15: 45892 | H15: 23.27 | I15: Foundation completed. | M15: 45913 | N15: MARC | P15: 10
B16: 4 | C16: 80/1 | D16: DA+6 | E16: WFR | F16: 45897 | G16: 45898 | H16: 36.66 | I16: Foundation completed. | M16: 45940 | N16: MARC | P16: 10
B17: 5 | C17: 80/5 | D17: DA+0 | E17: DRY | F17: 45898 | G17: 45902 | H17: 21.96 | I17: Foundation completed. | M17: 45918 | N17: MARC | P17: 10
B18: 6 | C18: 77/4 | D18: DA+0 | E18: DRY | F18: 45916 | G18: 45917 | H18: 21.96 | I18: Foundation Completed. | M18: 45961 | N18: BALRAJ CONSTRUCTION. | P18: 10
B19: 7 | C19: 80/4 | D19: DA+3 | E19: WFR | F19: 45919 | G19: 45923 | H19: 36.66 | I19: Foundation Completed. | M19: 45957 | N19: MARC | P19: 10
B20: 8 | C20: 59/5 | D20: DA+0 | E20: DRY | F20: 45930 | G20: 45938 | H20: 21.96 | I20: Foundation completed. | M20: 45949 | N20: SHRIARSHINI CONSTRUCTION. | P20: 10
B21: 9 | C21: 84/3 | D21: DA+0 | E21: DRY | F21: 45919 | G21: 45940 | H21: 21.96 | I21: Foundation completed. | M21: 45949 | N21: BALRAJ CONSTRUCTION. | P21: 10
B22: 10 | C22: 59/4 | D22: DA+6 | E22: DRY | F22: 45933 | G22: 45938 | H22: 25.04 | I22: Foundation completed. | M22: 45951 | N22: SHRIARSHINI CONSTRUCTION. | P22: 20
B23: 11 | C23: 84/4 | D23: DA+0 | E23: DRY | F23: 45925 | G23: 45941 | H23: 21.96 | I23: Foundation completed. | M23: 45954 | N23: BALRAJ CONSTRUCTION. | P23: 10
B24: 12 | C24: 60/2 | D24: DA+0 | E24: DFR | G24: 45944 | H24: 23.27 | I24: Foundation completed. | M24: 45955 | N24: SHRIARSHINI CONSTRUCTION | P24: 20
B25: 13 | C25: 60/3 | D25: DA+6 | E25: DRY | G25: 45953 | H25: 25.04 | I25: Foundation completed. | M25: 45976 | N25: SHRIARSHINI CONSTRUCTION | P25: 15
B26: 14 | C26: 77/10 | D26: DA+3 | E26: DRY | G26: 45957 | H26: 25.04 | I26: Foundation completed. | M26: 45966 | N26: BALRAJ CONSTRUCTION. | P26: 10
B27: 15 | C27: 58/3 | D27: DA+0 | E27: DRY | G27: 46000 | H27: 21.96 | I27: Foundation completed. | M27: 46005 | N27: SHRIARSHINI CONSTRUCTION | P27: 21
B28: 16 | C28: 84/2 | D28: DA+0 | I28: 2 Pits Excavated.
B29: 17 | C29: 59/2 | D29: DA+0 | E29: DRY | G29: 45959 | H29: 21.96 | I29: Foundation Completed. | M29: 45969 | N29: SHRIARSHINI CONSTRUCTION | P29: 15
B30: 18 | C30: 77/7 | D30: DA+0 | E30: DFR | G30: 45963 | H30: 23.27 | I30: Foundation Completed. | M30: 45970 | N30: BALRAJ CONSTRUCTION. | P30: 10
B31: 19 | C31: 77/8 | D31: DA+0 | E31: DFR | G31: 45963 | H31: 23.27 | I31: Foundation Completed. | M31: 45974 | N31: MARC | P31: 10
B32: 20 | C32: 77/1 | D32: DA+0 | E32: DRY | G32: 45968 | H32: 21.96 | I32: Foundation Completed. | M32: 45986 | N32: MARC | P32: 10
B33: 21 | C33: 77/3 | D33: DA+0 | E33: DFR | G33: 45968 | H33: 23.27 | I33: Foundation Completed. | M33: 45980 | N33: MARC | P33: 10
B34: 22 | C34: 60/8 | D34: DA+3 | E34: DFR | G34: 45973 | H34: 26.43 | I34: Foundation Completed. | M34: 45984 | N34: SHRIARSHINI CONSTRUCTION | P34: 10
B35: 23 | C35: 77/2 | D35: DA+0 | E35: DRY | G35: 45979 | H35: 21.96 | I35: Foundation Completed. | M35: 45991 | N35: MARC | P35: 10
B36: 24 | C36: 60/1 | D36: DA+0 | G36: 45983 | I36: Trial Pit Excavated.
B37: 25 | C37: 59/1 | D37: DA+0 | E37: DFR | G37: 45984 | H37: 23.27 | I37: Foundation Completed. | M37: 45990 | N37: SHRIARSHINI CONSTRUCTION | P37: 10
B38: 26 | C38: 77/6 | D38: DA+0 | E38: WC | G38: 45988 | H38: 22.4 | I38: Foundation Completed. | M38: 46003 | N38: MARC | P38: 15
B39: 27 | C39: 58/2 | D39: DA+0 | E39: DRY | G39: 45988 | H39: 21.96 | I39: Foundation Completed. | M39: 45994 | N39: SHRIARSHINI CONSTRUCTION | P39: 16
B40: 28 | C40: 58/1 | D40: DA+6 | E40: DRY | G40: 45992 | H40: 25.04 | I40: Foundation Completed. | M40: 45999 | N40: SHRIARSHINI CONSTRUCTION | P40: 16
B41: 29 | C41: 73/1 | D41: DA+6 | E41: WC | G41: 45995 | H41: 25.77 | I41: Foundation Completed. | M41: 46009 | N41: BALAJI INFRA | P41: 10
B42: 30 | C42: 73/2 | D42: DA+0 | E42: WC | G42: 45995 | H42: 22.4 | I42: Foundation Completed. | M42: 46015 | N42: BALAJI INFRA | P42: 10
B43: 31 | C43: 79/1 | D43: DA+3 | E43: WET | G43: 45997 | H43: 38.98 | I43: Foundation Completed. | M43: 46016 | N43: MARC | P43: 18
B44: 32 | C44: 94/2 | D44: DA+3 | E44: WFR | G44: 45997 | H44: 36.66 | I44: Excavation Completed. | N44: VKP TRADERS
...

Sheet Erection Compiled
A1: SL No. | B1: Location No. | C1: Tower Type | D1: Classification | F1: Starting Date | G1: Tower Weight | H1: Status | L1: Completion Date | M1: Gang Name | N1: Gang Strength | O1: Remark
A2: 1 | B2: 59/1 | C2: DA+0 | D2: DFR | F2: 46006 | G2: 36.574 | H2: Erection Completed. | L2: 46011 | M2: NASIRUDDIN | N2: 35
A3: 2 | B3: 77/3 | C3: DA+0 | D3: DFR | F3: 46013 | G3: 36.574 | H3: Erection Completed. | L3: 46022 | M3: ALI USLAM | N3: 25
A4: 3 | B4: 59/2 | C4: DA+0 | D4: DRY | F4: 46013 | G4: 36.574 | H4: Erection Completed. | L4: 46018 | M4: NASIRUDDIN | N4: 35
A5: 4 | B5: 77/2 | C5: DA+0 | D5: DRY | F5: 46016 | G5: 36.574 | H5: Erection Completed. | L5: 46030 | M5: UMA DEVI | N5: 25
A6: 5 | B6: 58/2 | C6: DA+0 | D6: DRY | F6: 46016 | G6: 36.574 | H6: Erection Completed. | L6: 46024 | M6: NASIRUDDIN | N6: 35
A7: 6 | B7: 77/1 | C7: DA+0 | D7: DRY | F7: 46023 | G7: 36.574 | H7: Bottom Section Completed. | M7: UMA DEVI | N7: 25
A8: 7 | B8: 58/1 | C8: DA+6 | D8: DRY | F8: 46024 | H8: Cage2 WIP. | M8: NASIRUDDIN | N8: 35

Sheet ROW
A1: TL-02 765kV Kurnool IV - Bidar line
A2: Foundation
A3: Sr. No. | B3: Location no. | C3: Type of tower | D3: Date of clearance
A4: 1 | B4: 82/1 | C4: DA+0 | D4: 45848
A5: =A4+1 -> 2 | B5: 81/2 | C5: DA+3 | D5: 45854
A6: =A5+1 -> 3 | B6: 81/1 | C6: DA+0 | D6: 45881
A7: =A6+1 -> 4 | B7: 83/2 | C7: DA+9 | D7: 45883
A8: =A7+1 -> 5 | B8: 84/2 | C8: DA+0 | D8: 45885
A9: =A8+1 -> 6 | B9: 80/1 | C9: DA+6 | D9: 45897
A10: =A9+1 -> 7 | B10: 80/5 | C10: DA+3 | D10: 45898
A11: =A10+1 -> 8 | B11: 77/4 | C11: DA+0 | D11: 45916
A12: =A11+1 -> 9 | B12: 84/3 | C12: DA+0 | D12: 45919
A13: =A12+1 -> 10 | B13: 84/2 | C13: DA+0 | D13: 45919
A14: =A13+1 -> 11 | B14: 80/4 | C14: DA+3 | D14: 45919
A15: 12 | B15: 84/4 | C15: DA+0 | D15: 45925
A16: 13 | B16: 59/5 | C16: DA+0 | D16: 45930
A17: 14 | B17: 60/3 | C17: DA+6 | D17: 45931
A18: 15 | B18: 59/4 | C18: DA+6 | D18: 45933
A19: 16 | B19: 60/2 | C19: DA+0

Sheet X-ing Details 
B2: CROSSINGS PROPOSAL STATUS : 765 KV D/C Kurnool IV - Bidar TL (Part-2)
B6: Crossing Type | C6: 132 KV | D6: 220kV | E6: SH-Xing | F6: NH-Xing | G6: Railway-Xing | H6: Total
B7: Total Nos | C7: 4 | D7: 2 | E7: 1 | F7: 3 | G7: 2 | H7: 12
B8: Submitted Till Date | C8: 4 | D8: 2 | E8: 0 | F8: 3 | G8: 2 | H8: =C8+D8+F8+G8 -> 11
B9: Approved Till Date | C9: 0 | D9: 0 | E9: 0 | F9: 0 | G9: 0 | H9: 0
B10: Balance to Execute | C10: =C7-C8 -> 0 | D10: =D7-D8 -> 0 | E10: =E7-E8 -> 1 | F10: =F7-F8 -> 0 | G10: =G7-G8 -> 0 | H10: 0
B12: Crossings Details
B13: Sl. No. | C13: FROM (AP) | D13: TO (AP) | E13: Name of the Line | F13: NAME OF CROSSING | G13: Date of First Submission | H13: Joint Inspection Status | I13: Provisional approval status
B14: 1 | C14: AP54 | D14: AP55 | E14: Railway crossing (Tandur - Vikarabad) | F14: Railway crossing | G14: 45987
B15: =B14+1 -> 2 | C15: AP57 | D15: AP58 | E15: 220kV D/C transmission line Tandur - Gachibowli (HYD) | F15: Power line | G15: 45946
B16: =B15+1 -> 3 | C16: AP61 | D16: AP62 | E16: NATIONAL HIGHWAY-163 (Kodangal - Hyderabad) | F16: National highway crossing | G16: 45989
B17: =B16+1 -> 4 | C17: AP71 | D17: AP72 | E17: 132kV D/C transmission line Tandur - Mahabubnagar | F17: Power line | G17: 45944
B18: =B17+1 -> 5 | C18: AP74 | D18: AP75 | E18: NATIONAL HIGHWAY-167N (Kodangal - Kosgi) | F18: National highway crossing | G18: 45989
B19: =B18+1 -> 6 | C19: AP76 | D19: AP77 | E19: 220kV D/C transmission line Kosgi - Pargi | F19: Power line | G19: 45946
B20: =B19+1 -> 7 | C20: AP88 | D20: AP89 | E20: 132kV S/C transmission line Maddur - Mahabubnagar | F20: Power line | G20: 45946
B21: =B20+1 -> 8 | C21: AP95 | D21: AP96 | E21: 132kV S/C transmission line Maddur - Makthal | F21: Power line | G21: 45946
B22: =B21+1 -> 9 | C22: AP98 | D22: AP99 | E22: STATE HIGHWAY-22 (Narayanpet - Marikal) | F22: State highway crossing
B23: =B22+1 -> 10 | C23: AP106 | D23: AP107 | E23: Railway crossing (Raichur - Makthal) | F23: Railway crossing | G23: 45988
B24: =B23+1 -> 11 | C24: AP109 | D24: AP110 | E24: 132kV S/C transmission line Makthal - Krishna Railway junction | F24: Power line | G24: 08.12.2025
B25: =B24+1 -> 12 | C25: AP110 | D25: AP111 | E25: NATIONAL HIGHWAY-167N (Raichur - Marikal) | F25: National highway crossing | G25: 08.12.2025

Sheet SuPPLY 
B1: Supply Status - Stubs & Towers
B2: Stub Details
B3: SL No | C3: Description | D3: Unit | E3: Line Qty | F3: Received | G3: Balance
B4: 1 | C4: 3DA Stub | D4: Set | F4: 120
B5: 2 | C5: 3DB Stub | D5: Set | F5: 5
B6: 3 | C6: 3DC Stub | D6: Set | F6: 3
B7: 4 | C7: 3D45 Stub | D7: Set | F7: 2
B8: 5 | C8: 3D60 Stub | D8: Set | F8: 2
C9: Total | D9: Set | E9: =SUM(E4:E8) -> 0 | F9: =SUM(F4:F8) -> 132 | G9: =SUM(G4:G8) -> 0 | H9: =SUM(H4:H8) -> 0 | I9: =SUM(I4:I8) -> 0
B11: Tower Details
B12: SL No | C12: Tower Type | D12: Description | E12: Line Qty | F12: Received | G12: Balance | J12: Remarks
B13: 1 | C13: 3DA Type | D13: Basic body | F13: 126
D14: +0m BE | F14: 104
D15: +3m BE | F15: 22
D16: +6m BE | F16: 13
D17: +9m BE | F17: 5
B18: 2 | C18: 3DB Type | D18: Basic body | F18: 20
D19: +0m BE | F19: 20
D20: +3m BE
D21: +6m BE
D22: +9m BE | F22: 5
B23: 3 | C23: 3DC Type | D23: Basic body | F23: 14
D24: +0m BE | F24: 11
D25: +3m BE | F25: 3
D26: +6m BE
D27: +9m BE | F27: 3
B28: 4 | C28: 3DD45 Type | D28: Basic body | K28: Balance after June'25
D29: +0m BE
D30: +3m BE
D31: +6m BE
D32: +9m BE
B33: 5 | C33: 3DD60 Type | D33: Basic body
D34: +0m BE
D35: +3m BE
D36: +6m BE
D37: +9m BE
D39: Total
B44: Activity | C44: Unit | D44: Final Est. Qty | E44: L2 till Last Month | F44: Received till Last Month | G44: Balance | H44: L2 Plan for Current Month | I44: Plan for Current Month | J44: Progress for the Month | K44: Received till Current Month | L44: Gap between Suppy & Cumm.L2 | M44: Remarks
B45: Stub | C45: Set | D45: 292 | E45: 260 | F45: 132 | G45: =D45-F45 -> 160 | H45: ='Master Sheet'!H31 -> 56 | I45: ='Master Sheet'!I31 -> 0 | J45: ='Master Sheet'!J31 -> 0 | K45: =J45+F45 -> 132 | L45: =E45+H45-(F45+J45) -> 184
B46: Tower | C46: No's | D46: 292 | E46: 160 | F46: 160 | G46: =D46-F46 -> 132 | H46: ='Master Sheet'!H32 -> 0 | I46: 0 | J46: 0 | K46: =146+14 -> 160 | L46: =E46+H46-(F46+J46) -> 0
...

Sheet Visual Chart
A1: VISUAL PROGRESS CHART
A2: 765 kV DC Kurnool IV - Bidar Transmission Line (TL-02)
B3: Foundation (Nos.):- | D3: 46 | E3: / 292 | F3: Erection (Nos.):- | H3: 5 | I3: /292 | J3: Earthing (Nos.):- | M3: 15/292 | N3: Rough Sag (Kms):- | P3: 0 / | Q3: 113.292 | R3: Final Sag (Kms):- | T3: 0 / | U3: 113.292 | V3: Date:- | W3: =TODAY() -> 46035
B4: COMPLETION CHART | C4: Unit | E4: +3 | F4: +6 | G4: +9 | H4: 18 | I4: Line Qty
J5: ERECTION | P5: Rough Sag | R5: SH / NH Road Crossing
J6: WIP | V6: River
B7: DA | C7: Nos | D7: 136 | E7: 47 | F7: 21 | G7: 12 | H7: =SUM(D7:G7) -> 216 | I7: =H7 -> 216 | J7: FOUNDATION | K7: Type | M7: Angle Tower | R7: Gas Pipeline
B8: DB1 | C8: Nos | D8: 8 | E8: 2 | F8: 1 | G8: 9 | H8: =SUM(D8:G8) -> 20 | I8: =H8 -> 20
B9: DB2 | C9: Nos | D9: 11 | E9: 2 | F9: 4 | G9: 1 | H9: =SUM(D9:G9) -> 18 | I9: =H9 -> 18 | O9: Final Sag
B10: DC1 | C10: Nos | D10: 10 | E10: 2 | F10: 1 | G10: 4 | H10: =SUM(D10:G10) -> 17 | I10: =H10 -> 17
B11: DC2 | C11: Nos | D11: 3 | E11: 3 | F11: 1 | G11: 0 | H11: =SUM(D11:G11) -> 7 | I11: =H11 -> 7 | S11: Railway
B12: DCT | C12: Nos | D12: 0 | E12: 0 | F12: 0 | G12: 0 | H12: =SUM(D12:G12) -> 0 | I12: =H12 -> 0 | Q12: WIP | S12: Crossing
B13: DD45 | C13: Nos | D13: 3 | E13: 1 | F13: 1 | G13: 4 | H13: =SUM(D13:G13) -> 9 | I13: =H13 -> 9 | J13: Section Tower | K13: SC | V13: 110-800 KV
B14: DD60 | C14: Nos | D14: 2 | E14: 2 | F14: 0 | G14: 1 | H14: =SUM(D14:G14) -> 5 | I14: =H14 -> 5 | J14: TP | K14: TT | M14: Earthing | P14: OPGW | V14: Line
B15: Total Completed Foundations | H15: 46 | I15: =292-H15 -> 246
B16: Wind Zone - 3 [AP48 - AP111] | F16: AP48 to AP77 : VIKRABAD DISTRICT
E17: AP77 to AP111 : NARAYANPET DISTRICT
B18: COMMON POINT
C21: 411 | E21: 432 | G21: 411 | I21: 432 | K21: 411 | M21: 432 | O21: 411 | Q21: 374.437 | S21: 376.003 | U21: 405 | V21: RC | W21: 340 | Y21: 397
B23: AP48/0 | D23: 48/1 | F23: 48/2 | H23: 48/3 | J23: 48/4 | L23: 48/5 | N23: 48/6 | P23: 48/7 | R23: AP49/0 | T23: 49/1 | V23: 49/2 | X23: 49/3
B24: DB1+0 | D24: 3DA+6 | F24: 3DA+0 | H24: 3DA+6 | J24: 3DA+3 | L24: 3DA+3 | N24: 3DA+3 | P24: 3DA+3 | R24: 3DC1+0 | T24: 3DA+0 | V24: 3DA+0 | X24: 3DA+0
B25: 3.314 | Y25: 4.832
C28: 399 | D28: RC | E28: 393 | F28: RC | G28: 370 | H28: RC | I28: 350 | J28: RC | K28: 395 | M28: 413 | N28: RC | O28: 366 | Q28: 377.77 | S28: 300 | U28: 393 | W28: 415 | Y28: 411
B30: 49/4 | D30: 49/5 | F30: 49/6 | H30: 49/7 | J30: 49/8 | L30: 49/9 | N30: 49/10 | P30: 49/11 | R30: AP50/0 | T30: 50/1 | V30: 50/2 | X30: 50/3
B31: 3DA+0 | D31: 3DA+3 | F31: 3DA+0 | H31: 3DA+0 | J31: 3DA+0 | L31: 3DA+0 | N31: 3DA+0 | P31: 3DA+0 | R31: 3DC2+0 | T31: 3DA+0 | V31: 3DA+0 | X31: 3DA+3
B32: 4.582 | R32: 1.519 | Y32: 4.583
C35: 378 | E35: 370 | G35: 370 | I35: 404 | K35: 374 | M35: 416 | N35: RC | O35: 425 | P35: RC | Q35: 411 | R35: RC | S35: 427 | U35: 370 | V35: RC | W35: 356 | Y35: 459
B37: AP51/0 | D37: 51/1 | F37: 51/2 | H37: 51/3 | J37: 51/4 | L37: 51/5 | N37: 51/6 | P37: 51/7 | R37: 51/8 | T37: 51/9 | V37: 51/10 | X37: AP52/0
B38: 3DC2+0 | D38: 3DA+3 | F38: 3DA+0 | H38: 3DA+0 | J38: 3DA+0 | L38: 3DA+0 | N38: 3DA+3 | P38: 3DA+3 | R38: 3DA+0 | T38: 3DA+3 | V38: 3DA+0 | X38: 3DB2+0
B39: 4.301 | Y39: 4.76
B42: RC | C42: 355 | D42: RC | E42: 348 | G42: 434 | H42: RC | I42: 401 | K42: 400 | M42: 413 | O42: 406 | P42: RC | Q42: 390 | S42: 390 | T42: RC | U42: 430 | V42: RC | W42: 332 | Y42: 229.642
B44: 52/1 | D44: 52/2 | F44: 52/3 | H44: 52/4 | J44: AP53/0 | L44: 53/1 | N44: 53/2 | P44: 53/3 | R44: 53/4 | T44: 53/5 | V44: 53/6 | X44: AP54/0
B45: 3DA+9 | D45: 3DA+0 | F45: 3DA+0 | H45: 3DA+0 | J45: 3DB1+3 | L45: 3DA+3 | N45: 3DA+0 | P45: 3DA+3 | R45: 3DA+0 | T45: 3DA+0 | V45: 3DA+3 | X45: 3DD60+0
B46: 1.997 | J46: 2.761 | X46: 0.23 | Y46: 4.529
C49: 339 | E49: 365 | G49: 409 | H49: SRIARSHINI | I49: 340.462 | J49: RC | K49: 352 | L49: SRIARSHINI | M49: 419 | N49: SRIARSHINI | O49: 410 | P49: SRIARSHINI | Q49: 413 | R49: SRIARSHINI | S49: 407 | T49: RC | U49: 351 | W49: 405 | X49: SRIARSHINI | Y49: 393
B51: AP55/0 | D51: 55/1 | F51: 55/2 | H51: 55/3 | J51: AP56/0 | L51: 56/1 | N51: 56/2 | P51: 56/3 | R51: 56/4 | T51: 56/5 | V51: 56/6 | X51: 56/7
B52: 3DD60+0 | D52: 3DA+0 | F52: 3DA+0 | H52: 3DA+0 | J52: 3DB2+0 | L52: 3DA+3 | N52: 3DA+3 | P52: 3DA+0 | R52: 3DA+3 | T52: 3DA+3 | V52: 3DA+0 | W52: =(K49+M49+O49+Q49+S49+U49+W49)/1000 -> 2.757 | X52: 3DB1+0
B53: 1.453 | Y53: 4.603
C56: 439 | D56: SRIARSHINI | E56: 398 | F56: RC | G56: 445 | H56: RC | I56: 355 | K56: 445.645 | L56: RC | M56: 214.742 | O56: 498 | P56: SRIARSHINI | Q56: 325 | R56: SRIARSHINI | S56: 372 | T56: SRIARSHINI | U56: 393.054 | V56: SRIARSHINI | W56: 349 | X56: SRIARSHINI | Y56: 373
B58: 56/8 | D58: 56/9 | F58: 56/10 | H58: 56/11 | J58: 56/12 | L58: AP57/0 | N58: AP58/0 | P58: 58/1 | R58: 58/2 | T58: 58/3 | V58: AP59/0 | X58: 59/1
...
