Workbook
Name __________________________b111121: #REF!
Name __________________________b111121: #REF!
Name _________________________b111121: #REF!
Name _________________________b111121: #REF!
Name ________________________b111121: #REF!
Name ________________________b111121: #REF!
Name _______________________b111121: #REF!
Name _______________________b111121: #REF!
Name ______________________b111121: #REF!
Name ______________________b111121: #REF!
Name ______________________TAB1: #REF!
Name _____________________b111121: #REF!
Name _____________________b111121: #REF!
Name _____________________TAB1: #REF!
Name ____________________b111121: #REF!
Name ____________________b111121: #REF!
Name ____________________KEY3: #REF!
Name ____________________KEY3: #REF!
Name ____________________TAB1: #REF!
Name ___________________b111121: #REF!
Name ___________________b111121: #REF!
Name ___________________KEY3: #REF!
Name ___________________KEY3: #REF!
Name ___________________TAB1: #REF!
Name __________________b111121: #REF!
Name __________________b111121: #REF!
Name __________________KEY3: #REF!
Name __________________KEY3: #REF!
Name __________________TAB1: #REF!
Name _________________b111121: #REF!
Name _________________b111121: #REF!
Name _________________KEY3: #REF!
Name _________________KEY3: #REF!
Name _________________TAB1: #REF!
Name ________________b111121: #REF!
Name ________________b111121: #REF!
Name ________________KEY3: #REF!
Name ________________KEY3: #REF!
Name ________________TAB1: #REF!
Name _______________b111121: #REF!
Name _______________b111121: #REF!
Name _______________KEY3: #REF!
Name _______________KEY3: #REF!
Name _______________TAB1: #REF!
Name ______________b111121: #REF!
Name ______________b111121: #REF!
Name ______________TAB1: #REF!
Name _____________A65537: #REF!
Name _____________A65537: #REF!
Name _____________b111121: #REF!
Name _____________b111121: #REF!
Name _____________TAB1: #REF!
Name ____________A655600: #REF!
Name ____________A655600: #REF!
Name ____________b111121: #REF!
Name ____________b111121: #REF!
Name ____________KEY3: #REF!
Name ____________KEY3: #REF!
Name ____________TAB1: #REF!
Name ___________A65537: #REF!

Sheet Visual Chart 
B1: VISUAL PROGRESS CHART
B2: TL-02 765 KV D/C Kurnool IV - Bidar Transmission Line
B3: Foundation (Nos.):- | D3: =H15 -> 0 | E3: / 297 | F3: Erection (Nos.):- | I3: / 297 | J3: Earthing (Nos.):- | M3: / 297 | N3: Rough Sag (Kms):- | Q3: 113.292 | R3: Final Sag (Kms):- | U3: 113.292 | V3: Date:- | W3: ='Master Sheet'!H2 -> 46244
B4: COMPLETION CHART | C4: -3 | D4: +0 | E4: +3 | F4: +6 | G4: +9 | H4: Total | I4: Line Qty
J5: ERECTION | P5: Rough Sag | R5: SH / NH Road Crossing
J6: WIP | V6: River
B7: DA | H7: =SUM(C7:G7) -> 0 | K7: Type | M7: Angle Tower | R7: Gas Pipeline
B8: DB1 | H8: =SUM(C8:G8) -> 0 | J8: FOUNDATION
B9: DB2 | H9: =SUM(C9:G9) -> 0 | O9: Final Sag
B10: DC1 | H10: =SUM(C10:G10) -> 0
B11: DC2 | H11: =SUM(C11:G11) -> 0 | S11: Railway
B12: DCT | H12: =SUM(C12:G12) -> 0 | Q12: WIP
B13: DD45 | H13: =SUM(C13:G13) -> 0 | J13: Section Tower | K13: SC | S13: Crossing | V13: 110-800 KV
B14: DD60 | H14: =SUM(C14:G14) -> 0 | J14: TP | K14: TT | M14: Earthing | P14: OPGW | V14: Line
B15: Total Completed Foundations | H15: =SUM(H7:H14) -> 0 | I15: =SUM(I7:I14) -> 0
AB16: 110kv OHTL
AA18: SH -122
C19: 411 | E19: 432 | G19: 408 | I19: 433 | K19: 409 | M19: 432 | O19: 375 | Q19: 414 | S19: 403 | U19: 406 | W19: 319 | Y19: 384
B21: 48/0 | D21: 48/1 | F21: 48/2 | H21: 48/3 | J21: 48/4 | L21: 48/5 | N21: 48/6 | P21: 48/7 | R21: 49/0 | T21: 49/1 | V21: 49/2 | X21: 49/3
B22: 3DB1+0 | D22: 3DA+6 | F22: 3DA+0 | H22: 3DA+6 | J22: 3DA+3 | L22: 3DA+3 | N22: 3DA+3 | P22: 3DA+6 | R22: 3DC1+3 | T22: 3DA+0 | V22: 3DA+0 | X22: 3DA+0
C25: 385 | E25: 409 | G25: 369 | I25: 350 | K25: 395 | M25: 412 | O25: 366 | Q25: 383 | S25: 300 | U25: 393 | W25: 414 | Y25: 412
B27: 49/4 | D27: 49/5 | F27: 49/6 | H27: 49/7 | J27: 49/8 | L27: 49/9 | N27: 49/10 | P27: 49/11 | R27: 50/0 | T27: 50/1 | V27: 50/2 | X27: 50/3
B28: 3DA+0 | D28: 3DA+6 | F28: 3DA+0 | H28: 3DA+0 | J28: 3DA+0 | L28: 3DA+0 | N28: 3DA+0 | P28: 3DA+0 | R28: 3DC2+0 | T28: 3DA+0 | V28: 3DA+0 | X28: 3DA+3
C32: 377 | E32: 369 | G32: 369 | I32: 403 | K32: 374 | M32: 416 | O32: 424 | Q32: 401 | S32: 437 | U32: 369 | W32: 361 | Y32: 458
B34: 51/0 | D34: 51/1 | F34: 51/2 | H34: 51/3 | J34: 51/4 | L34: 51/5 | N34: 51/6 | P34: 51/7 | R34: 51/8 | T34: 51/9 | V34: 51/10 | X34: 52/0
B35: 3DC2+0 | D35: 3DA+3 | F35: 3DA+0 | H35: 3DA+0 | J35: 3DA+0 | L35: 3DA+0 | N35: 3DA+3 | P35: 3DA+3 | R35: 3DA+3 | T35: 3DA+3 | V35: 3DA+0 | X35: 3DB2+0
X36: RWY Xing | Y36: TDR-VBD
C39: 355 | E39: 347 | G39: 430 | I39: 408 | K39: 402 | M39: 411 | O39: 397 | Q39: 404 | S39: 398 | U39: 430 | W39: 320 | Y39: 230
B41: 52/1 | D41: 52/2 | F41: 52/3 | H41: 52/4 | J41: 53/0 | L41: 53/1 | N41: 53/2 | P41: 53/3 | R41: 53/4 | T41: 53/5 | V41: 53/6 | X41: 54/0
B42: 3DA+9 | D42: 3DA+0 | F42: 3DA+0 | H42: 3DA+0 | J42: 3DB2+3 | L42: 3DA+3 | N42: 3DA+0 | P42: 3DA+3 | R42: 3DA+3 | T42: 3DA+0 | V42: 3DA+3 | X42: 3DD60+0
C46: 339 | E46: 365 | G46: 409 | I46: 343 | K46: 352 | M46: 419 | O46: 410 | Q46: 413 | S46: 407 | U46: 352 | W46: 405 | Y46: 393
B48: 55/0 | D48: 55/1 | F48: 55/2 | H48: 55/3 | J48: 56/0 | L48: 56/1 | N48: 56/2 | P48: 56/3 | R48: 56/4 | T48: 56/5 | V48: 56/6 | X48: 56/7
B49: 3DD60+0 | D49: 3DA+0 | F49: 3DA+0 | H49: 3DA+0 | J49: 3DC1+0 | L49: 3DA+3 | N49: 3DA+3 | P49: 3DA+0 | R49: 3DA+3 | T49: 3DA+3 | V49: 3DA+0 | X49: 3DA+0
M50: 220KV D/C OHTL
M51: TDR-GBL
C53: 439 | E53: 398 | G53: 445 | I53: 355 | K53: 447 | M53: 215 | O53: 498 | Q53: 325 | S53: 388 | U53: 381 | W53: 349 | Y53: 373
B55: 56/8 | D55: 56/9 | F55: 56/10 | H55: 56/11 | J55: 56/12 | L55: 57/0 | N55: 58/0 | P55: 58/1 | R55: 58/2 | T55: 58/3 | V55: 59/0 | X55: 59/1
B56: 3DA+0 | D56: 3DA+6 | F56: 3DA+0 | H56: 3DA+0 | J56: 3DA+0 | L56: 3DC1+9 | N56: 3DB2+6 | P56: 3DA+6 | R56: 3DA+0 | T56: 3DA+3 | X56: 3DA+0
C60: 386 | E60: 429 | G60: 377 | I60: 405 | K60: 425 | M60: 344 | O60: 399 | Q60: 439 | S60: 403 | U60: 480 | W60: 535 | Y60: 389
B62: 59/2 | D62: 59/3 | F62: 59/4 | H62: 59/5 | J62: 60/0 | L62: 60/1 | N62: 60/2 | P62: 60/3 | R62: 60/4 | T62: 60/5 | V62: 60/6 | X62: 60/7
...

Sheet Master Sheet
C2: Project Code | D2: TA-601 | G2: Date as on | H2: 46244 | I2: SBU Head | J2: Mr. Rajinder Gupta
C3: Project Name | D3: 765kV D/C Kurnool IV - Bidar trnasmission line (Part II) | G3: LOA Start Date | H3: 13.05.2025 | I3: PCH | J3: Mr. Arun Felbin R
C4: Client Name | D4: POWERGRID KURNOOL IV TRANSMISSION LIMITED | G4: LOA End Date | H4: 12.04.2027 | I4: Regional Manager | J4: Mr. Ajith Kumar MG
C5: Duration | D5: 23 Months | G5: Planning Engineer | H5: Mr. Siddhesh Bhoyar | I5: Chief Manger | J5: Mr. Senthil Jayaraman
B8: Survey Status
B9: Activity | C9: Unit | D9: Final Est. Qty | E9: L2 till Last Month | F9: Completed till Last Month | G9: Approved till Last Month | H9: Balance to Submit | I9: Plan for Current Month | J9: Balance to Approve | K9: L2 Submission Plan for Current Month | L9: Approved till Current Month | M9: Remarks
B10: Detailed Survey | C10: kms | D10: 113.286 | E10: 113.286 | F10: 113.286 | G10: 113.286 | H10: 0 | I10: 0 | J10: 0 | K10: 0 | L10: 113.286 | N10: `
B11: Check Survey | C11: kms | D11: 113.286 | E11: 113.286 | F11: 113.286 | G11: 112.888 | H11: =E11-F11 -> 0 | I11: 0.398 | J11: =I11 -> 0.398 | K11: 0 | L11: =G11 -> 112.888
B14: Foundation Status
B15: Activity | C15: Scope Quantity | D15: Cumulative L2 till Last Month | E15: Cumulative Progress till Last Month | F15: L2 for present Month | G15: Plan for the Month | H15: Today's Progress | I15: Progress for Current Month | J15: L2 till Current Month | K15: Completed till Date | L15: Balance Work | M15: Under Progress | N15: Gangs at Present | O15: Remarks
B16: Foundation | C16: 292 | D16: 297 | E16: 180 | F16: 9 | G16: 30 | H16: 0 | I16: 7 | J16: 306 | K16: =E16+I16 -> 187 | L16: =292-K16 -> 105 | M16: 12 | N16: 7
B17: Earthing | C17: 292 | D17: 297 | E17: 131 | F17: 9 | G17: 30 | H17: 0 | I17: 0 | J17: =J16 -> 306 | K17: =E17+I17 -> 131 | L17: =C17-K17 -> 161
B18: Tower Erection | C18: 292 | D18: 250 | E18: 118 | F18: 10 | G18: 25 | H18: 1 | I18: 7 | J18: 260 | K18: =E18+I18 -> 125 | L18: =C18-K18 -> 167 | M18: 8 | N18: 7
B19: Stringing -R/S | C19: 113.286 | D19: 36 | E19: 0 | F19: 2 | G19: 3.469 | H19: 0 | I19: 0 | J19: 38 | K19: =E19+I19 -> 0 | L19: =C19-K19 -> 113.286
B20: Stringing -F/S | C20: 113.286 | D20: 36 | E20: 0 | F20: 2 | G20: 3.469 | H20: 0 | I20: 0 | J20: 38 | K20: =E20+I20 -> 0 | L20: =C20-K20 -> 113.286
B21: OPGW | C21: 113.286 | D21: 36 | E21: 0 | F21: 2 | G21: 0 | H21: 0 | I21: 0 | J21: 38 | K21: =E21+I21 -> 0 | L21: =C21-K21 -> 113.286
B22: NH Crossing | C22: 3 | L22: =C22-K22 -> 3
B23: SH Crossing | C23: 1 | L23: =C23-K23 -> 1
B24: Railway crossing | C24: 2 | L24: =C24-K24 -> 2
B25: Power Line Crossing | C25: 6 | L25: =C25-K25 -> 6
B27: WIP - Foundations | C27: Pit A | D27: Pit B | E27: Pit C | F27: Pit D | G27: Gang | K27: WIP-Erection | L27: Type | M27: Status | N27: Gang
B28: 49/5 | C28: RCC (F&B) Completed | D28: RCC (F&B) Completed | E28: RCC (F&B) Completed | F28: Steel Binding WIP | G28: AMMU ENGG | K28: 54/0 | L28: DD60+0 | M28: Top Section WIP | N28: NASIRUDDIN-02
B29: 49/7 | C29: Block Level Completed | D29: Block Level Completed | E29: Block Level Completed | F29: Block Level Completed | G29: AMMU ENGG | K29: 49/0 | L29: DC1+0 | M29: Completed | N29: Tofit MIA-02
B30: 55/0 | C30: RCC (F&B) Completed | D30: RCC (F&B) Completed | E30: Block Level Completed | F30: PCC Completed | G30: Shriharshini | K30: 58/0 | L30: DB2+6 | M30: Bottom Section WIP | N30: NASIRUDDIN-01
B31: 60/7 | C31: Pit Marking Completed | D31: Pit Marking Completed | E31: Pit Marking Completed | F31: Pit Marking Completed | G31: VEER TEJA | K31: 71/0 | L31: DC2+6 | M31: 3rd Section WIP | N31: MASIDUR
B32: 63/0 | C32: Excavation WIP | D32: Excavation WIP | E32: Excavation WIP | F32: Excavation WIP | G32: D Govind Raj | K32: 49/4 | L32: DA+0 | M32: 3rd Section WIP | N32: Tofit MIA-01
B33: 80/3 | C33: Excavation WIP | D33: Excavation WIP | E33: RCC Chimney Completed | F33: RCC Chimney Completed | G33: ATK-02 | H33: ` | K33: 96/7 | L33: DA+0 | M33: 1st Section WIP | N33: SHAKILA KHATUN
B34: 85/0 | C34: RCC Chimney Completed | D34: RCC Chimney Completed | E34: Block Level Completed | F34: RCC Chimney Completed | G34: ATK-02 | K34: 101/4 | L34: DA+0 | M34: Material Supply WIP | N34: ANARUL HOQUE
B35: 83/2 | C35: RCC (F&B) Completed | D35: RCC (F&B) Completed | E35: PCC Completed | F35: PCC Completed | G35: ATK-02 | K35: 48/7 | L35: DA+3 | M35: Material Supply WIP | N35: Tofit MIA-02
B36: 96/3 | C36: Excavated | D36: Excavated | E36: Excavated | F36: Excavated | G36: ATK-01
B37: 96/6 | C37: PCC Completed | D37: PCC Completed | E37: PCC Completed | F37: RCC (F&B) Completed | G37: ATK-01
B40: Supply Status
B41: Activity | C41: Unit | D41: Final Est. Qty | E41: L2 till Last Month | F41: Received till Last Month | G41: Balance | H41: L2 Plan for Current Month | I41: Plan for Current Month | J41: Progress for the Month | K41: Received till Current Month | L41: Gap between Supply & Cumm.L2 | M41: Remarks
B42: Stub | C42: Set | D42: 292 | E42: 316 | F42: 277 | G42: =D42-F42 -> 15 | H42: 0 | I42: =G42 -> 15 | J42: 0 | K42: =F42+J42 -> 277 | L42: =E42+H42-K42 -> 39
B43: Tower | C43: No's | D43: 292 | E43: 316 | F43: 284 | G43: =D43-F43 -> 8 | H43: 0 | I43: 8 | J43: 0 | K43: =F43+J43 -> 284 | L43: =E43+H43-K43 -> 32
B44: AL59 Conductor | C44: kms | D44: 4118 | E44: 3800 | F44: 4109.057 | G44: =D44-F44 -> 8.943 | H44: 514 | I44: =G44 -> 8.943 | J44: 0 | K44: =F44 -> 4109.057 | L44: =E44+H44-K44 -> 204.943 | M44: 1379 DRUMS RECEIVED
B46: Support Required :
B47: 1) RC Foundation Drawings Required- DC Extension,DD45

Sheet Progress Sheet 
B2: Survey Status
B3: Activity | C3: Unit | D3: Final Est. Qty | E3: L2 till Last Month | G3: Completed till Last Month | H3: Approved till Last Month | I3: Balance to Submit | J3: Balance to Approve | K3: L2 Submission Plan for Current Month | L3: Progress For Month | M3: Approved till Current Month | N3: Remarks
B4: Detailed Survey | C4: kms | D4: ='Master Sheet'!D10 -> 113.286 | E4: ='Master Sheet'!E10 -> 113.286 | G4: 113.286 | H4: ='Master Sheet'!G10 -> 113.286 | I4: ='Master Sheet'!H10 -> 0 | J4: ='Master Sheet'!J10 -> 0 | K4: ='Master Sheet'!K10 -> 0 | L4: ='Master Sheet'!I10 -> 0 | M4: ='Master Sheet'!L10 -> 113.286
B5: Check Survey | C5: kms | D5: ='Master Sheet'!D11 -> 113.286 | E5: ='Master Sheet'!E11 -> 113.286 | G5: ='Master Sheet'!F11 -> 113.286 | H5: ='Master Sheet'!G11 -> 112.888 | I5: ='Master Sheet'!H11 -> 0 | J5: ='Master Sheet'!J11 -> 0.398 | K5: 20 | L5: ='Master Sheet'!I11 -> 0.398 | M5: ='Master Sheet'!L11 -> 112.888
B7: PROGRESS - Check Survey
B8: S.No | C8: Section | E8: Length | G8: Check survey status
L10: =COUNTIFS($I$13:$L$199,"Foundation Completed.") -> 187
B11: PROGRESS - FDN & EREC
B12: S.No | C12: Location No. | D12: Tower Type | E12: Classification | F12: ROW cleared date | G12: Start Date | H12: Conc Volume | I12: Foundation Status | M12: End Date | N12: Gang Name | O12: Erection Status | P12: Gang Strength
B13: 1 | C13: 81/2 | D13: DA+3 | E13: DFR | F13: =G13 -> 45854 | G13: 45854 | H13: 26.43 | I13: Foundation completed. | M13: 45876 | N13: MARC | P13: 10
B14: =B13+1 -> 2 | C14: 82/1 | D14: DA+0 | E14: WC | F14: 45848 | G14: 45849 | H14: 22.4 | I14: Foundation completed. | M14: 45891 | N14: MARC | P14: 10
B15: =B14+1 -> 3 | C15: 81/1 | D15: DA+0 | E15: DFR | F15: =#REF! -> #REF! | G15: 45892 | H15: 23.27 | I15: Foundation completed. | M15: 45913 | N15: MARC | P15: 10
B16: =B15+1 -> 4 | C16: 80/5 | D16: DA+0 | E16: DRY | F16: 45898 | G16: 45902 | H16: 21.96 | I16: Foundation completed. | M16: 45918 | N16: MARC | P16: 10
B17: =B16+1 -> 5 | C17: 80/1 | D17: DA+6 | E17: WFR | F17: 45897 | G17: 45898 | H17: 36.66 | I17: Foundation completed. | M17: 45940 | N17: MARC | P17: 10
B18: =B17+1 -> 6 | C18: 59/5 | D18: DA+0 | E18: DRY | F18: 45930 | G18: 45938 | H18: 21.96 | I18: Foundation completed. | M18: 45949 | N18: SHRIARSHINI | P18: 10
B19: =B18+1 -> 7 | C19: 84/3 | D19: DA+0 | E19: DRY | F19: 45919 | G19: 45940 | H19: 21.96 | I19: Foundation completed. | M19: 45949 | N19: SHIVRATHIRI BALRAJ | P19: 10
B20: =B19+1 -> 8 | C20: 59/4 | D20: DA+6 | E20: DRY | F20: 45933 | G20: 45938 | H20: 25.04 | I20: Foundation completed. | M20: 45951 | N20: SHRIARSHINI | P20: 20
B21: =B20+1 -> 9 | C21: 84/4 | D21: DA+0 | E21: DRY | F21: 45925 | G21: 45941 | H21: 21.96 | I21: Foundation completed. | M21: 45954 | N21: SHIVRATHIRI BALRAJ | P21: 10
B22: =B21+1 -> 10 | C22: 60/2 | D22: DA+0 | E22: DFR | G22: 45944 | H22: 23.27 | I22: Foundation completed. | M22: 45955 | N22: SHRIARSHINI | P22: 20
B23: =B22+1 -> 11 | C23: 80/4 | D23: DA+3 | E23: WFR | F23: 45919 | G23: 45923 | H23: 36.66 | I23: Foundation completed. | M23: 45957 | N23: MARC | P23: 10
B24: =B23+1 -> 12 | C24: 77/4 | D24: DA+0 | E24: DRY | F24: 45916 | G24: 45917 | H24: 21.96 | I24: Foundation completed. | M24: 45961 | N24: SHIVRATHIRI BALRAJ | P24: 10
B25: =B24+1 -> 13 | C25: 77/10 | D25: DA+3 | E25: DRY | G25: 45957 | H25: 25.04 | I25: Foundation completed. | M25: 45966 | N25: SHIVRATHIRI BALRAJ | P25: 10
B26: =B25+1 -> 14 | C26: 59/2 | D26: DA+0 | E26: DRY | G26: 45959 | H26: 21.96 | I26: Foundation completed. | M26: 45969 | N26: SHRIARSHINI | P26: 15
B27: =B26+1 -> 15 | C27: 77/7 | D27: DA+0 | E27: DFR | G27: 45963 | H27: 23.27 | I27: Foundation completed. | M27: 45970 | N27: SHIVRATHIRI BALRAJ | P27: 10
B28: =B27+1 -> 16 | C28: 77/8 | D28: DA+0 | E28: DFR | G28: 45963 | H28: 23.27 | I28: Foundation completed. | M28: 45974 | N28: MARC | P28: 10
B29: =B28+1 -> 17 | C29: 60/3 | D29: DA+6 | E29: DRY | G29: 45953 | H29: 25.04 | I29: Foundation completed. | M29: 45976 | N29: SHRIARSHINI | P29: 15
B30: =B29+1 -> 18 | C30: 77/3 | D30: DA+0 | E30: DFR | G30: 45968 | H30: 23.27 | I30: Foundation completed. | M30: 45980 | N30: MARC | P30: 10
B31: =B30+1 -> 19 | C31: 60/8 | D31: DA+3 | E31: DFR | G31: 45973 | H31: 26.43 | I31: Foundation completed. | M31: 45984 | N31: SHRIARSHINI | P31: 10
B32: =B31+1 -> 20 | C32: 77/1 | D32: DA+0 | E32: DRY | G32: 45968 | H32: 21.96 | I32: Foundation completed. | M32: 45986 | N32: MARC | P32: 10
B33: =B32+1 -> 21 | C33: 59/1 | D33: DA+0 | E33: DFR | G33: 45984 | H33: 23.27 | I33: Foundation completed. | M33: 45990 | N33: SHRIARSHINI | P33: 10
B34: =B33+1 -> 22 | C34: 77/2 | D34: DA+0 | E34: DRY | G34: 45979 | H34: 21.96 | I34: Foundation completed. | M34: 45991 | N34: MARC | P34: 10
B35: =B34+1 -> 23 | C35: 58/2 | D35: DA+0 | E35: DRY | G35: 45988 | H35: 21.96 | I35: Foundation completed. | M35: 45994 | N35: SHRIARSHINI | P35: 16
B36: =B35+1 -> 24 | C36: 58/1 | D36: DA+6 | E36: DRY | G36: 45992 | H36: 25.04 | I36: Foundation completed. | M36: 45999 | N36: SHRIARSHINI | P36: 16
... B124: =B123+1 -> 112 | C124: 65/3 | D124: DA+0 | E124: DFR | G124: 46139 | H124: 23.27 | I124: Foundation Completed. | M124: 46141 | N124: ATK | P124: 16
B125: =B124+1 -> 113 | C125: 49/8 | D125: DA+0 | E125: DFR | F125: 46128 | G125: 46136 | H125: 23.27 | I125: Foundation Completed. | M125: 46142 | N125: VEER TEJA CONSTRUCTION | P125: 10
B126: =B125+1 -> 114 | C126: 66/0 | D126: 3DB2+0 | E126: DFR | G126: 46142 | H126: 55.59 | I126: Foundation Completed. | M126: 46145 | N126: ATK | P126: 17
B127: =B126+1 -> 115 | C127: 67/1 | D127: DA+6 | E127: WC | G127: 46141 | H127: 25.77 | I127: Foundation Completed. | M127: 46147 | N127: ATK | P127: 17
B128: =B127+1 -> 116 | C128: 48/7 | D128: DA+0 | E128: DFR | G128: 46132 | H128: 23.27 | I128: Foundation Completed. | M128: 46152 | N128: BALAJI Services | P128: 10
B129: =B128+1 -> 117 | C129: 69/0 | D129: DB2+6 | E129: WET | G129: 46148 | H129: 74.68 | I129: Foundation Completed. | M129: 46155 | N129: ATK | P129: 14
B130: =B129+1 -> 118 | C130: 69/2 | D130: DA+6 | E130: DFR | G130: 46155 | H130: 26.43 | I130: Foundation Completed. | M130: 46158 | N130: ATK | P130: 14
...

Sheet Erection Compiled
A2: SL No. | B2: Location No. | C2: Tower Type | D2: Classification | E2: Start Date | F2: MT | G2: Status | H2: End Date | I2: Gang Name | J2: Gang Strength
A3: 1 | B3: 56/7 | C3: DA+0 | D3: DFR | E3: 46006 | F3: 35.089 | G3: Erection Completed. | H3: 46011 | I3: NASIRUDDIN | J3: 35
A4: =A3+1 -> 2 | B4: 59/2 | C4: DA+0 | D4: DRY | E4: 46013 | F4: 35.089 | G4: Erection Completed. | H4: 46018 | I4: NASIRUDDIN | J4: 35
A5: =A4+1 -> 3 | B5: 77/3 | C5: DA+0 | D5: DFR | E5: 46013 | F5: 35.089 | G5: Erection Completed. | H5: 46022 | I5: CRANE | J5: 49
A6: =A5+1 -> 4 | B6: 58/2 | C6: DA+0 | D6: DRY | E6: 46016 | F6: 35.089 | G6: Erection Completed. | H6: 46032 | I6: NASIRUDDIN | J6: 35
A7: =A6+1 -> 5 | B7: 77/2 | C7: DA+0 | D7: DRY | E7: 46016 | F7: 35.089 | G7: Erection Completed. | H7: 46030 | I7: CRANE | J7: 49
A8: =A7+1 -> 6 | B8: 58/1 | C8: DA+6 | D8: DRY | E8: 46024 | F8: 41.88 | G8: Erection Completed. | H8: 46032 | I8: NASIRUDDIN | J8: 35
A9: =A8+1 -> 7 | B9: 77/1 | C9: DA+0 | D9: DRY | E9: 46023 | F9: 35.089 | G9: Erection Completed. | H9: 46035 | I9: CRANE | J9: 49
A10: =A9+1 -> 8 | B10: 58/3 | C10: DA+0 | D10: DRY | E10: 46031 | F10: 35.089 | G10: Erection Completed. | H10: 46036 | I10: NASIRUDDIN | J10: 35
A11: =A10+1 -> 9 | B11: 77/4 | C11: DA+0 | D11: DRY | E11: 46029 | F11: 35.089 | G11: Erection Completed. | H11: 46038 | I11: DK VERMA | J11: 21
A12: =A11+1 -> 10 | B12: 82/1 | C12: DA+0 | D12: WC | E12: 46033 | F12: 35.089 | G12: Erection Completed. | H12: 46038 | I12: SHAKILA KHATUN | J12: 31
A13: =A12+1 -> 11 | B13: 80/5 | C13: DA+0 | D13: DFRY | E13: 46037 | F13: 35.089 | G13: Erection Completed. | H13: 46042 | I13: SHAKILA KHATUN | J13: 31
A14: =A13+1 -> 12 | B14: 59/4 | C14: DA+6 | D14: DRY | E14: 46037 | F14: 41.88 | G14: Erection Completed. | H14: 46043 | I14: NASIRUDDIN | J14: 35
A15: =A14+1 -> 13 | B15: 77/7 | C15: DA+0 | D15: DFR | E15: 46039 | F15: 35.089 | G15: Erection Completed. | H15: 46043 | I15: DK VERMA | J15: 21
... A70: =A69+1 -> 68 | B70: 100/8 | C70: DA+0 | D70: DFR | E70: 46111 | F70: 35.089 | G70: Erection Completed. | H70: 46085 | I70: TNR INFA | J70: 24
A71: =A70+1 -> 69 | B71: 53/5 | C71: DA+0 | D71: DRY | E71: 02.04-2026 | F71: 35.089 | G71: Erection Completed. | H71: 46119 | I71: NASIRUDDIN | J71: 30
A72: =A71+1 -> 70 | B72: 100/0 | C72: DB2+0 | D72: DFR | E72: 46117 | F72: 54.72 | G72: Erection Completed. | H72: 46124 | I72: TNR INFA | J72: 24
A73: =A72+1 -> 71 | B73: 60/0 | C73: DB2+0 | D73: DFR | E73: 46147 | F73: 54.72 | G73: Erection Completed. | H73: 46160 | I73: NASIRUDDIN | J73: 24
A74: =A73+1 -> 72 | B74: 59/0 | C74: DC1+0 | D74: DFR | E74: 46161 | F74: 62.501 | G74: Erection Completed. | H74: 46175 | I74: NASIRUDDIN | J74: 24
A75: =A74+1 -> 73 | B75: 49/8 | C75: DA+0 | D75: DFR | E75: 46179 | F75: 35.089 | G75: Erection Completed. | H75: 46185 | I75: TOFIT MIA-1 | J75: 30
A76: =A75+1 -> 74 | B76: 60/3 | C76: DA+6 | D76: DRY | E76: 46176 | F76: 41.88 | G76: Erection Completed. | H76: 46186 | I76: NASIRUDDIN-1 | J76: 31
A77: =A76+1 -> 75 | B77: 51/10 | C77: DA+0 | D77: WET | E77: 46182 | F77: 35.089 | G77: Erection Completed. | H77: 46189 | I77: NASIRUDDIN-2 | J77: 32
A78: =A77+1 -> 76 | B78: 49/10 | C78: DA+0 | D78: DFR | E78: 46181 | F78: 35.089 | G78: Erection Completed. | H78: 46181 | I78: TOFIT MIA-2 | J78: 30
A79: =A78+1 -> 77 | B79: 67/1 | C79: DA+6 | D79: DFR | E79: 46183 | F79: 35.089 | G79: Erection Completed. | H79: 46192 | I79: SHAKILA KHATUN | J79: 30
A80: =A79+1 -> 78 | B80: 49/11 | C80: DA+0 | D80: WFR | E80: 46186 | F80: 35.089 | G80: Erection Completed. | H80: 46192 | I80: TOFIT MIA-1 | J80: 30
A81: =A80+1 -> 79 | B81: 56/5 | C81: DA+3 | D81: WC | E81: 46187 | F81: 36.771 | G81: Erection Completed. | H81: 46193 | I81: NASIRUDDIN-1 | J81: 30
A82: =A81+1 -> 80 | B82: 51/8 | C82: DA+0 | D82: DFR | E82: 46189 | F82: 35.089 | G82: Erection Completed. | H82: 46196 | I82: NASIRUDDIN-2 | J82: 32
A83: =A82+1 -> 81 | B83: 65/3 | C83: DA+0 | D83: DFR | E83: 46192 | F83: 35.089 | G83: Erection Completed. | H83: 46196 | I83: SHAKILA KHATUN | J83: 30
... A108: =A107+1 -> 106 | B108: 51/2 | C108: DA+0 | D108: DFR | E108: 46218 | F108: 35.089 | G108: Erection Completed. | H108: 46222 | I108: TOFIT MIA-2 | J108: 30
A109: =A108+1 -> 107 | B109: 53/0 | C109: DB1+3 | D109: DFR/WFR | E109: 46215 | G109: Erection Completed. | H109: 46222 | I109: NASIRUDDIN-2 | J109: 30
A110: =A109+1 -> 108 | B110: 98/2 | C110: DA+0 | D110: DFR | E110: 46220 | F110: 35.089 | G110: Erection Completed. | H110: 46223 | I110: SHAKILA KHATUN | J110: 30
A111: =A110+1 -> 109 | B111: 56/0 | C111: DB2+0 | D111: DFR | E111: 46215 | F111: 54.72 | G111: Erection Completed. | H111: 46224 | I111: NASIRUDDIN-1 | J111: 30
A112: =A111+1 -> 110 | B112: 99/4 | C112: DA+3 | D112: DFR | E112: 46220 | F112: 36.771 | G112: Erection Completed. | H112: 46224 | I112: MASIDUR | J112: 30
A113: =A112+1 -> 111 | B113: 99/5 | C113: DA+0 | D113: DFR | E113: 46224 | F113: 35.089 | G113: Erection Completed. | H113: 46226 | I113: SHAKILA KHATUN | J113: 30
A114: =A113+1 -> 112 | B114: 98/3 | C114: DA+0 | D114: DFR | E114: 46225 | F114: 35.089 | G114: Erection Completed. | H114: 46228 | I114: MASIDUR | J114: 30
A115: =A114+1 -> 113 | B115: 52/2 | C115: DA+0 | D115: WC | E115: 46223 | F115: 35.089 | G115: Erection Completed. | H115: 46230 | I115: NASIRUDDIN-02 | J115: 30
A116: =A115+1 -> 114 | B116: 98/4 | C116: DA+0 | D116: DFR | E116: 46213 | F116: 35.089 | G116: Erection Completed. | H116: 46230 | I116: ANARUL HOQUE | J116: 30
A117: =A116+1 -> 115 | B117: 98/5 | C117: DA+6 | D117: WC | E117: 46227 | F117: 41.88 | G117: Erection Completed. | H117: 46230 | I117: SHAKILA KHATUN | J117: 30
A118: =A117+1 -> 116 | B118: 51/0 | C118: DC2+0 | D118: DFR | E118: 46223 | F118: 62.501 | G118: Erection Completed. | H118: 46231 | I118: TOFIT MIA-2 | J118: 30
A119: =A118+1 -> 117 | B119: 49/9 | C119: DA+0 | D119: DFR | E119: 46223 | F119: 35.089 | G119: Erection Completed. | H119: 46232 | I119: TOFIT MIA-1 | J119: 30
...

Sheet SUPPLY
B1: Supply Status - Stubs & Towers
B2: Stub Details
B3: SL No | C3: Description | D3: Unit | E3: Line Qty | F3: Received | G3: Balance
B4: 1 | C4: 3DA Stub | D4: Set | F4: 208
B5: 2 | C5: 3DB Stub | D5: Set | F5: 37
B6: 3 | C6: 3DC Stub | D6: Set | F6: 20
B7: 4 | C7: 3D45 Stub | D7: Set | F7: 8
B8: 5 | C8: 3D60 Stub | D8: Set | F8: 4
C9: Total | D9: Set | E9: =SUM(E4:E8) -> 0 | F9: =SUM(F4:F8) -> 277 | G9: =SUM(G4:G8) -> 0 | H9: =SUM(H4:H8) -> 0 | I9: =SUM(I4:I8) -> 0
B11: Tower Details
B12: SL No | C12: Tower Type | D12: Description | E12: Line Qty | F12: Received | G12: Balance | J12: Remarks
B13: 1 | C13: 3DA Type | D13: Basic body | F13: 216
D14: +0m BE | F14: 168
D15: +3m BE | F15: 48
D16: +6m BE | F16: 21
D17: +9m BE | F17: 12
B18: 2 | C18: 3DB Type | D18: Basic body | F18: 38
D19: +0m BE | F19: 33
D20: +3m BE | F20: 5
D21: +6m BE | F21: 5
D22: +9m BE | F22: 10
B23: 3 | C23: 3DC Type | D23: Basic body | F23: 21
D24: +0m BE | F24: 18
D25: +3m BE | F25: 3
D26: +6m BE | F26: 2
D27: +9m BE | F27: 3
B28: 4 | C28: 3DD45 Type | D28: Basic body | F28: 7
D29: +0m BE | F29: 6
D30: +3m BE | F30: 1
D31: +6m BE | F31: 0
D32: +9m BE | F32: 4
B33: 5 | C33: 3DD60 Type | D33: Basic body | F33: 2
D34: +0m BE | F34: 2
D35: +3m BE | F35: 0
D36: +6m BE | F36: 0
D37: +9m BE | F37: 0
D39: Total | F39: =F13+F18+F23+F28+F33 -> 284
B44: Activity | C44: Unit | D44: Final Est. Qty | E44: L2 till Last Month | F44: Received till Last Month | G44: Balance | H44: L2 Plan for Current Month | I44: Plan for Current Month | J44: Progress for the Month | K44: Received till Current Month | L44: Gap between Suppy & Cumm.L2 | M44: Remarks
B45: Stub | C45: Set | D45: ='Master Sheet'!D42 -> 292 | E45: ='Master Sheet'!E42 -> 316 | F45: ='Master Sheet'!F42 -> 277 | G45: ='Master Sheet'!G42 -> 15 | H45: ='Master Sheet'!H42 -> 0 | I45: ='Master Sheet'!I42 -> 15 | J45: ='Master Sheet'!J42 -> 0 | K45: ='Master Sheet'!K42 -> 277 | L45: ='Master Sheet'!L42 -> 39
B46: Tower | C46: No's | D46: ='Master Sheet'!D43 -> 292 | E46: ='Master Sheet'!E43 -> 316 | F46: ='Master Sheet'!F43 -> 284 | G46: ='Master Sheet'!G43 -> 8 | H46: ='Master Sheet'!H43 -> 0 | I46: ='Master Sheet'!I43 -> 8 | J46: ='Master Sheet'!J43 -> 0 | K46: ='Master Sheet'!K43 -> 284 | L46: ='Master Sheet'!L43 -> 32
...

Sheet X-ing Details 
B2: CROSSINGS PROPOSAL STATUS : 765 KV D/C Kurnool IV - Bidar TL (Part-2)
B6: Crossing Type | C6: 132 KV | D6: 220kV | E6: SH-Xing | F6: NH-Xing | G6: Railway-Xing | H6: Total
B7: Total Nos | C7: 4 | D7: 2 | E7: 1 | F7: 3 | G7: 2 | H7: 12
B8: Submitted Till Date | C8: 4 | D8: 2 | E8: 0 | F8: 3 | G8: 2 | H8: =C8+D8+F8+G8 -> 11
B9: Approved Till Date | C9: 0 | D9: 0 | E9: 0 | F9: 0 | G9: 0 | H9: 0
B10: Balance to Execute | C10: =C7-C8 -> 0 | D10: =D7-D8 -> 0 | E10: =E7-E8 -> 1 | F10: =F7-F8 -> 0 | G10: =G7-G8 -> 0 | H10: 0
B12: Crossings Details
B13: Sl. No. | C13: FROM (AP) | D13: TO (AP) | E13: Name of the Line | F13: NAME OF CROSSING | G13: Date of First Submission | H13: Joint Inspection Status | I13: Provisional approval status
B14: 1 | C14: AP54 | D14: AP55 | E14: Railway crossing (Tandur - Vikarabad) | F14: Railway crossing | G14: 45987 | I14: APPROVED
B15: =B14+1 -> 2 | C15: AP57 | D15: AP58 | E15: 220kV D/C transmission line Tandur - Gachibowli (HYD) | F15: Power line | G15: 45946 | I15: APPROVED
B16: =B15+1 -> 3 | C16: AP61 | D16: AP62 | E16: NATIONAL HIGHWAY-163 (Kodangal - Hyderabad) | F16: National highway crossing | G16: 45989
B17: =B16+1 -> 4 | C17: AP71 | D17: AP72 | E17: 132kV D/C transmission line Tandur - Mahabubnagar | F17: Power line | G17: 45944 | I17: APPROVED
B18: =B17+1 -> 5 | C18: AP74 | D18: AP75 | E18: NATIONAL HIGHWAY-167N (Kodangal - Kosgi) | F18: National highway crossing | G18: 45989
B19: =B18+1 -> 6 | C19: AP76 | D19: AP77 | E19: 220kV D/C transmission line Kosgi - Pargi | F19: Power line | G19: 45946 | I19: APPROVED
B20: =B19+1 -> 7 | C20: AP88 | D20: AP89 | E20: 132kV S/C transmission line Maddur - Mahabubnagar | F20: Power line | G20: 45946 | I20: APPROVED
B21: =B20+1 -> 8 | C21: AP95 | D21: AP96 | E21: 132kV S/C transmission line Maddur - Makthal | F21: Power line | G21: 45946 | I21: APPROVED
B22: =B21+1 -> 9 | C22: AP98 | D22: AP99 | E22: STATE HIGHWAY-22 (Narayanpet - Marikal) | F22: State highway crossing | G22: Not Required
B23: =B22+1 -> 10 | C23: AP106 | D23: AP107 | E23: Railway crossing (Raichur - Makthal) | F23: Railway crossing | G23: 45988
B24: =B23+1 -> 11 | C24: AP109 | D24: AP110 | E24: 132kV S/C transmission line Makthal - Krishna Railway junction | F24: Power line | G24: 08.12.2025
B25: =B24+1 -> 12 | C25: AP110 | D25: AP111 | E25: NATIONAL HIGHWAY-167N (Raichur - Marikal) | F25: National highway crossing | G25: 08.12.2025

Sheet Striging_Stretch
A1: Sl.No | B1: Section From | C1: Section TO | E1: Lenghth (Kms) | F1: T(T)/M(M) | G1: Total Fdn | H1: Fdn Completed | I1: Pending Fdn | J1: Fdn WIP | K1: Total Erection | L1: Erection Completed | M1: Erection Pending | N1: Erection WIP | O1: Stringing Status | P1: Stretch Ready Y/N | Q1: OPGW Status | R1: District | S1: POWER/NH/Railway Crossing | T1: LT | U1: 11kV | V1: 33kV | W1: Tree cutting status Pending/Clear
A2: 1 | B2: AP48 | C2: AP49 | D2: 48-49 | E2: 3.314 | F2: T | G2: 8 | H2: 4 | I2: =G2-H2 -> 4 | J2: 0 | K2: =G2 -> 8 | L2: 2 | M2: =K2-L2 -> 6 | N2: 0 | R2: Vikarabad | T2: 7 | U2: 1 | V2: 0
A3: =A2+1 -> 2 | B3: =C2 -> AP49 | C3: AP50 | D3: 49-50 | E3: 4.582 | F3: T | G3: 12 | H3: 9 | I3: =G3-H3 -> 3 | J3: 3 | K3: =G3 -> 12 | L3: 8 | M3: =K3-L3 -> 4 | N3: 2 | R3: Vikarabad | T3: 2 | U3: 0 | V3: 0
A4: =A3+1 -> 3 | B4: =C3 -> AP50 | C4: AP51 | D4: 50-51 | E4: 1.519 | F4: T | G4: 4 | H4: 4 | I4: =G4-H4 -> 0 | J4: 0 | K4: =G4 -> 4 | L4: 3 | M4: =K4-L4 -> 1 | N4: 0 | R4: Vikarabad | T4: 1 | U4: 2 | V4: 0
A5: =A4+1 -> 4 | B5: =C4 -> AP51 | C5: AP52 | D5: 51-52 | E5: 4.301 | F5: T | G5: 11 | H5: 11 | I5: =G5-H5 -> 0 | J5: 0 | K5: =G5 -> 11 | L5: 8 | M5: =K5-L5 -> 3 | N5: 0 | R5: Vikarabad | T5: 5 | U5: 9 | V5: 1
A6: =A5+1 -> 5 | B6: =C5 -> AP52 | C6: AP53 | D6: 52-53 | E6: 1.997 | F6: T | G6: 5 | H6: 5 | I6: =G6-H6 -> 0 | J6: 0 | K6: =G6 -> 5 | L6: 3 | M6: =K6-L6 -> 2 | N6: 0 | R6: Vikarabad | T6: 6 | U6: 2 | V6: 0
A7: =A6+1 -> 6 | B7: =C6 -> AP53 | C7: AP54 | D7: 53-54 | E7: 2.761 | F7: T | G7: 7 | H7: 7 | I7: =G7-H7 -> 0 | J7: 0 | K7: =G7 -> 7 | L7: 5 | M7: =K7-L7 -> 2 | N7: 0 | R7: Vikarabad | T7: 1 | U7: 1 | V7: 1
A8: =A7+1 -> 7 | B8: =C7 -> AP54 | C8: AP55 | D8: 54-55 | E8: 0.23 | F8: M | G8: 1 | H8: 1 | I8: =G8-H8 -> 0 | J8: 0 | K8: =G8 -> 1 | L8: 0 | M8: =K8-L8 -> 1 | N8: 1 | R8: Vikarabad | S8: Railway Double Track Eletrified | T8: 0 | U8: 0 | V8: 0
A9: =A8+1 -> 8 | B9: =C8 -> AP55 | C9: AP56 | D9: 55-56 | E9: 1.453 | F9: T | G9: 4 | H9: 2 | I9: =G9-H9 -> 2 | J9: 1 | K9: =G9 -> 4 | L9: 2 | M9: =K9-L9 -> 2 | N9: 0 | R9: Vikarabad | T9: 1 | U9: 1 | V9: 0
A10: =A9+1 -> 9 | B10: =C9 -> AP56 | C10: 56/7 | D10: 56-56/7 | E10: 2.757 | F10: T | G10: 7 | H10: 7 | I10: =G10-H10 -> 0 | J10: 0 | K10: =G10 -> 7 | L10: 6 | M10: =K10-L10 -> 1 | N10: 0 | R10: Vikarabad | T10: 3 | U10: 5 | V10: 1
A11: =A10+1 -> 10 | B11: =C10 -> 56/7 | C11: AP57 | D11: 56/7-57 | E11: 2.476 | F11: T | G11: 6 | H11: 6 | I11: =G11-H11 -> 0 | J11: 0 | K11: =G11 -> 6 | L11: 6 | M11: =K11-L11 -> 0 | N11: 0 | R11: Vikarabad | T11: 2 | U11: 0 | V11: 0
A12: =A11+1 -> 11 | B12: =C11 -> AP57 | C12: AP58 | D12: 57-58 | E12: 0.215 | F12: M | G12: 1 | H12: 1 | I12: =G12-H12 -> 0 | J12: 0 | K12: =G12 -> 1 | L12: 1 | M12: 1 | N12: 1 | R12: Vikarabad | S12: 220kV DC | T12: 0 | U12: 0 | V12: 0
A13: =A12+1 -> 12 | B13: =C12 -> AP58 | C13: AP59 | D13: 58-59 | E13: 1.588 | F13: T | G13: 4 | H13: 4 | I13: =G13-H13 -> 0 | J13: 0 | K13: =G13 -> 4 | L13: 3 | M13: =K13-L13 -> 1 | N13: 0 | R13: Vikarabad | T13: 0 | U13: 2 | V13: 0
A14: =A13+1 -> 13 | B14: =C13 -> AP59 | C14: AP60 | D14: 59-60 | E14: 2.316 | F14: T | G14: 6 | H14: 5 | I14: =G14-H14 -> 1 | J14: 0 | K14: =G14 -> 6 | L14: 5 | M14: =K14-L14 -> 1 | N14: 0 | R14: Vikarabad | T14: 5 | U14: 1 | V14: 0
A15: =A14+1 -> 14 | B15: =C14 -> AP60 | C15: 60/5 | D15: 60-60/5 | E15: 1.987 | F15: T | G15: 5 | H15: 4 | I15: =G15-H15 -> 1 | J15: 0 | K15: =G15 -> 5 | L15: 3 | M15: =K15-L15 -> 2 | N15: 0 | R15: Vikarabad | T15: 4 | U15: 2 | V15: 0
A16: =A15+1 -> 15 | B16: =C15 -> 60/5 | C16: 60/6 | D16: 60/5-60/6 | E16: 0.48 | F16: M | G16: 1 | H16: 0 | I16: =G16-H16 -> 1 | J16: 0 | K16: =G16 -> 1 | L16: 0 | M16: =K16-L16 -> 1 | N16: 0 | R16: Vikarabad | T16: 2 | U16: 2 | V16: 0
A17: =A16+1 -> 16 | B17: =C16 -> 60/6 | C17: 60/7 | D17: 60/6-60/7 | E17: 0.535 | F17: M | G17: 1 | H17: 0 | I17: =G17-H17 -> 1 | J17: 0 | K17: =G17 -> 1 | L17: 0 | M17: =K17-L17 -> 1 | N17: 0 | R17: Vikarabad | T17: 0 | U17: 1 | V17: 0
A18: =A17+1 -> 17 | B18: =C17 -> 60/7 | C18: AP61 | D18: 60/7-61 | E18: 0.843 | F18: M | G18: 2 | H18: 1 | I18: =G18-H18 -> 1 | J18: 1 | K18: =G18 -> 2 | L18: 0 | M18: =K18-L18 -> 2 | N18: 0 | R18: Vikarabad | T18: 3 | U18: 1 | V18: 0
A19: =A18+1 -> 18 | B19: =C18 -> AP61 | C19: AP62 | D19: 61-62 | E19: 0.247 | F19: M | G19: 1 | H19: 0 | I19: =G19-H19 -> 1 | J19: 0 | K19: =G19 -> 1 | L19: 0 | M19: =K19-L19 -> 1 | N19: 0 | R19: Vikarabad | S19: NH Crossing | T19: 0 | U19: 0 | V19: 2
A20: =A19+1 -> 19 | B20: =C19 -> AP62 | C20: AP63 | D20: 62-63 | E20: 1.82 | F20: T | G20: 5 | H20: 0 | I20: =G20-H20 -> 5 | J20: 0 | K20: =G20 -> 5 | L20: 0 | M20: =K20-L20 -> 5 | N20: 0 | R20: Vikarabad | T20: 1 | U20: 1
A21: =A20+1 -> 20 | B21: =C20 -> AP63 | C21: AP64 | D21: 63-64 | E21: 1.612 | F21: T | G21: 4 | H21: 3 | I21: =G21-H21 -> 1 | J21: 1 | K21: =G21 -> 4 | L21: 0 | M21: =K21-L21 -> 4 | N21: 0 | R21: Vikarabad | T21: 2 | U21: 1 | V21: 0
A22: =A21+1 -> 21 | B22: =C21 -> AP64 | C22: AP65 | D22: 64-65 | E22: 0.439 | F22: M | G22: 1 | H22: 0 | I22: =G22-H22 -> 1 | J22: 0 | K22: =G22 -> 1 | L22: 0 | M22: =K22-L22 -> 1 | N22: 0 | R22: Vikarabad | T22: 1 | U22: 0 | V22: 0
A23: =A22+1 -> 22 | B23: =C22 -> AP65 | C23: AP66 | D23: 65-66 | E23: 1.399 | F23: T | G23: 4 | H23: 2 | I23: =G23-H23 -> 2 | J23: 0 | K23: =G23 -> 4 | L23: 1 | M23: =K23-L23 -> 3 | N23: 0 | R23: Vikarabad | T23: 4 | U23: 1 | V23: 0
A24: =A23+1 -> 23 | B24: =C23 -> AP66 | C24: 66/1 | D24: 66-66/1 | E24: 0.421 | F24: M | G24: 1 | H24: 1 | I24: =G24-H24 -> 0 | J24: 0 | K24: =G24 -> 1 | L24: 1 | M24: =K24-L24 -> 0 | N24: 0 | R24: Vikarabad | T24: 1 | U24: 2 | V24: 0
A25: =A24+1 -> 24 | B25: =C24 -> 66/1 | C25: AP67 | D25: 66/1-67 | E25: 0.466 | F25: M | G25: 1 | H25: 1 | I25: =G25-H25 -> 0 | J25: 0 | K25: =G25 -> 1 | L25: 0 | M25: =K25-L25 -> 1 | N25: 0 | R25: Vikarabad | T25: 1 | U25: 0 | V25: 0
A26: =A25+1 -> 25 | B26: =C25 -> AP67 | C26: AP68 | D26: 67-68 | E26: 1.841 | F26: T | G26: 5 | H26: 2 | I26: =G26-H26 -> 3 | J26: 0 | K26: =G26 -> 5 | L26: 2 | M26: =K26-L26 -> 3 | N26: 0 | R26: Vikarabad | T26: 2 | U26: 1 | V26: 0
A27: =A26+1 -> 26 | B27: =C26 -> AP68 | C27: AP69 | D27: 68-69 | E27: 1.161 | F27: T | G27: 3 | H27: 2 | I27: =G27-H27 -> 1 | J27: 0 | K27: =G27 -> 3 | L27: 0 | M27: =K27-L27 -> 3 | N27: 0 | R27: Vikarabad | T27: 4 | U27: 1 | V27: 0
A28: =A27+1 -> 27 | B28: =C27 -> AP69 | C28: AP70 | D28: 69-70 | E28: 1.262 | F28: T | G28: 3 | H28: 3 | I28: =G28-H28 -> 0 | J28: 0 | K28: =G28 -> 3 | L28: 2 | M28: =K28-L28 -> 1 | N28: 0 | R28: Vikarabad | T28: 2 | U28: 1 | V28: 0
A29: =A28+1 -> 28 | B29: =C28 -> AP70 | C29: AP71 | D29: 70-71 | E29: 1.967 | F29: T | G29: 5 | H29: 4 | I29: =G29-H29 -> 1 | J29: 0 | K29: =G29 -> 5 | L29: 2 | M29: =K29-L29 -> 3 | N29: 0 | R29: Narayanpet | T29: 3 | U29: 2 | V29: 0
A30: =A29+1 -> 29 | B30: =C29 -> AP71 | C30: AP72 | D30: 71-72 | E30: 0.249 | F30: M | G30: 1 | H30: 1 | I30: =G30-H30 -> 0 | J30: 0 | K30: =G30 -> 1 | L30: 0 | M30: =K30-L30 -> 1 | N30: 0 | R30: Narayanpet | S30: 132kV DC | T30: 0 | U30: 2 | V30: 0
A31: =A30+1 -> 30 | B31: =C30 -> AP72 | C31: AP73 | D31: 72-73 | E31: 0.828 | F31: M | G31: 2 | H31: 2 | I31: =G31-H31 -> 0 | J31: 0 | K31: =G31 -> 2 | L31: 1 | M31: =K31-L31 -> 1 | N31: 1 | R31: Narayanpet | T31: 3 | U31: 2 | V31: 0
A32: =A31+1 -> 31 | B32: =C31 -> AP73 | C32: AP74 | D32: 73-74 | E32: 1.213 | F32: T | G32: 3 | H32: 3 | I32: =G32-H32 -> 0 | J32: 0 | K32: =G32 -> 3 | L32: 0 | M32: =K32-L32 -> 3 | N32: 0 | R32: Narayanpet | T32: 4 | U32: 6 | V32: 0
A33: =A32+1 -> 32 | B33: =C32 -> AP74 | C33: AP75 | D33: 74-75 | E33: 0.25 | F33: M | G33: 1 | H33: 0 | I33: =G33-H33 -> 1 | J33: 0 | K33: =G33 -> 1 | L33: 0 | M33: =K33-L33 -> 1 | N33: 0 | R33: Narayanpet | S33: NH Crossing | T33: 0 | U33: 2 | V33: 0
A34: =A33+1 -> 33 | B34: =C33 -> AP75 | C34: AP76 | D34: 75-76 | E34: 1.601 | F34: T | G34: 4 | H34: 3 | I34: =G34-H34 -> 1 | J34: 0 | K34: =G34 -> 4 | L34: 0 | M34: =K34-L34 -> 4 | N34: 0 | R34: Narayanpet | T34: 5 | U34: 2 | V34: 0
A35: =A34+1 -> 34 | B35: =C34 -> AP76 | C35: AP77 | D35: 76-77 | E35: 0.206 | F35: M | G35: 1 | H35: 1 | I35: =G35-H35 -> 0 | J35: 0 | K35: =G35 -> 1 | L35: 0 | M35: =K35-L35 -> 1 | N35: 0 | R35: Narayanpet | S35: 220kV DC | T35: 1 | U35: 0 | V35: 0
A36: =A35+1 -> 35 | B36: =C35 -> AP77 | C36: AP78 | D36: 77-78 | E36: 4.261 | F36: T | G36: 11 | H36: 10 | I36: =G36-H36 -> 1 | J36: 0 | K36: =G36 -> 11 | L36: 7 | M36: =K36-L36 -> 4 | N36: 0 | R36: Narayanpet | T36: 5 | U36: 6 | V36: 1
A37: =A36+1 -> 36 | B37: =C36 -> AP78 | C37: AP79 | D37: 78-79 | E37: 1.555 | F37: T | G37: 4 | H37: 3 | I37: =G37-H37 -> 1 | J37: 0 | K37: =G37 -> 4 | L37: 0 | M37: =K37-L37 -> 4 | N37: 0 | R37: Narayanpet | T37: 1 | U37: 3 | V37: 0
A38: =A37+1 -> 37 | B38: =C37 -> AP79 | C38: AP80 | D38: 79-80 | E38: 1.578 | F38: T | G38: 4 | H38: 3 | I38: =G38-H38 -> 1 | J38: 0 | K38: =G38 -> 4 | L38: 2 | M38: =K38-L38 -> 2 | N38: 0 | R38: Narayanpet | T38: 2 | U38: 2 | V38: 0
A39: =A38+1 -> 38 | B39: =C38 -> AP80 | C39: AP80/3 | D39: 80-80/3 | E39: 1.283 | F39: T | G39: 3 | H39: 2 | I39: =G39-H39 -> 1 | J39: 0 | K39: =G39 -> 3 | L39: 1 | M39: =K39-L39 -> 2 | N39: 0 | R39: Narayanpet | T39: 2 | U39: 1 | V39: 0
A40: =A39+1 -> 39 | B40: =C39 -> AP80/3 | C40: AP81 | D40: 80/3-81 | E40: 1.213 | F40: T | G40: 3 | H40: 2 | I40: =G40-H40 -> 1 | J40: 1 | K40: =G40 -> 3 | L40: 1 | M40: =K40-L40 -> 2 | N40: 0 | R40: Narayanpet | T40: 3 | U40: 2 | V40: 1
...

Sheet Visual Chart
A1: VISUAL PROGRESS CHART
A2: 765 kV DC Kurnool IV - Bidar Transmission Line (TL-02)
B3: Foundation (Nos.):- | D3: =Z16 -> 187 | E3: /292 | F3: Erection (Nos.):- | H3: =AA16 -> 125 | I3: /292 | J3: Earthing (Nos.):- | L3: =AB16 -> 131 | M3: /292 | N3: Rough Sag (Kms):- | P3: 0 / | Q3: 113.292 | R3: Final Sag (Kms):- | T3: 0 / | U3: 113.292 | V3: Date:- | W3: =TODAY() -> 46244
B4: COMPLETION CHART | C4: Unit | D4: 0 | E4: +3 | F4: 6 | G4: +9 | H4: Total | I4: Line Qty
J5: ERECTION | P5: Rough Sag | R5: SH / NH Road Crossing
J6: WIP | V6: River
B7: DA | C7: Nos | D7: 135 | E7: 48 | F7: 21 | G7: 12 | H7: =SUM(D7:G7) -> 216 | I7: =H7 -> 216 | J7: FOUNDATION | K7: Type | M7: Angle Tower | R7: Gas Pipeline
B8: DB1 | C8: Nos | D8: 5 | E8: 3 | F8: 4 | G8: 8 | H8: =SUM(D8:G8) -> 20 | I8: =H8 -> 20
B9: DB2 | C9: Nos | D9: 13 | E9: 2 | G9: 2 | H9: =SUM(D9:G9) -> 17 | I9: =H9 -> 17 | O9: Final Sag
B10: DCT | C10: Nos | D10: 1 | H10: =SUM(D10:G10) -> 1 | I10: =H10 -> 1
B11: DC1 | C11: Nos | D11: 10 | E11: 2 | F11: 1 | G11: 3 | H11: =SUM(D11:G11) -> 16 | I11: =H11 -> 16 | S11: Railway
B12: DC2 | C12: Nos | D12: 3 | E12: 3 | F12: 1 | G12: 0 | H12: =SUM(D12:G12) -> 7 | I12: =H12 -> 7 | Q12: WIP | S12: Crossing
B13: DCT | C13: Nos | D13: 0 | E13: 0 | F13: 0 | G13: 0 | H13: =SUM(D13:G13) -> 0 | I13: =H13 -> 0 | J13: Section Tower | K13: SC | V13: 110kV - 800kV | Z13: Foundation | AA13: Erection | AB13: Earthing
B14: DD45 | C14: Nos | D14: 3 | E14: 1 | F14: 1 | G14: 4 | H14: =SUM(D14:G14) -> 9 | I14: =H14 -> 9 | J14: TP | K14: TT | M14: Earthing | P14: OPGW | V14: Line
B15: DD60 | C15: Nos | D15: 2 | E15: 1 | F15: 1 | G15: 1 | H15: =SUM(D15:G15) -> 5 | I15: =H15 -> 5
B16: Total Completed Foundations | H16: =D3 -> 187 | I16: =292-H16 -> 105 | Z16: =SUM(Z18:Z254) -> 187 | AA16: =SUM(AA18:AA254) -> 125 | AB16: =SUM(AB18:AB254) -> 131
B17: Wind Zone - 3 [AP48 - AP111]
A18: COMMON TOWER (TL-1&2) | AD18: DS | AE18: CS | AF18: SI | AG18: FDN | AH18: EAR | AI18: ERN | AJ18: TW | AK18: PO | AL18: FS | AM18: OPGW
AC19: TOTAL | AD19: =(C21+E21+G21+I21+K21+M21+O21+Q21+S21+U21+W21+Y21)/1000 -> 4.83244 | AE19: =(C21+E21+G21+I21+K21+M21+O21+Q21+S21+U21+W21+Y21)/1000 -> 4.83244 | AG19: 12 | AH19: 12 | AI19: 12 | AJ19: 12 | AL19: =(C21+E21+G21+I21+K21+M21+O21+Q21+S21+U21+W21+Y21)/1000 -> 4.83244
AC20: COMPLETED | AG20: =B21+D21+F21 -> #VALUE!
B21: Balaji Services | C21: 411 | E21: 432 | F21: Balaji Service | G21: 411 | H21: Balaji Service | I21: 432 | K21: 411 | M21: 432 | O21: 411 | P21: Balaji Service | Q21: 374.437 | R21: AMMU ENGG | S21: 376.003 | T21: AMMU ENGG | U21: 405 | V21: AMMU ENGG | W21: 340 | X21: AMMU ENGG | Y21: 397 | Z21: 8 | AA21: 6 | AB21: 3 | AC21: BALANCE
B23: AP48/0 | D23: 48/1 | F23: 48/2 | H23: 48/3 | J23: 48/4 | L23: 48/5 | N23: 48/6 | P23: 48/7 | R23: AP49/0 | T23: 49/1 | V23: 49/2 | X23: 49/3
B24: 3DC1+0 | D24: 3DA+6 | F24: 3DA+0 | H24: 3DA+6 | J24: 3DA+3 | L24: 3DA+3 | N24: 3DA+3 | P24: 3DA+3 | Q24: =(Q21+O21+M21+K21+I21+G21+E21+C21)/1000 -> 3.314437 | R24: 3DC1+0 | T24: 3DA+0 | V24: 3DA+0 | X24: 3DA+0
B25: 1st Pit started | V25: RC
B30: AMMU ENGG | C30: 399 | D30: AMMU ENGG | E30: 393 | F30: AMMU ENGG | G30: 370 | H30: AMMU ENGG | I30: 350 | J30: VEER TEJA | K30: 395 | L30: VEER TEJA | M30: 413 | N30: VEER TEJA | O30: 366 | P30: VEER TEJA | Q30: 377.77 | R30: VEER TEJA | S30: 300 | T30: SRI HARSH-1 | U30: 393 | V30: SRI HARSH-1 | W30: 415 | X30: SRI HARSH-1 | Y30: 411 | Z30: 9 | AA30: 7 | AB30: 7
B32: 49/4 | D32: 49/5 | F32: 49/6 | H32: 49/7 | J32: 49/8 | L32: 49/9 | N32: 49/10 | P32: 49/11 | R32: AP50/0 | T32: 50/1 | V32: 50/2 | X32: 50/3
B33: 3DA+0 | D33: 3DA+3 | F33: 3DA+0 | H33: 3DA+0 | J33: 3DA+0 | L33: 3DA+0 | N33: 3DA+0 | P33: 3DA+0 | Q33: =(S21+U21+W21+Y21+Q30+O30+M30+K30+I30+G30+E30+C30)/1000 -> 4.581773 | R33: 3DC2+0 | T33: 3DA+0 | V33: 3DA+0 | X33: 3DA+3 | Y33: =(S30+U30+W30+Y30)/1000 -> 1.519
B39: Shriharshini | C39: 378 | D39: Shriharshini | E39: 370 | F39: Shriharshini | G39: 370 | H39: Shriharshini | I39: 404 | J39: Shriharshini | K39: 374 | L39: Shriharshini | M39: 416 | N39: SRI HARSH-1 | O39: 425 | P39: SRI HARSH-1 | Q39: 411 | R39: SRI HARSH-1 | S39: 427 | T39: SRI HARSH-1 | U39: 370 | V39: SRI HARSH-1 | W39: 356 | X39: SRI HARSHI-1 | Y39: 459
Z40: 12 | AA40: 9 | AB40: 12
B41: AP51/0 | D41: 51/1 | F41: 51/2 | H41: 51/3 | J41: 51/4 | L41: 51/5 | N41: 51/6 | P41: 51/7 | R41: 51/8 | T41: 51/9 | V41: 51/10 | X41: AP52/0
B42: 3DC2+0 | D42: 3DA+3 | F42: 3DA+0 | H42: 3DA+0 | J42: 3DA+0 | L42: 3DA+0 | N42: 3DA+3 | P42: 3DA+3 | R42: 3DA+0 | T42: 3DA+3 | V42: 3DA+0 | W42: =(C39+E39+G39+I39+K39+M39+O39+Q39+S39+U39+W39)/1000 -> 4.301 | X42: 3DB2+0
J46: J
B48: SRI HARSH-1 | C48: 355 | D48: SHRI HARSH | E48: 348 | F48: Shriharshini | G48: 434 | H48: Shriharshini | I48: 401 | J48: SRI HARSH-1 | K48: 400 | L48: SRI HARSH-1 | M48: 413 | N48: SRI HARSH-1 | O48: 406 | P48: SRI HARSH-1 | Q48: 390 | R48: SRI HARSH-1 | S48: 390 | T48: SRI HARSH-1 | U48: 430 | V48: SHRIHARSHINI | W48: 332 | X48: Shriharshnini | Y48: 229.642
Z49: 12 | AA49: 7 | AB49: 9
B50: 52/1 | D50: 52/2 | F50: 52/3 | H50: 52/4 | J50: AP53/0 | L50: 53/1 | N50: 53/2 | P50: 53/3 | R50: 53/4 | T50: 53/5 | V50: 53/6 | X50: AP54/0
B51: 3DA+9 | D51: 3DA+0 | F51: 3DA+0 | H51: 3DA+0 | I51: =(Y39+C48+E48+G48+I48)/1000 -> 1.997 | J51: 3DB1+3 | L51: 3DA+3 | N51: 3DA+0 | P51: 3DA+3 | R51: 3DA+0 | T51: 3DA+0 | V51: 3DA+3 | W51: =(K48+M48+O48+Q48+S48+U48+W48)/1000 -> 2.761 | X51: 3DD60+0 | Y51: =Y48/1000 -> 0.229642
X52: Rly X-ing
B57: Shriharshnini | C57: 339 | D57: SRI HARSH-1 | E57: 365 | F57: ROW | G57: 409 | H57: SRI HARSH-1 | I57: 340.462 | J57: D.Govind Raj | K57: 352 | L57: SRI HARSH-1 | M57: 419 | N57: SRI HARSH-1 | O57: 410 | P57: SRI HARSH-1 | Q57: 413 | R57: SRI HARSH-1 | S57: 407 | T57: VEER TEJA | U57: 351 | V57: SRI HARSH-1 | W57: 405 | X57: SRI HARSH-1 | Y57: 393
Z58: 10 | AA58: 9 | AB58: 8
B59: AP55/0 | D59: 55/1 | F59: 55/2 | H59: 55/3 | J59: AP56/0 | L59: 56/1 | N59: 56/2 | P59: 56/3 | R59: 56/4 | T59: 56/5 | V59: 56/6 | X59: 56/7
...

Sheet Foundation & Erection
A1: Description | G1: FOUNDATION DETAILS | L1: EARTHING DETAILS | N1: Erection Details
A2: SL. No | B2: Loc No. | C2: Type of Tower | D2: Type of FDN | E2: RC Fdn Y/N | F2: RC Drawing Status | G2: Stub Availbility Y/N | H2: Fdn ROW | I2: Date of Starting | J2: Date of Completion | K2: Gang Name | L2: Type of Earthing Cp/Pipe | M2: Date of Earthing Completed | N2: Tower Parts Availbility | O2: Tonnage MT | P2: Erection ROW | Q2: Date of Starting | R2: Date of Completion | S2: Gang Name
A3: 1 | B3: 48/0 | C3: 3DCT+0 | D3: DFR | E3: No | F3: Yes | G3: Yes | H3: Completed | I3: 46167 | J3: 46195 | K3: Balaji Services
A4: 2 | B4: 48/1 | C4: 3DA+6 | D4: DFR | E4: No | F4: Yes | G4: Yes | H4: Excavated | N4: Yes | O4: 41.88
A5: 3 | B5: 48/2 | C5: 3DA+0 | D5: DFR | E5: No | F5: Yes | G5: Yes | H5: Completed | I5: 46162 | J5: 46166 | K5: Balaji Services | L5: C P | M5: 46173 | N5: Yes | O5: 35.089 | P5: Erection Completed. | Q5: 46207 | R5: 46211 | S5: TOFIT MIA-1
A6: 4 | B6: 48/3 | C6: 3DA+6 | D6: DFR | E6: No | F6: Yes | G6: Yes | H6: Completed | I6: 46153 | J6: 46161 | K6: Balaji Services | L6: C P | M6: 46164 | N6: Yes | O6: 41.88 | P6: Erection Completed. | Q6: 46564 | R6: 46206 | S6: TOFIT MIA-1
A7: 5 | B7: 48/4 | C7: 3DA+3 | D7: DFR | E7: No | F7: Yes | G7: Yes | H7: Excavated | N7: Yes | O7: 36.771
A8: 6 | B8: 48/5 | C8: 3DA+3 | D8: DFR | E8: No | F8: Yes | G8: Yes | H8: Wip | N8: Yes | O8: 36.771
A9: 7 | B9: 48/6 | C9: 3DA+3 | D9: DFR | E9: No | F9: Yes | G9: Yes | H9: Wip | N9: Yes | O9: 36.771
A10: 8 | B10: 48/7 | C10: 3DA+3 | D10: DFR | E10: No | F10: Yes | G10: Yes | H10: Completed | I10: 46132 | J10: 46152 | K10: Balaji Services | L10: C P | M10: 46154 | N10: Yes | O10: 36.771
A11: 9 | B11: 49/0 | C11: 3DC1+0 | D11: DFR | E11: No | F11: - | G11: Yes | H11: Completed | I11: 46156 | J11: 46190 | K11: AMMU ENGG | N11: Yes | O11: 62.501 | P11: Erection Completed | Q11: 46232 | R11: 46244 | S11: TOFIT MIA-2
A12: 10 | B12: 49/1 | C12: 3DA+0 | D12: DFR | E12: No | F12: Yes | G12: Yes | H12: Completed | I12: 46191 | J12: 46193 | K12: AMMU ENGG | N12: Yes | O12: 35.089 | P12: Erection Completed | Q12: 46210 | R12: 46216 | S12: TOFIT MIA-1
A13: 11 | B13: 49/2 | C13: 3DA+0 | D13: DFR | E13: Yes | F13: Yes | G13: Yes | H13: Completed | I13: 46194 | J13: 46203 | K13: AMMU ENGG | N13: Yes | O13: 35.089 | P13: Erection Completed | Q13: 46217 | R13: 46222 | S13: TOFIT MIA-1
A14: 12 | B14: 49/3 | C14: 3DA+0 | D14: DFR | E14: No | F14: Yes | G14: Yes | H14: Completed | I14: 46204 | J14: 46217 | K14: AMMU ENGG | N14: Yes | O14: 35.089 | P14: Erection Completed | Q14: 46233 | R14: 46242 | S14: TOFIT MIA-1
A15: 13 | B15: 49/4 | C15: 3DA+0 | D15: DFR | E15: No | F15: Yes | G15: Yes | H15: Completed | I15: 46221 | J15: 46229 | K15: AMMU ENGG | N15: Yes | O15: 35.089
A16: 14 | B16: 49/5 | C16: 3DA+3 | D16: DFR | E16: No | F16: Yes | G16: Yes | H16: Clear | N16: Yes | O16: 36.771
A17: 15 | B17: 49/6 | C17: 3DA+0 | D17: DFR | E17: No | F17: Yes | G17: Yes | H17: Clear | N17: Yes | O17: 35.089
A18: 16 | B18: 49/7 | C18: 3DA+0 | D18: DFR | E18: No | F18: Yes | G18: Yes | H18: Clear | N18: Yes | O18: 35.089
A19: 17 | B19: 49/8 | C19: 3DA+0 | D19: DFR | E19: No | F19: Yes | G19: Yes | H19: Completed | I19: 46136 | J19: 46142 | K19: VEER TEJA CONSTRUCTION | L19: C P | M19: 46142 | N19: Yes | O19: 35.089 | P19: Erection Completed. | Q19: 46181 | R19: 46185 | S19: TOFIT MIA-1
A20: 18 | B20: 49/9 | C20: 3DA+0 | D20: DFR | E20: No | F20: Yes | G20: Yes | H20: Completed | I20: 46127 | J20: 46135 | K20: VEER TEJA CONSTRUCTION | N20: Yes | O20: 35.089 | P20: Erection Completed. | Q20: 46223 | R20: 46232 | S20: TOFIT MIA-1
A21: 19 | B21: 49/10 | C21: 3DA+0 | D21: DFR | E21: No | F21: Yes | G21: Yes | H21: Completed | I21: 46077 | J21: 46092 | K21: VEER TEJA CONSTRUCTION | L21: C P | M21: 46136 | N21: Yes | O21: 35.089 | P21: Erection Completed. | Q21: 46181 | R21: 46191 | S21: TOFIT MIA-2
A22: 20 | B22: 49/11 | C22: 3DA+0 | D22: WFR | E22: No | F22: Yes | G22: Yes | H22: Completed | I22: 46077 | J22: 46095 | K22: VEER TEJA CONSTRUCTION | L22: C P | M22: 46136 | N22: Yes | O22: 35.089 | P22: Erection Completed. | Q22: 46186 | R22: 46192 | S22: TOFIT MIA-1
A23: 21 | B23: 50/0 | C23: 3DC2+0 | D23: WFR | E23: No | F23: - | G23: Yes | H23: Completed | I23: 46077 | J23: 46128 | K23: VEER TEJA CONSTRUCTION | L23: C P | M23: 46114 | N23: Yes | O23: 62.501 | P23: Erection Completed. | Q23: 46199 | R23: 46209 | S23: TOFIT MIA-1
A24: 22 | B24: 50/1 | C24: 3DA+0 | D24: DFR | E24: No | F24: Yes | G24: Yes | H24: Completed | I24: 46060 | J24: 46065 | K24: SHRIARSHINI | L24: C P | M24: 46068 | N24: Yes | O24: 35.089
A25: 23 | B25: 50/2 | C25: 3DA+0 | D25: WET | E25: No | F25: Yes | G25: Yes | H25: Completed | I25: 46059 | J25: 46070 | K25: SHRIARSHINI | L25: PTE | M25: 46070 | N25: Yes | O25: 35.089 | P25: Erection Completed. | Q25: 46193 | R25: 46198 | S25: TOFIT MIA-1
A26: 24 | B26: 50/3 | C26: 3DA+3 | D26: DFR | E26: No | F26: Yes | G26: Yes | H26: Completed | I26: 46101 | J26: 46106 | K26: SHRIARSHINI | L26: C P | M26: 46110 | N26: Yes | O26: 36.771 | P26: Erection Completed. | Q26: 46192 | R26: 46198 | S26: TOFIT MIA-2
A27: 25 | B27: 51/0 | C27: 3DC2+0 | D27: DFR | E27: No | F27: - | G27: Yes | H27: Completed | I27: 46200 | J27: 46205 | K27: SHRIARSHINI | L27: C P | M27: 46213 | N27: Yes | O27: 62.501 | P27: Erection Completed. | Q27: 46223 | R27: 46231 | S27: TOFIT MIA-2
A28: 26 | B28: 51/1 | C28: 3DA+3 | D28: DFR | E28: No | F28: Yes | G28: Yes | H28: Completed | I28: 46189 | J28: 46193 | K28: SHRIARSHINI | L28: CP | M28: 46199 | N28: Yes | O28: 36.771 | P28: Erection Completed | Q28: 46212 | R28: 46217 | S28: TOFIT MIA-2
A29: 27 | B29: 51/2 | C29: 3DA+0 | D29: DFR | E29: No | F29: Yes | G29: Yes | H29: Completed | I29: 46102 | J29: 46108 | K29: SHRIARSHINI | L29: C P | M29: 46112 | N29: Yes | O29: 35.089 | P29: Erection Completed | Q29: 46218 | R29: 46222 | S29: TOFIT MIA-2
A30: 28 | B30: 51/3 | C30: 3DA+0 | D30: DFR | E30: No | F30: Yes | G30: Yes | H30: Completed | I30: 46209 | J30: 46211 | K30: SHRIARSHINI | L30: C P | M30: 46215 | N30: Yes | O30: 35.089
A31: 29 | B31: 51/4 | C31: 3DA+0 | D31: WET | E31: No | F31: Yes | G31: Yes | H31: Completed | I31: 46194 | J31: 46196 | K31: SHRIARSHINI | L31: C P | M31: 46199 | N31: Yes | O31: 35.089
A32: 30 | B32: 51/5 | C32: 3DA+0 | D32: DFR | E32: No | F32: Yes | G32: Yes | H32: Completed | I32: 46197 | J32: 46199 | K32: SHRIARSHINI | L32: CP | M32: 46215 | N32: Yes | O32: 35.089
A33: 31 | B33: 51/6 | C33: 3DA+3 | D33: DFR | E33: No | F33: Yes | G33: Yes | H33: Completed | I33: 46092 | J33: 46100 | K33: SHRIARSHINI | L33: C P | M33: 46110 | N33: Yes | O33: 36.771 | P33: Erection Completed. | Q33: 46204 | R33: 46209 | S33: NASIRUDDIN-2
A34: 32 | B34: 51/7 | C34: 3DA+3 | D34: DFR | E34: No | F34: Yes | G34: Yes | H34: Completed | I34: 46087 | J34: 46094 | K34: SHRIARSHINI | L34: C P | M34: 46095 | N34: Yes | O34: 36.771 | P34: Erection Completed. | Q34: 46210 | R34: 46214 | S34: NASIRUDDIN-2
A35: 33 | B35: 51/8 | C35: 3DA+0 | D35: DFR | E35: No | F35: Yes | G35: Yes | H35: Completed | I35: 46088 | J35: 46095 | K35: SHRIARSHINI | L35: C P | M35: 46098 | N35: Yes | O35: 35.089 | P35: Erection Completed. | Q35: 46189 | R35: 46196 | S35: NASIRUDDIN-2
A36: 34 | B36: 51/9 | C36: 3DA+3 | D36: DFR | E36: No | F36: Yes | G36: Yes | H36: Completed | I36: 46054 | J36: 46058 | K36: SHRIARSHINI | L36: C P | M36: 46069 | N36: Yes | O36: 36.771 | P36: Erection Completed. | Q36: 46081 | R36: 46086 | S36: SHAKILA KHATUN
A37: 35 | B37: 51/10 | C37: 3DA+0 | D37: WET | E37: No | F37: Yes | G37: Yes | H37: Completed | I37: 46090 | J37: 46098 | K37: SHRIARSHINI | L37: P T E | M37: 46127 | N37: Yes | O37: 35.089 | P37: Erection Completed. | Q37: 46182 | R37: 46189 | S37: NASIRUDDIN-2
A38: 36 | B38: 52/0 | C38: 3DB2+0 | D38: DFR | E38: No | G38: Yes | H38: Completed | I38: 46045 | J38: 46053 | K38: SHRIARSHINI | L38: C P | M38: 46056 | N38: Yes | O38: 54.72 | P38: Erection Completed. | Q38: 46070 | R38: 46074 | S38: SHAKILA KHATUN
A39: 37 | B39: 52/1 | C39: 3DA+9 | D39: DFR | E39: No | F39: Yes | G39: Yes | H39: Completed | I39: 46098 | J39: 46103 | K39: SHRIARSHINI | L39: C P | M39: 46112 | N39: Yes | O39: 43.575 | P39: Erection Completed. | Q39: 46197 | R39: 46203 | S39: NASIRUDDIN-2
A40: 38 | B40: 52/2 | C40: 3DA+0 | D40: WFR | E40: No | F40: Yes | G40: Yes | H40: Completed | I40: 46206 | J40: 46208 | K40: SHRIARSHINI | N40: Yes | O40: 35.089 | P40: Erection Completed. | Q40: 46223 | R40: 46230 | S40: NASIRUDDIN-2
...

Sheet Stringing Compiled
A1: S.no | B1: Sec | C1: From AP | D1: To AP | E1: Span (M) | F1: Method | G1: Section Readiness | H1: Insulator Hoisting | I1: P/O Starting Date | J1: P/O Completion Date | K1: P/O | L1: F/S Starting Date | M1: F/S/ Completion Date | N1: Jumpering | O1: Spacering | P1: Clipping | Q1: Length | R1: Status | S1: Gang Name | T1: Gang Strength | U1: Number of Fitters | V1: Hindrance | W1: Remarks
