Workbook
Name \D: '[1]Annex-7,Contingent'!#REF!
Name \I: '[1]Annex-7,Contingent'!#REF!
Name \R: '[1]Annex-7,Contingent'!#REF!
Name KKJ: '[1]Annex-7,Contingent'!#REF!

Sheet TB401 DPR.....
B1: Project Code | D1: TB-401 | F1: Date | H1: =TODAY() -> 46095 | I1: LOA Start Date | L1: 45041 | M1: Business Head (T&D)- India & Sri Lanka | P1: Rajinder Gupta
B2: Project Name | D2: 765KV D/C Fategarh-III Beawar Transmission Line | I2: LOA End Date | L2: 45498 | M2: PCH | P2: Sivaraman Nataraajan
B3: Client Name | D3: Strelite Power | I3: Time Extn | L3: 45498 | M3: Regional Manager | P3: Sandeep Singh Kumar
B4: LE Value | D4: Rs 312 Cr -Supply -Rs 227.5 Cr.; Service.-Rs 84.4 Cr | I4: Planning | L4: Shah Ali Khan | M4: Project Manager | P4: Virender Gupta
A5: Activity | B5: Unit | C5: LOA Qty. | D5: LE Qty | E5: Progress till Last Month | F5: Balance | G5: L2 for Dec'23 | H5: Plan for Dec.'23 | I5: Today's Progress | J5: Month Progress | K5: WIP | L5: Gangs at Present | M5: L2 Till Month-Dec.23 | N5: Progress Till Date | O5: Balance Work | P5: Remarks
A6: Route Alignment | B6: km | C6: 215 | D6: 202 | E6: 167 | F6: =D6-E6 -> 35 | G6: 0 | H6: 35 | M6: 215 | N6: =E6+J6 -> 167 | O6: =D6-N6 -> 35 | P6: 35 Km is hold due to ROW issues
A7: Detailed Survey | B7: km | C7: 215 | D7: 202 | E7: 202 | F7: =D7-E7 -> 0 | G7: 0 | M7: 215 | N7: =E7+J7 -> 202 | O7: =D7-N7 -> 0 | P7: SPTL Approved -202/202-Kms
A8: Check Survey | B8: km | C8: 215 | D8: 202 | E8: 92.704 | F8: =D8-E8 -> 109.296 | G8: 20 | H8: 50 | J8: 17.852 | M8: 160 | N8: =E8+J8 -> 110.556 | O8: =D8-N8 -> 91.444 | P8: 1. Total 7.854 Km is under review of SPTL. 2. Total check survey completed (Field work) 167 Km. 3. Total 60 Km check survey is hold due to row issues & Other issues.
A9: Foundation | B9: Nos | C9: 534 | D9: 521 | E9: 109 | F9: =D9-E9 -> 412 | G9: 75 | H9: 30 | J9: 1 | K9: 4 | L9: 3 | M9: 399 | N9: =E9+J9 -> 110 | O9: =D9-N9 -> 411 | AA9: =65/D9 -> 0.12476008 | AC9: =(D11-C9)/C9 -> -0.024344569 | AD9: =C9*AC9 -> -13 | AE9: =366-318 -> 48 | AF9: =318-12 -> 306
A10: Earthing | B10: Nos | C10: 534 | D10: 521 | E10: 106 | F10: =D10-E10 -> 415 | G10: 75 | H10: 30 | J10: 2 | M10: 399 | N10: =E10+J10 -> 108 | O10: =D10-N10 -> 413 | AA10: =65/D10 -> 0.12476008
A11: Tower Erection | B11: Nos | C11: 534 | D11: 521 | E11: 45 | F11: =D11-E11 -> 476 | G11: 75 | H11: 40 | I11: 2 | J11: 6 | K11: 5 | L11: 5 | M11: 260 | N11: =E11+J11 -> 51 | O11: =D11-N11 -> 470 | P11: 56/2 58/15 Complete | AA11: =65/D11 -> 0.12476008
A12: Tack welding | B12: Nos | C12: 534 | D12: 521 | E12: 15 | F12: =D12-E12 -> 506 | G12: 75 | H12: 40 | I12: 1 | J12: 3 | K12: 1 | L12: 1 | M12: 260 | N12: =E12+J12 -> 18 | O12: =D12-N12 -> 503 | P12: 56/7 complete | AA12: =65/D12 -> 0.12476008
A13: Stringing | B13: Km | C13: 215 | D13: 202 | E13: 0 | F13: =D13-E13 -> 202 | G13: 20 | M13: 25 | N13: =E13+J13 -> 0 | O13: =D13-N13 -> 202 | AA13: =20.635/D13 -> 0.10215347 | AD13: =103/151 -> 0.68211921
AA14: =20.635/D14 -> #DIV/0!

Sheet Eng.
A2: Tower | B2: Tower Design | D2: Test Tower | F2: Balance Structural Drawing. | H2: Tower | I2: Stub & Template Drawings | J2: Foundation
A3: Types | D3: Structural Drawing(BTB+0) | F3: (3M/6M/9M) | H3: Testing | J3: Design/Drg
B4: Target | C4: Status | D4: Target | E4: Status | F4: Target | G4: Status | J4: Target | K4: Status
A5: DA Tower | B5: 45058 | C5: Approved | D5: 45081 | E5: Approved | F5: 45101 | G5: Approved for proto | H5: Completed | I5: Approved | J5: 15-July | K5: Approved
A6: DB Tower | B6: 45076 | C6: Approved | D6: 45137 | E6: Approved | F6: 45126 | G6: Approvedin Cat-B | H6: Completed | I6: Approved for Proto | J6: DB all Fdn. By 25 -July | K6: Approved
A8: DD Tower | B8: 45098 | C8: Approved | D8: 30-Sept. | E8: Approved in Cat -B | F8: 45158 | G8: Approved in Cat -B | H8: Completed | I8: Approved in Cat -B | J8: 45138 | K8: Approved
A9: DC Tower | B9: 45123 | C9: Approved | D9: 45207 | E9: Approved in Cat -B | F9: 45188 | G9: Approved in Cat -B | H9: Completed | I9: Approved in Cat -B | J9: 45163 | K9: Approved

Sheet Fdn (Pkg -G Section -I)
A1: KEC INTERNATIONAL LIMITED | L1: Date: | M1: =TODAY() -> 46095
A2: LILO of 765 Kv DV Fatehgarh 3 Beawar TL
A3: FOUNDATION
A4: Sl. No. | B4: Month Sl. No. | C4: JMC No. | D4: Location No. | E4: Tower Type | F4: Classification | G4: Excavation Start | H4: Dt. of Start | I4: Dt. of Concrete | J4: Name of Sub-Contractor | K4: KEC representative | L4: KEC Section In-Charge | M4: Remarks
A6: 1 | B6: 1 | D6: 32/7 | E6: DA+0 | F6: SANDY | G6: 23.10.23 | H6: 25.10.23 | I6: 28.10.23 | J6: Shakti Construction | K6: Kumar Nayak | L6: Jish C Verghese | M6: Complete
A7: 2 | B7: 2 | D7: 32/5 | E7: DA+6 | F7: SANDY | G7: 29.10.23 | H7: 31.10.23 | I7: 04.11.2023 | J7: Shakti Construction | K7: Kumar Nayak | L7: Jish C Verghese | M7: Complete
A8: 3 | B8: 3 | D8: 32/1 | E8: DA+9 | F8: SANDY | G8: 03.11.23 | H8: 06.11.23 | I8: 10.11.23 | J8: Shakti Construction | K8: Kumar Nayak | L8: Jish C Verghese | M8: Complete
A9: 4 | B9: 4 | D9: 30/2 | E9: DA+0 | F9: SANDY | G9: 13.11.23 | H9: 15.11.23 | I9: 16.11.23 | J9: Shakti Construction | K9: Kumar Nayak | L9: Jish C Verghese | M9: Complete
A10: 5 | B10: 5 | D10: 32/0 | E10: DB2+6 | F10: SANDY | G10: 18.11.23 | H10: 20.11.23 | I10: 28.11.23 | J10: Shakti Construction | K10: Dipesh | L10: Jish C Verghese | M10: Complete
B11: Dec-23
A12: 1 | B12: 6 | D12: 31/3 | E12: DA+0 | F12: SANDY | G12: 28.11.23 | H12: 30.11.23 | I12: 04.12.23 | J12: Shakti Construction | K12: Dipesh | L12: Jish C Verghese | M12: Complete

Sheet TB401 DPR
A1: Project Progress for TB-401/408,Section-II
A2: 765KV D/C Fategarh-III Beawar Transmission Line | D2: TB-401 | G2: LOA Date | I2: Pkg-G -26.04.23 | L2: Completion Period | N2: 45747 | Q2: Date: | R2: =TODAY() -> 46095
D3: TB-408 | I3: Pkg-F - 11.09.23 | L3: Completion Period | N3: 45747
A4: .
A5: Activity | B5: Qty as per LOA | C5: Qty Received | D5: L2 | F5: Overall Progress | H5: Mar'25 | J5: Balance | K5: Apr'25 | O5: Plan | Q5: Remarks
D6: 45656 | E6: Till Mar-25 | F6: As on date | G6: Till Mar-25 | H6: Plan | I6: Actual | J6: As on date | K6: Plan | L6: WIP | M6: Today comp | N6: Actual | O6: 45536 | P6: 45474
A7: Details Survey | B7: 215 | C7: =C8+C9 -> 189.53 | E7: =E8+E9 -> 203 | F7: =F8+F9 -> 199.841 | G7: =G8+G9 -> 199.841
A8: Pkg-G (Section-II) | C8: 101.1 | E8: =215/2 -> 107.5 | F8: 101.1 | G8: 101.1
A9: Pkg-F (Section-II) | C9: 88.43 | E9: =(65+65+41+20)/2 -> 95.5 | F9: 98.741 | G9: 98.741
A10: Check Survey | B10: 215 | C10: =C11+C12 -> 189.53 | D10: =D11+D12 -> 0 | E10: =E11+E12 -> 203 | F10: =F11+F12 -> 189.526 | G10: =G11+G12 -> 184.552 | H10: =H11+H12 -> 14.88 | I10: =I11+I12 -> 6.08 | J10: =J11+J12 -> 0.004 | ... L10: =L11+L12 -> 0 | N10: =N11+N12 -> 4.974 | O10: =O11+O12 -> 0
A11: Pkg-G (Section-II) | C11: 101.1 | E11: =215/2 -> 107.5 | F11: =G11+N11 -> 101.096 | G11: 101.096 | H11: 6.08 | I11: 6.08 | J11: =C11-G11-N11 -> 0.004
A12: Pkg-F (Section-II) | C12: 88.43 | E12: =(65+65+41+20)/2 -> 95.5 | F12: =G12+N12 -> 88.43 | G12: =79.653+3.803 -> 83.456 | H12: 8.8 | J12: =C12-G12-N12 -> 0 | N12: 4.974
A13: Foundation | B13: 534 | C13: =C14+C15 -> 488 | D13: =D14+D15 -> 0 | E13: =E14+E15 -> 488 | F13: =F14+F15 -> 486 | G13: =G14+G15 -> 485 | H13: =H14+H15 -> 9 | I13: =I14+I15 -> 6 | J13: =J14+J15 -> 2 | ... L13: =L14+L15 -> 2 | N13: =N14+N15 -> 1 | O13: =O14+O15 -> 0 | P13: =P14+P15 -> 0
A14: Pkg-G (Section-II) | C14: 265 | E14: 265 | F14: =G14+N14 -> 265 | G14: 265 | H14: 5 | I14: 5 | J14: =C14-G14-N14 -> 0 | S14: 9649905358 | T14: D S Jangid
A15: Pkg-F (Section-II) | C15: 223 | E15: 223 | F15: =G15+N15 -> 221 | G15: 220 | H15: 4 | I15: 1 | J15: =C15-G15-N15 -> 2 | L15: 2 | M15: 1 | N15: 1 | Q15: 46/0 Complete | S15: 7014675307 | T15: jangid
A16: Gang / Worker | K16: 10/180 | L16: 02/55
A17: Erection | B17: 534 | C17: =C18+C19 -> 488 | D17: =D18+D19 -> 0 | E17: =E18+E19 -> 488 | F17: =F18+F19 -> 369 | G17: =G18+G19 -> 365 | H17: =H18+H19 -> 36 | I17: =I18+I19 -> 24 | J17: =J18+J19 -> 119 | ... P17: =P18+P19 -> 0
A18: Pkg-G (Section-II) | C18: 265 | E18: 265 | F18: =G18+N18 -> 201 | G18: 201 | H18: 20 | I18: 11 | J18: =C18-G18-N18 -> 64 | L18: 2
A19: Pkg-F (Section-II) | C19: 223 | E19: 223 | F19: =G19+N19 -> 168 | G19: 164 | H19: 16 | I19: 13 | J19: =C19-G19-N19 -> 55 | L19: 2 | M19: 1 | N19: 4 | Q19: 70/9 Complete
A20: Gang / Worker | K20: 7/240 | L20: 4/241
A21: Stringing Payout | B21: 215 | C21: =C22+C23 -> 189.53 | D21: =D22+D23 -> 0 | E21: =E22+E23 -> 189.53 | F21: =F22+F23 -> 95.792 | G21: =G22+G23 -> 94.743 | H21: =H22+H23 -> 0 | I21: =I22+I23 -> 9.18 | J21: =J22+J23 -> 93.738 | ... O21: =O22+O23 -> 0 | P21: 15
A22: Pkg-G (Section-II) | C22: 101.1 | E22: 101.1 | F22: =G22+N22 -> 52.284 | G22: 52.284 | J22: =C22-G22-N22 -> 48.816
A23: Pkg-F (Section-II) | C23: 88.43 | E23: 88.43 | F23: =G23+N23 -> 43.508 | G23: 42.459 | I23: 9.18 | J23: =C23-G23-N23 -> 44.922 | L23: 0.832 | N23: 1.049
A24: Gang / Worker | L24: 2/154
A25: Stringing Final sag | B25: 215 | C25: =C26+C27 -> 189.53 | D25: =D26+D27 -> 0 | E25: =E26+E27 -> 189.53 | F25: =F26+F27 -> 89.984 | G25: =G26+G27 -> 88.935 | H25: =H26+H27 -> 0 | I25: =I26+I27 -> 14.161 | J25: =J26+J27 -> 99.546 | ... O25: =O26+O27 -> 0 | P25: 15
A26: Pkg-G (Section-II) | C26: 101.1 | E26: 101.1 | F26: =G26+N26 -> 49.703 | G26: 49.703 | I26: 4.981 | J26: =C26-G26-N26 -> 51.397 | L26: =7.562-4.981 -> 2.581
A27: Pkg-F (Section-II) | C27: 88.43 | E27: 88.43 | F27: =G27+N27 -> 40.281 | G27: 39.232 | I27: 9.18 | J27: =C27-G27-N27 -> 48.149 | L27: 3.227 | M27: 1.049 | N27: 1.049 | Q27: 51/0 to 52/0 Complete
A28: Gang / Worker | L28: 2/154

Sheet Foundation (Pkg-F) 
A1: KEC INTERNATIONAL LIMITED | L1: Date: | M1: =TODAY() -> 46095
A2: LILO of 765 Kv DV Fatehgarh 3 Beawar TL
A3: FOUNDATION Pkg -F (Section -II)
A4: Sl. No. | B4: Month Sl. No. | C4: JMC No. | D4: Location No. | E4: Tower Type | F4: Classification | G4: Excavation Start | H4: Dt. of Start | I4: Dt. of Concrete | J4: Name of Sub-Contractor | K4: KEC representative | L4: KEC Section In-Charge | M4: Remarks
B6: 45261
A7: 1 | B7: 1 | D7: 61/3 | E7: DA+6 | F7: DRY | G7: 11.12.23 | H7: 13.12.23 | I7: 14.12.23 | J7: Manoj Sharma | K7: Dipesh | L7: RT Singh | M7: Complete
A8: 2 | B8: 2 | D8: 62/6 | E8: DA+3 | F8: DRY | G8: 08.12.23 | H8: 16.12.23 | I8: 18.12.23 | J8: Shakti Construction | K8: sanjay | L8: Rakesh Pathak | M8: Complete
A9: 3 | B9: 3 | D9: 59/14 | E9: DA+6 | F9: DRY | G9: 13.12.23 | H9: 17.12.23 | I9: 18.12.23 | J9: Manoj Sharma | K9: Dipesh | L9: RT Singh | M9: Complete
A10: 4 | B10: 4 | D10: 62/7 | E10: DA+3 | F10: DRY | G10: 08.12.23 | H10: 19.12.23 | I10: 21.12.23 | J10: Shakti Construction | K10: Umesh Kumar | L10: Rakesh Pathak | M10: Complete
A11: 5 | B11: 5 | D11: 59/13 | E11: DA+3 | F11: DRY | G11: 17.12.23 | H11: 21.12.23 | I11: 21.12.23 | J11: Manoj Sharma | K11: Dipesh | L11: RT Singh | M11: Complete
A12: 6 | B12: 6 | D12: 63/8 | E12: DA+3 | F12: DRY | G12: 08.12.23 | H12: 22.12..23 | I12: 24.12.23 | J12: Mahadev Eng | K12: Dipesh | L12: Rakesh Pathak | M12: Complete
A13: 7 | B13: 7 | D13: 59/10 | E13: DA+0 | F13: DRY | G13: 20.12.23 | H13: 23.12.23 | I13: 24.12.23 | J13: Manoj Sharma | K13: Dipesh | L13: RT Singh | M13: Complete
A14: 8 | B14: 8 | D14: 62/5 | E14: DA+0 | F14: DRY | G14: 18.12.23 | H14: 22.12..23 | I14: 25.12.23 | J14: Shakti Construction | K14: sanjay | L14: Rakesh Pathak | M14: Complete
A15: 9 | B15: 9 | D15: 59/9 | E15: DA+3 | F15: DRY | G15: 21.12.23 | H15: 25.12.23 | I15: 26.12.23 | J15: Manoj Sharma | K15: Dipesh | L15: RT Singh | M15: Complete
A16: 10 | B16: 10 | D16: 60/9 | E16: DA+3 | F16: DRY | G16: 20.12.23 | H16: 26.12.23 | I16: 27.12.23 | J16: Imran | K16: Ganesh | L16: Sumit | M16: Complete
A17: 11 | B17: 11 | D17: 62/4 | E17: DA+3 | F17: DRY | G17: 08.12.23 | H17: 26.12.23 | I17: 28.12.23 | J17: Shakti Construction | K17: sanjay | L17: Rakesh Pathak | M17: Complete | N17: Excavation & Rod binding - Amirul
A18: 12 | B18: 12 | D18: 59/8 | E18: DB+3 | F18: DRY | G18: 24.12.23 | H18: 27.12.23 | I18: 28.12.23 | J18: Manoj Sharma | K18: Kumar nayak | L18: Sumit | M18: Complete
A19: 13 | B19: 13 | D19: 59/6 | E19: DA+3 | F19: DFR | G19: 17.12.23 | H19: 27.12.23 | I19: 29.12.23 | J19: OM Const | K19: Umesh Kumar | L19: Rakesh Pathak | M19: Complete
A20: 14 | B20: 14 | D20: 63/6 | E20: DA+3 | F20: DRY | G20: 18.12.23 | H20: 27.12.23 | I20: 29.12.23 | J20: Mahadev Eng | K20: Dipesh | L20: Rakesh Pathak | M20: Complete
A21: 15 | B21: 15 | D21: 60/8 | E21: DA+0 | F21: DRY | G21: 24.12.23 | H21: 26.12.23 | I21: 29.12.23 | J21: Imran | K21: Ganesh | L21: Sumit | M21: Complete
A22: 16 | B22: 16 | D22: 59/7 | E22: DA+3 | F22: DRY | G22: 25.12.23 | H22: 29.12.23 | I22: 30.12.23 | J22: Manoj Sharma | K22: Kumar nayak | L22: RT Singh | M22: Complete
A23: 17 | B23: 17 | D23: 59/5 | E23: DA+3 | F23: DFR | G23: 15.12.23 | H23: 25.12.23 | I23: 31.12.23 | J23: OM Const | K23: Umesh Kumar | L23: RT Singh | M23: Complete
A24: 18 | B24: 18 | D24: 62/3 | E24: DA+0 | F24: DRY | G24: 25.12.23 | H24: 30.12.23 | I24: 31.12.23 | J24: Shakti Construction | K24: sanjay | L24: Rakesh Pathak | M24: Complete
B25: 45292
A26: 19 | B26: 1 | D26: 59/12 | E26: DA+6 | F26: DFR | G26: 19.12.23 | H26: 04.01.24 | I26: 05.01.24 | J26: Manoj Sharma | K26: Kumar nayak | L26: RT Singh | M26: Complete | N26: 284
A27: 20 | B27: 2 | D27: 60/7 | E27: DA+3 | F27: DRY | G27: 24.12.23 | H27: 01.01.24 | I27: 05.01.24 | J27: Imran | K27: Ganesh | L27: RT Singh | M27: Complete
A28: 21 | B28: 3 | D28: 62/2 | E28: DA+3(RC) | F28: DRY | G28: 29.12.23 | H28: 02.01.24 | I28: 05.01.24 | J28: Shakti Construction | K28: sanjay | L28: Rakesh Pathak | M28: Complete
A29: 22 | B29: 4 | D29: 59/3 | E29: DA+3(RC) | F29: DFR | G29: 30.12.23 | H29: 03.01.24 | I29: 05.01.24 | J29: OM Const | K29: Umesh Kumar | L29: RT Singh | M29: Complete
A30: 23 | B30: 5 | D30: 64/0 | E30: DB2+0 | F30: DRY | G30: 20.12.23 | H30: 04.01.24 | I30: 08.01.24 | J30: Mahadev Eng | K30: Dipesh | L30: Rakesh Pathak | M30: Complete
A31: 24 | B31: 6 | D31: 57/3 | E31: DA+0 | F31: DRY | G31: 04.01.24 | H31: 06.01.24 | I31: 08.01.24 | J31: OM Const | L31: RT Singh | M31: Complete
A32: 25 | B32: 7 | D32: 60/5 | E32: DA+3 | F32: DRY | G32: 02.01.24 | H32: 08.01.24 | I32: 09.01.24 | J32: Manoj Sharma | K32: Kumar nayak | L32: RT Singh | M32: Complete | N32: 249
A33: 26 | B33: 8 | D33: 65/2 | E33: DA+0 | F33: DRY | G33: 30.12.23 | H33: 08.01.24 | I33: 10.01.24 | J33: Veerteja Enterprises | K33: Rakesh Pathak | L33: Rakesh Pathak | M33: Complete
A34: 27 | B34: 9 | D34: 62/11 | E34: DA+3 | F34: DRY | G34: 05.01.24 | H34: 09.01.24 | I34: 10..01.24 | J34: Shakti Construction | K34: Rakesh Pathak | L34: Rakesh Pathak | M34: Complete
A35: 28 | B35: 10 | D35: 65/11 | E35: DA+0 | F35: DRY | G35: 05.01.24 | H35: 09.01.24 | I35: 10.01.24 | J35: Bhati Const. | K35: R Pandey | L35: Rakesh Pathak | M35: Complete
A36: 29 | B36: 11 | D36: 60/6 | E36: DA+0 | F36: DRY | G36: 7.0124 | H36: 10.01.24 | I36: 11.01.24 | J36: Manoj Sharma | K36: Kumar nayak | L36: RT Singh | M36: Complete
A37: 30 | B37: 12 | D37: 57/2 | E37: DA+3 | F37: DRY | G37: 07.01.24 | H37: 09.01.24 | I37: 11.01.24 | J37: OM Const | K37: RT Singh | L37: RT Singh | M37: Complete | N37: =249+74 -> 323
A38: 31 | B38: 13 | D38: 62/10 | E38: DA+0 | F38: DFR | G38: 06.01.24 | H38: 11.01.24 | I38: 13.01.24 | J38: Shakti Construction | K38: Rakesh Pathak | L38: Rakesh Pathak | M38: Complete
A39: 32 | B39: 14 | D39: 65/9 | E39: DA+0 | F39: DRY | G39: 05.01.24 | H39: 11.01.24 | I39: 13.01.24 | J39: Bhati Const. | K39: Rakesh Pathak | L39: Rakesh Pathak | M39: Complete
A40: 33 | B40: 15 | D40: 57/4 | E40: DA+0 | F40: SANDY | G40: 07.01.24 | H40: 12.01.24 | I40: 45305 | J40: OM Const | K40: RT Singh | L40: RT Singh | M40: Complete
A41: 34 | B41: 16 | D41: 64/4 | E41: DA+3 | F41: DRY | G41: 09.01.24 | H41: 45304 | I41: 45305 | J41: Mahadev Eng | L41: Rakesh Pathak | M41: Complete
...

Sheet Earthing (PKG-F)
A1: KEC INTERNATIONAL LIMITED
A2: LILO of 765 Kv DV Fatehgarh 3 Beawar TL
A3: Earthing
A4: Sl. No. | B4: Cum S No | C4: Location No. | D4: Tower Type | E4: Classification | F4: Type of Earthing | G4: Earthing | H4: Name of Sub-Contractor | I4: Check list
B6: 45261
A7: 1 | B7: 1 | C7: 61/3 | D7: DA+6 | E7: DRY | F7: Pipe Type | G7: 18.12.23 | H7: Manoj Sharma
A8: 2 | B8: 2 | C8: 62/4 | D8: DA+3 | E8: DRY | F8: Pipe Type | G8: 31.12.23 | H8: Shakti Const.
B9: 45292
A10: 3 | B10: 1 | C10: 59/7 | D10: DA+3 | E10: DRY | F10: Pipe Type | G10: 03.01.24 | H10: Manoj Sharma
A11: 4 | B11: 2 | C11: 59/8 | D11: DB+3 | E11: DRY | F11: Pipe Type | G11: 03.01.24 | H11: Manoj Sharma
A12: 5 | B12: 3 | C12: 59/9 | D12: DA+3 | E12: DRY | F12: Pipe Type | G12: 03.01.24 | H12: Manoj Sharma
A13: 6 | B13: 4 | C13: 59/10 | D13: DA+0 | E13: DRY | F13: Pipe Type | G13: 03.01.24 | H13: Manoj Sharma
A14: 7 | B14: 5 | C14: 59/13 | D14: DA+3 | E14: DRY | F14: Pipe Type | G14: 03.01.24 | H14: Manoj Sharma
A15: 8 | B15: 6 | C15: 59/14 | D15: DA+6 | E15: DRY | F15: Pipe Type | G15: 03.01.24 | H15: Manoj Sharma
A16: 9 | B16: 7 | C16: 59/5 | D16: DA+3 | E16: DFR | F16: Counter Poise | G16: 05.01.24 | H16: om Const.
A17: 10 | B17: 8 | C17: 59/6 | D17: DA+3 | E17: DFR | F17: Counter Poise | G17: 05.01.24 | H17: om Const.
A18: 11 | B18: 9 | C18: 60/7 | D18: DA+3 | E18: DRY | F18: Pipe Type | G18: 06.01.24 | H18: Imran
A19: 12 | B19: 10 | C19: 60/8 | D19: DA+0 | E19: DRY | F19: Pipe Type | G19: 06.01.24 | H19: Imran
A20: 13 | B20: 11 | C20: 60/9 | D20: DA+3 | E20: DRY | F20: Pipe Type | G20: 06.01.24 | H20: Imran
A21: 14 | B21: 12 | C21: 62/2 | D21: DA+3(RC) | E21: DRY | F21: Pipe Type | G21: 07.01.24 | H21: Shakti Const.
... A43: 36 | B43: 34 | C43: 55/6 | D43: DA+0 RC | E43: SANDY | F43: Pipe Type | G43: 29.01.24 | H43: Imran
B44: Feb-24
A45: 37 | B45: 1 | C45: 64/8 | D45: DA+3 | E45: DRY | F45: Pipe Type | G45: 01.02.24 | H45: Veerteja
A46: 38 | B46: 2 | C46: 60/10 | D46: DA+0 | E46: DFR | F46: Counter Poise | G46: 02.02.24 | H46: Manoj Sharma
A47: 39 | B47: 3 | C47: 60/11 | D47: DA+3 | E47: DRY | F47: Pipe Type | G47: 02.02.24 | H47: Manoj Sharma
A48: 40 | B48: 4 | C48: 61/0 | D48: DB2+0 | E48: DRY | F48: Pipe Type | G48: 02.02.24 | H48: Manoj Sharma
A49: 41 | B49: 5 | C49: 61/1 | D49: DA+6 | E49: DFR | F49: Counter Poise | G49: 02.02.24 | H49: Manoj Sharma
A50: 42 | B50: 6 | C50: 61/2 | D50: DA+6 | E50: DFR | F50: Counter Poise | G50: 02.02.24 | H50: Manoj Sharma
A51: 43 | B51: 7 | C51: 55/3 | D51: DA+0 | E51: SANDY | F51: Pipe Type | G51: 02.02.24 | H51: Imran
A52: 44 | B52: 8 | C52: 55/7 | D52: DA+0 | E52: SANDY | F52: Pipe Type | G52: 02.02.24 | H52: Imran
A53: 45 | B53: 9 | C53: 52/5 | D53: DA+9 RC | E53: SANDY | F53: Pipe Type | G53: 05.02.24 | H53: Imran
A54: 46 | B54: 10 | C54: 52/6 | D54: DA+6 | E54: SANDY | F54: Pipe Type | G54: 08.02.24 | H54: Imran
A55: 47 | B55: 11 | C55: 65/6 | D55: DA+0 | E55: DRY | F55: Pipe Type | G55: 09.02.24 | H55: Bhati Const.
A56: 48 | B56: 12 | C56: 65/5 | D56: DA+0 | E56: DRY | F56: Pipe Type | G56: 09.02.24 | H56: Bhati Const.
... A87: 79 | B87: 43 | C87: 52/9 | D87: DA+3 | E87: SANDY | F87: Pipe Type | G87: 22.02.24 | H87: Imran
A88: 80 | B88: 44 | C88: 52/8 | D88: DA+6 | E88: SANDY | F88: Pipe Type | G88: 22.02.24 | H88: Imran | L88: =126+84 -> 210
A89: 81 | B89: 45 | C89: 63/3 | D89: DA+3 | E89: DFR | F89: Pipe Type | G89: 22.02.24 | H89: Shakti Const.
A90: 82 | B90: 46 | C90: 67/1 | D90: DA+0 | E90: DRY | F90: Pipe Type | G90: 13.02.24 | H90: Bhati Const.
A91: 83 | B91: 47 | C91: 60/1 | D91: DA+6 | E91: DRY | F91: Pipe Type | G91: 23.02.24 | H91: om Const.
A92: 84 | B92: 48 | C92: 53/5 | D92: DA+3 | E92: SANDY | F92: Pipe Type | G92: 25.02.24 | H92: Imran
...

Sheet Project Details
A1: Project Code | B1: Project Name | C1: Client Name | D1: NOA Start Date | E1: LOA End Date | F1: Planning Engineer | G1: PCH | H1: Regional Manager | I1: Project Manger | J1: Section Incharge | K1: Supervisor
A2: TB401 | B2: 765 KV Fatehgarh III to Beawer 2nd Transmission Line, PKG G | C2: Resonia Limited | D2: 26/4/2023 | E2: 46022 | F2: Mr Santosh Pandey | G2: Mr. Sanjay Kumar Gupta | H2: Mr. Sandeep Singh Kumar | I2: Mr. Virender Gupta | J2: Sumit Kumar | K2: Pradeep Kumar
J3: Rajeev Kumar | K3: Vikas Kumar
J4: Vivek Shukla | K4: Ganesh Singh
J5: Vijay Yadav | K5: Dineshwar Mahto
J6: Ram Tirath Singh | K6: Kamla Pal Prasad
J7: Jitendra Saini | K7: Bisun Saw
K8: Shakib Hussain
K9: Umesh Prasad
K10: Prince Kumar Nirala
K11: Pramod Kumar Sahoo
K12: Jainath Mahto
K13: Rajesh Pal
K14: Ramji Tanti
K15: Rakesh Pramanik
K16: Sam Mahammad
K17: Suresh Kumar Pal
K18: Hulas Kumar Mahto
K19: Akash Dadarao Thul
... K40: Jaylal Mahto

Sheet Progress
A1: Project Code | B1: TB401 | E1: LOA Start Date | F1: 26.04.23 | G1: SBU Head | H1: Mr. Rajender Gupta | I1: Head T&D-North | J1: Sanjay K. Gupta
A2: Project Name | B2: 765KV DC Fateggarh III to Beawar (2nd) TL | E2: LOA Completion Date | F2: 31.03.25 | G2: Regional Manager | H2: Mr Sandeep Kumar Singh | I2: Planning Engineer | J2: Santosh Pandey
A3: Client Name | B3: RESONIA LIMITED | E3: Expected Completion | F3: 31.12.25 | G3: Project Manager | H3: Mr Virender Gupta | I3: Date | J3: =TODAY() -> 46095
A4: Activity | B4: Final Estimated Quantity | C4: Cumulative L2 Till Last Month | D4: Cumulative Progress Till last Month | E4: L2 For Present Month | F4: Plan for the Month | G4: Today's Progress | H4: Progress till Date for the Month | I4: L2 Till Current Month | J4: Completed Till Date | K4: Balance Work | L4: Under Progress | M4: Gangs at present | N4: Remarks
A5: FOUNDATION | B5: 521 | C5: 521 | D5: 521 | E5: 0 | F5: 0 | I5: 0 | J5: =D5+H5 -> 521 | K5: =B5-J5 -> 0 | O5: =J5/B5 -> 1
A6: EARTHING | B6: 521 | C6: 521 | D6: 521 | E6: 0 | F6: 0 | I6: 0 | J6: =D6+H6 -> 521 | K6: =B6-J6 -> 0
A7: ERECTION | B7: 521 | C7: 521 | D7: 521 | E7: 0 | F7: 0 | I7: 0 | J7: =D7+H7 -> 521 | K7: =B7-J7 -> 0 | O7: =J7/B7 -> 1
A8: TACK WELDING | B8: 521 | C8: 521 | D8: 507 | E8: 0 | F8: 14 | H8: 2 | I8: 0 | J8: =D8+H8 -> 509 | K8: =B8-J8 -> 12
A9: Strg (Pay-Out) | B9: 202.13 | C9: 202 | D9: 191.539 | E9: 0 | F9: 10.59 | G9: 3.172 | H9: =2.877+3.172 -> 6.049 | I9: 0 | J9: =D9+H9 -> 197.588 | K9: =B9-J9 -> 4.542 | L9: 4.543 | M9: 3 | O9: =J9/B9 -> 0.97752931
A10: Strg (Final Sag) | B10: 202.13 | C10: 202 | D10: 189.1 | E10: 0 | F10: 13.03 | H10: 5.317 | I10: 0 | J10: =D10+H10 -> 194.417 | K10: =B10-J10 -> 7.713 | L10: 3.172 | M10: 3
A11: Stringing OPGW | B11: 202.13 | C11: 202 | D11: 191.399 | E11: 0 | F11: 10.69 | H11: =5.552+0.636 -> 6.188 | I11: 0 | J11: =D11+H11 -> 197.587 | K11: =B11-J11 -> 4.543 | L11: 4.543 | M11: 1 | O11: =SUM(O5:O10)/3 -> 0.99250977
O12: =SUM(O5:O11)/4 -> 0.99250977
H91: 11.02.26 | L91: 4th Phase WIP& Top Phase Final Sag

Sheet Foundation (Pkg-G)
A1: KEC INTERNATIONAL LIMITED | K1: Date: | L1: =TODAY() -> 46095
A2: LILO of 765 Kv DV Fatehgarh 3 Beawar TL
A3: FOUNDATION Pkg -G (Section -II)
A4: Sl. No. | B4: Month Sl. No. | C4: Location No. | D4: Tower Type | E4: Classification | F4: Excavation Start | G4: Dt. of Start | H4: Dt. of complete | I4: Name of Sub-Contractor | J4: KEC representative | K4: KEC Section In-Charge | L4: Remarks
B6: July-23
A7: 1 | B7: 1 | C7: 58/12 | D7: DA+0 | E7: DRY | G7: 14.07.2023 | H7: 15.07.2023 | I7: Mahadev engg. | J7: Mr. Mahamaya | K7: Mr. Shah Ali Khan | L7: Complete
A8: =A7+1 -> 2 | B8: 2 | C8: 59/1 | D8: DA+0 | E8: DRY | G8: 19.07.2023 | H8: 20.07.2023 | I8: Manoj Sharma | J8: Mr Manoj | K8: Mr. Shah Ali Khan | L8: Complete
A9: =A8+1 -> 3 | B9: 3 | C9: 58/14 | D9: DA+0 | E9: DRY | G9: 17.07.2023 | H9: 20.07.2023 | I9: Mahadev engg. | J9: Mr Manoj | K9: Mr. Shah Ali Khan | L9: Complete
A10: =A9+1 -> 4 | B10: 4 | C10: 59/3 | D10: DA+0 | E10: DRY | G10: 17.07.2023 | H10: 29.07.2023 | I10: Manoj Sharma | J10: Mr. Mahamaya | K10: Mr. Shah Ali Khan | L10: Complete
A11: =A10+1 -> 5 | B11: 5 | C11: 58/9 | D11: DA+0 | E11: DRY | G11: 26.07.2023 | H11: 30.07.2023 | I11: Mahadev engg. | J11: RT Singh | K11: Mr. Shah Ali Khan | L11: Complete
B12: Aug-23
A13: =A11+1 -> 6 | B13: 1 | C13: 59/2 | D13: DA+0 | E13: DRY | G13: 01.08.23 | H13: 03.08.23 | I13: Manoj Sharma | J13: Mr. Mahamaya | K13: Mr. Shah Ali Khan | L13: Complete
A14: =A13+1 -> 7 | B14: 2 | C14: 58/1 | D14: DA+0 | E14: DRY | G14: 02.08.2023 | H14: 04.08.2023 | I14: Mahadev engg. | J14: RT Singh | K14: Mr. Shah Ali Khan | L14: Complete
A15: =A14+1 -> 8 | B15: 3 | C15: 59/6 | D15: DA+0 | E15: DRY | G15: 04.08.2023 | H15: 06.08.2023 | I15: Manoj Sharma | J15: Mr. Mahamaya | K15: Mr. Shah Ali Khan | L15: Complete
A16: =A15+1 -> 9 | B16: 4 | C16: 58/3 | D16: DA+3 | E16: DRY | G16: 04.08.2023 | H16: 06.08.2023 | I16: Mahadev engg. | J16: RT Singh | K16: Mr. Rajesh Yadav | L16: Complete
A17: =A16+1 -> 10 | B17: 5 | C17: 51/7 | D17: DA+3 | E17: DFR | G17: 08.08.23 | H17: 09.08.23 | I17: Vaishali Const | J17: Dipesh Das | K17: Mr. Ujjawal Nirala | L17: Complete
A18: =A17+1 -> 11 | B18: 6 | C18: 58/10 | D18: DA+3 | E18: DRY | G18: 09.08.23 | H18: 10.08.2023 | I18: Mahadev engg. | J18: RT Singh | K18: RT Singh | L18: Complete
A19: =A18+1 -> 12 | B19: 7 | C19: 57/9 | D19: DA+0 | E19: DRY | G19: 09.08.23 | H19: 11.08.2023 | I19: Manoj Sharma | J19: Mr. Mahamaya | K19: RT Singh | L19: Complete
A20: =A19+1 -> 13 | B20: 8 | C20: 58/5 | D20: DA+3 | E20: DRY | G20: 12.08.23 | H20: 13.08.2023 | I20: Mahadev engg. | J20: RT Singh | K20: RT Singh | L20: Complete
A21: =A20+1 -> 14 | B21: 9 | C21: 57/10 | D21: DA+0 | E21: DRY | G21: 11.08.23 | H21: 13.08.2023 | I21: Manoj Sharma | J21: RT Singh | K21: RT Singh | L21: Complete
A22: =A21+1 -> 15 | B22: 10 | C22: 51/5 | D22: DA+0 | E22: DRY | G22: 13.08.23 | H22: 14.08.23 | I22: Vaishali Const | J22: Dipesh Das | K22: Mr. Ujjawal Nirala | L22: Complete
A23: =A22+1 -> 16 | B23: 11 | C23: 52/2 | D23: DA+3 | E23: DFR | G23: 13.08.23 | H23: 16.08.23 | I23: Khewanjrai Electrical | J23: Dipesh Das | K23: Mr. Ujjawal Nirala | L23: Complete
A24: =A23+1 -> 17 | B24: 12 | C24: 57/13 | D24: DA+0 | E24: DRY | G24: 14.08.23 | H24: 16.08.23 | I24: Manoj Sharma | J24: RT Singh | K24: RT Singh | L24: Complete
A25: =A24+1 -> 18 | B25: 13 | C25: 58/11 | D25: DA+3 | E25: DRY | G25: 16.08.23 | H25: 17.08.23 | I25: Mahadev engg. | J25: RT Singh | K25: RT Singh | L25: Complete
... A46: =A45+1 -> 39 | B46: 34 | C46: 59/5 | D46: DA+0 | E46: DRY | G46: 30.08.23 | H46: 31.08.23 | I46: Mahadev engg. | J46: Mahmya Pratap | K46: Mr. Shah Ali Khan | L46: Complete
B47: 45170
A48: 40 | B48: 1 | C48: 57/2 | D48: DA+0 | E48: DRY | F48: 27.08.23 | G48: 30.08.23 | H48: 01.09.23 | I48: Manoj Sharma | J48: Jitendra Saini | K48: RT Singh | L48: Complete
A49: =A48+1 -> 41 | B49: 2 | C49: 61/1 | D49: DA+0 | E49: DRY | F49: 29.08.23 | G49: 02.09.23 | H49: 03.09.23 | I49: Mahadev engg. | K49: Mr. Shah Ali Khan | L49: Complete
A50: =A49+1 -> 42 | B50: 3 | C50: 53/4 | D50: DA+3 | E50: DRY | F50: 30.08.23 | G50: 02.09.23 | H50: 05.09.23 | I50: Vaishali Const | J50: Dipesh Das | K50: Mr. Ujjawal Nirala | L50: Complete
A51: =A50+1 -> 43 | B51: 4 | C51: 61/2 | D51: DA+0 | E51: DRY | F51: 02.09.23 | G51: 04.09.23 | H51: 05.09.23 | I51: Mahadev engg. | K51: Mr. Shah Ali Khan | L51: Complete
A52: =A51+1 -> 44 | B52: 5 | C52: 48/1 | D52: DA+0 | E52: DRY | F52: 31.08.23 | G52: 04.09.23 | H52: 06.09.23 | I52: Shri Bhadariyarai Enterprises | J52: Dipesh Das | K52: Mr. Ujjawal Nirala | L52: Complete
A53: =A52+1 -> 45 | B53: 6 | C53: 55/9 | D53: DA+3 | E53: DRY | F53: 31.08.23 | G53: 03.09.23 | H53: 06.09.23 | I53: Nurul Amin | J53: Ganesh Rajput | K53: RT Singh | L53: Complete
A54: =A53+1 -> 46 | B54: 7 | C54: 58/2 | D54: DA+0 | E54: DRY | F54: 04.09.23 | G54: 08.09.23 | H54: 09.09.23 | I54: Mahadev engg. | J54: RT Singh | K54: RT Singh | L54: Complete
A55: =A54+1 -> 47 | B55: 8 | C55: 47/2 | D55: DA+0 | E55: DFR | F55: 04.09.23 | G55: 06.09.23 | H55: 09.09.23 | I55: B S Electrical | J55: Dipesh Das | K55: Mr. Ujjawal Nirala | L55: Complete
A56: =A55+1 -> 48 | B56: 9 | C56: 57/1 | D56: DA+3 | E56: DRY | F56: 01.09.23 | G56: 09.09.23 | H56: 11.09.23 | I56: Manoj Sharma | J56: Jitendra Saini | K56: RT Singh | L56: Complete
A57: =A56+1 -> 49 | B57: 10 | C57: 48/2 | D57: DA+3 | E57: DRY | F57: 05.09.23 | G57: 10.09.23 | H57: 11.09.23 | I57: Shri Bhadariyarai Enterprises | J57: Dipesh Das | K57: Mr. Ujjawal Nirala | L57: Complete
A58: =A57+1 -> 50 | B58: 11 | C58: 51/10 | D58: DA+3 | E58: DFR | F58: 08.09.23 | G58: 10.09.23 | H58: 12.09.23 | I58: Amirul Islam | J58: Ganesh Rajput | K58: RT Singh | L58: Complete
A59: =A58+1 -> 51 | B59: 12 | C59: 57/3 | D59: DA+0 | E59: DRY | F59: 04.09.23 | G59: 12.09.23 | H59: 14.09.23 | I59: Manoj Sharma | J59: RT Singh | K59: RT Singh | L59: Complete
A60: =A59+1 -> 52 | B60: 13 | C60: 72/3 | D60: DA+0 | E60: DRY | F60: 08.09.23 | G60: 13.09.23 | H60: 14.09.23 | I60: Mahadev engg. | J60: Manoj | K60: Mr. Shah Ali Khan | L60: Complete
A61: =A60+1 -> 53 | B61: 14 | C61: 43/4 | D61: DA+9 | E61: DRY | F61: 09.09.23 | G61: 12.09.23 | H61: 14.09.23 | I61: Shakti Construction | J61: Dipesh Das | K61: Rakesh Pathak | L61: Complete
...

Sheet Earthing (PKG-G)
B1: KEC INTERNATIONAL LIMITED
B2: LILO of 765 Kv DV Fatehgarh 3 Beawar TL
B3: Earthing
A4: Cum S No | B4: Sl. No. | C4: Location No. | D4: Tower Type | E4: Classification | F4: Type of Earthing | G4: Earthing | H4: Name of Sub-Contractor | I4: Check list
B6: 45139
A7: 1 | B7: 1 | C7: 58/1 | D7: DA+0 | E7: DRY | F7: Pipe Type | G7: 16.08.23 | H7: Mahadev engg. | I7: Check list submitted
A8: 2 | B8: 2 | C8: 58/11 | D8: DA+3 | E8: DRY | F8: Pipe Type | G8: 20.08.23 | H8: Mahadev engg. | I8: Check list submitted
A9: 3 | B9: 3 | C9: 58/3 | D9: DA+3 | E9: DRY | F9: Pipe Type | G9: 24.8.23 | H9: Mahadev engg. | I9: Check list submitted
A10: 4 | B10: 4 | C10: 58/5 | D10: DA+3 | E10: DRY | F10: Pipe Type | G10: 24.8.23 | H10: Mahadev engg. | I10: Check list submitted
A11: 5 | B11: 5 | C11: 57/10 | D11: DA+0 | E11: DRY | F11: Pipe Type | G11: 24.8.23 | H11: Manoj Sharma | I11: Check list submitted
A12: 6 | B12: 6 | C12: 57/13 | D12: DA+0 | E12: DRY | F12: Pipe Type | G12: 24.8.23 | H12: Manoj Sharma | I12: Check list submitted
A13: 7 | B13: 7 | C13: 57/11 | D13: DA+0 | E13: DRY | F13: Pipe Type | G13: 24.8.23 | H13: Manoj Sharma | I13: Check list submitted
A14: 8 | B14: 8 | C14: 57/12 | D14: DA+3 | E14: DRY | F14: Pipe Type | G14: 24.8.23 | H14: Manoj Sharma | I14: Check list submitted
A15: 9 | B15: 9 | C15: 58/6 | D15: DA+3 | E15: DRY | F15: Pipe Type | G15: 24.8.23 | H15: Mahadev engg. | I15: Check list submitted
A16: 10 | B16: 10 | C16: 57/8 | D16: DA+3 | E16: DRY | F16: Pipe Type | G16: 25.08.23 | H16: Manoj Sharma | I16: Check list submitted
A17: 11 | B17: 11 | C17: 52/2 | D17: DA+3 | E17: DFR | F17: Counter Poise | G17: 25.08.23 | H17: Khewanjrai Electrical | I17: Check list submitted
A18: 12 | B18: 12 | C18: 57/9 | D18: DA+0 | E18: DRY | F18: Pipe Type | G18: 25.08.23 | H18: Manoj Sharma | I18: Check list submitted
... A28: 22 | B28: 22 | C28: 52/4 | D28: DA+0 | E28: DFR | F28: Counter Poise | G28: 31.08.23 | H28: Khewanjrai Electrical | I28: Check list submitted
B29: 45170
A30: 23 | B30: 1 | C30: 61/1 | D30: DA+0 | E30: DRY | F30: Pipe Type | G30: 03.09.2023 | H30: Mahadev engg. | I30: Check list submitted
A31: =A30+1 -> 24 | B31: 2 | C31: 59/5 | D31: DA+0 | E31: DRY | F31: Pipe Type | G31: 05.09.23 | H31: Mahadev engg. | I31: Check list submitted
A32: =A31+1 -> 25 | B32: 3 | C32: 61/2 | D32: DA+0 | E32: DRY | F32: Pipe Type | G32: 06.09.23 | H32: Mahadev engg. | I32: Check list submitted
A33: =A32+1 -> 26 | B33: 4 | C33: 58/2 | D33: DA+0 | E33: DRY | F33: Pipe Type | G33: 10.09.23 | H33: Mahadev engg. | I33: Check list submitted
A34: =A33+1 -> 27 | B34: 5 | C34: 59/1 | D34: DA+0 | E34: DRY | F34: Pipe Type | G34: 10.09.23 | H34: Manoj Sharma | I34: Check list submitted
A35: =A34+1 -> 28 | B35: 6 | C35: 59/3 | D35: DA+0 | E35: DRY | F35: Pipe Type | G35: 10.09.23 | H35: Manoj Sharma | I35: Check list submitted
A36: =A35+1 -> 29 | B36: 7 | C36: 59/2 | D36: DA+0 | E36: DRY | F36: Pipe Type | G36: 10.09.23 | H36: Manoj Sharma | I36: Check list submitted
A37: =A36+1 -> 30 | B37: 8 | C37: 59/6 | D37: DA+0 | E37: DRY | F37: Pipe Type | G37: 10.09.23 | H37: Manoj Sharma | I37: Check list submitted
A38: =A37+1 -> 31 | B38: 9 | C38: 53/3 | D38: DA+3 | E38: DRY | F38: Pipe Type | G38: 12.09.23 | H38: Vaishali Const | I38: Check list submitted
A39: =A38+1 -> 32 | B39: 10 | C39: 53/4 | D39: DA+3 | E39: DRY | F39: Pipe Type | G39: 12.09.23 | H39: Vaishali Const | I39: Check list submitted
A40: =A39+1 -> 33 | B40: 11 | C40: 47/3 | D40: DA+0 | E40: DFR | F40: Counter Poise | G40: 18.09.23 | H40: B S Electrical | I40: received
A41: =A40+1 -> 34 | B41: 12 | C41: 47/2 | D41: DA+0 | E41: DFR | F41: Counter Poise | G41: 18.09.23 | H41: B S Electrical | I41: received
A42: =A41+1 -> 35 | B42: 13 | C42: 51/10 | D42: DA+3 | E42: DFR | F42: Counter Poise | G42: 19.09.23 | H42: Nurul Amin | I42: received
... A57: =A56+1 -> 50 | B57: 28 | C57: 55/10 | D57: DA+3 | E57: DRY | F57: Pipe Type | G57: 29.09.23 | H57: Nurul Amin | I57: Not received
A58: =A57+1 -> 51 | B58: 29 | C58: 44/4 | D58: DA+0 | E58: WFR | F58: Counter Poise | G58: 30.09.23 | H58: B S Electrical
A59: =A58+1 -> 52 | B59: 30 | C59: 44/2 | D59: DA+0 | E59: SANDY | F59: Pipe Type | G59: 30.09.23 | H59: Shakti Construction
B60: 45200
A61: 53 | B61: 1 | C61: 50/3 | D61: DA+0 | E61: DFR | F61: Counter Poise | G61: 01.10.23 | H61: Shri Bhadariyarai Enterprises
A62: =A61+1 -> 54 | B62: 2 | C62: 72/3 | D62: DA+0 | E62: DRY | F62: Pipe Type | G62: 01.10.23 | H62: Mahadev engg.
A63: =A62+1 -> 55 | B63: 3 | C63: 72/4 | D63: DA+0 | E63: DRY | F63: Pipe Type | G63: 01.10.23 | H63: Mahadev engg.
A64: =A63+1 -> 56 | B64: 4 | C64: 72/5 | D64: DA+0 | E64: DRY | F64: Pipe Type | G64: 01.10.23 | H64: Mahadev engg.
...

Sheet  Benching Status-G
A1: RC, Benching & Revetment Locations
A2: Sl No. | B2: RC | C2: Loc No. | D2: Tower Type | E2: CP Position Up/Down | F2: Raised Chimney | G2: Chimney Extension | K2: Submitted Benching Volume (Cum) | M2: Approved Benching Volume (Cum) | O2: Approval Date | P2: JMC NO | Q2: JMC Date
G4: A | H4: B | I4: C | J4: D | K4: Cutting | L4: Filling | M4: Cutting | N4: Filling
A6: =A5+1 -> 1 | C6: 1/0 | D6: DE+0 | F6: 283.2 | J6: 1 | K6: 111.651 | M6: 89.5
A7: =A6+1 -> 2 | C7: 1A/0 | D7: DD60+0 | F7: 284.927 | K7: 270.309 | M7: 265.381
A8: =A7+1 -> 3 | C8: 1A/1 | D8: DA+0 | F8: 292.179 | I8: 2 | J8: 1 | K8: 46.489 | M8: 22.529
A9: =A8+1 -> 4 | C9: 1A/3 | D9: DA+0 | F9: 281.458 | I9: 1 | K9: 45.554 | M9: 45.554
A10: =A9+1 -> 5 | C10: 1A/4 | D10: DA+3 | F10: 281.508 | G10: 1 | K10: 81.372 | M10: 64.075
A11: =A10+1 -> 6 | C11: 1A/5 | D11: DA+6 | F11: 288.539 | H11: 1 | K11: 88.77 | M11: 88.77
A12: =A11+1 -> 7 | C12: 2/0 | D12: DC1+0 | F12: 277.997 | G12: 1 | H12: 1 | J12: 2 | K12: 69.275 | M12: 35.55
A13: =A12+1 -> 8 | C13: 2/2 | D13: DA+0 | F13: 282.591 | I13: 1 | J13: 1 | M13: 140.97
A14: =A13+1 -> 9 | C14: 2/3 | D14: DA+0 | F14: 293.068 | G14: 1 | H14: 1 | M14: 22.61
A15: =A14+1 -> 10 | C15: 2/4 | D15: DA+3 | F15: 294.942 | M15: 28.01
A16: =A15+1 -> 11 | C16: 2/5 | D16: DA+3 | F16: 295.491 | H16: 1 | I16: 1 | M16: 53.49
A17: =A16+1 -> 12 | C17: 2/6 | D17: DA+6 | F17: 288.339 | H17: 2 | M17: 107.54
A18: =A17+1 -> 13 | C18: 2/7 | D18: DA+6 | F18: 283.557 | I18: 1 | M18: 209.95
A19: =A18+1 -> 14 | C19: 5/0 | D19: DB1+9 | F19: 276.283 | G19: 2 | H19: 2 | I19: 2 | J19: 2
A20: =A19+1 -> 15 | C20: 6/0 | D20: DB2+9 | F20: 278.494 | G20: 2 | H20: 2 | I20: 2 | J20: 2
A21: =A20+1 -> 16 | C21: 6/1 | D21: DA+0 | F21: 286.666 | G21: 1 | M21: 53.48
A22: =A21+1 -> 17 | C22: 8/3 | D22: DA+3 | F22: 273.914 | J22: 1 | M22: 42.94
A23: =A22+1 -> 18 | C23: 8/4 | D23: DA+0 | F23: 276.398 | G23: 1 | H23: 1 | I23: 1 | J23: 2 | M23: 14.89
A24: =A23+1 -> 19 | C24: 8/5 | D24: DA+3 | F24: 278.586 | M24: 35.69
A25: =A24+1 -> 20 | C25: 8/9 | D25: DA+3 | F25: 271.848 | M25: 42.16
A26: =A25+1 -> 21 | C26: 10/1 | D26: DA+3 | F26: 260.835 | M26: 74.8
A27: =A26+1 -> 22 | C27: 10/22 | D27: DA+0 | F27: 258.665 | G27: 1 | H27: 4 | M27: 60.5
A28: =A27+1 -> 23 | C28: 10/23 | D28: DA+9 | F28: 265.711 | G28: 2 | H28: 6 | I28: 1 | J28: 1 | M28: 30.7
A29: =A28+1 -> 24 | C29: 11/0 | D29: DB1+0 | F29: 282.363 | G29: 2 | H29: 4 | J29: 3 | K29: 415.644 | M29: 213.823
A30: =A29+1 -> 25 | C30: 11/1 | D30: DA+6 | F30: 280.588 | H30: 2 | K30: 260.613 | M30: 159.329
A31: =A30+1 -> 26 | C31: 11/2 | D31: DA+9 | E31: +2.0 | F31: 260.522 | I31: 2 | K31: 101.072
A32: =A31+1 -> 27 | C32: 11/5 | D32: DA+3 | F32: 249.129 | G32: 1 | H32: 1 | J32: 1 | K32: 58.783 | M32: 58.783033
A33: =A32+1 -> 28 | C33: 11/7 | D33: DA+3 | F33: 244.613 | K33: 87.852 | M33: 64.41
A34: =A33+1 -> 29 | C34: 11/11 | D34: DA+0 | F34: 251.55 | H34: 1 | K34: 31.471 | M34: 18.401
A35: =A34+1 -> 30 | C35: 11/12 | D35: DA+0 | F35: 261.411 | G35: 2 | H35: 3 | I35: 1 | J35: 4 | K35: 171.833 | M35: 79.75
A36: =A35+1 -> 31 | C36: 11/13 | D36: DA+0 | F36: 260.743 | H36: 2 | I36: 4 | J36: 1 | K36: 146.701 | M36: 89.319
A37: =A36+1 -> 32 | C37: 15/2 | D37: DA+9 | F37: 262.781 | J37: 1 | K37: 251.127
A38: =A37+1 -> 33 | C38: 15/4 | D38: DA+3 | E38: -0.26 | F38: 256.602 | G38: 1 | J38: 1 | K38: 216.018
A39: =A38+1 -> 34 | C39: 15/5 | D39: DA+3 | E39: -0.3 | F39: 254.329 | K39: 192.519
A40: =A39+1 -> 35 | C40: 15/6 | D40: DA+0 | F40: 254.201 | J40: 1
A41: =A40+1 -> 36 | C41: 15/9 | D41: DA+9 | E41: -0.2 | F41: 244.162 | K41: 284.108 | M41: 284.108
A42: =A41+1 -> 37 | C42: 17/0 | D42: DC1+0 | E42: -0.259 | F42: 233.247 | K42: 313.985 | M42: 313.985
...

Sheet Revetment Pkg-G
B4: Revetment work
B5: SI. No | C5: Loc No | D5: Tower Type | E5: Dt. of Start | F5: Dt. of complete | G5: Random Rubble stone masonry including excavation (1:5 Cement concrete) | H5: Excavation Volume | I5: Back filling and levelling of volumes enclosed by revetment. | J5: M15 Conc Nominal Mix 1:2:4 for top seal cover | K5: M10 (PEDDING -PCC)
B6: 1 | C6: 35/5 | D6: DA+0 RC | E6: 20.11.24 | F6: 24.12.24 | G6: 83 | H6: 17.19 | I6: 282.1 | J6: 0.37 | K6: 2.73
B13: Total | G13: =SUM(G6:G12) -> 83 | I13: =SUM(I6:I12) -> 282.1 | J13: =SUM(J6:J12) -> 0.37 | K13: =SUM(K6:K12) -> 2.73

Sheet Erection Compiled
A1: KEC INTERNATIONAL LIMITED
A2: LILO of 765 Kv DV Fatehgarh 3 Beawar TL
A3: Erection
A4: Cum Sl. No. | B4: Month Sl. No. | C4: Location No. | D4: Tower Type | E4: Starting Date | F4: Completion Date | G4: Gang Name | H4: Status | I4: Tower Weight
B6: 45170
A7: 1 | B7: 1 | C7: 57/9 | D7: DA+0 | E7: 13.09.23 | F7: 21.09.23 | G7: Sobha Devi | H7: Complete | I7: 37.504
A8: 2 | B8: 2 | C8: 58/12 | D8: DA+0 | E8: 18.09.23 | F8: 25.09.23 | G8: Sunny Const | H8: Complete | I8: 37.504
A9: 3 | B9: 3 | C9: 57/11 | D9: DA+0 | E9: 21.09.23 | F9: 26.09.23 | G9: Sobha Devi | H9: Complete | I9: 37.504
B10: 45200 | J10: =SUM(I7:I10) -> 112.512
A11: 4 | B11: 1 | C11: 58/14 | D11: DA+0 | E11: 25.09.23 | F11: 01.10.23 | G11: Sunny Const | H11: Complete | I11: 37.504
A12: 5 | B12: 2 | C12: 57/13 | D12: DA+0 | E12: 26.09.23 | F12: 01.10.23 | G12: Sobha Devi | H12: Complete | I12: 37.504
A13: 6 | B13: 3 | C13: 57/10 | D13: DA+0 | E13: 01.10.23 | F13: 06.10.23 | G13: Sobha Devi | H13: Complete | I13: 37.504
A14: 7 | B14: 4 | C14: 58/9 | D14: DA+0 | E14: 01.10.23 | F14: 07.10.23 | G14: Sunny Const | H14: Complete | I14: 37.504
A15: 8 | B15: 5 | C15: 52/1 | D15: DA+0 | E15: 03.10.23 | F15: 10.10.23 | G15: Suraj const | H15: Complete | I15: 37.504
A16: 9 | B16: 6 | C16: 57/12 | D16: DA+3 | E16: 06.10.23 | F16: 11.10.23 | G16: Sobha Devi | H16: Complete | I16: 38.847
A17: 10 | B17: 7 | C17: 58/8 | D17: DA+0 | E17: 7.10.23 | F17: 11.10.23 | G17: Sunny Const | H17: Complete | I17: 37.504
A18: 11 | B18: 8 | C18: 58/1 | D18: DA+0 | E18: 25.09.23 | F18: 12.10.23 | G18: Ganesh Kr. Sinha | H18: Complete | I18: 37.504
A19: 12 | B19: 9 | C19: 57/2 | D19: DA+0 | E19: 10.10.23 | F19: 16.10.23 | G19: Sobha Devi | H19: Complete | I19: 37.504
A20: 13 | B20: 10 | C20: 51/2 | D20: DA+0 | E20: 10.10.23 | F20: 15.10.23 | G20: Suraj const | H20: Complete | I20: 37.504
A21: 14 | B21: 11 | C21: 58/16 | D21: DA+0 | E21: 10.10.23 | F21: 17.10.23 | G21: Sunny Const | H21: Complete | I21: 37.504
A22: 15 | B22: 12 | C22: 57/3 | D22: DA+0 | E22: 15.10.23 | F22: 20.10.23 | G22: Sobha Devi | H22: Complete | I22: 37.504
... A30: 23 | B30: 20 | C30: 58/11 | D30: DA+3 | E30: 23.10.23 | F30: 31.10.23 | G30: Sunny Const | H30: Complete | I30: 38.847
B31: 45231 | J31: =SUM(I11:I30) -> 759.481
A32: 24 | B32: 1 | C32: 57/8 | D32: DA+3 | E32: 30.10.23 | F32: 03.11.2023 | G32: Sobha Devi | H32: Complete | I32: 38.847
A33: 25 | B33: 2 | C33: 51/7 | D33: DA+3 | E33: 29.10.23 | F33: 04.11.2023 | G33: Suraj const | H33: Complete | I33: 38.847
A34: 26 | B34: 3 | C34: 59/6 | D34: DA+0 | E34: 31.10.23 | F34: 07.11.2023 | G34: Sunny Const | H34: Complete | I34: 37.504
A35: 27 | B35: 4 | C35: 57/7 | D35: DA+3 | E35: 03.11.23 | F35: 07.11.2023 | G35: Sobha Devi | H35: Complete | I35: 38.847
A36: 28 | B36: 5 | C36: 51/3 | D36: DA+0 | E36: 04.11.23 | F36: 09.11.2023 | G36: Suraj const | H36: Complete | I36: 37.504
A37: 29 | B37: 6 | C37: 58/4 | D37: DA+0 | E37: 31.10.23 | F37: 11.11.2023 | G37: Ganesh Kr. Sinha | H37: Complete | I37: 37.504
A38: 30 | B38: 7 | C38: 57/1 | D38: DA+3 | E38: 07.11.23 | F38: 13.11.2023 | G38: Sobha Devi | H38: Complete | I38: 38.847
A39: 31 | B39: 8 | C39: 59/5 | D39: DA+0 | E39: 07.11.23 | F39: 13.11.2023 | G39: Sunny Const | H39: Complete | I39: 37.504
A40: 32 | B40: 9 | C40: 51/10 | D40: DA+3 | E40: 10.11.23 | F40: 14.11.2023 | G40: Suraj const | H40: Complete | I40: 38.847
A41: 33 | B41: 10 | C41: 56/9 | D41: DA+3 | E41: 13.11.23 | F41: 16.11.2023 | G41: Sobha Devi | H41: Complete | I41: 38.847
A42: 34 | B42: 11 | C42: 59/3 | D42: DA+0 | E42: 13.11.23 | F42: 18.11.2023 | G42: Sunny Const | H42: Complete | I42: 37.504
A43: 35 | B43: 12 | C43: 52/2 | D43: DA+3 | E43: 15.11.23 | F43: 19.11.2023 | G43: Suraj const | H43: Complete | I43: 38.847
... A53: 45 | B53: 22 | C53: 59/1 | D53: DA+0 | E53: 24.11.23 | F53: 30.11.23 | G53: Sunny Const | H53: Complete | I53: 37.504
B54: 45261 | J54: =SUM(I32:I53) -> 841.204
A55: 46 | B55: 1 | C55: 50/4 | D55: DA+3 | E55: 22.11.23 | F55: 01.12.23 | G55: Ganesh Kr. Sinha | H55: Complete | I55: 38.847
A56: 47 | B56: 2 | C56: 55/4 | D56: DA+3 | E56: 27.11.23 | F56: 02.12.23 | G56: Chinta devi | H56: Complete | I56: 38.847
A57: 48 | B57: 3 | C57: 56/4 | D57: DA+3 | E57: 29.11.23 | F57: 02.12.23 | G57: Sobha Devi | H57: Complete | I57: 38.847
...

Sheet Tack Welding - PKG-G
A1: KEC INTERNATIONAL LIMITED
A2: LILO of 765 Kv DV Fatehgarh 3 Beawar TL
A3: Tack Welding
A4: Cum Sl. No. | B4: Month Sl. No. | C4: JMC No. | D4: Location No. | E4: Tower Type | F4: Dt. of Start | G4: Dt. of Complete | H4: Tack Welding Status | I4: Name of Sub-Contractor | J4: Ramarks
B6: 45200
A7: 1 | B7: 1 | D7: 57/12 | E7: DA+3 | F7: 24.10.23 | G7: 25.10.23 | H7: Done | I7: Suraja Ram
A8: 2 | B8: 2 | D8: 57/13 | E8: DA+0 | F8: 24.10.23 | G8: 25.10.23 | H8: Done | I8: Suraja Ram
A9: 3 | B9: 3 | D9: 57/11 | E9: DA+0 | F9: 25.10.23 | G9: 26.10.23 | H9: Done | I9: Suraja Ram
A10: 4 | B10: 4 | D10: 57/10 | E10: DA+3 | F10: 26.10.23 | G10: 27.10.23 | H10: Done | I10: Suraja Ram
A11: 5 | B11: 5 | D11: 57/9 | E11: DA+0 | F11: 27.10.23 | G11: 29.10.23 | H11: Done | I11: Suraja Ram
B12: 45231
A13: 6 | B13: 1 | D13: 57/4 | E13: DA+0 | F13: 31.10.23 | G13: 01.11.23 | H13: Done | I13: Suraja Ram
A14: 7 | B14: 2 | D14: 57/3 | E14: DA+0 | F14: 01.11.23 | G14: 02.11.23 | H14: Done | I14: Suraja Ram
A15: 8 | B15: 3 | D15: 57/2 | E15: DA+0 | F15: 02.11.23 | G15: 03.11.2023 | H15: Done | I15: Suraja Ram
A16: 9 | B16: 4 | D16: 57/5 | E16: DA+3 | F16: 03.11.2023 | G16: 04.11.2023 | H16: Done | I16: Suraja Ram
A17: 10 | B17: 5 | D17: 58/8 | E17: DA+0 | F17: 05.11.2023 | G17: 06.111.23 | H17: Done | I17: Suraja Ram
A18: 11 | B18: 6 | D18: 58/9 | E18: DA+0 | F18: 06.111.23 | G18: 07.11.23 | H18: Done | I18: Suraja Ram
A19: 12 | B19: 7 | D19: 57/8 | E19: DA+3 | F19: 07.11.23 | G19: 08.11.23 | H19: Done | I19: Suraja Ram
A20: 13 | B20: 8 | D20: 58/11 | E20: DA+3 | F20: 09.11.23 | G20: 27.11.23 | H20: Done | I20: Suraja Ram
A21: 14 | B21: 9 | D21: 58/12 | E21: DA+0 | F21: 27.11.23 | G21: 28.11.23 | H21: Done | I21: Suraja Ram
A22: 15 | B22: 10 | D22: 57/1 | E22: DA+3 | F22: 28.11.23 | G22: 30.11.23 | H22: Done | I22: Suraja Ram
B23: 45261
A24: 16 | B24: 1 | D24: 56/9 | E24: DA+3 | F24: 30.11.23 | G24: 02.12.23 | H24: Done | I24: Suraja Ram
A25: 17 | B25: 2 | D25: 56/8 | E25: DA+3 | F25: 02.12.23 | G25: 03.12.23 | H25: Done | I25: Suraja Ram
A26: 18 | B26: 3 | D26: 56/7 | E26: DA+3 | F26: 06.12.23 | G26: 06.12.23 | H26: Done | I26: Suraja Ram
A27: 19 | B27: 4 | D27: 58/14 | E27: DA+0 | F27: 07.12.23 | G27: 07.12.23 | H27: Done | I27: Suraja Ram
A28: 20 | B28: 5 | D28: 58/16 | E28: DA+0 | F28: 13.12.23 | G28: 13.12.23 | H28: Done | I28: Suraja Ram
A29: 21 | B29: 6 | D29: 58/10 | E29: DA+3 | F29: 14.12.23 | G29: 15.12.23 | H29: Done | I29: Suraja Ram
A30: 22 | B30: 7 | D30: 59/1 | E30: DA+0 | F30: 18.12.23 | G30: 18.12.23 | H30: Done | I30: Suraja Ram
A31: 23 | B31: 8 | D31: 59/2 | E31: DA+0 | F31: 19.12.23 | G31: 19.12.23 | H31: Done | I31: Suraja Ram
A32: 24 | B32: 9 | D32: 59/3 | E32: DA+0 | F32: 20.12.23 | G32: 20.12.23 | H32: Done | I32: Suraja Ram
A33: 25 | B33: 10 | D33: 59/5 | E33: DA+0 | F33: 21.12.23 | G33: 21.12.23 | H33: Done | I33: Suraja Ram
A34: 26 | B34: 11 | D34: 59/6 | E34: DA+0 | F34: 22.12.23 | G34: 22.12.23 | H34: Done | I34: Suraja Ram
A35: 27 | B35: 12 | D35: 56/3 | E35: DA+0 | F35: 23.12.23 | G35: 23.12.23 | H35: Done | I35: Suraja Ram
... A49: 41 | B49: 26 | D49: 52/2 | E49: DA+3 | F49: 31.12.23 | G49: 31.12.23 | H49: Done | I49: Kailash Nath
B50: 45292
A51: 42 | B51: 1 | D51: 55/10 | E51: DA+3 | F51: 02.01.24 | G51: 02.01.24 | H51: Done | I51: Suraja Ram
A52: 43 | B52: 2 | D52: 55/11 | E52: DA+3 | F52: 02.01.24 | G52: 02.01.24 | H52: Done | I52: Suraja Ram
A53: 44 | B53: 3 | D53: 52/5 | E53: DA+3 | F53: 02.01.24 | G53: 02.01.24 | H53: Done | I53: Kailash Nath
A54: 45 | B54: 4 | D54: 57/7 | E54: DA+3 | F54: 03.01.24 | G54: 03.01.24 | H54: Done | I54: Suraja Ram
...

Sheet Stringing - PKG-G
A1: KEC INTERNATIONAL LIMITED
A2: LILO of 765 Kv DV Fatehgarh 3 Beawar TL
A3: STRINGING- PKG-G
A4: S. No | B4: Section | E4: Paying Out | H4: Final Sag | K4: Name of Gang | L4: Remarks
B5: From | C5: To | D5: Length | E5: Start Date | F5: Finish Date | G5: Month | H5: Start Date | I5: Finish Date | J5: Month
A6: 1 | B6: 57/6 | C6: 58/0 | D6: 3.141 | E6: 06.05.2024 | F6: 10.05.24 | G6: 45436 | H6: 19.05.24 | I6: 24.05.24 | J6: 45436 | K6: GPJ Const. | L6: Final sag done | P6: =B6& " to " &C6 -> 57/6 to 58/0
A7: 2 | B7: 57/0 | C7: 57/6 | D7: 2.344 | E7: 16.05.24 | F7: 24.05.24 | G7: 45436 | H7: 07.06.24 | I7: 12.06.24 | J7: 45467 | K7: GPJ Const. | L7: Final sag done | P7: =B7& " to " &C7 -> 57/0 to 57/6
A8: 3 | B8: 56/0 | C8: 57/0 | D8: 4.127 | E8: 04.06.24 | F8: 12.06.24 | G8: 45467 | H8: 28.06.24 | I8: 04.07.24 | J8: 45497 | K8: GPJ Const. | L8: Final sag done | P8: =B8& " to " &C8 -> 56/0 to 57/0
A9: 4 | B9: 55/0 | C9: 56/0 | D9: 4.9 | E9: 25.06.24 | F9: 04.07.24 | G9: 45497 | H9: 17.07.24 | I9: 22.07.24 | J9: 45497 | K9: GPJ Const. | L9: 10.883 | P9: =B9& " to " &C9 -> 55/0 to 56/0
A10: 5 | B10: 53/0 | C10: 55/0 | D10: 2.013 | E10: 16.07.24 | F10: 22.07.24 | G10: 45497 | H10: 09.08.24 | I10: 10.08.24 | J10: 45528 | K10: GPJ Const. | L10: 11.112 | P10: =B10& " to " &C10 -> 53/0 to 55/0
A11: 6 | B11: 52/0 | C11: 53/0 | D11: 2.364 | E11: 19.08.24 | F11: 22.08.24 | G11: 45528 | H11: 04.09.24 | I11: 09.09.24 | J11: 45559 | K11: GPJ Const. | L11: Final sag done | P11: =B11& " to " &C11 -> 52/0 to 53/0
A12: 7 | B12: 51/0 | C12: 52/0 | D12: 4.403 | E12: 01.09.24 | F12: 08.09.24 | G12: 45559 | H12: 28.09.24 | I12: 05.10.24 | J12: 45589 | K12: GPJ Const. | L12: Final sag done | P12: =B12& " to " &C12 -> 51/0 to 52/0
A13: 8 | B13: 50/0 | C13: 51/0 | D13: 1.971 | E13: 26.9.24 | F13: 02.10.24 | G13: 45589 | H13: 08.10.24 | I13: 10.10.24 | J13: 45589 | K13: GPJ Const. | L13: Final sag done | P13: =B13& " to " &C13 -> 50/0 to 51/0
A14: 9 | B14: 72/7 | C14: 73/0 | D14: 0.49623 | E14: 12.11.24 | F14: 15.11.24 | G14: 45620 | H14: 27.11.24 | I14: 29.11.24 | J14: 45620 | K14: MR Power | L14: Final sag done | P14: =B14& " to " &C14 -> 72/7 to 73/0
A15: 10 | B15: 58/0 | C15: 58/7 | D15: 2.797 | E15: 20.11.24 | F15: 23.11.24 | G15: 45620 | H15: 01.12.245 | I15: 05.12.24 | J15: 45650 | K15: Kddus Ali | L15: Final sag done | P15: =B15& " to " &C15 -> 58/0 to 58/7
A16: 11 | B16: 72/0 | C16: 72/7 | D16: 2.589 | E16: 18.11.24 | F16: 23.11.24 | G16: 45620 | H16: 06.12.24 | I16: 10.12.24 | J16: 45650 | K16: MR Power | L16: Final sag done | P16: =B16& " to " &C16 -> 72/0 to 72/7
A17: 12 | B17: 67/1 | C17: 68/0 | D17: 0.42647 | E17: 22.12.24 | F17: 23.12.24 | G17: 45650 | H17: 23.12.24 | I17: 25.12.25 | J17: 45650 | K17: Nasruddin | L17: Final sag done | P17: =B17& " to " &C17 -> 67/1 to 68/0
A18: 13 | B18: 68/0 | C18: 69/0 | D18: 2.855 | E18: 11.12.24 | F18: 20.12.24 | G18: 45650 | H18: 01.01.25 | I18: 05.01.25 | J18: 45682 | K18: Nasruddin | L18: Final sag done | P18: =B18& " to " &C18 -> 68/0 to 69/0
A19: 14 | B19: 58/7 | C19: 59/0 | D19: 3.885 | E19: 27.12.24 | F19: 04.01.25 | G19: 45682 | H19: 07.01.25 | I19: 09.01.25 | J19: 45682 | K19: MR Power | L19: Final sag done | P19: =B19& " to " &C19 -> 58/7 to 59/0
A20: 15 | B20: 71/0 | C20: 72/0 | D20: 2.092 | E20: 03.12.24 | F20: 10.12.24 | G20: 45650 | H20: 16.01.25 | I20: 19.01.25 | J20: 45682 | K20: MR Power | L20: Final sag done | O20: =121-76 -> 45 | P20: =B20& " to " &C20 -> 71/0 to 72/0
A21: 16 | B21: 67/0 | C21: 67/1 | D21: 0.43755 | E21: 21.12.24 | F21: 22.12.24 | G21: 45650 | H21: 20.01.25 | I21: 21.01.25 | J21: 45682 | K21: Nasruddin | L21: Final sag done | P21: =B21& " to " &C21 -> 67/0 to 67/1
A22: 17 | B22: 69/0 | C22: 70/0 | D22: 3.881 | E22: 30.12.24 | F22: 05.01.25 | G22: 45682 | H22: 27.01.25 | I22: 28.01.25 | J22: 45682 | K22: Nasruddin | L22: Final sag done | P22: =B22& " to " &C22 -> 69/0 to 70/0
A23: 18 | B23: 41/0 | C23: 42/0 | D23: 4.981 | E23: 13.02.25 | F23: 20.02.25 | G23: 45713 | H23: 28.02.25 | I23: 02.03.25 | J23: 45741 | K23: Nasruddin | L23: Final sag done | M23: 41/0 hoisting done | P23: =B23& " to " &C23 -> 41/0 to 42/0
A24: 19 | B24: 59/0 | C24: 60/0 | D24: 2.581 | E24: 20.01.25 | F24: 25.01.25 | G24: 45682 | H24: 02.05.25 | I24: 04.05.25 | J24: 45802 | K24: MR Power | L24: Final sag done | M24: Acchelal | P24: =B24& " to " &C24 -> 59/0 to 60/0
A25: 20 | B25: 42/0 | C25: 43/0 | D25: 0.489 | E25: 04.05.25 | F25: 11.05.25 | G25: 45802 | H25: 07.05.25 | I25: 11.05.25 | J25: 45802 | K25: Indrajeet | L25: Final sag done | P25: =B25& " to " &C25 -> 42/0 to 43/0
A26: 21 | B26: 49/0 | C26: 50/0 | D26: 0.241 | E26: 15.05.25 | F26: 17.05.25 | G26: 45802 | H26: 15.05.25 | I26: 17.05.25 | J26: 45802 | K26: Indrajeet | L26: Final sag done | M26: 47/3 Half side hoisting done | P26: =B26& " to " &C26 -> 49/0 to 50/0
A27: 22 | B27: 48/0 | C27: 49/0 | D27: 1.162 | E27: 14.05.25 | F27: 17.05.25 | G27: 45802 | H27: 19.05.25 | I27: 21.05.25 | J27: 45802 | K27: Indrajeet | L27: Final sag done | P27: =B27& " to " &C27 -> 48/0 to 49/0
A28: 23 | B28: 47/0 | C28: 48/0 | D28: 1.274 | E28: 19.05.25 | F28: 21.05.25 | G28: 45802 | H28: 25.05.25 | I28: 29.05.25 | J28: 45802 | K28: Indrajeet | L28: Final sag done | P28: =B28& " to " &C28 -> 47/0 to 48/0
A29: 24 | B29: 37/2 | C29: 38/0 | D29: 2.711 | E29: 24.05.25 | F29: 30.05.25 | G29: 45802 | H29: 11.06.25 | I29: 15.06.25 | J29: 45833 | K29: Indrajeet | L29: Final sag done | P29: =B29& " to " &C29 -> 37/2 to 38/0
A30: 25 | B30: 43/0 | C30: 44/0 | D30: 2.856 | E30: 05.05.25 | F30: 10.05.25 | G30: 45802 | H30: 20.06.25 | I30: 25.06.25 | J30: 45833 | K30: Indrajeet | L30: Final sag done | M30: Jainath | P30: =B30& " to " &C30 -> 43/0 to 44/0
A31: 26 | B31: 61/0 | C31: 62/0 | D31: 1.028 | E31: 27.06.25 | F31: 29.6.25 | G31: 45833 | H31: 07.07.25 | I31: 10.07.25 | J31: Jul | K31: GPJ Const. | L31: Final sag done | M31: Clipping 61/0 to 62/0 done | O31: 62/0 jumper done | P31: =B31& " to " &C31 -> 61/0 to 62/0
A32: 27 | B32: 62/0 | C32: 63/0 | D32: 0.221 | E32: 07.07.25 | F32: 10.07.25 | G32: Jul | H32: 07.07.25 | I32: 10.07.25 | J32: Jul | K32: GPJ Const. | L32: Final sag done | M32: Clipping 62/0 to 63/0 done | P32: =B32& " to " &C32 -> 62/0 to 63/0
A33: 28 | B33: 38/0 | C33: 38/9 | D33: 3.215 | E33: 04.06.25 | F33: 10.06.25 | G33: 45833 | H33: 07.07.25 | I33: 13.7.25 | J33: Jul | K33: Indrajeet | L33: Final sag done | M33: 38/1 Clipping | P33: =B33& " to " &C33 -> 38/0 to 38/9
A34: 29 | B34: 40/10 | C34: 41/0 | D34: 1.073 | E34: 02.07.25 | F34: 05.07.25 | G34: Jul | H34: 24.07.25 | I34: 28.07.25 | J34: Jul | K34: Indrajeet/Rahim | L34: Final sag done | P34: =B34& " to " &C34 -> 40/10 to 41/0
A35: 30 | B35: 63/0 | C35: 64/0 | D35: 2.879 | E35: 24.07.25 | F35: 28.07.25 | G35: Jul | H35: 31.07.25 | I35: 02.08.25 | J35: Aug | K35: GPJ Const. | L35: Final sag done | P35: =B35& " to " &C35 -> 63/0 to 64/0
A36: 31 | B36: 39/0 | C36: 40/0 | D36: 2.744 | E36: 30.07.25 | F36: 06.08.25 | G36: Aug | H36: 09.08.25 | I36: 12.08.25 | J36: Aug | K36: Amir Sheikh | L36: Final sag done | M36: 39/1,39/2.39/4,5,6 Clipping done | N36: 39/0 Jumper | P36: =B36& " to " &C36 -> 39/0 to 40/0
A37: 32 | B37: 40/5 | C37: 40/10 | D37: 1.897 | E37: 11.07.25 | F37: 20.07.25 | G37: Jul | H37: 10.08.25 | I37: 16.08.25 | J37: Aug | K37: Indrajeet/Rahim | L37: Final sag done | M37: =48 -> 48 | P37: =B37& " to " &C37 -> 40/5 to 40/10
A38: 33 | B38: 38/9 | C38: 39/0 | D38: 0.544 | E38: 04.07.25 | F38: 11.07.25 | G38: Jul | H38: 19.08.25 | I38: 23.08.25 | J38: Aug | K38: Indrajeet/Mohan/Amir Sheikh | L38: Final sag done | M38: 50 | P38: =B38& " to " &C38 -> 38/9 to 39/0
A39: 34 | B39: 40/0 | C39: 40/2 | D39: 0.652 | E39: 28.07.25 | F39: 01.08.25 | G39: Aug | H39: 23.08.25 | I39: 31.08.25 | J39: Aug | K39: Rahim Khan | L39: Final sag done | P39: =B39& " to " &C39 -> 40/0 to 40/2
A40: 35 | B40: 40/2 | C40: 40/5 | D40: 1.219 | E40: 08.08.25 | F40: 14.08.25 | G40: Aug | H40: 23.08.25 | I40: 31.08.25 | J40: Aug | K40: Rahim Khan | L40: Final sag done | P40: =B40& " to " &C40 -> 40/2 to 40/5
...

Sheet OPGW PKG-G
A1: EXECUTING AGENCY : M/s. KEC INTERNATIONAL LIMITED
A2: LILO of 765 Kv DV Fatehgarh 3 Beawar TL
A3: OPGW Progress details(Pkg-G)
A4: Sr. No | B4: Section | D4: Section length in Kms | E4: OPGW Drum Length (In KMs) | F4: Start date | G4: End date | H4: Splicing | I4: Jointing Details | J4: Agency | K4: OTDR reading status | L4: Splicing done by | M4: Remarks
A5: 1 | B5: 51/0 | C5: 52/0 | D5: 4.403 | E5: 4.653 | F5: 11.01.25 | G5: 12.01.25 | H5: Done | J5: Congent tech | M5: Final sag completed | N5: =B5& " to " &C5 -> 51/0 to 52/0
A6: 2 | B6: 52/0 | C6: 55/0 | D6: 4.377 | E6: 4.627 | F6: 17.01.25 | G6: 18.01.25 | H6: Done | J6: Congent tech | M6: Final sag completed | N6: =B6& " to " &C6 -> 52/0 to 55/0
A7: 3 | B7: 55/0 | C7: 56/0 | D7: 4.9 | E7: 5.16 | F7: 20.01.25 | G7: 21.01.25 | H7: Done | J7: Congent tech | L7: Rakesh | M7: Final sag completed | N7: =B7& " to " &C7 -> 55/0 to 56/0
A8: 4 | B8: 56/0 | C8: 57/0 | D8: 4.127 | E8: 4.372 | F8: 23.01.25 | G8: 24.01.25 | H8: Done | J8: Congent tech | L8: Rakesh | M8: Final sag completed | N8: =B8& " to " &C8 -> 56/0 to 57/0
A9: 5 | B9: 57/0 | C9: 57/6 | D9: 2.344 | E9: 2.553 | F9: 27.01.25 | G9: 28.01.25 | H9: Done | J9: Congent tech | L9: Rakesh | M9: Final sag completed | N9: =B9& " to " &C9 -> 57/0 to 57/6
A10: 6 | B10: 57/6 | C10: 58/0 | D10: 3.141 | E10: 3.365 | F10: 29.01.25 | G10: 30.01.25 | H10: Done | J10: Congent tech | L10: Rakesh | M10: Final sag completed | N10: =B10& " to " &C10 -> 57/6 to 58/0
A11: 7 | B11: 58/0 | C11: 58/7 | D11: 2.797 | E11: 3.015 | F11: 01.02.25 | G11: 02.02.25 | H11: Done | J11: Congent tech | L11: Rakesh | M11: Final sag completed | N11: =B11& " to " &C11 -> 58/0 to 58/7
A12: 8 | B12: 58/7 | C12: 59/0 | D12: 3.885 | E12: 4.124 | F12: 04.02.25 | G12: 05.02.25 | H12: Done | J12: Congent tech | L12: Rakesh | M12: Final sag completed | N12: =B12& " to " &C12 -> 58/7 to 59/0
A13: 9 | B13: 41/0 | C13: 42/0 | D13: 4.98 | E13: 5.242 | F13: 27.07.25 | G13: 29.07.25 | H13: Done | J13: Congent tech | L13: Rakesh | M13: Final sag completed | N13: =B13& " to " &C13 -> 41/0 to 42/0
A14: 10 | B14: 42/0 | C14: 44/0 | D14: 3.345 | E14: 3.574 | F14: 06.08.25 | G14: 06.08.25 | H14: Done | J14: Congent tech | L14: Rakesh | M14: Final sag completed | N14: =B14& " to " &C14 -> 42/0 to 44/0
A15: 11 | B15: 48/0 | C15: 51/0 | D15: 3.374 | E15: 3.603 | F15: 10.08.25 | G15: 10.08.25 | H15: Done | J15: Congent tech | L15: Rakesh | M15: Final sag completed | N15: =B15& " to " &C15 -> 48/0 to 51/0
A16: 12 | B16: 39/0 | C16: 40/2 | D16: 3.395 | E16: 3.603 | F16: 12.08.25 | G16: 13.08.25 | H16: Done | J16: Congent tech | L16: Rakesh | M16: Final sag completed | N16: =B16& " to " &C16 -> 39/0 to 40/2
A17: 13 | B17: 38/0 | C17: 39/0 | D17: 3.759 | E17: 4.006 | F17: 18.08.25 | G17: 18.08.25 | H17: Done | J17: Congent tech | L17: Rakesh | M17: Final sag completed | N17: =B17& " to " &C17 -> 38/0 to 39/0
A18: 14 | B18: 63/0 | C18: 64/0 | D18: 2.879 | E18: 2.879 | F18: 27.11.25 | G18: 30.11.25 | H18: Done | J18: Congent tech | L18: Umesh | M18: Final sag completed | N18: =B18& " to " &C18 -> 63/0 to 64/0
... A28: 24 | B28: 28/0 | C28: 29/0 | D28: 3.914 | E28: 4.156 | F28: 05.01.26 | G28: 06.01.26 | H28: Done | J28: Congent tech | L28: Kamla Prasad | M28: Final sag completed | N28: =B28& " to " &C28 -> 28/0 to 29/0
A29: 25 | B29: 27/0 | C29: 28/0 | D29: 2.124 | E29: 2.339 | F29: 07.01.26 | G29: 08.01.26 | H29: Done | J29: Congent tech | L29: Balwan | M29: Final sag completed | N29: 27/0 to 28/0
A30: 26 | B30: 44/0 | C30: 46/0 | D30: 2.692 | E30: 2.941 | F30: 08.01.26 | G30: 09.01.26 | H30: Done | J30: Congent tech | L30: Umesh | M30: Final sag completed | N30: 44/0 to 46/0
A31: 27 | B31: 26/0 | C31: 27/0 | D31: 3.145123 | E31: 3.38 | F31: 09.01.26 | G31: 11.01.26 | H31: Done | J31: Congent tech | L31: Balwan | M31: Final sag completed | N31: 26/0 to 27/0
A32: 28 | B32: 46/0 | C32: 48/0 | D32: 3.002 | F32: 10.01.26 | G32: 11.01.26 | H32: Done | J32: Congent tech | L32: Umesh | M32: Final sag completed
A33: 29 | B33: 25/0 | C33: 26/0 | D33: 4.965 | F33: 12.01.26 | G33: 15.01.26 | H33: Done | J33: Congent tech | L33: Balwan | M33: Final sag completed
A34: 30 | B34: 40/2 | C34: 41/0 | D34: 4.188 | F34: 12.01.26 | G34: 14.01.26 | H34: Done | J34: Congent tech | L34: Umesh | M34: Final sag completed
A35: 31 | B35: 33/0 | C35: 34/0 | D35: 3.338 | F35: 15.01.26 | G35: 18.01.26 | H35: Done | J35: Congent tech | L35: Umesh | M35: Final sag completed
A36: 32 | B36: 37/0 | C36: 38/0 | D36: 3.497 | F36: 15.01.26 | G36: 16.01.26 | H36: Done | J36: Congent tech | L36: Umesh | M36: Final sag completed
A37: 33 | B37: 34/0 | C37: 35/0 | D37: 2.761 | F37: 19.01.26 | G37: 21.01.26 | H37: Done | J37: Congent tech | L37: Umesh | M37: Final sag completed
A38: 34 | B38: 35/0 | C38: 37/0 | D38: 3.816 | F38: 17.01.26 | G38: 20.01.26 | H38: Done | J38: Congent tech | L38: Umesh | M38: Final sag completed
A39: 35 | B39: 17/0 | C39: 18/0 | D39: 2.507 | F39: 19.01.26 | G39: 24.01.26 | H39: Done | J39: Congent tech | M39: Final sag completed
A40: 36 | B40: 24/0 | C40: 25/0 | D40: 2.69 | F40: 21.01.26 | G40: 24.01.26 | H40: Done | J40: Congent tech | M40: Final sag completed
A41: 37 | B41: 16/0 | C41: 17/0 | D41: 2.818 | F41: 25.01.26 | G41: 28.01.26 | H41: Done | J41: Congent tech | M41: Final sag completed
A42: 38 | B42: 23/0 | C42: 24/0 | D42: 4.809 | F42: 25.01.26 | G42: 29.01.26 | H42: Done | J42: Congent tech | M42: Final sag completed
A43: 39 | B43: Gantry | C43: 2/0 | D43: 3.41 | F43: 22.01.26 | G43: 29.01.26 | J43: Jai Bajrang Bali | M43: Final sag completed
A44: 40 | B44: 22/0 | C44: 23/0 | D44: 4.035 | F44: 29.01.26 | G44: 31.01.26 | H44: Done | J44: Congent tech | M44: Final sag completed
