Workbook
Name \0: #REF!
Name \0: #REF!
Name \2: #REF!
Name \A: #REF!
Name \a: #N/A
Name \A: #REF!
Name \A_1: "#REF!"
Name \B: #REF!
Name \B: #REF!
Name \C: #REF!
Name \c1: #REF!
Name \D: '[1]Annex-7,Contingent'!#REF!
Name \d: #N/A
Name \g: #REF!
Name \H: #REF!
Name \H: #REF!
Name \I: #REF!
Name \I: '[1]Annex-7,Contingent'!#REF!
Name \i: #REF!
Name \KWS123: #N/A
Name \l: #REF!
Name \l: #REF!
Name \M: #REF!
Name \N: #REF!
Name \P: #REF!
Name \q: #N/A
Name \R: '[1]Annex-7,Contingent'!#REF!
Name \R: #REF!
Name \S: #REF!
Name \t: #N/A
Name \U: #REF!
Name \V: #REF!
Name \z: #N/A
Name \z: #REF!
Name _: #REF!
Name _________________________________________________________dol12: #REF!
Name _________________________________________________________in18900: #REF!
Name _________________________________________________________iv19000: #REF!
Name ________________________________________________________dol12: #REF!
Name ________________________________________________________dol6: #REF!
Name ________________________________________________________in18900: #REF!
Name ________________________________________________________iv19000: #REF!
Name _______________________________________________________dol12: #REF!
Name _______________________________________________________dol6: #REF!
Name _______________________________________________________in18900: #REF!
Name _______________________________________________________iv19000: #REF!
Name ______________________________________________________dol12: #REF!
Name ______________________________________________________dol6: #REF!
Name _____________________________________________________dol12: #REF!
Name _____________________________________________________dol6: #REF!
Name _____________________________________________________in18900: #REF!
Name _____________________________________________________iv19000: #REF!
Name ____________________________________________________dol12: #REF!
Name ____________________________________________________dol6: #REF!
Name ____________________________________________________in18900: #REF!
Name ____________________________________________________iv19000: #REF!
Name ___________________________________________________dol12: #REF!
Name ___________________________________________________dol6: #REF!
Name ___________________________________________________in18900: #REF!
Name ___________________________________________________iv19000: #REF!

Sheet Progress Summary
A1: #VALUE! | B1: Project Code - | C1: TB-408 | D1: Date | E1: =+TODAY() -> 46123 | G1: Head - T&D | H1: Rajinder Gupta | J1: Head T&D-North | K1: N. K. Gupta | L1: Regional Manager | M1: Rajnish Pandey | Q1: Shortcut for previous of Full description
B2: Client Name- | C2: Resonia Limited (Formally Sterlite Power Transmission Limited) | G2: Project Manager | H2: Virendra Gupta | L2: Planning Engineer | M2: Raghav Ranjan | Q2: Link for go through
B3: Project Name- | C3: 765KV D/C Fatehgarh III- Beawar Transmission Line, PKG F | G3: Effective Date | H3: 45266 | J3: End Date | K3: 28-02-2026 (TE awaited) | L3: LOA Value | M3: Rs 283.08 Cr Supply -Rs 209.88 Cr., Service.-Rs 73.20 Cr | Q3: X-ing Status'!A1
A4: Sr. No. | B4: Activity | C4: As per latest Estimate | D4: Cumm. Progress up to last Month | E4: Opening Balance (This Month, excl. Tata) | F4: Plan for this Month | G4: Today Progress | H4: MTD | I4: WIP | J4: Cumulative Progress | K4: Balance | L4: Gangs at present | M4: Remarks | N4: Support Required | O4: % Completion | Q4: L2 Schedule'!A1
A5: 1 | B5: Check Survey (Kms) | C5: 191.392 | D5: 191.393 | E5: =C5-D5 -> -0.001 | F5: =E5 -> -0.001 | J5: =D5+H5 -> 191.393 | K5: =C5-J5 -> -0.001 | L5: - | O5: =(J5/C5)*100 -> 100.00052 | Q5: Hindrance Register (Row)'!A1
A6: 2 | B6: Foundation (Nos.) | C6: 485 | D6: 485 | E6: =C6-D6 -> 0 | F6: 0 | J6: =D6+H6 -> 485 | K6: =C6-J6 -> 0 | L6: - | O6: =(J6/C6)*100 -> 100 | Q6: Survey!A1
A7: 3 | B7: Earthing (Nos.) | C7: 485 | D7: 485 | E7: =C7-D7 -> 0 | F7: 0 | J7: =D7+H7 -> 485 | K7: =C7-J7 -> 0 | L7: - | O7: =(J7/C7)*100 -> 100 | Q7: Foundation!A1
A8: 4 | B8: Tower Erection (Nos) | C8: 485 | D8: 475 | E8: =C8-D8 -> 10 | F8: 10 | I8: 2 | J8: =D8+H8 -> 475 | K8: =C8-J8 -> 10 | L8: 3 | M8: WIP- 21/10, 22/1 Today Completed - | O8: =(J8/C8)*100 -> 97.938144 | Q8: Earthing!A1
A9: 5 | B9: Tack Welding (Nos) | C9: 485 | D9: 387 | E9: =C9-D9 -> 98 | F9: 45 | H9: 11 | J9: =D9+H9 -> 398 | K9: =C9-J9 -> 87 | L9: 1 | O9: =(J9/C9)*100 -> 82.061856 | Q9: Erection!A1
A10: 6 | B10: Paying Out (Kms) | C10: =C5 -> 191.392 | D10: 95.561 | E10: =C10-D10-33.766 -> 62.065 | F10: 41 | H10: 10.65 | I10: =Stringing!G58 -> 13.765 | J10: =D10+H10 -> 106.211 | K10: =+E10-H10 -> 51.415 | L10: 6 | M10: AP6-7:- WIP. AP11A-12:- WIP. AP43-44:- WIP. AP53-54:- WIP. | O10: =(J10/C10)*100 -> 55.49396 | Q10: Tackwelding!A1
A11: 7 | B11: Final Sag (Kms) | C11: =C10 -> 191.392 | D11: 90.6477 | E11: =C11-D11-33.766 -> 66.9783 | F11: 49 | G11: 5.27 | H11: =0.38+7.58+0.23+5.27 -> 13.46 | I11: =Stringing!G59 -> 2.078 | J11: =D11+H11 -> 104.1077 | K11: =+E11-H11 -> 53.5183 | M11: AP8-8/7:- Completed. AP13-14:- F/Sag will be started soon. AP54-55:- Completed. | O11: =(J11/C11)*100 -> 54.395011 | Q11: Stringing!A1
A12: 8 | B12: OPGW (Kms) | C12: =C11 -> 191.392 | D12: 81.07 | E12: =C12-D12-33.766 -> 76.556 | F12: 0 | J12: =D12+H12 -> 81.07 | K12: =+E12-H12 -> 76.556 | O12: =(J12/C12)*100 -> 42.358092 | Q12: Stringing associated works'!A1
Q13: OPGW!A1
A14: Workfront Status | Q14: Visual chart'!A1
Q15: Page Chart'!A1
A16: A. Foundation | Q16: Benching F'!A1
A17: Balance on 1st of this month | B17: Progress MTD | C17: WIP | D17: Clear/Yet to attempt | E17: ROW | F17: Remarks
A18: =E6 -> 0 | B18: =H6 -> 0 | C18: =I6 -> 0 | D18: ='Page Chart'!R4 -> 0 | E18: =A18-B18-C18-D18 -> 0
A20: B. Erection
A21: Balance on 1st of this month | B21: Progress MTD | C21: WIP | D21: Clear/Yet to attempt | E21: ROW | F21: Linked With Fnd | G21: Remarks
A22: =E8 -> 10 | B22: =H8 -> 0 | C22: =I8 -> 2 | D22: ='Page Chart'!W4+'Page Chart'!Y4-F22 -> 0 | E22: ='Page Chart'!X4 -> 8 | F22: =E18 -> 0
A24: C. Stringing
A25: STR P/Out Bal. on starting of this month | B25: Progress MTD | C25: WIP | D25: Clear/Yet to attempt | E25: ROW | F25: Readiness awaited due to Erec. | G25: Readiness awaited due to Tower Inspection
A26: =E10 -> 62.065 | B26: =H10 -> 10.65 | C26: =I10 -> 13.765

Sheet Project Details
A1: Project Code | B1: Project Name | C1: Client Name | D1: NOA Start Date | E1: LOA End Date | F1: Planning Engineer | G1: PCH | H1: Regional Manager | I1: Project Manger | J1: Section Incharge | K1: Supervisor
A2: TB408 | B2: 765 KV Beawer Transmission Line, PKG F | C2: Resonia Limited | D2: 45266 | E2: 45960 | F2: Mr. Raghav Ranjan | G2: Mr. Sanjay Kumar Gupta | H2: Mr. Sandeep Singh Kumar | I2: Mr. Partha Pal | J2: Dev Saran Swarakar | K2: Pradeep Kumar
I3: Mr. Virendra Gupta | J3: Rajeev Kumar | K3: Vikas Kumar
J4: Vivek Shukla | K4: Ganesh Singh
J5: Shubham Kumar | K5: Dineshwar Mahto
J6: Ram Tirath Singh | K6: Kamla Pal Prasad
J7: Jitendra Saini | K7: Bisun Saw
K8: Shakib Hussain
K9: Umesh Prasad
K10: Prince Kumar Nirala
K11: Pramod Kumar Sahoo
K12: Jainath Mahto
K13: Rajesh Pal
K14: Ramji Tanti
K15: Rakesh Pramanik
K16: Sam Mahammad
K17: Suresh Kumar Pal
K18: Hulas Kumar Mahto
K19: Vaibhav Sharma
... K38: Laxman Sarkar

Sheet X-ing Status
A1: Progress Summary'!A1
A2: Details of Crossing in 765KV D/C Fatehgarh-III to Beawar Transmission Line
A3: Sr. No. | B3: Name of Crossing | C3: From | D3: To | E3: Span in Mtrs | F3: Foundation Status | G3: Erection Status | H3: Stringing Status | I3: Plan for Stringing
A4: Power Line Crossing – 9 nos
A5: 1 | B5: 400 KV S/C Jaisalmer-Barmer Line | C5: 3/0 | D5: 4/0 | E5: 226.52 | F5: AP3:- Completed AP4:- Completed | G5: AP3:- Completed AP4:- Completed | H5: Completed
A6: 2 | B6: 220 KV D/C Barmer-Akal Line | C6: 5/0 | D6: 6/0 | E6: 246.019 | F6: AP5:- Completed AP6:- Completed | G6: AP5:- Completed AP6:- Completed | H6: Balance
A7: 3 | B7: 132 KV S/C Sheo-Jaisalmer Line | C7: 7/0 | D7: 8/0 | E7: 210.755 | F7: AP7:- Completed AP8:- Completed | G7: AP7:- Completed AP8:- Completed | H7: Completed
A8: 4 | B8: 400 KV D/C Barmer-Jaisalmer-2 Line | C8: 9/0 | D8: 10/0 | E8: 233.076 | F8: AP9:- Completed AP10:- Completed | G8: AP9:- Completed AP10:- Completed | H8: Completed
A9: 5 | B9: 132 KV S/C Sheo-Undoo Line | C9: 12/0 | D9: 13/0 | E9: 211.914 | F9: AP12:- Completed AP13:- Completed | G9: AP12:- Completed AP13:- Completed | H9: Balance
A10: 6 | B10: 132 KV S/C Undoo-Baytoo Line | C10: 23/0 | D10: 24/0 | E10: 222.155 | F10: AP23:- Completed AP24:- Completed | G10: AP23:- Balance AP24:- Completed | H10: Balance
A11: 7 | B11: 400 KV D/C Mandor-JSW Transmission Line | C11: 46/0 | D11: 47/0 | E11: 197.7 | F11: AP46:- Completed AP47:- Completed | G11: AP46:- Completed AP47:- Completed | H11: Completed
A12: 8 | B12: 400 KV D/C Line | C12: 56/0 | D12: 57/0 | E12: 179.9 | F12: AP56:- Completed AP57:- Completed | G12: AP56:- Completed AP57:- Completed | H12: Completed
A13: 9 | B13: 220 KV D/C Balotra-Boranada Transmission Line | C13: 66/0 | D13: 67/0 | E13: 207.8 | F13: AP66:- Completed AP67:- Completed | G13: AP66:- Completed AP67:- Completed | H13: Completed
A14: NH Crossings-3 Nos | B14: NH Crossing
A15: 1 | B15: NH - 68 (Barmer - Jaisalmer) | C15: 5/0 | D15: 6/0 | E15: 246.019 | F15: AP5:- Completed AP6:- Completed | G15: AP5:- Completed AP6:- Completed | H15: Balance
A16: 2 | B16: Expressway (Amritsar-Jamnagar) | C16: 58/0 | D16: 59/0 | E16: 238.9 | F16: AP58:- Completed AP59:- Completed | G16: AP58:- Completed AP59:- Completed | H16: Completed
A17: 3 | B17: NH | C17: 68/0 | D17: 69/0 | E17: 200.9 | F17: AP68:- Completed AP69:- Completed | G17: AP68:- Completed AP69:- Completed | H17: Completed
A18: Gas Pipe Line-1 Nos | B18: NH Crossing
A19: 1 | B19: Gas Pipe Lines | C19: 65/7 | D19: 65/8 | E19: 394.3 | F19: AP65/7:- Completed AP65/8:- Completed | G19: AP65/7:- Completed AP65/8:- Completed | H19: Completed

Sheet L2 Schedule
A1: Progress Summary'!A1 | B1: L2 Schedule vs Actual
B3: Line Name: Part F, 765KV D/C Fatehgarh- Beawar Transmission Line
B4: LOI Date: 11-Sep-2023
B5: Effective Date: 06-Dec-2023
B6: Schedule Completion as per LOA: 05-March-2025 | E6: Time Extension Extended till- 28.02.2026 (Further Extension applied till 30 July 2026)
B7: Scope & Discription | G7: Before L2 | H7: L2-Approved | X7: Extension of time (Approved) -1 | AE7: Extension of time (Approved) -2 | AI7: Extension of time-3 (Proposed) | AN7: Remarks
B8: Sr. No. | C8: Description | D8: Scope of Work | E8: UOM | F8: Qty. | G8: 45200 | H8: 45261 | I8: 45292 | J8: 45323 | K8: 45352 | L8: 45383 | M8: 45413 | N8: 45444 | O8: 45474 | P8: 45505 | Q8: 45536 | R8: 45566 | S8: 45597 | T8: 45627 | U8: 45658 | V8: 45689 | W8: 45717 | X8: 45748 | Y8: 45778 | Z8: 45809 | AA8: 45839 | AB8: 45870 | AC8: 45901 | AD8: 45931 | AE8: 45962 | AF8: 45992 | AG8: 46023 | AH8: 46054 | AI8: 46082 | AJ8: 46113 | AK8: 46143 | AL8: 46174 | AM8: 46204
G9: 0 | H9: 1 | I9: 2 | J9: 3 | K9: 4 | L9: 5 | M9: 6 | N9: 7 | O9: 8 | P9: 9 | Q9: 10 | R9: 11 | S9: 12 | T9: 13 | U9: 14 | V9: 15 | W9: 16 | X9: 17 | Y9: 18 | Z9: 19 | AA9: 20 | AB9: 21 | AC9: 22 | AD9: 23 | AE9: 24 | AF9: 25 | AG9: 26 | AH9: 27 | AI9: 28 | AJ9: 29 | AK9: 30 | AL9: 31 | AM9: 32
B10: 1 | C10: Release of Sag Template Curve & Tower Spotting Data | D10: Sterlite
B11: 2 | C11: Approval of repeated tower design & its BOMS | D11: Sterlite
B12: 3 | C12: Approval of repeated foundation design/drawings | D12: Sterlite
B13: 4 | C13: Supply
B14: i) | C14: Manufacturing of Stubs with Earthing material(incl. B&N) | D14: KEC
B15: A. | C15: Inspection of stub | D15: Sterlite | E15: Nos. | F15: 482 | H15: 40 | I15: 100 | J15: 100 | L15: 100 | M15: 65 | O15: 77
B16: B. | C16: Dispatch of stub | D16: KEC | E16: Nos. | F16: 482 | H16: =H15 -> 40 | I16: =I15 -> 100 | J16: =J15 -> 100 | K16: =K15 -> 0 | L16: =L15 -> 100 | M16: =M15 -> 65 | N16: =N15 -> 0 | O16: =O15 -> 77 | ... T16: =T15 -> 0
B17: C. | C17: Receipt of stubs at site | D17: KEC | E17: Nos. | F17: 482 | H17: =H15 -> 40 | I17: =I15 -> 100 | J17: =J15 -> 100 | K17: =K15 -> 0 | L17: =L15 -> 100 | M17: =M15 -> 65 | N17: =N15 -> 0 | O17: =O15 -> 77 | ... T17: =T15 -> 0
C18: MFC submitted on | H18: 192 | I18: 73 | J18: 73
C19: MFC received on | H19: =75+75+20+15+2+5 -> 192 | I19: =265-192 -> 73 | K19: =338-265 -> 73 | N19: =482-338 -> 144
C20: Actual | H20: 40 | I20: 120 | J20: 0 | K20: 10 | M20: 152 | N20: =361-322 -> 39 | O20: 5 | R20: =393-366 -> 27
B21: ii) | C21: Manufacturing of Tower (incl B&N) | D21: KEC
B22: A. | C22: Inspection of tower | D22: Sterlite | E22: Nos. | F22: 482 | H22: 50 | I22: 60 | J22: 60 | K22: 60 | L22: 60 | M22: 65 | N22: 66 | O22: 31 | P22: 30
B23: B. | C23: Dispatch of tower | D23: KEC | E23: Nos. | F23: 482 | I23: 50 | J23: 60 | K23: 60 | L23: 60 | M23: 60 | N23: 65 | O23: 66 | P23: 31 | Q23: 30 | R23: =R22 -> 0 | S23: =S22 -> 0 | T23: =T22 -> 0
B24: C. | C24: Receipt of complete towers at site | D24: KEC | E24: Nos. | F24: 482 | I24: 50 | J24: 60 | K24: 60 | L24: 60 | M24: 60 | N24: 65 | O24: 66 | P24: 31 | Q24: 30 | R24: =+R23 -> 0 | S24: =+S23 -> 0 | T24: =+T23 -> 0
C25: MFC submitted on | H25: 97 | I25: 128 | M25: 65 | N25: =482-290 -> 192
C26: MFC received on | H26: 97 | I26: 128 | N26: 257
C27: Actual | I27: 50 | J27: 60 | K27: 45 | L27: 74 | M27: 9 | N27: 99 | Q27: 54 | S27: 10
B28: iii) | C28: Supply of following Tower accessories
B29: A. | C29: Danger Plate | D29: KEC | E29: % | F29: 100 | P29: 1
B30: B. | C30: Number Plate | D30: KEC | E30: % | F30: 100 | P30: 1
B31: C. | C31: Phase Plate (Set of three) | D31: KEC | E31: % | F31: 100 | P31: 1
B32: D. | C32: Circuit Plate (Set of Two) | D32: KEC | E32: & | F32: 100 | P32: 1
B33: E. | C33: Anti-Climbing Device | D33: KEC | E33: % | F33: 100 | P33: 1
B34: F. | C34: Bird Guard (Set of Three) | D34: KEC | E34: % | F34: 100 | P34: 1
B35: iv) | C35: Other's Supply
B36: A. | C36: Span Marker | D36: KEC | E36: % | F36: 100 | P36: 1
B37: B. | C37: Aviation Light | D37: KEC | E37: % | F37: 100 | P37: 1
B38: v) | C38: OSM
B39: A. | C39: Supply of AL59 Zebra Conductor & associated Acessories | D39: Sterlite | E39: % | F39: 100 | K39: 0.25 | N39: 0.25 | P39: 0.25 | R39: 0.25
B40: B. | C40: Supply of Insulator & associated Hardwere | D40: Sterlite | E40: % | F40: 100 | K40: 0.25 | N40: 0.25 | P40: 0.25 | R40: 0.25
B41: C. | C41: Supply of Earth Wire & associated Hardwere | D41: Sterlite | E41: % | F41: 100 | H41: =H40 -> 0 | I41: =I40 -> 0 | K41: 0.25 | L41: =L40 -> 0 | N41: 0.25 | O41: =O40 -> 0 | P41: 0.25 | R41: 0.25
...

Sheet Hindrance Register (Row)
A1: Progress Summary'!A1
A2: HINDRANCE REGISTER (Note:- Day to day hindrance are captured on other sheet and intimate to resonia via DPR on Summary Sheet)
A3: 1 | B3: Name of the Substation/TL/Project | C3: 765 KV Fatehgarh-3 Beawer Transmission Line Part-F | G3: 2. Name of Work | I3: Transmission & Power Distribution
A4: 3 | B4: Name of the Executing Agency | C4: KEC International Limited | G4: 3. LOA No. & Date | I4: LOI/EPC/FBTL/PART-F/KEC/01 Dated 11.09.2023
A6: Sr. No. | B6: Activity | C6: Total | D6: Open | E6: Close | I6: Progress Summary'!A1
A7: 1 | B7: Survey | C7: =+COUNTIF($D$15:$D$983,B7) -> 20 | D7: =+COUNTIFS($D$15:$D$984,B7,$H$15:$H$984,"AWAITED") -> 0 | E7: =C7-D7 -> 20
A8: 2 | B8: Foundation | C8: =+COUNTIF($D$15:$D$983,B8) -> 210 | D8: =+COUNTIFS($D$15:$D$984,B8,$H$15:$H$984,"AWAITED") -> 0 | E8: =C8-D8 -> 210
A9: 3 | B9: Erection | C9: =+COUNTIF($D$15:$D$983,B9) -> 87 | D9: =+COUNTIFS($D$15:$D$984,B9,$H$15:$H$984,"AWAITED") -> 8 | E9: =C9-D9 -> 79
A10: 4 | B10: Stringing | C10: =+COUNTIF($D$15:$D$983,B10) -> 32 | D10: =+COUNTIFS($D$15:$D$984,B10,$H$15:$H$984,"AWAITED") -> 14 | E10: =C10-D10 -> 18
A11: 5 | B11: Others | C11: =+COUNTIF($D$15:$D$983,B11) -> 3 | D11: =+COUNTIFS($D$15:$D$984,B11,$H$15:$H$984,"AWAITED") -> 0 | E11: =C11-D11 -> 3
A12: Total | C12: =SUM(C7:C11) -> 352 | D12: =+SUM(D7:D11) -> 22 | E12: =+SUM(E7:E11) -> 330
A14: Check Survey
A15: S.No | B15: Nature of Hindrance | C15: Loc/Sec. | D15: Affected Activity | E15: Affected Gang Name | F15: Date of 1st attempt | G15: Date of removal (Last attempt) | H15: Period of hindrance | I15: Remarks
A16: 1 | B16: Check survey not done due to frequent obstruction by land owner from 38/0 to 39/0. | C16: 38-39 | D16: Survey | F16: 45266 | G16: 45575 | H16: =+IF(G16="","Awaited",_xlfn.DAYS(G16,F16)+1) -> 310 | I16: Refer KEC letter dated 02-01-24. Reattempted on 09-01-24 but still in ROW. 3rd time attempted on dated 10.07.24 informed to you via mail regarding ROW.
A17: 2 | B17: Check survey not done due to frequent obstruction by land owner from 39/0 to 40/0. | C17: 39-40 | D17: Survey | F17: 45266 | G17: 45575 | H17: =+IF(G17="","Awaited",_xlfn.DAYS(G17,F17)+1) -> 310 | I17: Refer KEC letter dated 02-01-24. Reattempted on 09-01-24 but still in ROW. 3rd time attempted on dated 10.07.24 informed to you via mail regarding ROW.
A18: 3 | B18: Check survey is on hold from Gantry to 2/0 due to Non-Finalization of Gantry. | C18: Gty-2 | D18: Survey | F18: 45266 | G18: 45488 | H18: =+IF(G18="","Awaited",_xlfn.DAYS(G18,F18)+1) -> 223 | I18: Refer KEC letter dated 02-01-24.
A19: 4 | B19: Check survey not done due to frequent obstruction by land owner from 10/12 to 11A. | C19: 10/12-11A | D19: Survey | F19: 45266 | G19: 45307 | H19: =+IF(G19="","Awaited",_xlfn.DAYS(G19,F19)+1) -> 42 | I19: Refer KEC letter dated 02-01-24.
A20: 5 | B20: Check survey not done due to ROW from AP 20-AP 21. | C20: 20-21 | D20: Survey | F20: 45266 | G20: 45831 | H20: =+IF(G20="","Awaited",_xlfn.DAYS(G20,F20)+1) -> 566 | I20: Refer KEC letter dated 02-01-24. SPTL mail dated 20/5/24 having subject Optimization from GTY to AP74 (Part- F). Clearance for check survey received on 17.10.24. however survey team along with machinery idled at this section since 18th. Section is still in ROW. on dated 19.10.2024.
A21: 6 | B21: Delay in approval of check survey report from Ap 21 to AP 25. | C21: 21-25 | D21: Survey | F21: 45266 | G21: 45274 | H21: =+IF(G21="","Awaited",_xlfn.DAYS(G21,F21)+1) -> 9
A22: 7 | B22: Delay in approval of check survey report from Ap 14 to AP 20. | C22: 14-20 | D22: Survey | F22: 45266 | G22: 45274 | H22: =+IF(G22="","Awaited",_xlfn.DAYS(G22,F22)+1) -> 9
A23: 8 | B23: ROW in check survey works. | C23: 47-48 | D23: Survey | F23: 45272 | G23: 45274 | H23: =+IF(G23="","Awaited",_xlfn.DAYS(G23,F23)+1) -> 3
A24: 9 | B24: ROW in check survey works. | C24: 70-71 | D24: Survey | F24: 45275 | G24: 45636 | H24: =+IF(G24="","Awaited",_xlfn.DAYS(G24,F24)+1) -> 362
A25: 10 | B25: ROW in check survey works. | C25: 71-72 | D25: Survey | F25: 45275 | G25: 45331 | H25: =+IF(G25="","Awaited",_xlfn.DAYS(G25,F25)+1) -> 57
A26: 11 | B26: ROW in check survey works. | C26: 72-73 | D26: Survey | F26: 45275 | G26: 45331 | H26: =+IF(G26="","Awaited",_xlfn.DAYS(G26,F26)+1) -> 57
A27: 12 | B27: ROW in check survey works. | C27: 73-74 | D27: Survey | F27: 45275 | G27: 45487 | H27: =+IF(G27="","Awaited",_xlfn.DAYS(G27,F27)+1) -> 213
A28: 13 | B28: Delay in approval of check survey report from Ap 32 to AP 37. | C28: 32-37 | D28: Survey | F28: 45281 | G28: 45289 | H28: =+IF(G28="","Awaited",_xlfn.DAYS(G28,F28)+1) -> 9
A29: 14 | B29: Delay in approval of check survey From AP 2-10/12 | C29: 2-10/12 | D29: Survey | F29: 45286 | G29: 45316 | H29: =+IF(G29="","Awaited",_xlfn.DAYS(G29,F29)+1) -> 31 | I29: Email dated 18/1/24 regarding Frequent obstruction by landowners.
A30: 15 | B30: Delay in approval of check survey From AP 11A-14. | C30: 11A-14 | D30: Survey | F30: 45286 | G30: 45316 | H30: =+IF(G30="","Awaited",_xlfn.DAYS(G30,F30)+1) -> 31 | I30: Email dated 18/1/24 regarding Frequent obstruction by landowners.
A31: 16 | B31: Location no 11/5 are on Hold due to ROW during check survey, Centre peg not done for verification of benching and others. | C31: 11/5 | D31: Survey | F31: 45308 | G31: 45432 | H31: =+IF(G31="","Awaited",_xlfn.DAYS(G31,F31)+1) -> 125 | I31: Email dated 18/1/24 regarding Frequent obstruction by landowners.
A32: 17 | B32: Location no 11A/0 are on Hold due to ROW during check survey, Centre peg not done for verification of benching and others. | C32: 11A/0 | D32: Survey | F32: 45308 | G32: 45432 | H32: =+IF(G32="","Awaited",_xlfn.DAYS(G32,F32)+1) -> 125 | I32: Email dated 18/1/24 regarding Frequent obstruction by landowners.
A33: 18 | B33: ROW in check survey works. | C33: 40-41 | D33: Survey | F33: 45318 | G33: 45390 | H33: =+IF(G33="","Awaited",_xlfn.DAYS(G33,F33)+1) -> 73
A34: 19 | B34: ROW in check survey works. | C34: 41-42 | D34: Survey | F34: 45318 | G34: 45390 | H34: =+IF(G34="","Awaited",_xlfn.DAYS(G34,F34)+1) -> 73
A35: 20 | B35: ROW in check survey works. | C35: 42-43 | D35: Survey | F35: 45318 | G35: 45390 | H35: =+IF(G35="","Awaited",_xlfn.DAYS(G35,F35)+1) -> 73
A38: Foundation
A39: S.No | B39: Nature of Hindrance | C39: Loc/Sec. | D39: Affected Activity | E39: Affected Gang Name | F39: Date of occurrence | G39: Date of removal | H39: Period of hindrance | I39: Remarks
A40: =+SUBTOTAL(3,$B$40:B40) -> 1 | B40: ROW due to obstruction by land owner at Loc No 37/2. Post Excavation work was stopped by Land owners. After that cleared on 07/12/2023. | C40: 37/2 | D40: Foundation | E40: Nagana Rai | F40: 45266 | G40: 45267 | H40: =+IF(G40="","Awaited",_xlfn.DAYS(G40,F40)+1) -> 2
A41: =+SUBTOTAL(3,$B$40:B41) -> 2 | B41: ROW encountered in Excavation works. | C41: 62/6 | D41: Foundation | F41: 45274 | G41: 45275 | H41: =+IF(G41="","Awaited",_xlfn.DAYS(G41,F41)+1) -> 2
A42: =+SUBTOTAL(3,$B$40:B42) -> 3 | B42: ROW due to obstruction by land owner at Loc No 26/2. | C42: 26/2 | D42: Foundation | E42: A.B. Construction | F42: 45276 | G42: 45277 | H42: =+IF(G42="","Awaited",_xlfn.DAYS(G42,F42)+1) -> 2 | I42: Refer Mail dated 16/12/2023.
A43: =+SUBTOTAL(3,$B$40:B43) -> 4 | B43: Our Whole team of one gang along with its machinery are completely idle at location no 26/2 | C43: 26/2 | D43: Foundation | E43: A.B. Construction | F43: 45276 | G43: 45277 | H43: =+IF(G43="","Awaited",_xlfn.DAYS(G43,F43)+1) -> 2 | I43: Idled Resources (Highly Skilled manpower-1, Skilled:- 2, Semi Skilled:- 3, Unskilled:- 4, JCB with operator:- 1, Azax flori with operator:- 1, Tracktor with operator:- 1, Tanker with Operator:- 1, Bolero/Camper with Diesel:- 1)
A44: =+SUBTOTAL(3,$B$40:B44) -> 5 | B44: ROW at Location No 27/11. | C44: 27/11 | D44: Foundation | E44: Nagana Rai | F44: 45266 | G44: 45334 | H44: =+IF(G44="","Awaited",_xlfn.DAYS(G44,F44)+1) -> 69 | I44: Email dated 18/1/24 regarding Frequent obstruction by landowners. Your email dated 12.02.24 regarding workfront
...

Sheet Page Chart
A1: Progress Summary'!A1 | N1: Village wise dashboard
A2: Location Wise Status | I2: Post Stringing work | N2: Foundation | T2: Erection | AA2: Stringing
A3: Sr. No. | B3: Loc No. | C3: TOT | D3: Village Name | E3: Span | F3: FDN | G3: ERE | H3: Str | I3: Hoisting | J3: Clipp. | K3: Spac. | L3: Jump. | M3: Remarks (if any) | N3: Village wise breakups | O3: Total | P3: Comp. | Q3: WIP | R3: Clear | S3: ROW | T3: Total | U3: Comp. | V3: WIP | W3: Clear | X3: ROW | Y3: Yet to attempt | Z3: Balance | AA3: Scope | AB3: C | AC3: WIP | AD3: Clear | AE3: ROW | AF3: Dep. | AG3: Other Fac.
A4: =+SUBTOTAL(3,$B$4:B4) -> 0 | B4: ='Visual chart Edit'!B7 -> 1/0 | C4: ='Visual chart Edit'!C7 -> DD60+0 | D4: Mandai | E4: ='Visual chart Edit'!I7 -> 122 | F4: ='Visual chart Edit'!K7 -> DRY | G4: ='Visual chart Edit'!L7 -> E | H4: C | I4: C | K4: C | L4: C | N4: Village (49 No's) | O4: =+SUM(O5:O53) -> 485 | P4: =+SUM(P5:P53) -> 485 | Q4: =+SUM(Q5:Q53) -> 0 | R4: =+SUM(R5:R53) -> 0 | S4: =+SUM(S5:S53) -> 0 | T4: =+SUM(T5:T53) -> 485 | U4: =+SUM(U5:U53) -> 475 | V4: =+SUM(V5:V53) -> 2 | ... Y4: =+SUM(Y5:Y53) -> 0 | Z4: =T4-U4 -> 10 | AA4: =+SUM(AA5:AA53) -> 191.39264 | AB4: =+SUM(AB5:AB53) -> 98.535075 | AC4: =+SUM(AC5:AC53) -> 14.4555 | AD4: =+SUM(AD5:AD53) -> 0 | AE4: =+SUM(AE5:AE53) -> 0 | AF4: =+SUM(AF5:AF53) -> 0 | AG4: =+SUM(AG5:AG53) -> 78.402068
A5: =+SUBTOTAL(3,$B$4:B5) -> 0 | B5: ='Visual chart Edit'!B8 -> 1A/0 | C5: ='Visual chart Edit'!C8 -> DD60+0 | D5: Mandai | E5: ='Visual chart Edit'!I8 -> 90 | F5: ='Visual chart Edit'!K8 -> DRY | G5: ='Visual chart Edit'!L8 -> E | H5: C | I5: C | K5: C | L5: C | N5: Mandai | O5: =+SUM(P5:S5) -> 16 | P5: =+COUNTIFS($D$4:$D$488,N5,$F$4:$F$488,"sandy")+COUNTIFS($D$4:$D$488,N5,$F$4:$F$488,"Dry")+COUNTIFS($D$4:$D$488,N5,$F$4:$F$488,"DFR")+COUNTIFS($D$4:$D$488,N5,$F$4:$F$488,"WFR")+COUNTIFS($D$4:$D$488,N5,$F$4:$F$488,"SFR") -> 16 | Q5: =+COUNTIFS($D$4:$D$488,N5,$F$4:$F$488,"WIP") -> 0 | R5: =+COUNTIFS($D$4:$D$488,N5,$F$4:$F$488,"Clear") -> 0 | S5: =+COUNTIFS($D$4:$D$488,N5,$F$4:$F$488,"ROW") -> 0 | T5: =+SUM(U5:Y5) -> 16 | U5: =+COUNTIFS($D$4:$D$488,N5,$G$4:$G$488,"E") -> 16 | V5: =+COUNTIFS($D$4:$D$488,N5,$G$4:$G$488,"WIP") -> 0 | W5: =+COUNTIFS($D$4:$D$488,N5,$G$4:$G$488,"Clear") -> 0 | X5: =+COUNTIFS($D$4:$D$488,N5,$G$4:$G$488,"ROW") -> 0 | Y5: =O5-X5-U5-W5-V5 -> 0 | Z5: =T5-U5 -> 0 | AA5: =+SUMIFS($E$4:$E$488,$D$4:$D$488,N5)/1000 -> 5.6287 | AB5: =+SUMIFS($E$4:$E$488,$D$4:$D$488,N5,$H$4:$H$488,$AB$3)/1000 -> 5.6287 | AC5: =+SUMIFS($E$4:$E$488,$D$4:$D$488,N5,$H$4:$H$488,$AC$3)/1000 -> 0 | AD5: =+SUMIFS($E$4:$E$488,$D$4:$D$488,N5,$H$4:$H$488,$AD$3)/1000 -> 0 | AE5: =+SUMIFS($E$4:$E$488,$D$4:$D$488,N5,$H$4:$H$488,$AE$3)/1000 -> 0 | AF5: =+SUMIFS($E$4:$E$488,$D$4:$D$488,N5,$H$4:$H$488,$AF$3)/1000 -> 0 | AG5: =AA5-SUM(AB5:AF5) -> 0
A6: =+SUBTOTAL(3,$B$4:B6) -> 0 | B6: ='Visual chart Edit'!B9 -> 1A/1 | C6: ='Visual chart Edit'!C9 -> DA+6 | D6: Mandai | E6: ='Visual chart Edit'!I9 -> 277.7 | F6: ='Visual chart Edit'!K9 -> DFR | G6: ='Visual chart Edit'!L9 -> E | H6: C | I6: C | J6: C | K6: C | N6: Harwa | O6: =+SUM(P6:S6) -> 22 | P6: =+COUNTIFS($D$4:$D$488,N6,$F$4:$F$488,"sandy")+COUNTIFS($D$4:$D$488,N6,$F$4:$F$488,"Dry")+COUNTIFS($D$4:$D$488,N6,$F$4:$F$488,"DFR")+COUNTIFS($D$4:$D$488,N6,$F$4:$F$488,"WFR")+COUNTIFS($D$4:$D$488,N6,$F$4:$F$488,"SFR") -> 22 | Q6: =+COUNTIFS($D$4:$D$488,N6,$F$4:$F$488,"WIP") -> 0 | R6: =+COUNTIFS($D$4:$D$488,N6,$F$4:$F$488,"Clear") -> 0 | S6: =+COUNTIFS($D$4:$D$488,N6,$F$4:$F$488,"ROW") -> 0 | T6: =+SUM(U6:Y6) -> 22 | U6: =+COUNTIFS($D$4:$D$488,N6,$G$4:$G$488,"E") -> 22 | V6: =+COUNTIFS($D$4:$D$488,N6,$G$4:$G$488,"WIP") -> 0 | W6: =+COUNTIFS($D$4:$D$488,N6,$G$4:$G$488,"Clear") -> 0 | X6: =+COUNTIFS($D$4:$D$488,N6,$G$4:$G$488,"ROW") -> 0 | Y6: =O6-X6-U6-W6-V6 -> 0 | Z6: =T6-U6 -> 0 | AA6: =+SUMIFS($E$4:$E$488,$D$4:$D$488,N6)/1000 -> 7.9501 | AB6: =+SUMIFS($E$4:$E$488,$D$4:$D$488,N6,$H$4:$H$488,$AB$3)/1000 -> 2.0597 | AC6: =+SUMIFS($E$4:$E$488,$D$4:$D$488,N6,$H$4:$H$488,$AC$3)/1000 -> 4.4404 | AD6: =+SUMIFS($E$4:$E$488,$D$4:$D$488,N6,$H$4:$H$488,$AD$3)/1000 -> 0 | AE6: =+SUMIFS($E$4:$E$488,$D$4:$D$488,N6,$H$4:$H$488,$AE$3)/1000 -> 0 | AF6: =+SUMIFS($E$4:$E$488,$D$4:$D$488,N6,$H$4:$H$488,$AF$3)/1000 -> 0 | AG6: =AA6-SUM(AB6:AF6) -> 1.45
A7: =+SUBTOTAL(3,$B$4:B7) -> 0 | B7: ='Visual chart Edit'!B10 -> 1A/2 | C7: ='Visual chart Edit'!C10 -> DA+0 | D7: Mandai | E7: ='Visual chart Edit'!I10 -> 386 | F7: ='Visual chart Edit'!K10 -> DRY | G7: ='Visual chart Edit'!L10 -> E | H7: C | I7: C | J7: C | K7: C | N7: Chak Goonga | O7: =+SUM(P7:S7) -> 8 | P7: =+COUNTIFS($D$4:$D$488,N7,$F$4:$F$488,"sandy")+COUNTIFS($D$4:$D$488,N7,$F$4:$F$488,"Dry")+COUNTIFS($D$4:$D$488,N7,$F$4:$F$488,"DFR")+COUNTIFS($D$4:$D$488,N7,$F$4:$F$488,"WFR")+COUNTIFS($D$4:$D$488,N7,$F$4:$F$488,"SFR") -> 8 | Q7: =+COUNTIFS($D$4:$D$488,N7,$F$4:$F$488,"WIP") -> 0 | R7: =+COUNTIFS($D$4:$D$488,N7,$F$4:$F$488,"Clear") -> 0 | S7: =+COUNTIFS($D$4:$D$488,N7,$F$4:$F$488,"ROW") -> 0 | T7: =+SUM(U7:Y7) -> 8 | U7: =+COUNTIFS($D$4:$D$488,N7,$G$4:$G$488,"E") -> 8 | V7: =+COUNTIFS($D$4:$D$488,N7,$G$4:$G$488,"WIP") -> 0 | W7: =+COUNTIFS($D$4:$D$488,N7,$G$4:$G$488,"Clear") -> 0 | X7: =+COUNTIFS($D$4:$D$488,N7,$G$4:$G$488,"ROW") -> 0 | Y7: =O7-X7-U7-W7-V7 -> 0 | Z7: =T7-U7 -> 0 | AA7: =+SUMIFS($E$4:$E$488,$D$4:$D$488,N7)/1000 -> 3.130267 | AB7: =+SUMIFS($E$4:$E$488,$D$4:$D$488,N7,$H$4:$H$488,$AB$3)/1000 -> 2.456067 | AC7: =+SUMIFS($E$4:$E$488,$D$4:$D$488,N7,$H$4:$H$488,$AC$3)/1000 -> 0.4411 | AD7: =+SUMIFS($E$4:$E$488,$D$4:$D$488,N7,$H$4:$H$488,$AD$3)/1000 -> 0 | AE7: =+SUMIFS($E$4:$E$488,$D$4:$D$488,N7,$H$4:$H$488,$AE$3)/1000 -> 0 | AF7: =+SUMIFS($E$4:$E$488,$D$4:$D$488,N7,$H$4:$H$488,$AF$3)/1000 -> 0 | AG7: =AA7-SUM(AB7:AF7) -> 0.2331
A8: =+SUBTOTAL(3,$B$4:B8) -> 0 | B8: ='Visual chart Edit'!B11 -> 1A/3 | C8: ='Visual chart Edit'!C11 -> DA+0 | D8: Mandai | E8: ='Visual chart Edit'!I11 -> 443.6 | F8: ='Visual chart Edit'!K11 -> DRY | G8: ='Visual chart Edit'!L11 -> E | H8: C | I8: C | J8: C | K8: C | N8: Goonga | O8: =+SUM(P8:S8) -> 5 | P8: =+COUNTIFS($D$4:$D$488,N8,$F$4:$F$488,"sandy")+COUNTIFS($D$4:$D$488,N8,$F$4:$F$488,"Dry")+COUNTIFS($D$4:$D$488,N8,$F$4:$F$488,"DFR")+COUNTIFS($D$4:$D$488,N8,$F$4:$F$488,"WFR")+COUNTIFS($D$4:$D$488,N8,$F$4:$F$488,"SFR") -> 5 | Q8: =+COUNTIFS($D$4:$D$488,N8,$F$4:$F$488,"WIP") -> 0 | R8: =+COUNTIFS($D$4:$D$488,N8,$F$4:$F$488,"Clear") -> 0 | S8: =+COUNTIFS($D$4:$D$488,N8,$F$4:$F$488,"ROW") -> 0 | T8: =+SUM(U8:Y8) -> 5 | U8: =+COUNTIFS($D$4:$D$488,N8,$G$4:$G$488,"E") -> 5 | V8: =+COUNTIFS($D$4:$D$488,N8,$G$4:$G$488,"WIP") -> 0 | W8: =+COUNTIFS($D$4:$D$488,N8,$G$4:$G$488,"Clear") -> 0 | X8: =+COUNTIFS($D$4:$D$488,N8,$G$4:$G$488,"ROW") -> 0 | Y8: =O8-X8-U8-W8-V8 -> 0 | Z8: =T8-U8 -> 0 | AA8: =+SUMIFS($E$4:$E$488,$D$4:$D$488,N8)/1000 -> 2.0524 | AB8: =+SUMIFS($E$4:$E$488,$D$4:$D$488,N8,$H$4:$H$488,$AB$3)/1000 -> 2.0524 | AC8: =+SUMIFS($E$4:$E$488,$D$4:$D$488,N8,$H$4:$H$488,$AC$3)/1000 -> 0 | AD8: =+SUMIFS($E$4:$E$488,$D$4:$D$488,N8,$H$4:$H$488,$AD$3)/1000 -> 0 | AE8: =+SUMIFS($E$4:$E$488,$D$4:$D$488,N8,$H$4:$H$488,$AE$3)/1000 -> 0 | AF8: =+SUMIFS($E$4:$E$488,$D$4:$D$488,N8,$H$4:$H$488,$AF$3)/1000 -> 0 | AG8: =AA8-SUM(AB8:AF8) -> 0
A9: =+SUBTOTAL(3,$B$4:B9) -> 0 | B9: ='Visual chart Edit'!B12 -> 1A/4 | C9: ='Visual chart Edit'!C12 -> DA+3 | D9: Mandai | E9: ='Visual chart Edit'!I12 -> 333.4 | F9: ='Visual chart Edit'!K12 -> DFR | G9: ='Visual chart Edit'!L12 -> E | H9: C | I9: C | J9: C | K9: C | N9: Pusar | O9: =+SUM(P9:S9) -> 14 | P9: =+COUNTIFS($D$4:$D$488,N9,$F$4:$F$488,"sandy")+COUNTIFS($D$4:$D$488,N9,$F$4:$F$488,"Dry")+COUNTIFS($D$4:$D$488,N9,$F$4:$F$488,"DFR")+COUNTIFS($D$4:$D$488,N9,$F$4:$F$488,"WFR")+COUNTIFS($D$4:$D$488,N9,$F$4:$F$488,"SFR") -> 14 | Q9: =+COUNTIFS($D$4:$D$488,N9,$F$4:$F$488,"WIP") -> 0 | R9: =+COUNTIFS($D$4:$D$488,N9,$F$4:$F$488,"Clear") -> 0 | S9: =+COUNTIFS($D$4:$D$488,N9,$F$4:$F$488,"ROW") -> 0 | T9: =+SUM(U9:Y9) -> 14 | U9: =+COUNTIFS($D$4:$D$488,N9,$G$4:$G$488,"E") -> 14 | V9: =+COUNTIFS($D$4:$D$488,N9,$G$4:$G$488,"WIP") -> 0 | W9: =+COUNTIFS($D$4:$D$488,N9,$G$4:$G$488,"Clear") -> 0 | X9: =+COUNTIFS($D$4:$D$488,N9,$G$4:$G$488,"ROW") -> 0 | Y9: =O9-X9-U9-W9-V9 -> 0 | Z9: =T9-U9 -> 0 | AA9: =+SUMIFS($E$4:$E$488,$D$4:$D$488,N9)/1000 -> 5.715468 | AB9: =+SUMIFS($E$4:$E$488,$D$4:$D$488,N9,$H$4:$H$488,$AB$3)/1000 -> 5.715468 | AC9: =+SUMIFS($E$4:$E$488,$D$4:$D$488,N9,$H$4:$H$488,$AC$3)/1000 -> 0 | AD9: =+SUMIFS($E$4:$E$488,$D$4:$D$488,N9,$H$4:$H$488,$AD$3)/1000 -> 0 | AE9: =+SUMIFS($E$4:$E$488,$D$4:$D$488,N9,$H$4:$H$488,$AE$3)/1000 -> 0 | AF9: =+SUMIFS($E$4:$E$488,$D$4:$D$488,N9,$H$4:$H$488,$AF$3)/1000 -> 0 | AG9: =AA9-SUM(AB9:AF9) -> 0
A10: =+SUBTOTAL(3,$B$4:B10) -> 0 | B10: ='Visual chart Edit'!B13 -> 1A/5 | C10: ='Visual chart Edit'!C13 -> DA+0 | D10: Mandai | E10: ='Visual chart Edit'!I13 -> 431.9 | F10: ='Visual chart Edit'!K13 -> DRY | G10: ='Visual chart Edit'!L13 -> E | H10: C | I10: C | J10: C | K10: C | N10: Bisoo Khurd | O10: =+SUM(P10:S10) -> 13 | P10: =+COUNTIFS($D$4:$D$488,N10,$F$4:$F$488,"sandy")+COUNTIFS($D$4:$D$488,N10,$F$4:$F$488,"Dry")+COUNTIFS($D$4:$D$488,N10,$F$4:$F$488,"DFR")+COUNTIFS($D$4:$D$488,N10,$F$4:$F$488,"WFR")+COUNTIFS($D$4:$D$488,N10,$F$4:$F$488,"SFR") -> 13 | Q10: =+COUNTIFS($D$4:$D$488,N10,$F$4:$F$488,"WIP") -> 0 | R10: =+COUNTIFS($D$4:$D$488,N10,$F$4:$F$488,"Clear") -> 0 | S10: =+COUNTIFS($D$4:$D$488,N10,$F$4:$F$488,"ROW") -> 0 | T10: =+SUM(U10:Y10) -> 13 | U10: =+COUNTIFS($D$4:$D$488,N10,$G$4:$G$488,"E") -> 13 | V10: =+COUNTIFS($D$4:$D$488,N10,$G$4:$G$488,"WIP") -> 0 | W10: =+COUNTIFS($D$4:$D$488,N10,$G$4:$G$488,"Clear") -> 0 | X10: =+COUNTIFS($D$4:$D$488,N10,$G$4:$G$488,"ROW") -> 0 | Y10: =O10-X10-U10-W10-V10 -> 0 | Z10: =T10-U10 -> 0 | AA10: =+SUMIFS($E$4:$E$488,$D$4:$D$488,N10)/1000 -> 5.1285 | AB10: =+SUMIFS($E$4:$E$488,$D$4:$D$488,N10,$H$4:$H$488,$AB$3)/1000 -> 2.0732 | AC10: =+SUMIFS($E$4:$E$488,$D$4:$D$488,N10,$H$4:$H$488,$AC$3)/1000 -> 0 | AD10: =+SUMIFS($E$4:$E$488,$D$4:$D$488,N10,$H$4:$H$488,$AD$3)/1000 -> 0 | AE10: =+SUMIFS($E$4:$E$488,$D$4:$D$488,N10,$H$4:$H$488,$AE$3)/1000 -> 0 | AF10: =+SUMIFS($E$4:$E$488,$D$4:$D$488,N10,$H$4:$H$488,$AF$3)/1000 -> 0 | AG10: =AA10-SUM(AB10:AF10) -> 3.0553
A11: =+SUBTOTAL(3,$B$4:B11) -> 0 | B11: ='Visual chart Edit'!B14 -> 1A/6 | C11: ='Visual chart Edit'!C14 -> DA+0 | D11: Mandai | E11: ='Visual chart Edit'!I14 -> 348.7 | F11: ='Visual chart Edit'!K14 -> Sandy | G11: ='Visual chart Edit'!L14 -> E | H11: C | I11: C | J11: C | K11: C | N11: Bhiyad | O11: =+SUM(P11:S11) -> 38 | P11: =+COUNTIFS($D$4:$D$488,N11,$F$4:$F$488,"sandy")+COUNTIFS($D$4:$D$488,N11,$F$4:$F$488,"Dry")+COUNTIFS($D$4:$D$488,N11,$F$4:$F$488,"DFR")+COUNTIFS($D$4:$D$488,N11,$F$4:$F$488,"WFR")+COUNTIFS($D$4:$D$488,N11,$F$4:$F$488,"SFR") -> 38 | Q11: =+COUNTIFS($D$4:$D$488,N11,$F$4:$F$488,"WIP") -> 0 | R11: =+COUNTIFS($D$4:$D$488,N11,$F$4:$F$488,"Clear") -> 0 | S11: =+COUNTIFS($D$4:$D$488,N11,$F$4:$F$488,"ROW") -> 0 | T11: =+SUM(U11:Y11) -> 38 | U11: =+COUNTIFS($D$4:$D$488,N11,$G$4:$G$488,"E") -> 38 | V11: =+COUNTIFS($D$4:$D$488,N11,$G$4:$G$488,"WIP") -> 0 | W11: =+COUNTIFS($D$4:$D$488,N11,$G$4:$G$488,"Clear") -> 0 | X11: =+COUNTIFS($D$4:$D$488,N11,$G$4:$G$488,"ROW") -> 0 | Y11: =O11-X11-U11-W11-V11 -> 0 | Z11: =T11-U11 -> 0 | AA11: =+SUMIFS($E$4:$E$488,$D$4:$D$488,N11)/1000 -> 15.03192 | AB11: =+SUMIFS($E$4:$E$488,$D$4:$D$488,N11,$H$4:$H$488,$AB$3)/1000 -> 0.3814 | AC11: =+SUMIFS($E$4:$E$488,$D$4:$D$488,N11,$H$4:$H$488,$AC$3)/1000 -> 2.2899 | AD11: =+SUMIFS($E$4:$E$488,$D$4:$D$488,N11,$H$4:$H$488,$AD$3)/1000 -> 0 | AE11: =+SUMIFS($E$4:$E$488,$D$4:$D$488,N11,$H$4:$H$488,$AE$3)/1000 -> 0 | AF11: =+SUMIFS($E$4:$E$488,$D$4:$D$488,N11,$H$4:$H$488,$AF$3)/1000 -> 0 | AG11: =AA11-SUM(AB11:AF11) -> 12.36062
A12: =+SUBTOTAL(3,$B$4:B12) -> 0 | B12: ='Visual chart Edit'!B15 -> 1A/7 | C12: ='Visual chart Edit'!C15 -> DA+3 | D12: Mandai | E12: ='Visual chart Edit'!I15 -> 395.7 | F12: ='Visual chart Edit'!K15 -> Sandy | G12: ='Visual chart Edit'!L15 -> E | H12: C | I12: C | J12: C | K12: C | N12: Kashmir | O12: =+SUM(P12:S12) -> 29 | P12: =+COUNTIFS($D$4:$D$488,N12,$F$4:$F$488,"sandy")+COUNTIFS($D$4:$D$488,N12,$F$4:$F$488,"Dry")+COUNTIFS($D$4:$D$488,N12,$F$4:$F$488,"DFR")+COUNTIFS($D$4:$D$488,N12,$F$4:$F$488,"WFR")+COUNTIFS($D$4:$D$488,N12,$F$4:$F$488,"SFR") -> 29 | Q12: =+COUNTIFS($D$4:$D$488,N12,$F$4:$F$488,"WIP") -> 0 | R12: =+COUNTIFS($D$4:$D$488,N12,$F$4:$F$488,"Clear") -> 0 | S12: =+COUNTIFS($D$4:$D$488,N12,$F$4:$F$488,"ROW") -> 0 | T12: =+SUM(U12:Y12) -> 29 | U12: =+COUNTIFS($D$4:$D$488,N12,$G$4:$G$488,"E") -> 21 | V12: =+COUNTIFS($D$4:$D$488,N12,$G$4:$G$488,"WIP") -> 2 | W12: =+COUNTIFS($D$4:$D$488,N12,$G$4:$G$488,"Clear") -> 0 | X12: =+COUNTIFS($D$4:$D$488,N12,$G$4:$G$488,"ROW") -> 6 | Y12: =O12-X12-U12-W12-V12 -> 0 | Z12: =T12-U12 -> 8 | AA12: =+SUMIFS($E$4:$E$488,$D$4:$D$488,N12)/1000 -> 11.512 | AB12: =+SUMIFS($E$4:$E$488,$D$4:$D$488,N12,$H$4:$H$488,$AB$3)/1000 -> 0 | AC12: =+SUMIFS($E$4:$E$488,$D$4:$D$488,N12,$H$4:$H$488,$AC$3)/1000 -> 0 | AD12: =+SUMIFS($E$4:$E$488,$D$4:$D$488,N12,$H$4:$H$488,$AD$3)/1000 -> 0 | AE12: =+SUMIFS($E$4:$E$488,$D$4:$D$488,N12,$H$4:$H$488,$AE$3)/1000 -> 0 | AF12: =+SUMIFS($E$4:$E$488,$D$4:$D$488,N12,$H$4:$H$488,$AF$3)/1000 -> 0 | AG12: =AA12-SUM(AB12:AF12) -> 11.512
A13: =+SUBTOTAL(3,$B$4:B13) -> 0 | B13: ='Visual chart Edit'!B16 -> 1A/8 | C13: ='Visual chart Edit'!C16 -> DA+0 | D13: Mandai | E13: ='Visual chart Edit'!I16 -> 415 | F13: ='Visual chart Edit'!K16 -> Sandy | G13: ='Visual chart Edit'!L16 -> E | H13: C | I13: C | J13: C | K13: C | N13: Rateu | O13: =+SUM(P13:S13) -> 35 | P13: =+COUNTIFS($D$4:$D$488,N13,$F$4:$F$488,"sandy")+COUNTIFS($D$4:$D$488,N13,$F$4:$F$488,"Dry")+COUNTIFS($D$4:$D$488,N13,$F$4:$F$488,"DFR")+COUNTIFS($D$4:$D$488,N13,$F$4:$F$488,"WFR")+COUNTIFS($D$4:$D$488,N13,$F$4:$F$488,"SFR") -> 35 | Q13: =+COUNTIFS($D$4:$D$488,N13,$F$4:$F$488,"WIP") -> 0 | R13: =+COUNTIFS($D$4:$D$488,N13,$F$4:$F$488,"Clear") -> 0 | S13: =+COUNTIFS($D$4:$D$488,N13,$F$4:$F$488,"ROW") -> 0 | T13: =+SUM(U13:Y13) -> 35 | U13: =+COUNTIFS($D$4:$D$488,N13,$G$4:$G$488,"E") -> 33 | V13: =+COUNTIFS($D$4:$D$488,N13,$G$4:$G$488,"WIP") -> 0 | W13: =+COUNTIFS($D$4:$D$488,N13,$G$4:$G$488,"Clear") -> 0 | X13: =+COUNTIFS($D$4:$D$488,N13,$G$4:$G$488,"ROW") -> 2 | Y13: =O13-X13-U13-W13-V13 -> 0 | Z13: =T13-U13 -> 2 | AA13: =+SUMIFS($E$4:$E$488,$D$4:$D$488,N13)/1000 -> 13.7801 | AB13: =+SUMIFS($E$4:$E$488,$D$4:$D$488,N13,$H$4:$H$488,$AB$3)/1000 -> 0 | AC13: =+SUMIFS($E$4:$E$488,$D$4:$D$488,N13,$H$4:$H$488,$AC$3)/1000 -> 0 | AD13: =+SUMIFS($E$4:$E$488,$D$4:$D$488,N13,$H$4:$H$488,$AD$3)/1000 -> 0 | AE13: =+SUMIFS($E$4:$E$488,$D$4:$D$488,N13,$H$4:$H$488,$AE$3)/1000 -> 0 | AF13: =+SUMIFS($E$4:$E$488,$D$4:$D$488,N13,$H$4:$H$488,$AF$3)/1000 -> 0 | AG13: =AA13-SUM(AB13:AF13) -> 13.7801
A14: =+SUBTOTAL(3,$B$4:B14) -> 0 | B14: ='Visual chart Edit'!B17 -> 2/0 | C14: ='Visual chart Edit'!C17 -> DC1+0 | D14: Mandai | E14: ='Visual chart Edit'!I17 -> 394.3 | F14: ='Visual chart Edit'!K17 -> DRY | G14: ='Visual chart Edit'!L17 -> E | H14: C | I14: C | K14: C | L14: C | N14: Sawau Moolraj | O14: =+SUM(P14:S14) -> 23 | P14: =+COUNTIFS($D$4:$D$488,N14,$F$4:$F$488,"sandy")+COUNTIFS($D$4:$D$488,N14,$F$4:$F$488,"Dry")+COUNTIFS($D$4:$D$488,N14,$F$4:$F$488,"DFR")+COUNTIFS($D$4:$D$488,N14,$F$4:$F$488,"WFR")+COUNTIFS($D$4:$D$488,N14,$F$4:$F$488,"SFR") -> 23 | Q14: =+COUNTIFS($D$4:$D$488,N14,$F$4:$F$488,"WIP") -> 0 | R14: =+COUNTIFS($D$4:$D$488,N14,$F$4:$F$488,"Clear") -> 0 | S14: =+COUNTIFS($D$4:$D$488,N14,$F$4:$F$488,"ROW") -> 0 | T14: =+SUM(U14:Y14) -> 23 | U14: =+COUNTIFS($D$4:$D$488,N14,$G$4:$G$488,"E") -> 23 | V14: =+COUNTIFS($D$4:$D$488,N14,$G$4:$G$488,"WIP") -> 0 | W14: =+COUNTIFS($D$4:$D$488,N14,$G$4:$G$488,"Clear") -> 0 | X14: =+COUNTIFS($D$4:$D$488,N14,$G$4:$G$488,"ROW") -> 0 | Y14: =O14-X14-U14-W14-V14 -> 0 | Z14: =T14-U14 -> 0 | AA14: =+SUMIFS($E$4:$E$488,$D$4:$D$488,N14)/1000 -> 9.072 | AB14: =+SUMIFS($E$4:$E$488,$D$4:$D$488,N14,$H$4:$H$488,$AB$3)/1000 -> 0 | AC14: =+SUMIFS($E$4:$E$488,$D$4:$D$488,N14,$H$4:$H$488,$AC$3)/1000 -> 0 | AD14: =+SUMIFS($E$4:$E$488,$D$4:$D$488,N14,$H$4:$H$488,$AD$3)/1000 -> 0 | AE14: =+SUMIFS($E$4:$E$488,$D$4:$D$488,N14,$H$4:$H$488,$AE$3)/1000 -> 0 | AF14: =+SUMIFS($E$4:$E$488,$D$4:$D$488,N14,$H$4:$H$488,$AF$3)/1000 -> 0 | AG14: =AA14-SUM(AB14:AF14) -> 9.072
A15: =+SUBTOTAL(3,$B$4:B15) -> 0 | B15: ='Visual chart Edit'!B18 -> 2/1 | C15: ='Visual chart Edit'!C18 -> DA+3 | D15: Mandai | E15: ='Visual chart Edit'!I18 -> 405.3 | F15: ='Visual chart Edit'!K18 -> Sandy | G15: ='Visual chart Edit'!L18 -> E | H15: C | I15: C | J15: C | K15: C | N15: Neemba Ki Dhani | O15: =+SUM(P15:S15) -> 23 | P15: =+COUNTIFS($D$4:$D$488,N15,$F$4:$F$488,"sandy")+COUNTIFS($D$4:$D$488,N15,$F$4:$F$488,"Dry")+COUNTIFS($D$4:$D$488,N15,$F$4:$F$488,"DFR")+COUNTIFS($D$4:$D$488,N15,$F$4:$F$488,"WFR")+COUNTIFS($D$4:$D$488,N15,$F$4:$F$488,"SFR") -> 23 | Q15: =+COUNTIFS($D$4:$D$488,N15,$F$4:$F$488,"WIP") -> 0 | R15: =+COUNTIFS($D$4:$D$488,N15,$F$4:$F$488,"Clear") -> 0 | S15: =+COUNTIFS($D$4:$D$488,N15,$F$4:$F$488,"ROW") -> 0 | T15: =+SUM(U15:Y15) -> 23 | U15: =+COUNTIFS($D$4:$D$488,N15,$G$4:$G$488,"E") -> 23 | V15: =+COUNTIFS($D$4:$D$488,N15,$G$4:$G$488,"WIP") -> 0 | W15: =+COUNTIFS($D$4:$D$488,N15,$G$4:$G$488,"Clear") -> 0 | X15: =+COUNTIFS($D$4:$D$488,N15,$G$4:$G$488,"ROW") -> 0 | Y15: =O15-X15-U15-W15-V15 -> 0 | Z15: =T15-U15 -> 0 | AA15: =+SUMIFS($E$4:$E$488,$D$4:$D$488,N15)/1000 -> 9.1431 | AB15: =+SUMIFS($E$4:$E$488,$D$4:$D$488,N15,$H$4:$H$488,$AB$3)/1000 -> 0 | AC15: =+SUMIFS($E$4:$E$488,$D$4:$D$488,N15,$H$4:$H$488,$AC$3)/1000 -> 0 | AD15: =+SUMIFS($E$4:$E$488,$D$4:$D$488,N15,$H$4:$H$488,$AD$3)/1000 -> 0 | AE15: =+SUMIFS($E$4:$E$488,$D$4:$D$488,N15,$H$4:$H$488,$AE$3)/1000 -> 0 | AF15: =+SUMIFS($E$4:$E$488,$D$4:$D$488,N15,$H$4:$H$488,$AF$3)/1000 -> 0 | AG15: =AA15-SUM(AB15:AF15) -> 9.1431
A16: =+SUBTOTAL(3,$B$4:B16) -> 0 | B16: ='Visual chart Edit'!B19 -> 2/2 | C16: ='Visual chart Edit'!C19 -> DA+3 | D16: Mandai | E16: ='Visual chart Edit'!I19 -> 338.5 | F16: ='Visual chart Edit'!K19 -> Sandy | G16: ='Visual chart Edit'!L19 -> E | H16: C | I16: C | J16: C | K16: C | M16: 33 KV SHUTDOWN, GANG IDLING SINCE 11.09.2025. | N16: Danpura | O16: =+SUM(P16:S16) -> 13 | P16: =+COUNTIFS($D$4:$D$488,N16,$F$4:$F$488,"sandy")+COUNTIFS($D$4:$D$488,N16,$F$4:$F$488,"Dry")+COUNTIFS($D$4:$D$488,N16,$F$4:$F$488,"DFR")+COUNTIFS($D$4:$D$488,N16,$F$4:$F$488,"WFR")+COUNTIFS($D$4:$D$488,N16,$F$4:$F$488,"SFR") -> 13 | Q16: =+COUNTIFS($D$4:$D$488,N16,$F$4:$F$488,"WIP") -> 0 | R16: =+COUNTIFS($D$4:$D$488,N16,$F$4:$F$488,"Clear") -> 0 | S16: =+COUNTIFS($D$4:$D$488,N16,$F$4:$F$488,"ROW") -> 0 | T16: =+SUM(U16:Y16) -> 13 | U16: =+COUNTIFS($D$4:$D$488,N16,$G$4:$G$488,"E") -> 13 | V16: =+COUNTIFS($D$4:$D$488,N16,$G$4:$G$488,"WIP") -> 0 | W16: =+COUNTIFS($D$4:$D$488,N16,$G$4:$G$488,"Clear") -> 0 | X16: =+COUNTIFS($D$4:$D$488,N16,$G$4:$G$488,"ROW") -> 0 | Y16: =O16-X16-U16-W16-V16 -> 0 | Z16: =T16-U16 -> 0 | AA16: =+SUMIFS($E$4:$E$488,$D$4:$D$488,N16)/1000 -> 5.298548 | AB16: =+SUMIFS($E$4:$E$488,$D$4:$D$488,N16,$H$4:$H$488,$AB$3)/1000 -> 0 | AC16: =+SUMIFS($E$4:$E$488,$D$4:$D$488,N16,$H$4:$H$488,$AC$3)/1000 -> 0 | AD16: =+SUMIFS($E$4:$E$488,$D$4:$D$488,N16,$H$4:$H$488,$AD$3)/1000 -> 0 | AE16: =+SUMIFS($E$4:$E$488,$D$4:$D$488,N16,$H$4:$H$488,$AE$3)/1000 -> 0 | AF16: =+SUMIFS($E$4:$E$488,$D$4:$D$488,N16,$H$4:$H$488,$AF$3)/1000 -> 0 | AG16: =AA16-SUM(AB16:AF16) -> 5.298548
A17: =+SUBTOTAL(3,$B$4:B17) -> 0 | B17: ='Visual chart Edit'!B20 -> 2/3 | C17: ='Visual chart Edit'!C20 -> DA+3 | D17: Mandai | E17: ='Visual chart Edit'!I20 -> 406 | F17: ='Visual chart Edit'!K20 -> Sandy | G17: ='Visual chart Edit'!L20 -> E | H17: C | I17: C | J17: C | K17: C | N17: Rampura Kharda | O17: =+SUM(P17:S17) -> 1 | P17: =+COUNTIFS($D$4:$D$488,N17,$F$4:$F$488,"sandy")+COUNTIFS($D$4:$D$488,N17,$F$4:$F$488,"Dry")+COUNTIFS($D$4:$D$488,N17,$F$4:$F$488,"DFR")+COUNTIFS($D$4:$D$488,N17,$F$4:$F$488,"WFR")+COUNTIFS($D$4:$D$488,N17,$F$4:$F$488,"SFR") -> 1 | Q17: =+COUNTIFS($D$4:$D$488,N17,$F$4:$F$488,"WIP") -> 0 | R17: =+COUNTIFS($D$4:$D$488,N17,$F$4:$F$488,"Clear") -> 0 | S17: =+COUNTIFS($D$4:$D$488,N17,$F$4:$F$488,"ROW") -> 0 | T17: =+SUM(U17:Y17) -> 1 | U17: =+COUNTIFS($D$4:$D$488,N17,$G$4:$G$488,"E") -> 1 | V17: =+COUNTIFS($D$4:$D$488,N17,$G$4:$G$488,"WIP") -> 0 | W17: =+COUNTIFS($D$4:$D$488,N17,$G$4:$G$488,"Clear") -> 0 | X17: =+COUNTIFS($D$4:$D$488,N17,$G$4:$G$488,"ROW") -> 0 | Y17: =O17-X17-U17-W17-V17 -> 0 | Z17: =T17-U17 -> 0 | AA17: =+SUMIFS($E$4:$E$488,$D$4:$D$488,N17)/1000 -> 0.4017 | AB17: =+SUMIFS($E$4:$E$488,$D$4:$D$488,N17,$H$4:$H$488,$AB$3)/1000 -> 0 | AC17: =+SUMIFS($E$4:$E$488,$D$4:$D$488,N17,$H$4:$H$488,$AC$3)/1000 -> 0 | AD17: =+SUMIFS($E$4:$E$488,$D$4:$D$488,N17,$H$4:$H$488,$AD$3)/1000 -> 0 | AE17: =+SUMIFS($E$4:$E$488,$D$4:$D$488,N17,$H$4:$H$488,$AE$3)/1000 -> 0 | AF17: =+SUMIFS($E$4:$E$488,$D$4:$D$488,N17,$H$4:$H$488,$AF$3)/1000 -> 0 | AG17: =AA17-SUM(AB17:AF17) -> 0.4017
A18: =+SUBTOTAL(3,$B$4:B18) -> 0 | B18: ='Visual chart Edit'!B21 -> 2/4 | C18: ='Visual chart Edit'!C21 -> DA+3 | D18: Mandai | E18: ='Visual chart Edit'!I21 -> 429 | F18: ='Visual chart Edit'!K21 -> Sandy | G18: ='Visual chart Edit'!L21 -> E | H18: C | I18: C | J18: C | K18: C | N18: Manpura Kharda | O18: =+SUM(P18:S18) -> 2 | P18: =+COUNTIFS($D$4:$D$488,N18,$F$4:$F$488,"sandy")+COUNTIFS($D$4:$D$488,N18,$F$4:$F$488,"Dry")+COUNTIFS($D$4:$D$488,N18,$F$4:$F$488,"DFR")+COUNTIFS($D$4:$D$488,N18,$F$4:$F$488,"WFR")+COUNTIFS($D$4:$D$488,N18,$F$4:$F$488,"SFR") -> 2 | Q18: =+COUNTIFS($D$4:$D$488,N18,$F$4:$F$488,"WIP") -> 0 | R18: =+COUNTIFS($D$4:$D$488,N18,$F$4:$F$488,"Clear") -> 0 | S18: =+COUNTIFS($D$4:$D$488,N18,$F$4:$F$488,"ROW") -> 0 | T18: =+SUM(U18:Y18) -> 2 | U18: =+COUNTIFS($D$4:$D$488,N18,$G$4:$G$488,"E") -> 2 | V18: =+COUNTIFS($D$4:$D$488,N18,$G$4:$G$488,"WIP") -> 0 | W18: =+COUNTIFS($D$4:$D$488,N18,$G$4:$G$488,"Clear") -> 0 | X18: =+COUNTIFS($D$4:$D$488,N18,$G$4:$G$488,"ROW") -> 0 | Y18: =O18-X18-U18-W18-V18 -> 0 | Z18: =T18-U18 -> 0 | AA18: =+SUMIFS($E$4:$E$488,$D$4:$D$488,N18)/1000 -> 0.7771 | AB18: =+SUMIFS($E$4:$E$488,$D$4:$D$488,N18,$H$4:$H$488,$AB$3)/1000 -> 0 | AC18: =+SUMIFS($E$4:$E$488,$D$4:$D$488,N18,$H$4:$H$488,$AC$3)/1000 -> 0 | AD18: =+SUMIFS($E$4:$E$488,$D$4:$D$488,N18,$H$4:$H$488,$AD$3)/1000 -> 0 | AE18: =+SUMIFS($E$4:$E$488,$D$4:$D$488,N18,$H$4:$H$488,$AE$3)/1000 -> 0 | AF18: =+SUMIFS($E$4:$E$488,$D$4:$D$488,N18,$H$4:$H$488,$AF$3)/1000 -> 0 | AG18: =AA18-SUM(AB18:AF18) -> 0.7771
A19: =+SUBTOTAL(3,$B$4:B19) -> 0 | B19: ='Visual chart Edit'!B22 -> 2/5 | C19: ='Visual chart Edit'!C22 -> DA+3 | D19: Mandai | E19: ='Visual chart Edit'!I22 -> 411.6 | F19: ='Visual chart Edit'!K22 -> Sandy | G19: ='Visual chart Edit'!L22 -> E | H19: C | I19: C | J19: C | K19: C | N19: Kharda Charnan | O19: =+SUM(P19:S19) -> 9 | P19: =+COUNTIFS($D$4:$D$488,N19,$F$4:$F$488,"sandy")+COUNTIFS($D$4:$D$488,N19,$F$4:$F$488,"Dry")+COUNTIFS($D$4:$D$488,N19,$F$4:$F$488,"DFR")+COUNTIFS($D$4:$D$488,N19,$F$4:$F$488,"WFR")+COUNTIFS($D$4:$D$488,N19,$F$4:$F$488,"SFR") -> 9 | Q19: =+COUNTIFS($D$4:$D$488,N19,$F$4:$F$488,"WIP") -> 0 | R19: =+COUNTIFS($D$4:$D$488,N19,$F$4:$F$488,"Clear") -> 0 | S19: =+COUNTIFS($D$4:$D$488,N19,$F$4:$F$488,"ROW") -> 0 | T19: =+SUM(U19:Y19) -> 9 | U19: =+COUNTIFS($D$4:$D$488,N19,$G$4:$G$488,"E") -> 9 | V19: =+COUNTIFS($D$4:$D$488,N19,$G$4:$G$488,"WIP") -> 0 | W19: =+COUNTIFS($D$4:$D$488,N19,$G$4:$G$488,"Clear") -> 0 | X19: =+COUNTIFS($D$4:$D$488,N19,$G$4:$G$488,"ROW") -> 0 | Y19: =O19-X19-U19-W19-V19 -> 0 | Z19: =T19-U19 -> 0 | AA19: =+SUMIFS($E$4:$E$488,$D$4:$D$488,N19)/1000 -> 3.4972 | AB19: =+SUMIFS($E$4:$E$488,$D$4:$D$488,N19,$H$4:$H$488,$AB$3)/1000 -> 0 | AC19: =+SUMIFS($E$4:$E$488,$D$4:$D$488,N19,$H$4:$H$488,$AC$3)/1000 -> 0.4039 | AD19: =+SUMIFS($E$4:$E$488,$D$4:$D$488,N19,$H$4:$H$488,$AD$3)/1000 -> 0 | AE19: =+SUMIFS($E$4:$E$488,$D$4:$D$488,N19,$H$4:$H$488,$AE$3)/1000 -> 0 | AF19: =+SUMIFS($E$4:$E$488,$D$4:$D$488,N19,$H$4:$H$488,$AF$3)/1000 -> 0 | AG19: =AA19-SUM(AB19:AF19) -> 3.0933
A20: =+SUBTOTAL(3,$B$4:B20) -> 0 | B20: ='Visual chart Edit'!B23 -> 2/6 | C20: ='Visual chart Edit'!C23 -> DA+3 | D20: Harwa | E20: ='Visual chart Edit'!I23 -> 425.7 | F20: ='Visual chart Edit'!K23 -> Sandy | G20: ='Visual chart Edit'!L23 -> E | H20: C | I20: C | J20: C | K20: C | N20: Beniwalon Ki Dhani | O20: =+SUM(P20:S20) -> 6 | P20: =+COUNTIFS($D$4:$D$488,N20,$F$4:$F$488,"sandy")+COUNTIFS($D$4:$D$488,N20,$F$4:$F$488,"Dry")+COUNTIFS($D$4:$D$488,N20,$F$4:$F$488,"DFR")+COUNTIFS($D$4:$D$488,N20,$F$4:$F$488,"WFR")+COUNTIFS($D$4:$D$488,N20,$F$4:$F$488,"SFR") -> 6 | Q20: =+COUNTIFS($D$4:$D$488,N20,$F$4:$F$488,"WIP") -> 0 | R20: =+COUNTIFS($D$4:$D$488,N20,$F$4:$F$488,"Clear") -> 0 | S20: =+COUNTIFS($D$4:$D$488,N20,$F$4:$F$488,"ROW") -> 0 | T20: =+SUM(U20:Y20) -> 6 | U20: =+COUNTIFS($D$4:$D$488,N20,$G$4:$G$488,"E") -> 6 | V20: =+COUNTIFS($D$4:$D$488,N20,$G$4:$G$488,"WIP") -> 0 | W20: =+COUNTIFS($D$4:$D$488,N20,$G$4:$G$488,"Clear") -> 0 | X20: =+COUNTIFS($D$4:$D$488,N20,$G$4:$G$488,"ROW") -> 0 | Y20: =O20-X20-U20-W20-V20 -> 0 | Z20: =T20-U20 -> 0 | AA20: =+SUMIFS($E$4:$E$488,$D$4:$D$488,N20)/1000 -> 2.4504 | AB20: =+SUMIFS($E$4:$E$488,$D$4:$D$488,N20,$H$4:$H$488,$AB$3)/1000 -> 0 | AC20: =+SUMIFS($E$4:$E$488,$D$4:$D$488,N20,$H$4:$H$488,$AC$3)/1000 -> 2.4504 | AD20: =+SUMIFS($E$4:$E$488,$D$4:$D$488,N20,$H$4:$H$488,$AD$3)/1000 -> 0 | AE20: =+SUMIFS($E$4:$E$488,$D$4:$D$488,N20,$H$4:$H$488,$AE$3)/1000 -> 0 | AF20: =+SUMIFS($E$4:$E$488,$D$4:$D$488,N20,$H$4:$H$488,$AF$3)/1000 -> 0 | AG20: =AA20-SUM(AB20:AF20) -> 0
A21: =+SUBTOTAL(3,$B$4:B21) -> 0 | B21: ='Visual chart Edit'!B24 -> 2/7 | C21: ='Visual chart Edit'!C24 -> DA+3 | D21: Harwa | E21: ='Visual chart Edit'!I24 -> 408.2 | F21: ='Visual chart Edit'!K24 -> Sandy | G21: ='Visual chart Edit'!L24 -> E | H21: C | I21: C | J21: C | K21: C | N21: Pareu | O21: =+SUM(P21:S21) -> 4 | P21: =+COUNTIFS($D$4:$D$488,N21,$F$4:$F$488,"sandy")+COUNTIFS($D$4:$D$488,N21,$F$4:$F$488,"Dry")+COUNTIFS($D$4:$D$488,N21,$F$4:$F$488,"DFR")+COUNTIFS($D$4:$D$488,N21,$F$4:$F$488,"WFR")+COUNTIFS($D$4:$D$488,N21,$F$4:$F$488,"SFR") -> 4 | Q21: =+COUNTIFS($D$4:$D$488,N21,$F$4:$F$488,"WIP") -> 0 | R21: =+COUNTIFS($D$4:$D$488,N21,$F$4:$F$488,"Clear") -> 0 | S21: =+COUNTIFS($D$4:$D$488,N21,$F$4:$F$488,"ROW") -> 0 | T21: =+SUM(U21:Y21) -> 4 | U21: =+COUNTIFS($D$4:$D$488,N21,$G$4:$G$488,"E") -> 4 | V21: =+COUNTIFS($D$4:$D$488,N21,$G$4:$G$488,"WIP") -> 0 | W21: =+COUNTIFS($D$4:$D$488,N21,$G$4:$G$488,"Clear") -> 0 | X21: =+COUNTIFS($D$4:$D$488,N21,$G$4:$G$488,"ROW") -> 0 | Y21: =O21-X21-U21-W21-V21 -> 0 | Z21: =T21-U21 -> 0 | AA21: =+SUMIFS($E$4:$E$488,$D$4:$D$488,N21)/1000 -> 1.5736 | AB21: =+SUMIFS($E$4:$E$488,$D$4:$D$488,N21,$H$4:$H$488,$AB$3)/1000 -> 0 | AC21: =+SUMIFS($E$4:$E$488,$D$4:$D$488,N21,$H$4:$H$488,$AC$3)/1000 -> 1.5736 | AD21: =+SUMIFS($E$4:$E$488,$D$4:$D$488,N21,$H$4:$H$488,$AD$3)/1000 -> 0 | AE21: =+SUMIFS($E$4:$E$488,$D$4:$D$488,N21,$H$4:$H$488,$AE$3)/1000 -> 0 | AF21: =+SUMIFS($E$4:$E$488,$D$4:$D$488,N21,$H$4:$H$488,$AF$3)/1000 -> 0 | AG21: =AA21-SUM(AB21:AF21) -> 0
A22: =+SUBTOTAL(3,$B$4:B22) -> 0 | B22: ='Visual chart Edit'!B25 -> 2/8 | C22: ='Visual chart Edit'!C25 -> DA+0 | D22: Harwa | E22: ='Visual chart Edit'!I25 -> 354.6 | F22: ='Visual chart Edit'!K25 -> Sandy | G22: ='Visual chart Edit'!L25 -> E | H22: C | I22: C | J22: C | K22: C | N22: Mahadeo Ka Mandir | O22: =+SUM(P22:S22) -> 7 | P22: =+COUNTIFS($D$4:$D$488,N22,$F$4:$F$488,"sandy")+COUNTIFS($D$4:$D$488,N22,$F$4:$F$488,"Dry")+COUNTIFS($D$4:$D$488,N22,$F$4:$F$488,"DFR")+COUNTIFS($D$4:$D$488,N22,$F$4:$F$488,"WFR")+COUNTIFS($D$4:$D$488,N22,$F$4:$F$488,"SFR") -> 7 | Q22: =+COUNTIFS($D$4:$D$488,N22,$F$4:$F$488,"WIP") -> 0 | R22: =+COUNTIFS($D$4:$D$488,N22,$F$4:$F$488,"Clear") -> 0 | S22: =+COUNTIFS($D$4:$D$488,N22,$F$4:$F$488,"ROW") -> 0 | T22: =+SUM(U22:Y22) -> 7 | U22: =+COUNTIFS($D$4:$D$488,N22,$G$4:$G$488,"E") -> 7 | V22: =+COUNTIFS($D$4:$D$488,N22,$G$4:$G$488,"WIP") -> 0 | W22: =+COUNTIFS($D$4:$D$488,N22,$G$4:$G$488,"Clear") -> 0 | X22: =+COUNTIFS($D$4:$D$488,N22,$G$4:$G$488,"ROW") -> 0 | Y22: =O22-X22-U22-W22-V22 -> 0 | Z22: =T22-U22 -> 0 | AA22: =+SUMIFS($E$4:$E$488,$D$4:$D$488,N22)/1000 -> 2.656 | AB22: =+SUMIFS($E$4:$E$488,$D$4:$D$488,N22,$H$4:$H$488,$AB$3)/1000 -> 2.2112 | AC22: =+SUMIFS($E$4:$E$488,$D$4:$D$488,N22,$H$4:$H$488,$AC$3)/1000 -> 0.4448 | AD22: =+SUMIFS($E$4:$E$488,$D$4:$D$488,N22,$H$4:$H$488,$AD$3)/1000 -> 0 | AE22: =+SUMIFS($E$4:$E$488,$D$4:$D$488,N22,$H$4:$H$488,$AE$3)/1000 -> 0 | AF22: =+SUMIFS($E$4:$E$488,$D$4:$D$488,N22,$H$4:$H$488,$AF$3)/1000 -> 0 | AG22: =AA22-SUM(AB22:AF22) -> 0
A23: =+SUBTOTAL(3,$B$4:B23) -> 0 | B23: ='Visual chart Edit'!B26 -> 2/9 | C23: ='Visual chart Edit'!C26 -> DA+0 | D23: Harwa | E23: ='Visual chart Edit'!I26 -> 308.7 | F23: ='Visual chart Edit'!K26 -> DRY | G23: ='Visual chart Edit'!L26 -> E | H23: C | I23: C | J23: C | K23: C | N23: Chimoniyon Ki Dhani | O23: =+SUM(P23:S23) -> 8 | P23: =+COUNTIFS($D$4:$D$488,N23,$F$4:$F$488,"sandy")+COUNTIFS($D$4:$D$488,N23,$F$4:$F$488,"Dry")+COUNTIFS($D$4:$D$488,N23,$F$4:$F$488,"DFR")+COUNTIFS($D$4:$D$488,N23,$F$4:$F$488,"WFR")+COUNTIFS($D$4:$D$488,N23,$F$4:$F$488,"SFR") -> 8 | Q23: =+COUNTIFS($D$4:$D$488,N23,$F$4:$F$488,"WIP") -> 0 | R23: =+COUNTIFS($D$4:$D$488,N23,$F$4:$F$488,"Clear") -> 0 | S23: =+COUNTIFS($D$4:$D$488,N23,$F$4:$F$488,"ROW") -> 0 | T23: =+SUM(U23:Y23) -> 8 | U23: =+COUNTIFS($D$4:$D$488,N23,$G$4:$G$488,"E") -> 8 | V23: =+COUNTIFS($D$4:$D$488,N23,$G$4:$G$488,"WIP") -> 0 | W23: =+COUNTIFS($D$4:$D$488,N23,$G$4:$G$488,"Clear") -> 0 | X23: =+COUNTIFS($D$4:$D$488,N23,$G$4:$G$488,"ROW") -> 0 | Y23: =O23-X23-U23-W23-V23 -> 0 | Z23: =T23-U23 -> 0 | AA23: =+SUMIFS($E$4:$E$488,$D$4:$D$488,N23)/1000 -> 3.17012 | AB23: =+SUMIFS($E$4:$E$488,$D$4:$D$488,N23,$H$4:$H$488,$AB$3)/1000 -> 3.17012 | AC23: =+SUMIFS($E$4:$E$488,$D$4:$D$488,N23,$H$4:$H$488,$AC$3)/1000 -> 0 | AD23: =+SUMIFS($E$4:$E$488,$D$4:$D$488,N23,$H$4:$H$488,$AD$3)/1000 -> 0 | AE23: =+SUMIFS($E$4:$E$488,$D$4:$D$488,N23,$H$4:$H$488,$AE$3)/1000 -> 0 | AF23: =+SUMIFS($E$4:$E$488,$D$4:$D$488,N23,$H$4:$H$488,$AF$3)/1000 -> 0 | AG23: =AA23-SUM(AB23:AF23) -> 0
A24: =+SUBTOTAL(3,$B$4:B24) -> 0 | B24: ='Visual chart Edit'!B27 -> 3/0 | C24: ='Visual chart Edit'!C27 -> DD60+6 | D24: Harwa | E24: ='Visual chart Edit'!I27 -> 336 | F24: ='Visual chart Edit'!K27 -> DRY | G24: ='Visual chart Edit'!L27 -> E | H24: C | I24: C | K24: C | N24: Godaron Ki Dhani | O24: =+SUM(P24:S24) -> 9 | P24: =+COUNTIFS($D$4:$D$488,N24,$F$4:$F$488,"sandy")+COUNTIFS($D$4:$D$488,N24,$F$4:$F$488,"Dry")+COUNTIFS($D$4:$D$488,N24,$F$4:$F$488,"DFR")+COUNTIFS($D$4:$D$488,N24,$F$4:$F$488,"WFR")+COUNTIFS($D$4:$D$488,N24,$F$4:$F$488,"SFR") -> 9 | Q24: =+COUNTIFS($D$4:$D$488,N24,$F$4:$F$488,"WIP") -> 0 | R24: =+COUNTIFS($D$4:$D$488,N24,$F$4:$F$488,"Clear") -> 0 | S24: =+COUNTIFS($D$4:$D$488,N24,$F$4:$F$488,"ROW") -> 0 | T24: =+SUM(U24:Y24) -> 9 | U24: =+COUNTIFS($D$4:$D$488,N24,$G$4:$G$488,"E") -> 9 | V24: =+COUNTIFS($D$4:$D$488,N24,$G$4:$G$488,"WIP") -> 0 | W24: =+COUNTIFS($D$4:$D$488,N24,$G$4:$G$488,"Clear") -> 0 | X24: =+COUNTIFS($D$4:$D$488,N24,$G$4:$G$488,"ROW") -> 0 | Y24: =O24-X24-U24-W24-V24 -> 0 | Z24: =T24-U24 -> 0 | AA24: =+SUMIFS($E$4:$E$488,$D$4:$D$488,N24)/1000 -> 3.45855 | AB24: =+SUMIFS($E$4:$E$488,$D$4:$D$488,N24,$H$4:$H$488,$AB$3)/1000 -> 3.45855 | AC24: =+SUMIFS($E$4:$E$488,$D$4:$D$488,N24,$H$4:$H$488,$AC$3)/1000 -> 0 | AD24: =+SUMIFS($E$4:$E$488,$D$4:$D$488,N24,$H$4:$H$488,$AD$3)/1000 -> 0 | AE24: =+SUMIFS($E$4:$E$488,$D$4:$D$488,N24,$H$4:$H$488,$AE$3)/1000 -> 0 | AF24: =+SUMIFS($E$4:$E$488,$D$4:$D$488,N24,$H$4:$H$488,$AF$3)/1000 -> 0 | AG24: =AA24-SUM(AB24:AF24) -> 0
A25: =+SUBTOTAL(3,$B$4:B25) -> 0 | B25: ='Visual chart Edit'!B28 -> 4/0 | C25: ='Visual chart Edit'!C28 -> DD60+6 | D25: Harwa | E25: ='Visual chart Edit'!I28 -> 226.5 | F25: ='Visual chart Edit'!K28 -> DRY | G25: ='Visual chart Edit'!L28 -> E | H25: C | I25: C | K25: C | N25: Daukiyon Ki Dhani | O25: =+SUM(P25:S25) -> 4 | P25: =+COUNTIFS($D$4:$D$488,N25,$F$4:$F$488,"sandy")+COUNTIFS($D$4:$D$488,N25,$F$4:$F$488,"Dry")+COUNTIFS($D$4:$D$488,N25,$F$4:$F$488,"DFR")+COUNTIFS($D$4:$D$488,N25,$F$4:$F$488,"WFR")+COUNTIFS($D$4:$D$488,N25,$F$4:$F$488,"SFR") -> 4 | Q25: =+COUNTIFS($D$4:$D$488,N25,$F$4:$F$488,"WIP") -> 0 | R25: =+COUNTIFS($D$4:$D$488,N25,$F$4:$F$488,"Clear") -> 0 | S25: =+COUNTIFS($D$4:$D$488,N25,$F$4:$F$488,"ROW") -> 0 | T25: =+SUM(U25:Y25) -> 4 | U25: =+COUNTIFS($D$4:$D$488,N25,$G$4:$G$488,"E") -> 4 | V25: =+COUNTIFS($D$4:$D$488,N25,$G$4:$G$488,"WIP") -> 0 | W25: =+COUNTIFS($D$4:$D$488,N25,$G$4:$G$488,"Clear") -> 0 | X25: =+COUNTIFS($D$4:$D$488,N25,$G$4:$G$488,"ROW") -> 0 | Y25: =O25-X25-U25-W25-V25 -> 0 | Z25: =T25-U25 -> 0 | AA25: =+SUMIFS($E$4:$E$488,$D$4:$D$488,N25)/1000 -> 1.6246 | AB25: =+SUMIFS($E$4:$E$488,$D$4:$D$488,N25,$H$4:$H$488,$AB$3)/1000 -> 1.6246 | AC25: =+SUMIFS($E$4:$E$488,$D$4:$D$488,N25,$H$4:$H$488,$AC$3)/1000 -> 0 | AD25: =+SUMIFS($E$4:$E$488,$D$4:$D$488,N25,$H$4:$H$488,$AD$3)/1000 -> 0 | AE25: =+SUMIFS($E$4:$E$488,$D$4:$D$488,N25,$H$4:$H$488,$AE$3)/1000 -> 0 | AF25: =+SUMIFS($E$4:$E$488,$D$4:$D$488,N25,$H$4:$H$488,$AF$3)/1000 -> 0 | AG25: =AA25-SUM(AB25:AF25) -> 0
A26: =+SUBTOTAL(3,$B$4:B26) -> 0 | B26: ='Visual chart Edit'!B29 -> 4/1 | C26: ='Visual chart Edit'!C29 -> DA+0 | D26: Harwa | E26: ='Visual chart Edit'!I29 -> 343 | F26: ='Visual chart Edit'!K29 -> DRY | G26: ='Visual chart Edit'!L29 -> E | N26: Nehru Nagar | O26: =+SUM(P26:S26) -> 6 | P26: =+COUNTIFS($D$4:$D$488,N26,$F$4:$F$488,"sandy")+COUNTIFS($D$4:$D$488,N26,$F$4:$F$488,"Dry")+COUNTIFS($D$4:$D$488,N26,$F$4:$F$488,"DFR")+COUNTIFS($D$4:$D$488,N26,$F$4:$F$488,"WFR")+COUNTIFS($D$4:$D$488,N26,$F$4:$F$488,"SFR") -> 6 | Q26: =+COUNTIFS($D$4:$D$488,N26,$F$4:$F$488,"WIP") -> 0 | R26: =+COUNTIFS($D$4:$D$488,N26,$F$4:$F$488,"Clear") -> 0 | S26: =+COUNTIFS($D$4:$D$488,N26,$F$4:$F$488,"ROW") -> 0 | T26: =+SUM(U26:Y26) -> 6 | U26: =+COUNTIFS($D$4:$D$488,N26,$G$4:$G$488,"E") -> 6 | V26: =+COUNTIFS($D$4:$D$488,N26,$G$4:$G$488,"WIP") -> 0 | W26: =+COUNTIFS($D$4:$D$488,N26,$G$4:$G$488,"Clear") -> 0 | X26: =+COUNTIFS($D$4:$D$488,N26,$G$4:$G$488,"ROW") -> 0 | Y26: =O26-X26-U26-W26-V26 -> 0 | Z26: =T26-U26 -> 0 | AA26: =+SUMIFS($E$4:$E$488,$D$4:$D$488,N26)/1000 -> 2.4092 | AB26: =+SUMIFS($E$4:$E$488,$D$4:$D$488,N26,$H$4:$H$488,$AB$3)/1000 -> 2.4092 | AC26: =+SUMIFS($E$4:$E$488,$D$4:$D$488,N26,$H$4:$H$488,$AC$3)/1000 -> 0 | AD26: =+SUMIFS($E$4:$E$488,$D$4:$D$488,N26,$H$4:$H$488,$AD$3)/1000 -> 0 | AE26: =+SUMIFS($E$4:$E$488,$D$4:$D$488,N26,$H$4:$H$488,$AE$3)/1000 -> 0 | AF26: =+SUMIFS($E$4:$E$488,$D$4:$D$488,N26,$H$4:$H$488,$AF$3)/1000 -> 0 | AG26: =AA26-SUM(AB26:AF26) -> 0
A27: =+SUBTOTAL(3,$B$4:B27) -> 0 | B27: ='Visual chart Edit'!B30 -> 4/2 | C27: ='Visual chart Edit'!C30 -> DA+0 | D27: Harwa | E27: ='Visual chart Edit'!I30 -> 358.4 | F27: ='Visual chart Edit'!K30 -> DRY | G27: ='Visual chart Edit'!L30 -> E | N27: Nematpura | O27: =+SUM(P27:S27) -> 7 | P27: =+COUNTIFS($D$4:$D$488,N27,$F$4:$F$488,"sandy")+COUNTIFS($D$4:$D$488,N27,$F$4:$F$488,"Dry")+COUNTIFS($D$4:$D$488,N27,$F$4:$F$488,"DFR")+COUNTIFS($D$4:$D$488,N27,$F$4:$F$488,"WFR")+COUNTIFS($D$4:$D$488,N27,$F$4:$F$488,"SFR") -> 7 | Q27: =+COUNTIFS($D$4:$D$488,N27,$F$4:$F$488,"WIP") -> 0 | R27: =+COUNTIFS($D$4:$D$488,N27,$F$4:$F$488,"Clear") -> 0 | S27: =+COUNTIFS($D$4:$D$488,N27,$F$4:$F$488,"ROW") -> 0 | T27: =+SUM(U27:Y27) -> 7 | U27: =+COUNTIFS($D$4:$D$488,N27,$G$4:$G$488,"E") -> 7 | V27: =+COUNTIFS($D$4:$D$488,N27,$G$4:$G$488,"WIP") -> 0 | W27: =+COUNTIFS($D$4:$D$488,N27,$G$4:$G$488,"Clear") -> 0 | X27: =+COUNTIFS($D$4:$D$488,N27,$G$4:$G$488,"ROW") -> 0 | Y27: =O27-X27-U27-W27-V27 -> 0 | Z27: =T27-U27 -> 0 | AA27: =+SUMIFS($E$4:$E$488,$D$4:$D$488,N27)/1000 -> 2.9564 | AB27: =+SUMIFS($E$4:$E$488,$D$4:$D$488,N27,$H$4:$H$488,$AB$3)/1000 -> 2.9564 | AC27: =+SUMIFS($E$4:$E$488,$D$4:$D$488,N27,$H$4:$H$488,$AC$3)/1000 -> 0 | AD27: =+SUMIFS($E$4:$E$488,$D$4:$D$488,N27,$H$4:$H$488,$AD$3)/1000 -> 0 | AE27: =+SUMIFS($E$4:$E$488,$D$4:$D$488,N27,$H$4:$H$488,$AE$3)/1000 -> 0 | AF27: =+SUMIFS($E$4:$E$488,$D$4:$D$488,N27,$H$4:$H$488,$AF$3)/1000 -> 0 | AG27: =AA27-SUM(AB27:AF27) -> 0
