Workbook
Name \0: #REF!
Name \0: #REF!
Name \2: #REF!
Name \A: #REF!
Name \a: #N/A
Name \A: #REF!
Name \A_1: "#REF!"
Name \B: #REF!
Name \B: #REF!
Name \C: #REF!
Name \c1: #REF!
Name \D: '[1]Annex-7,Contingent'!#REF!
Name \d: #N/A
Name \g: #REF!
Name \H: #REF!
Name \H: #REF!
Name \I: #REF!
Name \I: '[1]Annex-7,Contingent'!#REF!
Name \i: #REF!
Name \KWS123: #N/A
Name \l: #REF!
Name \l: #REF!
Name \M: #REF!
Name \N: #REF!
Name \P: #REF!
Name \q: #N/A
Name \R: '[1]Annex-7,Contingent'!#REF!
Name \R: #REF!
Name \S: #REF!
Name \t: #N/A
Name \U: #REF!
Name \V: #REF!
Name \z: #N/A
Name \z: #REF!
Name _: #REF!
Name _________________________________________________________dol12: #REF!
Name _________________________________________________________in18900: #REF!
Name _________________________________________________________iv19000: #REF!
Name ________________________________________________________dol12: #REF!
Name ________________________________________________________dol6: #REF!
Name ________________________________________________________in18900: #REF!
Name ________________________________________________________iv19000: #REF!
Name _______________________________________________________dol12: #REF!
Name _______________________________________________________dol6: #REF!
Name _______________________________________________________in18900: #REF!
Name _______________________________________________________iv19000: #REF!
Name ______________________________________________________dol12: #REF!
Name ______________________________________________________dol6: #REF!
Name _____________________________________________________dol12: #REF!
Name _____________________________________________________dol6: #REF!
Name _____________________________________________________in18900: #REF!
Name _____________________________________________________iv19000: #REF!
Name ____________________________________________________dol12: #REF!
Name ____________________________________________________dol6: #REF!
Name ____________________________________________________in18900: #REF!
Name ____________________________________________________iv19000: #REF!
Name ___________________________________________________dol12: #REF!
Name ___________________________________________________dol6: #REF!
Name ___________________________________________________in18900: #REF!
Name ___________________________________________________iv19000: #REF!

Sheet Progress Summary
A1: #VALUE! | B1: Project Code - | C1: TB-408 | D1: Date | E1: =+TODAY() -> 45964 | G1: Head - T&D | H1: Rajinder Gupta | J1: Head T&D-North | K1: Sanjay K. Gupta | L1: Regional Manager | M1: Sandeep Singh Kumar | Q1: Shortcut for previous of Full description
B2: Client Name- | C2: Resonia Limited (Formally Sterlite Power Transmission Limited) | G2: Project Manager | H2: Partha Pal | L2: Planning Engineer | M2: Raghav Ranjan | Q2: Link for go through
B3: Project Name- | C3: 765KV D/C Fatehgarh III- Beawar Transmission Line, PKG F | G3: Effective Date | H3: 45266 | J3: End Date | K3: 45961 | L3: LOA Value | M3: Rs 283.08 Cr Supply -Rs 209.88 Cr., Service.-Rs 73.20 Cr | Q3: X-ing Status'!A1
A4: Sr. No. | B4: Activity | C4: As per latest Estimate | D4: Cumm. Progress up to last Month | E4: Balance on Starting of this Month | F4: Plan for this Month | G4: Today Progress | H4: MTD | I4: WIP | J4: Cumulative Progress | K4: Balance | L4: Gangs at present | M4: Remarks | N4: Support Required | O4: % Completion | Q4: L2 Schedule'!A1
A5: 1 | B5: Check Survey (Kms) | C5: 191.373 | D5: 191.393 | E5: =C5-D5 -> -0.02 | F5: =E5 -> -0.02 | J5: =D5+H5 -> 191.393 | K5: =C5-J5 -> -0.02 | L5: - | O5: =(J5/C5)*100 -> 100.01045 | Q5: Hindrance Register (Row)'!A1
A6: 2 | B6: Foundation (Nos.) | C6: 485 | D6: 478 | E6: =C6-D6 -> 7 | F6: 7 | I6: 2 | J6: =D6+H6 -> 478 | K6: =C6-J6 -> 7 | L6: 1 | M6: WIP- 21/1 , 26/8 Completed:- | O6: =(J6/C6)*100 -> 98.556701 | Q6: Survey!A1
A7: 3 | B7: Earthing (Nos.) | C7: 485 | D7: 478 | E7: =C7-D7 -> 7 | F7: 7 | J7: =D7+H7 -> 478 | K7: =C7-J7 -> 7 | L7: =L6 -> 1 | O7: =(J7/C7)*100 -> 98.556701 | Q7: Foundation!A1
A8: 4 | B8: Tower Erection (Nos) | C8: 485 | D8: 375 | E8: =C8-D8 -> 110 | F8: 33 | I8: 10 | J8: =D8+H8 -> 375 | K8: =C8-J8 -> 110 | L8: 10 | M8: WIP- 3/0, 4/0, 5/0, 32/3, 33/0, 34/1, 34/4, 40/1, 42/0, 42/2 Today Completed - | N8: 38/3:- Under ROW, Based on instruction by resonia Limited, gang is shifted at other locs. | O8: =(J8/C8)*100 -> 77.319588 | Q8: Earthing!A1
A9: 5 | B9: Tack Welding (Nos) | C9: 485 | D9: 205 | E9: =C9-D9 -> 280 | F9: =F8 -> 33 | J9: =D9+H9 -> 205 | K9: =C9-J9 -> 280 | L9: 1 | O9: =(J9/C9)*100 -> 42.268041 | Q9: Erection!A1
A10: 6 | B10: Paying Out (Kms) | C10: =C5 -> 191.373 | D10: 47.296 | E10: =C10-D10 -> 144.077 | F10: 18 | I10: 1.68 | J10: =D10+H10 -> 47.296 | K10: =C10-J10 -> 144.077 | L10: 1 | M10: AP72-73:- Pilot Paying out done in 1st Phase. | O10: =(J10/C10)*100 -> 24.71404 | Q10: Tackwelding!A1
A11: 7 | B11: Final Sag (Kms) | C11: =C10 -> 191.373 | D11: 47.298 | E11: =C11-D11 -> 144.075 | F11: 18 | I11: 0 | J11: =D11+H11 -> 47.298 | K11: =C11-J11 -> 144.075 | L11: 0 | O11: =(J11/C11)*100 -> 24.715085 | Q11: Stringing!A1
A12: 8 | B12: OPGW (Kms) | C12: =C11 -> 191.373 | D12: 39.603 | E12: =C12-D12 -> 151.77 | F12: 0 | I12: 0 | J12: =D12+H12 -> 39.603 | K12: =C12-J12 -> 151.77 | L12: 0 | O12: =(J12/C12)*100 -> 20.694142 | Q12: Stringing associated works'!A1
Q13: OPGW!A1
A14: Workfront Status | Q14: Visual chart'!A1
Q15: Page Chart'!A1
A16: A. Foundation | Q16: Benching F'!A1
A17: Balance on 1st of this month | B17: Progress MTD | C17: WIP | D17: Clear/Yet to attempt | E17: ROW | F17: Remarks
A18: =E6 -> 7 | B18: =H6 -> 0 | C18: =I6 -> 2 | D18: ='Page Chart'!N4 -> 0 | E18: =A18-B18-C18-D18 -> 5
A20: B. Erection
A21: Balance on 1st of this month | B21: Progress MTD | C21: WIP | D21: Clear/Yet to attempt | E21: ROW | F21: Linked With Fnd | G21: Remarks
A22: =E8 -> 110 | B22: =H8 -> 0 | C22: =I8 -> 10 | D22: ='Page Chart'!S4+'Page Chart'!U4-F22 -> 33 | E22: ='Page Chart'!T4 -> 60 | F22: =A18 -> 7
A24: C. Stringing
A25: STR P/Out Bal. on starting of this month | B25: Progress MTD | C25: WIP | D25: Clear/Yet to attempt | E25: ROW | F25: Readiness awaited due to Erec. | G25: Readiness awaited due to Tower Inspection
A26: =E10 -> 144.077 | B26: =H10 -> 0 | C26: =I10 -> 1.68

Sheet Project Details
A1: Project Code | B1: Project Name | C1: Client Name | D1: NOA Start Date | E1: LOA End Date | F1: Planning Engineer | G1: PCH | H1: Regional Manager | I1: Project Manger | J1: Section Incharge | K1: Supervisor
A2: TB408 | B2: 765 KV Beawer Transmission Line, PKG F | C2: Resonia Limited | D2: 45266 | E2: 45960 | F2: Mr. Raghav Ranjan | G2: Mr. Sanjay Kumar Gupta | H2: Mr. Sandeep Singh Kumar | I2: Mr. Partha Pal | J2: Sumit Kumar | K2: Pradeep Kumar
J3: Vivek Shukla | K3: Vikas Kumar
J4: Vivek Kumar | K4: Ganesh Singh
J5: Vijay Yadav | K5: Dineshwar Mahto
J6: Ram Tirath Singh | K6: Kamla Pal Prasad
K7: Bisun Saw
K8: Shakib Hussain
K9: Umesh Prasad
K10: Prince Kumar Nirala
K11: Pramod Kumar Sahoo
K12: Jainath Mahto
K13: Rajesh Pal
K14: Ramji Tanti
K15: Rakesh Pramanik
K16: Sam Mahammad
K17: Suresh Kumar Pal
K18: Hulas Kumar Mahto
... K40: Jaylal Mahto

Sheet X-ing Status
A1: Progress Summary'!A1
A2: Details of Crossing in 765KV D/C Fatehgarh-III to Beawar Transmission Line
A3: Sr. No. | B3: Name of Crossing | C3: From | D3: To | E3: Span in Mtrs | F3: Submission Date | G3: Appr. Date | H3: Foundation Status | I3: Erection Status | J3: Stringing Status | K3: Plan for Stringing
A4: Power Line Crossing – 9 nos
A5: 1 | B5: 400 KV S/C Jaisalmer-Barmer Line | C5: 3/0 | D5: 4/0 | E5: 226.52 | F5: 45337 | H5: AP3:- Completed AP4:- Completed | I5: AP3:- WIP AP4:- Balance | J5: Balance
A6: 2 | B6: 220 KV D/C Barmer-Akal Line | C6: 5/0 | D6: 6/0 | E6: 246.019 | F6: 45337 | H6: AP5:- Completed AP6:- Completed | I6: AP5:- Balance AP6:- Balance | J6: Balance
A7: 3 | B7: 132 KV S/C Sheo-Jaisalmer Line | C7: 7/0 | D7: 8/0 | E7: 210.755 | F7: 45337 | H7: AP7:- Completed AP8:- Completed | I7: AP7:- Balance AP8:- Balance | J7: Balance
A8: 4 | B8: 400 KV D/C Barmer-Jaisalmer-2 Line | C8: 9/0 | D8: 10/0 | E8: 233.076 | F8: 45337 | H8: AP9:- Completed AP10:- Completed | I8: AP9:- Balance AP10:- Balance | J8: Balance
A9: 5 | B9: 132 KV S/C Sheo-Undoo Line | C9: 12/0 | D9: 13/0 | E9: 211.914 | F9: 45337 | H9: AP12:- Completed AP13:- Completed | I9: AP12:- Completed AP13:- Balance | J9: Balance
A10: 6 | B10: 132 KV S/C Undoo-Baytoo Line | C10: 23/0 | D10: 24/0 | E10: 222.155 | F10: 45307 | G10: 45470 | H10: AP23:- Completed AP24:- Completed | I10: AP23:- Balance AP24:- Completed | J10: Balance
A11: 7 | B11: 400 KV D/C Mandor-JSW Transmission Line | C11: 46/0 | D11: 47/0 | E11: 197.7 | H11: AP46:- Completed AP47:- Completed | I11: AP46:- Completed AP47:- Completed | J11: Balance
A12: 8 | B12: 400 KV D/C Line | C12: 56/0 | D12: 57/0 | E12: 179.9 | H12: AP56:- Completed AP57:- Completed | I12: AP56:- Completed AP57:- Completed. | J12: Balance
A13: 9 | B13: 220 KV D/C Balotra-Boranada Transmission Line | C13: 66/0 | D13: 67/0 | E13: 207.8 | F13: 45359 | G13: 45491 | H13: AP66:- Completed AP67:- Completed | I13: AP66:- Completed AP67:- Completed | J13: Balance
A14: NH Crossings-3 Nos | B14: NH Crossing
A15: 1 | B15: NH - 68 (Barmer - Jaisalmer) | C15: 5/0 | D15: 6/0 | E15: 246.019 | F15: 45337 | H15: AP5:- Completed AP6:- Completed | I15: AP5:- Balance AP6:- Balance
A16: 2 | B16: Expressway (Amritsar-Jamnagar) | C16: 58/0 | D16: 59/0 | E16: 238.9 | F16: 45359 | G16: 45444 | H16: AP58:- Completed AP59:- Completed | I16: AP58:- Completed AP59:- Completed | J16: Balance
A17: 3 | B17: NH | C17: 68/0 | D17: 69/0 | E17: 200.9 | F17: 45359 | G17: 45469 | H17: AP68:- Completed AP69:- Completed | I17: AP68:- Completed AP69:- Completed | J17: Balance
A18: Gas Pipe Line-1 Nos | B18: NH Crossing
A19: 1 | B19: Gas Pipe Lines | C19: 65/7 | D19: 65/8 | E19: 394.3 | H19: AP65/7:- Completed AP65/8:- Completed | I19: AP65/7:- Completed AP65/8:- Completed | J19: Completed

Sheet L2 Schedule
A1: Progress Summary'!A1 | B1: L2 Schedule vs Actual
B3: Line Name: Part F, 765KV D/C Fatehgarh- Beawar Transmission Line
B4: LOI Date: 11-Sep-2023
B5: Effective Date: 06-Dec-2023
B6: Schedule Completion as per LOA: 05-March-2025
B7: Scope & Discription | G7: Before L2 | H7: L2-Approved | X7: Extension of time (Approved) -1 | AE7: Remarks
B8: Sr. No. | C8: Description | D8: Scope of Work | E8: UOM | F8: Qty. | G8: 45200 | H8: 45261 | I8: 45292 | J8: 45323 | K8: 45352 | L8: 45383 | M8: 45413 | N8: 45444 | O8: 45474 | P8: 45505 | Q8: 45536 | R8: 45566 | S8: 45597 | T8: 45627 | U8: 45658 | V8: 45689 | W8: 45717 | X8: 45748 | Y8: 45778 | Z8: 45809 | AA8: 45839 | AB8: 45870 | AC8: 45901 | AD8: 45931
G9: 0 | H9: 1 | I9: 2 | J9: 3 | K9: 4 | L9: 5 | M9: 6 | N9: 7 | O9: 8 | P9: 9 | Q9: 10 | R9: 11 | S9: 12 | T9: 13 | U9: 14 | V9: 15 | W9: 16 | X9: 17 | Y9: 18 | Z9: 19 | AA9: 20 | AB9: 21 | AC9: 22 | AD9: 23
B10: 1 | C10: Release of Sag Template Curve & Tower Spotting Data | D10: Sterlite
B11: 2 | C11: Approval of repeated tower design & its BOMS | D11: Sterlite
B12: 3 | C12: Approval of repeated foundation design/drawings | D12: Sterlite
B13: 4 | C13: Supply
B14: i) | C14: Manufacturing of Stubs with Earthing material(incl. B&N) | D14: KEC
B15: A. | C15: Inspection of stub | D15: Sterlite | E15: Nos. | F15: 482 | H15: 40 | I15: 100 | J15: 100 | L15: 100 | M15: 65 | O15: 77
B16: B. | C16: Dispatch of stub | D16: KEC | E16: Nos. | F16: 482 | H16: =H15 -> 40 | I16: =I15 -> 100 | J16: =J15 -> 100 | K16: =K15 -> 0 | L16: =L15 -> 100 | M16: =M15 -> 65 | N16: =N15 -> 0 | O16: =O15 -> 77 | ... T16: =T15 -> 0
B17: C. | C17: Receipt of stubs at site | D17: KEC | E17: Nos. | F17: 482 | H17: =H15 -> 40 | I17: =I15 -> 100 | J17: =J15 -> 100 | K17: =K15 -> 0 | L17: =L15 -> 100 | M17: =M15 -> 65 | N17: =N15 -> 0 | O17: =O15 -> 77 | ... T17: =T15 -> 0
C18: MFC submitted on | H18: 192 | I18: 73 | J18: 73
C19: MFC received on | H19: =75+75+20+15+2+5 -> 192 | I19: =265-192 -> 73 | K19: =338-265 -> 73 | N19: =482-338 -> 144
C20: Actual | H20: 40 | I20: 120 | J20: 0 | K20: 10 | M20: 152 | N20: =361-322 -> 39 | O20: 5 | R20: =393-366 -> 27
B21: ii) | C21: Manufacturing of Tower (incl B&N) | D21: KEC
B22: A. | C22: Inspection of tower | D22: Sterlite | E22: Nos. | F22: 482 | H22: 50 | I22: 60 | J22: 60 | K22: 60 | L22: 60 | M22: 65 | N22: 66 | O22: 31 | P22: 30
B23: B. | C23: Dispatch of tower | D23: KEC | E23: Nos. | F23: 482 | I23: 50 | J23: 60 | K23: 60 | L23: 60 | M23: 60 | N23: 65 | O23: 66 | P23: 31 | Q23: 30 | R23: =R22 -> 0 | S23: =S22 -> 0 | T23: =T22 -> 0
B24: C. | C24: Receipt of complete towers at site | D24: KEC | E24: Nos. | F24: 482 | I24: 50 | J24: 60 | K24: 60 | L24: 60 | M24: 60 | N24: 65 | O24: 66 | P24: 31 | Q24: 30 | R24: =+R23 -> 0 | S24: =+S23 -> 0 | T24: =+T23 -> 0
C25: MFC submitted on | H25: 97 | I25: 128 | M25: 65 | N25: =482-290 -> 192
C26: MFC received on | H26: 97 | I26: 128 | N26: 257
C27: Actual | I27: 50 | J27: 60 | K27: 45 | L27: 74 | M27: 9 | N27: 99 | Q27: 54 | S27: 10
B28: iii) | C28: Supply of following Tower accessories
B29: A. | C29: Danger Plate | D29: KEC | E29: % | F29: 100 | P29: 1
B30: B. | C30: Number Plate | D30: KEC | E30: % | F30: 100 | P30: 1
B31: C. | C31: Phase Plate (Set of three) | D31: KEC | E31: % | F31: 100 | P31: 1
B32: D. | C32: Circuit Plate (Set of Two) | D32: KEC | E32: & | F32: 100 | P32: 1
B33: E. | C33: Anti-Climbing Device | D33: KEC | E33: % | F33: 100 | P33: 1
B34: F. | C34: Bird Guard (Set of Three) | D34: KEC | E34: % | F34: 100 | P34: 1
B35: iv) | C35: Other's Supply
B36: A. | C36: Span Marker | D36: KEC | E36: % | F36: 100 | P36: 1
B37: B. | C37: Aviation Light | D37: KEC | E37: % | F37: 100 | P37: 1
B38: v) | C38: OSM
B39: A. | C39: Supply of AL59 Zebra Conductor & associated Acessories | D39: Sterlite | E39: % | F39: 100 | K39: 0.25 | N39: 0.25 | P39: 0.25 | R39: 0.25
B40: B. | C40: Supply of Insulator & associated Hardwere | D40: Sterlite | E40: % | F40: 100 | K40: 0.25 | N40: 0.25 | P40: 0.25 | R40: 0.25
B41: C. | C41: Supply of Earth Wire & associated Hardwere | D41: Sterlite | E41: % | F41: 100 | H41: =H40 -> 0 | I41: =I40 -> 0 | K41: 0.25 | L41: =L40 -> 0 | N41: 0.25 | O41: =O40 -> 0 | P41: 0.25 | R41: 0.25
...

Sheet Hindrance Register (Row)
A1: Progress Summary'!A1
A2: HINDRANCE REGISTER (Note:- Day to day hindrance are captured on other sheet and intimate to resonia via DPR on Summary Sheet)
A3: 1 | B3: Name of the Substation/TL/Project | C3: 765 KV Fatehgarh-3 Beawer Transmission Line Part-F | G3: 2. Name of Work | I3: Transmission & Power Distribution
A4: 3 | B4: Name of the Executing Agency | C4: KEC International Limited | G4: 3. LOA No. & Date | I4: LOI/EPC/FBTL/PART-F/KEC/01 Dated 11.09.2023
A6: Sr. No. | B6: Activity | C6: Total | D6: Open | E6: Close | I6: Progress Summary'!A1
A7: 1 | B7: Survey | C7: =+COUNTIF($D$16:$D$994,B7) -> 20 | D7: =+COUNTIFS($D$16:$D$995,B7,$H$16:$H$995,"AWAITED") -> 0 | E7: =C7-D7 -> 20
A8: 2 | B8: Foundation | C8: =+COUNTIF($D$16:$D$994,B8) -> 210 | D8: =+COUNTIFS($D$16:$D$995,B8,$H$16:$H$995,"AWAITED") -> 5 | E8: =C8-D8 -> 205
A9: 3 | B9: Erection | C9: =+COUNTIF($D$16:$D$994,B9) -> 81 | D9: =+COUNTIFS($D$16:$D$995,B9,$H$16:$H$995,"AWAITED") -> 60 | E9: =C9-D9 -> 21
A10: 4 | B10: Stringing | C10: =+COUNTIF($D$16:$D$994,B10) -> 3 | D10: =+COUNTIFS($D$16:$D$995,B10,$H$16:$H$995,"AWAITED") -> 0 | E10: =C10-D10 -> 3
A11: 5 | B11: Others | C11: =+COUNTIF($D$16:$D$994,B11) -> 3 | D11: =+COUNTIFS($D$16:$D$995,B11,$H$16:$H$995,"AWAITED") -> 0 | E11: =C11-D11 -> 3
A12: Total | C12: =SUM(C7:C11) -> 317 | D12: =+SUM(D7:D11) -> 65 | E12: =+SUM(E7:E11) -> 252
A15: Check Survey
A16: S.No | B16: Nature of Hindrance | C16: Loc/Sec. | D16: Affected Activity | E16: Affected Gang Name | F16: Date of 1st attempt | G16: Date of removal (Last attempt) | H16: Period of hindrance | I16: Remarks
A17: 1 | B17: Check survey not done due to frequent obstruction by land owner from 38/0 to 39/0. | C17: 38-39 | D17: Survey | F17: 45266 | G17: 45575 | H17: =+IF(G17="","Awaited",_xlfn.DAYS(G17,F17)+1) -> 310 | I17: Refer KEC letter dated 02-01-24. Reattempted on 09-01-24 but still in ROW. 3rd time attempted on dated 10.07.24 informed to you via mail regarding ROW.
A18: 2 | B18: Check survey not done due to frequent obstruction by land owner from 39/0 to 40/0. | C18: 39-40 | D18: Survey | F18: 45266 | G18: 45575 | H18: =+IF(G18="","Awaited",_xlfn.DAYS(G18,F18)+1) -> 310 | I18: Refer KEC letter dated 02-01-24. Reattempted on 09-01-24 but still in ROW. 3rd time attempted on dated 10.07.24 informed to you via mail regarding ROW.
A19: 3 | B19: Check survey is on hold from Gantry to 2/0 due to Non-Finalization of Gantry. | C19: Gty-2 | D19: Survey | F19: 45266 | G19: 45488 | H19: =+IF(G19="","Awaited",_xlfn.DAYS(G19,F19)+1) -> 223 | I19: Refer KEC letter dated 02-01-24.
A20: 4 | B20: Check survey not done due to frequent obstruction by land owner from 10/12 to 11A. | C20: 10/12-11A | D20: Survey | F20: 45266 | G20: 45307 | H20: =+IF(G20="","Awaited",_xlfn.DAYS(G20,F20)+1) -> 42 | I20: Refer KEC letter dated 02-01-24.
A21: 5 | B21: Check survey not done due to ROW from AP 20-AP 21. | C21: 20-21 | D21: Survey | F21: 45266 | G21: 45831 | H21: =+IF(G21="","Awaited",_xlfn.DAYS(G21,F21)+1) -> 566 | I21: Refer KEC letter dated 02-01-24. SPTL mail dated 20/5/24 having subject Optimization from GTY to AP74 (Part- F). Clearance for check survey received on 17.10.24. however survey team along with machinery idled at this section since 18th. Section is still in ROW. on dated 19.10.2024.
A22: 6 | B22: Delay in approval of check survey report from Ap 21 to AP 25. | C22: 21-25 | D22: Survey | F22: 45266 | G22: 45274 | H22: =+IF(G22="","Awaited",_xlfn.DAYS(G22,F22)+1) -> 9
A23: 7 | B23: Delay in approval of check survey report from Ap 14 to AP 20. | C23: 14-20 | D23: Survey | F23: 45266 | G23: 45274 | H23: =+IF(G23="","Awaited",_xlfn.DAYS(G23,F23)+1) -> 9
A24: 8 | B24: ROW in check survey works. | C24: 47-48 | D24: Survey | F24: 45272 | G24: 45274 | H24: =+IF(G24="","Awaited",_xlfn.DAYS(G24,F24)+1) -> 3
A25: 9 | B25: ROW in check survey works. | C25: 70-71 | D25: Survey | F25: 45275 | G25: 45636 | H25: =+IF(G25="","Awaited",_xlfn.DAYS(G25,F25)+1) -> 362
A26: 10 | B26: ROW in check survey works. | C26: 71-72 | D26: Survey | F26: 45275 | G26: 45331 | H26: =+IF(G26="","Awaited",_xlfn.DAYS(G26,F26)+1) -> 57
A27: 11 | B27: ROW in check survey works. | C27: 72-73 | D27: Survey | F27: 45275 | G27: 45331 | H27: =+IF(G27="","Awaited",_xlfn.DAYS(G27,F27)+1) -> 57
A28: 12 | B28: ROW in check survey works. | C28: 73-74 | D28: Survey | F28: 45275 | G28: 45487 | H28: =+IF(G28="","Awaited",_xlfn.DAYS(G28,F28)+1) -> 213
A29: 13 | B29: Delay in approval of check survey report from Ap 32 to AP 37. | C29: 32-37 | D29: Survey | F29: 45281 | G29: 45289 | H29: =+IF(G29="","Awaited",_xlfn.DAYS(G29,F29)+1) -> 9
A30: 14 | B30: Delay in approval of check survey From AP 2-10/12 | C30: 2-10/12 | D30: Survey | F30: 45286 | G30: 45316 | H30: =+IF(G30="","Awaited",_xlfn.DAYS(G30,F30)+1) -> 31 | I30: Email dated 18/1/24 regarding Frequent obstruction by landowners.
A31: 15 | B31: Delay in approval of check survey From AP 11A-14. | C31: 11A-14 | D31: Survey | F31: 45286 | G31: 45316 | H31: =+IF(G31="","Awaited",_xlfn.DAYS(G31,F31)+1) -> 31 | I31: Email dated 18/1/24 regarding Frequent obstruction by landowners.
A32: 16 | B32: Location no 11/5 are on Hold due to ROW during check survey, Centre peg not done for verification of benching and others. | C32: 11/5 | D32: Survey | F32: 45308 | G32: 45432 | H32: =+IF(G32="","Awaited",_xlfn.DAYS(G32,F32)+1) -> 125 | I32: Email dated 18/1/24 regarding Frequent obstruction by landowners.
A33: 17 | B33: Location no 11A/0 are on Hold due to ROW during check survey, Centre peg not done for verification of benching and others. | C33: 11A/0 | D33: Survey | F33: 45308 | G33: 45432 | H33: =+IF(G33="","Awaited",_xlfn.DAYS(G33,F33)+1) -> 125 | I33: Email dated 18/1/24 regarding Frequent obstruction by landowners.
A34: 18 | B34: ROW in check survey works. | C34: 40-41 | D34: Survey | F34: 45318 | G34: 45390 | H34: =+IF(G34="","Awaited",_xlfn.DAYS(G34,F34)+1) -> 73
A35: 19 | B35: ROW in check survey works. | C35: 41-42 | D35: Survey | F35: 45318 | G35: 45390 | H35: =+IF(G35="","Awaited",_xlfn.DAYS(G35,F35)+1) -> 73
A36: 20 | B36: ROW in check survey works. | C36: 42-43 | D36: Survey | F36: 45318 | G36: 45390 | H36: =+IF(G36="","Awaited",_xlfn.DAYS(G36,F36)+1) -> 73
A39: Foundation
A40: S.No | B40: Nature of Hindrance | C40: Loc/Sec. | D40: Affected Activity | E40: Affected Gang Name | F40: Date of occurrence | G40: Date of removal | H40: Period of hindrance | I40: Remarks
A41: 1 | B41: ROW due to obstruction by land owner at Loc No 37/2. Post Excavation work was stopped by Land owners. After that cleared on 07/12/2023. | C41: 37/2 | D41: Foundation | E41: Nagana Rai | F41: 45266 | G41: 45267 | H41: =+IF(G41="","Awaited",_xlfn.DAYS(G41,F41)+1) -> 2
A42: 2 | B42: ROW encountered in Excavation works. | C42: 62/6 | D42: Foundation | F42: 45274 | G42: 45275 | H42: =+IF(G42="","Awaited",_xlfn.DAYS(G42,F42)+1) -> 2
A43: 3 | B43: ROW due to obstruction by land owner at Loc No 26/2. | C43: 26/2 | D43: Foundation | E43: A.B. Construction | F43: 45276 | G43: 45277 | H43: =+IF(G43="","Awaited",_xlfn.DAYS(G43,F43)+1) -> 2 | I43: Refer Mail dated 16/12/2023.
A44: 4 | B44: Our Whole team of one gang along with its machinery are completely idle at location no 26/2 | C44: 26/2 | D44: Foundation | E44: A.B. Construction | F44: 45276 | G44: 45277 | H44: =+IF(G44="","Awaited",_xlfn.DAYS(G44,F44)+1) -> 2 | I44: Idled Resources (Highly Skilled manpower-1, Skilled:- 2, Semi Skilled:- 3, Unskilled:- 4, JCB with operator:- 1, Azax flori with operator:- 1, Tracktor with operator:- 1, Tanker with Operator:- 1, Bolero/Camper with Diesel:- 1)
A45: 5 | B45: ROW at Location No 27/11. | C45: 27/11 | D45: Foundation | E45: Nagana Rai | F45: 45266 | G45: 45334 | H45: =+IF(G45="","Awaited",_xlfn.DAYS(G45,F45)+1) -> 69 | I45: Email dated 18/1/24 regarding Frequent obstruction by landowners. Your email dated 12.02.24 regarding workfront
...

Sheet Page Chart
A1: Progress Summary'!A1 | J1: Village wise dashboard
A2: Location Wise Status | J2: Foundation | P2: Erection
A3: Sr. No. | B3: Loc No. | C3: TOT | D3: Village Name | E3: Span | F3: FDN | G3: ERE | H3: Str | I3: Remarks (if any) | J3: Village wise breakups | K3: Total | L3: Comp. | M3: WIP | N3: Clear | O3: ROW | P3: Total | Q3: Comp. | R3: WIP | S3: Clear | T3: ROW | U3: Yet to attempt | V3: Balance
A4: =+SUBTOTAL(3,$B$4:B4) -> 1 | B4: ='Visual chart Edit'!B7 -> 1/0 | C4: ='Visual chart Edit'!C7 -> DD60+0 | D4: Mandai | E4: ='Visual chart Edit'!I7 -> 122 | F4: ='Visual chart Edit'!K7 -> DRY | G4: ='Visual chart Edit'!L7 -> E | J4: Total Number of Village (49 No's) | K4: =+SUM(K5:K53) -> 485 | L4: =+SUM(L5:L53) -> 478 | M4: =+SUM(M5:M53) -> 2 | N4: =+SUM(N5:N53) -> 0 | O4: =+SUM(O5:O53) -> 5 | P4: =+SUM(P5:P53) -> 485 | Q4: =+SUM(Q5:Q53) -> 375 | R4: =+SUM(R5:R53) -> 10 | ... U4: =+SUM(U5:U53) -> 30 | V4: =P4-Q4 -> 110
A5: =+SUBTOTAL(3,$B$4:B5) -> 2 | B5: ='Visual chart Edit'!B8 -> 1A/0 | C5: ='Visual chart Edit'!C8 -> DD60+0 | D5: Mandai | E5: ='Visual chart Edit'!I8 -> 90 | F5: ='Visual chart Edit'!K8 -> DRY | G5: ='Visual chart Edit'!L8 -> E | J5: Mandai | K5: =+SUM(L5:O5) -> 16 | L5: =+COUNTIFS($D$4:$D$488,J5,$F$4:$F$488,"sandy")+COUNTIFS($D$4:$D$488,J5,$F$4:$F$488,"Dry")+COUNTIFS($D$4:$D$488,J5,$F$4:$F$488,"DFR")+COUNTIFS($D$4:$D$488,J5,$F$4:$F$488,"WFR")+COUNTIFS($D$4:$D$488,J5,$F$4:$F$488,"SFR") -> 16 | M5: =+COUNTIFS($D$4:$D$488,J5,$F$4:$F$488,"WIP") -> 0 | N5: =+COUNTIFS($D$4:$D$488,J5,$F$4:$F$488,"Clear") -> 0 | O5: =+COUNTIFS($D$4:$D$488,J5,$F$4:$F$488,"ROW") -> 0 | P5: =+SUM(Q5:U5) -> 16 | Q5: =+COUNTIFS($D$4:$D$488,J5,$G$4:$G$488,"E") -> 16 | R5: =+COUNTIFS($D$4:$D$488,J5,$G$4:$G$488,"WIP") -> 0 | S5: =+COUNTIFS($D$4:$D$488,J5,$G$4:$G$488,"Clear") -> 0 | T5: =+COUNTIFS($D$4:$D$488,J5,$G$4:$G$488,"ROW") -> 0 | U5: =K5-T5-Q5-S5-R5 -> 0 | V5: =P5-Q5 -> 0
A6: =+SUBTOTAL(3,$B$4:B6) -> 3 | B6: ='Visual chart Edit'!B9 -> 1A/1 | C6: ='Visual chart Edit'!C9 -> DA+6 | D6: Mandai | E6: ='Visual chart Edit'!I9 -> 277.7 | F6: ='Visual chart Edit'!K9 -> DFR | G6: ='Visual chart Edit'!L9 -> E | J6: Harwa | K6: =+SUM(L6:O6) -> 22 | L6: =+COUNTIFS($D$4:$D$488,J6,$F$4:$F$488,"sandy")+COUNTIFS($D$4:$D$488,J6,$F$4:$F$488,"Dry")+COUNTIFS($D$4:$D$488,J6,$F$4:$F$488,"DFR")+COUNTIFS($D$4:$D$488,J6,$F$4:$F$488,"WFR")+COUNTIFS($D$4:$D$488,J6,$F$4:$F$488,"SFR") -> 21 | M6: =+COUNTIFS($D$4:$D$488,J6,$F$4:$F$488,"WIP") -> 0 | N6: =+COUNTIFS($D$4:$D$488,J6,$F$4:$F$488,"Clear") -> 0 | O6: =+COUNTIFS($D$4:$D$488,J6,$F$4:$F$488,"ROW") -> 1 | P6: =+SUM(Q6:U6) -> 22 | Q6: =+COUNTIFS($D$4:$D$488,J6,$G$4:$G$488,"E") -> 14 | R6: =+COUNTIFS($D$4:$D$488,J6,$G$4:$G$488,"WIP") -> 3 | S6: =+COUNTIFS($D$4:$D$488,J6,$G$4:$G$488,"Clear") -> 3 | T6: =+COUNTIFS($D$4:$D$488,J6,$G$4:$G$488,"ROW") -> 0 | U6: =K6-T6-Q6-S6-R6 -> 2 | V6: =P6-Q6 -> 8
A7: =+SUBTOTAL(3,$B$4:B7) -> 4 | B7: ='Visual chart Edit'!B10 -> 1A/2 | C7: ='Visual chart Edit'!C10 -> DA+0 | D7: Mandai | E7: ='Visual chart Edit'!I10 -> 386 | F7: ='Visual chart Edit'!K10 -> DRY | G7: ='Visual chart Edit'!L10 -> E | J7: Chak Goonga | K7: =+SUM(L7:O7) -> 8 | L7: =+COUNTIFS($D$4:$D$488,J7,$F$4:$F$488,"sandy")+COUNTIFS($D$4:$D$488,J7,$F$4:$F$488,"Dry")+COUNTIFS($D$4:$D$488,J7,$F$4:$F$488,"DFR")+COUNTIFS($D$4:$D$488,J7,$F$4:$F$488,"WFR")+COUNTIFS($D$4:$D$488,J7,$F$4:$F$488,"SFR") -> 7 | M7: =+COUNTIFS($D$4:$D$488,J7,$F$4:$F$488,"WIP") -> 0 | N7: =+COUNTIFS($D$4:$D$488,J7,$F$4:$F$488,"Clear") -> 0 | O7: =+COUNTIFS($D$4:$D$488,J7,$F$4:$F$488,"ROW") -> 1 | P7: =+SUM(Q7:U7) -> 8 | Q7: =+COUNTIFS($D$4:$D$488,J7,$G$4:$G$488,"E") -> 3 | R7: =+COUNTIFS($D$4:$D$488,J7,$G$4:$G$488,"WIP") -> 0 | S7: =+COUNTIFS($D$4:$D$488,J7,$G$4:$G$488,"Clear") -> 1 | T7: =+COUNTIFS($D$4:$D$488,J7,$G$4:$G$488,"ROW") -> 3 | U7: =K7-T7-Q7-S7-R7 -> 1 | V7: =P7-Q7 -> 5
A8: =+SUBTOTAL(3,$B$4:B8) -> 5 | B8: ='Visual chart Edit'!B11 -> 1A/3 | C8: ='Visual chart Edit'!C11 -> DA+0 | D8: Mandai | E8: ='Visual chart Edit'!I11 -> 443.6 | F8: ='Visual chart Edit'!K11 -> DRY | G8: ='Visual chart Edit'!L11 -> E | J8: Goonga | K8: =+SUM(L8:O8) -> 5 | L8: =+COUNTIFS($D$4:$D$488,J8,$F$4:$F$488,"sandy")+COUNTIFS($D$4:$D$488,J8,$F$4:$F$488,"Dry")+COUNTIFS($D$4:$D$488,J8,$F$4:$F$488,"DFR")+COUNTIFS($D$4:$D$488,J8,$F$4:$F$488,"WFR")+COUNTIFS($D$4:$D$488,J8,$F$4:$F$488,"SFR") -> 4 | M8: =+COUNTIFS($D$4:$D$488,J8,$F$4:$F$488,"WIP") -> 0 | N8: =+COUNTIFS($D$4:$D$488,J8,$F$4:$F$488,"Clear") -> 0 | O8: =+COUNTIFS($D$4:$D$488,J8,$F$4:$F$488,"ROW") -> 1 | P8: =+SUM(Q8:U8) -> 5 | Q8: =+COUNTIFS($D$4:$D$488,J8,$G$4:$G$488,"E") -> 3 | R8: =+COUNTIFS($D$4:$D$488,J8,$G$4:$G$488,"WIP") -> 0 | S8: =+COUNTIFS($D$4:$D$488,J8,$G$4:$G$488,"Clear") -> 0 | T8: =+COUNTIFS($D$4:$D$488,J8,$G$4:$G$488,"ROW") -> 1 | U8: =K8-T8-Q8-S8-R8 -> 1 | V8: =P8-Q8 -> 2
A9: =+SUBTOTAL(3,$B$4:B9) -> 6 | B9: ='Visual chart Edit'!B12 -> 1A/4 | C9: ='Visual chart Edit'!C12 -> DA+3 | D9: Mandai | E9: ='Visual chart Edit'!I12 -> 333.4 | F9: ='Visual chart Edit'!K12 -> DFR | G9: ='Visual chart Edit'!L12 -> E | J9: Pusar | K9: =+SUM(L9:O9) -> 14 | L9: =+COUNTIFS($D$4:$D$488,J9,$F$4:$F$488,"sandy")+COUNTIFS($D$4:$D$488,J9,$F$4:$F$488,"Dry")+COUNTIFS($D$4:$D$488,J9,$F$4:$F$488,"DFR")+COUNTIFS($D$4:$D$488,J9,$F$4:$F$488,"WFR")+COUNTIFS($D$4:$D$488,J9,$F$4:$F$488,"SFR") -> 14 | M9: =+COUNTIFS($D$4:$D$488,J9,$F$4:$F$488,"WIP") -> 0 | N9: =+COUNTIFS($D$4:$D$488,J9,$F$4:$F$488,"Clear") -> 0 | O9: =+COUNTIFS($D$4:$D$488,J9,$F$4:$F$488,"ROW") -> 0 | P9: =+SUM(Q9:U9) -> 14 | Q9: =+COUNTIFS($D$4:$D$488,J9,$G$4:$G$488,"E") -> 9 | R9: =+COUNTIFS($D$4:$D$488,J9,$G$4:$G$488,"WIP") -> 0 | S9: =+COUNTIFS($D$4:$D$488,J9,$G$4:$G$488,"Clear") -> 0 | T9: =+COUNTIFS($D$4:$D$488,J9,$G$4:$G$488,"ROW") -> 0 | U9: =K9-T9-Q9-S9-R9 -> 5 | V9: =P9-Q9 -> 5
A10: =+SUBTOTAL(3,$B$4:B10) -> 7 | B10: ='Visual chart Edit'!B13 -> 1A/5 | C10: ='Visual chart Edit'!C13 -> DA+0 | D10: Mandai | E10: ='Visual chart Edit'!I13 -> 431.9 | F10: ='Visual chart Edit'!K13 -> DRY | G10: ='Visual chart Edit'!L13 -> E | J10: Bisoo Khurd | K10: =+SUM(L10:O10) -> 13 | L10: =+COUNTIFS($D$4:$D$488,J10,$F$4:$F$488,"sandy")+COUNTIFS($D$4:$D$488,J10,$F$4:$F$488,"Dry")+COUNTIFS($D$4:$D$488,J10,$F$4:$F$488,"DFR")+COUNTIFS($D$4:$D$488,J10,$F$4:$F$488,"WFR")+COUNTIFS($D$4:$D$488,J10,$F$4:$F$488,"SFR") -> 13 | M10: =+COUNTIFS($D$4:$D$488,J10,$F$4:$F$488,"WIP") -> 0 | N10: =+COUNTIFS($D$4:$D$488,J10,$F$4:$F$488,"Clear") -> 0 | O10: =+COUNTIFS($D$4:$D$488,J10,$F$4:$F$488,"ROW") -> 0 | P10: =+SUM(Q10:U10) -> 13 | Q10: =+COUNTIFS($D$4:$D$488,J10,$G$4:$G$488,"E") -> 7 | R10: =+COUNTIFS($D$4:$D$488,J10,$G$4:$G$488,"WIP") -> 0 | S10: =+COUNTIFS($D$4:$D$488,J10,$G$4:$G$488,"Clear") -> 6 | T10: =+COUNTIFS($D$4:$D$488,J10,$G$4:$G$488,"ROW") -> 0 | U10: =K10-T10-Q10-S10-R10 -> 0 | V10: =P10-Q10 -> 6
A11: =+SUBTOTAL(3,$B$4:B11) -> 8 | B11: ='Visual chart Edit'!B14 -> 1A/6 | C11: ='Visual chart Edit'!C14 -> DA+0 | D11: Mandai | E11: ='Visual chart Edit'!I14 -> 348.7 | F11: ='Visual chart Edit'!K14 -> Sandy | G11: ='Visual chart Edit'!L14 -> E | J11: Bhiyad | K11: =+SUM(L11:O11) -> 38 | L11: =+COUNTIFS($D$4:$D$488,J11,$F$4:$F$488,"sandy")+COUNTIFS($D$4:$D$488,J11,$F$4:$F$488,"Dry")+COUNTIFS($D$4:$D$488,J11,$F$4:$F$488,"DFR")+COUNTIFS($D$4:$D$488,J11,$F$4:$F$488,"WFR")+COUNTIFS($D$4:$D$488,J11,$F$4:$F$488,"SFR") -> 37 | M11: =+COUNTIFS($D$4:$D$488,J11,$F$4:$F$488,"WIP") -> 0 | N11: =+COUNTIFS($D$4:$D$488,J11,$F$4:$F$488,"Clear") -> 0 | O11: =+COUNTIFS($D$4:$D$488,J11,$F$4:$F$488,"ROW") -> 1 | P11: =+SUM(Q11:U11) -> 38 | Q11: =+COUNTIFS($D$4:$D$488,J11,$G$4:$G$488,"E") -> 28 | R11: =+COUNTIFS($D$4:$D$488,J11,$G$4:$G$488,"WIP") -> 0 | S11: =+COUNTIFS($D$4:$D$488,J11,$G$4:$G$488,"Clear") -> 0 | T11: =+COUNTIFS($D$4:$D$488,J11,$G$4:$G$488,"ROW") -> 9 | U11: =K11-T11-Q11-S11-R11 -> 1 | V11: =P11-Q11 -> 10
A12: =+SUBTOTAL(3,$B$4:B12) -> 9 | B12: ='Visual chart Edit'!B15 -> 1A/7 | C12: ='Visual chart Edit'!C15 -> DA+3 | D12: Mandai | E12: ='Visual chart Edit'!I15 -> 395.7 | F12: ='Visual chart Edit'!K15 -> Sandy | G12: ='Visual chart Edit'!L15 -> E | J12: Kashmir | K12: =+SUM(L12:O12) -> 29 | L12: =+COUNTIFS($D$4:$D$488,J12,$F$4:$F$488,"sandy")+COUNTIFS($D$4:$D$488,J12,$F$4:$F$488,"Dry")+COUNTIFS($D$4:$D$488,J12,$F$4:$F$488,"DFR")+COUNTIFS($D$4:$D$488,J12,$F$4:$F$488,"WFR")+COUNTIFS($D$4:$D$488,J12,$F$4:$F$488,"SFR") -> 27 | M12: =+COUNTIFS($D$4:$D$488,J12,$F$4:$F$488,"WIP") -> 1 | N12: =+COUNTIFS($D$4:$D$488,J12,$F$4:$F$488,"Clear") -> 0 | O12: =+COUNTIFS($D$4:$D$488,J12,$F$4:$F$488,"ROW") -> 1 | P12: =+SUM(Q12:U12) -> 29 | Q12: =+COUNTIFS($D$4:$D$488,J12,$G$4:$G$488,"E") -> 9 | R12: =+COUNTIFS($D$4:$D$488,J12,$G$4:$G$488,"WIP") -> 0 | S12: =+COUNTIFS($D$4:$D$488,J12,$G$4:$G$488,"Clear") -> 0 | T12: =+COUNTIFS($D$4:$D$488,J12,$G$4:$G$488,"ROW") -> 15 | U12: =K12-T12-Q12-S12-R12 -> 5 | V12: =P12-Q12 -> 20
A13: =+SUBTOTAL(3,$B$4:B13) -> 10 | B13: ='Visual chart Edit'!B16 -> 1A/8 | C13: ='Visual chart Edit'!C16 -> DA+0 | D13: Mandai | E13: ='Visual chart Edit'!I16 -> 415 | F13: ='Visual chart Edit'!K16 -> Sandy | G13: ='Visual chart Edit'!L16 -> E | J13: Rateu | K13: =+SUM(L13:O13) -> 35 | L13: =+COUNTIFS($D$4:$D$488,J13,$F$4:$F$488,"sandy")+COUNTIFS($D$4:$D$488,J13,$F$4:$F$488,"Dry")+COUNTIFS($D$4:$D$488,J13,$F$4:$F$488,"DFR")+COUNTIFS($D$4:$D$488,J13,$F$4:$F$488,"WFR")+COUNTIFS($D$4:$D$488,J13,$F$4:$F$488,"SFR") -> 34 | M13: =+COUNTIFS($D$4:$D$488,J13,$F$4:$F$488,"WIP") -> 1 | N13: =+COUNTIFS($D$4:$D$488,J13,$F$4:$F$488,"Clear") -> 0 | O13: =+COUNTIFS($D$4:$D$488,J13,$F$4:$F$488,"ROW") -> 0 | P13: =+SUM(Q13:U13) -> 35 | Q13: =+COUNTIFS($D$4:$D$488,J13,$G$4:$G$488,"E") -> 14 | R13: =+COUNTIFS($D$4:$D$488,J13,$G$4:$G$488,"WIP") -> 0 | S13: =+COUNTIFS($D$4:$D$488,J13,$G$4:$G$488,"Clear") -> 0 | T13: =+COUNTIFS($D$4:$D$488,J13,$G$4:$G$488,"ROW") -> 19 | U13: =K13-T13-Q13-S13-R13 -> 2 | V13: =P13-Q13 -> 21
A14: =+SUBTOTAL(3,$B$4:B14) -> 11 | B14: ='Visual chart Edit'!B17 -> 2/0 | C14: ='Visual chart Edit'!C17 -> DC1+0 | D14: Mandai | E14: ='Visual chart Edit'!I17 -> 394.3 | F14: ='Visual chart Edit'!K17 -> DRY | G14: ='Visual chart Edit'!L17 -> E | J14: Sawau Moolraj | K14: =+SUM(L14:O14) -> 23 | L14: =+COUNTIFS($D$4:$D$488,J14,$F$4:$F$488,"sandy")+COUNTIFS($D$4:$D$488,J14,$F$4:$F$488,"Dry")+COUNTIFS($D$4:$D$488,J14,$F$4:$F$488,"DFR")+COUNTIFS($D$4:$D$488,J14,$F$4:$F$488,"WFR")+COUNTIFS($D$4:$D$488,J14,$F$4:$F$488,"SFR") -> 23 | M14: =+COUNTIFS($D$4:$D$488,J14,$F$4:$F$488,"WIP") -> 0 | N14: =+COUNTIFS($D$4:$D$488,J14,$F$4:$F$488,"Clear") -> 0 | O14: =+COUNTIFS($D$4:$D$488,J14,$F$4:$F$488,"ROW") -> 0 | P14: =+SUM(Q14:U14) -> 23 | Q14: =+COUNTIFS($D$4:$D$488,J14,$G$4:$G$488,"E") -> 13 | R14: =+COUNTIFS($D$4:$D$488,J14,$G$4:$G$488,"WIP") -> 0 | S14: =+COUNTIFS($D$4:$D$488,J14,$G$4:$G$488,"Clear") -> 0 | T14: =+COUNTIFS($D$4:$D$488,J14,$G$4:$G$488,"ROW") -> 10 | U14: =K14-T14-Q14-S14-R14 -> 0 | V14: =P14-Q14 -> 10
A15: =+SUBTOTAL(3,$B$4:B15) -> 12 | B15: ='Visual chart Edit'!B18 -> 2/1 | C15: ='Visual chart Edit'!C18 -> DA+3 | D15: Mandai | E15: ='Visual chart Edit'!I18 -> 405.3 | F15: ='Visual chart Edit'!K18 -> Sandy | G15: ='Visual chart Edit'!L18 -> E | J15: Neemba Ki Dhani | K15: =+SUM(L15:O15) -> 23 | L15: =+COUNTIFS($D$4:$D$488,J15,$F$4:$F$488,"sandy")+COUNTIFS($D$4:$D$488,J15,$F$4:$F$488,"Dry")+COUNTIFS($D$4:$D$488,J15,$F$4:$F$488,"DFR")+COUNTIFS($D$4:$D$488,J15,$F$4:$F$488,"WFR")+COUNTIFS($D$4:$D$488,J15,$F$4:$F$488,"SFR") -> 23 | M15: =+COUNTIFS($D$4:$D$488,J15,$F$4:$F$488,"WIP") -> 0 | N15: =+COUNTIFS($D$4:$D$488,J15,$F$4:$F$488,"Clear") -> 0 | O15: =+COUNTIFS($D$4:$D$488,J15,$F$4:$F$488,"ROW") -> 0 | P15: =+SUM(Q15:U15) -> 23 | Q15: =+COUNTIFS($D$4:$D$488,J15,$G$4:$G$488,"E") -> 13 | R15: =+COUNTIFS($D$4:$D$488,J15,$G$4:$G$488,"WIP") -> 4 | S15: =+COUNTIFS($D$4:$D$488,J15,$G$4:$G$488,"Clear") -> 0 | T15: =+COUNTIFS($D$4:$D$488,J15,$G$4:$G$488,"ROW") -> 2 | U15: =K15-T15-Q15-S15-R15 -> 4 | V15: =P15-Q15 -> 10
A16: =+SUBTOTAL(3,$B$4:B16) -> 13 | B16: ='Visual chart Edit'!B19 -> 2/2 | C16: ='Visual chart Edit'!C19 -> DA+3 | D16: Mandai | E16: ='Visual chart Edit'!I19 -> 338.5 | F16: ='Visual chart Edit'!K19 -> Sandy | G16: ='Visual chart Edit'!L19 -> E | I16: 33 KV SHUTDOWN, GANG IDLING SINCE 11.09.2025. | J16: Danpura | K16: =+SUM(L16:O16) -> 13 | L16: =+COUNTIFS($D$4:$D$488,J16,$F$4:$F$488,"sandy")+COUNTIFS($D$4:$D$488,J16,$F$4:$F$488,"Dry")+COUNTIFS($D$4:$D$488,J16,$F$4:$F$488,"DFR")+COUNTIFS($D$4:$D$488,J16,$F$4:$F$488,"WFR")+COUNTIFS($D$4:$D$488,J16,$F$4:$F$488,"SFR") -> 13 | M16: =+COUNTIFS($D$4:$D$488,J16,$F$4:$F$488,"WIP") -> 0 | N16: =+COUNTIFS($D$4:$D$488,J16,$F$4:$F$488,"Clear") -> 0 | O16: =+COUNTIFS($D$4:$D$488,J16,$F$4:$F$488,"ROW") -> 0 | P16: =+SUM(Q16:U16) -> 13 | Q16: =+COUNTIFS($D$4:$D$488,J16,$G$4:$G$488,"E") -> 9 | R16: =+COUNTIFS($D$4:$D$488,J16,$G$4:$G$488,"WIP") -> 1 | S16: =+COUNTIFS($D$4:$D$488,J16,$G$4:$G$488,"Clear") -> 0 | T16: =+COUNTIFS($D$4:$D$488,J16,$G$4:$G$488,"ROW") -> 1 | U16: =K16-T16-Q16-S16-R16 -> 2 | V16: =P16-Q16 -> 4
A17: =+SUBTOTAL(3,$B$4:B17) -> 14 | B17: ='Visual chart Edit'!B20 -> 2/3 | C17: ='Visual chart Edit'!C20 -> DA+3 | D17: Mandai | E17: ='Visual chart Edit'!I20 -> 406 | F17: ='Visual chart Edit'!K20 -> Sandy | G17: ='Visual chart Edit'!L20 -> E | J17: Rampura Kharda | K17: =+SUM(L17:O17) -> 1 | L17: =+COUNTIFS($D$4:$D$488,J17,$F$4:$F$488,"sandy")+COUNTIFS($D$4:$D$488,J17,$F$4:$F$488,"Dry")+COUNTIFS($D$4:$D$488,J17,$F$4:$F$488,"DFR")+COUNTIFS($D$4:$D$488,J17,$F$4:$F$488,"WFR")+COUNTIFS($D$4:$D$488,J17,$F$4:$F$488,"SFR") -> 1 | M17: =+COUNTIFS($D$4:$D$488,J17,$F$4:$F$488,"WIP") -> 0 | N17: =+COUNTIFS($D$4:$D$488,J17,$F$4:$F$488,"Clear") -> 0 | O17: =+COUNTIFS($D$4:$D$488,J17,$F$4:$F$488,"ROW") -> 0 | P17: =+SUM(Q17:U17) -> 1 | Q17: =+COUNTIFS($D$4:$D$488,J17,$G$4:$G$488,"E") -> 1 | R17: =+COUNTIFS($D$4:$D$488,J17,$G$4:$G$488,"WIP") -> 0 | S17: =+COUNTIFS($D$4:$D$488,J17,$G$4:$G$488,"Clear") -> 0 | T17: =+COUNTIFS($D$4:$D$488,J17,$G$4:$G$488,"ROW") -> 0 | U17: =K17-T17-Q17-S17-R17 -> 0 | V17: =P17-Q17 -> 0
A18: =+SUBTOTAL(3,$B$4:B18) -> 15 | B18: ='Visual chart Edit'!B21 -> 2/4 | C18: ='Visual chart Edit'!C21 -> DA+3 | D18: Mandai | E18: ='Visual chart Edit'!I21 -> 429 | F18: ='Visual chart Edit'!K21 -> Sandy | G18: ='Visual chart Edit'!L21 -> E | J18: Manpura Kharda | K18: =+SUM(L18:O18) -> 2 | L18: =+COUNTIFS($D$4:$D$488,J18,$F$4:$F$488,"sandy")+COUNTIFS($D$4:$D$488,J18,$F$4:$F$488,"Dry")+COUNTIFS($D$4:$D$488,J18,$F$4:$F$488,"DFR")+COUNTIFS($D$4:$D$488,J18,$F$4:$F$488,"WFR")+COUNTIFS($D$4:$D$488,J18,$F$4:$F$488,"SFR") -> 2 | M18: =+COUNTIFS($D$4:$D$488,J18,$F$4:$F$488,"WIP") -> 0 | N18: =+COUNTIFS($D$4:$D$488,J18,$F$4:$F$488,"Clear") -> 0 | O18: =+COUNTIFS($D$4:$D$488,J18,$F$4:$F$488,"ROW") -> 0 | P18: =+SUM(Q18:U18) -> 2 | Q18: =+COUNTIFS($D$4:$D$488,J18,$G$4:$G$488,"E") -> 1 | R18: =+COUNTIFS($D$4:$D$488,J18,$G$4:$G$488,"WIP") -> 0 | S18: =+COUNTIFS($D$4:$D$488,J18,$G$4:$G$488,"Clear") -> 0 | T18: =+COUNTIFS($D$4:$D$488,J18,$G$4:$G$488,"ROW") -> 0 | U18: =K18-T18-Q18-S18-R18 -> 1 | V18: =P18-Q18 -> 1
A19: =+SUBTOTAL(3,$B$4:B19) -> 16 | B19: ='Visual chart Edit'!B22 -> 2/5 | C19: ='Visual chart Edit'!C22 -> DA+3 | D19: Mandai | E19: ='Visual chart Edit'!I22 -> 411.6 | F19: ='Visual chart Edit'!K22 -> Sandy | G19: ='Visual chart Edit'!L22 -> E | J19: Kharda Charnan | K19: =+SUM(L19:O19) -> 9 | L19: =+COUNTIFS($D$4:$D$488,J19,$F$4:$F$488,"sandy")+COUNTIFS($D$4:$D$488,J19,$F$4:$F$488,"Dry")+COUNTIFS($D$4:$D$488,J19,$F$4:$F$488,"DFR")+COUNTIFS($D$4:$D$488,J19,$F$4:$F$488,"WFR")+COUNTIFS($D$4:$D$488,J19,$F$4:$F$488,"SFR") -> 9 | M19: =+COUNTIFS($D$4:$D$488,J19,$F$4:$F$488,"WIP") -> 0 | N19: =+COUNTIFS($D$4:$D$488,J19,$F$4:$F$488,"Clear") -> 0 | O19: =+COUNTIFS($D$4:$D$488,J19,$F$4:$F$488,"ROW") -> 0 | P19: =+SUM(Q19:U19) -> 9 | Q19: =+COUNTIFS($D$4:$D$488,J19,$G$4:$G$488,"E") -> 3 | R19: =+COUNTIFS($D$4:$D$488,J19,$G$4:$G$488,"WIP") -> 2 | S19: =+COUNTIFS($D$4:$D$488,J19,$G$4:$G$488,"Clear") -> 0 | T19: =+COUNTIFS($D$4:$D$488,J19,$G$4:$G$488,"ROW") -> 0 | U19: =K19-T19-Q19-S19-R19 -> 4 | V19: =P19-Q19 -> 6
A20: =+SUBTOTAL(3,$B$4:B20) -> 17 | B20: ='Visual chart Edit'!B23 -> 2/6 | C20: ='Visual chart Edit'!C23 -> DA+3 | D20: Harwa | E20: ='Visual chart Edit'!I23 -> 425.7 | F20: ='Visual chart Edit'!K23 -> Sandy | G20: ='Visual chart Edit'!L23 -> E | J20: Beniwalon Ki Dhani | K20: =+SUM(L20:O20) -> 6 | L20: =+COUNTIFS($D$4:$D$488,J20,$F$4:$F$488,"sandy")+COUNTIFS($D$4:$D$488,J20,$F$4:$F$488,"Dry")+COUNTIFS($D$4:$D$488,J20,$F$4:$F$488,"DFR")+COUNTIFS($D$4:$D$488,J20,$F$4:$F$488,"WFR")+COUNTIFS($D$4:$D$488,J20,$F$4:$F$488,"SFR") -> 6 | M20: =+COUNTIFS($D$4:$D$488,J20,$F$4:$F$488,"WIP") -> 0 | N20: =+COUNTIFS($D$4:$D$488,J20,$F$4:$F$488,"Clear") -> 0 | O20: =+COUNTIFS($D$4:$D$488,J20,$F$4:$F$488,"ROW") -> 0 | P20: =+SUM(Q20:U20) -> 6 | Q20: =+COUNTIFS($D$4:$D$488,J20,$G$4:$G$488,"E") -> 4 | R20: =+COUNTIFS($D$4:$D$488,J20,$G$4:$G$488,"WIP") -> 0 | S20: =+COUNTIFS($D$4:$D$488,J20,$G$4:$G$488,"Clear") -> 0 | T20: =+COUNTIFS($D$4:$D$488,J20,$G$4:$G$488,"ROW") -> 0 | U20: =K20-T20-Q20-S20-R20 -> 2 | V20: =P20-Q20 -> 2
A21: =+SUBTOTAL(3,$B$4:B21) -> 18 | B21: ='Visual chart Edit'!B24 -> 2/7 | C21: ='Visual chart Edit'!C24 -> DA+3 | D21: Harwa | E21: ='Visual chart Edit'!I24 -> 408.2 | F21: ='Visual chart Edit'!K24 -> Sandy | G21: ='Visual chart Edit'!L24 -> E | J21: Pareu | K21: =+SUM(L21:O21) -> 4 | L21: =+COUNTIFS($D$4:$D$488,J21,$F$4:$F$488,"sandy")+COUNTIFS($D$4:$D$488,J21,$F$4:$F$488,"Dry")+COUNTIFS($D$4:$D$488,J21,$F$4:$F$488,"DFR")+COUNTIFS($D$4:$D$488,J21,$F$4:$F$488,"WFR")+COUNTIFS($D$4:$D$488,J21,$F$4:$F$488,"SFR") -> 4 | M21: =+COUNTIFS($D$4:$D$488,J21,$F$4:$F$488,"WIP") -> 0 | N21: =+COUNTIFS($D$4:$D$488,J21,$F$4:$F$488,"Clear") -> 0 | O21: =+COUNTIFS($D$4:$D$488,J21,$F$4:$F$488,"ROW") -> 0 | P21: =+SUM(Q21:U21) -> 4 | Q21: =+COUNTIFS($D$4:$D$488,J21,$G$4:$G$488,"E") -> 4 | R21: =+COUNTIFS($D$4:$D$488,J21,$G$4:$G$488,"WIP") -> 0 | S21: =+COUNTIFS($D$4:$D$488,J21,$G$4:$G$488,"Clear") -> 0 | T21: =+COUNTIFS($D$4:$D$488,J21,$G$4:$G$488,"ROW") -> 0 | U21: =K21-T21-Q21-S21-R21 -> 0 | V21: =P21-Q21 -> 0
A22: =+SUBTOTAL(3,$B$4:B22) -> 19 | B22: ='Visual chart Edit'!B25 -> 2/8 | C22: ='Visual chart Edit'!C25 -> DA+0 | D22: Harwa | E22: ='Visual chart Edit'!I25 -> 354.6 | F22: ='Visual chart Edit'!K25 -> Sandy | G22: ='Visual chart Edit'!L25 -> E | J22: Mahadeo Ka Mandir | K22: =+SUM(L22:O22) -> 7 | L22: =+COUNTIFS($D$4:$D$488,J22,$F$4:$F$488,"sandy")+COUNTIFS($D$4:$D$488,J22,$F$4:$F$488,"Dry")+COUNTIFS($D$4:$D$488,J22,$F$4:$F$488,"DFR")+COUNTIFS($D$4:$D$488,J22,$F$4:$F$488,"WFR")+COUNTIFS($D$4:$D$488,J22,$F$4:$F$488,"SFR") -> 7 | M22: =+COUNTIFS($D$4:$D$488,J22,$F$4:$F$488,"WIP") -> 0 | N22: =+COUNTIFS($D$4:$D$488,J22,$F$4:$F$488,"Clear") -> 0 | O22: =+COUNTIFS($D$4:$D$488,J22,$F$4:$F$488,"ROW") -> 0 | P22: =+SUM(Q22:U22) -> 7 | Q22: =+COUNTIFS($D$4:$D$488,J22,$G$4:$G$488,"E") -> 7 | R22: =+COUNTIFS($D$4:$D$488,J22,$G$4:$G$488,"WIP") -> 0 | S22: =+COUNTIFS($D$4:$D$488,J22,$G$4:$G$488,"Clear") -> 0 | T22: =+COUNTIFS($D$4:$D$488,J22,$G$4:$G$488,"ROW") -> 0 | U22: =K22-T22-Q22-S22-R22 -> 0 | V22: =P22-Q22 -> 0
A23: =+SUBTOTAL(3,$B$4:B23) -> 20 | B23: ='Visual chart Edit'!B26 -> 2/9 | C23: ='Visual chart Edit'!C26 -> DA+0 | D23: Harwa | E23: ='Visual chart Edit'!I26 -> 308.7 | F23: ='Visual chart Edit'!K26 -> DRY | G23: ='Visual chart Edit'!L26 -> E | J23: Chimoniyon Ki Dhani | K23: =+SUM(L23:O23) -> 8 | L23: =+COUNTIFS($D$4:$D$488,J23,$F$4:$F$488,"sandy")+COUNTIFS($D$4:$D$488,J23,$F$4:$F$488,"Dry")+COUNTIFS($D$4:$D$488,J23,$F$4:$F$488,"DFR")+COUNTIFS($D$4:$D$488,J23,$F$4:$F$488,"WFR")+COUNTIFS($D$4:$D$488,J23,$F$4:$F$488,"SFR") -> 8 | M23: =+COUNTIFS($D$4:$D$488,J23,$F$4:$F$488,"WIP") -> 0 | N23: =+COUNTIFS($D$4:$D$488,J23,$F$4:$F$488,"Clear") -> 0 | O23: =+COUNTIFS($D$4:$D$488,J23,$F$4:$F$488,"ROW") -> 0 | P23: =+SUM(Q23:U23) -> 8 | Q23: =+COUNTIFS($D$4:$D$488,J23,$G$4:$G$488,"E") -> 8 | R23: =+COUNTIFS($D$4:$D$488,J23,$G$4:$G$488,"WIP") -> 0 | S23: =+COUNTIFS($D$4:$D$488,J23,$G$4:$G$488,"Clear") -> 0 | T23: =+COUNTIFS($D$4:$D$488,J23,$G$4:$G$488,"ROW") -> 0 | U23: =K23-T23-Q23-S23-R23 -> 0 | V23: =P23-Q23 -> 0
A24: =+SUBTOTAL(3,$B$4:B24) -> 21 | B24: ='Visual chart Edit'!B27 -> 3/0 | C24: ='Visual chart Edit'!C27 -> DD60+6 | D24: Harwa | E24: ='Visual chart Edit'!I27 -> 336 | F24: ='Visual chart Edit'!K27 -> DRY | G24: WIP | J24: Godaron Ki Dhani | K24: =+SUM(L24:O24) -> 9 | L24: =+COUNTIFS($D$4:$D$488,J24,$F$4:$F$488,"sandy")+COUNTIFS($D$4:$D$488,J24,$F$4:$F$488,"Dry")+COUNTIFS($D$4:$D$488,J24,$F$4:$F$488,"DFR")+COUNTIFS($D$4:$D$488,J24,$F$4:$F$488,"WFR")+COUNTIFS($D$4:$D$488,J24,$F$4:$F$488,"SFR") -> 9 | M24: =+COUNTIFS($D$4:$D$488,J24,$F$4:$F$488,"WIP") -> 0 | N24: =+COUNTIFS($D$4:$D$488,J24,$F$4:$F$488,"Clear") -> 0 | O24: =+COUNTIFS($D$4:$D$488,J24,$F$4:$F$488,"ROW") -> 0 | P24: =+SUM(Q24:U24) -> 9 | Q24: =+COUNTIFS($D$4:$D$488,J24,$G$4:$G$488,"E") -> 9 | R24: =+COUNTIFS($D$4:$D$488,J24,$G$4:$G$488,"WIP") -> 0 | S24: =+COUNTIFS($D$4:$D$488,J24,$G$4:$G$488,"Clear") -> 0 | T24: =+COUNTIFS($D$4:$D$488,J24,$G$4:$G$488,"ROW") -> 0 | U24: =K24-T24-Q24-S24-R24 -> 0 | V24: =P24-Q24 -> 0
A25: =+SUBTOTAL(3,$B$4:B25) -> 22 | B25: ='Visual chart Edit'!B28 -> 4/0 | C25: ='Visual chart Edit'!C28 -> DD60+6 | D25: Harwa | E25: ='Visual chart Edit'!I28 -> 226.5 | F25: ='Visual chart Edit'!K28 -> DRY | G25: WIP | J25: Daukiyon Ki Dhani | K25: =+SUM(L25:O25) -> 4 | L25: =+COUNTIFS($D$4:$D$488,J25,$F$4:$F$488,"sandy")+COUNTIFS($D$4:$D$488,J25,$F$4:$F$488,"Dry")+COUNTIFS($D$4:$D$488,J25,$F$4:$F$488,"DFR")+COUNTIFS($D$4:$D$488,J25,$F$4:$F$488,"WFR")+COUNTIFS($D$4:$D$488,J25,$F$4:$F$488,"SFR") -> 4 | M25: =+COUNTIFS($D$4:$D$488,J25,$F$4:$F$488,"WIP") -> 0 | N25: =+COUNTIFS($D$4:$D$488,J25,$F$4:$F$488,"Clear") -> 0 | O25: =+COUNTIFS($D$4:$D$488,J25,$F$4:$F$488,"ROW") -> 0 | P25: =+SUM(Q25:U25) -> 4 | Q25: =+COUNTIFS($D$4:$D$488,J25,$G$4:$G$488,"E") -> 4 | R25: =+COUNTIFS($D$4:$D$488,J25,$G$4:$G$488,"WIP") -> 0 | S25: =+COUNTIFS($D$4:$D$488,J25,$G$4:$G$488,"Clear") -> 0 | T25: =+COUNTIFS($D$4:$D$488,J25,$G$4:$G$488,"ROW") -> 0 | U25: =K25-T25-Q25-S25-R25 -> 0 | V25: =P25-Q25 -> 0
A26: =+SUBTOTAL(3,$B$4:B26) -> 23 | B26: ='Visual chart Edit'!B29 -> 4/1 | C26: ='Visual chart Edit'!C29 -> DA+0 | D26: Harwa | E26: ='Visual chart Edit'!I29 -> 343 | F26: ='Visual chart Edit'!K29 -> DRY | G26: ='Visual chart Edit'!L29 -> E | J26: Nehru Nagar | K26: =+SUM(L26:O26) -> 6 | L26: =+COUNTIFS($D$4:$D$488,J26,$F$4:$F$488,"sandy")+COUNTIFS($D$4:$D$488,J26,$F$4:$F$488,"Dry")+COUNTIFS($D$4:$D$488,J26,$F$4:$F$488,"DFR")+COUNTIFS($D$4:$D$488,J26,$F$4:$F$488,"WFR")+COUNTIFS($D$4:$D$488,J26,$F$4:$F$488,"SFR") -> 6 | M26: =+COUNTIFS($D$4:$D$488,J26,$F$4:$F$488,"WIP") -> 0 | N26: =+COUNTIFS($D$4:$D$488,J26,$F$4:$F$488,"Clear") -> 0 | O26: =+COUNTIFS($D$4:$D$488,J26,$F$4:$F$488,"ROW") -> 0 | P26: =+SUM(Q26:U26) -> 6 | Q26: =+COUNTIFS($D$4:$D$488,J26,$G$4:$G$488,"E") -> 6 | R26: =+COUNTIFS($D$4:$D$488,J26,$G$4:$G$488,"WIP") -> 0 | S26: =+COUNTIFS($D$4:$D$488,J26,$G$4:$G$488,"Clear") -> 0 | T26: =+COUNTIFS($D$4:$D$488,J26,$G$4:$G$488,"ROW") -> 0 | U26: =K26-T26-Q26-S26-R26 -> 0 | V26: =P26-Q26 -> 0
A27: =+SUBTOTAL(3,$B$4:B27) -> 24 | B27: ='Visual chart Edit'!B30 -> 4/2 | C27: ='Visual chart Edit'!C30 -> DA+0 | D27: Harwa | E27: ='Visual chart Edit'!I30 -> 358.4 | F27: ='Visual chart Edit'!K30 -> DRY | G27: ='Visual chart Edit'!L30 -> E | J27: Nematpura | K27: =+SUM(L27:O27) -> 7 | L27: =+COUNTIFS($D$4:$D$488,J27,$F$4:$F$488,"sandy")+COUNTIFS($D$4:$D$488,J27,$F$4:$F$488,"Dry")+COUNTIFS($D$4:$D$488,J27,$F$4:$F$488,"DFR")+COUNTIFS($D$4:$D$488,J27,$F$4:$F$488,"WFR")+COUNTIFS($D$4:$D$488,J27,$F$4:$F$488,"SFR") -> 7 | M27: =+COUNTIFS($D$4:$D$488,J27,$F$4:$F$488,"WIP") -> 0 | N27: =+COUNTIFS($D$4:$D$488,J27,$F$4:$F$488,"Clear") -> 0 | O27: =+COUNTIFS($D$4:$D$488,J27,$F$4:$F$488,"ROW") -> 0 | P27: =+SUM(Q27:U27) -> 7 | Q27: =+COUNTIFS($D$4:$D$488,J27,$G$4:$G$488,"E") -> 7 | R27: =+COUNTIFS($D$4:$D$488,J27,$G$4:$G$488,"WIP") -> 0 | S27: =+COUNTIFS($D$4:$D$488,J27,$G$4:$G$488,"Clear") -> 0 | T27: =+COUNTIFS($D$4:$D$488,J27,$G$4:$G$488,"ROW") -> 0 | U27: =K27-T27-Q27-S27-R27 -> 0 | V27: =P27-Q27 -> 0
A28: =+SUBTOTAL(3,$B$4:B28) -> 25 | B28: ='Visual chart Edit'!B31 -> 4/3 | C28: ='Visual chart Edit'!C31 -> DA+0 | D28: Harwa | E28: ='Visual chart Edit'!I31 -> 381 | F28: ='Visual chart Edit'!K31 -> DRY | G28: ='Visual chart Edit'!L31 -> E | J28: Gangapura | K28: =+SUM(L28:O28) -> 4 | L28: =+COUNTIFS($D$4:$D$488,J28,$F$4:$F$488,"sandy")+COUNTIFS($D$4:$D$488,J28,$F$4:$F$488,"Dry")+COUNTIFS($D$4:$D$488,J28,$F$4:$F$488,"DFR")+COUNTIFS($D$4:$D$488,J28,$F$4:$F$488,"WFR")+COUNTIFS($D$4:$D$488,J28,$F$4:$F$488,"SFR") -> 4 | M28: =+COUNTIFS($D$4:$D$488,J28,$F$4:$F$488,"WIP") -> 0 | N28: =+COUNTIFS($D$4:$D$488,J28,$F$4:$F$488,"Clear") -> 0 | O28: =+COUNTIFS($D$4:$D$488,J28,$F$4:$F$488,"ROW") -> 0 | P28: =+SUM(Q28:U28) -> 4 | Q28: =+COUNTIFS($D$4:$D$488,J28,$G$4:$G$488,"E") -> 4 | R28: =+COUNTIFS($D$4:$D$488,J28,$G$4:$G$488,"WIP") -> 0 | S28: =+COUNTIFS($D$4:$D$488,J28,$G$4:$G$488,"Clear") -> 0 | T28: =+COUNTIFS($D$4:$D$488,J28,$G$4:$G$488,"ROW") -> 0 | U28: =K28-T28-Q28-S28-R28 -> 0 | V28: =P28-Q28 -> 0
A29: =+SUBTOTAL(3,$B$4:B29) -> 26 | B29: ='Visual chart Edit'!B32 -> 4/4 | C29: ='Visual chart Edit'!C32 -> DA+0 | D29: Harwa | E29: ='Visual chart Edit'!I32 -> 367.6 | F29: ='Visual chart Edit'!K32 -> DRY | G29: ='Visual chart Edit'!L32 -> E | J29: Barnama Charnan | K29: =+SUM(L29:O29) -> 7 | L29: =+COUNTIFS($D$4:$D$488,J29,$F$4:$F$488,"sandy")+COUNTIFS($D$4:$D$488,J29,$F$4:$F$488,"Dry")+COUNTIFS($D$4:$D$488,J29,$F$4:$F$488,"DFR")+COUNTIFS($D$4:$D$488,J29,$F$4:$F$488,"WFR")+COUNTIFS($D$4:$D$488,J29,$F$4:$F$488,"SFR") -> 7 | M29: =+COUNTIFS($D$4:$D$488,J29,$F$4:$F$488,"WIP") -> 0 | N29: =+COUNTIFS($D$4:$D$488,J29,$F$4:$F$488,"Clear") -> 0 | O29: =+COUNTIFS($D$4:$D$488,J29,$F$4:$F$488,"ROW") -> 0 | P29: =+SUM(Q29:U29) -> 7 | Q29: =+COUNTIFS($D$4:$D$488,J29,$G$4:$G$488,"E") -> 7 | R29: =+COUNTIFS($D$4:$D$488,J29,$G$4:$G$488,"WIP") -> 0 | S29: =+COUNTIFS($D$4:$D$488,J29,$G$4:$G$488,"Clear") -> 0 | T29: =+COUNTIFS($D$4:$D$488,J29,$G$4:$G$488,"ROW") -> 0 | U29: =K29-T29-Q29-S29-R29 -> 0 | V29: =P29-Q29 -> 0
A30: =+SUBTOTAL(3,$B$4:B30) -> 27 | B30: ='Visual chart Edit'!B33 -> 5/0 | C30: ='Visual chart Edit'!C33 -> DB1+9 | D30: Harwa | E30: ='Visual chart Edit'!I33 -> 423.1 | F30: ='Visual chart Edit'!K33 -> DRY | G30: WIP | J30: Khanora | K30: =+SUM(L30:O30) -> 13 | L30: =+COUNTIFS($D$4:$D$488,J30,$F$4:$F$488,"sandy")+COUNTIFS($D$4:$D$488,J30,$F$4:$F$488,"Dry")+COUNTIFS($D$4:$D$488,J30,$F$4:$F$488,"DFR")+COUNTIFS($D$4:$D$488,J30,$F$4:$F$488,"WFR")+COUNTIFS($D$4:$D$488,J30,$F$4:$F$488,"SFR") -> 13 | M30: =+COUNTIFS($D$4:$D$488,J30,$F$4:$F$488,"WIP") -> 0 | N30: =+COUNTIFS($D$4:$D$488,J30,$F$4:$F$488,"Clear") -> 0 | O30: =+COUNTIFS($D$4:$D$488,J30,$F$4:$F$488,"ROW") -> 0 | P30: =+SUM(Q30:U30) -> 13 | Q30: =+COUNTIFS($D$4:$D$488,J30,$G$4:$G$488,"E") -> 13 | R30: =+COUNTIFS($D$4:$D$488,J30,$G$4:$G$488,"WIP") -> 0 | S30: =+COUNTIFS($D$4:$D$488,J30,$G$4:$G$488,"Clear") -> 0 | T30: =+COUNTIFS($D$4:$D$488,J30,$G$4:$G$488,"ROW") -> 0 | U30: =K30-T30-Q30-S30-R30 -> 0 | V30: =P30-Q30 -> 0
A31: =+SUBTOTAL(3,$B$4:B31) -> 28 | B31: ='Visual chart Edit'!B34 -> 6/0 | C31: ='Visual chart Edit'!C34 -> DB2+9 | D31: Harwa | E31: ='Visual chart Edit'!I34 -> 246 | F31: ='Visual chart Edit'!K34 -> DRY | G31: Clear | I31: attempeted on 10.07.2025 | J31: Sathuni Purohitan | K31: =+SUM(L31:O31) -> 3 | L31: =+COUNTIFS($D$4:$D$488,J31,$F$4:$F$488,"sandy")+COUNTIFS($D$4:$D$488,J31,$F$4:$F$488,"Dry")+COUNTIFS($D$4:$D$488,J31,$F$4:$F$488,"DFR")+COUNTIFS($D$4:$D$488,J31,$F$4:$F$488,"WFR")+COUNTIFS($D$4:$D$488,J31,$F$4:$F$488,"SFR") -> 3 | M31: =+COUNTIFS($D$4:$D$488,J31,$F$4:$F$488,"WIP") -> 0 | N31: =+COUNTIFS($D$4:$D$488,J31,$F$4:$F$488,"Clear") -> 0 | O31: =+COUNTIFS($D$4:$D$488,J31,$F$4:$F$488,"ROW") -> 0 | P31: =+SUM(Q31:U31) -> 3 | Q31: =+COUNTIFS($D$4:$D$488,J31,$G$4:$G$488,"E") -> 3 | R31: =+COUNTIFS($D$4:$D$488,J31,$G$4:$G$488,"WIP") -> 0 | S31: =+COUNTIFS($D$4:$D$488,J31,$G$4:$G$488,"Clear") -> 0 | T31: =+COUNTIFS($D$4:$D$488,J31,$G$4:$G$488,"ROW") -> 0 | U31: =K31-T31-Q31-S31-R31 -> 0 | V31: =P31-Q31 -> 0
A32: =+SUBTOTAL(3,$B$4:B32) -> 29 | B32: ='Visual chart Edit'!B35 -> 6/1 | C32: ='Visual chart Edit'!C35 -> DA+0 | D32: Harwa | E32: ='Visual chart Edit'!I35 -> 429.9 | F32: ='Visual chart Edit'!K35 -> DFR | G32: ='Visual chart Edit'!L35 -> E | J32: Sathuni Charnan | K32: =+SUM(L32:O32) -> 8 | L32: =+COUNTIFS($D$4:$D$488,J32,$F$4:$F$488,"sandy")+COUNTIFS($D$4:$D$488,J32,$F$4:$F$488,"Dry")+COUNTIFS($D$4:$D$488,J32,$F$4:$F$488,"DFR")+COUNTIFS($D$4:$D$488,J32,$F$4:$F$488,"WFR")+COUNTIFS($D$4:$D$488,J32,$F$4:$F$488,"SFR") -> 8 | M32: =+COUNTIFS($D$4:$D$488,J32,$F$4:$F$488,"WIP") -> 0 | N32: =+COUNTIFS($D$4:$D$488,J32,$F$4:$F$488,"Clear") -> 0 | O32: =+COUNTIFS($D$4:$D$488,J32,$F$4:$F$488,"ROW") -> 0 | P32: =+SUM(Q32:U32) -> 8 | Q32: =+COUNTIFS($D$4:$D$488,J32,$G$4:$G$488,"E") -> 8 | R32: =+COUNTIFS($D$4:$D$488,J32,$G$4:$G$488,"WIP") -> 0 | S32: =+COUNTIFS($D$4:$D$488,J32,$G$4:$G$488,"Clear") -> 0 | T32: =+COUNTIFS($D$4:$D$488,J32,$G$4:$G$488,"ROW") -> 0 | U32: =K32-T32-Q32-S32-R32 -> 0 | V32: =P32-Q32 -> 0
A33: =+SUBTOTAL(3,$B$4:B33) -> 30 | B33: ='Visual chart Edit'!B36 -> 6/2 | C33: ='Visual chart Edit'!C36 -> DA+0 | D33: Harwa | E33: ='Visual chart Edit'!I36 -> 362.4 | F33: ='Visual chart Edit'!K36 -> DFR | G33: ='Visual chart Edit'!L36 -> E | J33: Simarkhiya | K33: =+SUM(L33:O33) -> 3 | L33: =+COUNTIFS($D$4:$D$488,J33,$F$4:$F$488,"sandy")+COUNTIFS($D$4:$D$488,J33,$F$4:$F$488,"Dry")+COUNTIFS($D$4:$D$488,J33,$F$4:$F$488,"DFR")+COUNTIFS($D$4:$D$488,J33,$F$4:$F$488,"WFR")+COUNTIFS($D$4:$D$488,J33,$F$4:$F$488,"SFR") -> 3 | M33: =+COUNTIFS($D$4:$D$488,J33,$F$4:$F$488,"WIP") -> 0 | N33: =+COUNTIFS($D$4:$D$488,J33,$F$4:$F$488,"Clear") -> 0 | O33: =+COUNTIFS($D$4:$D$488,J33,$F$4:$F$488,"ROW") -> 0 | P33: =+SUM(Q33:U33) -> 3 | Q33: =+COUNTIFS($D$4:$D$488,J33,$G$4:$G$488,"E") -> 3 | R33: =+COUNTIFS($D$4:$D$488,J33,$G$4:$G$488,"WIP") -> 0 | S33: =+COUNTIFS($D$4:$D$488,J33,$G$4:$G$488,"Clear") -> 0 | T33: =+COUNTIFS($D$4:$D$488,J33,$G$4:$G$488,"ROW") -> 0 | U33: =K33-T33-Q33-S33-R33 -> 0 | V33: =P33-Q33 -> 0
A34: =+SUBTOTAL(3,$B$4:B34) -> 31 | B34: ='Visual chart Edit'!B37 -> 7/0 | C34: ='Visual chart Edit'!C37 -> DB1+0 | D34: Harwa | E34: ='Visual chart Edit'!I37 -> 347.9 | F34: ='Visual chart Edit'!K37 -> DRY | G34: Clear | J34: Bagawas | K34: =+SUM(L34:O34) -> 11 | L34: =+COUNTIFS($D$4:$D$488,J34,$F$4:$F$488,"sandy")+COUNTIFS($D$4:$D$488,J34,$F$4:$F$488,"Dry")+COUNTIFS($D$4:$D$488,J34,$F$4:$F$488,"DFR")+COUNTIFS($D$4:$D$488,J34,$F$4:$F$488,"WFR")+COUNTIFS($D$4:$D$488,J34,$F$4:$F$488,"SFR") -> 11 | M34: =+COUNTIFS($D$4:$D$488,J34,$F$4:$F$488,"WIP") -> 0 | N34: =+COUNTIFS($D$4:$D$488,J34,$F$4:$F$488,"Clear") -> 0 | O34: =+COUNTIFS($D$4:$D$488,J34,$F$4:$F$488,"ROW") -> 0 | P34: =+SUM(Q34:U34) -> 11 | Q34: =+COUNTIFS($D$4:$D$488,J34,$G$4:$G$488,"E") -> 11 | R34: =+COUNTIFS($D$4:$D$488,J34,$G$4:$G$488,"WIP") -> 0 | S34: =+COUNTIFS($D$4:$D$488,J34,$G$4:$G$488,"Clear") -> 0 | T34: =+COUNTIFS($D$4:$D$488,J34,$G$4:$G$488,"ROW") -> 0 | U34: =K34-T34-Q34-S34-R34 -> 0 | V34: =P34-Q34 -> 0
A35: =+SUBTOTAL(3,$B$4:B35) -> 32 | B35: ='Visual chart Edit'!B38 -> 8/0 | C35: ='Visual chart Edit'!C38 -> DB1+0 | D35: Harwa | E35: ='Visual chart Edit'!I38 -> 210.8 | F35: ='Visual chart Edit'!K38 -> DRY | G35: Clear | J35: Mohanpura | K35: =+SUM(L35:O35) -> 6 | L35: =+COUNTIFS($D$4:$D$488,J35,$F$4:$F$488,"sandy")+COUNTIFS($D$4:$D$488,J35,$F$4:$F$488,"Dry")+COUNTIFS($D$4:$D$488,J35,$F$4:$F$488,"DFR")+COUNTIFS($D$4:$D$488,J35,$F$4:$F$488,"WFR")+COUNTIFS($D$4:$D$488,J35,$F$4:$F$488,"SFR") -> 6 | M35: =+COUNTIFS($D$4:$D$488,J35,$F$4:$F$488,"WIP") -> 0 | N35: =+COUNTIFS($D$4:$D$488,J35,$F$4:$F$488,"Clear") -> 0 | O35: =+COUNTIFS($D$4:$D$488,J35,$F$4:$F$488,"ROW") -> 0 | P35: =+SUM(Q35:U35) -> 6 | Q35: =+COUNTIFS($D$4:$D$488,J35,$G$4:$G$488,"E") -> 6 | R35: =+COUNTIFS($D$4:$D$488,J35,$G$4:$G$488,"WIP") -> 0 | S35: =+COUNTIFS($D$4:$D$488,J35,$G$4:$G$488,"Clear") -> 0 | T35: =+COUNTIFS($D$4:$D$488,J35,$G$4:$G$488,"ROW") -> 0 | U35: =K35-T35-Q35-S35-R35 -> 0 | V35: =P35-Q35 -> 0
A36: =+SUBTOTAL(3,$B$4:B36) -> 33 | B36: ='Visual chart Edit'!B39 -> 8/1 | C36: ='Visual chart Edit'!C39 -> DA+3 | D36: Harwa | E36: ='Visual chart Edit'!I39 -> 409.2 | F36: ='Visual chart Edit'!K39 -> DRY | G36: ='Visual chart Edit'!L39 -> E | J36: Meghawas | K36: =+SUM(L36:O36) -> 5 | L36: =+COUNTIFS($D$4:$D$488,J36,$F$4:$F$488,"sandy")+COUNTIFS($D$4:$D$488,J36,$F$4:$F$488,"Dry")+COUNTIFS($D$4:$D$488,J36,$F$4:$F$488,"DFR")+COUNTIFS($D$4:$D$488,J36,$F$4:$F$488,"WFR")+COUNTIFS($D$4:$D$488,J36,$F$4:$F$488,"SFR") -> 5 | M36: =+COUNTIFS($D$4:$D$488,J36,$F$4:$F$488,"WIP") -> 0 | N36: =+COUNTIFS($D$4:$D$488,J36,$F$4:$F$488,"Clear") -> 0 | O36: =+COUNTIFS($D$4:$D$488,J36,$F$4:$F$488,"ROW") -> 0 | P36: =+SUM(Q36:U36) -> 5 | Q36: =+COUNTIFS($D$4:$D$488,J36,$G$4:$G$488,"E") -> 5 | R36: =+COUNTIFS($D$4:$D$488,J36,$G$4:$G$488,"WIP") -> 0 | S36: =+COUNTIFS($D$4:$D$488,J36,$G$4:$G$488,"Clear") -> 0 | T36: =+COUNTIFS($D$4:$D$488,J36,$G$4:$G$488,"ROW") -> 0 | U36: =K36-T36-Q36-S36-R36 -> 0 | V36: =P36-Q36 -> 0
A37: =+SUBTOTAL(3,$B$4:B37) -> 34 | B37: ='Visual chart Edit'!B40 -> 8/2 | C37: ='Visual chart Edit'!C40 -> DA+3 | D37: Harwa | E37: ='Visual chart Edit'!I40 -> 413.6 | F37: ='Visual chart Edit'!K40 -> DRY | G37: ='Visual chart Edit'!L40 -> E | J37: Sagaranari | K37: =+SUM(L37:O37) -> 10 | L37: =+COUNTIFS($D$4:$D$488,J37,$F$4:$F$488,"sandy")+COUNTIFS($D$4:$D$488,J37,$F$4:$F$488,"Dry")+COUNTIFS($D$4:$D$488,J37,$F$4:$F$488,"DFR")+COUNTIFS($D$4:$D$488,J37,$F$4:$F$488,"WFR")+COUNTIFS($D$4:$D$488,J37,$F$4:$F$488,"SFR") -> 10 | M37: =+COUNTIFS($D$4:$D$488,J37,$F$4:$F$488,"WIP") -> 0 | N37: =+COUNTIFS($D$4:$D$488,J37,$F$4:$F$488,"Clear") -> 0 | O37: =+COUNTIFS($D$4:$D$488,J37,$F$4:$F$488,"ROW") -> 0 | P37: =+SUM(Q37:U37) -> 10 | Q37: =+COUNTIFS($D$4:$D$488,J37,$G$4:$G$488,"E") -> 10 | R37: =+COUNTIFS($D$4:$D$488,J37,$G$4:$G$488,"WIP") -> 0 | S37: =+COUNTIFS($D$4:$D$488,J37,$G$4:$G$488,"Clear") -> 0 | T37: =+COUNTIFS($D$4:$D$488,J37,$G$4:$G$488,"ROW") -> 0 | U37: =K37-T37-Q37-S37-R37 -> 0 | V37: =P37-Q37 -> 0
A38: =+SUBTOTAL(3,$B$4:B38) -> 35 | B38: ='Visual chart Edit'!B41 -> 8/3 | C38: ='Visual chart Edit'!C41 -> DA+0 | D38: Harwa | E38: ='Visual chart Edit'!I41 -> 393.2 | F38: ='Visual chart Edit'!K41 -> DRY | G38: ='Visual chart Edit'!L41 | J38: Nagana | K38: =+SUM(L38:O38) -> 6 | L38: =+COUNTIFS($D$4:$D$488,J38,$F$4:$F$488,"sandy")+COUNTIFS($D$4:$D$488,J38,$F$4:$F$488,"Dry")+COUNTIFS($D$4:$D$488,J38,$F$4:$F$488,"DFR")+COUNTIFS($D$4:$D$488,J38,$F$4:$F$488,"WFR")+COUNTIFS($D$4:$D$488,J38,$F$4:$F$488,"SFR") -> 6 | M38: =+COUNTIFS($D$4:$D$488,J38,$F$4:$F$488,"WIP") -> 0 | N38: =+COUNTIFS($D$4:$D$488,J38,$F$4:$F$488,"Clear") -> 0 | O38: =+COUNTIFS($D$4:$D$488,J38,$F$4:$F$488,"ROW") -> 0 | P38: =+SUM(Q38:U38) -> 6 | Q38: =+COUNTIFS($D$4:$D$488,J38,$G$4:$G$488,"E") -> 6 | R38: =+COUNTIFS($D$4:$D$488,J38,$G$4:$G$488,"WIP") -> 0 | S38: =+COUNTIFS($D$4:$D$488,J38,$G$4:$G$488,"Clear") -> 0 | T38: =+COUNTIFS($D$4:$D$488,J38,$G$4:$G$488,"ROW") -> 0 | U38: =K38-T38-Q38-S38-R38 -> 0 | V38: =P38-Q38 -> 0
A39: =+SUBTOTAL(3,$B$4:B39) -> 36 | B39: ='Visual chart Edit'!B42 -> 8/4 | C39: ='Visual chart Edit'!C42 -> DA+3 | D39: Harwa | E39: ='Visual chart Edit'!I42 -> 416.5 | F39: ='Visual chart Edit'!K42 -> DRY | G39: ='Visual chart Edit'!L42 -> E | J39: Deoriya | K39: =+SUM(L39:O39) -> 9 | L39: =+COUNTIFS($D$4:$D$488,J39,$F$4:$F$488,"sandy")+COUNTIFS($D$4:$D$488,J39,$F$4:$F$488,"Dry")+COUNTIFS($D$4:$D$488,J39,$F$4:$F$488,"DFR")+COUNTIFS($D$4:$D$488,J39,$F$4:$F$488,"WFR")+COUNTIFS($D$4:$D$488,J39,$F$4:$F$488,"SFR") -> 9 | M39: =+COUNTIFS($D$4:$D$488,J39,$F$4:$F$488,"WIP") -> 0 | N39: =+COUNTIFS($D$4:$D$488,J39,$F$4:$F$488,"Clear") -> 0 | O39: =+COUNTIFS($D$4:$D$488,J39,$F$4:$F$488,"ROW") -> 0 | P39: =+SUM(Q39:U39) -> 9 | Q39: =+COUNTIFS($D$4:$D$488,J39,$G$4:$G$488,"E") -> 9 | R39: =+COUNTIFS($D$4:$D$488,J39,$G$4:$G$488,"WIP") -> 0 | S39: =+COUNTIFS($D$4:$D$488,J39,$G$4:$G$488,"Clear") -> 0 | T39: =+COUNTIFS($D$4:$D$488,J39,$G$4:$G$488,"ROW") -> 0 | U39: =K39-T39-Q39-S39-R39 -> 0 | V39: =P39-Q39 -> 0
A40: =+SUBTOTAL(3,$B$4:B40) -> 37 | B40: ='Visual chart Edit'!B43 -> 8/5 | C40: ='Visual chart Edit'!C43 -> DA+3 | D40: Harwa | E40: ='Visual chart Edit'!I43 -> 394.6 | F40: ='Visual chart Edit'!K43 -> DRY | G40: ='Visual chart Edit'!L43 -> E | J40: Bakati | K40: =+SUM(L40:O40) -> 9 | L40: =+COUNTIFS($D$4:$D$488,J40,$F$4:$F$488,"sandy")+COUNTIFS($D$4:$D$488,J40,$F$4:$F$488,"Dry")+COUNTIFS($D$4:$D$488,J40,$F$4:$F$488,"DFR")+COUNTIFS($D$4:$D$488,J40,$F$4:$F$488,"WFR")+COUNTIFS($D$4:$D$488,J40,$F$4:$F$488,"SFR") -> 9 | M40: =+COUNTIFS($D$4:$D$488,J40,$F$4:$F$488,"WIP") -> 0 | N40: =+COUNTIFS($D$4:$D$488,J40,$F$4:$F$488,"Clear") -> 0 | O40: =+COUNTIFS($D$4:$D$488,J40,$F$4:$F$488,"ROW") -> 0 | P40: =+SUM(Q40:U40) -> 9 | Q40: =+COUNTIFS($D$4:$D$488,J40,$G$4:$G$488,"E") -> 9 | R40: =+COUNTIFS($D$4:$D$488,J40,$G$4:$G$488,"WIP") -> 0 | S40: =+COUNTIFS($D$4:$D$488,J40,$G$4:$G$488,"Clear") -> 0 | T40: =+COUNTIFS($D$4:$D$488,J40,$G$4:$G$488,"ROW") -> 0 | U40: =K40-T40-Q40-S40-R40 -> 0 | V40: =P40-Q40 -> 0
...

Sheet Survey
A1: Progress Summary'!A1 | B1: KEC International Limited
B3: Survey status at TB-408
A4: Section | B4: Sl. No | C4: Section | E4: Section Length (in Mtrs) | F4: Detail Survey received Date | G4: Check Survey | M4: Total | N4: Susp. | O4: Tens.
C5: From | D5: To | G5: Status | H5: Date of Submission | I5: Further Modification date | J5: Approved Date | K5: Remarks | L5: Remarks
