Workbook
Name \0: #REF!
Name \0: #REF!
Name \0: #REF!
Name \0: #REF!
Name \0: #REF!
Name \0: #REF!
Name \0: #REF!
Name \0: #REF!
Name \A: #REF!
Name \A: #REF!
Name \A: #REF!
Name \A: #REF!
Name \A: #REF!
Name \A: #REF!
Name \A: #REF!
Name \A: #REF!
Name \B: #REF!
Name \B: #REF!
Name \B: #REF!
Name \B: #REF!
Name \B: #REF!
Name \B: #REF!
Name \B: #REF!
Name \B: #REF!
Name \C: #REF!
Name \C: #REF!
Name \C: #REF!
Name \C: #REF!
Name \C: #REF!
Name \C: #REF!
Name \C: #REF!
Name \C: #REF!
Name \i: #REF!
Name \i: #REF!
Name \i: #REF!
Name \i: #REF!
Name \i: #REF!
Name \i: #REF!
Name \i: #REF!
Name \i: #REF!
Name \M: #REF!
Name \M: #REF!
Name \M: #REF!
Name \M: #REF!
Name \M: #REF!
Name \M: #REF!
Name \M: #REF!
Name \M: #REF!
Name \N: #REF!
Name \N: #REF!
Name \N: #REF!
Name \N: #REF!
Name \N: #REF!
Name \N: #REF!
Name \N: #REF!
Name \N: #REF!
Name \P: #REF!
Name \P: #REF!
Name \P: #REF!
Name \P: #REF!

Sheet TB-412 SUMMARY
A1: Daily Progress Report Summary
L2: ='Summary-'!M3:M3 -> Date-09/07/2026
B3: Contractual Start Date | C3: 45287 | D3: Project | E3: TB-412 TL
B4: Contractual Finish Date | C4: 45831 | D4: Client | E4: Bihar State Power Transmission corporation Limited
B5: TOE | C5: 46081 | D5: NOA Supply: | E5: 18. Dated - | F5: 27/12/2023
D6: NOA Service: | E6: 19. Dated - | F6: 45287
A7: TB-412 Chhapra- TL
A8: Sr no. | B8: Activity | C8: Total Quantity | E8: Cumm. Progress up to Last Month (June'26) | F8: Target as per L2 Schedule Cummulative (upto July'26) | G8: Target of Month for (July'2026) | H8: Comp This Month (July'2026) | I8: Cumulative Progress | J8: WIP | K8: Balance | L8: No of Gangs | M8: Remark
C9: LOA | D9: Estimated
A10: 1 | B10: Route Alignment (Km) | C10: ='Summary-'!C11+'Summary-'!C28+'Summary-'!C47 -> 165 | D10: ='Summary-'!D11+'Summary-'!D28+'Summary-'!D47 -> 150.833 | E10: ='Summary-'!E11+'Summary-'!E28+'Summary-'!E47 -> 150.833 | F10: ='Summary-'!F11+'Summary-'!F28+'Summary-'!F47 -> 150.833 | G10: ='Summary-'!G11+'Summary-'!G28+'Summary-'!G47 -> 0 | H10: ='Summary-'!H11+'Summary-'!H28+'Summary-'!H47 -> 0 | I10: ='Summary-'!I11+'Summary-'!I28+'Summary-'!I47 -> 150.833 | J10: ='Summary-'!J11+'Summary-'!J28+'Summary-'!J47 -> 0 | K10: =D10-I10-J10 -> 0 | L10: ='Summary-'!L11+'Summary-'!L28+'Summary-'!L47 -> 0 | M10: Completed
A11: 2 | B11: Detailed Survey (Km) | C11: ='Summary-'!C12+'Summary-'!C29+'Summary-'!C48 -> 165 | D11: ='Summary-'!D12+'Summary-'!D29+'Summary-'!D48 -> 150.833 | E11: ='Summary-'!E12+'Summary-'!E29+'Summary-'!E48 -> 149.147 | F11: ='Summary-'!F12+'Summary-'!F29+'Summary-'!F48 -> 150.833 | G11: ='Summary-'!G12+'Summary-'!G29+'Summary-'!G48 -> 1.686 | H11: ='Summary-'!H12+'Summary-'!H29+'Summary-'!H48 -> 0 | I11: ='Summary-'!I12+'Summary-'!I29+'Summary-'!I48 -> 149.147 | J11: ='Summary-'!J12+'Summary-'!J29+'Summary-'!J48 -> 0 | K11: =D11-I11-J11 -> 1.686 | L11: ='Summary-'!L12+'Summary-'!L29+'Summary-'!L48 -> 0
A12: 3 | B12: Detailed Survey Profiling (Km) | C12: ='Summary-'!C13+'Summary-'!C30+'Summary-'!C49 -> 165 | D12: ='Summary-'!D13+'Summary-'!D30+'Summary-'!D49 -> 150.833 | E12: ='Summary-'!E13+'Summary-'!E30+'Summary-'!E49 -> 147.499 | F12: ='Summary-'!F13+'Summary-'!F30+'Summary-'!F49 -> 150.833 | G12: ='Summary-'!G13+'Summary-'!G30+'Summary-'!G49 -> 3.334 | H12: ='Summary-'!H13+'Summary-'!H30+'Summary-'!H49 -> 0 | I12: ='Summary-'!I13+'Summary-'!I30+'Summary-'!I49 -> 147.499 | J12: ='Summary-'!J13+'Summary-'!J30+'Summary-'!J49 -> 0 | K12: =D12-I12-J12 -> 3.334 | L12: ='Summary-'!L13+'Summary-'!L30+'Summary-'!L49 -> 0
A13: 4 | B13: Approved detail survey (Km) | C13: ='Summary-'!C14+'Summary-'!C31+'Summary-'!C50 -> 165 | D13: ='Summary-'!D14+'Summary-'!D31+'Summary-'!D50 -> 150.833 | E13: ='Summary-'!E14+'Summary-'!E31+'Summary-'!E50 -> 143.334 | F13: ='Summary-'!F14+'Summary-'!F31+'Summary-'!F50 -> 150.833 | G13: ='Summary-'!G14+'Summary-'!G31+'Summary-'!G50 -> 7.499 | H13: ='Summary-'!H14+'Summary-'!H31+'Summary-'!H50 -> 0 | I13: ='Summary-'!I14+'Summary-'!I31+'Summary-'!I50 -> 143.334 | J13: ='Summary-'!J14+'Summary-'!J31+'Summary-'!J50 -> 0 | K13: =D13-I13-J13 -> 7.499 | L13: ='Summary-'!L14+'Summary-'!L31+'Summary-'!L50 -> 0
A14: 5 | B14: Check Survey (Km) | C14: ='Summary-'!C15+'Summary-'!C32+'Summary-'!C51 -> 165 | D14: ='Summary-'!D15+'Summary-'!D32+'Summary-'!D51 -> 150.833 | E14: ='Summary-'!E15+'Summary-'!E32+'Summary-'!E51 -> 137.191 | F14: ='Summary-'!F15+'Summary-'!F32+'Summary-'!F51 -> 150.833 | G14: ='Summary-'!G15+'Summary-'!G32+'Summary-'!G51 -> 13.642 | H14: ='Summary-'!H15+'Summary-'!H32+'Summary-'!H51 -> 0 | I14: ='Summary-'!I15+'Summary-'!I32+'Summary-'!I51 -> 137.191 | J14: ='Summary-'!J15+'Summary-'!J32+'Summary-'!J51 -> 0 | K14: =D14-I14-J14 -> 13.642 | L14: ='Summary-'!L15+'Summary-'!L32+'Summary-'!L51 -> 0 | M14: U/P
A15: 6 | B15: Approved check survey ( Km) | C15: ='Summary-'!C16+'Summary-'!C33+'Summary-'!C52 -> 165 | D15: ='Summary-'!D16+'Summary-'!D33+'Summary-'!D52 -> 150.833 | E15: ='Summary-'!E16+'Summary-'!E33+'Summary-'!E52 -> 119.607 | F15: ='Summary-'!F16+'Summary-'!F33+'Summary-'!F52 -> 150.833 | G15: ='Summary-'!G16+'Summary-'!G33+'Summary-'!G52 -> 31.226 | H15: ='Summary-'!H16+'Summary-'!H33+'Summary-'!H52 -> 0 | I15: ='Summary-'!I16+'Summary-'!I33+'Summary-'!I52 -> 119.607 | J15: ='Summary-'!J16+'Summary-'!J33+'Summary-'!J52 -> 0 | K15: =D15-I15-J15 -> 31.226 | L15: ='Summary-'!L16+'Summary-'!L33+'Summary-'!L52 -> 0
A16: 7 | B16: Soil Investigation (Nos) | C16: ='Summary-'!C17+'Summary-'!C34+'Summary-'!C53 -> 165 | D16: ='Summary-'!D17+'Summary-'!D34+'Summary-'!D53 -> 147 | E16: ='Summary-'!E17+'Summary-'!E34+'Summary-'!E53 -> 147 | F16: ='Summary-'!F17+'Summary-'!F34+'Summary-'!F53 -> 147 | G16: ='Summary-'!G17+'Summary-'!G34+'Summary-'!G53 -> 0 | H16: ='Summary-'!H17+'Summary-'!H34+'Summary-'!H53 -> 0 | I16: ='Summary-'!I17+'Summary-'!I34+'Summary-'!I53 -> 147 | J16: ='Summary-'!J17+'Summary-'!J34+'Summary-'!J53 -> 0 | K16: =D16-I16-J16 -> 0 | L16: ='Summary-'!L17+'Summary-'!L34+'Summary-'!L53 -> 0 | M16: Completed
A17: 8 | B17: Excavation (Nos) | C17: ='Summary-'!C18+'Summary-'!C35+'Summary-'!C54 -> 564 | D17: ='Summary-'!D18+'Summary-'!D35+'Summary-'!D54 -> 505 | E17: ='Summary-'!E18+'Summary-'!E35+'Summary-'!E54 -> 324 | F17: ='Summary-'!F18+'Summary-'!F35+'Summary-'!F54 -> 505 | G17: ='Summary-'!G18+'Summary-'!G35+'Summary-'!G54 -> 35 | H17: ='Summary-'!H18+'Summary-'!H35+'Summary-'!H54 -> 0 | I17: ='Summary-'!I18+'Summary-'!I35+'Summary-'!I54 -> 324 | J17: ='Summary-'!J18+'Summary-'!J35+'Summary-'!J54 -> 0 | K17: =D17-I17-J17 -> 181 | L17: ='Summary-'!L18+'Summary-'!L35+'Summary-'!L54 -> 0
A18: 9 | B18: Foundation (Nos) | C18: ='Summary-'!C19+'Summary-'!C36+'Summary-'!C55 -> 564 | D18: ='Summary-'!D19+'Summary-'!D36+'Summary-'!D55 -> 505 | E18: ='Summary-'!E19+'Summary-'!E36+'Summary-'!E55 -> 312 | F18: ='Summary-'!F19+'Summary-'!F36+'Summary-'!F55 -> 505 | G18: ='Summary-'!G19+'Summary-'!G36+'Summary-'!G55 -> 35 | H18: ='Summary-'!H19+'Summary-'!H36+'Summary-'!H55 -> 7 | I18: ='Summary-'!I19+'Summary-'!I36+'Summary-'!I55 -> 319 | J18: ='Summary-'!J19+'Summary-'!J36+'Summary-'!J55 -> 11 | K18: =D18-I18-J18 -> 175 | L18: ='Summary-'!L19+'Summary-'!L36+'Summary-'!L55 -> 11
A19: 10 | B19: Earthing (Nos) | C19: ='Summary-'!C20+'Summary-'!C37+'Summary-'!C56 -> 564 | D19: ='Summary-'!D20+'Summary-'!D37+'Summary-'!D56 -> 505 | E19: ='Summary-'!E20+'Summary-'!E37+'Summary-'!E56 -> 226 | F19: ='Summary-'!F20+'Summary-'!F37+'Summary-'!F56 -> 505 | G19: ='Summary-'!G20+'Summary-'!G37+'Summary-'!G56 -> 38 | H19: ='Summary-'!H20+'Summary-'!H37+'Summary-'!H56 -> 5 | I19: ='Summary-'!I20+'Summary-'!I37+'Summary-'!I56 -> 231 | J19: ='Summary-'!J20+'Summary-'!J37+'Summary-'!J56 -> 0 | K19: =D19-I19-J19 -> 274
A20: 11 | B20: Tower Erection (Nos) | C20: ='Summary-'!C21+'Summary-'!C38+'Summary-'!C57 -> 564 | D20: ='Summary-'!D21+'Summary-'!D38+'Summary-'!D57 -> 505 | E20: ='Summary-'!E21+'Summary-'!E38+'Summary-'!E57 -> 138 | F20: ='Summary-'!F21+'Summary-'!F38+'Summary-'!F57 -> 505 | G20: ='Summary-'!G21+'Summary-'!G38+'Summary-'!G57 -> 45 | H20: ='Summary-'!H21+'Summary-'!H38+'Summary-'!H57 -> 8 | I20: ='Summary-'!I21+'Summary-'!I38+'Summary-'!I57 -> 146 | J20: ='Summary-'!J21+'Summary-'!J38+'Summary-'!J57 -> 6 | K20: =D20-I20-J20 -> 353 | L20: ='Summary-'!L21+'Summary-'!L38+'Summary-'!L57 -> 6
A21: 12 | B21: Tack Welding (Nos) | C21: ='Summary-'!C22+'Summary-'!C39+'Summary-'!C58 -> 564 | D21: ='Summary-'!D22+'Summary-'!D39+'Summary-'!D58 -> 505 | E21: ='Summary-'!E22+'Summary-'!E39+'Summary-'!E58 -> 21 | F21: ='Summary-'!F22+'Summary-'!F39+'Summary-'!F58 -> 505 | G21: ='Summary-'!G22+'Summary-'!G39+'Summary-'!G58 -> 45 | H21: ='Summary-'!H22+'Summary-'!H39+'Summary-'!H58 -> 0 | I21: ='Summary-'!I22+'Summary-'!I39+'Summary-'!I58 -> 21 | J21: ='Summary-'!J22+'Summary-'!J39+'Summary-'!J58 -> 0 | K21: =D21-I21-J21 -> 484
A22: 13 | B22: Stringing (Km) | C22: ='Summary-'!C23+'Summary-'!C40+'Summary-'!C59 -> 165 | D22: ='Summary-'!D23+'Summary-'!D40+'Summary-'!D59 -> 150.833 | E22: ='Summary-'!E23+'Summary-'!E40+'Summary-'!E59 -> 3.199 | F22: ='Summary-'!F23+'Summary-'!F40+'Summary-'!F59 -> 150.833 | G22: ='Summary-'!G23+'Summary-'!G40+'Summary-'!G59 -> 6.2 | H22: ='Summary-'!H23+'Summary-'!H40+'Summary-'!H59 -> 0 | I22: ='Summary-'!I23+'Summary-'!I40+'Summary-'!I59 -> 3.199 | J22: ='Summary-'!J23+'Summary-'!J40+'Summary-'!J59 -> 0.748 | K22: =D22-I22-J22 -> 146.886 | L22: ='Summary-'!L40+'Summary-'!L59 -> 2
A23: 14 | B23: OPGW Stringing (Km) | C23: ='Summary-'!C24+'Summary-'!C41+'Summary-'!C60 -> 165 | D23: ='Summary-'!D24+'Summary-'!D41+'Summary-'!D60 -> 150.833 | E23: ='Summary-'!E24+'Summary-'!E41+'Summary-'!E60 -> 0 | F23: ='Summary-'!F24+'Summary-'!F41+'Summary-'!F60 -> 150.833 | G23: ='Summary-'!G24+'Summary-'!G41+'Summary-'!G60 -> 0 | H23: ='Summary-'!H24+'Summary-'!H41+'Summary-'!H60 -> 0 | I23: ='Summary-'!I24+'Summary-'!I41+'Summary-'!I60 -> 0 | J23: ='Summary-'!J24+'Summary-'!J41+'Summary-'!J60 -> 0 | K23: =D23-I23-J23 -> 150.833 | L23: ='Summary-'!L24+'Summary-'!L41+'Summary-'!L60 -> 0

Sheet Summary-
C1: Daily Progress Report
M3: Date-09/07/2026
B4: Contractual Start Date | C4: 45287 | D4: Project | E4: TB-412 TL
B5: Contractual Finish Date | C5: 45831 | D5: Client | E5: Bihar State Power Transmission corporation Limited
B6: TOE | C6: 46081 | D6: NOA Supply: | E6: 18. Dated - | F6: 27/12/2023
D7: NOA Service: | E7: 19. Dated - | F7: 45287
A8: 220 KV DC Twin Moose Chhapra - Amnour TL
A9: Sr no. | B9: Activity | C9: Total Quantity | E9: Cumm. Progress up to Last Month (June'26) | F9: Target as per L2 Schedule Cummulative (upto July'26) | G9: Target of Month for (July'2026) | H9: Comp This Month (July'2026) | I9: Cumulative Progress | J9: WIP | K9: Balance | L9: No of Gangs | M9: Remark
C10: LOA | D10: Estimated
A11: 1 | B11: Route Alignment (Km) | C11: 25 | D11: 6.6 | E11: 6.6 | F11: 6.6 | G11: 0 | H11: 0 | I11: =E11+H11 -> 6.6 | J11: 0 | K11: =D11-I11-J11 -> 0
A12: 2 | B12: Detailed Survey (Km) | C12: 25 | D12: 6.6 | E12: 6.6 | F12: 6.6 | G12: 0 | H12: 0 | I12: =E12+H12 -> 6.6 | J12: 0 | K12: =D12-I12-J12 -> 0
A13: 3 | B13: Detailed Survey Profiling (Km) | C13: 25 | D13: 6.6 | E13: 6.6 | F13: 6.6 | I13: =E13+H13 -> 6.6 | J13: 0 | K13: =D13-I13-J13 -> 0 | M13: Revised 0.33 KM Profile Submitted to BSPTCL HO from 23.12.2025
A14: 4 | B14: Approved detail survey (Km) | C14: 25 | D14: 6.6 | E14: 6.27 | F14: 6.6 | G14: 0.33 | H14: 0 | I14: =E14+H14 -> 6.27 | J14: 0 | K14: =D14-I14-J14 -> 0.33
A15: 5 | B15: Check Survey (Km) | C15: 25 | D15: 6.6 | E15: 6.6 | F15: 6.6 | H15: 0 | I15: =E15+H15 -> 6.6 | J15: 0 | K15: =D15-I15-J15 -> 0
A16: 6 | B16: Approved check survey ( Km) | C16: 25 | D16: 6.6 | E16: 5.539 | F16: 6.6 | G16: 1.061 | H16: 0 | I16: =E16+H16 -> 5.539 | J16: 0 | K16: =D16-I16-J16 -> 1.061
A17: 7 | B17: Soil Investigation (Nos) | C17: 25 | D17: 7 | E17: 7 | F17: 7 | G17: 0 | H17: 0 | I17: =E17+H17 -> 7 | J17: 0 | K17: =D17-I17-J17 -> 0 | M17: Completed
A18: 8 | B18: Excavation (Nos) | C18: 82 | D18: 28 | E18: 25 | F18: 28 | G18: 3 | H18: 0 | I18: =E18+H18 -> 25 | J18: 0 | K18: =D18-I18-J18 -> 3
A19: 9 | B19: Foundation (Nos) | C19: 82 | D19: 28 | E19: 25 | F19: 28 | G19: 3 | H19: 0 | I19: =E19+H19 -> 25 | J19: 1 | K19: =D19-I19-J19 -> 2 | L19: 1
A20: 10 | B20: Earthing (Nos) | C20: 82 | D20: 28 | E20: 22 | F20: 28 | G20: 6 | H20: 0 | I20: =E20+H20 -> 22 | K20: =D20-I20-J20 -> 6
A21: 11 | B21: Tower Erection (Nos) | C21: 82 | D21: 28 | E21: 12 | F21: 28 | G21: 10 | H21: 1 | I21: =E21+H21 -> 13 | J21: 1 | K21: =D21-I21-J21 -> 14 | L21: 1
A22: 12 | B22: Tack Welding (Nos) | C22: 82 | D22: 28 | E22: 0 | F22: 28 | G22: 10 | H22: 0 | I22: =E22+H22 -> 0 | J22: 0 | K22: =D22-I22-J22 -> 28
A23: 13 | B23: Stringing (Km) | C23: 25 | D23: 6.6 | E23: 0 | F23: 6.6 | G23: 1.4 | H23: 0 | I23: =E23+H23 -> 0 | J23: 0 | K23: =D23-I23-J23 -> 6.6 | M23: Harware fittings required to start stringing
A24: 14 | B24: OPGW Stringing (Km) | C24: 25 | D24: 6.6 | E24: 0 | F24: 6.6 | G24: 0 | H24: 0 | I24: =E24+H24 -> 0 | J24: 0 | K24: =D24-I24-J24 -> 6.6
A25: LILO 400 KV DC QUAD ACSR
A26: Sr no. | B26: Activity | C26: Total Quantity | E26: Cumm. Progress up to Last Month (June'26) | F26: Target as per L2 Schedule Cummulative (upto July'26) | G26: Target of Month for (July'2026) | H26: Comp This Month (July'2026) | I26: Cumulative Progress | J26: WIP | K26: Balance | L26: No of Gangs | M26: Remark
C27: LOA | D27: Estimated
A28: 1 | B28: Route Alignment (Km) | C28: 40 | D28: =21.266+20.007 -> 41.273 | E28: 41.273 | F28: 41.273 | G28: 0 | H28: 0 | I28: =E28+H28 -> 41.273 | J28: 0 | K28: =D28-I28-J28 -> 0 | L28: 0
A29: 2 | B29: Detailed Survey (Km) | C29: 40 | D29: 41.273 | E29: 41.273 | F29: 41.273 | G29: 0 | H29: 0 | I29: =E29+H29 -> 41.273 | J29: 0 | K29: =D29-I29-J29 -> 0 | L29: 0
A30: 3 | B30: Detailed Survey Profiling (Km) | C30: 40 | D30: 41.273 | E30: 39.625 | F30: 41.273 | G30: =D30-E30 -> 1.648 | H30: 0 | I30: =E30+H30 -> 39.625 | J30: 0 | K30: =D30-I30-J30 -> 1.648 | L30: 0 | M30: Pendig for MC tower
A31: 4 | B31: Approved detail survey (Km) | C31: 40 | D31: 41.273 | E31: 38.159 | F31: 41.273 | G31: =F31-E31 -> 3.114 | H31: 0 | I31: =E31+H31 -> 38.159 | J31: 0 | K31: =D31-I31-J31 -> 3.114 | L31: 0 | M31: 1.65 KM Detailed Survey Submitted
A32: 5 | B32: Check Survey (Km) | C32: 40 | D32: 41.273 | E32: 31.686 | F32: 41.273 | G32: =F32-E32 -> 9.587 | H32: 0 | I32: =E32+H32 -> 31.686 | J32: 0 | K32: =D32-I32-J32 -> 9.587 | L32: 0
A33: 6 | B33: Approved check survey ( Km) | C33: 40 | D33: 41.273 | E33: 31.686 | F33: 41.273 | G33: =F33-E33 -> 9.587 | H33: 0 | I33: =E33+H33 -> 31.686 | J33: 0 | K33: =D33-I33-J33 -> 9.587 | L33: 0
A34: 7 | B34: Soil Investigation (Nos) | C34: 40 | D34: 40 | E34: 40 | F34: 40 | G34: 0 | H34: 0 | I34: =E34+H34 -> 40 | J34: 0 | K34: =D34-I34-J34 -> 0 | L34: 0 | M34: Completed
A35: 8 | B35: Excavation (Nos) | C35: 122 | D35: 129 | E35: 96 | F35: 129 | G35: 12 | H35: 0 | I35: =E35+H35 -> 96 | K35: =D35-I35-J35 -> 33 | L35: 0
A36: 9 | B36: Foundation (Nos) | C36: 122 | D36: 129 | E36: 91 | F36: 129 | G36: 12 | H36: 1 | I36: =E36+H36 -> 92 | J36: 3 | K36: =D36-I36-J36 -> 34 | L36: 3
A37: 10 | B37: Earthing (Nos) | C37: 122 | D37: 129 | E37: 65 | F37: 129 | G37: 12 | H37: 0 | I37: =E37+H37 -> 65 | J37: 0 | K37: =D37-I37-J37 -> 64 | L37: 0
A38: 11 | B38: Tower Erection (Nos) | C38: 122 | D38: 129 | E38: 46 | F38: 129 | G38: 10 | H38: 3 | I38: =E38+H38 -> 49 | J38: 3 | K38: =D38-I38-J38 -> 77 | L38: 3
A39: 12 | B39: Tack Welding (Nos) | C39: 122 | D39: =+D35 -> 129 | E39: 10 | F39: =+F35 -> 129 | G39: 10 | H39: 0 | I39: 10 | J39: 0 | K39: =D39-I39-J39 -> 119
A40: 13 | B40: Stringing (Km) | C40: 40 | D40: 41.273 | E40: 0 | F40: 41.273 | G40: 2.8 | H40: 0 | I40: =E40+H40 -> 0 | J40: 0.399 | K40: =D40-I40-J40 -> 40.874 | L40: 1
A41: 14 | B41: OPGW Stringing (Km) | C41: 40 | D41: 41.273 | E41: 0 | F41: 41.273 | G41: 0 | H41: 0 | I41: =E41+H41 -> 0 | J41: 0 | K41: =D41-I41-J41 -> 41.273 | L41: 0
...

Sheet Survey Status
A1: TB412 BSPTCL - Survey Status
A2: Sl | B2: Line Name | C2: Activity | E2: Length | F2: Location | G2: Remarks / Plan for completion
E3: km | F3: Nos.
A4: 1 | B4: LILO of 400 kv Barh (NTPC)- Motihari (DMTCL) D/C ( QUAD) Transmission line at Chhapra (New) | C4: NOA | D4: - | E4: 40 | F4: 122
C5: Route Alignment | D5: Submitted | E5: 41.27 | F5: 128
D6: Approved | E6: 41.27 | F6: 128
C7: Detailed Survey | D7: Completed | E7: 36.884 | F7: 122 | G7: 1.575KM Pending at BSPTCL HO MC TSD Required
D8: Submitted | E8: 36.884 | F8: 112
D9: Approved | E9: 36.884 | F9: 112
C10: Check Survey | D10: Completed | E10: 32.046 | F10: 52 | G10: Balance Check Survey Under progress
D11: Submitted | E11: 14.5 | F11: 0
D12: Approved | E12: 14.5 | F12: 0
A14: 2 | B14: 220 KV D/C Chapra - Gopalganj Transmission Line with ACSR Zebra Conductor | C14: NOA | D14: - | E14: 100 | F14: 360
C15: Route Alignment | D15: Submitted | E15: 102.96 | F15: 348
D16: Approved | E16: 102.96 | F16: 348
C17: Detailed Survey | D17: Completed | E17: 101.44 | F17: 340
D18: Submitted | E18: 99.073 | F18: 312 | G18: 1.051 km profile submitted to BSPTCL HO from 15.12.2025
D19: Approved | E19: 99.073 | F19: 312
C20: Check Survey | D20: Completed | E20: 82.377 | F20: 276
D21: Submitted | E21: 82.377 | F21: 276
D22: Approved | E22: 82.377 | F22: 276
A24: 3 | B24: Construction of 220 KV D/C Twin Moose Chhapra- Amnaur Transmission line- | C24: NOA | D24: - | E24: 25 | F24: 82
C25: Route Alignment | D25: Submitted | E25: 6.6 | F25: 28
D26: Approved | E26: 6.6 | F26: 28
C27: Detailed Survey | D27: Completed | E27: 6.6 | F27: 28
D28: Submitted | E28: 6.475 | F28: 25 | G28: 0.33 Revised Profile Submitted to BSPTCL site office from 15.12.2025
D29: Approved | E29: 6.475 | F29: 25
C30: Check Survey | D30: Completed | E30: 5.5 | F30: 22
D31: Submitted | E31: 5.5 | F31: 22
D32: Approved | E32: 5.5 | F32: 22

Sheet Sheet3
A1: PROGRESS SUMMARY PLAN VS ACTUAL
A2: Foundation | B2: Nos. | C2: Comp Till Jan-26 | D2: Comp Till Feb-26 | E2: Plan Feb-26 | F2: Actual Feb-26 | G2: WIP | H2: Gang | I2: Balance | J2: Remarks
A4: 400kV LILO | B4: 128 | C4: 25 | D4: 28 | E4: 25 | F4: =D4-C4 -> 3 | G4: 5 | H4: 5 | I4: =B4-D4-G4 -> 95
A5: 220kV Gopalganj | B5: 348 | C5: 42 | D5: 50 | E5: 45 | F5: =D5-C5 -> 8 | G5: 5 | H5: 5 | I5: =B5-D5-G5 -> 293
A6: 220kV Amnour | B6: 28 | C6: 12 | D6: 12 | E6: 5 | F6: =D6-C6 -> 0 | G6: 0 | H6: 0 | I6: =B6-D6-G6 -> 16
A7: Total Nos | B7: =SUM(B4:B6) -> 504 | C7: =SUM(C4:C6) -> 79 | D7: =SUM(D4:D6) -> 90 | E7: =SUM(E4:E6) -> 75 | F7: =SUM(F4:F6) -> 11 | G7: =SUM(G4:G6) -> 10 | H7: =SUM(H4:H6) -> 10 | I7: =SUM(I4:I6) -> 404
A9: Erection | B9: Nos. | C9: Comp Till Jan-26 | D9: Comp Till Feb-26 | E9: Plan Feb-26 | F9: Actual Feb-26 | G9: WIP | H9: Gang | I9: Balance | J9: Remarks
A11: 400kV LILO | B11: 128 | C11: 0 | D11: 0 | E11: 10 | F11: 0 | G11: 1 | H11: 1 | I11: =B11-D11-G11 -> 127
A12: 220kV Gopalganj | B12: 348 | C12: 0 | D12: 0 | E12: 4 | F12: 0 | G12: 0 | H12: 0 | I12: =B12-D12-G12 -> 348
A13: 220kV Amnour | B13: 28 | C13: 1 | D13: 2 | E13: 6 | F13: 1 | G13: 1 | H13: 1 | I13: =B13-D13-G13 -> 25
A14: Total Nos | B14: =SUM(B11:B13) -> 504 | C14: =SUM(C11:C13) -> 1 | D14: =SUM(D11:D13) -> 2 | E14: =SUM(E11:E13) -> 20 | F14: =SUM(F11:F13) -> 1 | G14: =SUM(G11:G13) -> 2 | H14: =SUM(H11:H13) -> 2 | I14: =SUM(I11:I13) -> 500

Sheet DPR Sheet 
A1: KEC INTERNATIONAL LIMITED
A2: DAILY PROGRESS REPORT : STATUS AS ON | F2: ='Summary-'!M3 -> Date-09/07/2026
A3: Name of the Project: | B3: TB-412 T/L
A4: Contract No. & Date : | B4: NOA Supply/Service-18,19, Dated 27.12.2023
A5: ROUTE ALIGNMENT PROGRESS SUMMARY
A6: T/L Name | B6: TOTAL QTY (Tentative) | C6: COMPLETED UP TO PREV MONTH | D6: COMP. IN CURRENT MONTH | E6: CUMULATIVE | F6: BAL.QTY
A7: 400kV D/C QM LILO | B7: ='Summary-'!D28 -> 41.273 | C7: ='Summary-'!E28 -> 41.273 | D7: ='Summary-'!H28 -> 0 | E7: =C7+D7 -> 41.273 | F7: =B7-E7 -> 0
A8: 220 D/C SZ Chapra-Gopalganj | B8: ='Summary-'!D47 -> 102.96 | C8: ='Summary-'!E47 -> 102.96 | D8: ='Summary-'!H47 -> 0 | E8: =C8+D8 -> 102.96 | F8: =B8-E8 -> 0
A9: 220 D/C TM Chapra-Amnour | B9: ='Summary-'!D11 -> 6.6 | C9: ='Summary-'!E11 -> 6.6 | D9: ='Summary-'!H11 -> 0 | E9: =C9+D9 -> 6.6 | F9: =B9-E9 -> 0
A10: TOTAL | B10: =SUM(B7:B9) -> 150.833 | C10: =SUM(C7:C9) -> 150.833 | D10: =SUM(D7:D9) -> 0 | E10: =SUM(E7:E9) -> 150.833 | F10: =SUM(F7:F9) -> 0
A11: SOIL INVESTIGATION PROGRESS SUMMARY
A12: T/L Name | B12: TOTAL QTY (Tentative) | C12: COMPLETED UP TO PREV MONTH | D12: COMP. IN CURRENT MONTH | E12: CUMULATIVE | F12: BAL.QTY
A13: 400kV D/C QM LILO | B13: ='Summary-'!D34 -> 40 | C13: ='Summary-'!I34 -> 40 | D13: ='Summary-'!H34 -> 0 | E13: =C13+D13 -> 40 | F13: =B13-E13 -> 0
A14: 220 D/C SZ Chapra-Gopalganj | B14: ='Summary-'!D53 -> 100 | C14: ='Summary-'!D53 -> 100 | D14: ='Summary-'!H53 -> 0 | E14: =C14+D14 -> 100 | F14: =B14-E14 -> 0
A15: 220 D/C TM Chapra-Amnour | B15: ='Summary-'!D17 -> 7 | C15: ='Summary-'!E17 -> 7 | D15: ='Summary-'!H17 -> 0 | E15: =C15+D15 -> 7 | F15: =B15-E15 -> 0
A16: TOTAL | B16: =SUM(B13:B15) -> 147 | C16: =SUM(C13:C15) -> 147 | D16: =SUM(D13:D15) -> 0 | E16: =SUM(E13:E15) -> 147 | F16: =SUM(F13:F15) -> 0
A17: DETAILED SURVEY PROGRESS SUMMARY
A18: T/L Name | B18: TOTAL QTY (Tentative) | C18: COMPLETED UP TO PREV MONTH | D18: COMP. IN CURRENT MONTH | E18: CUMULATIVE | F18: BAL.QTY
A19: 400kV D/C QM LILO | B19: ='Summary-'!D31 -> 41.273 | C19: ='Summary-'!E31 -> 38.159 | D19: ='Summary-'!H31 -> 0 | E19: =C19+D19 -> 38.159 | F19: =B19-E19 -> 3.114
A20: 220 D/C SZ Chapra-Gopalganj | B20: ='Summary-'!D50 -> 102.96 | C20: ='Summary-'!E50 -> 98.905 | D20: ='Summary-'!H50 -> 0 | E20: =C20+D20 -> 98.905 | F20: =B20-E20 -> 4.055
A21: 220 D/C TM Chapra-Amnour | B21: ='Summary-'!D14 -> 6.6 | C21: ='Summary-'!E14 -> 6.27 | D21: ='Summary-'!H14 -> 0 | E21: =C21+D21 -> 6.27 | F21: =B21-E21 -> 0.33
A22: TOTAL | B22: =SUM(B19:B21) -> 150.833 | C22: =SUM(C19:C21) -> 143.334 | D22: =SUM(D19:D21) -> 0 | E22: =SUM(E19:E21) -> 143.334 | F22: =SUM(F19:F21) -> 7.499
A23: CHECK SURVEY PROGRESS SUMMARY
A24: T/L Name | B24: TOTAL QTY (Tentative) | C24: COMPLETED UP TO PREV MONTH | D24: COMP. IN CURRENT MONTH | E24: CUMULATIVE | F24: BAL.QTY
A25: 400kV D/C QM LILO | B25: ='Summary-'!D33 -> 41.273 | C25: ='Summary-'!E33 -> 31.686 | D25: ='Summary-'!H33 -> 0 | E25: =C25+D25 -> 31.686 | F25: =B25-E25 -> 9.587
A26: 220 D/C SZ Chapra-Gopalganj | B26: ='Summary-'!D52 -> 102.96 | C26: ='Summary-'!E52 -> 82.382 | D26: ='Summary-'!H52 -> 0 | E26: =C26+D26 -> 82.382 | F26: =B26-E26 -> 20.578
A27: 220 D/C TM Chapra-Amnour | B27: ='Summary-'!D16 -> 6.6 | C27: ='Summary-'!E16 -> 5.539 | D27: ='Summary-'!H16 -> 0 | E27: =C27+D27 -> 5.539 | F27: =B27-E27 -> 1.061
A28: TOTAL | B28: =SUM(B25:B27) -> 150.833 | C28: =SUM(C25:C27) -> 119.607 | D28: =SUM(D25:D27) -> 0 | E28: =SUM(E25:E27) -> 119.607 | F28: =SUM(F25:F27) -> 31.226
A29: FOUNDATION PROGRESS SUMMARY
A30: T/L Name | B30: TOTAL QTY (Tentative) | C30: COMPLETED UP TO PREV MONTH | D30: COMP. IN CURRENT MONTH | E30: CUMULATIVE | F30: BAL.QTY
A31: 400kV D/C QM LILO | B31: ='Summary-'!D36 -> 129 | C31: ='Summary-'!E36 -> 91 | D31: ='Summary-'!H36 -> 1 | E31: =C31+D31 -> 92 | F31: =B31-E31 -> 37
A32: 220 D/C SZ Chapra-Gopalganj | B32: ='Summary-'!D55 -> 348 | C32: ='Summary-'!E55 -> 196 | D32: ='Summary-'!H55 -> 6 | E32: =C32+D32 -> 202 | F32: =B32-E32 -> 146
A33: 220 D/C TM Chapra-Amnour | B33: ='Summary-'!D19 -> 28 | C33: ='Summary-'!E19 -> 25 | D33: ='Summary-'!H19 -> 0 | E33: =C33+D33 -> 25 | F33: =B33-E33 -> 3
A34: TOTAL | B34: =SUM(B31:B33) -> 505 | C34: =SUM(C31:C33) -> 312 | D34: =SUM(D31:D33) -> 7 | E34: =SUM(E31:E33) -> 319 | F34: =SUM(F31:F33) -> 186
A35: EARTHING PROGRESS SUMMARY
A36: T/L Name | B36: TOTAL QTY (Tentative) | C36: COMPLETED UP TO PREV MONTH | D36: COMP. IN CURRENT MONTH | E36: CUMULATIVE | F36: BAL.QTY
A37: 400kV D/C QM LILO | B37: ='Summary-'!D37 -> 129 | C37: ='Summary-'!E37 -> 65 | D37: ='Summary-'!H37 -> 0 | E37: =C37+D37 -> 65 | F37: =B37-E37 -> 64
A38: 220 D/C SZ Chapra-Gopalganj | B38: ='Summary-'!D56 -> 348 | C38: ='Summary-'!E56 -> 139 | D38: ='Summary-'!H56 -> 5 | E38: =C38+D38 -> 144 | F38: =B38-E38 -> 204
A39: 220 D/C TM Chapra-Amnour | B39: ='Summary-'!D20 -> 28 | C39: ='Summary-'!E20 -> 22 | D39: ='Summary-'!H20 -> 0 | E39: =C39+D39 -> 22 | F39: =B39-E39 -> 6
A40: TOTAL | B40: =SUM(B37:B39) -> 505 | C40: =SUM(C37:C39) -> 226 | D40: =SUM(D37:D39) -> 5 | E40: =SUM(E37:E39) -> 231 | F40: =SUM(F37:F39) -> 274
...

Sheet WIP
A1: ='DPR Sheet '!A1:F1 -> KEC INTERNATIONAL LIMITED
A2: ='DPR Sheet '!A2:E2 -> DAILY PROGRESS REPORT : STATUS AS ON | J2: ='Summary-'!M3 -> Date-09/07/2026
A3: Name of the Project: | D3: ='DPR Sheet '!B3 -> TB-412 T/L
A4: Contract No. & Date : | D4: ='DPR Sheet '!B4 -> NOA Supply/Service-18,19, Dated 27.12.2023
A5: FOUNDATION
A6: T/L Name | B6: SR.NO. | C6: GANG NAME | D6: LOC. NO. | E6: T.O.T | F6: T.O.CL | G6: D.O.S | H6: D.O.C | I6: MP | J6: REMARKS
A7: 400 KV LOOP OUT | B7: 1 | C7: Rajeshwar | D7: 6/0 | E7: DD+0 Aux | F7: PS | G7: 46204 | H7: 46212 | J7: Completed
A8: 400 KV LOOP IN | B8: 2 | C8: Nav Durga Traders | D8: 33/0 | E8: DD+3 | F8: PS | G8: 46205 | J8: Excavation WIP & Material Shifting WIP
A9: 400 KV LOOP OUT | B9: 3 | C9: Nav Durga Traders | D9: 46/0 | E9: DD+3 | F9: PS | G9: 46205 | J9: Pit Marking WIP
A10: 400 KV LOOP OUT | B10: 4 | C10: Rajeshwar | D10: 7/0 | E10: DB+0 | F10: PS | G10: 46213 | J10: Excavation WIP & Material Shifting WIP
A13: 220 TM Chapra-Amnour | B13: 1 | C13: Nav Durga Traders | D13: 12/0 | E13: DD+0 | F13: PS | G13: 46208 | J13: Work Stopped due to ROW
B14: 2
A17: 220 SZ Chapra-Gopalganj | B17: 1 | C17: Shakti | D17: 140/0 | E17: DD+3 | F17: PS | G17: 46204 | H17: =G17+2 -> 46206 | J17: COMPLETED
B18: =B17+1 -> 2 | C18: Anmol | D18: 144/0 | E18: DD+9 | F18: PS | G18: 46204 | H18: =G18+3 -> 46207 | J18: COMPLETED
B19: =B18+1 -> 3 | C19: Dharmendra Mishra | D19: 76/1 | E19: DA+6 | F19: PS | G19: 46204 | H19: =G19+3 -> 46207 | J19: COMPLETED
B20: =B19+1 -> 4 | C20: Construction Wala | D20: 104/1 | E20: DA+3 | F20: FS | G20: 46206 | H20: =G20+3 -> 46209 | J20: COMPLETED
B21: =B20+1 -> 5 | C21: Hetansh | D21: 148/3 | E21: DA+6 | F21: FS | G21: 46207 | H21: =G21+2 -> 46209 | J21: COMPLETED
B22: =B21+1 -> 6 | C22: Dharmendra Mishra | D22: 75/0 | E22: DC+0 | F22: FS | G22: =H17 -> 46206 | H22: =G22+5 -> 46211 | J22: COMPLETED
B23: =B22+1 -> 7 | C23: MAA | D23: 67/1 | E23: DA+6 1MRC | F23: FS | G23: 46206 | I23: 8 | J23: Excavation WIP
B24: =B23+1 -> 8 | C24: Suman Kumar Singh | D24: 75/1 | E24: DA+0 | F24: FS | G24: 46206 | I24: 8 | J24: Prop setting WIP
B25: =B24+1 -> 9 | C25: Construction Wala | D25: 104/3 | E25: DA+3 | F25: PS | G25: 46206 | I25: 8 | J25: Prop setting WIP
B26: =B25+1 -> 10 | C26: Shakti | D26: 141/0 | E26: DD+25 | F26: FS | G26: =H19 -> 46207 | I26: 10 | J26: RCC WIP
B27: =B26+1 -> 11 | C27: Anmol | D27: 143/0 | E27: DC+3 | F27: FS | G27: 46207 | I27: 7 | J27: ROW
B28: 12 | C28: Dharmendra Mishra | D28: 77/0 | E28: DC+6 | F28: FS | G28: 46212 | I28: 8 | J28: RCC WIP
B29: =B28+1 -> 13 | C29: Hetansh | D29: 155/0 | E29: DD+3 | F29: PS | G29: 46212 | I29: 8 | J29: Excavation WIP
B30: 14
A34: ERECTION
A35: T/L Name | B35: SR.NO. | C35: GANG | D35: LOC. NO. | E35: T.O.T | F35: D.O.S | G35: D.O.C | H35: MP | I35: Remarks
A36: 220 SZ Chapra-Gopalganj | B36: 1 | C36: Riyansh Construction | D36: 105/0 | E36: DC+6 | F36: 46204 | G36: =F36+2 -> 46206 | I36: Completed
A37: 400 KV LOOP IN | B37: =B36+1 -> 2 | C37: SGSE | D37: 26/1 | E37: DA+3 | F37: 46204 | G37: =F37+2 -> 46206 | I37: Completed
A38: 220 SZ Chapra-Gopalganj | B38: =B37+1 -> 3 | C38: Sanjeev Kumar | D38: 63/1 | E38: DA+3 | F38: 46204 | G38: =F38+2 -> 46206 | I38: Completed
A39: 220 SZ Chapra-Gopalganj | B39: =B38+1 -> 4 | C39: Sanjeev Kumar | D39: 63/2 | E39: DA+3 | F39: =G38 -> 46206 | G39: =F39+1 -> 46207 | I39: Completed
A40: 220 TM Chapra-Amnour | B40: =B39+1 -> 5 | C40: Yashoda Devi | D40: 8/2 | E40: DA+6 | F40: 46204 | G40: =F40+3 -> 46207 | I40: Completed
A41: 400 KV LOOP OUT | B41: =B40+1 -> 6 | C41: Pinki Devi | D41: 41/0 | E41: DC+0 | F41: 46204 | G41: =F41+4 -> 46208 | I41: Completed
A42: 220 SZ Chapra-Gopalganj | B42: =B41+1 -> 7 | C42: Sanjeev Kumar | D42: 79/0 | E42: DA+3 | F42: 46208 | G42: =F42+3 -> 46211 | I42: Completed
A43: 400 KV LOOP IN | B43: =B42+1 -> 8 | C43: SGSE | D43: 25/1 | E43: DA+3 | F43: 46207 | G43: =F43+5 -> 46212 | I43: Completed
A44: 220 TM Chapra-Amnour | B44: =B43+1 -> 9 | C44: Yashoda Devi | D44: 11/0 | E44: DC+0 | F44: 46208 | H44: 16 | I44: 1st Section WIP
A45: 400 KV LOOP IN | B45: =B44+1 -> 10 | C45: Rang | D45: 4/0 | E45: DA+6 | F45: 46211 | H45: 25 | I45: Material Shifting WIP
A46: 220 SZ Chapra-Gopalganj | B46: =B45+1 -> 11 | C46: Riyansh Construction | D46: 105/2 | E46: DA+6 | F46: 46208 | H46: 18 | I46: Material Shifting WIP
A47: 400 KV LOOP OUT | B47: =B46+1 -> 12 | C47: Pinki Devi | D47: 44/0 | E47: DD+0 | F47: 46209 | H47: 25 | I47: Bottom Section WIP
...

Sheet GANG Mapping MAY-26 
A1: FOUNDATION
A2: T/L Name | B2: Total Planned Locations for May'26 | C2: Total Gang Deployed (Nos) | D2: Total Man Power (Nos) | E2: Total Completed Locations for May'26 | F2: WIP | G2: Balanced Locations for May'26 as per planned | H2: Remarks
A3: 400kV D/C QM LILO | B3: 25 | C3: 5 | D3: =I85+I90+I95+I100+I105 -> 46 | E3: 11 | F3: 5 | G3: =B3-E3-F3 -> 9
A4: 220 D/C SZ Chapra-Gopalganj | B4: 65 | C4: 8 | D4: =I10+I16+I25+I40+I45+I50+I55+I60+I65 -> 68 | E4: 27 | F4: 8 | G4: =B4-E4-F4 -> 30
A5: 220 D/C TM Chapra-Amnour | B5: 10 | C5: 2 | D5: =I75+I80 -> 18 | E5: 4 | F5: 2 | G5: =B5-E5-F5 -> 4
A6: TOTAL | B6: =SUM(B3:B5) -> 100 | C6: =SUM(C3:C5) -> 15 | D6: =SUM(D3:D5) -> 132 | E6: =SUM(E3:E5) -> 42 | F6: =SUM(F3:F5) -> 15 | G6: =SUM(G3:G5) -> 43
A8: Foundation Plan of May-2026 for TB-412 TL
A9: S.n | B9: LOC N. | C9: TOT | D9: RC | E9: CLASSIFICATION | F9: START DATE | G9: COMPLETION DATE | H9: GANG | I9: Man Power | J9: Exc. Volume (In CUM) | K9: M10 In CUM | L9: M20 In CUM | M9: Steel in MT | N9: Excavation/CUM | O9: M10/CUM | P9: M20/CUM | Q9: Steel Per MT | R9: Revenue | S9: Remarks
A10: 1 | B10: 80/3 | C10: DA+3 | D10: 1 | E10: FS | F10: 46143 | G10: =F10+4 -> 46147 | H10: Exel Power | I10: 8 | J10: 140.36 | K10: 1.96 | L10: 14.51 | M10: 0.945 | N10: 204 | O10: 8390 | P10: 9675 | Q10: 78403 | R10: =(J10*N10+K10*O10+L10*P10+M10*Q10) -> 259552.92 | S10: Completed
A11: 2 | B11: 80/1 | C11: DA+0 | D11: 1 | E11: PS | F11: =G10 -> 46147 | G11: =F11+5 -> 46152 | H11: Exel Power | J11: 84.27 | K11: 1.1 | L11: 11.09 | M11: 0.751 | N11: 204 | O11: 8390 | P11: 9675 | Q11: 78403 | R11: =(J11*N11+K11*O11+L11*P11+M11*Q11) -> 192596.48 | S11: WIP
A12: 3 | B12: 80/2 | C12: DA+3 | D12: 1 | E12: FS | F12: =G11 -> 46152 | G12: =F12+5 -> 46157 | H12: Exel Power | J12: 140.36 | K12: 1.96 | L12: 14.51 | M12: 0.945 | N12: 204 | O12: 8390 | P12: 9675 | Q12: 78403 | R12: =(J12*N12+K12*O12+L12*P12+M12*Q12) -> 259552.92
A13: 4 | B13: 80/0 | C13: DD+0 | D13: 1 | E13: FS | F13: =G12 -> 46157 | G13: =F13+5 -> 46162 | H13: Exel Power | J13: 329.49 | K13: 4.88 | L13: 32.62 | M13: 2.607 | N13: 204 | O13: 8390 | P13: 9675 | Q13: 78403 | R13: =(J13*N13+K13*O13+L13*P13+M13*Q13) -> 628154.28
A14: 5 | B14: 79/0 | C14: DC+6 | E14: PS | F14: =G13 -> 46162 | G14: =F14+5 -> 46167 | H14: Exel Power | J14: 166.06 | K14: 2.34 | L14: 16.38 | M14: 0.951 | N14: 204 | O14: 8390 | P14: 9675 | Q14: 78403 | R14: =(J14*N14+K14*O14+L14*P14+M14*Q14) -> 286546.59
A15: 6 | B15: 78/0 | C15: DD+9 | E15: PS | F15: =G14 -> 46167 | G15: =F15+6 -> 46173 | H15: Exel Power | J15: 270.75 | K15: 3.96 | L15: 25.67 | M15: 1.84 | N15: 204 | O15: 8390 | P15: 9675 | Q15: 78403 | R15: =(J15*N15+K15*O15+L15*P15+M15*Q15) -> 481076.17
A16: 7 | B16: 64/1 | C16: DA+0 | E16: FS | F16: 46143 | G16: =F16+3 -> 46146 | H16: MAA | I16: 8 | J16: 108 | K16: 1.46 | L16: 10.98 | M16: 0.606 | N16: 204 | O16: 8390 | P16: 9675 | Q16: 78403 | R16: =(J16*N16+K16*O16+L16*P16+M16*Q16) -> 188025.12 | S16: Completed
A17: 8 | B17: 64/2 | C17: DA+0 | E17: FS | F17: =G16 -> 46146 | G17: =F17+3 -> 46149 | H17: MAA | J17: 133.87 | K17: 1.85 | L17: 11.71 | M17: 0.697 | N17: 204 | O17: 8390 | P17: 9675 | Q17: 78403 | R17: =(J17*N17+K17*O17+L17*P17+M17*Q17) -> 210772.12 | S17: Completed
A18: 9 | B18: 63/1 | C18: DA+3 | E18: FS | F18: =G17 -> 46149 | G18: =F18+3 -> 46152 | H18: MAA | J18: 133.87 | K18: 1.85 | L18: 11.71 | M18: 0.697 | N18: 204 | O18: 8390 | P18: 9675 | Q18: 78403 | R18: =(J18*N18+K18*O18+L18*P18+M18*Q18) -> 210772.12
A19: 10 | B19: 63/0 | C19: DD+0 | E19: FS | F19: =G18 -> 46152 | G19: =F19+3 -> 46155 | H19: MAA | J19: 329.49 | K19: 4.88 | L19: 31.12 | M19: 2.312 | N19: 204 | O19: 8390 | P19: 9675 | Q19: 78403 | R19: =(J19*N19+K19*O19+L19*P19+M19*Q19) -> 590512.9
A20: 11 | B20: 62A/0 | C20: DB+3 | E20: FS | F20: =G19 -> 46155 | G20: =F20+3 -> 46158 | H20: MAA | J20: 161.63 | K20: 2.27 | L20: 15.51 | M20: 0.848 | N20: 204 | O20: 8390 | P20: 9675 | Q20: 78403 | R20: =(J20*N20+K20*O20+L20*P20+M20*Q20) -> 268562.81
A21: 12 | B21: 62/2 | C21: DA+6 | E21: FS | F21: =G20 -> 46158 | G21: =F21+3 -> 46161 | H21: MAA | J21: 133.87 | K21: 1.85 | L21: 11.71 | M21: 0.697 | N21: 204 | O21: 8390 | P21: 9675 | Q21: 78403 | R21: =(J21*N21+K21*O21+L21*P21+M21*Q21) -> 210772.12
A22: 13 | B22: 53/0 | C22: DB+6 | D22: 1 | E22: FS | F22: =G21 -> 46161 | G22: =F22+3 -> 46164 | H22: MAA | J22: 161.63 | K22: 2.27 | L22: 18.32 | M22: 1.099 | N22: 204 | O22: 8390 | P22: 9675 | Q22: 78403 | R22: =(J22*N22+K22*O22+L22*P22+M22*Q22) -> 315428.72
A23: 14 | B23: 52/0 | C23: DD+6 | D23: 1 | E23: FS | F23: =G22 -> 46164 | G23: 46167 | H23: MAA | J23: 329.49 | K23: 4.88 | L23: 32.62 | M23: 2.607 | N23: 204 | O23: 8390 | P23: 9675 | Q23: 78403 | R23: =(J23*N23+K23*O23+L23*P23+M23*Q23) -> 628154.28
A24: 15 | B24: 51/0 | C24: DD+0 | D24: 1 | E24: FS | F24: 46167 | G24: 46173 | H24: MAA | J24: 329.49 | K24: 4.88 | L24: 32.62 | M24: 2.607 | N24: 204 | O24: 8390 | P24: 9675 | Q24: 78403 | R24: =(J24*N24+K24*O24+L24*P24+M24*Q24) -> 628154.28
A25: 16 | B25: 111A/0 | C25: DD+18 | D25: 1 | E25: FS | F25: 46143 | G25: =F25+2 -> 46145 | H25: Shakti | I25: 12 | J25: 344.76 | K25: 5.12 | L25: 34.77 | M25: 2.726 | N25: 204 | O25: 8390 | P25: 9675 | Q25: 78403 | R25: =(J25*N25+K25*O25+L25*P25+M25*Q25) -> 663414.17 | S25: Completed
A26: 17 | B26: 112/0 | C26: DD+18 | D26: 1 | E26: FS | F26: =G25 -> 46145 | G26: =F26+2 -> 46147 | H26: Shakti | J26: 344.76 | K26: 5.12 | L26: 34.77 | M26: 2.726 | N26: 204 | O26: 8390 | P26: 9675 | Q26: 78403 | R26: =(J26*N26+K26*O26+L26*P26+M26*Q26) -> 663414.17 | S26: Completed
A27: 18 | B27: 144/0 | C27: DD+9 | E27: FS | F27: =G26 -> 46147 | G27: =F27+2 -> 46149 | H27: Shakti | J27: 329.49 | K27: 4.88 | L27: 31.12 | M27: 2.312 | N27: 204 | O27: 8390 | P27: 9675 | Q27: 78403 | R27: =(J27*N27+K27*O27+L27*P27+M27*Q27) -> 590512.9 | S27: WIP
A28: 19 | B28: 145/0 | C28: DD+0 | E28: FS | F28: =G27 -> 46149 | G28: =F28+2 -> 46151 | H28: Shakti | J28: 329.49 | K28: 4.88 | L28: 31.12 | M28: 2.312 | N28: 204 | O28: 8390 | P28: 9675 | Q28: 78403 | R28: =(J28*N28+K28*O28+L28*P28+M28*Q28) -> 590512.9
A29: 20 | B29: 145/1 | C29: DA+0 | E29: FS | F29: =G28 -> 46151 | G29: =F29+2 -> 46153 | H29: Shakti | J29: 108 | K29: 1.46 | L29: 10.98 | M29: 0.606 | N29: 204 | O29: 8390 | P29: 9675 | Q29: 78403 | R29: =(J29*N29+K29*O29+L29*P29+M29*Q29) -> 188025.12
A30: 21 | B30: 145/2 | C30: DA+3 | E30: PS | F30: =G29 -> 46153 | G30: =F30+2 -> 46155 | H30: Shakti | J30: 108 | K30: 1.46 | L30: 9.71 | M30: 0.613 | N30: 204 | O30: 8390 | P30: 9675 | Q30: 78403 | R30: =(J30*N30+K30*O30+L30*P30+M30*Q30) -> 176286.69
A31: 22 | B31: 146/0 | C31: DC+6 | E31: FS | F31: =G30 -> 46155 | G31: =F31+2 -> 46157 | H31: Shakti | J31: 206.67 | K31: 2.96 | L31: 20.24 | M31: 1.129 | N31: 204 | O31: 8390 | P31: 9675 | Q31: 78403 | R31: =(J31*N31+K31*O31+L31*P31+M31*Q31) -> 351334.07
A32: 23 | B32: 147/0 | C32: DC+9 | E32: PS | F32: =G31 -> 46157 | G32: =F32+2 -> 46159 | H32: Shakti | J32: 166.06 | K32: 2.34 | L32: 16.38 | M32: 0.951 | N32: 204 | O32: 8390 | P32: 9675 | Q32: 78403 | R32: =(J32*N32+K32*O32+L32*P32+M32*Q32) -> 286546.59
A33: 24 | B33: AP147A/0 | C33: DD+6 | E33: FS | F33: =G32 -> 46159 | G33: =F33+2 -> 46161 | H33: Shakti | J33: 329.49 | K33: 4.88 | L33: 31.12 | M33: 2.312 | N33: 204 | O33: 8390 | P33: 9675 | Q33: 78403 | R33: =(J33*N33+K33*O33+L33*P33+M33*Q33) -> 590512.9
A34: 25 | B34: 148/0 | C34: DC+3 | E34: FS | F34: =G33 -> 46161 | G34: =F34+2 -> 46163 | H34: Shakti | J34: 206.67 | K34: 2.96 | L34: 20.24 | M34: 1.129 | N34: 204 | O34: 8390 | P34: 9675 | Q34: 78403 | R34: =(J34*N34+K34*O34+L34*P34+M34*Q34) -> 351334.07
A35: 26 | B35: 148/1 | C35: DA+3 | E35: PS | F35: =G34 -> 46163 | G35: =F35+2 -> 46165 | H35: Shakti | J35: 108 | K35: 1.46 | L35: 9.71 | M35: 0.613 | N35: 204 | O35: 8390 | P35: 9675 | Q35: 78403 | R35: =(J35*N35+K35*O35+L35*P35+M35*Q35) -> 176286.69
A36: 27 | B36: 148/2 | C36: DA+3 | E36: PS | F36: =G35 -> 46165 | G36: =F36+2 -> 46167 | H36: Shakti | J36: 108 | K36: 1.46 | L36: 9.71 | M36: 0.613 | N36: 204 | O36: 8390 | P36: 9675 | Q36: 78403 | R36: =(J36*N36+K36*O36+L36*P36+M36*Q36) -> 176286.69
A37: 28 | B37: 148/3 | C37: DA+6 | E37: PS | F37: =G36 -> 46167 | G37: =F37+2 -> 46169 | H37: Shakti | J37: 108 | K37: 1.46 | L37: 9.71 | M37: 0.613 | N37: 204 | O37: 8390 | P37: 9675 | Q37: 78403 | R37: =(J37*N37+K37*O37+L37*P37+M37*Q37) -> 176286.69
A38: 29 | B38: 149/0 | C38: DD+0 | E38: FS | F38: =G37 -> 46169 | G38: =F38+2 -> 46171 | H38: Shakti | J38: 329.49 | K38: 4.88 | L38: 31.12 | M38: 2.312 | N38: 204 | O38: 8390 | P38: 9675 | Q38: 78403 | R38: =(J38*N38+K38*O38+L38*P38+M38*Q38) -> 590512.9
A39: 30 | B39: 149/1 | C39: DA+3 | E39: PS | F39: =G38 -> 46171 | G39: =F39+2 -> 46173 | H39: Shakti | J39: 108 | K39: 1.46 | L39: 9.71 | M39: 0.613 | N39: 204 | O39: 8390 | P39: 9675 | Q39: 78403 | R39: =(J39*N39+K39*O39+L39*P39+M39*Q39) -> 176286.69
A40: 31 | B40: 132/5 | C40: DA+3 | E40: PS | F40: 46143 | G40: =F40+7 -> 46150 | H40: Hetansh | I40: 8 | J40: 108 | K40: 1.46 | L40: 9.71 | M40: 0.613 | N40: 204 | O40: 8390 | P40: 9675 | Q40: 78403 | R40: =(J40*N40+K40*O40+L40*P40+M40*Q40) -> 176286.69 | S40: Completed
A41: 32 | B41: 132/1 | C41: DA+3 | E41: PS | F41: =G40 -> 46150 | G41: =F41+7 -> 46157 | H41: Hetansh | J41: 108 | K41: 1.46 | L41: 9.71 | M41: 0.613 | N41: 204 | O41: 8390 | P41: 9675 | Q41: 78403 | R41: =(J41*N41+K41*O41+L41*P41+M41*Q41) -> 176286.69
...

Sheet Soil Investigation
A1: Soil Investigation Status
A2: LILO of 400 KV Barh (NTPC) Motihari (DMTCL) D/C (Quad Moose) TL at Chhapra (New) | G2: Status as on | H2: ='DPR Sheet '!F2 -> Date-09/07/2026
A3: SL.No. | B3: Tower No. | C3: Soil Investigation date | D3: Classification | E3: Remarks | G3: LINE NAME | H3: Discription | I3: Qty
A4: 1 | B4: AP 1 | C4: 45896 | D4: WET | E4: LOOP IN (21.266RKM) | G4: LILO of 400 KV Barh (NTPC) Motihari (DMTCL) D/C (Quad Moose) TL at Chhapra (New) | H4: SCOPE | I4: 40
A5: 2 | B5: AP 4 | C5: 45896 | D5: PS | H5: COMPLETED | I5: 40
A6: 3 | B6: AP 5 | C6: 45896 | D6: PS | H6: Report Submiteed | I6: 40
A7: 4 | B7: AP 7 | C7: 45896 | D7: PS | H7: Report Approved | I7: 40
A8: 5 | B8: AP 7A | C8: 45896 | D8: PS | H8: Balanced | I8: 0
A9: 6 | B9: AP 9 | C9: 45897 | D9: PS
A10: 7 | B10: AP 10 | C10: 45897 | D10: PS | G10: 220 KV Chhapra(NEW) to Amnour DCDS Transmission Line with Twin Moose | H10: SCOPE | I10: 7
A11: 8 | B11: AP 11 | C11: 45896 | D11: PS | H11: COMPLETED | I11: 7
A12: 9 | B12: AP 13 | C12: 45897 | D12: WET | H12: Report Submiteed | I12: 7
A13: 10 | B13: AP 14 | C13: 45897 | D13: WET | H13: Report Approved | I13: 7
A14: 11 | B14: AP 15 | C14: 45897 | D14: PS | H14: Balanced | I14: 0
A15: 12 | B15: AP 17 | C15: 45898 | D15: PS
A16: 13 | B16: AP 18 | C16: 45898 | D16: PS | G16: 220 KV D/C Chhapra - Gopalganj Transmission Line with ACSR Zebra Conductor | H16: SCOPE | I16: 100
A17: 14 | B17: AP 20 | C17: 45898 | D17: FS | H17: COMPLETED | I17: 100
A18: 15 | B18: AP 21 | C18: 45898 | D18: FS | H18: Report Submited | I18: 25
A19: 16 | B19: AP 24 | C19: 45898 | D19: PS | H19: Report Approved | I19: 21
A20: 17 | B20: AP 25 | C20: 45898 | D20: PS | H20: Report Awaited | I20: 36
A21: 18 | B21: AP 26 | C21: 45899 | D21: PS | H21: Balanced | I21: =I16-I17 -> 0
A22: 19 | B22: AP 28 | C22: 45899 | D22: PS
A23: 20 | B23: AP 32 | C23: 45899 | D23: FS
A24: 21 | B24: AP 1 | C24: 45905 | D24: WET | E24: LOOP OUT (20.007RKM)
A25: 22 | B25: AP 3A | C25: 45899 | D25: WET
A26: 23 | B26: AP 5A | C26: 45899 | D26: PS
A27: 24 | B27: AP 8A | C27: 45900 | D27: PS
A28: 25 | B28: AP 9 | C28: 45900 | D28: PS
A29: 26 | B29: AP 11 | C29: 45900 | D29: PS
A30: 27 | B30: AP 12 | C30: 45901 | D30: PS
A31: 28 | B31: AP 15 | C31: 45901 | D31: PS
A32: 29 | B32: AP 15 A | C32: 45901 | D32: PS
A33: 30 | B33: AP 17 | C33: 45902 | D33: PS
A34: 31 | B34: AP 18 | C34: 45902 | D34: WET
A35: 32 | B35: AP 19 | C35: 45903 | D35: PS
A36: 33 | B36: AP 21 | C36: 45902 | D36: PS
... A43: 40 | B43: AP 37 | C43: 45905 | D43: FS
A44: Total Completed | C44: =COUNTA(C4:C43) -> 40
A46: 220 KV D/C Chhapra - Gopalganj T L with ACSR Zebra Conductor
A47: SL.No. | B47: Location No. | C47: Soil Investigation date | D47: Classification | E47: Remarks
...

Sheet Sheet1
A1: 220 KV D/C Chhapra - Gopalganj Transmission Line with ACSR Zebra Conductor
A2: SL.No. | B2: Location No. | C2: Soil Investigation date | D2: Type of Soil | E2: GPS Co-ordinates (in degree) | G2: Remarks/Crossings
E3: Latitude | F3: Longitude
A4: 1 | B4: AP 54 | C4: 45982 | D4: FS | E4: 26°14'50.9" | F4: 84°33'51.9"
A5: 2 | B5: AP 55 | C5: 45982 | D5: PS | E5: 26°14'17.5" | F5: 84°34'9.6"
A6: 3 | B6: AP 57 | C6: 45982 | D6: WET | E6: 26°13'56.9" | F6: 84°34'40.8"
A7: 4 | B7: AP 59 | C7: 45981 | D7: FS | E7: 26°13'32" | F7: 84°35'20.1"
A8: 5 | B8: AP 60 | C8: 45981 | D8: FS | E8: 26°12'9.6" | F8: 84°35'24.2"
A9: 6 | B9: AP 61 | C9: 45981 | D9: FS | E9: 26°12'2.6" | F9: 84°35'24.5"
A10: 7 | B10: AP 62 | C10: 45980 | D10: FS | E10: 26°11'7" | F10: 84°35'19"
A11: 8 | B11: AP 63 | C11: 45980 | D11: FS | E11: 26°10'37.2" | F11: 84°35'35.6"
A12: 9 | B12: AP 64 | C12: 45980 | D12: FS | E12: 26°10'21.2" | F12: 84°36'6.6"
A13: 10 | B13: AP 65 | C13: 45978 | D13: PS | E13: 26°10'24.8" | F13: 84°36'44.8"
A14: 11 | B14: AP 67 | C14: 45978 | D14: PS | E14: 26°9'58.2" | F14: 84°36'53.3"
A15: 12 | B15: AP 68 | C15: 45978 | D15: FS | E15: 26°9'25.1" | F15: 84°36'43.7" | G15: 800kV HVDC (GPJ_GKP)
A16: 13 | B16: AP 69 | C16: 45977 | D16: FS | E16: 26°9'19.3" | F16: 84°36'41.9"
A17: 14 | B17: AP 71 | C17: 45977 | D17: FS | E17: 26°8'26.3" | F17: 84°36'37.2" | G17: 400kV D/C (BAR_GKP)
A18: 15 | B18: AP 72 | C18: 45977 | D18: FS | E18: 26°8'17" | F18: 84°36'33.2"
A19: 16 | B19: AP 73 | C19: 45976 | D19: FS | E19: 26°8'10.9" | F19: 84°36'36.4" | G19: Railway Crossing
A20: 17 | B20: AP 74 | C20: 45976 | D20: PS | E20: 26°7'28" | F20: 84°36'34.1"
A21: 18 | B21: AP 76 | C21: 45976 | D21: PS | E21: 26°6'58.1" | F21: 84°36'18.9"
A22: 19 | B22: AP 78 | C22: 45975 | D22: PS | E22: 26°6'32.1" | F22: 84°36'38.3"
A23: 20 | B23: AP 80 | C23: 45975 | D23: FS | E23: 26°6'21.7" | F23: 84°36'54.9"
A24: 21 | B24: AP 81 | C24: 45975 | D24: FS | E24: 26°5'42.3" | F24: 84°36'47"
A25: 22 | B25: AP 83 | C25: 45974 | D25: FS | E25: 26°5'11.7" | F25: 84°36'58.6"
A26: 23 | B26: AP 85 | C26: 45974 | D26: FS | E26: 26°4'43" | F26: 84°37'8.9"
A27: 24 | B27: AP 87 | C27: 45974 | D27: FS | E27: 26°4'43.5" | F27: 84°37'44.3"
A28: 25 | B28: AP 89 | C28: 45973 | D28: PS | E28: 26°4'1.7" | F28: 84°38'18.1"
A29: 26 | B29: AP 92 | C29: 45973 | D29: PS | E29: 26°3'5.9" | F29: 84°39'0.9" | G29: 132kV D/C (CHO_SWN)
A30: 27 | B30: AP 93 | C30: 45973 | D30: PS | E30: 26°2'57.1" | F30: 84°38'55.3"

Sheet Progress 400kV QM
A1: Client:- | C1: BIHAR STATE POWER TRANSMISSION COMPANY LIMITED (BSPTCL)
A2: Line Name:- | C2: LILO of 400 KV Barh (NTPC) Motihari (DMTCL) D/C (Quad Moose) Transmission Line at Chhapra (New) LOOP IN & LOOP OUT
A3: EPC:- | C3: KEC International Limited
A4: S.NO. | B4: LOC. NO. | C4: TYPE OF TOWER | D4: ANGLE OF DEVATION | E4: RAISED CHIMNEY | F4: RAISED CHIMNEY | J4: SPAN | K4: Crossing Detail/Statutary | L4: ROW Status | M4: Foundation Status | N4: Contractor Name | O4: Earthing Status | P4: Erection Status | Q4: Contractor Name | R4: Tack Welding Status | S4: VILLAGES | T4: Remarks
F5: A | G5: B | H5: C | I5: D
A6: 1 | B6: 1/0 | C6: 4DD+0 | D6: 45° 33' 45"RT | J6: 112.764 | M6: HOLD | S6: ARNA | T6: LOOP IN
A7: =A6+1 -> 2 | B7: 2/0 | C7: 4DD+0 | D7: 35° 58' 12"RT | J7: 158.659 | M7: HOLD | S7: SANDALPUR | T7: LOOP IN
A8: =A7+1 -> 3 | B8: 3/0 | C8: 4DD+0 | D8: 30° 18' 41"RT | J8: 296 | M8: HOLD | S8: SANDALPUR | T8: LOOP IN
A9: =A8+1 -> 4 | B9: 3/1 | C9: 4DA+0 | J9: 332 | M9: HOLD | S9: SANDALPUR | T9: LOOP IN
A10: =A9+1 -> 5 | B10: 3/2 | C10: 4DA+0 | J10: 277 | M10: HOLD | S10: SANDALPUR | T10: LOOP IN
A11: =A10+1 -> 6 | B11: 3/3 | C11: 4DA+0 | J11: 340.684 | M11: HOLD | S11: MOLNAPUR | T11: LOOP IN
A12: =A11+1 -> 7 | B12: 4/0 | C12: 4DC+0 | D12: 18° 12' 5"RT | J12: 229.841 | K12: NH-722 | M12: HOLD | S12: MOLNAPUR | T12: LOOP IN
A13: =A12+1 -> 8 | B13: 5/0 | C13: 4DD+0 | D13: 50° 6' 30"LT | J13: 276.925 | M13: HOLD | S13: GANESHPATTI | T13: LOOP IN
A14: =A13+1 -> 9 | B14: 6/0 | C14: 4DD+0 | D14: 53° 5' 45"RT | J14: 357 | M14: HOLD | S14: GANESHPATTI | T14: LOOP IN
A15: =A14+1 -> 10 | B15: 6/1 | C15: 4DA+3 | J15: 243.767 | M15: HOLD | S15: BASAUTI | T15: LOOP IN
A16: =A15+1 -> 11 | B16: 7/0 | C16: 4DB+0 | D16: 8° 59' 29"RT | J16: 338 | M16: HOLD | S16: BASAUTI | T16: LOOP IN
A17: =A16+1 -> 12 | B17: 7/1 | C17: 4DA+0 | J17: 309 | M17: WIP | N17: Dharmendra Mishra | O17: WIP | S17: MURLI SIRSIA | T17: LOOP IN
A18: =A17+1 -> 13 | B18: 7/2 | C18: 4DA+0 | J18: 381.534 | M18: WIP | N18: AR | S18: MURLI SIRSIA | T18: LOOP IN
A19: =A18+1 -> 14 | B19: 8/0 | C19: 4DB+0 | D19: 5° 20' 56"LT | J19: 331.87 | M19: Completed | N19: AR | S19: MURLI SIRSIA | T19: LOOP IN
A20: =A19+1 -> 15 | B20: 9/0 | C20: 4DC+0 | D20: 18° 23' 40"LT | J20: 341.212 | M20: Completed | N20: Kutir Vihar | O20: Completed | S20: MURLI SIRSIA | T20: LOOP IN
A21: =A20+1 -> 16 | B21: 10/0 | C21: 4DB+0 | D21: 2° 36' 19"LT | J21: 243.495 | M21: Completed | N21: Kutir Vihar | O21: Completed | S21: MURLI SIRSIA | T21: LOOP IN
A22: =A21+1 -> 17 | B22: 11/0 | C22: 4DD+0 | D22: 30° 45' 23"LT | J22: 316 | M22: Completed | N22: Kutir Vihar | O22: Completed | S22: JAGARNATHPUR | T22: LOOP IN
A23: =A22+1 -> 18 | B23: 11/1 | C23: 4DA+0 | J23: 325 | M23: Completed | N23: Dharmendra Mishra | O23: Completed | S23: JAGARNATHPUR | T23: LOOP IN
A24: =A23+1 -> 19 | B24: 11/2 | C24: 4DA+0 | J24: 269 | M24: Completed | N24: Rajeswar Singh | S24: BARKI SIRSIA | T24: LOOP IN
A25: =A24+1 -> 20 | B25: 11/3 | C25: 4DA+0 | J25: 281.828 | M25: Completed | N25: Dharmendra Mishra | S25: BARKI SIRSIA | T25: LOOP IN
A26: =A25+1 -> 21 | B26: 12/0 | C26: 4DB+3 | D26: 7° 1' 5"LT | J26: 423 | L26: ROW | M26: ROW | S26: BARKI SIRSIA | T26: LOOP IN
A27: =A26+1 -> 22 | B27: 12/1 | C27: 4DA+9 | J27: 376.095 | M27: Completed | N27: Dharmendra Mishra | S27: BHIMA BANDH | T27: LOOP IN
A28: =A27+1 -> 23 | B28: 13/0 | C28: 4DD+6 | D28: 53° 3' 22"LT | J28: 439.076 | L28: ROW | M28: ROW | S28: PIROZPUR | T28: LOOP IN
A29: =A28+1 -> 24 | B29: 14/0 | C29: 4DC+6 | D29: 28° 21' 50"LT | J29: 317.989 | L29: ROW | M29: ROW | S29: PACHRUKHI | T29: LOOP IN
A30: =A29+1 -> 25 | B30: 15/0 | C30: 4DC+0 | D30: 22° 22' 10"LT | J30: 350 | L30: ROW | M30: ROW | S30: BHIMA BANDH | T30: LOOP IN
A31: =A30+1 -> 26 | B31: 15/1 | C31: 4DA+3 | J31: 434.141 | L31: ROW | M31: ROW | S31: LANGARPURA | T31: LOOP IN
A32: =A31+1 -> 27 | B32: 16/0 | C32: 4DD+18 | D32: 42° 12' 40"RT | J32: 271.003 | K32: 220kV D/C OHTL BGCL (HJP- CHP) | L32: Stub NA | S32: LANGARPURA | T32: LOOP IN
A33: =A32+1 -> 28 | B33: 17/0 | C33: 4DD+25 | D33: 51° 38' 13"RT | J33: 190.909 | L33: Stub NA | S33: LANGARPURA | T33: LOOP IN
A34: =A33+1 -> 29 | B34: 18/0 | C34: 4DC+6 | D34: 16° 4' 36"RT | J34: 411 | M34: Completed | N34: Rajeshwar Singh | O34: Completed | P34: Completed | Q34: Rang | S34: LANGARPURA | T34: LOOP IN
A35: =A34+1 -> 30 | B35: 18/1 | C35: 4DA+3 | J35: 387 | M35: Completed | N35: Rajeshwar Singh | O35: Completed | P35: Completed | Q35: Rang | S35: PACHRUKHI | T35: LOOP IN
A36: =A35+1 -> 31 | B36: 18/2 | C36: 4DA+6 | J36: 377.351 | M36: Completed | N36: Rajeshwar Singh | O36: Completed | P36: Completed | Q36: Rang | S36: PACHRUKHI | T36: LOOP IN
A37: =A36+1 -> 32 | B37: 19/0 | C37: 4DB+3 | D37: 12° 30' 39"RT | J37: 392 | M37: Completed | N37: Rajeshwar Singh | O37: Completed | P37: Completed | Q37: Rang | S37: PACHRUKHI | T37: LOOP IN
A38: =A37+1 -> 33 | B38: 19/1 | C38: 4DA+0 | J38: 313 | M38: Completed | N38: Rajeshwar Singh | O38: Completed | P38: Completed | Q38: Rang | S38: PACHRUKHI | T38: LOOP IN
A39: =A38+1 -> 34 | B39: 19/2 | C39: 4DA+0 | J39: 318 | M39: Completed | N39: Rajeshwar Singh | O39: Completed | P39: Completed | Q39: Rang | S39: BANKERWA BHAW | T39: LOOP IN
A40: =A39+1 -> 35 | B40: 19/3 | C40: 4DA+0 | J40: 347 | M40: Completed | N40: Rajeshwar Singh | P40: Completed | Q40: Rang | S40: BANKERWA BHAW | T40: LOOP IN
...

Sheet VC 400 KV QM
C1: 46212
A2: LILO of 400 KV Barh (NTPC) Motihari (DMTCL) D/C (Quad Moose) Transmission Line at Chhapra (New) LOOP IN & LOOP OUT
A3: M/S KEC INTERNATIONAL LIMITED
A4: Progress Visual Chart
P6: HOLD
B7: Foundation Cumulative | G7: Nos. | I7: 92/129 | Q7: MC,Design and Special Tower & DS
B8: Earthing Cumulative | G8: Nos. | I8: 65/129 | Q8: ROW
B9: Erection Cumulative | G9: Nos. | I9: 49/129 | P9: Statutary | Q9: RLY XING
B10: Stringing Payingout (RS) | G10: Km. | I10: 0.00/41.381 | Q10: NH
B11: Stringing Final sag Cumulative | G11: Km. | I11: 0.00/41.381 | Q11: PL
Q12: IOCL
C13: =C1 -> 46212
A14: LILO of 400 KV Barh (NTPC) Motihari (DMTCL) D/C (Quad Moose) Transmission Line at Chhapra (New) LOOP IN
A15: M/S KEC INTERNATIONAL LIMITED
A16: Progress Visual Chart
N18: LEGENDS
O19: TE Dt | P19: STG | T19: Major Power Line Crossing | W19: Railway Crossing | Y19: River Crossing | AA19: Highway Crossing (EH & NH)
C20: Foundation Cumulative | H20: Nos. | J20: 43/63 | P20: Dt | S20: STG UP
C21: Earthing Cumulative | H21: Nos. | J21: 31/63 | M21: ERECTION
C22: Erection Cumulative | H22: Nos. | J22: 24/63 | O22: Date | P22: SPAN
C23: Stringing Payingout (RS) | H23: Km. | J23: 0.00/21.279 | M23: FOUNDATION | O23: Type
C24: Stringing Final sag Cumulative | H24: Km. | J24: 0.00/21.279
I25: ` | M25: Tower+Extn | O25: X+Y | Q25: Earthing | S25: U/P
P26: Suspn Tower | Q26: Angle Tower
M27: TOWER NO | O27: YY
W29: Cum Length | X29: Fdn Comp | Y29: Ear Comp | Z29: TE Comp | AA29: STG Comp
B33: 146.26 | D33: 112.78 | F33: 158.66 | H33: 296 | J33: 332 | L33: 277 | N33: 340.68 | P33: 229.84 | R33: 276.93 | T33: 357 | V33: New Proposed Railway | W33: =SUM(A33:V33) -> 2527.15 | X33: 1 | Y33: 0 | Z33: 0 | AA33: 0
A35: Ext.TWR | C35: 1/0 | E35: 2/0 | G35: 3/0 | I35: 3/1 | K35: 3/2 | M35: 3/3 | O35: 4/0 | Q35: 5/0 | S35: 6/0 | U35: 6/1
C36: 4DD+0 | E36: 4DD+0 | G36: 4DD+0 | I36: 4DA+0 | K36: 4DA+0 | M36: 4DA+0 | O36: 4DD+6 | P36: NH - 722 | Q36: 4DD+6 | S36: 4DD+0 | U36: 4DD+9
C37: HOLD MC | E37: HOLD MC | G37: HOLD MC | I37: HOLD MC | M37: HOLD NH | O37: HOLD NH | Q37: HOLD NH | S37: HOLD NH
R39: `
B41: 243.77 | D41: 338 | F41: 309 | H41: 381.53 | J41: 331.87 | L41: 341.21 | N41: 243.5 | P41: 316 | R41: 325 | S41: PS 15.01.26 | T41: 269 | W41: =SUM(A41:V41) -> 3098.88 | X41: 9 | Y41: 8 | Z41: 3 | AA41: 0
C43: 7/0 | E43: 7/1 | G43: 7/2 | I43: 8/0 | K43: 9/0 | M43: 10/0 | O43: 11/0 | Q43: 11/1 | S43: 11/2 | U43: 11/3
C44: 4DD+9 | E44: 4DA+0 | G44: 4DA+0 | I44: 4DB+0 | K44: 4DC+0 | M44: 4DB+0 | O44: 4DD+0 | Q44: 4DA+0 | S44: 4DA+0 | U44: 4DA+0
C45: ROW
R47: `
B49: 281.83 | D49: 423 | F49: 376.1 | H49: 439.08 | J49: 317.99 | L49: 350 | N49: 434.14 | P49: 271 | R49: 190.91 | T49: 411 | U49: PS 09.01.26 | W49: =SUM(A49:V49) -> 3495.05 | X49: 4 | Y49: 2 | Z49: 2 | AA49: 0
P50: 220kV D/C OHTL BGCL (HJP- CHP)
C51: 12/0 | E51: 12/1 | G51: 13/0 | I51: 14/0 | K51: 15/0 | M51: 15/1 | O51: 16/0 | Q51: 17/0 | S51: 18/0 | U51: 18/1
C52: 4DB+3 | E52: 4DA+9 | G52: 4DD+6 | I52: 4DC+6 | K52: 4DC+0 | M52: 4DA+3 | O52: 4DD+18 | Q52: 4DD+25 | S52: 4DC+6 | U52: 4DA+3
...

Sheet Progress 220KV TM
A1: Client:- | C1: BIHAR STATE POWER TRANSMISSION COMPANY LIMITED (BSPTCL)
A2: Line Name:- | C2: 220kV Chhapra(New) Amnour DCDS with Twin Moose Conductor
A3: EPC:- | C3: KEC International Limited
A4: S.NO. | B4: LOC. NO. | C4: TYPE OF TOWER | D4: ANGLE OF DEVATION | E4: RAISED CHIMNEY | F4: RAISED CHIMNEY | J4: SPAN | K4: Crossing Detail/Statutary | L4: ROW Status | M4: Foundation Status | N4: Contractor Name | O4: Earthing Status | P4: Erection Status | Q4: Contractor Name | R4: Tack Welding Status | S4: VILLAGES
F5: A | G5: B | H5: C | I5: D
A6: 1 | B6: 1/0 | C6: 2TNMD+0 | D6: 4° 59' 40"RT | F6: 0 | G6: 0 | H6: 0 | I6: 0 | J6: 102.49 | M6: HOLD | S6: KASTA
A7: =A6+1 -> 2 | B7: 2/0 | C7: 2TNMD+0 | D7: 29° 43' 51"RT | F7: 0 | G7: 0 | H7: 0 | I7: 0 | J7: 217.2 | M7: COMPLETED | N7: Nav Durga Traders | O7: COMPLETED | S7: KASTA
A8: =A7+1 -> 3 | B8: 3/0 | C8: 2TNMD+0 | D8: 29° 2' 31"RT | F8: 0 | G8: 0 | H8: 0 | I8: 0 | J8: 331.422 | M8: COMPLETED | N8: Nav Durga Traders | O8: COMPLETED | S8: KASTA
A9: =A8+1 -> 4 | B9: 3/1 | C9: 2TDD+9 | D9: 15° 32' 23"RT | F9: 0 | G9: 0 | H9: 0 | I9: 0 | J9: 186 | K9: Dabra River | M9: COMPLETED | N9: Nav Durga Traders | S9: KASTA
A10: =A9+1 -> 5 | B10: 6/0 | C10: 2TDC+0 | D10: 24° 37' 47"RT | F10: 0 | G10: 0 | H10: 0 | I10: 0 | J10: 217.97 | M10: COMPLETED | N10: Nav Durga Traders | O10: COMPLETED | P10: completed | Q10: YASHODA DEVI | S10: KASTA
A11: =A10+1 -> 6 | B11: 6/1 | C11: 2TDA+3 | F11: 0 | G11: 0 | H11: 0 | I11: 0 | J11: 330.8 | K11: Dabra River | M11: COMPLETED | N11: Nav Durga Traders | O11: COMPLETED | P11: completed | Q11: YASHODA DEVI | S11: KASTA
A12: =A11+1 -> 7 | B12: 7/0 | C12: 2TDD+0 | D12: 32° 58' 11"RT | F12: 0 | G12: 0 | H12: 0 | I12: 0 | J12: 218 | M12: COMPLETED | N12: Nav Durga Traders | O12: COMPLETED | P12: completed | Q12: SGSE | S12: MADARPUR
A13: =A12+1 -> 8 | B13: 7/1 | C13: 2TDA+0 | F13: 0 | G13: 0 | H13: 0 | I13: 0 | J13: 220.351 | M13: COMPLETED | N13: Nav Durga Traders | O13: COMPLETED | P13: completed | Q13: kumar k2 | S13: GOSI CHHAPRA
A14: =A13+1 -> 9 | B14: 8/0 | C14: 2TDC+0 | D14: 23° 15' 49"LT | F14: 0 | G14: 0 | H14: 0 | I14: 0 | J14: 190 | M14: COMPLETED | N14: Nav Durga Traders | O14: COMPLETED | P14: completed | Q14: RABISH | S14: GOSI CHHAPRA
A15: =A14+1 -> 10 | B15: 8/1 | C15: 2TDA+3 | F15: 0 | G15: 0 | H15: 0 | I15: 0 | J15: 260 | M15: COMPLETED | N15: Nav Durga Traders | O15: COMPLETED | P15: completed | Q15: kumar k2 | S15: GOSI CHHAPRA
A16: =A15+1 -> 11 | B16: 8/2 | C16: 2TDA+6 | F16: 0 | G16: 0 | H16: 0 | I16: 0 | J16: 323.052 | K16: Dabra River | M16: COMPLETED | N16: Nav Durga Traders | O16: COMPLETED | P16: completed | Q16: YASHODA DEVI | S16: MADARPUR
A17: =A16+1 -> 12 | B17: 9/0 | C17: 2TDC+6 | D17: 28° 36' 34"RT | F17: 0 | G17: 0 | H17: 0 | I17: 0 | J17: 246.023 | M17: COMPLETED | N17: Nav Durga Traders | O17: COMPLETED | S17: MADARPUR
A18: =A17+1 -> 13 | B18: 10/0 | C18: 2TDD+0 | D18: 32° 7' 44"RT | F18: 0 | G18: 0 | H18: 0 | I18: 0 | J18: 255 | K18: Dabra River | M18: COMPLETED | N18: Nav Durga Traders | O18: COMPLETED | P18: completed | Q18: SR Enterprises | S18: GAWANDRI
A19: =A18+1 -> 14 | B19: 10/1 | C19: 2TDA+3 | F19: 0 | G19: 0 | H19: 0 | I19: 0 | J19: 152 | M19: COMPLETED | N19: Nav Durga Traders | O19: COMPLETED | P19: completed | Q19: SR Enterprises | S19: MALAHI
A20: =A19+1 -> 15 | B20: 10/2 | C20: 2TDA+3 | F20: 0 | G20: 0 | H20: 0 | I20: 0 | J20: 294.498 | K20: Dabra River | M20: COMPLETED | N20: Nav Durga Traders | O20: COMPLETED | P20: completed | Q20: SR Enterprises | S20: MALAHI
A21: =A20+1 -> 16 | B21: 11/0 | C21: 2TDC+0 | D21: 22° 19' 24"RT | F21: 0 | G21: 0 | H21: 0 | I21: 0 | J21: 269 | M21: COMPLETED | N21: AR | O21: COMPLETED | P21: wip | Q21: YASHODA DEVI | S21: HAKMA
A22: =A21+1 -> 17 | B22: 11/1 | C22: 2TDA+3 | F22: 0 | G22: 0 | H22: 0 | I22: 0 | J22: 333 | M22: COMPLETED | N22: Nav Durga Traders | O22: COMPLETED | P22: completed | Q22: SR Enterprises | S22: HAKMA
A23: =A22+1 -> 18 | B23: 11/2 | C23: 2TDA+3 | F23: 0 | G23: 0 | H23: 0 | I23: 0 | J23: 257 | M23: COMPLETED | N23: Nav Durga Traders | O23: COMPLETED | P23: completed | Q23: SR Enterprises | S23: HAKMA
A24: =A23+1 -> 19 | B24: 11/3 | C24: 2TDA+0 | F24: 0 | G24: 0 | H24: 0 | I24: 0 | J24: 297 | M24: COMPLETED | N24: Nav Durga Traders | O24: COMPLETED | P24: completed | Q24: SR Enterprises | S24: SHIKARPUR
A25: =A24+1 -> 20 | B25: 11/4 | C25: 2TDA+0 | F25: 0 | G25: 0 | H25: 0 | I25: 0 | J25: 291.09 | M25: COMPLETED | N25: Nav Durga Traders | O25: COMPLETED | S25: SHIKARPUR
A26: =A25+1 -> 21 | B26: 12/0 | C26: 2TDD+0 | D26: 31° 35' 34"LT | F26: 0 | G26: 0 | H26: 0 | I26: 0 | J26: 235 | L26: ROW | S26: TARWAR
A27: =A26+1 -> 22 | B27: 12/1 | C27: 2TDA+6 | F27: 0 | G27: 0 | H27: 0 | I27: 0 | J27: 358.489 | S27: TARWAR
A28: =A27+1 -> 23 | B28: 13/0 | C28: 2TDD+18 | D28: 1° 10' 58"RT | F28: 0 | G28: 0 | H28: 0 | I28: 0 | J28: 231.686 | K28: 220kV D/C OHTL BGCL HJP-CHP | M28: COMPLETED | N28: Nav Durga Traders | O28: COMPLETED | S28: TARWAR
A29: =A28+1 -> 24 | B29: 14/0 | C29: 2TDD+25 | D29: 31° 48' 49"LT | F29: 0 | G29: 0 | H29: 0 | I29: 0 | J29: 209.429 | M29: COMPLETED | N29: Nav Durga Traders | O29: COMPLETED | S29: TARWAR
A30: =A29+1 -> 25 | B30: 15/0 | C30: 2TDD+9 | D30: 59° 5' 38"LT | E30: 2 | F30: 2 | G30: 2 | H30: 2 | I30: 2 | J30: 104.552 | K30: 220kV D/C OHTL BSPTCL ANR-MZP | M30: COMPLETED | N30: Nav Durga Traders | S30: TARWAR
A31: =A30+1 -> 26 | B31: 16/0 | C31: 2TDD+3 | D31: 59° 0' 51"LT | F31: 0 | G31: 0 | H31: 0 | I31: 0 | J31: 88.059 | M31: COMPLETED | N31: Nav Durga Traders
A32: =A31+1 -> 27 | B32: 17/0 | C32: 2TDD+0 | D32: 39° 49' 50"RT | F32: 0 | G32: 0 | H32: 0 | I32: 0 | J32: 72.888 | M32: COMPLETED | N32: Nav Durga Traders | O32: COMPLETED
A33: =A32+1 -> 28 | B33: 18/0 | C33: 2TDD+3 | D33: 54° 21' 38"RT | F33: 0 | G33: 0 | H33: 0 | I33: 0 | M33: COMPLETED | N33: Nav Durga Traders | O33: COMPLETED
J34: =SUM(J6:J33)/1000 -> 6.291999 | L34: FOUNDATION SUMMARY | N34: ERECTION SUMMARY
L35: Scope | M35: =COUNT(A6:A33) -> 28 | N35: Scope | O35: =COUNT(A6:A33) -> 28
L36: Completed | M36: =COUNTIF(M6:M33, "Completed") -> 25 | N36: Completed | O36: =COUNTIF(P6:P33,"Completed") -> 13
L37: WIP | M37: =COUNTIF(M6:M33, "WIP") -> 0 | N37: WIP | O37: =COUNTIF(P6:P33, "WIP") -> 1
L38: Frount Available | M38: 0 | N38: Frount Available | O38: =COUNTBLANK(P6:P33) -> 14
L39: Hold | M39: =COUNTIF(M6:M33, "HOLD") -> 1 | N39: Hold | O39: =COUNTIF(P6:P33, "HOLD") -> 0
L40: ROW | M40: 2 | N40: ROW | O40: =COUNTIF(P6:P33, "ROW") -> 0
...

Sheet VC 220 TM
C2: 46212
A3: 220kV Chhapra(New) Amnour DCDS with Twin Moose Conductor
A4: M/S KEC INTERNATIONAL LIMITED
A5: Progress Visual Chart
M7: LEGENDS
O8: TE Dt | P8: STG | T8: Major Power Line Crossing | W8: Railway Crossing | X8: River Crossing | Y8: Highway Crossing (SH & NH)
C9: Foundation Cumulative | H9: Nos. | J9: 25/28 | P9: Dt | S9: STG UP
C10: Earthing Cumulative | H10: Nos. | J10: 15/28 | M10: ERECTION
C11: Erection Cumulative | H11: Nos. | J11: 13/28 | O11: Date | P11: SPAN
C12: Stringing Payingout (RS) | H12: Km. | J12: 0.00/6.61 | M12: FOUNDATION | O12: Type
C13: Stringing Final sag Cumulative | H13: Km. | J13: 0.00/6.61
I14: ` | M14: Tower+Extn | O14: X+Y | P14: Suspn Tower | Q14: Earthing | S14: U/P
Q15: Angle Tower
M16: TOWER NO | O16: X/Y
W18: Cum Length | X18: Fdn Comp | Y18: Ear Comp | Z18: TE Comp | AA18: STG Comp
D22: 102.49 | F22: 217.2 | H22: 331.422 | J22: 186 | L22: 217.97 | N22: 253 | O22: WET | P22: 330.8 | Q22: WET 16.11.25 | R22: 218 | S22: WET | T22: 220.351 | W22: =SUM(A22:V22) -> 2077.233 | X22: 8 | Y22: 7 | Z22: 5 | AA22: 0 | AC22: 1022
O23: 23.09.25 | S23: 18.09.25
