Workbook
Name A_D: INDEX(#REF!,MATCH(#REF!,#REF!,0))
Name AA: INDEX(#REF!,MATCH(#REF!,#REF!,0))
Name AB: INDEX(#REF!,MATCH(#REF!,#REF!,0))
Name AC: INDEX(#REF!,MATCH(#REF!,#REF!,0))
Name AE: INDEX(#REF!,MATCH(#REF!,#REF!,0))
Name AF: INDEX(#REF!,MATCH(#REF!,#REF!,0))
Name AG: INDEX(#REF!,MATCH(#REF!,#REF!,0))
Name AH: INDEX(#REF!,MATCH(#REF!,#REF!,0))
Name AI: INDEX(#REF!,MATCH(#REF!,#REF!,0))
Name AJ: INDEX(#REF!,MATCH(#REF!,#REF!,0))
Name AK: INDEX(#REF!,MATCH(#REF!,#REF!,0))
Name AL: INDEX(#REF!,MATCH(#REF!,#REF!,0))
Name AM: INDEX(#REF!,MATCH(#REF!,#REF!,0))
Name BA: INDEX(#REF!,MATCH(#REF!,#REF!,0))
Name BB: INDEX(#REF!,MATCH(#REF!,#REF!,0))
Name BC: INDEX(#REF!,MATCH(#REF!,#REF!,0))
Name BD: INDEX(#REF!,MATCH(#REF!,#REF!,0))
Name BE: INDEX(#REF!,MATCH(#REF!,#REF!,0))
Name BF: INDEX(#REF!,MATCH(#REF!,#REF!,0))
Name BG: INDEX(#REF!,MATCH(#REF!,#REF!,0))
Name BH: INDEX(#REF!,MATCH(#REF!,#REF!,0))
Name BI: INDEX(#REF!,MATCH(#REF!,#REF!,0))
Name BJ: INDEX(#REF!,MATCH(#REF!,#REF!,0))
Name BK: INDEX(#REF!,MATCH(#REF!,#REF!,0))
Name BL: INDEX(#REF!,MATCH(#REF!,#REF!,0))
Name BM: INDEX(#REF!,MATCH(#REF!,#REF!,0))
Name CA: INDEX(#REF!,MATCH(#REF!,#REF!,0))
Name CB: INDEX(#REF!,MATCH(#REF!,#REF!,0))
Name CC: INDEX(#REF!,MATCH(#REF!,#REF!,0))
Name CD: INDEX(#REF!,MATCH(#REF!,#REF!,0))
Name CE: INDEX(#REF!,MATCH(#REF!,#REF!,0))
Name CF: INDEX(#REF!,MATCH(#REF!,#REF!,0))
Name CG: INDEX(#REF!,MATCH(#REF!,#REF!,0))
Name CH: INDEX(#REF!,MATCH(#REF!,#REF!,0))
Name CI: INDEX(#REF!,MATCH(#REF!,#REF!,0))
Name CJ: INDEX(#REF!,MATCH(#REF!,#REF!,0))
Name CK: INDEX(#REF!,MATCH(#REF!,#REF!,0))
Name CL: INDEX(#REF!,MATCH(#REF!,#REF!,0))
Name CM: INDEX(#REF!,MATCH(#REF!,#REF!,0))
Name D_D: INDEX(#REF!,MATCH(#REF!,#REF!,0))
Name DA: INDEX(#REF!,MATCH(#REF!,#REF!,0))
Name DB: INDEX(#REF!,MATCH(#REF!,#REF!,0))
Name DC: INDEX(#REF!,MATCH(#REF!,#REF!,0))
Name DE: INDEX(#REF!,MATCH(#REF!,#REF!,0))
Name DF: INDEX(#REF!,MATCH(#REF!,#REF!,0))
Name DG: INDEX(#REF!,MATCH(#REF!,#REF!,0))
Name DH: INDEX(#REF!,MATCH(#REF!,#REF!,0))
Name DI: INDEX(#REF!,MATCH(#REF!,#REF!,0))
Name DJ: INDEX(#REF!,MATCH(#REF!,#REF!,0))
Name DK: INDEX(#REF!,MATCH(#REF!,#REF!,0))
Name DL: INDEX(#REF!,MATCH(#REF!,#REF!,0))
Name DM: INDEX(#REF!,MATCH(#REF!,#REF!,0))
Name DPR: #REF!&#REF!&#REF!&#REF!&#REF!&#REF!&#REF!&#REF!&#REF!&#REF!
Name EA: INDEX(#REF!,MATCH(#REF!,#REF!,0))
Name EB: INDEX(#REF!,MATCH(#REF!,#REF!,0))
Name EC: INDEX(#REF!,MATCH(#REF!,#REF!,0))
Name ED: INDEX(#REF!,MATCH(#REF!,#REF!,0))
Name EE: INDEX(#REF!,MATCH(#REF!,#REF!,0))
Name EF: INDEX(#REF!,MATCH(#REF!,#REF!,0))
Name EG: INDEX(#REF!,MATCH(#REF!,#REF!,0))

Sheet 765kV Summery
C3: TB-507 | D3: DAILY PROGRESS REPORT | N3: =NOW()-1 -> 46245.364
A4: CONTRACTUAL START DATE: | C4: 45632 | D4: FATEGARH III-BEAWAR 765KV D/C TRANSMISSION LILO LINE
A5: CONTRACTUAL FINISH DATE: | C5: 46178
A6: REPORTING DATE | D6: Client Name : RAJASTHAN IV A POWER TRANSMISSION LTD
A7: TOTAL DAYS | D7: NOA Ref No(Supply): RIVA/LOA-KEC(SUP)/AUG 24/405
A8: COMP. DAYS | D8: NOA Ref No(Service): RIVA/LOA-KEC(SER)/AUG 24/406
A9: Progress Summary | N9: =N3 -> 46245.364
A10: Sl No. | B10: Activity | C10: LOA Quantity | D10: Estimated Line Quantity | E10: Cumm. Progress till Last Month | F10: Plan For Aug'26 | G10: Progress in Aug'26 | H10: WIP | I10: Today's Progress | J10: Cumulative progress till date | K10: Balance | L10: ="Gangs working "&CHAR(10)&TEXT(N3,"mmm-yy") -> Gangs working Aug-26 | M10: Manpower | N10: Remarks
A11: A.i | B11: Route Alignment (Kms) | C11: 15.478 | D11: 15.478 | E11: 15.478 | F11: 0 | G11: 0 | H11: 0 | I11: 0 | J11: 15.478 | K11: =D11-J11 -> 0
A12: ii | B12: Detailed Survey (Kms) | C12: 15.478 | D12: 15.478 | E12: 15.478 | F12: 0 | G12: 0 | H12: 0 | I12: 0 | J12: 15.478 | K12: =D12-J12 -> 0
A13: iii | B13: Check Survey (Kms) | C13: 15.478 | D13: 15.478 | E13: 15.478 | F13: 0 | G13: 0 | H13: 0 | I13: 0 | J13: 15.478 | K13: =D13-J13 -> 0
A14: B. | B14: Soil Investigation (Nos) | C14: 26 | D14: 26 | E14: 26 | F14: 0 | G14: 0 | H14: 0 | I14: 0 | J14: 26 | K14: 0
A15: C. | B15: Foundation (Nos) | C15: 43 | D15: 43 | E15: 41 | F15: 2 | G15: 0 | H15: 1 | J15: =SUM(E15+G15) -> 41 | K15: =D15-J15 -> 2 | L15: 1 | M15: 13 | N15: WIP:6/0 LO ; Balance Work Stopped due to Row by New Solar Agency LI- 2/0
A16: D. | B16: Earthing (Nos) | C16: 43 | D16: 43 | E16: 3 | F16: =J15-E16+F15 -> 40 | G16: 0 | I16: 0 | J16: =SUM(E16+G16) -> 3 | K16: =D16-J16 -> 40
A17: E. | B17: Tower Erection (Nos) | C17: 43 | D17: 43 | E17: 21 | F17: 21 | G17: 4 | H17: 1 | J17: =SUM(E17+G17) -> 25 | K17: =D17-J17 -> 18 | L17: 2 | M17: 56 | N17: Completed:4/3(LI); WIP: LO: 3/0
A18: F. | B18: Tack Welding (Nos) | C18: 43 | D18: 43 | E18: 5 | F18: =K17-E18 -> 13 | G18: 0 | J18: =E18+G18 -> 5 | K18: =D18-J18 -> 38
A19: G. | B19: Stringing (Kms) | K19: =D19-J19 -> 0
A20: i | B20: Paying Out (Kms) | C20: 15.478 | D20: 15.478 | E20: 0 | F20: 5.863 | G20: 0 | J20: =E20+G20 -> 0 | K20: =D20-J20 -> 15.478
A21: ii | B21: Final Sag (Kms) | C21: 15.478 | D21: 15.478 | E21: 0 | F21: 5.863 | G21: 0 | J21: =E21+G21 -> 0 | K21: =D21-J21 -> 15.478
A22: I. | B22: OPGW Stringing (Kms) | C22: 15.478 | D22: 15.478 | E22: 0 | J22: =E22+G22 -> 0 | K22: =D22-J22 -> 15.478
K23: =D23-J23 -> 0

Sheet Check Survey Status
A1: NAME OF PROJECT : FARHEGARH IV-BHINMAL 400KV D/C TRANSMISSION LINE
A2: Client : RAJASTHAN IV A POWER TRANSMISSION LTD.
A3: CONTRACTOR : KEC INTERNATIONAL LIMITED
A4: 400 KV CHECK SURVEY
A5: SL No | B5: Section | C5: Section Length | D5: Submission Date | E5: Approval Date | F5: Remarks
A6: 1 | B6: AP 51- AP 54 | C6: 2.653 | D6: 45684 | E6: 45691 | F6: Approved
A7: =A6+1 -> 2 | B7: AP 54- AP 60 | C7: 5.31 | F7: Approved
A8: =A7+1 -> 3 | B8: AP 60- AP 75 | C8: 19.672 | D8: 15.02.2025 , 24-02-2025 25-02-2025 | E8: 45713 | F8: Approved | G8: Required Change
A9: =A8+1 -> 4 | B9: AP 75- AP 92 | C9: 20.273 | D9: 45657 | E9: 45691 | F9: Approved
A10: =A9+1 -> 5 | B10: AP 92- AP 96 | C10: 3.084 | D10: 15-02-25 & 21-02-2025 | E10: 45712 | F10: Approved
A11: =A10+1 -> 6 | B11: AP 96- AP 97 | C11: 1.063 | D11: 45713 | E11: 45715 | F11: Approved
A12: =A11+1 -> 7 | B12: AP 97- AP 98B | C12: 2.09 | D12: 45713 | F12: Approved
A13: =A12+1 -> 8 | B13: AP 98B- 99A/0 | C13: 3.893 | D13: 45713 | F13: Approved
A14: =A13+1 -> 9 | B14: AP99A/0-AP 107 | C14: 6.971 | D14: 45713 | F14: Approved
A15: =A14+1 -> 10 | B15: AP 107- AP 121 | C15: 9.495 | D15: 45721 | E15: 45722 | F15: Approved
A16: =A15+1 -> 11 | B16: AP 121- AP 131 | C16: 8.697 | D16: 12-03-2025 & ReSubmission 4-04-2025 | F16: Submitted | G16: Resubmitted
A17: =A16+1 -> 12 | B17: AP 131- AP 133 | C17: 3.084 | F17: Submitted
A18: =A17+1 -> 13 | B18: AP 133- AP 134 | C18: 3.963 | F18: Submitted
A19: =A18+1 -> 14 | B19: AP 134- AP 135 | C19: 1.656 | F19: Submitted
A20: =A19+1 -> 15 | B20: AP 135- AP 136 | C20: 1.635 | F20: Submitted
A21: =A20+1 -> 16 | B21: AP 136 - AP 139 | C21: 2.221 | F21: Submitted
A22: =A21+1 -> 17 | B22: AP 139 - AP 147 | C22: 10.724 | D22: 26-03-2025 Resubmission 4-04-2025 &28-04-25 | F22: Submitted | G22: Resubmitted
A23: =A22+1 -> 18 | B23: AP 147/0 - AP 148 | C23: 3.666 | D23: 26-03-2025 Resubmission 4-04-2025 & 28-04-25 | F23: Submitted | G23: Resubmitted
A24: =A23+1 -> 19 | B24: AP148/0 - AP 149B | C24: 4.88 | F24: Submitted
A25: =A24+1 -> 20 | B25: AP 150 to Bhinmal GTY | C25: 2.474 | D25: 45765 | F25: Submitted
A26: =A25+1 -> 21 | B26: AP 50- AP 51 | C26: 0.275 | D26: 45752 | F26: Submitted
A27: =A26+1 -> 22 | B27: AP 47- AP 50 | C27: 2.008 | D27: 45752 | F27: Submitted
A28: =A27+1 -> 23 | B28: AP 46- AP 47 | C28: 0.223 | D28: 45752 | F28: Submitted
A29: =A28+1 -> 24 | B29: AP 42- AP 43 | C29: 2.731 | D29: 45752 | F29: Submitted
A30: =A29+1 -> 25 | B30: AP 45- AP 46 | C30: 1.717 | D30: 45752 | F30: Submitted
A31: =A30+1 -> 26 | B31: AP 43- AP 45 | C31: 1.068 | D31: 45752 | F31: Submitted
A32: =A31+1 -> 27 | B32: AP 40- AP 42 | C32: 2.873 | D32: 45752 | F32: Submitted
A34: =A32+1 -> 28 | B34: AP 10- AP 21 | C34: 19.57 | D34: 16-04-2025 & 16.05.2025 | F34: Re Submitted
A35: =A34+1 -> 29 | B35: 21/0-24/0 | C35: 2.618 | D35: 45781 | F35: Complete
A36: =A35+1 -> 30 | B36: 24/0-40/0 | C36: 18.193 | D36: 45805 | F36: Complete
B39: AS on date | C39: =SUM(C6:C36) -> 168.78
B43: Submission of Check Survey
A44: SL. No. | B44: Section | C44: Date of submission | D44: Section Length in kms | E44: Letter Reference Number | F44: Date of Approval | G44: Section Length in kms
A45: 1 | B45: AP75 To AP92 | C45: 45657 | D45: 20.273 | E45: KEC/FBTL/RPTL/TB507/008A | F45: 45691 | G45: 20.273
A46: =A45+1 -> 2 | B46: AP51 To AP60 | C46: 45684 | D46: 7.962 | E46: KEC/FBTL/RPTL/TB507/0014 | F46: 45691 | G46: 7.962
...

Sheet Check Survey
A1: NAME OF PROJECT : FARHEGARH IV-BHINMAL 400KV D/C TRANSMISSION LINE
A2: Client : RAJASTHAN IV A POWER TRANSMISSION LTD.
A3: CONTRACTOR : KEC INTERNATIONAL LIMITED
A4: 400 KV CHECK SURVEY
A5: SL No | B5: Section | C5: Section Length | D5: Submission Date | E5: Approval Date | F5: Remarks
A6: 1 | B6: AP 51- AP 54 | C6: 2.653 | D6: 45684 | E6: 45691 | F6: Approved
A7: =A6+1 -> 2 | B7: AP 54- AP 60 | C7: 5.31 | F7: Approved
A8: =A7+1 -> 3 | B8: AP 60- AP 75 | C8: 19.672 | D8: 15.02.2025 , 24-02-2025 25-02-2025 | E8: 45713 | F8: Approved | G8: Required Change | H8: Approved | I8: =G63 -> 97.59
A9: =A8+1 -> 4 | B9: AP 75- AP 92 | C9: 20.273 | D9: 45657 | E9: 45691 | F9: Approved
A10: =A9+1 -> 5 | B10: AP 92- AP 96 | C10: 3.084 | D10: 15-02-25 & 21-02-2025 | E10: 45712 | F10: Approved | H10: Submitted | I10: =D63 -> 151.916
A11: =A10+1 -> 6 | B11: AP 96- AP 97 | C11: 1.063 | D11: 45713 | E11: 45715 | F11: Approved
A12: =A11+1 -> 7 | B12: AP 97- AP 98B | C12: 2.09 | D12: 45713 | F12: Approved
A13: =A12+1 -> 8 | B13: AP 98B- 99A/0 | C13: 3.893 | D13: 45713 | F13: Approved
A14: =A13+1 -> 9 | B14: AP99A/0-AP 107 | C14: 6.971 | D14: 45713 | F14: Approved
A15: =A14+1 -> 10 | B15: AP 107- AP 121 | C15: 9.495 | D15: 45721 | E15: 45722 | F15: Approved
A16: =A15+1 -> 11 | B16: AP 121- AP 131 | C16: 8.697 | D16: 12-03-2025 & ReSubmission 4-04-2025 | F16: Submitted | G16: Resubmitted
A17: =A16+1 -> 12 | B17: AP 131- AP 133 | C17: 3.084 | F17: Submitted
A18: =A17+1 -> 13 | B18: AP 133- AP 134 | C18: 3.963 | F18: Submitted
A19: =A18+1 -> 14 | B19: AP 134- AP 135 | C19: 1.656 | F19: Submitted
A20: =A19+1 -> 15 | B20: AP 135- AP 136 | C20: 1.635 | F20: Submitted
A21: =A20+1 -> 16 | B21: AP 136 - AP 139 | C21: 2.221 | F21: Submitted
A22: =A21+1 -> 17 | B22: AP 139 - AP 147 | C22: 10.724 | D22: 26-03-2025 Resubmission 4-04-2025 &28-04-25 | F22: Submitted | G22: Resubmitted
A23: =A22+1 -> 18 | B23: AP 147/0 - AP 148 | C23: 3.666 | D23: 26-03-2025 Resubmission 4-04-2025 & 28-04-25 | F23: Submitted | G23: Resubmitted | M23: Blance | N23: =187.176-M11 -> 187.176
A24: =A23+1 -> 19 | B24: AP148/0 - AP 149B | C24: 4.88 | F24: Submitted
A25: =A24+1 -> 20 | B25: AP 150 to Bhinmal GTY | C25: 2.474 | D25: 45765 | F25: Submitted
A26: =A25+1 -> 21 | B26: AP 50- AP 51 | C26: 0.275 | D26: 45752 | F26: Submitted
A27: =A26+1 -> 22 | B27: AP 47- AP 50 | C27: 2.008 | D27: 45752 | F27: Submitted
A28: =A27+1 -> 23 | B28: AP 46- AP 47 | C28: 0.223 | D28: 45752 | F28: Submitted
A29: =A28+1 -> 24 | B29: AP 42- AP 43 | C29: 2.731 | D29: 45752 | F29: Submitted
A30: =A29+1 -> 25 | B30: AP 45- AP 46 | C30: 1.717 | D30: 45752 | F30: Submitted
A31: =A30+1 -> 26 | B31: AP 43- AP 45 | C31: 1.068 | D31: 45752 | F31: Submitted
A32: =A31+1 -> 27 | B32: AP 40- AP 42 | C32: 2.873 | D32: 45752 | F32: Submitted
A34: =A32+1 -> 28 | B34: AP 10- AP 21 | C34: 19.57 | D34: 16-04-2025 & 16.05.2025 | F34: Re Submitted
A35: =A34+1 -> 29 | B35: 21/0-24/0 | C35: 2.618 | D35: 45781 | F35: Complete
A36: =A35+1 -> 30 | B36: 24/0-40/0 | C36: 18.193 | D36: 45805 | F36: Complete | I36: =155.849-130.528 -> 25.321
B39: AS on date | C39: =SUM(C6:C36) -> 168.78
B43: Submission of Check Survey
A44: SL. No. | B44: Section | C44: Date of submission | D44: Section Length in kms | E44: Letter Reference Number | F44: Date of Approval | G44: Section Length in kms | H44: Approved By | I44: Remarks
A45: 1 | B45: AP75 To AP92 | C45: 45657 | D45: 20.273 | E45: KEC/FBTL/RPTL/TB507/008A | F45: 45691 | G45: 20.273 | H45: Gundewadi Mallappa
A46: =A45+1 -> 2 | B46: AP51 To AP60 | C46: 45684 | D46: 7.962 | E46: KEC/FBTL/RPTL/TB507/0014 | F46: 45691 | G46: 7.962 | H46: Gundewadi Mallappa
...

Sheet Sheet8
A1: S No. | B1: MOM as on 11/6/25 | C1: Timeline | D1: Responsibility | E1: Status as on 19/6/25
A2: 1 | B2: 400kv Detail Survey from AP 01 to AP 10
A3: a | B3: Apraava will give clearance for further proceeding of Detail Survey | C3: 45821 | D3: M/S Apraava | E3: Clearance provided for Detail Survey
A4: b | B4: Completion of Detail Survey | C4: 45833 | D4: M/S KEC | E4: Detail Survey work under progress
A5: c | B5: Detail Survey of 765 kV is submitted by KEC, observation raised by Apraava, KEC has to re-submitted according to observation | C5: 45824 | D5: M/S KEC | E5: Reobservation mail by Engg. Team on dt. 19.06.25
A6: 2 | B6: Check Survey
A7: a | B7: 50 km will be approved | C7: 45820 | D7: M/S Apraava & KEC | E7: 33 km Approved & 15 km submitted by KEC
A8: b | B8: Pending Section of 21 km will be approved | C8: 45828 | D8: M/S Apraava & KEC | E8: Under Progress
A9: c | B9: Check Survey of 765kV is to be submitted by KEC | C9: 46198 | D9: M/S KEC | E9: Detail Survey work under progress
A10: 3 | B10: Statutory Approvals
A11: a | B11: 02 No NH Proposal Submission | C11: 45838 | D11: M/S KEC | E11: Under Progress
A12: b | B12: 02 No Railway Proposal Submission | C12: 45838 | D12: M/S KEC | E12: Under Progress
A13: c | B13: 02 Nos PLC Proposal of 400 kV Underneath has to Submit | C13: ASAP | D13: M/S KEC | E13: Under Progress
A14: d | B14: Statutory Approvals tracker to be maintain for monitoring current status of NOC | C14: N/A | D14: M/S Apraava & KEC | E14: Under Progress
A15: e | B15: 04 Submission of SH Proposal to SH Authority | C15: 45828 | D15: M/S Apraava | E15: Under Progress
A16: f | B16: 03 Submission of Oil Proposal to Oil Authority | C16: 45828 | D16: M/s Apraava | E16: Under Progress
A17: 4 | B17: Deployment of surveyor, supervisors, engineers & section in charge to be expedite in Bhinmal Section | C17: 45820 | D17: M/S KEC | E17: Under Progress
A18: 5 | B18: KEC committed 43 nos. foundation for this month & accordingly Apraava will provide ROW clearance | C18: 45838 | D18: M/S Apraava & KEC | E18: Till date 13 foundations completed, 10 are in WIP and 30 work fronts are available
A19: 6 | B19: Manpower in each foundation gang need to be strengthen with at least 8-10 manpower/gang | C19: ASAP | D19: M/S KEC | E19: Under Progress
A20: 7 | B20: Apraava asked to increase 4 more foundation gangs to expedite foundation work (currently 7 gangs are available with insufficient manpower | C20: ASAP | D20: M/S KEC | E20: 9 Gangs are available (insufficient manpower in 4 gangs)
A21: 8 | B21: 40 Nos Departmental Manpower availability at site | C21: 45838 | D21: M/S KEC | E21: -
A22: 9 | B22: Quality Constraints
A23: a | B23: Information regarding supply of cement with prior & proper documentation | C23: N/A | D23: M/S KEC | E23: -
A24: b | B24: Material availability at site from approved source | C24: - | D24: M/S KEC | E24: -
A25: c | B25: Approval of use of Curing compound in foundation work need to be expedite after jointly discussion of both team | C25: ASAP | D25: M/S Apraava & KEC | E25: Cubes taken after applying curing compound & further process is u/p
A26: d | B26: CTM Machine at store need be installed on priority for cube testing | C26: 45821 | D26: M/S KEC | E26: Under Progress
A27: 10 | B27: Erection team to be deployed and erection to be start | C27: 45826 | D27: M/S KEC | E27: Erection to be start by Monday, 23/6/25
A28: 11 | B28: July month foundation & erection plan to be shared by KEC | C28: 45824 | D28: M/S KEC | E28: July month plan to be shared within 2-3 days by KEC
A29: 12 | B29: Supply of conductor to be start in September month | C29: 45930 | D29: M/S Apraava | E29: Planned for September month
A30: 13 | B30: Total 121 nos. of DA type of tower supplied to store & 2nd lot of 74 nos. towers (approx. 1500 MT) supply, consisting of DC & DD type towers are scheduled for next month | C30: 45848 | D30: M/S KEC | E30: DA type towers are supplied

Sheet Sheet2
C2: 400kV D/C Fatehgarh IV (Section-2)PS - Bhinmal (PG) Transmission Line
C4: Sl No | D4: Section AP To AP | E4: Section length | F4: Remarks
C5: 1 | D5: AP-21/0 To AP-24/0 | E5: 2.618
C6: =C5+1 -> 2 | D6: AP-24/0 To AP-27/0 | E6: 1.428
C7: =C6+1 -> 3 | D7: AP-27/0 To AP-40/0 | E7: 16.76
C8: =C7+1 -> 4 | D8: AP-45/0 To AP-48/0 | E8: 3.187
C9: =C8+1 -> 5 | D9: AP-153/0 To AP-154/0 | E9: 0.732
C10: =C9+1 -> 6 | D10: AP-154/0 To AP-155/0 | E10: 0.218
C11: =C10+1 -> 7 | D11: AP-155/0 To S/S Gantry | E11: 0.571
D12: TOTAL | E12: =SUM(E5:E11) -> 25.514
C14: 765kV D/C Fatehgarh IV (Section-2)PS - Bhinmal (PG) Transmission Line
C16: Sl No | D16: Section AP To AP | E16: Section length | F16: Route Allignment,Detail Survey,Check survey
D17: LI | E17: =7584/1000 -> 7.584
D18: LO | E18: =6951/1000 -> 6.951
D19: TOTAL | E19: =SUM(E17:E18) -> 14.535

Sheet Sheet1
B1: FOUNDATION STATUS | J1: =SUBTOTAL(3,J5:J24) -> 18
B2: SL. No. | C2: Location Number | D2: Span | E2: Tower Type | F2: RC | G2: Foundation type
H3: Starting date | I3: Completion Date | J3: Agency | K3: Remark | L3: Remarks
B4: 1 | C4: 83/1 | D4: 83/1 | E4: DA+3 | G4: Sandy | H4: 45665 | I4: 45674 | J4: Mahadeep Company | K4: 45674 | L4: Complete
B5: =B4+1 -> 2 | C5: 81/4 | D5: 81/4 | E5: DA+0 | G5: Sandy | H5: 45675 | I5: ROW | J5: Mahadeep Company | K5: ROW LOC HOLD | L5: Row Since 20-01-2025, Gang Domobilized
B6: =B5+1 -> 3 | C6: 75/7 | D6: 75/7 | E6: DA+0 | G6: Sandy | H6: 45675 | I6: 45684 | J6: AR PATEL | L6: RCC Complete
B7: =B6+1 -> 4 | C7: 75/6 | E7: DA+0 | G7: Sandy | H7: 45685 | I7: 45690 | J7: AR PATEL | L7: RCC Complete, Backfilling Done
B8: =B7+1 -> 5 | C8: 75/5 | E8: DA+0 | G8: Sandy | H8: 45685 | I8: 45693 | J8: AR PATEL | L8: RCC Complete.
B9: =B8+1 -> 6 | C9: 75/4 | E9: DA+0 | G9: Sandy | H9: 45686 | I9: 45693 | J9: Om Constraction | L9: RCC Complete, Backfilling Done
B10: =B9+1 -> 7 | C10: 75/3 | E10: DA+3 | G10: Sandy | H10: 45691 | I10: 45698 | J10: Om Constraction | L10: RCC Complete.
B11: =B10+1 -> 8 | C11: 75/1 | E11: DA+0 | G11: Sandy | H11: 45697 | I11: 45705 | J11: Om Constraction | L11: RCC Complete.
B12: =B11+1 -> 9 | C12: 75/2 | E12: DA+0 | G12: Sandy | H12: 45700 | I12: 45706 | J12: Om Constraction | L12: RCC Complete.
B13: =B12+1 -> 10 | C13: 77/1 | E13: DA+0 | G13: Sandy | H13: 45691 | I13: 45699 | J13: Anjaana Construction | L13: RCC Complete.
B14: =B13+1 -> 11 | C14: 77/2 | E14: DA+3 | G14: Sandy | H14: 45691 | I14: 45697 | J14: AR PATEL | L14: RCC Complete, Backfilling Done
B15: =B14+1 -> 12 | C15: 77/3 | E15: DA+0 | G15: Sandy | H15: 45696 | I15: 45702 | J15: AR PATEL | L15: RCC Complete.
B16: =B15+1 -> 13 | C16: 77/4 | E16: DA+3 | G16: Sandy | H16: 42046 | I16: 45705 | J16: Anjaana Construction | L16: RCC Complete.
B17: =B16+1 -> 14 | C17: 77/5 | E17: DA+6 | G17: Sandy | H17: 45701 | J17: AR PATEL | L17: Pit B,C RCC Done & Pit A,D Frustrum RCC done.
B18: =B17+1 -> 15 | C18: 86/2 | E18: DA+0 | G18: Sandy | H18: 45698 | J18: Kalpana Enterprises | L18: Pit A , Pit B RCC Done , Pit C -Stub setting.
B19: =B18+1 -> 16 | C19: 66/1 | E19: DA+9 | G19: Sandy | H19: 45705 | J19: Siyag Construction | L19: Excavation WIP, ROW,Material Shifting WIP
B20: =B19+1 -> 17 | C20: 73/3 | E20: DA+9 | G20: Sandy | H20: 45705 | J20: Om Constraction | L20: Excavation WIP, ROW, Material Shifting WIP
B21: =B20+1 -> 18 | C21: 79/1 | E21: DA+9 | G21: Sandy | H21: 45705 | J21: Anjana Construction | L21: Excavation WIP, ROW, Material Shifting WIP
B22: =B21+1 -> 19 | C22: 95A/1 | E22: DA+0 | G22: Sandy | J22: Gurukripa Enterprises | L22: Pit Marking Done
B23: =B22+1 -> 20 | C23: 80/1
B24: =B23+1 -> 21 | C24: 85/1
B25: =B24+1 -> 22 | C25: 73/2
B26: =B25+1 -> 23 | C26: 66/2
B27: =B26+1 -> 24 | C27: 66/3
B28: =B27+1 -> 25 | C28: 86/1
B29: =B28+1 -> 26 | C29: 76/1

Sheet VC 51-96
B1: TB-507 400 KV (Twin) D/C Fatehgarh IV - Bhinmal Transmission Line
A2: DPR and VISUAL CHART
A4: DPR- | D4: District | F4: No.Of Towers | G4: Length | H4: Foundation | K4: Earthing | L4: Tower Erection | O4: Stringing
H5: Com | I5: WIP | J5: Bal | K5: Com | L5: Com | M5: WIP | N5: Bal | O5: Com | P5: WIP | Q5: Bal
F6: 163 | G6: 50.886 | H6: 16 | I6: 5 | J6: =F6-H6-I6 -> 142 | K6: 10 | N6: =F6-L6 -> 163 | Q6: =G6-O6 -> 50.886
C8: =A8+1 -> 1 | E8: =C8+1 -> 2 | G8: =E8+1 -> 3 | I8: =G8+1 -> 4 | K8: =I8+1 -> 5 | M8: =K8+1 -> 6 | O8: =M8+1 -> 7 | Q8: =O8+1 -> 8 | S8: =Q8+1 -> 9
D10: 465.03 | F10: 375.98 | H10: 414.86 | J10: 381.02 | L10: 353.63 | N10: 351.4 | P10: 433.26 | R10: 396.56 | T10: 408.11 | U10: =B10+F10+H10+J10+L10+D10+N10+P10+R10+T10 -> 3579.85
C13: AP51 | E13: 51/1 | G13: 51/2 | I13: 51/3 | K13: AP52 | M13: 52/1 | O13: AP53 | Q13: AP54 | S13: 54/1
C14: DD+18 | E14: DA+03 | G14: DA+00 | I14: DA+03 | K14: DB+0 | M14: DA+06 | O14: DD+0 | Q14: DC+00 | S14: DA+03
K15: RC | M15: RC
B17: =S8+1 -> 10 | D17: =B17+1 -> 11 | F17: =D17+1 -> 12 | H17: =F17+1 -> 13 | J17: =H17+1 -> 14 | L17: =J17+1 -> 15 | N17: =L17+1 -> 16 | P17: =N17+1 -> 17 | R17: =P17+1 -> 18 | T17: =R17+1 -> 19
C19: 425.22 | E19: 420.54 | G19: 340.56 | I19: 336.52 | K19: 375.99 | M19: 303.41 | O19: 448.76 | Q19: 393.09 | S19: 407.8 | U19: 206.06 | V19: =C19+G19+I19+K19+M19+E19+O19+Q19+S19+U19 -> 3657.95
B22: 54/2 | D22: 54/3 | F22: AP55 | H22: AP56 | J22: 56/1 | L22: 56/2 | N22: 56/3 | P22: 56/4 | R22: 56/5 | T22: AP57
B23: DA+06 | D23: DA+03 | F23: DD+18 | H23: DB+09 | J23: DB+9 | L23: DA+0 | N23: DB+9 | P23: DA+6 | R23: DA+6 | T23: DB+09
B24: Benching &RC | D24: RC | F24: RC | H24: Benching &RC | L24: Benching Required | R24: Benching &RC | T24: Benching &RC
B26: =T17+1 -> 20 | D26: =B26+1 -> 21 | F26: =D26+1 -> 22 | H26: =F26+1 -> 23 | J26: =H26+1 -> 24 | L26: =J26+1 -> 25 | N26: =L26+1 -> 26 | P26: =N26+1 -> 27 | R26: =P26+1 -> 28 | T26: =R26+1 -> 29
C28: 417.38 | E28: 304.56 | G28: 408.66 | I28: 434.89 | K28: 408.17 | M28: 398.59 | O28: 446.37 | Q28: 297.58 | S28: 240.47 | U28: 312.69 | V28: =C28+G28+I28+K28+M28+E28+O28+Q28+S28+U28 -> 3669.36
B31: AP58 | D31: AP59 | F31: 59/1 | H31: AP60 | J31: 60/1 | L31: 60/2 | N31: 60/3 | P31: AP61 | R31: 61/1 | T31: AP62
B32: DB+09 | D32: DC+09 | F32: DA+0 | H32: DD+00 | J32: DA+9 | L32: DA+0 | N32: DA+9 | P32: DC+00 | R32: DA+9 | T32: DB+00
F33: Benching | N33: RC
B35: =T26+1 -> 30 | D35: =B35+1 -> 31 | F35: =D35+1 -> 32 | H35: =F35+1 -> 33 | J35: =H35+1 -> 34 | L35: =J35+1 -> 35 | N35: =L35+1 -> 36 | P35: =N35+1 -> 37 | R35: =P35+1 -> 38 | T35: =R35+1 -> 39
C37: 347.88 | E37: 379.25 | G37: 398.7 | I37: 439.06 | K37: 381.53 | M37: 379.71 | O37: 426.3 | Q37: 387.14 | U37: 423.77 | V37: =C37+G37+I37+K37+M37+E37+#REF!+O37+Q37+#REF! -> #REF!
B40: 62/1 | D40: 62/2 | F40: 62/3 | H40: 62/4 | J40: 62/5 | L40: AP63 | N40: 63/1 | P40: AP64 | R40: 64/1 | T40: 64/2
B41: DA+0 | D41: DA+0 | F41: DA+09 | H41: DA+06 | J41: DA+06 | L41: DC+00 | N41: DA+0 | P41: DC+09 | R41: DA+9 | T41: DA+9
B42: RC | F42: RC | P42: Benching &RC | T42: RC
B43: =T35+1 -> 40 | D43: =B43+1 -> 41 | F43: =D43+1 -> 42 | H43: =F43+1 -> 43 | J43: =H43+1 -> 44 | L43: =J43+1 -> 45 | N43: =L43+1 -> 46 | P43: =N43+1 -> 47 | R43: =P43+1 -> 48 | T43: =R43+1 -> 49
C45: 407.9 | E45: 426.63 | G45: 392.27 | I45: 431.96 | K45: 426.02 | M45: 405.36 | O45: 411.93 | Q45: 423.77 | S45: 407.9 | U45: 426.63
B46: F | D46: WIP | R46: F | T46: F
B48: 64/3 | D48: 64/4 | F48: 64/5 | H48: 64/6 | J48: 64/7 | L48: 65/0 | N48: 65/1 | P48: 66/0 | R48: 66/1 | T48: 66/2
B49: DA+9 | D49: DA+9 | F49: DA+9 | H49: DA+3 | J49: DA+3 | L49: DD+0 | N49: DB+09 | P49: DD+0 | R49: DA+9 | T49: DA+0 | V49: =#REF!+I77+K77+M77+O77+G77+Q77+S77+#REF!+#REF! -> #REF!
P50: RC
B51: =T43+1 -> 50 | D51: =B51+1 -> 51 | F51: =D51+1 -> 52 | H51: =F51+1 -> 53 | J51: =H51+1 -> 54 | L51: =J51+1 -> 55 | N51: =L51+1 -> 56 | P51: =N51+1 -> 57 | R51: =P51+1 -> 58 | T51: =R51+1 -> 59
C53: 392.27 | E53: 431.96 | G53: 426.02 | I53: 405.36 | K53: 411.93 | M53: 350.33 | O53: 378.3 | Q53: 416.82 | S53: 371.85
B54: WIP
B56: 66/3 | D56: 66/4 | F56: 67/0 | H56: 67/1 | J56: 67/2 | L56: AP68 | N56: AP69 | P56: 69/1 | R56: 69/2 | T56: 69/3
B57: DA+3 | D57: DA+9 | F57: DC+6 | H57: DA+6 | J57: DB+0 | L57: DB+09 | N57: DD+3 | P57: DA+6 | R57: DA+0 | T57: DA+00
F58: RC | R58: Benching | T58: RC | V58: =A85+I77+K77+M77+O77+G77+Q77+S77+#REF!+C77 -> #REF!
B59: =T51+1 -> 60 | D59: =B59+1 -> 61 | F59: =D59+1 -> 62 | H59: =F59+1 -> 63 | J59: =H59+1 -> 64 | L59: =J59+1 -> 65 | N59: =L59+1 -> 66 | P59: =N59+1 -> 67 | R59: =P59+1 -> 68 | T59: =R59+1 -> 69
C61: 392.27 | E61: 431.96 | G61: 426.02 | I61: 405.36 | K61: 411.93 | M61: 350.33 | O61: 378.3 | Q61: 416.82 | S61: 371.85
T62: F
...

Sheet VC
C2: TB-507 400 KV (Twin) D/C Fatehgarh IV - Bhinmal Transmission Line
C3: DPR and VISUAL CHART
C5: DPR- | F5: District | H5: No.Of Towers | I5: Length | J5: Foundation | M5: Earthing | N5: Tower Erection | Q5: Stringing
J6: Com | K6: WIP | L6: Bal | M6: Com | N6: Com | O6: WIP | P6: Bal | Q6: Com | R6: WIP | S6: Bal
H7: 495 | I7: 187.175 | J7: 9 | K7: 5 | L7: =H7-J7-K7 -> 481 | M7: 3 | P7: =H7-N7 -> 495 | S7: =I7-Q7 -> 187.175
I8: r
C9: 1 | E9: =C9+1 -> 2 | G9: =E9+1 -> 3 | I9: =G9+1 -> 4 | K9: =I9+1 -> 5 | M9: =K9+1 -> 6 | O9: =M9+1 -> 7 | Q9: =O9+1 -> 8 | S9: =Q9+1 -> 9 | U9: =S9+1 -> 10
D11: 97.4 | F11: 139.42 | H11: 484.04 | J11: 398 | L11: 443.16 | N11: 399.53 | P11: 402.87 | R11: 437.15 | T11: 381.84 | V11: 416.91 | W11: =D11+H11+J11+L11+N11+F11+P11+R11+T11+V11 -> 3600.32 | X11: FDN | Y11: TE | Z11: Earthing | AA11: Stringing | AC11: Tack Welding | AE11: =SUM(D11:V11) -> 3600.32
A12: 1 | X12: =COUNTIF(C12:U12,"F") -> 0 | Y12: =COUNTIF(C11:U11,"E") -> 0 | Z12: =COUNTIF(C13:V13,"Er") -> 0 | AB12: COM
X13: =COUNTIF(C13:U13,"U/P") -> 0 | Y13: 0 | Z13: 0 | AB13: WIP
C14: GE | E14: AP1 | G14: AP2 | I14: AP3 | K14: 03/1 | M14: 3/2 | O14: 3/3 | Q14: 3/4 | S14: 3/5 | U14: 3/6 | X14: =COUNTIF(C12:U12,"ROW") -> 0 | Y14: 0 | Z14: 0 | AB14: ROW
E15: DD+03 | G15: DD+9 | I15: DC+9 | K15: DA+9 | M15: DA+0 | O15: DA+3 | Q15: DA+6 | S15: DA+3 | U15: DA+00
C17: =U9+1 -> 11 | E17: =C17+1 -> 12 | G17: =E17+1 -> 13 | I17: =G17+1 -> 14 | K17: =I17+1 -> 15 | M17: =K17+1 -> 16 | O17: =M17+1 -> 17 | Q17: =O17+1 -> 18 | S17: =Q17+1 -> 19 | U17: =S17+1 -> 20
D19: 428.12 | F19: 249.58 | H19: 454.54 | J19: 377.83 | L19: 447.64 | N19: 396.44 | P19: 445.93 | R19: 156.98 | T19: 409.67 | V19: 382.38 | W19: =D19+H19+J19+L19+N19+F19+P19+R19+T19+V19 -> 3749.11 | AE19: =SUM(D19:V19) -> 3749.11
A20: =A12+1 -> 2 | X20: =COUNTIF(C20:U20,"F") -> 0 | Y20: =COUNTIF(C19:U19,"E") -> 0 | Z20: =COUNTIF(C21:V21,"Er") -> 0 | AB20: COM
X21: =COUNTIF(C21:U21,"U/P") -> 0 | Y21: 0 | Z21: 0 | AB21: WIP
C22: 3/7 | E22: 3/8 | G22: AP4 | I22: 4/1 | K22: AP5 | M22: 5/1 | O22: 5/2 | Q22: AP6 | S22: AP7 | U22: 7/1 | X22: =COUNTIF(C20:U20,"ROW") -> 0 | Y22: 0 | Z22: 0 | AB22: ROW
C23: DA+03 | E23: DD+03 RC | G23: DD+03 | I23: DA+09 | K23: DC+3 | M23: DA+06 | O23: DA+03 | Q23: DD+09 | S23: DD+09 | U23: DA+00
C25: =U17+1 -> 21 | E25: =C25+1 -> 22 | G25: =E25+1 -> 23 | I25: =G25+1 -> 24 | K25: =I25+1 -> 25 | M25: =K25+1 -> 26 | O25: =M25+1 -> 27 | Q25: =O25+1 -> 28 | S25: =Q25+1 -> 29 | U25: =S25+1 -> 30
D27: 353.89 | F27: 385.21 | H27: 367.67 | J27: 378.32 | L27: 392.49 | N27: 399.24 | P27: 390.93 | R27: 412.07 | T27: 421.95 | V27: 391.87 | W27: =D27+H27+J27+L27+N27+F27+P27+R27+T27+V27 -> 3893.64 | AE27: =SUM(D27:V27) -> 3893.64
A28: =A20+1 -> 3 | X28: =COUNTIF(C28:U28,"F") -> 0 | Y28: =COUNTIF(C27:U27,"E") -> 0 | Z28: =COUNTIF(C29:V29,"Er") -> 0 | AB28: COM
X29: =COUNTIF(C29:U29,"U/P") -> 0 | Y29: 0 | Z29: 0 | AB29: WIP
C30: 7/2 | E30: 7/3 | G30: 7/4 | I30: 7/5 | K30: 7/6 | M30: '7/7 | O30: AP8 | Q30: 08/01 | S30: 08/2 | U30: 08/3 | X30: =COUNTIF(C28:U28,"ROW") -> 0 | Y30: 0 | Z30: 0 | AB30: ROW
C31: DA+00 | E31: DA+00 | G31: DA+00 | I31: DA+00 | K31: DA+00 | M31: DA+00 | O31: DB+00 | Q31: DA+06 | S31: DA+00 | U31: DA+00
C33: =U25+1 -> 31 | E33: =C33+1 -> 32 | G33: =E33+1 -> 33 | I33: =G33+1 -> 34 | K33: =I33+1 -> 35 | M33: =K33+1 -> 36 | O33: =M33+1 -> 37 | Q33: =O33+1 -> 38 | S33: =Q33+1 -> 39 | U33: =S33+1 -> 40
D35: 406.65 | F35: 383.31 | H35: 402.96 | J35: 433.9 | L35: 328.55 | N35: 331.44 | P35: 358.83 | R35: 358.55 | T35: 429.37 | V35: 354.9 | W35: =D35+H35+J35+L35+N35+F35+P35+R35+T35+V35 -> 3788.46 | AE35: =SUM(D35:V35) -> 3788.46
A36: =A28+1 -> 4 | X36: =COUNTIF(C36:U36,"F") -> 0 | Y36: =COUNTIF(C35:U35,"E") -> 0 | Z36: =COUNTIF(C37:V37,"Er") -> 0 | AB36: COM
X37: =COUNTIF(C37:U37,"U/P") -> 0 | Y37: 0 | Z37: 0 | AB37: WIP
C38: 08/4 | E38: 08/5 | G38: 08/6 | I38: 08/7 | K38: AP9 | M38: 09/01 | O38: 09/02 | Q38: 09/03 | S38: 09/04 | U38: 09/05 | X38: =COUNTIF(C36:U36,"ROW") -> 0 | Y38: 0 | Z38: 0 | AB38: ROW
C39: DA+03 | E39: DA+00 | G39: DA+06 | I39: DA+06 | K39: DB+00 | M39: DA+00 | O39: DA+00 | Q39: DA+00 | S39: DA+00 | U39: DA+00
C41: =U33+1 -> 41 | E41: =C41+1 -> 42 | G41: =E41+1 -> 43 | I41: =G41+1 -> 44 | K41: =I41+1 -> 45 | M41: =K41+1 -> 46 | O41: =M41+1 -> 47 | Q41: =O41+1 -> 48 | S41: =Q41+1 -> 49 | U41: =S41+1 -> 50
D43: 340.94 | F43: 405.66 | H43: 409.41 | J43: 378.36 | L43: 322.47 | N43: 386.39 | P43: 386.19 | R43: 406.2 | T43: 351.15 | V43: 380.59 | W43: =D43+H43+J43+L43+N43+F43+P43+R43+T43+V43 -> 3767.36 | AE43: =SUM(D43:V43) -> 3767.36
A44: =A36+1 -> 5 | X44: =COUNTIF(C44:U44,"F") -> 0 | Y44: =COUNTIF(C43:U43,"E") -> 0 | Z44: =COUNTIF(C45:V45,"Er") -> 0 | AB44: COM
X45: =COUNTIF(C45:U45,"U/P") -> 0 | Y45: 0 | Z45: 0 | AB45: WIP
C46: 09/06 | E46: AP10 | G46: 10/01 | I46: 10/02 | K46: 10/03 | M46: 10/04 | O46: 10/05 | Q46: 10/06 | S46: 10/07 | U46: 10/08 | X46: =COUNTIF(C44:U44,"ROW") -> 0 | Y46: 0 | Z46: 0 | AB46: ROW
C47: DA+00 | E47: DC+9 | G47: DA+09 | I47: DA+00 | K47: DA+00 | M47: DA+00 | O47: DA+00 | Q47: DA+00 | S47: DA+00 | U47: DA+00
C49: =U41+1 -> 51 | E49: =C49+1 -> 52 | G49: =E49+1 -> 53 | I49: =G49+1 -> 54 | K49: =I49+1 -> 55 | M49: =K49+1 -> 56 | O49: =M49+1 -> 57 | Q49: =O49+1 -> 58 | S49: =Q49+1 -> 59 | U49: =S49+1 -> 60
D51: 380.02 | F51: 393.7 | H51: 390.68 | J51: 349.16 | L51: 416.01 | N51: 400.75 | P51: 406.84 | R51: 404.76 | T51: 311.74 | V51: 389.98 | W51: =D51+H51+J51+L51+N51+F51+P51+R51+T51+V51 -> 3843.64 | AE51: =SUM(D51:V51) -> 3843.64
A52: =A44+1 -> 6 | X52: =COUNTIF(C52:U52,"F") -> 0 | Y52: =COUNTIF(C51:U51,"E") -> 0 | Z52: =COUNTIF(C53:V53,"Er") -> 0 | AB52: COM
X53: =COUNTIF(C53:U53,"U/P") -> 0 | Y53: 0 | Z53: 0 | AB53: WIP
...

Sheet ROW
A1: NAME OF PROJECT : FARHEGARH IV-BHINMAL 400KV D/C TRANSMISSION LINE
A2: Client : RAJASTHAN IV A POWER TRANSMISSION LTD.
A3: CONTRACTOR : KEC INTERNATIONAL LIMITED
A6: FOUNDATION STATUS
A7: SL. No. | B7: Location Number | C7: Span | D7: Tower Type | E7: AS PER RAPTL ROW CLEARED ON | F7: WORK COMMENCED KEC | G7: STATUS
A9: 1 | B9: 80/0
A10: =A9+1 -> 2 | B10: 66/4 | F10: ROW
A11: =A10+1 -> 3 | B11: 89/1 | F11: ROW
A12: =A11+1 -> 4 | B12: 102/1
A13: =A12+1 -> 5 | B13: 102/2 | F13: Anjana Const | H13: Previous Loc Done 99/2 on 25/4/2025
A14: =A13+1 -> 6 | B14: 107/1
A15: =A14+1 -> 7 | B15: 90/1 | F15: ROW
A16: =A15+1 -> 8 | B16: 81/1
A17: =A16+1 -> 9 | B17: 51/1
A18: =A17+1 -> 10 | B18: 99A/2
A19: =A18+1 -> 11 | B19: 61/1
A20: =A19+1 -> 12 | B20: 72/2
A21: =A20+1 -> 13 | B21: 73/1
A22: =A21+1 -> 14 | B22: 99/5
A23: =A22+1 -> 15 | B23: 56/2
A24: =A23+1 -> 16 | B24: 63/1
A25: =A24+1 -> 17 | B25: 114/1
A26: =A25+1 -> 18 | B26: 116/1
A27: =A26+1 -> 19 | B27: 56/1
... A40: =A39+1 -> 32 | B40: 147/7

Sheet June
B1: Sl No | C1: Loc No | D1: TOT | F1: Classification | G1: Starting Date | H1: Completion
B2: 1 | C2: 81/3 | D2: DA+0 | F2: Sandy | G2: 45799 | H2: 45812
B3: =B2+1 -> 2 | C3: 120/1 | D3: DA+6 | F3: Sandy | G3: 45807 | H3: 45813
B4: =B3+1 -> 3 | C4: 96/0 | D4: DC+0 | F4: DFR | G4: 45805 | H4: 45814
B5: =B4+1 -> 4 | C5: 75/0 | D5: DC+0 | F5: Sandy | G5: 45809 | H5: 45815
B6: =B5+1 -> 5 | C6: 147/2 | D6: DA+0 | F6: Sandy | G6: 45810 | H6: 45816
B7: =B6+1 -> 6 | C7: 82/2 | D7: DA+0 | F7: Sandy | G7: 45810 | H7: 45818
B8: =B7+1 -> 7 | C8: 79/0 | D8: DD+0 | F8: Sandy | G8: 45877 | H8: 45820
B9: =B8+1 -> 8 | C9: 147/5 | D9: DA+0 | F9: Sandy | G9: 45812 | H9: 45820
B10: =B9+1 -> 9 | C10: 119/0 | D10: DD+3 | F10: Sandy | G10: 45813 | H10: 45823
B11: =B10+1 -> 10 | C11: 82/1 | D11: DA+6 | F11: Sandy | G11: 45818 | H11: 45823
B12: =B11+1 -> 11 | C12: 147/0 | D12: DC+0 | F12: Sandy | G12: 45816 | H12: 45823
B13: =B12+1 -> 12 | C13: 78/0 | D13: DC+0 | F13: Sandy | G13: 45821 | H13: 45824
B14: =B13+1 -> 13 | C14: 147/4 | D14: DA+0 | F14: Sandy | G14: 45821 | H14: 45824
... B26: =B25+1 -> 25 | C26: 147/8 | D26: DA+0 | F26: Sandy | G26: 45833 | H26: 45838

Sheet Check survey Loop out
A2: CLIENT :- RAJASTHAN IV A POWER TRANSMISSION LTD.
A3: NAME OF PROJECT :- Lilo of 765 kv D/C Fathegarh III -Beawar at Fathegarh-IV Transmission Line
A4: CONTRACTOR : KEC INTERNATIONAL LTD
A5: Detail Survey Tower Schedule : GANTRY TO Existing 10/6 (Loop Out) (Rev-06)
A6: AS PER DETAILED SURVEY | G6: AS PER DETAIL SURVEY
A7: Sl. No | B7: Twr No. | C7: Tower Type | D7: Deviation Angle | E7: Span (mtr) | F7: Section Length (mtr) | G7: Sl.No | H7: Tower No. | I7: TYPE OF TOWER | J7: HT of Tower (Mtr) | K7: SPAN (Mtr) | L7: Section | M7: CUMULATIVE SPAN | N7: R.L (Mtr) | O7: DEVIATION ANGLE (Deg) | P7: Sum of Adjacent Spans | Q7: WIND SPAN (Mtr) | R7: WEIGHT SPAN IN Mtr (Cold) | U7: WEIGHT SPAN IN Mtr (Hot) | X7: UTM Coordinates | Z7: CROSSING DETAILS
R8: Left | S8: Right | T8: Total | U8: Left | V8: Right | W8: Total | X8: Easting (m) | Y8: Y Northing (m)
A9: 1 | B9: Gantry | C9: Gantry | F9: =E10 -> 174.263 | G9: 1 | H9: Gantry 1 | I9: Gantry | J9: 46.3 | L9: =K10 -> 143.312 | M9: 0 | N9: 253.455 | P9: =K10 -> 143.312 | Q9: 73 | R9: 0 | S9: 75 | T9: 75 | U9: 0 | V9: 75 | W9: 75 | X9: 723713 | Y9: 2905256 | Z9: Existing Fathegarh-IV S/S
E10: 174.263 | K10: 143.312 | M10: (Maximum Tension @ 32deg+156KG/SQM wind condition is limited to 7.62/6=1.27T for the Slack Span between Gantry to AP01 section) | Z10: GSS BOUNDARY, 33 Kv Line
A11: 2 | B11: AP-01 | C11: DE+3 | D11: 47° 48' 2"LT | F11: =SUM(E12:E28) -> 2912.04 | G11: 2 | H11: AP-01 | I11: DE+3 | J11: 73.75 | L11: =SUM(K12:K28) -> 3083.343 | M11: =K10+M9 -> 143.312 | N11: 256.062 | O11: 66° 56' 18"LT | P11: =K12+K10 -> 527.002 | Q11: 265 | R11: 134 | S11: 252 | T11: 386 | U11: 129 | V11: 230 | W11: 358 | X11: 723824.35 | Y11: 2905166.3 | Z11: WITH AUX- ARM
E12: 325 | K12: 383.69 | Z12: OFC AND Cart Track
A13: 3 | B13: 01/1 | C13: DA-1.5 | G13: 3 | H13: 01/1 | I13: DA-3 | J13: 68.95 | M13: =K12+M11 -> 527.002 | N13: 252.393 | P13: =K12+K14 -> 701.026 | Q13: 351 | R13: 132 | S13: 155 | T13: 287 | U13: 155 | V13: 157 | W13: 312 | X13: 724163.45 | Y13: 2905345.9
E14: 315 | K14: 317.336 | Z14: MOHRUM ROAD
A15: 4 | B15: 01/2 | C15: DA-3 | G15: 4 | H15: 01/2 | I15: DA-3 | J15: 68.95 | M15: =K14+M13 -> 844.338 | N15: 252.922 | P15: 613.925 | Q15: 306.9625 | R15: 163 | S15: 121 | T15: 284 | U15: 161 | V15: 132 | W15: 293 | X15: 724443.9 | Y15: 2905494.4
E16: 296.194 | K16: 296.59
A17: 5 | B17: 01/3 | C17: DA-3 | D17: 0° 39' 6"RT | G17: 5 | H17: 2/0 | I17: DC1+0 | J17: 70.75 | M17: =K16+M15 -> 1140.928 | N17: 252.912 | O17: 20° 46' 08"LT | P17: 663.829 | Q17: 331.9145 | R17: 176 | S17: 195 | T17: 371 | U17: 165 | V17: 191 | W17: 356 | X17: 724706.01 | Y17: 2905633.2
E18: 335 | K18: 367.239
A19: 6 | B19: 01/4 | C19: DA+0 | G19: 6 | H19: 2/1 | I19: DA+0 | J19: 71.95 | M19: =K18+M17 -> 1508.167 | N19: 251.735 | P19: 710.508 | Q19: 355.254 | R19: 173 | S19: 188 | T19: 361 | U19: 177 | V19: 183 | W19: 360 | X19: 724948.54 | Y19: 2905908.9
E20: 320 | K20: 343.268 | Z20: Cart Track
A21: 7 | B21: 01/5 | C21: DA-3 | G21: 7 | H21: 2/2 | I21: DA-3 | J21: 68.95 | M21: =K20+M19 -> 1851.435 | N21: 252.173 | P21: 641.98 | Q21: 320.99 | R21: 155 | S21: 132 | T21: 287 | U21: 162 | V21: 139 | W21: 301 | X21: 725175.23 | Y21: 2906166.7
E22: 349.269 | K22: 298.712 | Z22: Lt Line, Cart Track
A23: 8 | B23: 01/6 | C23: DA-1.5 | D23: 0° 38' 40"RT | G23: 8 | H23: 2/3 | I23: DA+0 | J23: 71.95 | M23: =K22+M21 -> 2150.147 | N23: 251.524 | P23: 683.011 | Q23: 341.5055 | R23: 167 | S23: 185 | T23: 352 | U23: 161 | V23: 188 | W23: 349 | X23: 725372.5 | Y23: 2906391
E24: 310 | K24: 384.299 | Z24: 11 KV LINE
A25: 9 | B25: 01/7 | C25: DA-3 | G25: 9 | H25: 2/4 | I25: DA+3 | J25: 74.95 | M25: =K24+M23 -> 2534.446 | N25: 249.746 | P25: 740.398 | Q25: 370.199 | R25: 199 | S25: 231 | T25: 431 | U25: 197 | V25: 212 | W25: 410 | X25: 725626.29 | Y25: 2906679.6
E26: 400 | K26: 356.099 | Z26: Cart Track
A27: 10 | B27: 01/8 | C27: DA-1.5 | G27: 10 | H27: 2/5 | I27: DA-3 | J27: 68.95 | M27: =K26+M25 -> 2890.545 | N27: 247.223 | P27: 692.209 | Q27: 346.1045 | R27: 125 | S27: 155 | T27: 280 | U27: 145 | V27: 160 | W27: 305 | X27: 725861.46 | Y27: 2906947
E28: 261.577 | K28: 336.11 | Z28: Cart Track
A29: 11 | B29: AP-02 | C29: DD60+0 | D29: 48° 13' 40"LT | F29: =SUM(E30:E32) -> 572.317 | G29: 11 | H29: AP-03 | I29: DC1+0 | J29: 70.75 | L29: =SUM(K30:K32) -> 833.541 | M29: =K28+M27 -> 3226.655 | N29: 245.676 | O29: 11° 36' 6"RT | P29: 752.234 | Q29: 376.117 | R29: 182 | S29: 200 | T29: 382 | U29: 177 | V29: 203 | W29: 380 | X29: 726083.43 | Y29: 2907199.4
E30: 285 | K30: 416.124
A31: 12 | B31: 02/1 | C31: DA-3 | G31: 12 | H31: 03/1 | I31: DA+3 | J31: 74.95 | M31: =K30+M29 -> 3642.779 | N31: 244.995 | P31: 833.541 | Q31: 416.7705 | R31: 217 | S31: 204 | T31: 421 | U31: 215 | V31: 206 | W31: 421 | X31: 726415.46 | Y31: 2907450.2
E32: 287.317 | K32: 417.417 | Z32: Mohrum Road, 11 kv line, ct
A33: 13 | B33: AP-03 | C33: DC1+0 | D33: 16° 49' 30"LT | F33: =SUM(E34:E40) -> 1510.095 | G33: 13 | H33: 03/2 | I33: DA+0 | J33: 71.95 | L33: =SUM(K34:K40) -> 1536.038 | M33: =K32+M31 -> 4060.196 | N33: 248.945 | P33: 815.155 | Q33: 407.5775 | R33: 214 | S33: 173 | T33: 387 | U33: 213 | V33: 182 | W33: 394 | X33: 726748.53 | Y33: 2907701.8
E34: 375 | K34: 397.738
A35: 14 | B35: 03/1 | C35: DA+0 | G35: 14 | H35: 03/3 | I35: DA+3 | J35: 74.95 | M35: =K34+M33 -> 4457.934 | N35: 250.871 | P35: 814.228 | Q35: 407.114 | R35: 225 | S35: 228 | T35: 453 | U35: 218 | V35: 223 | W35: 441 | X35: 727065.9 | Y35: 2907941.5
E36: 375 | K36: 416.49 | Z36: Cart Track, lt Line
A37: 15 | B37: 03/2 | C37: DA+0 | G37: 15 | H37: 3/4 | I37: DA+0 | J37: 71.95 | M37: =K36+M35 -> 4874.424 | N37: 249.994 | P37: 771.147 | Q37: 385.5735 | R37: 189 | S37: 199 | T37: 388 | U37: 195 | V37: 193 | W37: 388 | X37: 727398.22 | Y37: 2908192.6
E38: 360 | K38: 354.657 | Z38: 2 Nos. Cart Tracks
A39: 16 | B39: 03/3 | C39: DA+3 | G39: 16 | H39: 3/5 | I39: DA-3 | J39: 68.95 | M39: =K38+M37 -> 5229.081 | N39: 249.311 | P39: 721.81 | Q39: 360.905 | R39: 156 | S39: 181 | T39: 337 | U39: 163 | V39: 182 | W39: 345 | X39: 727681.21 | Y39: 2908406.4
E40: 400.095 | K40: 367.153
A41: 17 | B41: AP-04 | C41: DD45+0 | D41: 32° 38' 24"RT | F41: =SUM(E42:E48) -> 1528.052 | G41: 17 | H41: AP-04 | I41: DD60+0 | J41: 70.75 | L41: =SUM(K42:K48) -> 1407.307 | M41: =K40+M39 -> 5596.234 | N41: 246.196 | O41: 57° 53' 9"LT | P41: 729.011 | Q41: 364.5055 | R41: 187 | S41: 180 | T41: 367 | U41: 186 | V41: 181 | W41: 367 | X41: 727974.17 | Y41: 2908627.7
...

Sheet Check survey Loop In
A1: CLIENT :- RAJASTHAN IV A POWER TRANSMISSION LTD.
A2: NAME OF PROJECT :- Lilo of 765 kv D/C Fathegarh III -Beawar at Fathegarh-IV Transmission Line
A3: CONTRACTOR : KEC INTERNATIONAL LIMITED
A4: CHECK SURVEY REPORT
A5: Detail Survey Tower Schedule : Existing 10/4 TO GANTRY (Loop in) (Rev-06)
A6: Check Survey Tower Schedule : GANTRY TO Existing 10/6 (Loop Out) (Rev-0) | G6: AS PER DETAIL SURVEY
A7: Sl. No | B7: Twr No. | C7: Tower Type | D7: Deviation Angle | E7: Span (mtr) | F7: Section Length (mtr) | G7: Sl.No | H7: Tower No. | I7: TYPE OF TOWER | J7: HT of Tower (Mtr) | K7: SPAN (Mtr) | L7: Section | M7: CUMULATIVE SPAN | N7: R.L (Mtr) | O7: DEVIATION ANGLE (Deg) | P7: Sum of Adjacent Spans | Q7: WIND SPAN (Mtr) | R7: WEIGHT SPAN IN Mtr (Cold) | U7: WEIGHT SPAN IN Mtr (Hot) | X7: UTM Coordinates | Z7: CROSSING DETAILS
R8: Left | S8: Right | T8: Total | U8: Left | V8: Right | W8: Total | X8: Easting (m) | Y8: Y Northing (m)
A9: 1 | B9: Existing 10/4 | C9: DA+3 | F9: =E10 -> 200.23 | G9: 1 | H9: Existing 10/4 | I9: DA+3 | J9: 74.86 | L9: =K10 -> 200.23 | M9: 0 | N9: 249.33 | P9: 200.23 | Q9: 100.115 | R9: 0 | S9: 137 | T9: 137 | U9: 0 | V9: 115 | W9: 115 | X9: 726986.39 | Y9: 2910572.5 | Z9: Existing Tapping Tower
E10: 200.23 | K10: 200.23
A11: 2 | B11: AP-01 | C11: DD60+0 | D11: 25° 14' 5"RT | F11: =E12 -> 131.759 | G11: 2 | H11: AP-01 | I11: DD60+0 | J11: 70.75 | L11: =K12 -> 131.759 | M11: =M9+K10 -> 200.23 | N11: 249.33 | O11: 25° 14' 5"RT | P11: 331.989 | Q11: 165.9945 | R11: 63 | S11: 68 | T11: 132 | U11: 85 | V11: 67 | W11: 152 | X11: 727186.1 | Y11: 2910558.1 | Z11: ONE SIDE BOX X-ARM & ONE SIDE POINTED
E12: 131.759 | K12: 131.759
A13: 3 | B13: AP-02 | C13: DD60+0 (Aux. X-arm) | D13: 72° 53' 17"RT | F13: =E14 -> 163.285 | G13: 3 | H13: AP-02 | I13: DD60+0 | J13: 70.75 | L13: =K14 -> 357.494 | M13: =M11+K12 -> 331.989 | N13: 249.22 | O13: 25° 6' 5"RT | P13: 489.253 | Q13: 244.6265 | R13: 63 | S13: 183 | T13: 246 | U13: 65 | V13: 182 | W13: 247 | X13: 727300.93 | Y13: 2910493.5
E14: 163.285 | K14: 357.494
A15: 4 | B15: AP-03 | C15: DD45+0 | D15: 31° 57' 20"RT | F15: =SUM(E16:E18) -> 653.104 | G15: 4 | H15: 2A/0 | I15: DD45+0 | J15: 70.75 | L15: =SUM(K16:K18) -> 741.191 | M15: =M13+K14 -> 689.483 | N15: 248.585 | O15: 14° 6' 42"LT | P15: 701.156 | Q15: 350.578 | R15: 175 | S15: 179 | T15: 354 | U15: 177 | V15: 177 | W15: 354 | X15: 727508.7 | Y15: 2910202.6
E16: 325.001 | K16: 343.662
A17: 5 | B17: 03/1 | C17: DA-3 | G17: 5 | H17: 3/0 | I17: DD60+0 | J17: 70.75 | M17: =M15+K16 -> 1033.145 | N17: 247.512 | O17: 51° 38' 29"RT | P17: 741.191 | Q17: 370.5955 | R17: 165 | S17: 192 | T17: 357 | U17: 168 | V17: 194 | W17: 362 | X17: 727770.59 | Y17: 2909980
E18: 328.103 | K18: 397.529
A19: 6 | B19: AP-04 | C19: DB1+0 | D19: 5° 57' 6"LT | F19: =SUM(E20:E26) -> 1417.038 | G19: 6 | H19: 3A/0 | I19: DD45+3 | J19: 73.75 | L19: =SUM(K20:K26) -> 1665.271 | M19: =M17+K18 -> 1430.674 | N19: 246.022 | O19: 43° 42' 10"RT | P19: 817.394 | Q19: 408.697 | R19: 207 | S19: 189 | T19: 396 | U19: 205 | V19: 195 | W19: 400 | X19: 727756.74 | Y19: 2909582.8
E20: 350 | K20: 419.865
A21: 7 | B21: 04/1 | C21: DA-3 | G21: 7 | H21: 3A/1 | I21: DB1+6 | J21: 76.75 | M21: =M19+K20 -> 1850.539 | N21: 247.6 | P21: 840.538 | Q21: 420.269 | R21: 231 | S21: 227 | T21: 458 | U21: 226 | V21: 223 | W21: 449 | X21: 727456.26 | Y21: 2909289.5
E22: 355 | K22: 420.673 | Z22: POND
A23: 8 | B23: 04/2 | C23: DA-1.5 | G23: 8 | H23: 3B/0 | I23: DC2+3 | J23: 73.75 | M23: =M21+K22 -> 2271.212 | N23: 247.042 | O23: 27° 51' 4"LT | P23: 838.539 | Q23: 419.2695 | R23: 195 | S23: 227 | T23: 422 | U23: 199 | V23: 223 | W23: 422 | X23: 727155.19 | Y23: 2908995.7
E24: 355 | K24: 417.866 | Z24: CART TRACK
A25: 9 | B25: 04/3 | C25: DA-1.5 | G25: 9 | H25: 4/0 | I25: DD45+0 | J25: 70.75 | M25: =M23+K24 -> 2689.078 | N25: 246.108 | O25: 29° 34' 51"RT | P25: 824.733 | Q25: 412.3665 | R25: 191 | S25: 192 | T25: 383 | U25: 196 | V25: 196 | W25: 392 | X25: 727027.12 | Y25: 2908597.9
E26: 357.038 | K26: 406.867
A27: 10 | B27: AP-05 | C27: DC1+0 | D27: 17° 4' 3"LT | F27: =SUM(E28:E42) -> 3013.026 | G27: 10 | H27: 4/1 | I27: DA+3 | J27: 74.95 | L27: =SUM(K28:K42) -> 3126.267 | M27: =M25+K26 -> 3095.945 | N27: 246.161 | P27: 821.358 | Q27: 410.679 | R27: 216 | S27: 194 | T27: 410 | U27: 213 | V27: 199 | W27: 412 | X27: 726727.49 | Y27: 2908322.7
E28: 400 | K28: 414.491
A29: 11 | B29: 05/1 | C29: DA+3 | G29: 11 | H29: 4/2 | I29: DA+3 | J29: 74.95 | M29: =M27+K28 -> 3510.436 | N29: 248.85 | P29: 824.711 | Q29: 412.3555 | R29: 221 | S29: 208 | T29: 429 | U29: 217 | V29: 208 | W29: 425 | X29: 726422.24 | Y29: 2908042.3
E30: 400 | K30: 410.22 | Z30: 11 kV Line, track, Cart Track,
A31: 12 | B31: 05/2 | C31: DA+0 | G31: 12 | H31: 4/3 | I31: DA+3 | J31: 74.95 | M31: =M29+K30 -> 3920.656 | N31: 248.245 | P31: 807.302 | Q31: 403.651 | R31: 202 | S31: 221 | T31: 423 | U31: 204 | V31: 214 | W31: 418 | X31: 726120.15 | Y31: 2907764.8
E32: 350 | K32: 397.082 | Z32: CART TRACK
A33: 13 | B33: 05/3 | C33: DA+0 | G33: 13 | H33: 4/4 | I33: DA+0 | J33: 71.95 | M33: =M31+K32 -> 4317.738 | N33: 247.061 | P33: 784.74 | Q33: 392.37 | R33: 177 | S33: 188 | T33: 365 | U33: 184 | V33: 190 | W33: 374 | X33: 725827.72 | Y33: 2907496.1
E34: 375 | K34: 387.658
A35: 14 | B35: 05/4 | C35: DA-1.5 | G35: 14 | H35: 4/5 | I35: DA+0 | J35: 71.95 | M35: =M33+K34 -> 4705.396 | N35: 248.274 | P35: 787.54 | Q35: 393.77 | R35: 201 | S35: 183 | T35: 384 | U35: 199 | V35: 188 | W35: 387 | X35: 725542.23 | Y35: 2907233.9
E36: 385 | K36: 399.882
A37: 15 | B37: 05/5 | C37: DA+0 | G37: 15 | H37: 5/0 | I37: DC2+0 | J37: 70.75 | M37: =M35+K36 -> 5105.278 | N37: 250.992 | O37: 26° 30' 29"LT | P37: 765.029 | Q37: 382.5145 | R37: 217 | S37: 172 | T37: 389 | U37: 213 | V37: 176 | W37: 389 | X37: 725247.75 | Y37: 2906963.4
E38: 365 | K38: 365.147 | Z38: Cart Track
A39: 16 | B39: 05/6 | C39: DA+0 | G39: 16 | H39: 5/1 | I39: DA+0 | J39: 71.95 | M39: =M37+K38 -> 5470.425 | N39: 253.37 | P39: 752.233 | Q39: 376.1165 | R39: 193 | S39: 197 | T39: 390 | U39: 190 | V39: 196 | W39: 386 | X39: 725117.36 | Y39: 2906622.3
E40: 380 | K40: 387.086 | Z40: lt Line
...

Sheet Royalty
O3: OM Construction
C4: Loc No | D4: TOT | E4: M-10 | F4: M-20
C5: 120/1 | D5: DA+6 | E5: 1.86 | F5: 12.47 | O5: 75/0 | P5: DC+0 | Q5: 1.6 | R5: 13.13
C6: 119/0 | D6: DD+3 | E6: 2.93 | F6: 20.34 | O6: 79/0 | P6: DD+0 | Q6: 2.93 | R6: 20.34
D7: CUM | E7: =SUM(E5:E6) -> 4.79 | F7: =SUM(F5:F6) -> 32.81 | J7: ROYALTY ISSUED | O7: 78/0 | P7: DC+0 | Q7: 1.6 | R7: 13.13
C8: CUM | D8: 20MM | E8: =E7*1.54*6/10 -> 4.42596 | F8: =F7*1.54*3/5.5 -> 27.5604 | G8: =SUM(E8:F8) -> 31.98636 | J8: 20MM | O8: 74/0 | P8: DB+9 | Q8: 1.68 | R8: 12.41
C9: CUM | D9: SAND | E9: =E8*1.54*3/10 -> 2.0447935 | F9: =F8*1.54*1.5/5.5 -> 11.575368 | G9: =SUM(E9:F9) -> 13.620162 | J9: 18.48 | O9: 73/0 | P9: DB+0 | Q9: 1.68 | R9: 12.41
C10: MT | D10: 20MM | G10: =G8*1600/1000 -> 51.178176 | H10: Required | J10: 14.67 | O10: 72/2 | P10: DA+3 | Q10: 1.86 | R10: 12.47
C11: MT | D11: SAND | G11: =G9*1600/1000 -> 21.792258 | H11: Required | J11: =SUM(J9:J10) -> 33.15 | Q11: =SUM(Q5:Q10) -> 11.35 | R11: =SUM(R5:R10) -> 83.89
O12: CUM | P12: 20MM | Q12: =Q11*1.54*6/10 -> 10.4874 | R12: =R11*1.54*3/5.5 -> 70.4676 | S12: =SUM(Q12:R12) -> 80.955
O13: CUM | P13: SAND | Q13: =Q12*1.54*3/10 -> 4.8451788 | R13: =R12*1.54*1.5/5.5 -> 29.596392 | S13: =SUM(Q13:R13) -> 34.441571
C14: 77/1 | D14: DA+0 | E14: 1.57 | F14: 11.05 | O14: MT | P14: 20MM | S14: =S12*1600/1000 -> 129.528
C15: 77/4 | D15: DA+3 | E15: 1.86 | F15: 12.47 | O15: MT | P15: SAND | S15: =S13*1600/1000 -> 55.106513
C16: 79/1 | D16: DA+9 | E16: 1.86 | F16: 12.47
C17: 76/1 | D17: DA+6 | E17: 1.86 | F17: 12.47
C18: 85/1 | D18: DA+0 | E18: 1.57 | F18: 11.05 | O18: JP Enterprises
C19: 87/1 | D19: DA+3 | E19: 1.86 | F19: 12.47 | P19: 147/2 | Q19: DA+0 | R19: 1.57 | S19: 11.05
C20: 87/2 | D20: DA+9 | E20: 1.86 | F20: 12.47 | P20: 147/0 | Q20: DC+0 | R20: 1.6 | S20: 13.13
C21: 91/1 | D21: DA+0 | E21: 1.57 | F21: 11.05 | P21: 147/1 | Q21: DA+0 | R21: 1.57 | S21: 11.05
C22: 91/2 | D22: DA+0 | E22: 1.57 | F22: 11.05 | P22: 146/2 | Q22: DA+0 | R22: 1.57 | S22: 11.05
C23: 99/2 | D23: DA+0 | E23: 1.08 | F23: 8.68 | P23: 146/1 | Q23: DA+3 | R23: 1.86 | S23: 12.47
C24: 97/0 | D24: DC+0 | E24: 1.6 | F24: 13.13 | R24: =SUM(R19:R23) -> 8.17 | S24: =SUM(S19:S23) -> 58.75
C25: 82/2 | D25: DA+0 | E25: 1.57 | F25: 11.05 | P25: CUM | Q25: 20MM | R25: =R24*1.54*6/10 -> 7.54908 | S25: =S24*1.54*3/5.5 -> 49.35 | T25: =SUM(R25:S25) -> 56.89908
C26: 82/1 | D26: DA+6 | E26: 1.86 | F26: 12.47 | P26: CUM | Q26: SAND | R26: =R25*1.54*3/10 -> 3.487675 | S26: =S25*1.54*1.5/5.5 -> 20.727 | T26: =SUM(R26:S26) -> 24.214675
C27: 86/0 | D27: DD+0 | E27: 2.93 | F27: 20.34 | P27: MT | Q27: 20MM | T27: =T25*1600/1000 -> 91.038528
C28: 85/0 | D28: DC+0 | E28: 1.6 | F28: 13.13 | P28: MT | Q28: SAND | T28: =T26*1600/1000 -> 38.74348
E29: =SUM(E14:E28) -> 26.22 | F29: =SUM(F14:F28) -> 185.35 | U29: Balance
C30: CUM | D30: 20MM | E30: =E29*1.54*6/10 -> 24.22728 | F30: =F29*1.54*3/5.5 -> 155.694 | G30: =SUM(E30:F30) -> 179.92128 | O30: Submitted | P30: MT | Q30: 20MM | T30: =16.74+14.83+18.51+18.5 -> 68.58 | U30: =T27-T30 -> 22.458528
C31: CUM | D31: SAND | E31: =E30*1.54*3/10 -> 11.193003 | F31: =F30*1.54*1.5/5.5 -> 65.39148 | G31: =SUM(E31:F31) -> 76.584483
C32: MT | D32: 20MM | G32: =G30*1600/1000 -> 287.87405
C33: MT | D33: SAND | G33: =G31*1600/1000 -> 122.53517

Sheet Sheet14
A2: 1 | B2: 95/1 | C2: DB+0 | E2: DFR | F2: 45831 | G2: 45842 | H2: Baba Ramdev Construction | I2: RCC Complete, Backfilling Done
A3: =A2+1 -> 2 | B3: 148/3 | C3: DA+0 | E3: Sandy | F3: 45835 | G3: 45843 | H3: AR Patel | I3: RCC Complete, Backfilling Done
A4: =A3+1 -> 3 | B4: 106/0 | C4: DC+6 | E4: Sandy | F4: 45833 | G4: 45844 | H4: Mundhan Trading Company | I4: RCC Complete, Backfilling Done
A5: =A4+1 -> 4 | B5: 148/1 | C5: DA+0 | E5: Sandy | F5: 45842 | G5: 45846 | H5: AR Patel | I5: RCC Complete, Backfilling Done
A6: =A5+1 -> 5 | B6: 146/0 | C6: DC+0 | E6: Sandy | F6: 45841 | G6: 45846 | H6: JP Enterprises | I6: RCC Complete, Backfilling Done
A7: =A6+1 -> 6 | B7: 80/0 | C7: DB+3 | D7: 1MRC | E7: Sandy | F7: 45836 | G7: 45848 | H7: Mahadev Enterprises | I7: RCC Complete, Backfilling Done
A8: =A7+1 -> 7 | B8: 114/1 | C8: DA+9 | E8: Sandy | F8: 45842 | G8: 45848 | H8: Goswami and Company | I8: RCC Complete, Backfilling Done
A9: =A8+1 -> 8 | B9: 148/2 | C9: DA+0 | E9: Sandy | F9: 45845 | G9: 45848 | H9: AR Patel | I9: RCC Complete, Backfilling Done
A10: =A9+1 -> 9 | B10: 95/0 | C10: DB+6 | E10: Sandy | F10: 45835 | G10: 45849 | H10: Baba Ramdev Construction | I10: RCC Complete, Backfilling Done
A11: =A10+1 -> 10 | B11: 141/1 | C11: DA+0 | E11: Sandy | F11: 45845 | G11: 45849 | H11: Mahadev Construction | I11: RCC Complete, Backfilling Done
A12: =A11+1 -> 11 | B12: 148/4 | C12: DA+0 | E12: Sandy | F12: 45848 | G12: 45850 | H12: AR Patel | I12: RCC Complete, Backfilling Done
A13: =A12+1 -> 12 | B13: 141/2 | C13: DA+6 | E13: Sandy | F13: 45847 | G13: 45851 | H13: Mahadev Construction | I13: RCC Complete, Backfilling Done
A14: =A13+1 -> 13 | B14: 145/4 | C14: DA+3 | E14: Sandy | F14: 45847 | G14: 45851 | H14: JP Enterprises | I14: RCC Complete, Backfilling Done
A15: =A14+1 -> 14 | B15: 133/6 | C15: DA+3 | E15: Sandy | F15: 45848 | G15: 45852 | H15: OM Construction | I15: RCC Complete, Backfilling Done
A16: =A15+1 -> 15 | B16: 125/1 | C16: DA+0 | E16: Sandy | F16: 45842 | G16: 45852 | H16: Instance Wave Pvt Ltd | I16: RCC Complete, Backfilling Done
A17: =A16+1 -> 16 | B17: 148/5 | C17: DA+0 | E17: Sandy | F17: 45851 | G17: 45853 | H17: AR Patel | I17: RCC Complete, Backfilling Done
A18: =A17+1 -> 17 | B18: 109A/0 | C18: DB+6 | E18: Sandy | F18: 45847 | G18: 45854 | H18: Mundhan Construction | I18: RCC Complete, Backfilling Done
A19: =A18+1 -> 18 | B19: 113A/0 | C19: DC+0 | E19: Sandy | F19: 45846 | G19: 45854 | H19: Goswami and Company-1 | I19: RCC Complete, Backfilling Done
... A51: =A50+1 -> 50 | B51: 116/0 | C51: DD+0 | E51: Sandy | F51: 45861 | G51: 45869 | H51: Goswami and Company-2 | I51: RCC Complete, Backfilling Done

Sheet Sheet7
D4: SL | E4: Loc | F4: TOT | G4: Gang | H4: Starting Date | I4: Completion
D5: 1 | E5: 148/3 | F5: DA+0 | G5: Gokul Sarkar | H5: 45898 | I5: 45904 | J5: Completed
D6: =D5+1 -> 2 | E6: 81/2 | F6: DA+3 | G6: Dipak | H6: 45901 | I6: 45905 | J6: Completed
D7: =D6+1 -> 3 | E7: 145/1 | F7: DA+3 | G7: Ayansh Const | H7: 45896 | I7: 45909 | J7: Completed
D8: =D7+1 -> 4 | E8: 81/4 | F8: DA+0 | G8: Dipak | H8: 45905 | I8: 45909 | J8: Completed
D9: =D8+1 -> 5 | E9: 148/2 | F9: DA+0 | G9: Gokul Sarkar | H9: 45905 | I9: 45910 | J9: Completed
D10: =D9+1 -> 6 | E10: 83/1 | F10: DA+3 | G10: Ahmed Construction | H10: 45898 | I10: 45911 | J10: Completed
D11: =D10+1 -> 7 | E11: 97/0 | F11: DC+0 | G11: Ajay Kumar1 | H11: 45901 | I11: 45911 | J11: Completed
D12: =D11+1 -> 8 | E12: 148/5 | F12: DA+0 | G12: Gokul Sarkar | H12: 45911 | I12: 45914 | J12: Completed
D13: =D12+1 -> 9 | E13: 145/2 | F13: DA+0 | G13: Ayansh Const | H13: 45909 | I13: 45914 | J13: Completed
D14: =D13+1 -> 10 | E14: 82/1 | F14: DA+6 | G14: Dipak | H14: 45909 | I14: 45914 | J14: Completed
D15: =D14+1 -> 11 | E15: 96/1 | F15: DA+0 | G15: Ajay Kumar1 | H15: 45901 | I15: 45915 | J15: Completed
D16: =D15+1 -> 12 | E16: 79/2 | F16: DA+0 | G16: Ahmed Construction | H16: 45911 | I16: 45915 | J16: Completed
D17: =D16+1 -> 13 | E17: 133/2 | F17: DA+0 | G17: Windbridge Energy | H17: 45897 | I17: 45916 | J17: Completed
... D34: =D33+1 -> 30 | E34: 149B/1 | F34: DA+3 | G34: Gokul Sarkar | H34: 45924 | I34: 45927 | J34: Completed

Sheet Project Details
A1: Project Code | B1: Project Name | C1: Client Name | D1: LOA Start Date | E1: LOA End Date | F1: Planning Engineer | G1: PCH | H1: Regional Manager | I1: Project Manger | J1: Section Incharge | K1: Supervisor/Engineer
A2: TB 507 | B2: 400kV D/C Fatehgarh IV (Section-2)PS - Bhinmal (PG) Transmission Line | C2: RAJASTHAN IV A POWER TRANSMISSION LTD | D2: 45632 | E2: 46178 | F2: Mr.Amartya sarkar | G2: Mr. N K Gupta | I2: Mr.ALOK SINHA | J2: Mr.ALOK JANA Mr.VARUN TYAGI

Sheet Foundation
A1: NAME OF PROJECT : FARHEGARH IV-BHINMAL 400KV D/C TRANSMISSION LINE
A2: Client : RAJASTHAN IV A POWER TRANSMISSION LTD.
A3: CONTRACTOR : KEC INTERNATIONAL LIMITED
A5: FOUNDATION STATUS
A6: SL. No. | B6: Location Number | C6: Span | E6: Tower Type | F6: M10 | G6: M20 | H6: Excavation | I6: Reinforcement | J6: Stub | K6: RC | L6: Foundation type
D7: LI / LO | M7: Starting date | N7: Completion Date | O7: Agency | P7: Remark | R7: Remarks
A8: 1 | B8: 7/0 | D8: LI | E8: DE+9 (Aux. X-arm) | F8: 10.22 | G8: 143.9 | I8: 2.712 | L8: DFR | M8: 46059 | N8: 46064 | O8: Karni Mata Construction Company | R8: RCC Complete, Backfilling Done
A9: =A8+1 -> 2 | B9: 1/1 | D9: LO | E9: DA-3 | F9: 2.74 | G9: 30.2 | I9: 2.712 | L9: DFR | M9: 46064 | N9: 46067 | O9: Karni Mata Construction Company | R9: RCC Complete, Backfilling Done
A10: =A9+1 -> 3 | B10: 6/2 | D10: LI | E10: DA+0 | F10: 2.74 | G10: 30.2 | I10: 2.712 | L10: DFR | M10: 46065 | N10: 46069 | O10: Karni Mata Construction Company | R10: RCC Complete, Backfilling Done
A11: =A10+1 -> 4 | B11: 1/2 | D11: LO | E11: DA-3 | F11: 2.74 | G11: 30.2 | I11: 2.712 | L11: DFR | M11: 46068 | N11: 46071 | O11: Karni Mata Construction Company | R11: RCC Complete, Backfilling Done
A12: =A11+1 -> 5 | B12: 6/1 | D12: LI | E12: DA+0 | F12: 2.74 | G12: 30.2 | I12: 2.712 | L12: DFR | M12: 46070 | N12: 46073 | O12: Karni Mata Construction Company | R12: RCC Complete, Backfilling Done
A13: =A12+1 -> 6 | B13: 1/0 | D13: LO | E13: DE+3 | F13: 10.22 | G13: 143.9 | I13: 2.712 | L13: DFR | M13: 46064 | N13: 46081 | O13: Karni Mata Construction Company | R13: RCC Complete, Backfilling Done
A14: =A13+1 -> 7 | B14: 6/0 | D14: Li | E14: DD45+0 | F14: 8.37 | G14: 114.8 | I14: 7.585 | L14: DFR | M14: 46072 | N14: 46081 | O14: Karni Mata Construction Company | R14: RCC Complete, Backfilling Done | AE14: 185
A15: =A14+1 -> 8 | B15: 2/1 | D15: LO | E15: DA+0 | F15: 2.74 | G15: 30.2 | I15: 2.712 | L15: DFR | M15: 46089 | N15: 46092 | O15: Karni Mata Construction Company | R15: RCC Complete, Backfilling Done
A16: =A15+1 -> 9 | B16: 2/0 | D16: LO | E16: DC1+0 | F16: 5.06 | G16: 61.79 | I16: 5.31 | J16: 1828.3 | L16: DFR | M16: 46081 | N16: 46094 | O16: Karni Mata Construction Company | R16: RCC Complete, Backfilling Done | AE16: 5
A17: =A16+1 -> 10 | B17: 2/2 | D17: LO | E17: DA-3 | F17: 2.74 | G17: 30.2 | I17: 2.712 | L17: DFR | M17: 46093 | N17: 46096 | O17: Karni Mata Construction Company | R17: RCC Complete, Backfilling Done
A18: =A17+1 -> 11 | B18: 2/3 | D18: LO | E18: DA+0 | F18: 2.74 | G18: 30.2 | I18: 2.712 | L18: DFR | M18: 46094 | N18: 46097 | O18: Karni Mata Construction Company | R18: RCC Complete, Backfilling Done
A19: =A18+1 -> 12 | B19: 2/4 | D19: LO | E19: DA+3 | F19: 2.92 | G19: 31.5 | I19: 2.911 | L19: DFR | M19: 46096 | N19: 46098 | O19: Karni Mata Construction Company | R19: RCC Complete, Backfilling Done
A20: =A19+1 -> 13 | B20: 1/0 | D20: LI | E20: DD60+0 | F20: 10.22 | G20: 143.9 | I20: 2.712 | L20: DFR | M20: 46091 | N20: 46103 | O20: Karni Mata Construction Company | R20: RCC Complete, Backfilling Done
A21: =A20+1 -> 14 | B21: 2/5 | D21: LO | E21: DA-3 | F21: 2.74 | G21: 30.2 | I21: 2.712 | L21: DFR | M21: 46105 | N21: 46108 | O21: Karni Mata Construction Company | R21: RCC Complete, Backfilling Done
A22: =A21+1 -> 15 | B22: 5/2 | D22: LI | E22: DA+0 | F22: 2.74 | G22: 30.2 | I22: 2.712 | L22: DFR | M22: 46101 | N22: 46112 | O22: Karni Mata Construction Company | R22: RCC Complete, Backfilling Done
A23: =A22+1 -> 16 | B23: 5/1 | D23: LI | E23: DA+0 | F23: 2.74 | G23: 30.2 | I23: 2.712 | L23: DFR | M23: 46112 | N23: 46114 | O23: Karni Mata Construction Company | R23: RCC Complete, Backfilling Done
A24: =A23+1 -> 17 | B24: 3/1 | D24: LO | E24: DA+3 | F24: 2.92 | G24: 31.5 | I24: 2.911 | L24: DFR | M24: 46108 | N24: 46116 | O24: Karni Mata Construction Company | R24: RCC Complete, Backfilling Done
A25: =A24+1 -> 18 | B25: 5/0 | D25: LI | E25: DC2+0 | F25: 6.05 | G25: 74.87 | I25: 6.44 | L25: DFR | M25: 46115 | N25: 46124 | O25: Karni Mata Construction Company | R25: RCC Complete, Backfilling Done
A26: =A25+1 -> 19 | B26: 4/5 | D26: LI | E26: DA+0 | F26: 2.74 | G26: 30.2 | I26: 2.712 | L26: DFR | M26: 46118 | N26: 46128 | O26: Karni Mata Construction Company | R26: RCC Complete, Backfilling Done
A27: =A26+1 -> 20 | B27: 3/3 | D27: LO | E27: DA+3 | F27: 2.92 | G27: 31.5 | I27: 2.911 | L27: DFR | M27: 46122 | N27: 46130 | O27: Karni Mata Construction Company | R27: RCC Complete, Backfilling Done
A28: =A27+1 -> 21 | B28: 3/2 | D28: LO | E28: DA+0 | F28: 2.74 | G28: 30.2 | I28: 2.712 | L28: DFR | M28: 46117 | N28: 46133 | O28: Karni Mata Construction Company | R28: RCC Complete, Backfilling Done
... A43: =A42+1 -> 36 | B43: 3B/0 | D43: LI | E43: DC2+3 | F43: 6.05 | G43: 74.87 | I43: 6.44 | L43: DFR | M43: 46174 | N43: 46188 | O43: Karni Mata Construction Company | R43: RCC Complete, Backfilling Done
A44: =A43+1 -> 37 | B44: 3/0 | D44: LI | E44: DD60+0 | F44: 10.22 | G44: 143.9 | L44: DFR | M44: 46172 | N44: 46197 | O44: Karni Mata Construction Company | R44: RCC Complete, Backfilling Done
A45: =A44+1 -> 38 | B45: 5/0 | D45: LO | E45: DD45+0 | F45: 8.37 | G45: 114.8 | I45: 7.585 | L45: DFR | M45: 46162 | N45: 46197 | O45: Karni Mata Construction Company | R45: RCC Complete, Backfilling Done
A46: =A45+1 -> 39 | B46: 5A/0 | D46: LO | E46: DC2+0 | F46: 6.05 | G46: 74.87 | I46: 6.44 | L46: DFR | M46: 46190 | N46: 46202 | O46: Karni Mata Construction Company | R46: RCC Complete, Backfilling Done
A47: =A46+1 -> 40 | B47: 3/0 | D47: LO | E47: DC1+0 | F47: 5.06 | G47: 61.79 | I47: 5.31 | J47: 1828.3 | L47: DFR | M47: 46177 | N47: 46205 | O47: Karni Mata Construction Company | R47: RCC Complete, Backfilling Done
A48: =A47+1 -> 41 | B48: 2A/0 | D48: LI | E48: DD45+0 | F48: 10.22 | G48: 143.9 | L48: DFR | M48: =N47+2 -> 46207 | N48: 46233 | O48: Karni Mata Construction Company | Q48: 12 | R48: RCC Complete
A49: =A48+1 -> 42 | B49: 2/0 | D49: LI | E49: DD60+0 | F49: 10.22 | G49: 143.9 | L49: DFR | O49: Karni Mata Construction Company | R49: ROW/Excavation WIP
A50: =A49+1 -> 43 | B50: 6/0 | D50: LO | E50: DD60+0 (Aux. X-arm) | F50: 10.22 | G50: 143.9 | L50: DFR | O50: Karni Mata Construction Company | Q50: 12 | R50: Frustum PitA, B RCC Done, Pit C RCC Frustum : Next :Pit D Excavation WIP

Sheet Erection 
A1: NAME OF PROJECT : FARHEGARH IV-BHINMAL 400KV D/C TRANSMISSION LINE
A2: Client : RAJASTHAN IV A POWER TRANSMISSION LTD.
