Workbook
Name A_D: INDEX(#REF!,MATCH(#REF!,#REF!,0))
Name AA: INDEX(#REF!,MATCH(#REF!,#REF!,0))
Name AB: INDEX(#REF!,MATCH(#REF!,#REF!,0))
Name AC: INDEX(#REF!,MATCH(#REF!,#REF!,0))
Name AE: INDEX(#REF!,MATCH(#REF!,#REF!,0))
Name AF: INDEX(#REF!,MATCH(#REF!,#REF!,0))
Name AG: INDEX(#REF!,MATCH(#REF!,#REF!,0))
Name AH: INDEX(#REF!,MATCH(#REF!,#REF!,0))
Name AI: INDEX(#REF!,MATCH(#REF!,#REF!,0))
Name AJ: INDEX(#REF!,MATCH(#REF!,#REF!,0))
Name AK: INDEX(#REF!,MATCH(#REF!,#REF!,0))
Name AL: INDEX(#REF!,MATCH(#REF!,#REF!,0))
Name AM: INDEX(#REF!,MATCH(#REF!,#REF!,0))
Name BA: INDEX(#REF!,MATCH(#REF!,#REF!,0))
Name BB: INDEX(#REF!,MATCH(#REF!,#REF!,0))
Name BC: INDEX(#REF!,MATCH(#REF!,#REF!,0))
Name BD: INDEX(#REF!,MATCH(#REF!,#REF!,0))
Name BE: INDEX(#REF!,MATCH(#REF!,#REF!,0))
Name BF: INDEX(#REF!,MATCH(#REF!,#REF!,0))
Name BG: INDEX(#REF!,MATCH(#REF!,#REF!,0))
Name BH: INDEX(#REF!,MATCH(#REF!,#REF!,0))
Name BI: INDEX(#REF!,MATCH(#REF!,#REF!,0))
Name BJ: INDEX(#REF!,MATCH(#REF!,#REF!,0))
Name BK: INDEX(#REF!,MATCH(#REF!,#REF!,0))
Name BL: INDEX(#REF!,MATCH(#REF!,#REF!,0))
Name BM: INDEX(#REF!,MATCH(#REF!,#REF!,0))
Name CA: INDEX(#REF!,MATCH(#REF!,#REF!,0))
Name CB: INDEX(#REF!,MATCH(#REF!,#REF!,0))
Name CC: INDEX(#REF!,MATCH(#REF!,#REF!,0))
Name CD: INDEX(#REF!,MATCH(#REF!,#REF!,0))
Name CE: INDEX(#REF!,MATCH(#REF!,#REF!,0))
Name CF: INDEX(#REF!,MATCH(#REF!,#REF!,0))
Name CG: INDEX(#REF!,MATCH(#REF!,#REF!,0))
Name CH: INDEX(#REF!,MATCH(#REF!,#REF!,0))
Name CI: INDEX(#REF!,MATCH(#REF!,#REF!,0))
Name CJ: INDEX(#REF!,MATCH(#REF!,#REF!,0))
Name CK: INDEX(#REF!,MATCH(#REF!,#REF!,0))
Name CL: INDEX(#REF!,MATCH(#REF!,#REF!,0))
Name CM: INDEX(#REF!,MATCH(#REF!,#REF!,0))
Name D_D: INDEX(#REF!,MATCH(#REF!,#REF!,0))
Name DA: INDEX(#REF!,MATCH(#REF!,#REF!,0))
Name DB: INDEX(#REF!,MATCH(#REF!,#REF!,0))
Name DC: INDEX(#REF!,MATCH(#REF!,#REF!,0))
Name DE: INDEX(#REF!,MATCH(#REF!,#REF!,0))
Name DF: INDEX(#REF!,MATCH(#REF!,#REF!,0))
Name DG: INDEX(#REF!,MATCH(#REF!,#REF!,0))
Name DH: INDEX(#REF!,MATCH(#REF!,#REF!,0))
Name DI: INDEX(#REF!,MATCH(#REF!,#REF!,0))
Name DJ: INDEX(#REF!,MATCH(#REF!,#REF!,0))
Name DK: INDEX(#REF!,MATCH(#REF!,#REF!,0))
Name DL: INDEX(#REF!,MATCH(#REF!,#REF!,0))
Name DM: INDEX(#REF!,MATCH(#REF!,#REF!,0))
Name DPR: #REF!&#REF!&#REF!&#REF!&#REF!&#REF!&#REF!&#REF!&#REF!&#REF!
Name EA: INDEX(#REF!,MATCH(#REF!,#REF!,0))
Name EB: INDEX(#REF!,MATCH(#REF!,#REF!,0))
Name EC: INDEX(#REF!,MATCH(#REF!,#REF!,0))
Name ED: INDEX(#REF!,MATCH(#REF!,#REF!,0))
Name EE: INDEX(#REF!,MATCH(#REF!,#REF!,0))
Name EF: INDEX(#REF!,MATCH(#REF!,#REF!,0))
Name EG: INDEX(#REF!,MATCH(#REF!,#REF!,0))

Sheet 765kV Summery
C3: TB-507 | D3: DAILY PROGRESS REPORT | M3: =NOW()-1 -> 46114.469
A4: CONTRACTUAL START DATE: | C4: 45632 | D4: FATEGARH III-BEAWAR 765KV D/C TRANSMISSION LILO LINE
A5: CONTRACTUAL FINISH DATE: | C5: 46178
A6: REPORTING DATE | D6: Client Name : RAJASTHAN IV A POWER TRANSMISSION LTD
A7: TOTAL DAYS | D7: NOA Ref No(Supply): RIVA/LOA-KEC(SUP)/AUG 24/405
A8: COMP. DAYS | D8: NOA Ref No(Service): RIVA/LOA-KEC(SER)/AUG 24/406
A9: Progress Summary | M9: =M3 -> 46114.469
A10: Sl No. | B10: Activity | C10: LOA Quantity | D10: Estimated Line Quantity | E10: Cumm. Progress till Last Month | F10: Plan For MAR'25 | G10: Progress in MAR'25 | H10: WIP | I10: Today's Progress | J10: Cumulative progress till date | K10: Balance | L10: ="Gangs working "&CHAR(10)&TEXT(M3,"mmm-yy") -> Gangs working Apr-26 | M10: Remarks
A11: A.i | B11: Route Alignment (Kms) | C11: 15.478 | D11: 15.478 | J11: 15.478 | K11: =D11-J11 -> 0 | M11: In the Scope of Rajasthan IV A Power Transmission Ltd
A12: ii | B12: Detailed Survey (Kms) | C12: 15.478 | D12: 15.478 | E12: 15.478 | G12: =D12-E12 -> 0 | J12: 15.478 | K12: =D12-J12 -> 0
A13: iii | B13: Check Survey (Kms) | C13: 15.478 | D13: 15.478 | E13: 15.478 | F13: 15.478 | J13: 15.478 | K13: =D13-J13 -> 0
A14: B. | B14: Soil Investigation (Nos) | C14: 26 | D14: 26 | E14: 26 | J14: 26 | K14: 0
A15: C. | B15: Foundation (Nos) | C15: 43 | D15: 43 | E15: 15 | F15: 0 | G15: 1 | H15: 2 | I15: 1 | J15: =SUM(E15+G15) -> 16 | K15: =D15-J15 -> 27 | L15: 2
A16: D. | B16: Earthing (Nos) | C16: 43 | D16: 43 | E16: 3 | F16: 0 | G16: 0 | I16: 0 | J16: =SUM(E16+G16) -> 3 | K16: =D16-J16 -> 40
A17: E. | B17: Tower Erection (Nos) | C17: 43 | D17: 43 | E17: 0 | F17: 0 | G17: 0 | H17: 1 | I17: 0 | J17: =SUM(E17+G17) -> 0 | K17: =D17-J17 -> 43
A18: F. | B18: Tack Welding (Nos) | C18: 43 | D18: 43 | J18: =E18+G18 -> 0 | K18: =D18-J18 -> 43
A19: G. | B19: Stringing (Kms) | K19: =D19-J19 -> 0
A20: i | B20: Paying Out (Kms) | C20: 15.478 | D20: 15.478 | E20: 0 | J20: =E20+G20 -> 0 | K20: =D20-J20 -> 15.478
A21: ii | B21: Final Sag (Kms) | C21: 15.478 | D21: 15.478 | E21: 0 | J21: =E21+G21 -> 0 | K21: =D21-J21 -> 15.478
A22: I. | B22: OPGW Stringing (Kms) | C22: 15.478 | D22: 15.478 | E22: 0 | J22: =E22+G22 -> 0 | K22: =D22-J22 -> 15.478
K23: =D23-J23 -> 0

Sheet Check Survey 
A100: Sr. no | B100: Section AP To AP | C100: Section length | D100: Check Survey | E100: Details Survey | F100: Remarks
A101: 1 | B101: S/S Gantry To AP-7/0 | C101: 10.369 | D101: YES | E101: YES | F101: Details Survey Completed. Profile & Tower Schedule Submitted with Apraava Engg.
A102: =A101+1 -> 2 | B102: AP-7/0 To AP-10/0 | C102: 8.713 | D102: YES | F102: Approved
A103: =A102+1 -> 3 | B103: AP-10/0 To AP-21/0 | C103: 19.57 | D103: YES | F103: Approved
A104: =A103+1 -> 4 | B104: AP-21/0 To AP-24/0 | C104: 2.618 | D104: YES | F104: Approved
A105: =A104+1 -> 5 | B105: AP-24/0 To AP-27/0 | C105: 1.44 | D105: YES | F105: Check Survey Completed. Profile & Tower Schedule Submitted with Apraava Engg.
A106: =A105+1 -> 6 | B106: AP-27/0 To AP-40/0 | C106: 16.759 | D106: YES | F106: Approved
A107: =A106+1 -> 7 | B107: AP-40/0 To AP-45/0 | C107: 6.672 | D107: YES | F107: Approved
A108: =A107+1 -> 8 | B108: AP-45/0 To AP-48/0 | C108: 3.172 | D108: YES | E108: YES | F108: Details Survey Completed. Profile & Tower Schedule Submitted with Apraava Engg.
A109: =A108+1 -> 9 | B109: AP 48/0 to AP 51/0, | C109: 1.05 | D109: Yes | F109: Approved
A110: =A109+1 -> 10 | B110: AP-51/0 To AP-60/0 | C110: 7.962 | D110: Yes | F110: Approved
A111: =A110+1 -> 11 | B111: AP-60/0 To AP-75/0 | C111: 19.567 | D111: Yes | F111: Approved
A112: =A111+1 -> 12 | B112: AP-75/0 To AP-92/0 | C112: 20.273 | D112: Yes | F112: Approved
A113: =A112+1 -> 13 | B113: AP-92/0 To AP-96/0 | C113: 3.084 | D113: Yes | F113: Approved
A114: =A113+1 -> 14 | B114: AP-96/0 To AP-107/0 | C114: 14.119 | D114: Yes | F114: Approved
A115: =A114+1 -> 15 | B115: AP-107/0 To AP-121/0 | C115: 9.495 | D115: Yes | F115: Approved
A116: =A115+1 -> 16 | B116: AP-121/0 To AP-131/0 | C116: 8.697 | D116: Yes | F116: Approved
A117: =A116+1 -> 17 | B117: AP-131/0 To AP-139/0 | C117: 12.65 | D117: Yes | F117: Approved
A118: =A117+1 -> 18 | B118: AP-139/0 To AP-148/0 | C118: 14.392 | D118: Yes | F118: Approved
A119: =A118+1 -> 19 | B119: AP-148/0 To AP-153/0 | C119: 6.321 | D119: Yes | F119: Approved
A120: =A119+1 -> 20 | B120: AP-153/0 To S/S Gantry | C120: 1.521 | D120: Yes | F120: Check Survey Completed. Profile & Tower Schedule Submitted with Apraava Engg.
B121: TOTAL | C121: =SUM(C101:C120) -> 188.444

Sheet Check Survey Status
A1: NAME OF PROJECT : FARHEGARH IV-BHINMAL 400KV D/C TRANSMISSION LINE
A2: Client : RAJASTHAN IV A POWER TRANSMISSION LTD.
A3: CONTRACTOR : KEC INTERNATIONAL LIMITED
A4: 400 KV CHECK SURVEY
A5: SL No | B5: Section | C5: Section Length | D5: Submission Date | E5: Approval Date | F5: Remarks
A6: 1 | B6: AP 51- AP 54 | C6: 2.653 | D6: 45684 | E6: 45691 | F6: Approved
A7: =A6+1 -> 2 | B7: AP 54- AP 60 | C7: 5.31 | F7: Approved
A8: =A7+1 -> 3 | B8: AP 60- AP 75 | C8: 19.672 | D8: 15.02.2025 , 24-02-2025 25-02-2025 | E8: 45713 | F8: Approved | G8: Required Change
A9: =A8+1 -> 4 | B9: AP 75- AP 92 | C9: 20.273 | D9: 45657 | E9: 45691 | F9: Approved
A10: =A9+1 -> 5 | B10: AP 92- AP 96 | C10: 3.084 | D10: 15-02-25 & 21-02-2025 | E10: 45712 | F10: Approved
A11: =A10+1 -> 6 | B11: AP 96- AP 97 | C11: 1.063 | D11: 45713 | E11: 45715 | F11: Approved
A12: =A11+1 -> 7 | B12: AP 97- AP 98B | C12: 2.09 | D12: 45713 | F12: Approved
A13: =A12+1 -> 8 | B13: AP 98B- 99A/0 | C13: 3.893 | D13: 45713 | F13: Approved
A14: =A13+1 -> 9 | B14: AP99A/0-AP 107 | C14: 6.971 | D14: 45713 | F14: Approved
A15: =A14+1 -> 10 | B15: AP 107- AP 121 | C15: 9.495 | D15: 45721 | E15: 45722 | F15: Approved
A16: =A15+1 -> 11 | B16: AP 121- AP 131 | C16: 8.697 | D16: 12-03-2025 & ReSubmission 4-04-2025 | F16: Submitted | G16: Resubmitted
A17: =A16+1 -> 12 | B17: AP 131- AP 133 | C17: 3.084 | F17: Submitted
A18: =A17+1 -> 13 | B18: AP 133- AP 134 | C18: 3.963 | F18: Submitted
A19: =A18+1 -> 14 | B19: AP 134- AP 135 | C19: 1.656 | F19: Submitted
A20: =A19+1 -> 15 | B20: AP 135- AP 136 | C20: 1.635 | F20: Submitted
A21: =A20+1 -> 16 | B21: AP 136 - AP 139 | C21: 2.221 | F21: Submitted
A22: =A21+1 -> 17 | B22: AP 139 - AP 147 | C22: 10.724 | D22: 26-03-2025 Resubmission 4-04-2025 &28-04-25 | F22: Submitted | G22: Resubmitted
A23: =A22+1 -> 18 | B23: AP 147/0 - AP 148 | C23: 3.666 | D23: 26-03-2025 Resubmission 4-04-2025 & 28-04-25 | F23: Submitted | G23: Resubmitted
A24: =A23+1 -> 19 | B24: AP148/0 - AP 149B | C24: 4.88 | F24: Submitted
A25: =A24+1 -> 20 | B25: AP 150 to Bhinmal GTY | C25: 2.474 | D25: 45765 | F25: Submitted
A26: =A25+1 -> 21 | B26: AP 50- AP 51 | C26: 0.275 | D26: 45752 | F26: Submitted
A27: =A26+1 -> 22 | B27: AP 47- AP 50 | C27: 2.008 | D27: 45752 | F27: Submitted
A28: =A27+1 -> 23 | B28: AP 46- AP 47 | C28: 0.223 | D28: 45752 | F28: Submitted
A29: =A28+1 -> 24 | B29: AP 42- AP 43 | C29: 2.731 | D29: 45752 | F29: Submitted
A30: =A29+1 -> 25 | B30: AP 45- AP 46 | C30: 1.717 | D30: 45752 | F30: Submitted
A31: =A30+1 -> 26 | B31: AP 43- AP 45 | C31: 1.068 | D31: 45752 | F31: Submitted
A32: =A31+1 -> 27 | B32: AP 40- AP 42 | C32: 2.873 | D32: 45752 | F32: Submitted
A34: =A32+1 -> 28 | B34: AP 10- AP 21 | C34: 19.57 | D34: 16-04-2025 & 16.05.2025 | F34: Re Submitted
A35: =A34+1 -> 29 | B35: 21/0-24/0 | C35: 2.618 | D35: 45781 | F35: Complete
A36: =A35+1 -> 30 | B36: 24/0-40/0 | C36: 18.193 | D36: 45805 | F36: Complete
B39: AS on date | C39: =SUM(C6:C36) -> 168.78
B43: Submission of Check Survey
A44: SL. No. | B44: Section | C44: Date of submission | D44: Section Length in kms | E44: Letter Reference Number | F44: Date of Approval | G44: Section Length in kms
A45: 1 | B45: AP75 To AP92 | C45: 45657 | D45: 20.273 | E45: KEC/FBTL/RPTL/TB507/008A | F45: 45691 | G45: 20.273
A46: =A45+1 -> 2 | B46: AP51 To AP60 | C46: 45684 | D46: 7.962 | E46: KEC/FBTL/RPTL/TB507/0014 | F46: 45691 | G46: 7.962
...

Sheet Check Survey
A1: NAME OF PROJECT : FARHEGARH IV-BHINMAL 400KV D/C TRANSMISSION LINE
A2: Client : RAJASTHAN IV A POWER TRANSMISSION LTD.
A3: CONTRACTOR : KEC INTERNATIONAL LIMITED
A4: 400 KV CHECK SURVEY
A5: SL No | B5: Section | C5: Section Length | D5: Submission Date | E5: Approval Date | F5: Remarks
A6: 1 | B6: AP 51- AP 54 | C6: 2.653 | D6: 45684 | E6: 45691 | F6: Approved
A7: =A6+1 -> 2 | B7: AP 54- AP 60 | C7: 5.31 | F7: Approved
A8: =A7+1 -> 3 | B8: AP 60- AP 75 | C8: 19.672 | D8: 15.02.2025 , 24-02-2025 25-02-2025 | E8: 45713 | F8: Approved | G8: Required Change | H8: Approved | I8: =G63 -> 97.59
A9: =A8+1 -> 4 | B9: AP 75- AP 92 | C9: 20.273 | D9: 45657 | E9: 45691 | F9: Approved
A10: =A9+1 -> 5 | B10: AP 92- AP 96 | C10: 3.084 | D10: 15-02-25 & 21-02-2025 | E10: 45712 | F10: Approved | H10: Submitted | I10: =D63 -> 151.916
A11: =A10+1 -> 6 | B11: AP 96- AP 97 | C11: 1.063 | D11: 45713 | E11: 45715 | F11: Approved
A12: =A11+1 -> 7 | B12: AP 97- AP 98B | C12: 2.09 | D12: 45713 | F12: Approved
A13: =A12+1 -> 8 | B13: AP 98B- 99A/0 | C13: 3.893 | D13: 45713 | F13: Approved
A14: =A13+1 -> 9 | B14: AP99A/0-AP 107 | C14: 6.971 | D14: 45713 | F14: Approved
A15: =A14+1 -> 10 | B15: AP 107- AP 121 | C15: 9.495 | D15: 45721 | E15: 45722 | F15: Approved
A16: =A15+1 -> 11 | B16: AP 121- AP 131 | C16: 8.697 | D16: 12-03-2025 & ReSubmission 4-04-2025 | F16: Submitted | G16: Resubmitted
A17: =A16+1 -> 12 | B17: AP 131- AP 133 | C17: 3.084 | F17: Submitted
A18: =A17+1 -> 13 | B18: AP 133- AP 134 | C18: 3.963 | F18: Submitted
A19: =A18+1 -> 14 | B19: AP 134- AP 135 | C19: 1.656 | F19: Submitted
A20: =A19+1 -> 15 | B20: AP 135- AP 136 | C20: 1.635 | F20: Submitted
A21: =A20+1 -> 16 | B21: AP 136 - AP 139 | C21: 2.221 | F21: Submitted
A22: =A21+1 -> 17 | B22: AP 139 - AP 147 | C22: 10.724 | D22: 26-03-2025 Resubmission 4-04-2025 &28-04-25 | F22: Submitted | G22: Resubmitted
A23: =A22+1 -> 18 | B23: AP 147/0 - AP 148 | C23: 3.666 | D23: 26-03-2025 Resubmission 4-04-2025 & 28-04-25 | F23: Submitted | G23: Resubmitted | M23: Blance | N23: =187.176-M11 -> 187.176
A24: =A23+1 -> 19 | B24: AP148/0 - AP 149B | C24: 4.88 | F24: Submitted
A25: =A24+1 -> 20 | B25: AP 150 to Bhinmal GTY | C25: 2.474 | D25: 45765 | F25: Submitted
A26: =A25+1 -> 21 | B26: AP 50- AP 51 | C26: 0.275 | D26: 45752 | F26: Submitted
A27: =A26+1 -> 22 | B27: AP 47- AP 50 | C27: 2.008 | D27: 45752 | F27: Submitted
A28: =A27+1 -> 23 | B28: AP 46- AP 47 | C28: 0.223 | D28: 45752 | F28: Submitted
A29: =A28+1 -> 24 | B29: AP 42- AP 43 | C29: 2.731 | D29: 45752 | F29: Submitted
A30: =A29+1 -> 25 | B30: AP 45- AP 46 | C30: 1.717 | D30: 45752 | F30: Submitted
A31: =A30+1 -> 26 | B31: AP 43- AP 45 | C31: 1.068 | D31: 45752 | F31: Submitted
A32: =A31+1 -> 27 | B32: AP 40- AP 42 | C32: 2.873 | D32: 45752 | F32: Submitted
A34: =A32+1 -> 28 | B34: AP 10- AP 21 | C34: 19.57 | D34: 16-04-2025 & 16.05.2025 | F34: Re Submitted
A35: =A34+1 -> 29 | B35: 21/0-24/0 | C35: 2.618 | D35: 45781 | F35: Complete
A36: =A35+1 -> 30 | B36: 24/0-40/0 | C36: 18.193 | D36: 45805 | F36: Complete | I36: =155.849-130.528 -> 25.321
B39: AS on date | C39: =SUM(C6:C36) -> 168.78
B43: Submission of Check Survey
A44: SL. No. | B44: Section | C44: Date of submission | D44: Section Length in kms | E44: Letter Reference Number | F44: Date of Approval | G44: Section Length in kms | H44: Approved By | I44: Remarks
A45: 1 | B45: AP75 To AP92 | C45: 45657 | D45: 20.273 | E45: KEC/FBTL/RPTL/TB507/008A | F45: 45691 | G45: 20.273 | H45: Gundewadi Mallappa
A46: =A45+1 -> 2 | B46: AP51 To AP60 | C46: 45684 | D46: 7.962 | E46: KEC/FBTL/RPTL/TB507/0014 | F46: 45691 | G46: 7.962 | H46: Gundewadi Mallappa
...

Sheet Sheet8
A1: S No. | B1: MOM as on 11/6/25 | C1: Timeline | D1: Responsibility | E1: Status as on 19/6/25
A2: 1 | B2: 400kv Detail Survey from AP 01 to AP 10
A3: a | B3: Apraava will give clearance for further proceeding of Detail Survey | C3: 45821 | D3: M/S Apraava | E3: Clearance provided for Detail Survey
A4: b | B4: Completion of Detail Survey | C4: 45833 | D4: M/S KEC | E4: Detail Survey work under progress
A5: c | B5: Detail Survey of 765 kV is submitted by KEC, observation raised by Apraava, KEC has to re-submitted according to observation | C5: 45824 | D5: M/S KEC | E5: Reobservation mail by Engg. Team on dt. 19.06.25
A6: 2 | B6: Check Survey
A7: a | B7: 50 km will be approved | C7: 45820 | D7: M/S Apraava & KEC | E7: 33 km Approved & 15 km submitted by KEC
A8: b | B8: Pending Section of 21 km will be approved | C8: 45828 | D8: M/S Apraava & KEC | E8: Under Progress
A9: c | B9: Check Survey of 765kV is to be submitted by KEC | C9: 46198 | D9: M/S KEC | E9: Detail Survey work under progress
A10: 3 | B10: Statutory Approvals
A11: a | B11: 02 No NH Proposal Submission | C11: 45838 | D11: M/S KEC | E11: Under Progress
A12: b | B12: 02 No Railway Proposal Submission | C12: 45838 | D12: M/S KEC | E12: Under Progress
A13: c | B13: 02 Nos PLC Proposal of 400 kV Underneath has to Submit | C13: ASAP | D13: M/S KEC | E13: Under Progress
A14: d | B14: Statutory Approvals tracker to be maintain for monitoring current status of NOC | C14: N/A | D14: M/S Apraava & KEC | E14: Under Progress
A15: e | B15: 04 Submission of SH Proposal to SH Authority | C15: 45828 | D15: M/S Apraava | E15: Under Progress
A16: f | B16: 03 Submission of Oil Proposal to Oil Authority | C16: 45828 | D16: M/s Apraava | E16: Under Progress
A17: 4 | B17: Deployment of surveyor, supervisors, engineers & section in charge to be expedite in Bhinmal Section | C17: 45820 | D17: M/S KEC | E17: Under Progress
A18: 5 | B18: KEC committed 43 nos. foundation for this month & accordingly Apraava will provide ROW clearance | C18: 45838 | D18: M/S Apraava & KEC | E18: Till date 13 foundations completed, 10 are in WIP and 30 work fronts are available
A19: 6 | B19: Manpower in each foundation gang need to be strengthen with at least 8-10 manpower/gang | C19: ASAP | D19: M/S KEC | E19: Under Progress
A20: 7 | B20: Apraava asked to increase 4 more foundation gangs to expedite foundation work (currently 7 gangs are available with insufficient manpower | C20: ASAP | D20: M/S KEC | E20: 9 Gangs are available (insufficient manpower in 4 gangs)
A21: 8 | B21: 40 Nos Departmental Manpower availability at site | C21: 45838 | D21: M/S KEC | E21: -
A22: 9 | B22: Quality Constraints
A23: a | B23: Information regarding supply of cement with prior & proper documentation | C23: N/A | D23: M/S KEC | E23: -
A24: b | B24: Material availability at site from approved source | C24: - | D24: M/S KEC | E24: -
A25: c | B25: Approval of use of Curing compound in foundation work need to be expedite after jointly discussion of both team | C25: ASAP | D25: M/S Apraava & KEC | E25: Cubes taken after applying curing compound & further process is u/p
A26: d | B26: CTM Machine at store need be installed on priority for cube testing | C26: 45821 | D26: M/S KEC | E26: Under Progress
A27: 10 | B27: Erection team to be deployed and erection to be start | C27: 45826 | D27: M/S KEC | E27: Erection to be start by Monday, 23/6/25
A28: 11 | B28: July month foundation & erection plan to be shared by KEC | C28: 45824 | D28: M/S KEC | E28: July month plan to be shared within 2-3 days by KEC
A29: 12 | B29: Supply of conductor to be start in September month | C29: 45930 | D29: M/S Apraava | E29: Planned for September month
A30: 13 | B30: Total 121 nos. of DA type of tower supplied to store & 2nd lot of 74 nos. towers (approx. 1500 MT) supply, consisting of DC & DD type towers are scheduled for next month | C30: 45848 | D30: M/S KEC | E30: DA type towers are supplied

Sheet Sheet2
C2: 400kV D/C Fatehgarh IV (Section-2)PS - Bhinmal (PG) Transmission Line
C4: Sl No | D4: Section AP To AP | E4: Section length | F4: Remarks
C5: 1 | D5: AP-21/0 To AP-24/0 | E5: 2.618
C6: =C5+1 -> 2 | D6: AP-24/0 To AP-27/0 | E6: 1.428
C7: =C6+1 -> 3 | D7: AP-27/0 To AP-40/0 | E7: 16.76
C8: =C7+1 -> 4 | D8: AP-45/0 To AP-48/0 | E8: 3.187
C9: =C8+1 -> 5 | D9: AP-153/0 To AP-154/0 | E9: 0.732
C10: =C9+1 -> 6 | D10: AP-154/0 To AP-155/0 | E10: 0.218
C11: =C10+1 -> 7 | D11: AP-155/0 To S/S Gantry | E11: 0.571
D12: TOTAL | E12: =SUM(E5:E11) -> 25.514
C14: 765kV D/C Fatehgarh IV (Section-2)PS - Bhinmal (PG) Transmission Line
C16: Sl No | D16: Section AP To AP | E16: Section length | F16: Route Allignment,Detail Survey,Check survey
D17: LI | E17: =7584/1000 -> 7.584
D18: LO | E18: =6951/1000 -> 6.951
D19: TOTAL | E19: =SUM(E17:E18) -> 14.535

Sheet Sheet1
B1: FOUNDATION STATUS | J1: =SUBTOTAL(3,J5:J24) -> 18
B2: SL. No. | C2: Location Number | D2: Span | E2: Tower Type | F2: RC | G2: Foundation type
H3: Starting date | I3: Completion Date | J3: Agency | K3: Remark | L3: Remarks
B4: 1 | C4: 83/1 | D4: 83/1 | E4: DA+3 | G4: Sandy | H4: 45665 | I4: 45674 | J4: Mahadeep Company | K4: 45674 | L4: Complete
B5: =B4+1 -> 2 | C5: 81/4 | D5: 81/4 | E5: DA+0 | G5: Sandy | H5: 45675 | I5: ROW | J5: Mahadeep Company | K5: ROW LOC HOLD | L5: Row Since 20-01-2025, Gang Domobilized
B6: =B5+1 -> 3 | C6: 75/7 | D6: 75/7 | E6: DA+0 | G6: Sandy | H6: 45675 | I6: 45684 | J6: AR PATEL | L6: RCC Complete
B7: =B6+1 -> 4 | C7: 75/6 | E7: DA+0 | G7: Sandy | H7: 45685 | I7: 45690 | J7: AR PATEL | L7: RCC Complete, Backfilling Done
B8: =B7+1 -> 5 | C8: 75/5 | E8: DA+0 | G8: Sandy | H8: 45685 | I8: 45693 | J8: AR PATEL | L8: RCC Complete.
B9: =B8+1 -> 6 | C9: 75/4 | E9: DA+0 | G9: Sandy | H9: 45686 | I9: 45693 | J9: Om Constraction | L9: RCC Complete, Backfilling Done
B10: =B9+1 -> 7 | C10: 75/3 | E10: DA+3 | G10: Sandy | H10: 45691 | I10: 45698 | J10: Om Constraction | L10: RCC Complete.
B11: =B10+1 -> 8 | C11: 75/1 | E11: DA+0 | G11: Sandy | H11: 45697 | I11: 45705 | J11: Om Constraction | L11: RCC Complete.
B12: =B11+1 -> 9 | C12: 75/2 | E12: DA+0 | G12: Sandy | H12: 45700 | I12: 45706 | J12: Om Constraction | L12: RCC Complete.
B13: =B12+1 -> 10 | C13: 77/1 | E13: DA+0 | G13: Sandy | H13: 45691 | I13: 45699 | J13: Anjaana Construction | L13: RCC Complete.
B14: =B13+1 -> 11 | C14: 77/2 | E14: DA+3 | G14: Sandy | H14: 45691 | I14: 45697 | J14: AR PATEL | L14: RCC Complete, Backfilling Done
B15: =B14+1 -> 12 | C15: 77/3 | E15: DA+0 | G15: Sandy | H15: 45696 | I15: 45702 | J15: AR PATEL | L15: RCC Complete.
B16: =B15+1 -> 13 | C16: 77/4 | E16: DA+3 | G16: Sandy | H16: 42046 | I16: 45705 | J16: Anjaana Construction | L16: RCC Complete.
B17: =B16+1 -> 14 | C17: 77/5 | E17: DA+6 | G17: Sandy | H17: 45701 | J17: AR PATEL | L17: Pit B,C RCC Done & Pit A,D Frustrum RCC done.
B18: =B17+1 -> 15 | C18: 86/2 | E18: DA+0 | G18: Sandy | H18: 45698 | J18: Kalpana Enterprises | L18: Pit A , Pit B RCC Done , Pit C -Stub setting.
B19: =B18+1 -> 16 | C19: 66/1 | E19: DA+9 | G19: Sandy | H19: 45705 | J19: Siyag Construction | L19: Excavation WIP, ROW,Material Shifting WIP
B20: =B19+1 -> 17 | C20: 73/3 | E20: DA+9 | G20: Sandy | H20: 45705 | J20: Om Constraction | L20: Excavation WIP, ROW, Material Shifting WIP
B21: =B20+1 -> 18 | C21: 79/1 | E21: DA+9 | G21: Sandy | H21: 45705 | J21: Anjana Construction | L21: Excavation WIP, ROW, Material Shifting WIP
B22: =B21+1 -> 19 | C22: 95A/1 | E22: DA+0 | G22: Sandy | J22: Gurukripa Enterprises | L22: Pit Marking Done
B23: =B22+1 -> 20 | C23: 80/1
B24: =B23+1 -> 21 | C24: 85/1
B25: =B24+1 -> 22 | C25: 73/2
B26: =B25+1 -> 23 | C26: 66/2
B27: =B26+1 -> 24 | C27: 66/3
B28: =B27+1 -> 25 | C28: 86/1
B29: =B28+1 -> 26 | C29: 76/1

Sheet VC 51-96
B1: TB-507 400 KV (Twin) D/C Fatehgarh IV - Bhinmal Transmission Line
A2: DPR and VISUAL CHART
A4: DPR- | D4: District | F4: No.Of Towers | G4: Length | H4: Foundation | K4: Earthing | L4: Tower Erection | O4: Stringing
H5: Com | I5: WIP | J5: Bal | K5: Com | L5: Com | M5: WIP | N5: Bal | O5: Com | P5: WIP | Q5: Bal
F6: 163 | G6: 50.886 | H6: 16 | I6: 5 | J6: =F6-H6-I6 -> 142 | K6: 10 | N6: =F6-L6 -> 163 | Q6: =G6-O6 -> 50.886
C8: =A8+1 -> 1 | E8: =C8+1 -> 2 | G8: =E8+1 -> 3 | I8: =G8+1 -> 4 | K8: =I8+1 -> 5 | M8: =K8+1 -> 6 | O8: =M8+1 -> 7 | Q8: =O8+1 -> 8 | S8: =Q8+1 -> 9
D10: 465.03 | F10: 375.98 | H10: 414.86 | J10: 381.02 | L10: 353.63 | N10: 351.4 | P10: 433.26 | R10: 396.56 | T10: 408.11 | U10: =B10+F10+H10+J10+L10+D10+N10+P10+R10+T10 -> 3579.85
C13: AP51 | E13: 51/1 | G13: 51/2 | I13: 51/3 | K13: AP52 | M13: 52/1 | O13: AP53 | Q13: AP54 | S13: 54/1
C14: DD+18 | E14: DA+03 | G14: DA+00 | I14: DA+03 | K14: DB+0 | M14: DA+06 | O14: DD+0 | Q14: DC+00 | S14: DA+03
K15: RC | M15: RC
B17: =S8+1 -> 10 | D17: =B17+1 -> 11 | F17: =D17+1 -> 12 | H17: =F17+1 -> 13 | J17: =H17+1 -> 14 | L17: =J17+1 -> 15 | N17: =L17+1 -> 16 | P17: =N17+1 -> 17 | R17: =P17+1 -> 18 | T17: =R17+1 -> 19
C19: 425.22 | E19: 420.54 | G19: 340.56 | I19: 336.52 | K19: 375.99 | M19: 303.41 | O19: 448.76 | Q19: 393.09 | S19: 407.8 | U19: 206.06 | V19: =C19+G19+I19+K19+M19+E19+O19+Q19+S19+U19 -> 3657.95
B22: 54/2 | D22: 54/3 | F22: AP55 | H22: AP56 | J22: 56/1 | L22: 56/2 | N22: 56/3 | P22: 56/4 | R22: 56/5 | T22: AP57
B23: DA+06 | D23: DA+03 | F23: DD+18 | H23: DB+09 | J23: DB+9 | L23: DA+0 | N23: DB+9 | P23: DA+6 | R23: DA+6 | T23: DB+09
B24: Benching &RC | D24: RC | F24: RC | H24: Benching &RC | L24: Benching Required | R24: Benching &RC | T24: Benching &RC
B26: =T17+1 -> 20 | D26: =B26+1 -> 21 | F26: =D26+1 -> 22 | H26: =F26+1 -> 23 | J26: =H26+1 -> 24 | L26: =J26+1 -> 25 | N26: =L26+1 -> 26 | P26: =N26+1 -> 27 | R26: =P26+1 -> 28 | T26: =R26+1 -> 29
C28: 417.38 | E28: 304.56 | G28: 408.66 | I28: 434.89 | K28: 408.17 | M28: 398.59 | O28: 446.37 | Q28: 297.58 | S28: 240.47 | U28: 312.69 | V28: =C28+G28+I28+K28+M28+E28+O28+Q28+S28+U28 -> 3669.36
B31: AP58 | D31: AP59 | F31: 59/1 | H31: AP60 | J31: 60/1 | L31: 60/2 | N31: 60/3 | P31: AP61 | R31: 61/1 | T31: AP62
B32: DB+09 | D32: DC+09 | F32: DA+0 | H32: DD+00 | J32: DA+9 | L32: DA+0 | N32: DA+9 | P32: DC+00 | R32: DA+9 | T32: DB+00
F33: Benching | N33: RC
B35: =T26+1 -> 30 | D35: =B35+1 -> 31 | F35: =D35+1 -> 32 | H35: =F35+1 -> 33 | J35: =H35+1 -> 34 | L35: =J35+1 -> 35 | N35: =L35+1 -> 36 | P35: =N35+1 -> 37 | R35: =P35+1 -> 38 | T35: =R35+1 -> 39
C37: 347.88 | E37: 379.25 | G37: 398.7 | I37: 439.06 | K37: 381.53 | M37: 379.71 | O37: 426.3 | Q37: 387.14 | U37: 423.77 | V37: =C37+G37+I37+K37+M37+E37+#REF!+O37+Q37+#REF! -> #REF!
B40: 62/1 | D40: 62/2 | F40: 62/3 | H40: 62/4 | J40: 62/5 | L40: AP63 | N40: 63/1 | P40: AP64 | R40: 64/1 | T40: 64/2
B41: DA+0 | D41: DA+0 | F41: DA+09 | H41: DA+06 | J41: DA+06 | L41: DC+00 | N41: DA+0 | P41: DC+09 | R41: DA+9 | T41: DA+9
B42: RC | F42: RC | P42: Benching &RC | T42: RC
B43: =T35+1 -> 40 | D43: =B43+1 -> 41 | F43: =D43+1 -> 42 | H43: =F43+1 -> 43 | J43: =H43+1 -> 44 | L43: =J43+1 -> 45 | N43: =L43+1 -> 46 | P43: =N43+1 -> 47 | R43: =P43+1 -> 48 | T43: =R43+1 -> 49
C45: 407.9 | E45: 426.63 | G45: 392.27 | I45: 431.96 | K45: 426.02 | M45: 405.36 | O45: 411.93 | Q45: 423.77 | S45: 407.9 | U45: 426.63
B46: F | D46: WIP | R46: F | T46: F
B48: 64/3 | D48: 64/4 | F48: 64/5 | H48: 64/6 | J48: 64/7 | L48: 65/0 | N48: 65/1 | P48: 66/0 | R48: 66/1 | T48: 66/2
B49: DA+9 | D49: DA+9 | F49: DA+9 | H49: DA+3 | J49: DA+3 | L49: DD+0 | N49: DB+09 | P49: DD+0 | R49: DA+9 | T49: DA+0 | V49: =#REF!+I77+K77+M77+O77+G77+Q77+S77+#REF!+#REF! -> #REF!
P50: RC
B51: =T43+1 -> 50 | D51: =B51+1 -> 51 | F51: =D51+1 -> 52 | H51: =F51+1 -> 53 | J51: =H51+1 -> 54 | L51: =J51+1 -> 55 | N51: =L51+1 -> 56 | P51: =N51+1 -> 57 | R51: =P51+1 -> 58 | T51: =R51+1 -> 59
C53: 392.27 | E53: 431.96 | G53: 426.02 | I53: 405.36 | K53: 411.93 | M53: 350.33 | O53: 378.3 | Q53: 416.82 | S53: 371.85
B54: WIP
B56: 66/3 | D56: 66/4 | F56: 67/0 | H56: 67/1 | J56: 67/2 | L56: AP68 | N56: AP69 | P56: 69/1 | R56: 69/2 | T56: 69/3
B57: DA+3 | D57: DA+9 | F57: DC+6 | H57: DA+6 | J57: DB+0 | L57: DB+09 | N57: DD+3 | P57: DA+6 | R57: DA+0 | T57: DA+00
F58: RC | R58: Benching | T58: RC | V58: =A85+I77+K77+M77+O77+G77+Q77+S77+#REF!+C77 -> #REF!
B59: =T51+1 -> 60 | D59: =B59+1 -> 61 | F59: =D59+1 -> 62 | H59: =F59+1 -> 63 | J59: =H59+1 -> 64 | L59: =J59+1 -> 65 | N59: =L59+1 -> 66 | P59: =N59+1 -> 67 | R59: =P59+1 -> 68 | T59: =R59+1 -> 69
C61: 392.27 | E61: 431.96 | G61: 426.02 | I61: 405.36 | K61: 411.93 | M61: 350.33 | O61: 378.3 | Q61: 416.82 | S61: 371.85
T62: F
...

Sheet VC
C2: TB-507 400 KV (Twin) D/C Fatehgarh IV - Bhinmal Transmission Line
C3: DPR and VISUAL CHART
C5: DPR- | F5: District | H5: No.Of Towers | I5: Length | J5: Foundation | M5: Earthing | N5: Tower Erection | Q5: Stringing
J6: Com | K6: WIP | L6: Bal | M6: Com | N6: Com | O6: WIP | P6: Bal | Q6: Com | R6: WIP | S6: Bal
H7: 495 | I7: 187.175 | J7: 9 | K7: 5 | L7: =H7-J7-K7 -> 481 | M7: 3 | P7: =H7-N7 -> 495 | S7: =I7-Q7 -> 187.175
I8: r
C9: 1 | E9: =C9+1 -> 2 | G9: =E9+1 -> 3 | I9: =G9+1 -> 4 | K9: =I9+1 -> 5 | M9: =K9+1 -> 6 | O9: =M9+1 -> 7 | Q9: =O9+1 -> 8 | S9: =Q9+1 -> 9 | U9: =S9+1 -> 10
D11: 97.4 | F11: 139.42 | H11: 484.04 | J11: 398 | L11: 443.16 | N11: 399.53 | P11: 402.87 | R11: 437.15 | T11: 381.84 | V11: 416.91 | W11: =D11+H11+J11+L11+N11+F11+P11+R11+T11+V11 -> 3600.32 | X11: FDN | Y11: TE | Z11: Earthing | AA11: Stringing | AC11: Tack Welding | AE11: =SUM(D11:V11) -> 3600.32
A12: 1 | X12: =COUNTIF(C12:U12,"F") -> 0 | Y12: =COUNTIF(C11:U11,"E") -> 0 | Z12: =COUNTIF(C13:V13,"Er") -> 0 | AB12: COM
X13: =COUNTIF(C13:U13,"U/P") -> 0 | Y13: 0 | Z13: 0 | AB13: WIP
C14: GE | E14: AP1 | G14: AP2 | I14: AP3 | K14: 03/1 | M14: 3/2 | O14: 3/3 | Q14: 3/4 | S14: 3/5 | U14: 3/6 | X14: =COUNTIF(C12:U12,"ROW") -> 0 | Y14: 0 | Z14: 0 | AB14: ROW
E15: DD+03 | G15: DD+9 | I15: DC+9 | K15: DA+9 | M15: DA+0 | O15: DA+3 | Q15: DA+6 | S15: DA+3 | U15: DA+00
C17: =U9+1 -> 11 | E17: =C17+1 -> 12 | G17: =E17+1 -> 13 | I17: =G17+1 -> 14 | K17: =I17+1 -> 15 | M17: =K17+1 -> 16 | O17: =M17+1 -> 17 | Q17: =O17+1 -> 18 | S17: =Q17+1 -> 19 | U17: =S17+1 -> 20
D19: 428.12 | F19: 249.58 | H19: 454.54 | J19: 377.83 | L19: 447.64 | N19: 396.44 | P19: 445.93 | R19: 156.98 | T19: 409.67 | V19: 382.38 | W19: =D19+H19+J19+L19+N19+F19+P19+R19+T19+V19 -> 3749.11 | AE19: =SUM(D19:V19) -> 3749.11
A20: =A12+1 -> 2 | X20: =COUNTIF(C20:U20,"F") -> 0 | Y20: =COUNTIF(C19:U19,"E") -> 0 | Z20: =COUNTIF(C21:V21,"Er") -> 0 | AB20: COM
X21: =COUNTIF(C21:U21,"U/P") -> 0 | Y21: 0 | Z21: 0 | AB21: WIP
C22: 3/7 | E22: 3/8 | G22: AP4 | I22: 4/1 | K22: AP5 | M22: 5/1 | O22: 5/2 | Q22: AP6 | S22: AP7 | U22: 7/1 | X22: =COUNTIF(C20:U20,"ROW") -> 0 | Y22: 0 | Z22: 0 | AB22: ROW
C23: DA+03 | E23: DD+03 RC | G23: DD+03 | I23: DA+09 | K23: DC+3 | M23: DA+06 | O23: DA+03 | Q23: DD+09 | S23: DD+09 | U23: DA+00
C25: =U17+1 -> 21 | E25: =C25+1 -> 22 | G25: =E25+1 -> 23 | I25: =G25+1 -> 24 | K25: =I25+1 -> 25 | M25: =K25+1 -> 26 | O25: =M25+1 -> 27 | Q25: =O25+1 -> 28 | S25: =Q25+1 -> 29 | U25: =S25+1 -> 30
D27: 353.89 | F27: 385.21 | H27: 367.67 | J27: 378.32 | L27: 392.49 | N27: 399.24 | P27: 390.93 | R27: 412.07 | T27: 421.95 | V27: 391.87 | W27: =D27+H27+J27+L27+N27+F27+P27+R27+T27+V27 -> 3893.64 | AE27: =SUM(D27:V27) -> 3893.64
A28: =A20+1 -> 3 | X28: =COUNTIF(C28:U28,"F") -> 0 | Y28: =COUNTIF(C27:U27,"E") -> 0 | Z28: =COUNTIF(C29:V29,"Er") -> 0 | AB28: COM
X29: =COUNTIF(C29:U29,"U/P") -> 0 | Y29: 0 | Z29: 0 | AB29: WIP
C30: 7/2 | E30: 7/3 | G30: 7/4 | I30: 7/5 | K30: 7/6 | M30: '7/7 | O30: AP8 | Q30: 08/01 | S30: 08/2 | U30: 08/3 | X30: =COUNTIF(C28:U28,"ROW") -> 0 | Y30: 0 | Z30: 0 | AB30: ROW
C31: DA+00 | E31: DA+00 | G31: DA+00 | I31: DA+00 | K31: DA+00 | M31: DA+00 | O31: DB+00 | Q31: DA+06 | S31: DA+00 | U31: DA+00
C33: =U25+1 -> 31 | E33: =C33+1 -> 32 | G33: =E33+1 -> 33 | I33: =G33+1 -> 34 | K33: =I33+1 -> 35 | M33: =K33+1 -> 36 | O33: =M33+1 -> 37 | Q33: =O33+1 -> 38 | S33: =Q33+1 -> 39 | U33: =S33+1 -> 40
D35: 406.65 | F35: 383.31 | H35: 402.96 | J35: 433.9 | L35: 328.55 | N35: 331.44 | P35: 358.83 | R35: 358.55 | T35: 429.37 | V35: 354.9 | W35: =D35+H35+J35+L35+N35+F35+P35+R35+T35+V35 -> 3788.46 | AE35: =SUM(D35:V35) -> 3788.46
A36: =A28+1 -> 4 | X36: =COUNTIF(C36:U36,"F") -> 0 | Y36: =COUNTIF(C35:U35,"E") -> 0 | Z36: =COUNTIF(C37:V37,"Er") -> 0 | AB36: COM
X37: =COUNTIF(C37:U37,"U/P") -> 0 | Y37: 0 | Z37: 0 | AB37: WIP
C38: 08/4 | E38: 08/5 | G38: 08/6 | I38: 08/7 | K38: AP9 | M38: 09/01 | O38: 09/02 | Q38: 09/03 | S38: 09/04 | U38: 09/05 | X38: =COUNTIF(C36:U36,"ROW") -> 0 | Y38: 0 | Z38: 0 | AB38: ROW
C39: DA+03 | E39: DA+00 | G39: DA+06 | I39: DA+06 | K39: DB+00 | M39: DA+00 | O39: DA+00 | Q39: DA+00 | S39: DA+00 | U39: DA+00
C41: =U33+1 -> 41 | E41: =C41+1 -> 42 | G41: =E41+1 -> 43 | I41: =G41+1 -> 44 | K41: =I41+1 -> 45 | M41: =K41+1 -> 46 | O41: =M41+1 -> 47 | Q41: =O41+1 -> 48 | S41: =Q41+1 -> 49 | U41: =S41+1 -> 50
D43: 340.94 | F43: 405.66 | H43: 409.41 | J43: 378.36 | L43: 322.47 | N43: 386.39 | P43: 386.19 | R43: 406.2 | T43: 351.15 | V43: 380.59 | W43: =D43+H43+J43+L43+N43+F43+P43+R43+T43+V43 -> 3767.36 | AE43: =SUM(D43:V43) -> 3767.36
A44: =A36+1 -> 5 | X44: =COUNTIF(C44:U44,"F") -> 0 | Y44: =COUNTIF(C43:U43,"E") -> 0 | Z44: =COUNTIF(C45:V45,"Er") -> 0 | AB44: COM
X45: =COUNTIF(C45:U45,"U/P") -> 0 | Y45: 0 | Z45: 0 | AB45: WIP
C46: 09/06 | E46: AP10 | G46: 10/01 | I46: 10/02 | K46: 10/03 | M46: 10/04 | O46: 10/05 | Q46: 10/06 | S46: 10/07 | U46: 10/08 | X46: =COUNTIF(C44:U44,"ROW") -> 0 | Y46: 0 | Z46: 0 | AB46: ROW
C47: DA+00 | E47: DC+9 | G47: DA+09 | I47: DA+00 | K47: DA+00 | M47: DA+00 | O47: DA+00 | Q47: DA+00 | S47: DA+00 | U47: DA+00
C49: =U41+1 -> 51 | E49: =C49+1 -> 52 | G49: =E49+1 -> 53 | I49: =G49+1 -> 54 | K49: =I49+1 -> 55 | M49: =K49+1 -> 56 | O49: =M49+1 -> 57 | Q49: =O49+1 -> 58 | S49: =Q49+1 -> 59 | U49: =S49+1 -> 60
D51: 380.02 | F51: 393.7 | H51: 390.68 | J51: 349.16 | L51: 416.01 | N51: 400.75 | P51: 406.84 | R51: 404.76 | T51: 311.74 | V51: 389.98 | W51: =D51+H51+J51+L51+N51+F51+P51+R51+T51+V51 -> 3843.64 | AE51: =SUM(D51:V51) -> 3843.64
A52: =A44+1 -> 6 | X52: =COUNTIF(C52:U52,"F") -> 0 | Y52: =COUNTIF(C51:U51,"E") -> 0 | Z52: =COUNTIF(C53:V53,"Er") -> 0 | AB52: COM
X53: =COUNTIF(C53:U53,"U/P") -> 0 | Y53: 0 | Z53: 0 | AB53: WIP
...

Sheet ROW
A1: NAME OF PROJECT : FARHEGARH IV-BHINMAL 400KV D/C TRANSMISSION LINE
A2: Client : RAJASTHAN IV A POWER TRANSMISSION LTD.
A3: CONTRACTOR : KEC INTERNATIONAL LIMITED
A6: FOUNDATION STATUS
A7: SL. No. | B7: Location Number | C7: Span | D7: Tower Type | E7: AS PER RAPTL ROW CLEARED ON | F7: WORK COMMENCED KEC | G7: STATUS
A9: 1 | B9: 80/0
A10: =A9+1 -> 2 | B10: 66/4 | F10: ROW
A11: =A10+1 -> 3 | B11: 89/1 | F11: ROW
A12: =A11+1 -> 4 | B12: 102/1
A13: =A12+1 -> 5 | B13: 102/2 | F13: Anjana Const | H13: Previous Loc Done 99/2 on 25/4/2025
A14: =A13+1 -> 6 | B14: 107/1
A15: =A14+1 -> 7 | B15: 90/1 | F15: ROW
A16: =A15+1 -> 8 | B16: 81/1
A17: =A16+1 -> 9 | B17: 51/1
A18: =A17+1 -> 10 | B18: 99A/2
A19: =A18+1 -> 11 | B19: 61/1
A20: =A19+1 -> 12 | B20: 72/2
A21: =A20+1 -> 13 | B21: 73/1
A22: =A21+1 -> 14 | B22: 99/5
A23: =A22+1 -> 15 | B23: 56/2
A24: =A23+1 -> 16 | B24: 63/1
A25: =A24+1 -> 17 | B25: 114/1
A26: =A25+1 -> 18 | B26: 116/1
A27: =A26+1 -> 19 | B27: 56/1
... A40: =A39+1 -> 32 | B40: 147/7

Sheet June
B1: Sl No | C1: Loc No | D1: TOT | F1: Classification | G1: Starting Date | H1: Completion
B2: 1 | C2: 81/3 | D2: DA+0 | F2: Sandy | G2: 45799 | H2: 45812
B3: =B2+1 -> 2 | C3: 120/1 | D3: DA+6 | F3: Sandy | G3: 45807 | H3: 45813
B4: =B3+1 -> 3 | C4: 96/0 | D4: DC+0 | F4: DFR | G4: 45805 | H4: 45814
B5: =B4+1 -> 4 | C5: 75/0 | D5: DC+0 | F5: Sandy | G5: 45809 | H5: 45815
B6: =B5+1 -> 5 | C6: 147/2 | D6: DA+0 | F6: Sandy | G6: 45810 | H6: 45816
B7: =B6+1 -> 6 | C7: 82/2 | D7: DA+0 | F7: Sandy | G7: 45810 | H7: 45818
B8: =B7+1 -> 7 | C8: 79/0 | D8: DD+0 | F8: Sandy | G8: 45877 | H8: 45820
B9: =B8+1 -> 8 | C9: 147/5 | D9: DA+0 | F9: Sandy | G9: 45812 | H9: 45820
B10: =B9+1 -> 9 | C10: 119/0 | D10: DD+3 | F10: Sandy | G10: 45813 | H10: 45823
B11: =B10+1 -> 10 | C11: 82/1 | D11: DA+6 | F11: Sandy | G11: 45818 | H11: 45823
B12: =B11+1 -> 11 | C12: 147/0 | D12: DC+0 | F12: Sandy | G12: 45816 | H12: 45823
B13: =B12+1 -> 12 | C13: 78/0 | D13: DC+0 | F13: Sandy | G13: 45821 | H13: 45824
B14: =B13+1 -> 13 | C14: 147/4 | D14: DA+0 | F14: Sandy | G14: 45821 | H14: 45824
... B26: =B25+1 -> 25 | C26: 147/8 | D26: DA+0 | F26: Sandy | G26: 45833 | H26: 45838

Sheet Foundation
A1: NAME OF PROJECT : FARHEGARH IV-BHINMAL 400KV D/C TRANSMISSION LINE
A2: Client : RAJASTHAN IV A POWER TRANSMISSION LTD.
A3: CONTRACTOR : KEC INTERNATIONAL LIMITED
A5: FOUNDATION STATUS
A6: SL. No. | B6: Location Number | C6: Span | E6: Tower Type | F6: M10 | G6: M20 | H6: Excavation | I6: Reinforcement | J6: Stub | K6: RC | L6: Foundation type
D7: LI / LO | M7: Starting date | N7: Completion Date | O7: Agency | P7: Remark | Q7: Remarks
A8: 1 | B8: 7/0 | D8: LI | E8: DE+9 (Aux. X-arm) | L8: DFR | M8: 46059 | N8: 46064 | O8: Karni Mata Construction Company | Q8: RCC Complete, Backfilling Done
A9: =A8+1 -> 2 | B9: 1/1 | D9: LO | E9: DA-3 | L9: DFR | M9: 46064 | N9: 46067 | O9: Karni Mata Construction Company | Q9: RCC Complete, Backfilling Done
A10: =A9+1 -> 3 | B10: 6/2 | D10: LI | E10: DA+0 | L10: DFR | M10: 46065 | N10: 46069 | O10: Karni Mata Construction Company | Q10: RCC Complete, Backfilling Done
A11: =A10+1 -> 4 | B11: 1/2 | D11: LO | E11: DA-3 | L11: DFR | M11: 46068 | N11: 46071 | O11: Karni Mata Construction Company | Q11: RCC Complete, Backfilling Done
A12: =A11+1 -> 5 | B12: 6/1 | D12: LI | E12: DA+0 | L12: DFR | M12: 46070 | N12: 46073 | O12: Karni Mata Construction Company | Q12: RCC Complete, Backfilling Done
A13: =A12+1 -> 6 | B13: 1/0 | D13: LO | E13: DE+3 | L13: DFR | M13: 46064 | N13: 46081 | O13: Karni Mata Construction Company | Q13: RCC Complete, Backfilling Done
A14: =A13+1 -> 7 | B14: 6/0 | D14: Li | E14: DD45+0 | L14: DFR | M14: 46072 | N14: 46081 | O14: Karni Mata Construction Company | Q14: RCC Complete, Backfilling Done | AD14: 185
A15: =A14+1 -> 8 | B15: 2/1 | D15: LO | E15: DA+0 | L15: DFR | M15: 08-03-226 | N15: 46092 | O15: Karni Mata Construction Company | Q15: RCC Complete, Backfilling Done
A16: =A15+1 -> 9 | B16: 2/0 | D16: LO | E16: DC1+0 | L16: DFR | M16: 46081 | N16: 46094 | O16: Karni Mata Construction Company | Q16: RCC Complete, Backfilling Done | AD16: 5
A17: =A16+1 -> 10 | B17: 2/2 | D17: LO | E17: DA-3 | L17: DFR | M17: 46093 | N17: 46096 | O17: Karni Mata Construction Company | Q17: RCC Complete, Backfilling Done
A18: =A17+1 -> 11 | B18: 2/3 | D18: LO | E18: DA+0 | L18: DFR | M18: 46094 | N18: 46097 | O18: Karni Mata Construction Company | Q18: RCC Complete, Backfilling Done
A19: =A18+1 -> 12 | B19: 2/4 | D19: LO | E19: DA+3 | L19: DFR | M19: 46096 | N19: 46098 | O19: Karni Mata Construction Company | Q19: RCC Complete, Backfilling Done
A20: =A19+1 -> 13 | B20: 1/0 | D20: LI | E20: DD60+0 | L20: DFR | M20: 46091 | N20: 46103 | O20: Karni Mata Construction Company | Q20: RCC Complete, Backfilling Done
A21: =A20+1 -> 14 | B21: 2/5 | D21: LO | E21: DA-3 | L21: DFR | M21: 46105 | N21: 46108 | O21: Karni Mata Construction Company | Q21: RCC Complete, Backfilling Done
A22: =A21+1 -> 15 | B22: 5/2 | D22: LI | E22: DA+0 | L22: DFR | M22: 46101 | N22: 46112 | O22: Karni Mata Construction Company | Q22: RCC Complete, Backfilling Done
A23: =A25+1 -> 18 | B23: 5/1 | D23: LI | E23: DA+0 | L23: DFR | M23: 46112 | N23: 46114 | O23: Karni Mata Construction Company | Q23: RCC Complete, Backfilling Done
A24: =A22+1 -> 16 | B24: 7/0 | D24: LO | E24: DD60+0 | L24: DFR | M24: 46101 | O24: Karni Mata Construction Company | Q24: C step Box , B Frustum Next: C,B Chimney Work resume after clear ROW
A25: =A24+1 -> 17 | B25: 3/1 | D25: LO | E25: DA+3 | L25: DFR | M25: 46108 | O25: Karni Mata Construction Company | Q25: Prop set

Sheet Royalty
O3: OM Construction
C4: Loc No | D4: TOT | E4: M-10 | F4: M-20
C5: 120/1 | D5: DA+6 | E5: 1.86 | F5: 12.47 | O5: 75/0 | P5: DC+0 | Q5: 1.6 | R5: 13.13
C6: 119/0 | D6: DD+3 | E6: 2.93 | F6: 20.34 | O6: 79/0 | P6: DD+0 | Q6: 2.93 | R6: 20.34
D7: CUM | E7: =SUM(E5:E6) -> 4.79 | F7: =SUM(F5:F6) -> 32.81 | J7: ROYALTY ISSUED | O7: 78/0 | P7: DC+0 | Q7: 1.6 | R7: 13.13
C8: CUM | D8: 20MM | E8: =E7*1.54*6/10 -> 4.42596 | F8: =F7*1.54*3/5.5 -> 27.5604 | G8: =SUM(E8:F8) -> 31.98636 | J8: 20MM | O8: 74/0 | P8: DB+9 | Q8: 1.68 | R8: 12.41
C9: CUM | D9: SAND | E9: =E8*1.54*3/10 -> 2.0447935 | F9: =F8*1.54*1.5/5.5 -> 11.575368 | G9: =SUM(E9:F9) -> 13.620162 | J9: 18.48 | O9: 73/0 | P9: DB+0 | Q9: 1.68 | R9: 12.41
C10: MT | D10: 20MM | G10: =G8*1600/1000 -> 51.178176 | H10: Required | J10: 14.67 | O10: 72/2 | P10: DA+3 | Q10: 1.86 | R10: 12.47
C11: MT | D11: SAND | G11: =G9*1600/1000 -> 21.792258 | H11: Required | J11: =SUM(J9:J10) -> 33.15 | Q11: =SUM(Q5:Q10) -> 11.35 | R11: =SUM(R5:R10) -> 83.89
O12: CUM | P12: 20MM | Q12: =Q11*1.54*6/10 -> 10.4874 | R12: =R11*1.54*3/5.5 -> 70.4676 | S12: =SUM(Q12:R12) -> 80.955
O13: CUM | P13: SAND | Q13: =Q12*1.54*3/10 -> 4.8451788 | R13: =R12*1.54*1.5/5.5 -> 29.596392 | S13: =SUM(Q13:R13) -> 34.441571
C14: 77/1 | D14: DA+0 | E14: 1.57 | F14: 11.05 | O14: MT | P14: 20MM | S14: =S12*1600/1000 -> 129.528
C15: 77/4 | D15: DA+3 | E15: 1.86 | F15: 12.47 | O15: MT | P15: SAND | S15: =S13*1600/1000 -> 55.106513
C16: 79/1 | D16: DA+9 | E16: 1.86 | F16: 12.47
C17: 76/1 | D17: DA+6 | E17: 1.86 | F17: 12.47
C18: 85/1 | D18: DA+0 | E18: 1.57 | F18: 11.05 | O18: JP Enterprises
C19: 87/1 | D19: DA+3 | E19: 1.86 | F19: 12.47 | P19: 147/2 | Q19: DA+0 | R19: 1.57 | S19: 11.05
C20: 87/2 | D20: DA+9 | E20: 1.86 | F20: 12.47 | P20: 147/0 | Q20: DC+0 | R20: 1.6 | S20: 13.13
C21: 91/1 | D21: DA+0 | E21: 1.57 | F21: 11.05 | P21: 147/1 | Q21: DA+0 | R21: 1.57 | S21: 11.05
C22: 91/2 | D22: DA+0 | E22: 1.57 | F22: 11.05 | P22: 146/2 | Q22: DA+0 | R22: 1.57 | S22: 11.05
C23: 99/2 | D23: DA+0 | E23: 1.08 | F23: 8.68 | P23: 146/1 | Q23: DA+3 | R23: 1.86 | S23: 12.47
C24: 97/0 | D24: DC+0 | E24: 1.6 | F24: 13.13 | R24: =SUM(R19:R23) -> 8.17 | S24: =SUM(S19:S23) -> 58.75
C25: 82/2 | D25: DA+0 | E25: 1.57 | F25: 11.05 | P25: CUM | Q25: 20MM | R25: =R24*1.54*6/10 -> 7.54908 | S25: =S24*1.54*3/5.5 -> 49.35 | T25: =SUM(R25:S25) -> 56.89908
C26: 82/1 | D26: DA+6 | E26: 1.86 | F26: 12.47 | P26: CUM | Q26: SAND | R26: =R25*1.54*3/10 -> 3.487675 | S26: =S25*1.54*1.5/5.5 -> 20.727 | T26: =SUM(R26:S26) -> 24.214675
C27: 86/0 | D27: DD+0 | E27: 2.93 | F27: 20.34 | P27: MT | Q27: 20MM | T27: =T25*1600/1000 -> 91.038528
C28: 85/0 | D28: DC+0 | E28: 1.6 | F28: 13.13 | P28: MT | Q28: SAND | T28: =T26*1600/1000 -> 38.74348
E29: =SUM(E14:E28) -> 26.22 | F29: =SUM(F14:F28) -> 185.35 | U29: Balance
C30: CUM | D30: 20MM | E30: =E29*1.54*6/10 -> 24.22728 | F30: =F29*1.54*3/5.5 -> 155.694 | G30: =SUM(E30:F30) -> 179.92128 | O30: Submitted | P30: MT | Q30: 20MM | T30: =16.74+14.83+18.51+18.5 -> 68.58 | U30: =T27-T30 -> 22.458528
C31: CUM | D31: SAND | E31: =E30*1.54*3/10 -> 11.193003 | F31: =F30*1.54*1.5/5.5 -> 65.39148 | G31: =SUM(E31:F31) -> 76.584483
C32: MT | D32: 20MM | G32: =G30*1600/1000 -> 287.87405
C33: MT | D33: SAND | G33: =G31*1600/1000 -> 122.53517

Sheet Sheet14
A2: 1 | B2: 95/1 | C2: DB+0 | E2: DFR | F2: 45831 | G2: 45842 | H2: Baba Ramdev Construction | I2: RCC Complete, Backfilling Done
A3: =A2+1 -> 2 | B3: 148/3 | C3: DA+0 | E3: Sandy | F3: 45835 | G3: 45843 | H3: AR Patel | I3: RCC Complete, Backfilling Done
A4: =A3+1 -> 3 | B4: 106/0 | C4: DC+6 | E4: Sandy | F4: 45833 | G4: 45844 | H4: Mundhan Trading Company | I4: RCC Complete, Backfilling Done
A5: =A4+1 -> 4 | B5: 148/1 | C5: DA+0 | E5: Sandy | F5: 45842 | G5: 45846 | H5: AR Patel | I5: RCC Complete, Backfilling Done
A6: =A5+1 -> 5 | B6: 146/0 | C6: DC+0 | E6: Sandy | F6: 45841 | G6: 45846 | H6: JP Enterprises | I6: RCC Complete, Backfilling Done
A7: =A6+1 -> 6 | B7: 80/0 | C7: DB+3 | D7: 1MRC | E7: Sandy | F7: 45836 | G7: 45848 | H7: Mahadev Enterprises | I7: RCC Complete, Backfilling Done
A8: =A7+1 -> 7 | B8: 114/1 | C8: DA+9 | E8: Sandy | F8: 45842 | G8: 45848 | H8: Goswami and Company | I8: RCC Complete, Backfilling Done
A9: =A8+1 -> 8 | B9: 148/2 | C9: DA+0 | E9: Sandy | F9: 45845 | G9: 45848 | H9: AR Patel | I9: RCC Complete, Backfilling Done
A10: =A9+1 -> 9 | B10: 95/0 | C10: DB+6 | E10: Sandy | F10: 45835 | G10: 45849 | H10: Baba Ramdev Construction | I10: RCC Complete, Backfilling Done
A11: =A10+1 -> 10 | B11: 141/1 | C11: DA+0 | E11: Sandy | F11: 45845 | G11: 45849 | H11: Mahadev Construction | I11: RCC Complete, Backfilling Done
A12: =A11+1 -> 11 | B12: 148/4 | C12: DA+0 | E12: Sandy | F12: 45848 | G12: 45850 | H12: AR Patel | I12: RCC Complete, Backfilling Done
A13: =A12+1 -> 12 | B13: 141/2 | C13: DA+6 | E13: Sandy | F13: 45847 | G13: 45851 | H13: Mahadev Construction | I13: RCC Complete, Backfilling Done
A14: =A13+1 -> 13 | B14: 145/4 | C14: DA+3 | E14: Sandy | F14: 45847 | G14: 45851 | H14: JP Enterprises | I14: RCC Complete, Backfilling Done
A15: =A14+1 -> 14 | B15: 133/6 | C15: DA+3 | E15: Sandy | F15: 45848 | G15: 45852 | H15: OM Construction | I15: RCC Complete, Backfilling Done
A16: =A15+1 -> 15 | B16: 125/1 | C16: DA+0 | E16: Sandy | F16: 45842 | G16: 45852 | H16: Instance Wave Pvt Ltd | I16: RCC Complete, Backfilling Done
A17: =A16+1 -> 16 | B17: 148/5 | C17: DA+0 | E17: Sandy | F17: 45851 | G17: 45853 | H17: AR Patel | I17: RCC Complete, Backfilling Done
A18: =A17+1 -> 17 | B18: 109A/0 | C18: DB+6 | E18: Sandy | F18: 45847 | G18: 45854 | H18: Mundhan Construction | I18: RCC Complete, Backfilling Done
A19: =A18+1 -> 18 | B19: 113A/0 | C19: DC+0 | E19: Sandy | F19: 45846 | G19: 45854 | H19: Goswami and Company-1 | I19: RCC Complete, Backfilling Done
... A51: =A50+1 -> 50 | B51: 116/0 | C51: DD+0 | E51: Sandy | F51: 45861 | G51: 45869 | H51: Goswami and Company-2 | I51: RCC Complete, Backfilling Done

Sheet Sheet7
D4: SL | E4: Loc | F4: TOT | G4: Gang | H4: Starting Date | I4: Completion
D5: 1 | E5: 148/3 | F5: DA+0 | G5: Gokul Sarkar | H5: 45898 | I5: 45904 | J5: Completed
D6: =D5+1 -> 2 | E6: 81/2 | F6: DA+3 | G6: Dipak | H6: 45901 | I6: 45905 | J6: Completed
D7: =D6+1 -> 3 | E7: 145/1 | F7: DA+3 | G7: Ayansh Const | H7: 45896 | I7: 45909 | J7: Completed
D8: =D7+1 -> 4 | E8: 81/4 | F8: DA+0 | G8: Dipak | H8: 45905 | I8: 45909 | J8: Completed
D9: =D8+1 -> 5 | E9: 148/2 | F9: DA+0 | G9: Gokul Sarkar | H9: 45905 | I9: 45910 | J9: Completed
D10: =D9+1 -> 6 | E10: 83/1 | F10: DA+3 | G10: Ahmed Construction | H10: 45898 | I10: 45911 | J10: Completed
D11: =D10+1 -> 7 | E11: 97/0 | F11: DC+0 | G11: Ajay Kumar1 | H11: 45901 | I11: 45911 | J11: Completed
D12: =D11+1 -> 8 | E12: 148/5 | F12: DA+0 | G12: Gokul Sarkar | H12: 45911 | I12: 45914 | J12: Completed
D13: =D12+1 -> 9 | E13: 145/2 | F13: DA+0 | G13: Ayansh Const | H13: 45909 | I13: 45914 | J13: Completed
D14: =D13+1 -> 10 | E14: 82/1 | F14: DA+6 | G14: Dipak | H14: 45909 | I14: 45914 | J14: Completed
D15: =D14+1 -> 11 | E15: 96/1 | F15: DA+0 | G15: Ajay Kumar1 | H15: 45901 | I15: 45915 | J15: Completed
D16: =D15+1 -> 12 | E16: 79/2 | F16: DA+0 | G16: Ahmed Construction | H16: 45911 | I16: 45915 | J16: Completed
D17: =D16+1 -> 13 | E17: 133/2 | F17: DA+0 | G17: Windbridge Energy | H17: 45897 | I17: 45916 | J17: Completed
... D34: =D33+1 -> 30 | E34: 149B/1 | F34: DA+3 | G34: Gokul Sarkar | H34: 45924 | I34: 45927 | J34: Completed

Sheet Project Details
A1: Project Code | B1: Project Name | C1: Client Name | D1: LOA Start Date | E1: LOA End Date | F1: Planning Engineer | G1: PCH | H1: Regional Manager | I1: Project Manger | J1: Section Incharge | K1: Supervisor/Engineer
A2: TB 507 | B2: 400kV D/C Fatehgarh IV (Section-2)PS - Bhinmal (PG) Transmission Line | C2: RAJASTHAN IV A POWER TRANSMISSION LTD | D2: 45632 | E2: 46178 | F2: Amartya sarkar | G2: Sanjay Kr Gupta | I2: ALOK SINHA | J2: ALOK JANA VARUN TYAGI

Sheet Erection 
A1: NAME OF PROJECT : FARHEGARH IV-BHINMAL 400KV D/C TRANSMISSION LINE
A2: Client : RAJASTHAN IV A POWER TRANSMISSION LTD.
A3: CONTRACTOR : KEC INTERNATIONAL LIMITED
A5: SL. No. | B5: Location No. | C5: Tower Type | D5: Tower Weight | E5: Gang Name | F5: Starting Date | G5: Completion Date | H5: Remarks
A6: 1 | B6: 77/2 | C6: DA+3 | D6: 11.145 | E6: Dipak | F6: 45831 | G6: 45836 | H6: Completed
A7: =A6+1 -> 2 | B7: 77/4 | C7: DA+3 | D7: 11.997 | E7: Dipak | F7: 45836 | G7: 45840 | H7: Completed
A8: =A7+1 -> 3 | B8: 75/7 | C8: DA+0 | D8: 11.145 | E8: Srikarni | F8: 45837 | G8: 45843 | H8: Completed
A9: =A8+1 -> 4 | B9: 77/5 | C9: DA+6 | D9: 13.072 | E9: Dipak | F9: 45841 | G9: 45843 | H9: Completed
A10: =A9+1 -> 5 | B10: 77/3 | C10: DA+0 | D10: 11.145 | E10: Dipak | F10: 45845 | G10: 45848 | H10: Completed
A11: =A10+1 -> 6 | B11: 77/1 | C11: DA+0 | D11: 11.145 | E11: Dipak | F11: 45849 | G11: 45852 | H11: Completed | M11: 185
A12: =A11+1 -> 7 | B12: 75/6 | C12: DA+0 | D12: 11.145 | E12: Dipak | F12: 45853 | G12: 45856 | H12: Completed
A13: =A12+1 -> 8 | B13: 75/5 | C13: DA+0 | D13: 11.145 | E13: Dipak | F13: 45857 | G13: 45860 | H13: Completed | K13: 90 | M13: 24
A14: =A13+1 -> 9 | B14: 75/4 | C14: DA+0 | D14: 11.145 | E14: Dipak | F14: 45860 | G14: 45863 | H14: Completed
A15: =A14+1 -> 10 | B15: 75/3 | C15: DA+3 | D15: 11.997 | E15: Dipak | F15: 45863 | G15: 45866 | H15: Completed
A16: =A15+1 -> 11 | B16: 75/2 | C16: DA+0 | D16: 11.145 | E16: Dipak | F16: 45867 | G16: 45869 | H16: Completed
A17: =A16+1 -> 12 | B17: 74/1 | C17: DA+0 | D17: 11.145 | E17: Ahmed Construction | F17: 45862 | G17: 45869 | H17: Completed
A18: =A17+1 -> 13 | B18: 75/1 | C18: DA+0 | D18: 11.145 | E18: Dipak | F18: 45870 | G18: 45873 | H18: Completed | J18: 41
A19: =A18+1 -> 14 | B19: 73/3 | C19: DA+9 | D19: 13.958 | E19: Ahmed Construction | F19: 45870 | G19: 45877 | H19: Completed
A20: =A19+1 -> 15 | B20: 75/0 | C20: DC+0 | D20: 18.727009 | E20: Dipak | F20: 45873 | G20: 45878 | H20: Completed
A21: =A20+1 -> 16 | B21: 73/2 | C21: DA+9 | D21: 13.958 | E21: Ahmed Construction | F21: 45877 | G21: 45885 | H21: Completed
A22: =A21+1 -> 17 | B22: 78/0 | C22: DC+0 | D22: 18.727009 | E22: Dipak | F22: 45879 | G22: 45885 | H22: Completed
A23: =A22+1 -> 18 | B23: 85/1 | C23: DA+0 | D23: 11.145 | E23: Ahmed Construction | F23: 45886 | G23: 45892 | H23: Completed
A24: =A23+1 -> 19 | B24: 79/0 | C24: DD+0 | D24: 21.41 | E24: Dipak | F24: 45886 | G24: 45892 | H24: Completed
A25: =A24+1 -> 20 | B25: 86/1 | C25: DA+6 | D25: 13.072 | E25: Ahmed Construction | F25: 45892 | G25: 45897 | H25: Completed
A26: =A25+1 -> 21 | B26: 80/1 | C26: DA+9 | D26: 13.958 | E26: Dipak | F26: 45892 | G26: 45897 | H26: Completed
A27: =A26+1 -> 22 | B27: 148/4 | C27: DA+0 | D27: 11.145 | E27: Gokul Sarkar | F27: 45896 | G27: 45898 | H27: Completed
A28: =A27+1 -> 23 | B28: 95A/1 | C28: DA+0 | D28: 11.145 | E28: Ajay Kumar | F28: 45892 | G28: 45900 | H28: Completed
A29: =A28+1 -> 24 | B29: 81/3 | C29: DA+0 | D29: 11.145 | E29: Dipak | F29: 45898 | G29: 45900 | H29: Completed
A30: =A29+1 -> 25 | B30: 148/3 | C30: DA+0 | D30: 11.145 | E30: Gokul Sarkar | F30: 45898 | G30: 45904 | H30: Completed
... A32: =A31+1 -> 27 | B32: 145/1 | C32: DA+3 | D32: 11.997 | E32: Ayansh Const | F32: 45896 | G32: 45909 | H32: Completed
A33: =A32+1 -> 28 | B33: 81/4 | C33: DA+0 | D33: 11.145 | E33: Dipak | F33: 45905 | G33: 45909 | H33: Completed | I33: 148/1 | J33: HOLD
A34: =A33+1 -> 29 | B34: 148/2 | C34: DA+0 | D34: 11.145 | E34: Gokul Sarkar | F34: 45905 | G34: 45910 | H34: Completed
A35: =A34+1 -> 30 | B35: 83/1 | C35: DA+3 | D35: 11.997 | E35: Ahmed Construction | F35: 45898 | G35: 45911 | H35: Completed
A36: =A35+1 -> 31 | B36: 97/0 | C36: DC+0 | D36: 18.727009 | E36: Ajay Kumar1 | F36: 45901 | G36: 45911 | H36: Completed
A37: =A36+1 -> 32 | B37: 148/5 | C37: DA+0 | D37: 11.145 | E37: Gokul Sarkar | F37: 45911 | G37: 45914 | H37: Completed
A38: =A37+1 -> 33 | B38: 145/2 | C38: DA+0 | D38: 11.145 | E38: Ayansh Const | F38: 45909 | G38: 45914 | H38: Completed
A39: =A38+1 -> 34 | B39: 82/1 | C39: DA+6 | D39: 13.072 | E39: Dipak | F39: 45909 | G39: 45914 | H39: Completed | J39: 113/0,DC+0
A40: =A39+1 -> 35 | B40: 96/1 | C40: DA+0 | D40: 11.145 | E40: Ajay Kumar1 | F40: 45901 | G40: 45915 | H40: Completed
A41: =A40+1 -> 36 | B41: 79/2 | C41: DA+0 | D41: 11.145 | E41: Ahmed Construction | F41: 45911 | G41: 45915 | H41: Completed | I41: 133/3
A42: =A41+1 -> 37 | B42: 133/2 | C42: DA+0 | D42: 11.145 | E42: Bhoi Enterprises | F42: 45897 | G42: 45916 | H42: Completed
...

Sheet Completion date
A1: Location no | B1: Tower type | C1: FDN TYPE | D1: FDN CMP date | E1: Erection CMP Date | F1: Earthing CMP Date
A2: GANTRY | B2: GE | C2: =VLOOKUP(A2,Foundation!$B$8:$Q$294,10, 0) -> #N/A | D2: =VLOOKUP(A2,Foundation!$B$8:$Q$277,12, 0) -> #N/A | E2: =VLOOKUP(A2,'Erection Compiled '!$B$2:$R$340,10, 0) -> #N/A | F2: =VLOOKUP(A2,Earthing!$C$7:$H$307,4, 0) -> #N/A
A3: 1/0 | B3: DE+0 | C3: =VLOOKUP(A3,Foundation!$B$8:$Q$294,10, 0) -> 0 | D3: =VLOOKUP(A3,Foundation!$B$8:$Q$277,12, 0) -> 46064 | E3: =VLOOKUP(A3,'Erection Compiled '!$B$2:$R$340,10, 0) -> #N/A | F3: =VLOOKUP(A3,Earthing!$C$7:$H$307,4, 0) -> #N/A
A4: 1A/0 | B4: DD+0 | C4: =VLOOKUP(A4,Foundation!$B$8:$Q$294,10, 0) -> #N/A | D4: =VLOOKUP(A4,Foundation!$B$8:$Q$277,12, 0) -> #N/A | E4: =VLOOKUP(A4,'Erection Compiled '!$B$2:$R$340,10, 0) -> #N/A | F4: =VLOOKUP(A4,Earthing!$C$7:$H$307,4, 0) -> #N/A
A5: 2/0 | B5: DD+0 | C5: =VLOOKUP(A5,Foundation!$B$8:$Q$294,10, 0) -> 0 | D5: =VLOOKUP(A5,Foundation!$B$8:$Q$277,12, 0) -> 46081 | E5: =VLOOKUP(A5,'Erection Compiled '!$B$2:$R$340,10, 0) -> #N/A | F5: =VLOOKUP(A5,Earthing!$C$7:$H$307,4, 0) -> #N/A
A6: 2/1 | B6: Gantry UCS | C6: =VLOOKUP(A6,Foundation!$B$8:$Q$294,10, 0) -> 0 | D6: =VLOOKUP(A6,Foundation!$B$8:$Q$277,12, 0) -> 08-03-226 | E6: =VLOOKUP(A6,'Erection Compiled '!$B$2:$R$340,10, 0) -> #N/A | F6: =VLOOKUP(A6,Earthing!$C$7:$H$307,4, 0) -> #N/A
A7: 3/0 | B7: Gantry UCS | C7: =VLOOKUP(A7,Foundation!$B$8:$Q$294,10, 0) -> #N/A | D7: =VLOOKUP(A7,Foundation!$B$8:$Q$277,12, 0) -> #N/A | E7: =VLOOKUP(A7,'Erection Compiled '!$B$2:$R$340,10, 0) -> #N/A | F7: =VLOOKUP(A7,Earthing!$C$7:$H$307,4, 0) -> #N/A
A8: 3/1 | B8: DD+3 | C8: =VLOOKUP(A8,Foundation!$B$8:$Q$294,10, 0) -> 0 | D8: =VLOOKUP(A8,Foundation!$B$8:$Q$277,12, 0) -> 46108 | E8: =VLOOKUP(A8,'Erection Compiled '!$B$2:$R$340,10, 0) -> #N/A | F8: =VLOOKUP(A8,Earthing!$C$7:$H$307,4, 0) -> #N/A
A9: 4/0 | B9: DD+18 | C9: =VLOOKUP(A9,Foundation!$B$8:$Q$294,10, 0) -> #N/A | D9: =VLOOKUP(A9,Foundation!$B$8:$Q$277,12, 0) -> #N/A | E9: =VLOOKUP(A9,'Erection Compiled '!$B$2:$R$340,10, 0) -> #N/A | F9: =VLOOKUP(A9,Earthing!$C$7:$H$307,4, 0) -> #N/A
A10: 5/0 | B10: DD+9 | C10: =VLOOKUP(A10,Foundation!$B$8:$Q$294,10, 0) -> #N/A | D10: =VLOOKUP(A10,Foundation!$B$8:$Q$277,12, 0) -> #N/A | E10: =VLOOKUP(A10,'Erection Compiled '!$B$2:$R$340,10, 0) -> #N/A | F10: =VLOOKUP(A10,Earthing!$C$7:$H$307,4, 0) -> #N/A
A11: 5/1 | B11: DA+0 | C11: =VLOOKUP(A11,Foundation!$B$8:$Q$294,10, 0) -> 0 | D11: =VLOOKUP(A11,Foundation!$B$8:$Q$277,12, 0) -> 46112 | E11: =VLOOKUP(A11,'Erection Compiled '!$B$2:$R$340,10, 0) -> #N/A | F11: =VLOOKUP(A11,Earthing!$C$7:$H$307,4, 0) -> #N/A
A12: 5/2 | B12: DA+0 | C12: =VLOOKUP(A12,Foundation!$B$8:$Q$294,10, 0) -> 0 | D12: =VLOOKUP(A12,Foundation!$B$8:$Q$277,12, 0) -> 46101 | E12: =VLOOKUP(A12,'Erection Compiled '!$B$2:$R$340,10, 0) -> #N/A | F12: =VLOOKUP(A12,Earthing!$C$7:$H$307,4, 0) -> #N/A
A13: 5/3 | B13: DA+0 | C13: =VLOOKUP(A13,Foundation!$B$8:$Q$294,10, 0) -> #N/A | D13: =VLOOKUP(A13,Foundation!$B$8:$Q$277,12, 0) -> #N/A | E13: =VLOOKUP(A13,'Erection Compiled '!$B$2:$R$340,10, 0) -> #N/A | F13: =VLOOKUP(A13,Earthing!$C$7:$H$307,4, 0) -> #N/A
... A509: 150/0 | B509: DD+9 | C509: =VLOOKUP(A509,Foundation!$B$8:$Q$294,10, 0) -> #N/A | D509: =VLOOKUP(A509,Foundation!$B$8:$Q$277,12, 0) -> #N/A | E509: =VLOOKUP(A509,'Erection Compiled '!$B$2:$R$340,10, 0) -> #N/A | F509: =VLOOKUP(A509,Earthing!$C$7:$H$307,4, 0) -> #N/A

Sheet Erection Compiled 
A1: Sl. No. | B1: Location No. | C1: LI / LO | D1: Tower Type | E1: Classification | F1: Starting Date | G1: Tower Weight | H1: Status | L1: Completion Date | M1: Gang Name | N1: Gang Strength | O1: Remark
A2: 1 | B2: 1/1 | C2: LO | D2: DA-3 | E2: DFR | F2: 46108 | H2: WIP | M2: Priyanka Dbi | N2: 28

Sheet Earthing
A1: NAME OF PROJECT : FARHEGARH IV-BHINMAL 400KV D/C TRANSMISSION LINE
A2: Client : RAJASTHAN IV A POWER TRANSMISSION LTD.
A3: CONTRACTOR : KEC INTERNATIONAL LIMITED
A5: SL. No. | B5: Location Number | C5: LI / LO | D5: Tower Type | E5: Foundation type | F5: Completion Date | G5: Remarks
A7: 1 | B7: 1/1 | C7: LO | D7: DA-3 | E7: DFR | F7: 46073
A8: 2 | B8: 1/2 | C8: LO | D8: DA-3 | E8: DFR | F8: 46073
A9: 3 | B9: 6/2 | C9: LI | D9: DA+0 | E9: DFR | F9: 46073

Sheet Stringing Compiled 
D1: Number of TSE
A3: S.no | B3: Sec | C3: From AP | D3: To AP | E3: Span (M) | F3: Method | G3: Section Readiness | H3: P/O Starting Date | I3: P/O Completion Date | J3: P/O | K3: F/S Starting Date | L3: F/S/ Completion Date | M3: Length | N3: Status | O3: Gang Name | P3: Hindrance | Q3: Remarks
D5: Total

Sheet Soil Investigation
A1: NAME OF PROJECT : FARHEGARH IV-BHINMAL 400KV D/C TRANSMISSION LINE
A2: Client : RAJASTHAN IV A POWER TRANSMISSION LTD.
A3: CONTRACTOR : KEC INTERNATIONAL LIMITED

Sheet Sheet9
A1: 400 KV D/C (TWIN) FATEHGARH IV - BHINMAL (PG) TRANSMISSION LINE (VISUAL CHART)
A2: Name of Contractor:M/S KEC INTERNATIONAL LIMITED | Z2: AS ON | AB2: =NOW()-1 -> 46114.469
A3: PROGRESS AT A GLANCE :
S4: Stringing WIP | W4: Stringing Completed
A5: Sl. No. | C5: Activity | F5: UoM | H5: Total Qty | K5: Completed | N5: Balance | AA5: River Crossing
A7: 1 | C7: Detail survey | F7: Kms. | H7: 188.444 | K7: 188.444 | N7: =H7-K7 -> 0
A8: =A7+1 -> 2 | C8: Check survey | F8: Kms. | H8: 188.444 | K8: 178.075 | N8: =H8-K8 -> 10.369
A9: =A8+1 -> 3 | C9: CS Approval | F9: Kms. | H9: 188.444 | K9: 178.075 | N9: =H9-K9 -> 10.369
A10: =A9+1 -> 4 | C10: Soil Investigation | F10: Loc | H10: 73 | K10: 73 | N10: =H10-K10 -> 0
A11: =A10+1 -> 5 | C11: Foundation | F11: Loc | H11: 512 | K11: 208 | N11: =H11-K11 -> 304 | AA11: Erection WIP
A12: =A11+1 -> 6 | C12: Earthing | F12: Nos. | H12: 514 | K12: 190 | N12: =H12-K12 -> 324 | S12: Erection Comp | V12: Span | AC12: Rly. X-ing
A13: =A12+1 -> 7 | C13: Erection | F13: Loc | H13: 512 | K13: 75 | N13: =H13-K13 -> 437 | S13: Earthing
A14: =A13+1 -> 8 | C14: Tack Welding | F14: Nos. | H14: 512 | N14: =H14-K14 -> 512
A15: =A14+1 -> 9 | C15: Stringing(P/0) | F15: Kms. | H15: 188.444 | N15: 188.444 | S15: Pipe Line | X15: Excavation
A16: =A15+1 -> 10 | C16: Stringing (F/S) | F16: Kms. | H16: 188.444 | N16: 188.444 | Z16: NH | AA16: SH | AB16: 66/132/ 220/ 400
A17: GANTRY | D17: AP1 | F17: AP 1A | H17: AP2 | J17: AP3 | L17: 3/1 | N17: 3/2 | P17: 3/3 | R17: AP4 | T17: 4/1 | V17: 4/2 | X17: 4/3 | Z17: 4/4 | AB17: 4/5 | AC17: SH
AM18: U/P | AN18: ROW | AO18: CLEAR
C20: 89 | E20: 113 | G20: 264 | I20: 244 | K20: 657 | M20: 419.226 | O20: 420.01 | Q20: 416.531 | S20: 356.262 | U20: 343.074 | W20: 381.329 | Y20: 373.323 | AA20: 246.012 | AC20: 249.424 | AM20: =COUNTIF(B20:AB20,"U/P") -> 0 | AN20: =COUNTIF(C20:AC20,"ROW") -> 0 | AO20: =COUNTIF(D20:AD20,"C") -> 0
D22: DD+0 | F22: DD+3 | H22: DD+25 | J22: DD+25 | L22: DB+6 | N22: DA+0 | P22: DA+9 | R22: DC+0 | T22: DA+0 | V22: DA+0 | X22: DA+6 | Z22: DA+3 | AB22: DB+0
A23: REVISED DETAIL SURVEY REPORT SUBMITTED
B24: 4/6 | D24: 4/7 | F24: 4/8 | H24: 4/9 | J24: AP5 | L24: AP6 | N24: 6/1 | P24: 6/2 | R24: 6/3 | T24: 6/4 | V24: 6/5 | X24: 6/6 | Z24: 6/7 | AB24: AP7
C27: 399.707 | E27: 438.616 | G27: 400.604 | I27: 438.765 | K27: 226.315 | M27: 442.553 | O27: 389.329 | Q27: 359.361 | S27: 405.006 | U27: 426.518 | W27: 356.055 | Y27: 369.295 | AA27: 374.993 | AC27: 383.768 | AM27: =COUNTIF(B27:AB27,"U/P") -> 0 | AN27: =COUNTIF(C27:AC27,"ROW") -> 0 | AO27: =COUNTIF(D27:AD27,"C") -> 0
B29: DA+0 | D29: DA+6 | F29: DA+6 | H29: DA+3 | J29: DD+18 | L29: DD+18 | N29: DA+3 | P29: DA+0 | R29: DA+0 | T29: DA+0 | V29: DA+0 | X29: DA+0 | Z29: DA+0 | AB29: DB+0
A30: REVISED DETAIL SURVEY REPORT SUBMITTED
B31: 7/1 | F31: 7/2 | H31: 7/3 | J31: 7/4 | L31: 7/5 | N31: 7/6 | P31: 7/7 | R31: 7/8 | T31: 7/9 | V31: 7/10 | X31: AP8 | Z31: 8/1 | AB31: 8/2
D34: 396.38 | G34: 392.534 | I34: 332.162 | K34: 352.112 | M34: 389.393 | O34: 374.477 | Q34: 419.977 | S34: 387.899 | U34: 407.654 | W34: 402.357 | Y34: 372.259 | AA34: 410.949 | AC34: 379.075 | AM34: =COUNTIF(B34:AB34,"U/P") -> 0 | AN34: =COUNTIF(C34:AC34,"ROW") -> 0 | AO34: =COUNTIF(D34:AD34,"C") -> 0
T35: 1MRC
B36: DA+0 | F36: DA+0 | H36: DA+0 | J36: DA+0 | L36: DA+0 | N36: DA+0 | P36: DA+0 | R36: DA+3 | T36: DA+0 | V36: DA+3 | X36: DB+0 | Z36: DA+0 | AB36: DA+0
A37: WORK FRONT TO BE CLEARED
B38: 8/3 | D38: 8/4 | F38: AP9 | H38: 9/1 | J38: 9/2 | L38: 9/3 | N38: 9/4 | P38: 9/5 | R38: AP 10 | T38: 10/1 | V38: 10/2 | X38: 10/3 | Z38: 10/4 | AB38: 10/5
C41: 412.596 | E41: 340.112 | G41: 410.76 | I41: 427.9 | K41: 404.21 | M41: 398.446 | O41: 431.939 | Q41: 486.196 | S41: 369.717 | U41: 389.344 | W41: 395.602 | Y41: 375 | AA41: 462 | AC41: 382 | AM41: =COUNTIF(B41:AB41,"U/P") -> 0 | AN41: =COUNTIF(C41:AC41,"ROW") -> 0 | AO41: =COUNTIF(D41:AD41,"C") -> 0
B43: DA+0 | D43: DA+3 | F43: DB+0 | H43: DA+3 | J43: DA+6 | L43: DA+0 | N43: DA+3 | P43: DB+9 | R43: DC+3 | T43: DA+3 | V43: DA+0 | X43: DA+3 | Z43: DA+6 | AB43: DA+0
A44: WORK FRONT YET TO BE CLEARED
B45: 10/6 | D45: 10/7 | F45: 10/8 | H45: 10/9 | J45: 10/10 | L45: 10/11 | N45: 10/12 | P45: 10/13 | R45: 10/14 | T45: 10/15 | V45: AP11 | X45: 11/1 | Z45: 11/2 | AB45: 11/3
