Workbook
Name A_D: INDEX(#REF!,MATCH(#REF!,#REF!,0))
Name AA: INDEX(#REF!,MATCH(#REF!,#REF!,0))
Name AB: INDEX(#REF!,MATCH(#REF!,#REF!,0))
Name AC: INDEX(#REF!,MATCH(#REF!,#REF!,0))
Name AE: INDEX(#REF!,MATCH(#REF!,#REF!,0))
Name AF: INDEX(#REF!,MATCH(#REF!,#REF!,0))
Name AG: INDEX(#REF!,MATCH(#REF!,#REF!,0))
Name AH: INDEX(#REF!,MATCH(#REF!,#REF!,0))
Name AI: INDEX(#REF!,MATCH(#REF!,#REF!,0))
Name AJ: INDEX(#REF!,MATCH(#REF!,#REF!,0))
Name AK: INDEX(#REF!,MATCH(#REF!,#REF!,0))
Name AL: INDEX(#REF!,MATCH(#REF!,#REF!,0))
Name AM: INDEX(#REF!,MATCH(#REF!,#REF!,0))
Name BA: INDEX(#REF!,MATCH(#REF!,#REF!,0))
Name BB: INDEX(#REF!,MATCH(#REF!,#REF!,0))
Name BC: INDEX(#REF!,MATCH(#REF!,#REF!,0))
Name BD: INDEX(#REF!,MATCH(#REF!,#REF!,0))
Name BE: INDEX(#REF!,MATCH(#REF!,#REF!,0))
Name BF: INDEX(#REF!,MATCH(#REF!,#REF!,0))
Name BG: INDEX(#REF!,MATCH(#REF!,#REF!,0))
Name BH: INDEX(#REF!,MATCH(#REF!,#REF!,0))
Name BI: INDEX(#REF!,MATCH(#REF!,#REF!,0))
Name BJ: INDEX(#REF!,MATCH(#REF!,#REF!,0))
Name BK: INDEX(#REF!,MATCH(#REF!,#REF!,0))
Name BL: INDEX(#REF!,MATCH(#REF!,#REF!,0))
Name BM: INDEX(#REF!,MATCH(#REF!,#REF!,0))
Name CA: INDEX(#REF!,MATCH(#REF!,#REF!,0))
Name CB: INDEX(#REF!,MATCH(#REF!,#REF!,0))
Name CC: INDEX(#REF!,MATCH(#REF!,#REF!,0))
Name CD: INDEX(#REF!,MATCH(#REF!,#REF!,0))
Name CE: INDEX(#REF!,MATCH(#REF!,#REF!,0))
Name CF: INDEX(#REF!,MATCH(#REF!,#REF!,0))
Name CG: INDEX(#REF!,MATCH(#REF!,#REF!,0))
Name CH: INDEX(#REF!,MATCH(#REF!,#REF!,0))
Name CI: INDEX(#REF!,MATCH(#REF!,#REF!,0))
Name CJ: INDEX(#REF!,MATCH(#REF!,#REF!,0))
Name CK: INDEX(#REF!,MATCH(#REF!,#REF!,0))
Name CL: INDEX(#REF!,MATCH(#REF!,#REF!,0))
Name CM: INDEX(#REF!,MATCH(#REF!,#REF!,0))
Name D_D: INDEX(#REF!,MATCH(#REF!,#REF!,0))
Name DA: INDEX(#REF!,MATCH(#REF!,#REF!,0))
Name DB: INDEX(#REF!,MATCH(#REF!,#REF!,0))
Name DC: INDEX(#REF!,MATCH(#REF!,#REF!,0))
Name DE: INDEX(#REF!,MATCH(#REF!,#REF!,0))
Name DF: INDEX(#REF!,MATCH(#REF!,#REF!,0))
Name DG: INDEX(#REF!,MATCH(#REF!,#REF!,0))
Name DH: INDEX(#REF!,MATCH(#REF!,#REF!,0))
Name DI: INDEX(#REF!,MATCH(#REF!,#REF!,0))
Name DJ: INDEX(#REF!,MATCH(#REF!,#REF!,0))
Name DK: INDEX(#REF!,MATCH(#REF!,#REF!,0))
Name DL: INDEX(#REF!,MATCH(#REF!,#REF!,0))
Name DM: INDEX(#REF!,MATCH(#REF!,#REF!,0))
Name DPR: #REF!&#REF!&#REF!&#REF!&#REF!&#REF!&#REF!&#REF!&#REF!&#REF!
Name EA: INDEX(#REF!,MATCH(#REF!,#REF!,0))
Name EB: INDEX(#REF!,MATCH(#REF!,#REF!,0))
Name EC: INDEX(#REF!,MATCH(#REF!,#REF!,0))
Name ED: INDEX(#REF!,MATCH(#REF!,#REF!,0))
Name EE: INDEX(#REF!,MATCH(#REF!,#REF!,0))
Name EF: INDEX(#REF!,MATCH(#REF!,#REF!,0))
Name EG: INDEX(#REF!,MATCH(#REF!,#REF!,0))

Sheet 400kV Summery
C3: TB-507 | D3: DAILY PROGRESS REPORT | N3: =NOW()-1 -> 46184.443
A4: CONTRACTUAL START DATE: | C4: 45632 | D4: 400kV D/C Fatehgarh IV (Section-2)PS - Bhinmal (PG) Transmission Line
A5: CONTRACTUAL FINISH DATE: | C5: 46178
A6: REPORTING DATE | D6: Client Name : RAJASTHAN IV A POWER TRANSMISSION LTD
A7: TOTAL DAYS | D7: NOA Ref No(Supply): RIVA/LOA-KEC(SUP)/AUG 24/405
A8: COMP. DAYS | D8: NOA Ref No(Service): RIVA/LOA-KEC(SER)/AUG 24/406
A9: Progress Summary | N9: =N3 -> 46184.443
A10: Sl No. | B10: Activity | C10: LOA Quantity | D10: Estimated Line Quantity | E10: Cumm. Progress till Last Month | F10: Plan For JUNE'26 | G10: Progress in JUNE'26 | H10: WIP | I10: Today's Progress | J10: Cumulative progress till date | K10: Balance | L10: ="Gangs working "&CHAR(10)&TEXT(N3,"mmm-yy") -> Gangs working Jun-26 | M10: Manpower | N10: Remarks
A11: A.i | B11: Route Alignment (Kms) | C11: 184 | D11: 188.678 | E11: 188.678 | F11: 0 | G11: 0 | H11: 0 | I11: 0 | J11: =E11 -> 188.678 | K11: =D11-E11 -> 0 | N11: In the Scope of Rajasthan IV A Power Transmission Ltd
A12: ii | B12: Detailed Survey (Kms) | C12: 184 | D12: 188.678 | E12: 188.678 | F12: 0 | G12: =D12-E12 -> 0 | H12: 0 | I12: 0 | J12: 188.678 | K12: =D12-J12 -> 0 | N12: 188.678 Kms Approved
A13: iii | B13: Check Survey (Kms) | C13: 184 | D13: 188.678 | E13: 188.678 | F13: 0 | G13: =D13-E13 -> 0 | H13: 0 | I13: 0 | J13: 188.678 | K13: =D13-J13 -> 0 | N13: 188.678 KmsApproved
A14: B. | B14: Soil Investigation (Nos) | C14: 73 | D14: 73 | E14: 73 | F14: 0 | G14: 0 | H14: 0 | I14: 0 | J14: 73 | K14: 0
A15: C. | B15: Foundation (Nos) | C15: 508 | D15: 513 | E15: 308 | F15: 34 | G15: 6 | H15: 3 | J15: =SUM(E15+G15) -> 314 | K15: =D15-J15 -> 199 | L15: 5 | M15: 45 | N15: Completed -Nil ,WIP- 5/0,5/6,10/4,10/9, 56/3 ,49/0, Loc Hold due to ROW -13/1,13/3,42/2,62/3
A16: D. | B16: Earthing (Nos) | C16: 508 | D16: 513 | E16: 266 | J16: =SUM(E16+G16) -> 266 | K16: =D16-J16 -> 247
A17: E. | B17: Tower Erection (Nos) | C17: 508 | D17: 513 | E17: 218 | F17: 39 | G17: 5 | H17: 4 | J17: =SUM(E17+G17) -> 223 | K17: =D17-J17 -> 290 | L17: 4 | M17: 79 | N17: Completed : NIL, WIP -100/1, 120/0,10/13,9/0 ROW-10/0,
A18: F. | B18: Tack Welding (Nos) | C18: 508 | D18: 513 | E18: 104 | F18: 153 | G18: 8 | H18: 0 | J18: =SUM(E18+G18) -> 112 | K18: =D18-J18 -> 401 | L18: 1 | M18: 3 | N18: Today Com -NIL WIP - Nil
A19: G. | B19: Stringing (Kms)
A20: i | B20: Paying Out (Kms) | C20: 184 | D20: 188.678 | E20: 21.797 | F20: 21.084 | H20: 0.425 | J20: =E20+G20 -> 21.797 | K20: =D20-J20 -> 166.881 | L20: 2 | M20: 40 | N20: Today Com -NIL WIP - SK Tajirul 75/0-76/0 Insulator Hoisting,Mahadev Enterprizes- 147/0-148/0 Clipping ROW- 115/0-115/1 since 3.6.2026
A21: ii | B21: Final Sag (Kms) | C21: 184 | D21: 188.678 | E21: 21.36 | F21: 21.084 | J21: =E21+G21 -> 21.36 | K21: =D21-J21 -> 167.318 | N21: Today Complete: NIL, ,WIP- NIL
A22: I. | B22: OPGW Stringing (Kms) | C22: 184 | D22: 188.678 | E22: 0
A23: i | B23: Paying Out (Kms) | C23: 184 | D23: 188.678 | J23: 0 | K23: =D23-J23 -> 188.678
A24: ii | B24: Final Sag (Kms) | C24: 184 | D24: 188.678 | J24: 0 | K24: =D24-J24 -> 188.678

Sheet Check Survey 
A1: NAME OF PROJECT : FARHEGARH IV-BHINMAL 400KV D/C TRANSMISSION LINE
A2: Client : RAJASTHAN IV A POWER TRANSMISSION LTD.
A3: CONTRACTOR : KEC INTERNATIONAL LIMITED
A4: 400 KV CHECK SURVEY
A5: SL No | B5: Section | C5: Section Length | D5: Submission Date | E5: Approval Date | F5: Remarks
A6: 1 | B6: AP 51- AP 54 | C6: 2.653 | D6: 45684 | E6: 45691 | F6: Approved
A7: =A6+1 -> 2 | B7: AP 54- AP 60 | C7: 5.31 | F7: Approved
A8: =A7+1 -> 3 | B8: AP 60- AP 75 | C8: 19.672 | D8: 15.02.2025 , 24-02-2025 25-02-2025 | E8: 45713 | F8: Approved | G8: Required Change
A9: =A8+1 -> 4 | B9: AP 75- AP 92 | C9: 20.273 | D9: 45657 | E9: 45691 | F9: Approved
A10: =A9+1 -> 5 | B10: AP 92- AP 96 | C10: 3.084 | D10: 15-02-25 & 21-02-2025 | E10: 45712 | F10: Approved
A11: =A10+1 -> 6 | B11: AP 96- AP 97 | C11: 1.063 | D11: 45713 | E11: 45715 | F11: Approved
A12: =A11+1 -> 7 | B12: AP 97- AP 98B | C12: 2.09 | D12: 45713 | F12: Approved
A13: =A12+1 -> 8 | B13: AP 98B- 99A/0 | C13: 3.893 | D13: 45713 | F13: Approved
A14: =A13+1 -> 9 | B14: AP99A/0-AP 107 | C14: 6.971 | D14: 45713 | F14: Approved
A15: =A14+1 -> 10 | B15: AP 107- AP 121 | C15: 9.495 | D15: 45721 | E15: 45722 | F15: Approved
A16: =A15+1 -> 11 | B16: AP 121- AP 131 | C16: 8.697 | D16: 12-03-2025 & ReSubmission 4-04-2025 | F16: Submitted | G16: Resubmitted
A17: =A16+1 -> 12 | B17: AP 131- AP 133 | C17: 3.084 | F17: Submitted
A18: =A17+1 -> 13 | B18: AP 133- AP 134 | C18: 3.963 | F18: Submitted
A19: =A18+1 -> 14 | B19: AP 134- AP 135 | C19: 1.656 | F19: Submitted
A20: =A19+1 -> 15 | B20: AP 135- AP 136 | C20: 1.635 | F20: Submitted
A21: =A20+1 -> 16 | B21: AP 136 - AP 139 | C21: 2.221 | F21: Submitted
A22: =A21+1 -> 17 | B22: AP 139 - AP 147 | C22: 10.724 | D22: 26-03-2025 Resubmission 4-04-2025 &28-04-25 | F22: Submitted | G22: Resubmitted
A23: =A22+1 -> 18 | B23: AP 147/0 - AP 148 | C23: 3.666 | D23: 26-03-2025 Resubmission 4-04-2025 & 28-04-25 | F23: Submitted | G23: Resubmitted
A24: =A23+1 -> 19 | B24: AP148/0 - AP 149B | C24: 4.88 | F24: Submitted
A25: =A24+1 -> 20 | B25: AP 150 to Bhinmal GTY | C25: 2.474 | D25: 45765 | F25: Submitted
A26: =A25+1 -> 21 | B26: AP 50- AP 51 | C26: 0.275 | D26: 45752 | F26: Submitted
A27: =A26+1 -> 22 | B27: AP 47- AP 50 | C27: 2.008 | D27: 45752 | F27: Submitted
A28: =A27+1 -> 23 | B28: AP 46- AP 47 | C28: 0.223 | D28: 45752 | F28: Submitted
A29: =A28+1 -> 24 | B29: AP 42- AP 43 | C29: 2.731 | D29: 45752 | F29: Submitted
A30: =A29+1 -> 25 | B30: AP 45- AP 46 | C30: 1.717 | D30: 45752 | F30: Submitted
A31: =A30+1 -> 26 | B31: AP 43- AP 45 | C31: 1.068 | D31: 45752 | F31: Submitted
A32: =A31+1 -> 27 | B32: AP 40- AP 42 | C32: 2.873 | D32: 45752 | F32: Submitted
A34: =A32+1 -> 28 | B34: AP 10- AP 21 | C34: 19.57 | D34: 16-04-2025 & 16.05.2025 | F34: Re Submitted
A35: =A34+1 -> 29 | B35: 21/0-24/0 | C35: 2.618 | D35: 45781 | F35: Complete
A36: =A35+1 -> 30 | B36: 24/0-40/0 | C36: 18.193 | D36: 45805 | F36: Complete
B39: AS on date | C39: =SUM(C6:C36) -> 168.78
B43: Submission of Check Survey
A44: SL. No. | B44: Section | C44: Date of submission | D44: Section Length in kms | E44: Letter Reference Number | F44: Date of Approval | G44: Section Length in kms
A45: 1 | B45: AP75 To AP92 | C45: 45657 | D45: 20.273 | E45: KEC/FBTL/RPTL/TB507/008A | F45: 45691 | G45: 20.273 | H45: JMC -01
A46: =A45+1 -> 2 | B46: AP51 To AP60 | C46: 45684 | D46: 7.962 | E46: KEC/FBTL/RPTL/TB507/0014 | F46: 45691 | G46: 7.962 | H46: JMC -01
...

Sheet Check Survey Status
A1: NAME OF PROJECT : FARHEGARH IV-BHINMAL 400KV D/C TRANSMISSION LINE
A2: Client : RAJASTHAN IV A POWER TRANSMISSION LTD.
A3: CONTRACTOR : KEC INTERNATIONAL LIMITED
A4: 400 KV CHECK SURVEY
A5: SL No | B5: Section | C5: Section Length | D5: Submission Date | E5: Approval Date | F5: Remarks
A6: 1 | B6: AP 51- AP 54 | C6: 2.653 | D6: 45684 | E6: 45691 | F6: Approved
A7: =A6+1 -> 2 | B7: AP 54- AP 60 | C7: 5.31 | F7: Approved
A8: =A7+1 -> 3 | B8: AP 60- AP 75 | C8: 19.672 | D8: 15.02.2025 , 24-02-2025 25-02-2025 | E8: 45713 | F8: Approved | G8: Required Change
A9: =A8+1 -> 4 | B9: AP 75- AP 92 | C9: 20.273 | D9: 45657 | E9: 45691 | F9: Approved
A10: =A9+1 -> 5 | B10: AP 92- AP 96 | C10: 3.084 | D10: 15-02-25 & 21-02-2025 | E10: 45712 | F10: Approved
A11: =A10+1 -> 6 | B11: AP 96- AP 97 | C11: 1.063 | D11: 45713 | E11: 45715 | F11: Approved
A12: =A11+1 -> 7 | B12: AP 97- AP 98B | C12: 2.09 | D12: 45713 | F12: Approved
A13: =A12+1 -> 8 | B13: AP 98B- 99A/0 | C13: 3.893 | D13: 45713 | F13: Approved
A14: =A13+1 -> 9 | B14: AP99A/0-AP 107 | C14: 6.971 | D14: 45713 | F14: Approved
A15: =A14+1 -> 10 | B15: AP 107- AP 121 | C15: 9.495 | D15: 45721 | E15: 45722 | F15: Approved
A16: =A15+1 -> 11 | B16: AP 121- AP 131 | C16: 8.697 | D16: 12-03-2025 & ReSubmission 4-04-2025 | F16: Submitted | G16: Resubmitted
A17: =A16+1 -> 12 | B17: AP 131- AP 133 | C17: 3.084 | F17: Submitted
A18: =A17+1 -> 13 | B18: AP 133- AP 134 | C18: 3.963 | F18: Submitted
A19: =A18+1 -> 14 | B19: AP 134- AP 135 | C19: 1.656 | F19: Submitted
A20: =A19+1 -> 15 | B20: AP 135- AP 136 | C20: 1.635 | F20: Submitted
A21: =A20+1 -> 16 | B21: AP 136 - AP 139 | C21: 2.221 | F21: Submitted
A22: =A21+1 -> 17 | B22: AP 139 - AP 147 | C22: 10.724 | D22: 26-03-2025 Resubmission 4-04-2025 &28-04-25 | F22: Submitted | G22: Resubmitted
A23: =A22+1 -> 18 | B23: AP 147/0 - AP 148 | C23: 3.666 | D23: 26-03-2025 Resubmission 4-04-2025 & 28-04-25 | F23: Submitted | G23: Resubmitted
A24: =A23+1 -> 19 | B24: AP148/0 - AP 149B | C24: 4.88 | F24: Submitted
A25: =A24+1 -> 20 | B25: AP 150 to Bhinmal GTY | C25: 2.474 | D25: 45765 | F25: Submitted
A26: =A25+1 -> 21 | B26: AP 50- AP 51 | C26: 0.275 | D26: 45752 | F26: Submitted
A27: =A26+1 -> 22 | B27: AP 47- AP 50 | C27: 2.008 | D27: 45752 | F27: Submitted
A28: =A27+1 -> 23 | B28: AP 46- AP 47 | C28: 0.223 | D28: 45752 | F28: Submitted
A29: =A28+1 -> 24 | B29: AP 42- AP 43 | C29: 2.731 | D29: 45752 | F29: Submitted
A30: =A29+1 -> 25 | B30: AP 45- AP 46 | C30: 1.717 | D30: 45752 | F30: Submitted
A31: =A30+1 -> 26 | B31: AP 43- AP 45 | C31: 1.068 | D31: 45752 | F31: Submitted
A32: =A31+1 -> 27 | B32: AP 40- AP 42 | C32: 2.873 | D32: 45752 | F32: Submitted
A34: =A32+1 -> 28 | B34: AP 10- AP 21 | C34: 19.57 | D34: 16-04-2025 & 16.05.2025 | F34: Re Submitted
A35: =A34+1 -> 29 | B35: 21/0-24/0 | C35: 2.618 | D35: 45781 | F35: Complete
A36: =A35+1 -> 30 | B36: 24/0-40/0 | C36: 18.193 | D36: 45805 | F36: Complete
B39: AS on date | C39: =SUM(C6:C36) -> 168.78
B43: Submission of Check Survey
A44: SL. No. | B44: Section | C44: Date of submission | D44: Section Length in kms | E44: Letter Reference Number | F44: Date of Approval | G44: Section Length in kms
A45: 1 | B45: AP75 To AP92 | C45: 45657 | D45: 20.273 | E45: KEC/FBTL/RPTL/TB507/008A | F45: 45691 | G45: 20.273
A46: =A45+1 -> 2 | B46: AP51 To AP60 | C46: 45684 | D46: 7.962 | E46: KEC/FBTL/RPTL/TB507/0014 | F46: 45691 | G46: 7.962
...

Sheet Check Survey
A1: NAME OF PROJECT : FARHEGARH IV-BHINMAL 400KV D/C TRANSMISSION LINE
A2: Client : RAJASTHAN IV A POWER TRANSMISSION LTD.
A3: CONTRACTOR : KEC INTERNATIONAL LIMITED
A4: 400 KV CHECK SURVEY
A5: SL No | B5: Section | C5: Section Length | D5: Submission Date | E5: Approval Date | F5: Remarks
A6: 1 | B6: AP 51- AP 54 | C6: 2.653 | D6: 45684 | E6: 45691 | F6: Approved
A7: =A6+1 -> 2 | B7: AP 54- AP 60 | C7: 5.31 | F7: Approved
A8: =A7+1 -> 3 | B8: AP 60- AP 75 | C8: 19.672 | D8: 15.02.2025 , 24-02-2025 25-02-2025 | E8: 45713 | F8: Approved | G8: Required Change | H8: Approved | I8: =G63 -> 97.59
A9: =A8+1 -> 4 | B9: AP 75- AP 92 | C9: 20.273 | D9: 45657 | E9: 45691 | F9: Approved
A10: =A9+1 -> 5 | B10: AP 92- AP 96 | C10: 3.084 | D10: 15-02-25 & 21-02-2025 | E10: 45712 | F10: Approved | H10: Submitted | I10: =D63 -> 151.916
A11: =A10+1 -> 6 | B11: AP 96- AP 97 | C11: 1.063 | D11: 45713 | E11: 45715 | F11: Approved
A12: =A11+1 -> 7 | B12: AP 97- AP 98B | C12: 2.09 | D12: 45713 | F12: Approved
A13: =A12+1 -> 8 | B13: AP 98B- 99A/0 | C13: 3.893 | D13: 45713 | F13: Approved
A14: =A13+1 -> 9 | B14: AP99A/0-AP 107 | C14: 6.971 | D14: 45713 | F14: Approved
A15: =A14+1 -> 10 | B15: AP 107- AP 121 | C15: 9.495 | D15: 45721 | E15: 45722 | F15: Approved
A16: =A15+1 -> 11 | B16: AP 121- AP 131 | C16: 8.697 | D16: 12-03-2025 & ReSubmission 4-04-2025 | F16: Submitted | G16: Resubmitted
A17: =A16+1 -> 12 | B17: AP 131- AP 133 | C17: 3.084 | F17: Submitted
A18: =A17+1 -> 13 | B18: AP 133- AP 134 | C18: 3.963 | F18: Submitted
A19: =A18+1 -> 14 | B19: AP 134- AP 135 | C19: 1.656 | F19: Submitted
A20: =A19+1 -> 15 | B20: AP 135- AP 136 | C20: 1.635 | F20: Submitted
A21: =A20+1 -> 16 | B21: AP 136 - AP 139 | C21: 2.221 | F21: Submitted
A22: =A21+1 -> 17 | B22: AP 139 - AP 147 | C22: 10.724 | D22: 26-03-2025 Resubmission 4-04-2025 &28-04-25 | F22: Submitted | G22: Resubmitted
A23: =A22+1 -> 18 | B23: AP 147/0 - AP 148 | C23: 3.666 | D23: 26-03-2025 Resubmission 4-04-2025 & 28-04-25 | F23: Submitted | G23: Resubmitted | M23: Blance | N23: =187.176-M11 -> 187.176
A24: =A23+1 -> 19 | B24: AP148/0 - AP 149B | C24: 4.88 | F24: Submitted
A25: =A24+1 -> 20 | B25: AP 150 to Bhinmal GTY | C25: 2.474 | D25: 45765 | F25: Submitted
A26: =A25+1 -> 21 | B26: AP 50- AP 51 | C26: 0.275 | D26: 45752 | F26: Submitted
A27: =A26+1 -> 22 | B27: AP 47- AP 50 | C27: 2.008 | D27: 45752 | F27: Submitted
A28: =A27+1 -> 23 | B28: AP 46- AP 47 | C28: 0.223 | D28: 45752 | F28: Submitted
A29: =A28+1 -> 24 | B29: AP 42- AP 43 | C29: 2.731 | D29: 45752 | F29: Submitted
A30: =A29+1 -> 25 | B30: AP 45- AP 46 | C30: 1.717 | D30: 45752 | F30: Submitted
A31: =A30+1 -> 26 | B31: AP 43- AP 45 | C31: 1.068 | D31: 45752 | F31: Submitted
A32: =A31+1 -> 27 | B32: AP 40- AP 42 | C32: 2.873 | D32: 45752 | F32: Submitted
A34: =A32+1 -> 28 | B34: AP 10- AP 21 | C34: 19.57 | D34: 16-04-2025 & 16.05.2025 | F34: Re Submitted
A35: =A34+1 -> 29 | B35: 21/0-24/0 | C35: 2.618 | D35: 45781 | F35: Complete
A36: =A35+1 -> 30 | B36: 24/0-40/0 | C36: 18.193 | D36: 45805 | F36: Complete | I36: =155.849-130.528 -> 25.321
B39: AS on date | C39: =SUM(C6:C36) -> 168.78
B43: Submission of Check Survey
A44: SL. No. | B44: Section | C44: Date of submission | D44: Section Length in kms | E44: Letter Reference Number | F44: Date of Approval | G44: Section Length in kms | H44: Approved By | I44: Remarks
A45: 1 | B45: AP75 To AP92 | C45: 45657 | D45: 20.273 | E45: KEC/FBTL/RPTL/TB507/008A | F45: 45691 | G45: 20.273 | H45: Gundewadi Mallappa
A46: =A45+1 -> 2 | B46: AP51 To AP60 | C46: 45684 | D46: 7.962 | E46: KEC/FBTL/RPTL/TB507/0014 | F46: 45691 | G46: 7.962 | H46: Gundewadi Mallappa
...

Sheet Sheet8
A1: S No. | B1: MOM as on 11/6/25 | C1: Timeline | D1: Responsibility | E1: Status as on 19/6/25
A2: 1 | B2: 400kv Detail Survey from AP 01 to AP 10
A3: a | B3: Apraava will give clearance for further proceeding of Detail Survey | C3: 45821 | D3: M/S Apraava | E3: Clearance provided for Detail Survey
A4: b | B4: Completion of Detail Survey | C4: 45833 | D4: M/S KEC | E4: Detail Survey work under progress
A5: c | B5: Detail Survey of 765 kV is submitted by KEC, observation raised by Apraava, KEC has to re-submitted according to observation | C5: 45824 | D5: M/S KEC | E5: Reobservation mail by Engg. Team on dt. 19.06.25
A6: 2 | B6: Check Survey
A7: a | B7: 50 km will be approved | C7: 45820 | D7: M/S Apraava & KEC | E7: 33 km Approved & 15 km submitted by KEC
A8: b | B8: Pending Section of 21 km will be approved | C8: 45828 | D8: M/S Apraava & KEC | E8: Under Progress
A9: c | B9: Check Survey of 765kV is to be submitted by KEC | C9: 46198 | D9: M/S KEC | E9: Detail Survey work under progress
A10: 3 | B10: Statutory Approvals
A11: a | B11: 02 No NH Proposal Submission | C11: 45838 | D11: M/S KEC | E11: Under Progress
A12: b | B12: 02 No Railway Proposal Submission | C12: 45838 | D12: M/S KEC | E12: Under Progress
A13: c | B13: 02 Nos PLC Proposal of 400 kV Underneath has to Submit | C13: ASAP | D13: M/S KEC | E13: Under Progress
A14: d | B14: Statutory Approvals tracker to be maintain for monitoring current status of NOC | C14: N/A | D14: M/S Apraava & KEC | E14: Under Progress
A15: e | B15: 04 Submission of SH Proposal to SH Authority | C15: 45828 | D15: M/S Apraava | E15: Under Progress
A16: f | B16: 03 Submission of Oil Proposal to Oil Authority | C16: 45828 | D16: M/s Apraava | E16: Under Progress
A17: 4 | B17: Deployment of surveyor, supervisors, engineers & section in charge to be expedite in Bhinmal Section | C17: 45820 | D17: M/S KEC | E17: Under Progress
A18: 5 | B18: KEC committed 43 nos. foundation for this month & accordingly Apraava will provide ROW clearance | C18: 45838 | D18: M/S Apraava & KEC | E18: Till date 13 foundations completed, 10 are in WIP and 30 work fronts are available
A19: 6 | B19: Manpower in each foundation gang need to be strengthen with at least 8-10 manpower/gang | C19: ASAP | D19: M/S KEC | E19: Under Progress
A20: 7 | B20: Apraava asked to increase 4 more foundation gangs to expedite foundation work (currently 7 gangs are available with insufficient manpower | C20: ASAP | D20: M/S KEC | E20: 9 Gangs are available (insufficient manpower in 4 gangs)
A21: 8 | B21: 40 Nos Departmental Manpower availability at site | C21: 45838 | D21: M/S KEC | E21: -
A22: 9 | B22: Quality Constraints
A23: a | B23: Information regarding supply of cement with prior & proper documentation | C23: N/A | D23: M/S KEC | E23: -
A24: b | B24: Material availability at site from approved source | C24: - | D24: M/S KEC | E24: -
A25: c | B25: Approval of use of Curing compound in foundation work need to be expedite after jointly discussion of both team | C25: ASAP | D25: M/S Apraava & KEC | E25: Cubes taken after applying curing compound & further process is u/p
A26: d | B26: CTM Machine at store need be installed on priority for cube testing | C26: 45821 | D26: M/S KEC | E26: Under Progress
A27: 10 | B27: Erection team to be deployed and erection to be start | C27: 45826 | D27: M/S KEC | E27: Erection to be start by Monday, 23/6/25
A28: 11 | B28: July month foundation & erection plan to be shared by KEC | C28: 45824 | D28: M/S KEC | E28: July month plan to be shared within 2-3 days by KEC
A29: 12 | B29: Supply of conductor to be start in September month | C29: 45930 | D29: M/S Apraava | E29: Planned for September month
A30: 13 | B30: Total 121 nos. of DA type of tower supplied to store & 2nd lot of 74 nos. towers (approx. 1500 MT) supply, consisting of DC & DD type towers are scheduled for next month | C30: 45848 | D30: M/S KEC | E30: DA type towers are supplied

Sheet Sheet2
C2: 400kV D/C Fatehgarh IV (Section-2)PS - Bhinmal (PG) Transmission Line
C4: Sl No | D4: Section AP To AP | E4: Section length | F4: Remarks
C5: 1 | D5: AP-21/0 To AP-24/0 | E5: 2.618
C6: =C5+1 -> 2 | D6: AP-24/0 To AP-27/0 | E6: 1.428
C7: =C6+1 -> 3 | D7: AP-27/0 To AP-40/0 | E7: 16.76
C8: =C7+1 -> 4 | D8: AP-45/0 To AP-48/0 | E8: 3.187
C9: =C8+1 -> 5 | D9: AP-153/0 To AP-154/0 | E9: 0.732
C10: =C9+1 -> 6 | D10: AP-154/0 To AP-155/0 | E10: 0.218
C11: =C10+1 -> 7 | D11: AP-155/0 To S/S Gantry | E11: 0.571
D12: TOTAL | E12: =SUM(E5:E11) -> 25.514
C14: 765kV D/C Fatehgarh IV (Section-2)PS - Bhinmal (PG) Transmission Line
C16: Sl No | D16: Section AP To AP | E16: Section length | F16: Route Allignment,Detail Survey,Check survey
D17: LI | E17: =7584/1000 -> 7.584
D18: LO | E18: =6951/1000 -> 6.951
D19: TOTAL | E19: =SUM(E17:E18) -> 14.535

Sheet Project Details
A1: Project Code | B1: Project Name | C1: Client Name | D1: LOA Start Date | E1: LOA End Date | F1: Planning Engineer | G1: PCH | H1: Regional Manager | I1: Project Manger | J1: Section Incharge | K1: Supervisor/Engineer
A2: TB 507 | B2: 400kV D/C Fatehgarh IV (Section-2)PS - Bhinmal (PG) Transmission Line | C2: RAJASTHAN IV A POWER TRANSMISSION LTD | D2: 23.08.2024 | E2: 22.02.2026 | F2: Mr. Amartya sarkar | G2: Mr. N K Gupta | I2: Mr.ALOK SINHA | J2: Mr.ALOK JANA Mr. VARUN TYAGI

Sheet Statutory Clearence
A1: Rajasthan IV A 400 KV LINE - STATUTORY APPROVAL STATUS
B2: KEC RESPONSIBILITY | F2: APRAAVA RESPONSIBILITY
A3: S N | B3: Loc No. | C3: Line Crossing | D3: Asset Owner | E3: Submission by KEC | F3: Submission to Asset Owner | G3: Date of Joint site visit | H3: Demand letter from Asset Owner | I3: Letter submission/ Demand fulfillment | J3: Date of NOC/ Approval | K3: Target date for NOC | L3: Status as on 31-03-2026 | M3: Remarks
A4: Power Line Crossing for Line (12 Nos)
A5: 1 | B5: AP 2 - 3/1 | C5: 400KV D/C | D5: APRAAVA | E5: 01.02.2026 | F5: 01.02.2026 | J5: Approved | L5: PL crossing Apraava's Line. Technical team approved during check survey
A6: 2 | B6: AP4-AP5 | C6: 220KV D/C | D6: AMPIN | E6: 01.04.2026 | K6: 30.04.2026
A7: 3 | B7: AP 5D - AP 5E | C7: 132KV S/C | D7: RRVPNL | E7: 21.02.2026 | F7: 06.03.2026 | K7: 15.04.2026 | L7: Joint Site visit planned by 7th April
A8: 4 | B8: AP 6D/5 - AP 7/0 | C8: 132KV D/C | D8: RRVPNL | E8: 21.02.2026 | F8: 06.03.2026 | K8: 15.04.2026 | L8: Joint Site visit planned by 7th April
A9: 5 | B9: AP25 - AP 26 | C9: 400KV D/C | D9: RRVPNL | E9: 25.09.2025 | F9: DONE | G9: DONE | J9: 07.11.2025
A10: 6 | B10: AP 27- AP 27A | C10: 220KV S/C | D10: RRVPNL | E10: 24.05.2025 | F10: 30.05.2025 | G10: 31.08.2025 | J10: 07.11.2025 | M10: Demand letter awiated
A11: 7 | B11: AP 50-AP 51 | C11: 220KV S/C | D11: RRVPNL | E11: 24.05.2025 | F11: 30.05.2025 | G11: 26.08.2025 | J11: 07.11.2025 | M11: Demand letter awiated | N11: Barmer
A12: 8 | B12: AP 58-AP 59 | C12: 132KV S/C | D12: RRVPNL | E12: 24.05.2025 | F12: 30.05.2025 | G12: 31.08.2025 | J12: 07.11.2025 | M12: Demand letter awiated
A13: 9 | B13: AP 111-AP 112 | C13: 132KV S/C | D13: RRVPNL | E13: 24.05.2025 | F13: 05.06.2025 | G13: 30.06.2025 | J13: 28.08.2025
A14: 10 | B14: AP 144-AP 145 | C14: 132KV S/C | D14: RRVPNL | E14: 24.05.2025 | F14: 05.06.2025 | G14: 30.06.2025 | J14: 28.08.2025 | N14: Sirohi
A15: 11 | B15: AP 152-AP 153 | C15: 220KV D/C | D15: RRVPNL | E15: 24.05.2025 | F15: 05.06.2025 | G15: 30.06.2025 | J15: 28.08.2025
A16: 12 | B16: AP 154-AP 155 | C16: 400KV D/C | D16: RRVPNL | E16: 25.09.2025 | F16: 21.11.2025 | G16: 28.01.2026 | J16: 17.02.2026
A17: NH/Expressway Crossing (02 Nos)
A18: 1 | B18: AP 43 - AP 44 | C18: Barmer-Jodhpur National Highway-25 | D18: NHAI | E18: 14.07.2025 | F18: 14.07.2025 | G18: 06.10.2025 | K18: 15.04.2026 | L18: Demand letter expected by 7th April
A19: 2 | B19: AP 121 - AP 122 | C19: Jamnagar-Amritsar Bharat Mala Expressway NH -754 | D19: NHAI | E19: 14.07.2025 | F19: 14.07.2025 | G19: 08.09.2025 | H19: 28.10.2025 | I19: 21.11.2025 | J19: 06.12.2025
A20: Railway Crossing (02 Nos)
A21: 1 | B21: AP 46 - AP 47 | C21: Barmer-Jodhpur Single Track Electrified | D21: NWR | E21: 14.07.2025 | F21: 03.08.2025 | G21: 27.08.2025 | H21: 13.11.2025 | I21: 19.11.2025 | J21: 13.11.2025
A22: 2 | B22: AP 150 - AP 151 | C22: Jalore-Bhinmal Single Track Electrified | D22: NWR | E22: 14.07.2025 | F22: 03.08.2025 | G22: 18.08.2025 | H22: 13.11.2025 | I22: 19.11.2025 | J22: 13.11.2025
A23: SH Crossing (07 Nos)
A24: 1 | B24: 5/6 - AP 5A/0 | C24: SH- 65 Sheo - Phalsund | D24: PWD | E24: 01.04.2026 | K24: 30.04.2026
A25: 2 | B25: AP 53-AP 54 | C25: Baytu (Balotra Road) -Chava (Barmer Road) | D25: PWD | E25: 31.05.2025 | F25: 25.06.2025 | G25: 13.08.2025 | J25: 15.10.2025
A26: 3 | B26: AP 71 - 71/1 | C26: Barmer-Sindhari | D26: PWD | E26: 31.05.2025 | F26: 25.06.2025 | G26: 26.08.2025 | H26: 24.09.2025 | I26: 45964 | J26: 45975
A27: 4 | B27: AP 92- AP 93 | C27: Sindhari-Gudamalani | D27: PWD | E27: 31.05.2025 | F27: 25.06.2025 | J27: 21.08.2025
A28: 5 | B28: 103/1-104/0 | C28: Bagoda-Sindhari SH | D28: PWD | E28: 21.02.2026 | F28: 06.03.2026 | K28: 15.04.2026 | L28: Joint Site visit planned by 7th April
A29: 6 | B29: 130/1 - AP 131 | C29: Bagoda-Sayla | D29: PWD | E29: 31.05.2025 | F29: 25.06.2025 | G29: 26.08.2025 | H29: 24.09.2025 | I29: 45964 | J29: 45975
A30: 7 | B30: AP 147/9 - AP 148 | C30: Siyawat/Daspa- Bhinmal | D30: PWD | E30: 31.05.2025 | F30: 25.06.2025 | G30: 26.08.2025 | H30: 24.09.2025 | I30: 45964 | J30: 45975
A31: Oil Line Crossing (06 Nos) | M31: Required document for final approval
A32: 1 | B32: AP 29 - AP 29/1 | C32: OIL Line | D32: Vedanta Cairn Oil & Pipeline | E32: 28.05.2025 | F32: 12.06.2025 | G32: 20.06.2025 | J32: 26.09.2025
A33: 2 | B33: AP 36A - AP 37 | C33: OIL Line | D33: Mangla Crude Oil Pipeline | E33: 28.05.2025 | F33: 11.06.2025 | G33: 10.07.2025 | H33: 17.11.2025 | I33: 31.12.2025 | K33: 46111 | L33: Hard copies submitted on 06.03.2026 | M33: 1. Joint agreement to be signed 2. Special contingency insurance policy (5cr) to be taken and policy shall be valid till one month after completion of work. 3. Supervision charges (E-payment mode) : Rs. 50,000 + 18% GST (Non-Refundable) 4. Processing fee (E-payment mode) : Rs. 25,000 + 18% GST (Non-Refundable) 5. Concrete slab work on pipeline at crossing to be done by Apraava.
A34: 3 | B34: AP 99B - AP 99C | C34: OIL Line | D34: GSPL | E34: 28.05.2025 | F34: 11.06.2025 | G34: 14.07.2025 | H34: 19.06.2025 | I34: 31.12.2025 | K34: 46111 | L34: Soft copies submitted through mail and hard copies will be submitted as per confirmation of address. | M34: 1. Joint agreement to be signed 2. Special contingency insurance policy (2.5cr) to be taken till the completion of work 3. Security deposit (DD) : Rs. 2 lakh - Refundable 4. Processing fee & Supervision charges (DD) : Rs.1.18 lakh (Non-Refundable) 5. AC mitigation Earthing work to be done by Apraava.
A35: 4 | B35: AP 102/1 - AP 102/2 | C35: OIL Line | D35: HPCL Rajasthan Refinery Ltd. | E35: 28.05.2025 | F35: 09.06.2025 | G35: 20.06.2025 | H35: 22.07.2025 | I35: 31.12.2025 | K35: 46111 | L35: Hard copies submitted on 06.03.2026 | M35: 1. Joint agreement to be signed 2. Special contingency insurance policy (5cr) to be taken and policy shall be valid till one month after completion of work. 3. Supervision charges (E-payment mode) : Rs. 50,000 + 18% GST (Non-Refundable) 4. Processing fee (E-payment mode) : Rs. 25,000 + 18% GST (Non-Refundable) 5. AC mitigation Earthing work to be done by Apraava.
A36: 5 | B36: AP 134 - AP 134A | C36: OIL Line | D36: BPPL | E36: 28.05.2025 | F36: 16.06.2025 | G36: 24.07.2025 | H36: 07.11.2025 | I36: 31.12.2025 | K36: 46111 | L36: Hard copies submitted on 06.03.2026 | M36: 1. Joint agreement to be signed 2. Processing fee (E-payment mode) : Rs. 25,000 + 18% GST (Non-Refundable) 3. Sepervision charges : Rs. 1.21 lakh - Non-Refundable 4. AC mitigation charges : Rs.9.36 lakh - Non-Refundable We need to conduct AC-DC interference survey to verify the effectiveness of the mitigation measures implemented, within 30 days of the completion of the crossing work and the charging of the HT Line.
A37: 6 | B37: AP 149 - AP 149A | C37: OIL Line | D37: HMEL | E37: 28.05.2025 | F37: 16.06.2025 | G37: 01.07.2025 | H37: 14.07.2025 | I37: 31.12.2025 | K37: 46111 | L37: Hard copies submitted on 06.03.2026 (Stringing work completed) | M37: 1. Joint agreement to be signed 2. Security deposit : Rs. 5 lakh - Refundable 3. Sepervision charges : Rs. 1.475 lakh - Non-Refundable 4. AC mitigation charges : Rs.3.304 lakh - Non-Refundable
A38: Forest Proposal (01 Nos)
A39: 1 | B39: FP/RJ/PWR_TRANS/554020/2025 | D39: MoECC | F39: 45939 | I39: 04.03.2026 | J39: 21.01.2026 (Stage-1) | K39: 46142 | L39: Demand letter received on 16.02.2026 Payment done on 04.03.2026 Processing for Stage-II approval
A40: Defence Proposal (01 Nos)
...

Sheet  Crossing Proposal
A1: Sl No. | B1: Crossing Span | C1: Type | D1: Description | G1: Proposal Status | M1: Remarks
A2: A | B2: Power Line Crossings
A3: 1 | B3: AP2/1 - AP3 | C3: 400KV D/C Fatehgarh III Fatehgarh IV T/L | D3: Apraava Energy PVT. LTD. | E3: 10.07.2025 | F3: Subject to Approval of CS | G3: Survey Report Submitted to Apraava Engg,
A4: 2 | B4: AP4 - AP5 | C4: 220 KV S/C PSS To FS IV Ampin CKT-1. | D4: RRVPNL | E4: 10.07.2025 | F4: Subject to Approval of CS | G4: Survey Report Submitted to Apraava Engg,
A5: 3 | B5: AP5D - AP5E | C5: 132 KV S/C Sheo to Undoo Line. | D5: RRVPNL | E5: 10.07.2025 | F5: Subject to Approval of CS | G5: Survey Report Submitted to Apraava Engg,
A6: 4 | B6: AP25 - 26 | C6: 400kV D/C Rajwest to Jodhpur TL & Rajwest to Pancpadra | D6: RRVPNL | E6: 07.07.2025 | F6: Crossing Proposal Hardcopy submitted to Apraava | G6: Proposal Submitted to Apraava
A7: 5 | B7: A 27- A 27A | C7: 220kV S/C BALOTARA TO GIRAL T/ Lin | D7: RRVPNL | F7: Submitted on 24.05.25 | G7: AE will forward proposal for NOC to Chief Zonal by 10.10.2025
A8: 6 | B8: AP50-AP51 | C8: 220kV S/C BALOTARA TO BARMER T/ Line | D8: RRVPNL | F8: Submitted on 24.05.25
A9: 7 | B9: AP58-AP59 | C9: 132kV S/C BALOTARA TO BARMER T/ Line | D9: RRVPNL | F9: Submitted on 24.05.25
A10: 8 | B10: AP111-AP112 | C10: 132kV S/C KHOOKHA TO JIWANA T/ Line | D10: RRVPNL | F10: Submitted on 24.05.25 | G10: NOC/Approval Given on 28.08.2025
A11: 9 | B11: AP144-AP145 | C11: 132kV S/C BHINMAL TO DASPUR T/ Line | D11: RRVPNL | F11: Submitted on 24.05.25
A12: 10 | B12: AP152-AP153 | C12: 220kV D/C SAYLA TO BHINMAL,PGCIL (RRVPNL) T/ Line | D12: RRVPNL | F12: Submitted on 24.05.25
A13: 11 | B13: AP154-AP155 | C13: 400kV D/C BARMER-II TO BHINMAL T/ Line | D13: RRVPNL | E13: 07.07.2025 | F13: Crossing Proposal Hardcopy under submission | G13: Proposal submited by KEC.
A14: B | B14: River Crossing
A15: 1 | B15: AP 94 TO AP 95 | C15: LUNI River | D15: River Crossing
A16: 2 | B16: 133/0 TO 133/4 | C16: SUKRI River | D16: River Crossing
A17: 3 | B17: 137/0 TO138/0 | C17: BANDI RIVER | D17: River Crossing
A18: C | B18: Railway Crossings
A19: 1 | B19: AP 46 TO AP 47 | C19: Rly | D19: Barmer-Jodhpur Single Track | G19: Partial payment done on 25th Sep. Further proceedings of approval are under process.
A20: =A19+1 -> 2 | B20: AP 150 AP 151 | C20: Rly | D20: Jalore-Bhinmal Single Track
A21: D. | B21: NH/Expressway Crossing (02 Nos)
A22: 1 | B22: AP 43 - AP 44 | C22: Barmer-Jodhpur National Highway-25 | D22: NHAI | F22: 15.12.2025 | G22: Reply to the queries raised by PIU Jaisalmer will be submitted by 26th Nov
A23: 2 | B23: AP 121 - AP 122 | C23: Jamnagar-Amritsar Bharat Mala Expressway NH -754 | D23: NHAI | F23: 15.12.2025 | G23: NOC expected by 30th Nov 25
A24: E. | B24: Road Crossing
A25: 1 | B25: AP 53-AP-54 | C25: Baytu (Balotra Road) -Chava (Barmer Road) | D25: PWD | F25: NOC pending
A26: 2 | B26: AP 71 - 71/1 | C26: Barmer-Sindhari | D26: PWD
A27: 3 | B27: AP 92- AP 93 | C27: Sindhari-Gudamalani | D27: PWD | E27: NOC/Approved on21.08.2025
A28: 4 | B28: 130/1 - AP 131 | C28: Bagoda-Sayla | D28: PWD
A29: 5 | B29: AP 147/9 - AP 148 | C29: Siyawat/Daspa- Bhinmal | D29: PWD
A30: 6 | B30: AP 04 - AP 05 | C30: Re-Route | F30: Detail survey submitted by KEC.
A31: F. | B31: Oil Pipe Crossing
A32: 1 | B32: 29/0-29/1 | D32: VEDANTA CAIRN OIL & GAS PIPE LINE RAJASTHAN | G32: NOC/APPROVAL 26.09.2025
A33: =A32+1 -> 2 | B33: 36A/0-37/0 | D33: MANGALA CRUDE OIL PIPE LINE (HPCL-RAJASTHAN REFINERY LIMITED) RAJASTHAN | G33: Demand letter expected by 15.10.2025
A34: =A33+1 -> 3 | B34: 99B/0-99C/0 | D34: HRRL CONNECTIVITY GAS PIPE LINE(GSPL INDIA GASNE LIMITED BALOTRA ) RAJASTHAN | G34: DD submitted and other documents to be submitted as per GSPL requirement
A35: =A34+1 -> 4 | B35: 102/1-102/2 | D35: ARAB MIX CRUDE OIL PIPE LINE(HPCL RAJASTHAN REFINERY LIMITED PACHADRA,BALOTRA ) RAJASTHAN | G35: Documents to be submitted as per HRRL requirement
A36: =A35+1 -> 5 | B36: 134/0-134A/0 | D36: BARMER- PALANPUR PRTROLEUM PIPE LINE (HINDUSTAN PERTOLEUM CORP.LTD) RAJASTHAN | G36: Demand letter expected by 15.10.2025
A37: 6 | B37: 149/0-149A/0 | D37: MUNDRA- BATHINDA CRUDE OIL PIPE LINE (HPCL-Mittal Pipelines Limited) RAJASTHAN | G37: Draft agreement copy submitted for HMEL review
AC302: 185
AC303: 5

Sheet Sheet1
B1: FOUNDATION STATUS | J1: =SUBTOTAL(3,J5:J24) -> 18
B2: SL. No. | C2: Location Number | D2: Span | E2: Tower Type | F2: RC | G2: Foundation type
H3: Starting date | I3: Completion Date | J3: Agency | K3: Remark | L3: Remarks
B4: 1 | C4: 83/1 | D4: 83/1 | E4: DA+3 | G4: Sandy | H4: 45665 | I4: 45674 | J4: Mahadeep Company | K4: 45674 | L4: Complete
B5: =B4+1 -> 2 | C5: 81/4 | D5: 81/4 | E5: DA+0 | G5: Sandy | H5: 45675 | I5: ROW | J5: Mahadeep Company | K5: ROW LOC HOLD | L5: Row Since 20-01-2025, Gang Domobilized
B6: =B5+1 -> 3 | C6: 75/7 | D6: 75/7 | E6: DA+0 | G6: Sandy | H6: 45675 | I6: 45684 | J6: AR PATEL | L6: RCC Complete
B7: =B6+1 -> 4 | C7: 75/6 | E7: DA+0 | G7: Sandy | H7: 45685 | I7: 45690 | J7: AR PATEL | L7: RCC Complete, Backfilling Done
B8: =B7+1 -> 5 | C8: 75/5 | E8: DA+0 | G8: Sandy | H8: 45685 | I8: 45693 | J8: AR PATEL | L8: RCC Complete.
B9: =B8+1 -> 6 | C9: 75/4 | E9: DA+0 | G9: Sandy | H9: 45686 | I9: 45693 | J9: Om Constraction | L9: RCC Complete, Backfilling Done
B10: =B9+1 -> 7 | C10: 75/3 | E10: DA+3 | G10: Sandy | H10: 45691 | I10: 45698 | J10: Om Constraction | L10: RCC Complete.
B11: =B10+1 -> 8 | C11: 75/1 | E11: DA+0 | G11: Sandy | H11: 45697 | I11: 45705 | J11: Om Constraction | L11: RCC Complete.
B12: =B11+1 -> 9 | C12: 75/2 | E12: DA+0 | G12: Sandy | H12: 45700 | I12: 45706 | J12: Om Constraction | L12: RCC Complete.
B13: =B12+1 -> 10 | C13: 77/1 | E13: DA+0 | G13: Sandy | H13: 45691 | I13: 45699 | J13: Anjaana Construction | L13: RCC Complete.
B14: =B13+1 -> 11 | C14: 77/2 | E14: DA+3 | G14: Sandy | H14: 45691 | I14: 45697 | J14: AR PATEL | L14: RCC Complete, Backfilling Done
B15: =B14+1 -> 12 | C15: 77/3 | E15: DA+0 | G15: Sandy | H15: 45696 | I15: 45702 | J15: AR PATEL | L15: RCC Complete.
B16: =B15+1 -> 13 | C16: 77/4 | E16: DA+3 | G16: Sandy | H16: 42046 | I16: 45705 | J16: Anjaana Construction | L16: RCC Complete.
B17: =B16+1 -> 14 | C17: 77/5 | E17: DA+6 | G17: Sandy | H17: 45701 | J17: AR PATEL | L17: Pit B,C RCC Done & Pit A,D Frustrum RCC done.
B18: =B17+1 -> 15 | C18: 86/2 | E18: DA+0 | G18: Sandy | H18: 45698 | J18: Kalpana Enterprises | L18: Pit A , Pit B RCC Done , Pit C -Stub setting.
B19: =B18+1 -> 16 | C19: 66/1 | E19: DA+9 | G19: Sandy | H19: 45705 | J19: Siyag Construction | L19: Excavation WIP, ROW,Material Shifting WIP
B20: =B19+1 -> 17 | C20: 73/3 | E20: DA+9 | G20: Sandy | H20: 45705 | J20: Om Constraction | L20: Excavation WIP, ROW, Material Shifting WIP
B21: =B20+1 -> 18 | C21: 79/1 | E21: DA+9 | G21: Sandy | H21: 45705 | J21: Anjana Construction | L21: Excavation WIP, ROW, Material Shifting WIP
B22: =B21+1 -> 19 | C22: 95A/1 | E22: DA+0 | G22: Sandy | J22: Gurukripa Enterprises | L22: Pit Marking Done
B23: =B22+1 -> 20 | C23: 80/1
B24: =B23+1 -> 21 | C24: 85/1
B25: =B24+1 -> 22 | C25: 73/2
B26: =B25+1 -> 23 | C26: 66/2
B27: =B26+1 -> 24 | C27: 66/3
B28: =B27+1 -> 25 | C28: 86/1
B29: =B28+1 -> 26 | C29: 76/1

Sheet VC 51-96
B1: TB-507 400 KV (Twin) D/C Fatehgarh IV - Bhinmal Transmission Line
A2: DPR and VISUAL CHART
A4: DPR- | D4: District | F4: No.Of Towers | G4: Length | H4: Foundation | K4: Earthing | L4: Tower Erection | O4: Stringing
H5: Com | I5: WIP | J5: Bal | K5: Com | L5: Com | M5: WIP | N5: Bal | O5: Com | P5: WIP | Q5: Bal
F6: 163 | G6: 50.886 | H6: 16 | I6: 5 | J6: =F6-H6-I6 -> 142 | K6: 10 | N6: =F6-L6 -> 163 | Q6: =G6-O6 -> 50.886
C8: =A8+1 -> 1 | E8: =C8+1 -> 2 | G8: =E8+1 -> 3 | I8: =G8+1 -> 4 | K8: =I8+1 -> 5 | M8: =K8+1 -> 6 | O8: =M8+1 -> 7 | Q8: =O8+1 -> 8 | S8: =Q8+1 -> 9
D10: 465.03 | F10: 375.98 | H10: 414.86 | J10: 381.02 | L10: 353.63 | N10: 351.4 | P10: 433.26 | R10: 396.56 | T10: 408.11 | U10: =B10+F10+H10+J10+L10+D10+N10+P10+R10+T10 -> 3579.85
C13: AP51 | E13: 51/1 | G13: 51/2 | I13: 51/3 | K13: AP52 | M13: 52/1 | O13: AP53 | Q13: AP54 | S13: 54/1
C14: DD+18 | E14: DA+03 | G14: DA+00 | I14: DA+03 | K14: DB+0 | M14: DA+06 | O14: DD+0 | Q14: DC+00 | S14: DA+03
K15: RC | M15: RC
B17: =S8+1 -> 10 | D17: =B17+1 -> 11 | F17: =D17+1 -> 12 | H17: =F17+1 -> 13 | J17: =H17+1 -> 14 | L17: =J17+1 -> 15 | N17: =L17+1 -> 16 | P17: =N17+1 -> 17 | R17: =P17+1 -> 18 | T17: =R17+1 -> 19
C19: 425.22 | E19: 420.54 | G19: 340.56 | I19: 336.52 | K19: 375.99 | M19: 303.41 | O19: 448.76 | Q19: 393.09 | S19: 407.8 | U19: 206.06 | V19: =C19+G19+I19+K19+M19+E19+O19+Q19+S19+U19 -> 3657.95
B22: 54/2 | D22: 54/3 | F22: AP55 | H22: AP56 | J22: 56/1 | L22: 56/2 | N22: 56/3 | P22: 56/4 | R22: 56/5 | T22: AP57
B23: DA+06 | D23: DA+03 | F23: DD+18 | H23: DB+09 | J23: DB+9 | L23: DA+0 | N23: DB+9 | P23: DA+6 | R23: DA+6 | T23: DB+09
B24: Benching &RC | D24: RC | F24: RC | H24: Benching &RC | L24: Benching Required | R24: Benching &RC | T24: Benching &RC
B26: =T17+1 -> 20 | D26: =B26+1 -> 21 | F26: =D26+1 -> 22 | H26: =F26+1 -> 23 | J26: =H26+1 -> 24 | L26: =J26+1 -> 25 | N26: =L26+1 -> 26 | P26: =N26+1 -> 27 | R26: =P26+1 -> 28 | T26: =R26+1 -> 29
C28: 417.38 | E28: 304.56 | G28: 408.66 | I28: 434.89 | K28: 408.17 | M28: 398.59 | O28: 446.37 | Q28: 297.58 | S28: 240.47 | U28: 312.69 | V28: =C28+G28+I28+K28+M28+E28+O28+Q28+S28+U28 -> 3669.36
B31: AP58 | D31: AP59 | F31: 59/1 | H31: AP60 | J31: 60/1 | L31: 60/2 | N31: 60/3 | P31: AP61 | R31: 61/1 | T31: AP62
B32: DB+09 | D32: DC+09 | F32: DA+0 | H32: DD+00 | J32: DA+9 | L32: DA+0 | N32: DA+9 | P32: DC+00 | R32: DA+9 | T32: DB+00
F33: Benching | N33: RC
B35: =T26+1 -> 30 | D35: =B35+1 -> 31 | F35: =D35+1 -> 32 | H35: =F35+1 -> 33 | J35: =H35+1 -> 34 | L35: =J35+1 -> 35 | N35: =L35+1 -> 36 | P35: =N35+1 -> 37 | R35: =P35+1 -> 38 | T35: =R35+1 -> 39
C37: 347.88 | E37: 379.25 | G37: 398.7 | I37: 439.06 | K37: 381.53 | M37: 379.71 | O37: 426.3 | Q37: 387.14 | U37: 423.77 | V37: =C37+G37+I37+K37+M37+E37+#REF!+O37+Q37+#REF! -> #REF!
B40: 62/1 | D40: 62/2 | F40: 62/3 | H40: 62/4 | J40: 62/5 | L40: AP63 | N40: 63/1 | P40: AP64 | R40: 64/1 | T40: 64/2
B41: DA+0 | D41: DA+0 | F41: DA+09 | H41: DA+06 | J41: DA+06 | L41: DC+00 | N41: DA+0 | P41: DC+09 | R41: DA+9 | T41: DA+9
B42: RC | F42: RC | P42: Benching &RC | T42: RC
B43: =T35+1 -> 40 | D43: =B43+1 -> 41 | F43: =D43+1 -> 42 | H43: =F43+1 -> 43 | J43: =H43+1 -> 44 | L43: =J43+1 -> 45 | N43: =L43+1 -> 46 | P43: =N43+1 -> 47 | R43: =P43+1 -> 48 | T43: =R43+1 -> 49
C45: 407.9 | E45: 426.63 | G45: 392.27 | I45: 431.96 | K45: 426.02 | M45: 405.36 | O45: 411.93 | Q45: 423.77 | S45: 407.9 | U45: 426.63
B46: F | D46: WIP | R46: F | T46: F
B48: 64/3 | D48: 64/4 | F48: 64/5 | H48: 64/6 | J48: 64/7 | L48: 65/0 | N48: 65/1 | P48: 66/0 | R48: 66/1 | T48: 66/2
B49: DA+9 | D49: DA+9 | F49: DA+9 | H49: DA+3 | J49: DA+3 | L49: DD+0 | N49: DB+09 | P49: DD+0 | R49: DA+9 | T49: DA+0 | V49: =#REF!+I77+K77+M77+O77+G77+Q77+S77+#REF!+#REF! -> #REF!
P50: RC
B51: =T43+1 -> 50 | D51: =B51+1 -> 51 | F51: =D51+1 -> 52 | H51: =F51+1 -> 53 | J51: =H51+1 -> 54 | L51: =J51+1 -> 55 | N51: =L51+1 -> 56 | P51: =N51+1 -> 57 | R51: =P51+1 -> 58 | T51: =R51+1 -> 59
C53: 392.27 | E53: 431.96 | G53: 426.02 | I53: 405.36 | K53: 411.93 | M53: 350.33 | O53: 378.3 | Q53: 416.82 | S53: 371.85
B54: WIP
B56: 66/3 | D56: 66/4 | F56: 67/0 | H56: 67/1 | J56: 67/2 | L56: AP68 | N56: AP69 | P56: 69/1 | R56: 69/2 | T56: 69/3
B57: DA+3 | D57: DA+9 | F57: DC+6 | H57: DA+6 | J57: DB+0 | L57: DB+09 | N57: DD+3 | P57: DA+6 | R57: DA+0 | T57: DA+00
F58: RC | R58: Benching | T58: RC | V58: =A85+I77+K77+M77+O77+G77+Q77+S77+#REF!+C77 -> #REF!
B59: =T51+1 -> 60 | D59: =B59+1 -> 61 | F59: =D59+1 -> 62 | H59: =F59+1 -> 63 | J59: =H59+1 -> 64 | L59: =J59+1 -> 65 | N59: =L59+1 -> 66 | P59: =N59+1 -> 67 | R59: =P59+1 -> 68 | T59: =R59+1 -> 69
C61: 392.27 | E61: 431.96 | G61: 426.02 | I61: 405.36 | K61: 411.93 | M61: 350.33 | O61: 378.3 | Q61: 416.82 | S61: 371.85
T62: F
...

Sheet VC
C2: TB-507 400 KV (Twin) D/C Fatehgarh IV - Bhinmal Transmission Line
C3: DPR and VISUAL CHART
C5: DPR- | F5: District | H5: No.Of Towers | I5: Length | J5: Foundation | M5: Earthing | N5: Tower Erection | Q5: Stringing
J6: Com | K6: WIP | L6: Bal | M6: Com | N6: Com | O6: WIP | P6: Bal | Q6: Com | R6: WIP | S6: Bal
H7: 495 | I7: 187.175 | J7: 9 | K7: 5 | L7: =H7-J7-K7 -> 481 | M7: 3 | P7: =H7-N7 -> 495 | S7: =I7-Q7 -> 187.175
I8: r
C9: 1 | E9: =C9+1 -> 2 | G9: =E9+1 -> 3 | I9: =G9+1 -> 4 | K9: =I9+1 -> 5 | M9: =K9+1 -> 6 | O9: =M9+1 -> 7 | Q9: =O9+1 -> 8 | S9: =Q9+1 -> 9 | U9: =S9+1 -> 10
D11: 97.4 | F11: 139.42 | H11: 484.04 | J11: 398 | L11: 443.16 | N11: 399.53 | P11: 402.87 | R11: 437.15 | T11: 381.84 | V11: 416.91 | W11: =D11+H11+J11+L11+N11+F11+P11+R11+T11+V11 -> 3600.32 | X11: FDN | Y11: TE | Z11: Earthing | AA11: Stringing | AC11: Tack Welding | AE11: =SUM(D11:V11) -> 3600.32
A12: 1 | X12: =COUNTIF(C12:U12,"F") -> 0 | Y12: =COUNTIF(C11:U11,"E") -> 0 | Z12: =COUNTIF(C13:V13,"Er") -> 0 | AB12: COM
X13: =COUNTIF(C13:U13,"U/P") -> 0 | Y13: 0 | Z13: 0 | AB13: WIP
C14: GE | E14: AP1 | G14: AP2 | I14: AP3 | K14: 03/1 | M14: 3/2 | O14: 3/3 | Q14: 3/4 | S14: 3/5 | U14: 3/6 | X14: =COUNTIF(C12:U12,"ROW") -> 0 | Y14: 0 | Z14: 0 | AB14: ROW
E15: DD+03 | G15: DD+9 | I15: DC+9 | K15: DA+9 | M15: DA+0 | O15: DA+3 | Q15: DA+6 | S15: DA+3 | U15: DA+00
C17: =U9+1 -> 11 | E17: =C17+1 -> 12 | G17: =E17+1 -> 13 | I17: =G17+1 -> 14 | K17: =I17+1 -> 15 | M17: =K17+1 -> 16 | O17: =M17+1 -> 17 | Q17: =O17+1 -> 18 | S17: =Q17+1 -> 19 | U17: =S17+1 -> 20
D19: 428.12 | F19: 249.58 | H19: 454.54 | J19: 377.83 | L19: 447.64 | N19: 396.44 | P19: 445.93 | R19: 156.98 | T19: 409.67 | V19: 382.38 | W19: =D19+H19+J19+L19+N19+F19+P19+R19+T19+V19 -> 3749.11 | AE19: =SUM(D19:V19) -> 3749.11
A20: =A12+1 -> 2 | X20: =COUNTIF(C20:U20,"F") -> 0 | Y20: =COUNTIF(C19:U19,"E") -> 0 | Z20: =COUNTIF(C21:V21,"Er") -> 0 | AB20: COM
X21: =COUNTIF(C21:U21,"U/P") -> 0 | Y21: 0 | Z21: 0 | AB21: WIP
C22: 3/7 | E22: 3/8 | G22: AP4 | I22: 4/1 | K22: AP5 | M22: 5/1 | O22: 5/2 | Q22: AP6 | S22: AP7 | U22: 7/1 | X22: =COUNTIF(C20:U20,"ROW") -> 0 | Y22: 0 | Z22: 0 | AB22: ROW
C23: DA+03 | E23: DD+03 RC | G23: DD+03 | I23: DA+09 | K23: DC+3 | M23: DA+06 | O23: DA+03 | Q23: DD+09 | S23: DD+09 | U23: DA+00
C25: =U17+1 -> 21 | E25: =C25+1 -> 22 | G25: =E25+1 -> 23 | I25: =G25+1 -> 24 | K25: =I25+1 -> 25 | M25: =K25+1 -> 26 | O25: =M25+1 -> 27 | Q25: =O25+1 -> 28 | S25: =Q25+1 -> 29 | U25: =S25+1 -> 30
D27: 353.89 | F27: 385.21 | H27: 367.67 | J27: 378.32 | L27: 392.49 | N27: 399.24 | P27: 390.93 | R27: 412.07 | T27: 421.95 | V27: 391.87 | W27: =D27+H27+J27+L27+N27+F27+P27+R27+T27+V27 -> 3893.64 | AE27: =SUM(D27:V27) -> 3893.64
A28: =A20+1 -> 3 | X28: =COUNTIF(C28:U28,"F") -> 0 | Y28: =COUNTIF(C27:U27,"E") -> 0 | Z28: =COUNTIF(C29:V29,"Er") -> 0 | AB28: COM
X29: =COUNTIF(C29:U29,"U/P") -> 0 | Y29: 0 | Z29: 0 | AB29: WIP
C30: 7/2 | E30: 7/3 | G30: 7/4 | I30: 7/5 | K30: 7/6 | M30: '7/7 | O30: AP8 | Q30: 08/01 | S30: 08/2 | U30: 08/3 | X30: =COUNTIF(C28:U28,"ROW") -> 0 | Y30: 0 | Z30: 0 | AB30: ROW
C31: DA+00 | E31: DA+00 | G31: DA+00 | I31: DA+00 | K31: DA+00 | M31: DA+00 | O31: DB+00 | Q31: DA+06 | S31: DA+00 | U31: DA+00
C33: =U25+1 -> 31 | E33: =C33+1 -> 32 | G33: =E33+1 -> 33 | I33: =G33+1 -> 34 | K33: =I33+1 -> 35 | M33: =K33+1 -> 36 | O33: =M33+1 -> 37 | Q33: =O33+1 -> 38 | S33: =Q33+1 -> 39 | U33: =S33+1 -> 40
D35: 406.65 | F35: 383.31 | H35: 402.96 | J35: 433.9 | L35: 328.55 | N35: 331.44 | P35: 358.83 | R35: 358.55 | T35: 429.37 | V35: 354.9 | W35: =D35+H35+J35+L35+N35+F35+P35+R35+T35+V35 -> 3788.46 | AE35: =SUM(D35:V35) -> 3788.46
A36: =A28+1 -> 4 | X36: =COUNTIF(C36:U36,"F") -> 0 | Y36: =COUNTIF(C35:U35,"E") -> 0 | Z36: =COUNTIF(C37:V37,"Er") -> 0 | AB36: COM
X37: =COUNTIF(C37:U37,"U/P") -> 0 | Y37: 0 | Z37: 0 | AB37: WIP
C38: 08/4 | E38: 08/5 | G38: 08/6 | I38: 08/7 | K38: AP9 | M38: 09/01 | O38: 09/02 | Q38: 09/03 | S38: 09/04 | U38: 09/05 | X38: =COUNTIF(C36:U36,"ROW") -> 0 | Y38: 0 | Z38: 0 | AB38: ROW
C39: DA+03 | E39: DA+00 | G39: DA+06 | I39: DA+06 | K39: DB+00 | M39: DA+00 | O39: DA+00 | Q39: DA+00 | S39: DA+00 | U39: DA+00
C41: =U33+1 -> 41 | E41: =C41+1 -> 42 | G41: =E41+1 -> 43 | I41: =G41+1 -> 44 | K41: =I41+1 -> 45 | M41: =K41+1 -> 46 | O41: =M41+1 -> 47 | Q41: =O41+1 -> 48 | S41: =Q41+1 -> 49 | U41: =S41+1 -> 50
D43: 340.94 | F43: 405.66 | H43: 409.41 | J43: 378.36 | L43: 322.47 | N43: 386.39 | P43: 386.19 | R43: 406.2 | T43: 351.15 | V43: 380.59 | W43: =D43+H43+J43+L43+N43+F43+P43+R43+T43+V43 -> 3767.36 | AE43: =SUM(D43:V43) -> 3767.36
A44: =A36+1 -> 5 | X44: =COUNTIF(C44:U44,"F") -> 0 | Y44: =COUNTIF(C43:U43,"E") -> 0 | Z44: =COUNTIF(C45:V45,"Er") -> 0 | AB44: COM
X45: =COUNTIF(C45:U45,"U/P") -> 0 | Y45: 0 | Z45: 0 | AB45: WIP
C46: 09/06 | E46: AP10 | G46: 10/01 | I46: 10/02 | K46: 10/03 | M46: 10/04 | O46: 10/05 | Q46: 10/06 | S46: 10/07 | U46: 10/08 | X46: =COUNTIF(C44:U44,"ROW") -> 0 | Y46: 0 | Z46: 0 | AB46: ROW
C47: DA+00 | E47: DC+9 | G47: DA+09 | I47: DA+00 | K47: DA+00 | M47: DA+00 | O47: DA+00 | Q47: DA+00 | S47: DA+00 | U47: DA+00
C49: =U41+1 -> 51 | E49: =C49+1 -> 52 | G49: =E49+1 -> 53 | I49: =G49+1 -> 54 | K49: =I49+1 -> 55 | M49: =K49+1 -> 56 | O49: =M49+1 -> 57 | Q49: =O49+1 -> 58 | S49: =Q49+1 -> 59 | U49: =S49+1 -> 60
D51: 380.02 | F51: 393.7 | H51: 390.68 | J51: 349.16 | L51: 416.01 | N51: 400.75 | P51: 406.84 | R51: 404.76 | T51: 311.74 | V51: 389.98 | W51: =D51+H51+J51+L51+N51+F51+P51+R51+T51+V51 -> 3843.64 | AE51: =SUM(D51:V51) -> 3843.64
A52: =A44+1 -> 6 | X52: =COUNTIF(C52:U52,"F") -> 0 | Y52: =COUNTIF(C51:U51,"E") -> 0 | Z52: =COUNTIF(C53:V53,"Er") -> 0 | AB52: COM
X53: =COUNTIF(C53:U53,"U/P") -> 0 | Y53: 0 | Z53: 0 | AB53: WIP
...

Sheet ROW
A1: NAME OF PROJECT : FARHEGARH IV-BHINMAL 400KV D/C TRANSMISSION LINE
A2: Client : RAJASTHAN IV A POWER TRANSMISSION LTD.
A3: CONTRACTOR : KEC INTERNATIONAL LIMITED
A6: FOUNDATION STATUS
A7: SL. No. | B7: Location Number | C7: Span | D7: Tower Type | E7: AS PER RAPTL ROW CLEARED ON | F7: WORK COMMENCED KEC | G7: STATUS
A9: 1 | B9: 80/0
A10: =A9+1 -> 2 | B10: 66/4 | F10: ROW
A11: =A10+1 -> 3 | B11: 89/1 | F11: ROW
A12: =A11+1 -> 4 | B12: 102/1
A13: =A12+1 -> 5 | B13: 102/2 | F13: Anjana Const | H13: Previous Loc Done 99/2 on 25/4/2025
A14: =A13+1 -> 6 | B14: 107/1
A15: =A14+1 -> 7 | B15: 90/1 | F15: ROW
A16: =A15+1 -> 8 | B16: 81/1
A17: =A16+1 -> 9 | B17: 51/1
A18: =A17+1 -> 10 | B18: 99A/2
A19: =A18+1 -> 11 | B19: 61/1
A20: =A19+1 -> 12 | B20: 72/2
A21: =A20+1 -> 13 | B21: 73/1
A22: =A21+1 -> 14 | B22: 99/5
A23: =A22+1 -> 15 | B23: 56/2
A24: =A23+1 -> 16 | B24: 63/1
A25: =A24+1 -> 17 | B25: 114/1
A26: =A25+1 -> 18 | B26: 116/1
A27: =A26+1 -> 19 | B27: 56/1
... A40: =A39+1 -> 32 | B40: 147/7

Sheet June
B1: Sl No | C1: Loc No | D1: TOT | F1: Classification | G1: Starting Date | H1: Completion
B2: 1 | C2: 81/3 | D2: DA+0 | F2: Sandy | G2: 45799 | H2: 45812
B3: =B2+1 -> 2 | C3: 120/1 | D3: DA+6 | F3: Sandy | G3: 45807 | H3: 45813
B4: =B3+1 -> 3 | C4: 96/0 | D4: DC+0 | F4: DFR | G4: 45805 | H4: 45814
B5: =B4+1 -> 4 | C5: 75/0 | D5: DC+0 | F5: Sandy | G5: 45809 | H5: 45815
B6: =B5+1 -> 5 | C6: 147/2 | D6: DA+0 | F6: Sandy | G6: 45810 | H6: 45816
B7: =B6+1 -> 6 | C7: 82/2 | D7: DA+0 | F7: Sandy | G7: 45810 | H7: 45818
B8: =B7+1 -> 7 | C8: 79/0 | D8: DD+0 | F8: Sandy | G8: 45877 | H8: 45820
B9: =B8+1 -> 8 | C9: 147/5 | D9: DA+0 | F9: Sandy | G9: 45812 | H9: 45820
B10: =B9+1 -> 9 | C10: 119/0 | D10: DD+3 | F10: Sandy | G10: 45813 | H10: 45823
B11: =B10+1 -> 10 | C11: 82/1 | D11: DA+6 | F11: Sandy | G11: 45818 | H11: 45823
B12: =B11+1 -> 11 | C12: 147/0 | D12: DC+0 | F12: Sandy | G12: 45816 | H12: 45823
B13: =B12+1 -> 12 | C13: 78/0 | D13: DC+0 | F13: Sandy | G13: 45821 | H13: 45824
B14: =B13+1 -> 13 | C14: 147/4 | D14: DA+0 | F14: Sandy | G14: 45821 | H14: 45824
... B26: =B25+1 -> 25 | C26: 147/8 | D26: DA+0 | F26: Sandy | G26: 45833 | H26: 45838

Sheet Foundation
A1: NAME OF PROJECT : FARHEGARH IV-BHINMAL 400KV D/C TRANSMISSION LINE
A2: Client : RAJASTHAN IV A POWER TRANSMISSION LTD.
A3: CONTRACTOR : KEC INTERNATIONAL LIMITED
A5: FOUNDATION STATUS
A6: SL. No. | B6: Location Number | C6: Span | D6: Tower Type | E6: M10 | F6: M20 | G6: Excavation | H6: Reinforcement | I6: Stub | J6: RC | K6: Foundation type
L7: Starting date | M7: Completion Date | N7: Agency | O7: Remark | P7: Working Manpower | Q7: Remarks
A8: 1 | B8: 83/1 | C8: 83/1 | D8: DA+3 | E8: 1.86 | F8: 12.47 | G8: 134.7 | H8: 1.115 | I8: 0.299 | K8: Sandy | L8: 45665 | M8: 45674 | N8: Mahadeep Company | O8: 45674 | Q8: RCC Complete, Backfilling Done
A9: =A8+1 -> 2 | B9: 75/7 | C9: 75/7 | D9: DA+0 | E9: 1.57 | F9: 11.05 | G9: 115.3 | H9: 0.919 | I9: 0.299 | K9: Sandy | L9: 45675 | M9: 45684 | N9: AR Patel Contractor | Q9: RCC Complete, Backfilling Done
A10: =A9+1 -> 3 | B10: 75/6 | D10: DA+0 | E10: 1.57 | F10: 11.05 | G10: 115.3 | H10: 0.919 | I10: 0.299 | K10: Sandy | L10: 45685 | M10: 45690 | N10: AR Patel Contractor | Q10: RCC Complete, Backfilling Done
A11: =A10+1 -> 4 | B11: 75/4 | D11: DA+0 | E11: 1.57 | F11: 11.05 | G11: 115.3 | H11: 0.919 | I11: 0.299 | K11: Sandy | L11: 45686 | M11: 45693 | N11: OM Construction | Q11: RCC Complete, Backfilling Done
A12: =A11+1 -> 5 | B12: 75/5 | D12: DA+0 | E12: 1.57 | F12: 11.05 | G12: 115.3 | H12: 0.919 | I12: 0.299 | K12: Sandy | L12: 45691 | M12: 45693 | N12: AR Patel Contractor | Q12: RCC Complete, Backfilling Done
A13: =A12+1 -> 6 | B13: 77/2 | D13: DA+3 | E13: 1.86 | F13: 12.47 | G13: 134.7 | H13: 1.115 | I13: 0.299 | K13: Sandy | L13: 45691 | M13: 45697 | N13: AR Patel Contractor | Q13: RCC Complete, Backfilling Done
A14: =A13+1 -> 7 | B14: 75/3 | D14: DA+3 | E14: 1.86 | F14: 12.47 | G14: 134.7 | H14: 1.115 | I14: 0.299 | K14: Sandy | L14: 24 | M14: 45698 | N14: OM Construction | Q14: RCC Complete, Backfilling Done
A15: =A14+1 -> 8 | B15: 77/1 | D15: DA+0 | E15: 1.57 | F15: 11.05 | G15: 115.3 | H15: 0.919 | I15: 0.299 | K15: Sandy | L15: 45691 | M15: 45699 | N15: AAnjana Contractors | Q15: RCC Complete, Backfilling Done
A16: =A15+1 -> 9 | B16: 77/3 | D16: DA+0 | E16: 1.57 | F16: 11.05 | G16: 115.3 | H16: 0.919 | I16: 0.299 | K16: Sandy | L16: 45696 | M16: 45702 | N16: AR Patel Contractor | Q16: RCC Complete, Backfilling Done
A17: =A16+1 -> 10 | B17: 75/1 | D17: DA+0 | E17: 1.57 | F17: 11.05 | G17: 115.3 | H17: 0.919 | I17: 0.299 | K17: Sandy | L17: 45697 | M17: 45705 | N17: OM Construction | Q17: RCC Complete, Backfilling Done
A18: =A17+1 -> 11 | B18: 77/4 | D18: DA+3 | E18: 1.86 | F18: 12.47 | G18: 134.7 | H18: 1.115 | I18: 0.299 | K18: Sandy | L18: 45699 | M18: 45705 | N18: AAnjana Contractors | Q18: RCC Complete, Backfilling Done
A19: =A18+1 -> 12 | B19: 75/2 | D19: DA+0 | E19: 1.57 | F19: 11.05 | G19: 115.3 | H19: 0.919 | I19: 0.299 | K19: Sandy | L19: 45700 | M19: 45706 | N19: OM Construction | Q19: RCC Complete, Backfilling Done
A20: =A19+1 -> 13 | B20: 77/5 | D20: DA+6 | E20: 1.86 | F20: 12.47 | G20: 134.7 | H20: 1.115 | I20: 0.299 | K20: Sandy | L20: 45701 | M20: 45707 | N20: AR Patel Contractor | Q20: RCC Complete, Backfilling Done
A21: =A20+1 -> 14 | B21: 73/3 | D21: DA+9 | E21: 1.86 | F21: 12.47 | G21: 134.7 | H21: 1.115 | I21: 0.299 | K21: Sandy | L21: 45705 | M21: 45710 | N21: OM Construction | Q21: RCC Complete, Backfilling Done
... A64: =A63+1 -> 57 | B64: 99C/2 | D64: DA+3 | E64: 1.86 | F64: 12.47 | G64: 134.7 | H64: 1.115 | I64: 0.299 | K64: Sandy | L64: 45795 | M64: 45802 | N64: Mundhan Trading Company | Q64: RCC Complete, Backfilling Done
A65: =A64+1 -> 58 | B65: 105/0 | D65: DD+0 | E65: =1.81+1.12 -> 2.93 | F65: =8.16+12.18 -> 20.34 | G65: =79.95+144.9 -> 224.85 | H65: =1.476+1.188 -> 2.664 | I65: =(265.195+236.256)/1000 -> 0.501451 | K65: Sandy | L65: 45793 | M65: 45805 | N65: Gurukripa Enterprizes | Q65: RCC Complete, Backfilling Done
A66: =A65+1 -> 59 | B66: 98A/0 | D66: DC+0 | E66: 1.6 | F66: 13.13 | G66: 87.25 | H66: 1.374 | I66: 0.501 | K66: DFR | L66: 45789 | M66: 45806 | N66: Ganga Construction Company | Q66: RCC Complete, Backfilling Done
A67: =A66+1 -> 60 | B67: 62/5 | D67: DA+6 | E67: 1.86 | F67: 12.47 | G67: 134.7 | H67: 1.115 | I67: 0.299 | K67: Sandy | L67: 45779 | M67: 45808 | N67: Ram Shenai Construction | Q67: RCC Complete, Backfilling Done
A68: =A67+1 -> 61 | B68: 81/3 | D68: DA+0 | E68: 1.57 | F68: 11.05 | G68: 115.3 | H68: 0.919 | I68: 0.299 | K68: Sandy | L68: 45799 | M68: 45812 | N68: Ram Shenai Construction | Q68: RCC Complete, Backfilling Done
A69: =A68+1 -> 62 | B69: 120/1 | D69: DA+6 | E69: 1.86 | F69: 12.47 | G69: 134.7 | H69: 1.115 | I69: 0.299 | K69: Sandy | L69: 45807 | M69: 45813 | N69: Majisa Construction | Q69: RCC Complete, Backfilling Done
A70: =A69+1 -> 63 | B70: 96/0 | D70: DC+0 | E70: 1.6 | F70: 13.13 | G70: 87.25 | H70: 1.374 | I70: 0.501 | K70: DFR | L70: 45805 | M70: 45814 | N70: Mundhan Trading Company | Q70: RCC Complete, Backfilling Done
A71: =A70+1 -> 64 | B71: 75/0 | D71: DC+0 | E71: 1.6 | F71: 13.13 | G71: 87.25 | H71: 1.374 | I71: 0.501 | K71: Sandy | L71: 45809 | M71: 45815 | N71: OM Construction | Q71: RCC Complete, Backfilling Done
A72: =A71+1 -> 65 | B72: 147/2 | D72: DA+0 | E72: 1.57 | F72: 11.05 | G72: 115.3 | H72: 0.919 | I72: 0.299 | K72: Sandy | L72: 45810 | M72: 45816 | N72: JP Enterprises | Q72: RCC Complete, Backfilling Done
A73: =A72+1 -> 66 | B73: 82/2 | D73: DA+0 | E73: 1.57 | F73: 11.05 | G73: 115.3 | H73: 0.919 | I73: 0.299 | K73: Sandy | L73: 45810 | M73: 45818 | N73: AAnjana Contractors | Q73: RCC Complete, Backfilling Done
A74: =A73+1 -> 67 | B74: 147/5 | D74: DA+0 | E74: 1.57 | F74: 11.05 | G74: 115.3 | H74: 0.919 | I74: 0.299 | K74: Sandy | L74: 45812 | M74: 45820 | N74: AR Patel Contractor | Q74: RCC Complete, Backfilling Done
A75: =A74+1 -> 68 | B75: 79/0 | D75: DD+0 | E75: =1.81+1.12 -> 2.93 | F75: =8.16+12.18 -> 20.34 | G75: =79.95+144.9 -> 224.85 | H75: =1.476+1.188 -> 2.664 | I75: =(265.195+236.256)/1000 -> 0.501451 | K75: Sandy | L75: 45877 | M75: 45820 | N75: OM Construction | Q75: RCC Complete, Backfilling Done
A76: =A75+1 -> 69 | B76: 119/0 | D76: DD+3 | E76: =1.81+1.12 -> 2.93 | F76: =8.16+12.18 -> 20.34 | G76: =79.95+144.9 -> 224.85 | H76: =1.476+1.188 -> 2.664 | I76: =(265.195+236.256)/1000 -> 0.501451 | K76: Sandy | L76: 45813 | M76: 45823 | N76: Majisa Construction | Q76: RCC Complete, Backfilling Done
A77: =A76+1 -> 70 | B77: 147/0 | D77: DC+0 | E77: 1.6 | F77: 13.13 | G77: 87.25 | H77: 1.374 | I77: 0.501 | K77: Sandy | L77: 45816 | M77: 45823 | N77: JP Enterprises | Q77: RCC Complete, Backfilling Done
A78: =A77+1 -> 71 | B78: 82/1 | D78: DA+6 | E78: 1.86 | F78: 12.47 | G78: 134.7 | H78: 1.115 | I78: 0.299 | K78: Sandy | L78: 45818 | M78: 45823 | N78: AAnjana Contractors | Q78: RCC Complete, Backfilling Done
A79: =A78+1 -> 72 | B79: 147/4 | D79: DA+0 | E79: 1.57 | F79: 11.05 | G79: 115.3 | H79: 0.919 | I79: 0.299 | K79: Sandy | L79: 45821 | M79: 45824 | N79: AR Patel Contractor1 | Q79: RCC Complete, Backfilling Done
A80: =A79+1 -> 73 | B80: 78/0 | D80: DC+0 | E80: 1.6 | F80: 13.13 | G80: 87.25 | H80: 1.374 | I80: 0.501 | K80: Sandy | L80: 45821 | M80: 45824 | N80: OM Construction | Q80: RCC Complete, Backfilling Done
A81: =A80+1 -> 74 | B81: 74/0 | D81: DB+9 | E81: 1.68 | F81: 12.41 | G81: 143.4 | H81: 1.728 | I81: 0.414 | K81: Sandy | L81: 45824 | M81: 45828 | N81: OM Construction | Q81: RCC Complete, Backfilling Done
A82: =A81+1 -> 75 | B82: 147/1 | D82: DA+0 | E82: 1.57 | F82: 11.05 | G82: 115.3 | H82: 0.919 | I82: 0.299 | K82: Sandy | L82: 45823 | M82: 45829 | N82: JP Enterprises | Q82: RCC Complete, Backfilling Done
A83: =A82+1 -> 76 | B83: 147/7 | D83: DA+0 | E83: 1.57 | F83: 11.05 | G83: 115.3 | H83: 0.919 | I83: 0.299 | K83: Sandy | L83: 45823 | M83: 45830 | N83: AR Patel Contractor 2 | Q83: RCC Complete, Backfilling Done
...

Sheet Royalty
O3: OM Construction
C4: Loc No | D4: TOT | E4: M-10 | F4: M-20
C5: 120/1 | D5: DA+6 | E5: 1.86 | F5: 12.47 | O5: 75/0 | P5: DC+0 | Q5: 1.6 | R5: 13.13
C6: 119/0 | D6: DD+3 | E6: 2.93 | F6: 20.34 | O6: 79/0 | P6: DD+0 | Q6: 2.93 | R6: 20.34
D7: CUM | E7: =SUM(E5:E6) -> 4.79 | F7: =SUM(F5:F6) -> 32.81 | J7: ROYALTY ISSUED | O7: 78/0 | P7: DC+0 | Q7: 1.6 | R7: 13.13
C8: CUM | D8: 20MM | E8: =E7*1.54*6/10 -> 4.42596 | F8: =F7*1.54*3/5.5 -> 27.5604 | G8: =SUM(E8:F8) -> 31.98636 | J8: 20MM | O8: 74/0 | P8: DB+9 | Q8: 1.68 | R8: 12.41
C9: CUM | D9: SAND | E9: =E8*1.54*3/10 -> 2.0447935 | F9: =F8*1.54*1.5/5.5 -> 11.575368 | G9: =SUM(E9:F9) -> 13.620162 | J9: 18.48 | O9: 73/0 | P9: DB+0 | Q9: 1.68 | R9: 12.41
C10: MT | D10: 20MM | G10: =G8*1600/1000 -> 51.178176 | H10: Required | J10: 14.67 | O10: 72/2 | P10: DA+3 | Q10: 1.86 | R10: 12.47
C11: MT | D11: SAND | G11: =G9*1600/1000 -> 21.792258 | H11: Required | J11: =SUM(J9:J10) -> 33.15 | Q11: =SUM(Q5:Q10) -> 11.35 | R11: =SUM(R5:R10) -> 83.89
O12: CUM | P12: 20MM | Q12: =Q11*1.54*6/10 -> 10.4874 | R12: =R11*1.54*3/5.5 -> 70.4676 | S12: =SUM(Q12:R12) -> 80.955
O13: CUM | P13: SAND | Q13: =Q12*1.54*3/10 -> 4.8451788 | R13: =R12*1.54*1.5/5.5 -> 29.596392 | S13: =SUM(Q13:R13) -> 34.441571
C14: 77/1 | D14: DA+0 | E14: 1.57 | F14: 11.05 | O14: MT | P14: 20MM | S14: =S12*1600/1000 -> 129.528
C15: 77/4 | D15: DA+3 | E15: 1.86 | F15: 12.47 | O15: MT | P15: SAND | S15: =S13*1600/1000 -> 55.106513
C16: 79/1 | D16: DA+9 | E16: 1.86 | F16: 12.47
C17: 76/1 | D17: DA+6 | E17: 1.86 | F17: 12.47
C18: 85/1 | D18: DA+0 | E18: 1.57 | F18: 11.05 | O18: JP Enterprises
C19: 87/1 | D19: DA+3 | E19: 1.86 | F19: 12.47 | P19: 147/2 | Q19: DA+0 | R19: 1.57 | S19: 11.05
C20: 87/2 | D20: DA+9 | E20: 1.86 | F20: 12.47 | P20: 147/0 | Q20: DC+0 | R20: 1.6 | S20: 13.13
C21: 91/1 | D21: DA+0 | E21: 1.57 | F21: 11.05 | P21: 147/1 | Q21: DA+0 | R21: 1.57 | S21: 11.05
C22: 91/2 | D22: DA+0 | E22: 1.57 | F22: 11.05 | P22: 146/2 | Q22: DA+0 | R22: 1.57 | S22: 11.05
C23: 99/2 | D23: DA+0 | E23: 1.08 | F23: 8.68 | P23: 146/1 | Q23: DA+3 | R23: 1.86 | S23: 12.47
C24: 97/0 | D24: DC+0 | E24: 1.6 | F24: 13.13 | R24: =SUM(R19:R23) -> 8.17 | S24: =SUM(S19:S23) -> 58.75
C25: 82/2 | D25: DA+0 | E25: 1.57 | F25: 11.05 | P25: CUM | Q25: 20MM | R25: =R24*1.54*6/10 -> 7.54908 | S25: =S24*1.54*3/5.5 -> 49.35 | T25: =SUM(R25:S25) -> 56.89908
C26: 82/1 | D26: DA+6 | E26: 1.86 | F26: 12.47 | P26: CUM | Q26: SAND | R26: =R25*1.54*3/10 -> 3.487675 | S26: =S25*1.54*1.5/5.5 -> 20.727 | T26: =SUM(R26:S26) -> 24.214675
C27: 86/0 | D27: DD+0 | E27: 2.93 | F27: 20.34 | P27: MT | Q27: 20MM | T27: =T25*1600/1000 -> 91.038528
C28: 85/0 | D28: DC+0 | E28: 1.6 | F28: 13.13 | P28: MT | Q28: SAND | T28: =T26*1600/1000 -> 38.74348
E29: =SUM(E14:E28) -> 26.22 | F29: =SUM(F14:F28) -> 185.35 | U29: Balance
