Workbook
Name \0: #REF!
Name \0: #REF!
Name \A: #REF!
Name \A: #REF!
Name \B: #REF!
Name \B: #REF!
Name \C: #REF!
Name \c1: #REF!
Name \D: #REF!
Name \g: #REF!
Name \H: #REF!
Name \i: #REF!
Name \M: #REF!
Name \N: #REF!
Name \P: #REF!
Name \R: #REF!
Name \S: #REF!
Name \U: #REF!
Name \V: #REF!
Name \z: #REF!
Name _: "tcap"
Name _____________A65537: #REF!
Name _____________A65537: #REF!
Name ____________A655600: #REF!
Name ____________A655600: #REF!
Name ____________drg1: #REF!
Name ____________drg1: #REF!
Name ___________A65537: #REF!
Name ___________A65537: #REF!
Name ___________A655600: #REF!
Name ___________A655600: #REF!
Name ___________a655601: #REF!
Name ___________a655601: #REF!
Name __________A65537: #REF!
Name __________A65537: #REF!
Name __________A655600: #REF!
Name __________A655600: #REF!
Name __________a655601: #REF!
Name __________a655601: #REF!
Name __________a999999: #REF!
Name __________drg1: #REF!
Name __________drg1: #REF!
Name _________A65537: #REF!
Name _________A65537: #REF!
Name _________A655600: #REF!
Name _________A655600: #REF!
Name _________a655601: #REF!
Name _________a655601: #REF!
Name _________a999999: #REF!
Name ________A65537: #REF!
Name ________A65537: #REF!
Name ________A655600: #REF!
Name ________A655600: #REF!
Name ________A655600: #REF!
Name ________A655600: #REF!
Name ________A655600: #REF!
Name ________a655601: #REF!
Name ________a655601: #REF!
Name ________a655601: #REF!
Name ________a655601: #REF!

Sheet Detail Survey-220kV
A2: 220kV - Detailed Survey Progress
A3: Sl. No. | B3: LOC NO | C3: TowerType | D3: Deviation of Angle | E3: CP | F3: Leg Extension | J3: RC | K3: Chimney Extension | O3: Span Length (m) | P3: Section Length | Q3: Detail Survey completion status | T3: Detail Survey Report Submision | W3: Detail Survey Approval | Z3: Remarks
D4: DMS | E4: m | F4: A | G4: B | H4: C | I4: D | J4: m | K4: A | L4: B | M4: C | N4: D | O4: m | P4: m | Q4: Surveyed | R4: DOC | S4: Re-survey | T4: Submitted | U4: Date | V4: Re-submitted | W4: Approved | X4: Date | Y4: Re-apprpved
B5: GANTRY | C5: GANTRY | K5: 0 | L5: 0 | M5: 0 | N5: 0 | Q5: Completed
O6: 126.19 | Q6: Completed
A7: 1 | B7: 0/0 | C7: DD+0 | D7: 16° 50' 9"RT | K7: 0 | L7: 0 | M7: 0 | N7: 0 | P7: 126.19 | Q7: Completed
O8: 292 | Q8: Completed
A9: =IF(B9>0,A7+1," ") -> 2 | B9: 0/1 | C9: DA+3 | K9: 0 | L9: 0 | M9: 0 | N9: 0 | Q9: Completed
A10: =IF(B10>0,A8+1," ") | O10: 360.47 | Q10: Completed
A11: =IF(B11>0,A9+1," ") -> 3 | B11: 1/0 | C11: DC+0 | D11: 15° 52' 12"RT | K11: 0 | L11: 0 | M11: 0 | N11: 0 | P11: 652.47 | Q11: Completed
A12: =IF(B12>0,A10+1," ") | O12: 293 | Q12: Completed
A13: =IF(B13>0,A11+1," ") -> 4 | B13: 1/1 | C13: DA+0 | K13: 0 | L13: 0 | M13: 0 | N13: 0 | Q13: Completed
A14: =IF(B14>0,A12+1," ") | O14: 390.88 | Q14: Completed
A15: =IF(B15>0,A13+1," ") -> 5 | B15: 1/2 | C15: DA+3 | D15: 19° 5' 19"LT | K15: 0 | L15: 0 | M15: 0 | N15: 0 | P15: 683.88 | Q15: Completed | T15: Submitted | V15: 45533 | W15: Approved | X15: 45545
A16: =IF(B16>0,A14+1," ") | O16: 351 | Q16: Completed | T16: Submitted | V16: 45533 | W16: Approved | X16: 45545
A17: =IF(B17>0,A15+1," ") -> 6 | B17: 1A/0 | C17: DC+3 | K17: 0 | L17: 0 | M17: 0 | N17: 0 | Q17: Completed | T17: Submitted | V17: 45533 | W17: Approved | X17: 45545
A18: =IF(B18>0,A16+1," ") | O18: 258 | Q18: Completed | T18: Submitted | V18: 45533 | W18: Approved | X18: 45545
A19: =IF(B19>0,A17+1," ") -> 7 | B19: 1A/1 | C19: DA+3 | K19: 0 | L19: 0 | M19: 0 | N19: 0 | Q19: Completed | T19: Submitted | V19: 45533 | W19: Approved | X19: 45545
A20: =IF(B20>0,A18+1," ") | O20: 322.492 | Q20: Completed | T20: Submitted | V20: 45533 | W20: Approved | X20: 45545
A21: =IF(B21>0,A19+1," ") -> 8 | B21: 1A/2 | C21: DC+0 | D21: 57° 12' 54"LT | K21: 0 | L21: 0 | M21: 0 | N21: 0 | P21: 930.56 | Q21: Completed | T21: Submitted | V21: 45533 | W21: Approved | X21: 45545
A22: =IF(B22>0,A20+1," ") | O22: 248 | Q22: Completed | T22: Submitted | V22: 45533 | W22: Approved | X22: 45545
A23: =IF(B23>0,A21+1," ") -> 9 | B23: 1B/0 | C23: DD+3 | D23: 44° 32' 20"RT | K23: 0 | L23: 0 | M23: 0 | N23: 0 | P23: 249.73 | Q23: Completed | T23: Submitted | V23: 45533 | W23: Approved | X23: 45545
A24: =IF(B24>0,A22+1," ") | O24: 294 | Q24: Completed | T24: Submitted | V24: 45533 | W24: Approved | X24: 45545
A25: =IF(B25>0,A23+1," ") -> 10 | B25: 1C/0 | C25: DD+9 | K25: 0 | L25: 0 | M25: 0 | N25: 0 | Q25: Completed | T25: Submitted | V25: 45533 | W25: Approved | X25: 45545
A26: =IF(B26>0,A24+1," ") | O26: 294.431 | Q26: Completed | T26: Submitted | V26: 45533 | W26: Approved | X26: 45545
A27: =IF(B27>0,A25+1," ") -> 11 | B27: 1C/1 | C27: DA+6 | D27: 28° 26' 27"RT | K27: 0 | L27: 0 | M27: 0 | N27: 0 | P27: 588.43 | Q27: Completed | T27: Submitted | V27: 45533 | W27: Approved | X27: 45545
A28: =IF(B28>0,A26+1," ") | O28: 306 | Q28: Completed | T28: Submitted | V28: 45533 | W28: Approved | X28: 45545
A29: =IF(B29>0,A27+1," ") -> 12 | B29: 1D/0 | C29: DC+0 | K29: 0 | L29: 0 | M29: 0 | N29: 0 | Q29: Completed | T29: Submitted | V29: 45533 | W29: Approved | X29: 45545
A30: =IF(B30>0,A28+1," ") | O30: 393.921 | Q30: Completed | T30: Submitted | V30: 45533 | W30: Approved | X30: 45545
A31: =IF(B31>0,A29+1," ") -> 13 | B31: 1D/1 | C31: DA+0 | D31: 42° 49' 3"RT | K31: 0 | L31: 0 | M31: 0 | N31: 0 | P31: 699.92 | Q31: Completed | T31: Submitted | V31: 45533 | W31: Approved | X31: 45545
A32: =IF(B32>0,A30+1," ") | O32: 356.664 | Q32: Completed | T32: Submitted | V32: 45533 | W32: Approved | X32: 45545
A33: =IF(B33>0,A31+1," ") -> 14 | B33: 1E/0 | C33: DD+6 | D33: 27° 13' 43"RT | K33: 0 | L33: 0 | M33: 0 | N33: 0 | P33: 356.66 | Q33: Completed | T33: Submitted | V33: 45533 | W33: Approved | X33: 45545
A34: =IF(B34>0,A32+1," ") | O34: 174.205 | Q34: Completed | T34: Submitted | V34: 45533 | W34: Approved | X34: 45545
A35: =IF(B35>0,A33+1," ") -> 15 | B35: 2/0 | C35: DC+6 | D35: 49° 56' 13"RT | K35: 0 | L35: 0 | M35: 0 | N35: 0 | P35: 174.21 | Q35: Completed | T35: Submitted | V35: 45533 | W35: Approved | X35: 45545
A36: =IF(B36>0,A34+1," ") | O36: 229.73 | Q36: Completed | T36: Submitted | V36: 45533 | W36: Approved | X36: 45545
A37: =IF(B37>0,A35+1," ") -> 16 | B37: 3/0 | C37: DD+3 | D37: 7° 56' 47"LT | K37: 0 | L37: 0 | M37: 0 | N37: 0 | P37: 229.73 | Q37: Completed | T37: Submitted | V37: 45533 | W37: Approved | X37: 45545
A38: =IF(B38>0,A36+1," ") | O38: 391 | Q38: Completed | T38: Submitted | V38: 45533 | W38: Approved | X38: 45545
A39: =IF(B39>0,A37+1," ") -> 17 | B39: 4/0 | C39: DB+9 | K39: 0 | L39: 0 | M39: 0 | N39: 0 | Q39: Completed | T39: Submitted | V39: 45533 | W39: Approved | X39: 45545
A40: =IF(B40>0,A38+1," ") | O40: 328 | Q40: Completed | T40: Submitted | V40: 45533 | W40: Approved | X40: 45545
A41: =IF(B41>0,A39+1," ") -> 18 | B41: 4/1 | C41: DA+6 | K41: 0 | L41: 0 | M41: 0 | N41: 0 | Q41: Completed | T41: Submitted | V41: 45533 | W41: Approved | X41: 45545
...

Sheet Check Survey-220kV
A1: =+Summary!A2 -> Name of the Line: 220KV DC AL59 line from Neemuch - Chanderiya + 132KV DC ACSS Line from Chanderiya to Hindustan Zinc
A2: 220kV - Check Survey Progress
A3: Sl. No. | B3: LOC NO | C3: TowerType | D3: Deviation of Angle | E3: CP | F3: Leg Extension | J3: RC | K3: Chimney Extension | O3: Span Length (m) | P3: Section Length | Q3: Detail Survey completion status | T3: Detail Survey Report Submision | W3: Detail Survey Approval | Z3: Remarks
D4: DMS | E4: m | F4: A | G4: B | H4: C | I4: D | J4: m | K4: A | L4: B | M4: C | N4: D | O4: m | P4: m | Q4: Surveyed | R4: DOC | S4: Re-survey | T4: Submitted | U4: Date | V4: Re-submitted | W4: Approved | X4: Date | Y4: Re-apprpved
B5: GANTRY | C5: GANTRY | K5: 0 | L5: 0 | M5: 0 | N5: 0
O6: 47
A7: 1 | B7: 0/0 | C7: DD+0 | D7: 16° 50' 9"RT | K7: 0 | L7: 0 | M7: 0 | N7: 0 | P7: 126.19
O8: 196
A9: =IF(B9>0,A7+1," ") -> 2 | B9: 0/1 | C9: DA+3 | K9: 0 | L9: 0 | M9: 0 | N9: 0
A10: =IF(B10>0,A8+1," ") | O10: 196.743
A11: =IF(B11>0,A9+1," ") -> 3 | B11: 1/0 | C11: DC+0 | D11: 15° 52' 12"RT | K11: 0 | L11: 0 | M11: 0 | N11: 0 | P11: 652.47 | W11: Approved
A12: =IF(B12>0,A10+1," ") | O12: 334 | W12: Approved
A13: =IF(B13>0,A11+1," ") -> 4 | B13: 1/1 | C13: DA+0 | K13: 0 | L13: 0 | M13: 0 | N13: 0 | W13: Approved
A14: =IF(B14>0,A12+1," ") | O14: 319 | W14: Approved
B15: 1/2 | C15: DA+3
O16: 384.318
A17: =IF(B17>0,A13+1," ") -> 5 | B17: 1A/0 | C17: DC+3 | D17: 18° 59' 57"LT | K17: 0 | L17: 0 | M17: 0 | N17: 0 | P17: 683.88 | W17: Approved
A18: =IF(B18>0,A14+1," ") | O18: 329 | W18: Approved
A19: =IF(B19>0,A17+1," ") -> 6 | B19: 1A/1 | C19: DA+3 | K19: 0 | L19: 0 | M19: 0 | N19: 0 | W19: Approved
A20: =IF(B20>0,A18+1," ") | O20: 280 | W20: Approved
A21: =IF(B21>0,A19+1," ") -> 7 | B21: 1A/2 | C21: DC+0 | K21: 0 | L21: 0 | M21: 0 | N21: 0 | W21: Approved
A22: =IF(B22>0,A20+1," ") | O22: 232.098 | W22: Approved
A23: =IF(B23>0,A21+1," ") -> 8 | B23: 1B/0 | C23: DD+3 | D23: 57° 18' 17"LT | K23: 0 | L23: 0 | M23: 0 | N23: 0 | P23: 930.56 | W23: Approved
A24: =IF(B24>0,A22+1," ") | O24: 237.783 | W24: Approved
A25: =IF(B25>0,A23+1," ") -> 9 | B25: 1C/0 | C25: DD+9 | D25: 44° 32' 20"RT | K25: 0 | L25: 0 | M25: 0 | N25: 0 | P25: 249.73 | W25: Approved
A26: =IF(B26>0,A24+1," ") | O26: 334 | W26: Approved
A27: =IF(B27>0,A25+1," ") -> 10 | B27: 1C/1 | C27: DA+6 | K27: 0 | L27: 0 | M27: 0 | N27: 0 | W27: Approved
A28: =IF(B28>0,A26+1," ") | O28: 341.209 | W28: Approved
A29: =IF(B29>0,A27+1," ") -> 11 | B29: 1D/0 | C29: DC+0 | D29: 28° 26' 27"RT | K29: 0 | L29: 0 | M29: 0 | N29: 0 | P29: 588.43 | W29: Approved
A30: =IF(B30>0,A28+1," ") | O30: 306.001 | W30: Approved
A31: =IF(B31>0,A29+1," ") -> 12 | B31: 1D/1 | C31: DA+0 | K31: 0 | L31: 0 | M31: 0 | N31: 0 | W31: Approved
A32: =IF(B32>0,A30+1," ") | O32: 393.92 | W32: Approved
A33: =IF(B33>0,A31+1," ") -> 13 | B33: 1E/0 | C33: DD+6 | D33: 42° 49' 3"RT | K33: 0 | L33: 0 | M33: 0 | N33: 0 | P33: 699.92 | W33: Approved
A34: =IF(B34>0,A32+1," ") | O34: 356.664 | W34: Approved
A35: =IF(B35>0,A33+1," ") -> 14 | B35: 2/0 | C35: DC+6 | D35: 27° 13' 43"RT | K35: 0 | L35: 0 | M35: 0 | N35: 0 | P35: 356.66 | W35: Approved
A36: =IF(B36>0,A34+1," ") | O36: 174.205 | W36: Approved
A37: =IF(B37>0,A35+1," ") -> 15 | B37: 3/0 | C37: DD+3 | D37: 49° 56' 13"RT | K37: 0 | L37: 0 | M37: 0 | N37: 0 | P37: 174.21 | W37: Approved
A38: =IF(B38>0,A36+1," ") | O38: 229.73 | W38: Approved
A39: =IF(B39>0,A37+1," ") -> 16 | B39: 4/0 | C39: DB+9 | D39: 7° 56' 47"LT | K39: 0 | L39: 0 | M39: 0 | N39: 0 | P39: 229.73 | W39: Approved
A40: =IF(B40>0,A38+1," ") | O40: 391 | W40: Approved
...

Sheet Detail Survey-132kV
A1: =+Summary!A2 -> Name of the Line: 220KV DC AL59 line from Neemuch - Chanderiya + 132KV DC ACSS Line from Chanderiya to Hindustan Zinc
A2: 132kV - Detailed Survey Progress
A3: Sl. No. | B3: LOC NO | C3: TowerType | D3: Deviation of Angle | E3: CP | F3: Leg Extension | J3: RC | K3: Chimney Extension | O3: Span Length (m) | P3: Section Length | Q3: Detail Survey completion status | T3: Detail Survey Report Submision | W3: Detail Survey Approval | Z3: Remarks
D4: DMS | E4: m | F4: A | G4: B | H4: C | I4: D | J4: m | K4: A | L4: B | M4: C | N4: D | O4: m | P4: m | Q4: Surveyed | R4: DOC | S4: Re-survey | T4: Submitted | U4: Date | V4: Re-submitted | W4: Approved | X4: Date | Y4: Re-apprpved
B5: Tapping Tower | C5: DD+0 | D5: 2° 10' 33"LT | F5: 0 | G5: 0 | H5: 0 | I5: 0 | K5: 0 | L5: 0 | M5: 0 | N5: 0 | Q5: Completed
O6: 25.917 | Q6: Completed
A7: 1 | B7: DE | C7: DD+0 | D7: 44° 51' 5"RT | F7: 0 | G7: 0 | H7: 0 | I7: 0 | K7: 0 | L7: 0 | M7: 0 | N7: 0 | P7: 25.92 | Q7: Completed
O8: 261.985 | Q8: Completed
A9: =IF(B9>0,A7+1," ") -> 2 | B9: 1/0 | C9: DB+0 | D9: 6° 49' 55"RT | F9: 0 | G9: 0 | H9: 0 | I9: 0 | K9: 0 | L9: 0 | M9: 0 | N9: 0 | P9: 261.99 | Q9: Completed
A10: =IF(B10>0,A8+1," ") | O10: 339.331 | Q10: Completed
A11: =IF(B11>0,A9+1," ") -> 3 | B11: 2/0 | C11: DC+6 | D11: 26° 16' 38"LT | F11: 0 | G11: 0 | H11: 0 | I11: 0 | K11: 0 | L11: 0 | M11: 0 | N11: 0 | P11: 339.33 | Q11: Completed
A12: =IF(B12>0,A10+1," ") | O12: 379.175 | Q12: Completed
A13: =IF(B13>0,A11+1," ") -> 4 | B13: 3/0 | C13: DB+6 | D13: 13° 55' 42"RT | F13: 0 | G13: 0 | H13: 0 | I13: 0 | K13: 0 | L13: 0 | M13: 0 | N13: 0 | P13: 379.18 | Q13: Completed
A14: =IF(B14>0,A12+1," ") | O14: 238 | Q14: Completed
A15: =IF(B15>0,A13+1," ") -> 5 | B15: 3/1 | C15: DA+6 | F15: 0 | G15: 0 | H15: 0 | I15: 0 | K15: 0 | L15: 0 | M15: 0 | N15: 0 | Q15: Completed | T15: Submitted | V15: 45533 | W15: Approved | X15: 45545
A16: =IF(B16>0,A14+1," ") | O16: 260 | Q16: Completed | T16: Submitted | V16: 45533 | W16: Approved | X16: 45545
A17: =IF(B17>0,A15+1," ") -> 6 | B17: 3/2 | C17: DA+3 | F17: 0 | G17: 0 | H17: 0 | I17: 0 | K17: 0 | L17: 0 | M17: 0 | N17: 0 | Q17: Completed | T17: Submitted | V17: 45533 | W17: Approved | X17: 45545
A18: =IF(B18>0,A16+1," ") | O18: 256.018 | Q18: Completed | T18: Submitted | V18: 45533 | W18: Approved | X18: 45545
A19: =IF(B19>0,A17+1," ") -> 7 | B19: 4/0 | C19: DB+0 | D19: 2° 10' 59"RT | F19: 0 | G19: 0 | H19: 0 | I19: 0 | K19: 0 | L19: 0 | M19: 0 | N19: 0 | P19: 754.02 | Q19: Completed | T19: Submitted | V19: 45533 | W19: Approved | X19: 45545
A20: =IF(B20>0,A18+1," ") | O20: 321.753 | Q20: Completed | T20: Submitted | V20: 45533 | W20: Approved | X20: 45545
A21: =IF(B21>0,A19+1," ") -> 8 | B21: 4/1 | C21: DB+0 | F21: 0 | G21: 0 | H21: 0 | I21: 0 | K21: 0 | L21: 0 | M21: 0 | N21: 0 | P21: 321.75 | Q21: Completed | T21: Submitted | V21: 45533 | W21: Approved | X21: 45545
A22: =IF(B22>0,A20+1," ") | O22: 161.247 | Q22: Completed | T22: Submitted | V22: 45533 | W22: Approved | X22: 45545
A23: =IF(B23>0,A21+1," ") -> 9 | B23: 4/2 | C23: DA+3 | F23: 0 | G23: 0 | H23: 0 | I23: 0 | K23: 0 | L23: 0 | M23: 0 | N23: 0 | Q23: Completed | T23: Submitted | V23: 45533 | W23: Approved | X23: 45545
A24: =IF(B24>0,A22+1," ") | O24: 327.381 | Q24: Completed | T24: Submitted | V24: 45533 | W24: Approved | X24: 45545
A25: =IF(B25>0,A23+1," ") -> 10 | B25: 5/0 | C25: DD+3 | D25: 23° 16' 52"RT | F25: 0 | G25: 0 | H25: 0 | I25: 0 | K25: 0 | L25: 0 | M25: 0 | N25: 0 | P25: 488.63 | Q25: Completed | T25: Submitted | V25: 45533 | W25: Approved | X25: 45545
A26: =IF(B26>0,A24+1," ") | O26: 36.276 | Q26: Completed | T26: Submitted | V26: 45533 | W26: Approved | X26: 45545
A27: =IF(B27>0,A25+1," ") -> 11 | B27: 5/1 | C27: GANTRY UC (+2M) | F27: 0 | G27: 0 | H27: 0 | I27: 0 | K27: 0 | L27: 0 | M27: 0 | N27: 0 | P27: 29 | Q27: Completed | T27: Submitted | V27: 45533 | W27: Approved | X27: 45545
A28: =IF(B28>0,A26+1," ") | O28: 61.139 | Q28: Completed | T28: Submitted | V28: 45533 | W28: Approved | X28: 45545
A29: =IF(B29>0,A27+1," ") -> 12 | B29: 5/2 | C29: GANTRY UC (+2M) | F29: 0 | G29: 0 | H29: 0 | I29: 0 | K29: 0 | L29: 0 | M29: 0 | N29: 0 | P29: 81 | Q29: Completed | T29: Submitted | V29: 45533 | W29: Approved | X29: 45545
A30: =IF(B30>0,A28+1," ") | O30: 38.566 | Q30: Completed | T30: Submitted | V30: 45533 | W30: Approved | X30: 45545
A31: =IF(B31>0,A29+1," ") -> 13 | B31: 6/0 | C31: DD+0 | D31: 25° 0' 0"LT | F31: 0 | G31: 0 | H31: 0 | I31: 0 | K31: 0 | L31: 0 | M31: 0 | N31: 0 | P31: 25.98 | Q31: Completed | T31: Submitted | V31: 45533 | W31: Approved | X31: 45545
A32: =IF(B32>0,A30+1," ") | O32: 182.043 | Q32: Completed | T32: Submitted | V32: 45533 | W32: Approved | X32: 45545
A33: =IF(B33>0,A31+1," ") -> 14 | B33: 6A/0 | C33: DD+0 | D33: 53° 55' 29"LT | F33: 0 | G33: 0 | H33: 0 | I33: 0 | K33: 0 | L33: 0 | M33: 0 | N33: 0 | P33: 182.04 | Q33: Completed | T33: Submitted | V33: 45533 | W33: Approved | X33: 45545
A34: =IF(B34>0,A32+1," ") | O34: 204.148 | Q34: Completed | T34: Submitted | V34: 45533 | W34: Approved | X34: 45545
A35: =IF(B35>0,A33+1," ") -> 15 | B35: 7/0 | C35: DB+0 | D35: 12° 53' 30"LT | F35: 0 | G35: 0 | H35: 0 | I35: 0 | K35: 0 | L35: 0 | M35: 0 | N35: 0 | P35: 204.15 | Q35: Completed | T35: Submitted | V35: 45533 | W35: Approved | X35: 45545
A36: =IF(B36>0,A34+1," ") | O36: 254 | Q36: Completed | T36: Submitted | V36: 45533 | W36: Approved | X36: 45545
A37: =IF(B37>0,A35+1," ") -> 16 | B37: 7/1 | C37: DA+3 | F37: 0 | G37: 0 | H37: 0 | I37: 0 | K37: 0 | L37: 0 | M37: 0 | N37: 0 | Q37: Completed | T37: Submitted | V37: 45533 | W37: Approved | X37: 45545
A38: =IF(B38>0,A36+1," ") | O38: 294 | Q38: Completed | T38: Submitted | V38: 45533 | W38: Approved | X38: 45545
A39: =IF(B39>0,A37+1," ") -> 17 | B39: 7/2 | C39: DA+3 | F39: 0 | G39: 0 | H39: 0 | I39: 0 | K39: 0 | L39: 0 | M39: 0 | N39: 0 | Q39: Completed | T39: Submitted | V39: 45533 | W39: Approved | X39: 45545
A40: =IF(B40>0,A38+1," ") | O40: 249.824 | Q40: Completed | T40: Submitted | V40: 45533 | W40: Approved | X40: 45545
...

Sheet Check Survey-132kV
A1: =+Summary!A2 -> Name of the Line: 220KV DC AL59 line from Neemuch - Chanderiya + 132KV DC ACSS Line from Chanderiya to Hindustan Zinc
A2: 220kV - Check Survey Progress
A3: Sl. No. | B3: LOC NO | C3: TowerType | D3: Deviation of Angle | E3: CP | F3: Leg Extension | J3: RC | K3: Chimney Extension | O3: Span Length (m) | P3: Section Length | Q3: Detail Survey completion status | T3: Detail Survey Report Submision | W3: Detail Survey Approval | Z3: Remarks
D4: DMS | E4: m | F4: A | G4: B | H4: C | I4: D | J4: m | K4: A | L4: B | M4: C | N4: D | O4: m | P4: m | Q4: Surveyed | R4: DOC | S4: Re-survey | T4: Submitted | U4: Date | V4: Re-submitted | W4: Approved | X4: Date | Y4: Re-apprpved
B5: GANTRY | C5: GANTRY | K5: 0 | L5: 0 | M5: 0 | N5: 0
A6: =IF(B6>0,#REF!+1," ") -> #REF! | B6: 1/0 | C6: DE+0 | D6: 42° 49' 3"RT | K6: 0 | L6: 0 | M6: 0 | N6: 0 | P6: 699.92
A7: =IF(B7>0,#REF!+1," ") | O7: 230.15
A8: =IF(B8>0,A6+1," ") -> #REF! | B8: 2/0 | C8: DB+0 | D8: 27° 13' 43"RT | K8: 0 | L8: 0 | M8: 0 | N8: 0 | P8: 356.66
A9: =IF(B9>0,A7+1," ") | O9: 234.56
A10: =IF(B10>0,A8+1," ") -> #REF! | B10: 2/1 | C10: DB+6 | D10: 49° 56' 13"RT | K10: 0 | L10: 0 | M10: 0 | N10: 0 | P10: 174.21
A11: =IF(B11>0,A9+1," ") | O11: 251.12
A12: =IF(B12>0,A10+1," ") -> #REF! | B12: 3/0 | C12: DD+0 | D12: 7° 56' 47"LT | K12: 0 | L12: 0 | M12: 0 | N12: 0
A13: =IF(B13>0,A11+1," ") | O13: 183
A14: =IF(B14>0,A12+1," ") -> #REF! | B14: 3/1 | C14: DA+3 | K14: 0 | L14: 0 | M14: 0 | N14: 0 | P14: 321.75
A15: =IF(B15>0,A13+1," ") | O15: 182.07
A16: =IF(B16>0,A14+1," ") -> #REF! | B16: 4/0 | C16: DC+0 | K16: 0 | L16: 0 | M16: 0 | N16: 0
A17: =IF(B17>0,A15+1," ") | O17: 328.09
A18: =IF(B18>0,A16+1," ") -> #REF! | B18: 5/0 | C18: DD+3 | K18: 0 | L18: 0 | M18: 0 | N18: 0 | P18: 488.63 | Q18: Completed | W18: Approved
A19: =IF(B19>0,A17+1," ") | O19: 40 | Q19: Completed | W19: Approved
A20: =IF(B20>0,A18+1," ") -> #REF! | B20: 5/1 | C20: GANTRY UC (+2M) | K20: 0 | L20: 0 | M20: 0 | N20: 0 | P20: 40 | Q20: Completed | W20: Approved
A21: =IF(B21>0,A19+1," ") | O21: 57.415 | Q21: Completed | W21: Approved
A22: =IF(B22>0,A20+1," ") -> #REF! | B22: 5/2 | C22: GANTRY UC (+2M) | K22: 0 | L22: 0 | M22: 0 | N22: 0 | P22: 57.42 | Q22: Completed | W22: Approved
A23: =IF(B23>0,A21+1," ") | O23: 38.566 | Q23: Completed | W23: Approved
A24: =IF(B24>0,A22+1," ") -> #REF! | B24: 6/0 | C24: DD+0 | K24: 0 | L24: 0 | M24: 0 | N24: 0 | P24: 38.57 | Q24: Completed | W24: Approved
A25: =IF(B25>0,A23+1," ") | O25: 182.043 | Q25: Completed | W25: Approved
A26: =IF(B26>0,A24+1," ") -> #REF! | B26: 6A/0 | C26: DD+0 | K26: 0 | L26: 0 | M26: 0 | N26: 0 | P26: 182.04 | Q26: Completed | W26: Approved
A27: =IF(B27>0,A25+1," ") | O27: 204.148 | Q27: Completed | W27: Approved
A28: =IF(B28>0,A26+1," ") -> #REF! | B28: 7/0 | C28: DB+0 | K28: 0 | L28: 0 | M28: 0 | N28: 0 | P28: 204.15 | Q28: Completed | W28: Approved
A29: =IF(B29>0,A27+1," ") | O29: 230 | Q29: Completed | W29: Approved
A30: =IF(B30>0,A28+1," ") -> #REF! | B30: 7/1 | C30: DA+3 | K30: 0 | L30: 0 | M30: 0 | N30: 0 | Q30: Completed | W30: Approved
A31: =IF(B31>0,A29+1," ") | O31: 294 | Q31: Completed | W31: Approved
A32: =IF(B32>0,A30+1," ") -> #REF! | B32: 7/2 | C32: DA+3 | J32: 1 | K32: 1 | L32: 1 | M32: 1 | N32: 1 | Q32: Completed | W32: Approved
A33: =IF(B33>0,A31+1," ") | O33: 249.82 | Q33: Completed | W33: Approved
A34: =IF(B34>0,A32+1," ") -> #REF! | B34: 8/0 | C34: DD+3 | K34: 0 | L34: 0 | M34: 0 | N34: 0 | Q34: Completed | W34: Approved
A35: =IF(B35>0,A33+1," ") | O35: 329.66 | Q35: Completed | W35: Approved
A36: =IF(B36>0,A34+1," ") -> #REF! | B36: 9/0 | C36: DD+3 | K36: 0 | L36: 0 | M36: 0 | N36: 0 | Q36: Completed | W36: Approved
A37: =IF(B37>0,A35+1," ") | O37: 170 | Q37: Completed | W37: Approved
A38: =IF(B38>0,A36+1," ") -> #REF! | B38: 9/1 | C38: DA+6 | K38: 0 | L38: 0 | M38: 0 | N38: 0 | Q38: Completed | W38: Approved
A39: =IF(B39>0,A37+1," ") | O39: 312 | Q39: Completed | W39: Approved
A40: =IF(B40>0,A38+1," ") -> #REF! | B40: 9/2 | C40: DA+6 | K40: 0 | L40: 0 | M40: 0 | N40: 0 | Q40: Completed | W40: Approved
...

Sheet Summary
A1: Client: M/S STERLITE POWER TRANSMISSION LIMITED
A2: Name of the Line: 220KV DC AL59 line from Neemuch - Chanderiya + 132KV DC ACSS Line from Chanderiya to Hindustan Zinc | O2: Contractual Start Date : | R2: 45449
A3: Name of Document : Daily Progress Report (DPR) | O3: Contractual Completion Date: | R3: 45802
A4: Office: Neemuch | O4: Revised Completion Date : | R4: 46022
A5: Progress of 220kV Line | Q5: Date: | R5: 46030
A6: Sr. No. | B6: Activity | C6: UoM | D6: Total Quantity | E6: As per L2 | G6: Cumm. Progress up to last Month | I6: Progress of Current Month (Jan'26) | L6: Cumulative till current month | O6: Resources Status | R6: Critical Issues, if any & Remark
E7: Start Date | F7: End Date | G7: L2 | H7: Actual | I7: Plan | J7: Today | K7: Progress in Month | L7: Target (L2) | M7: Completed | N7: Balance | O7: Targeted Gang | P7: Available Gang | Q7: Shortfall Gang
A8: 1 | B8: Detailed Survey | C8: Kms | D8: 64 | E8: 45461 | F8: 45535 | G8: 69.18 | H8: 64.178 | I8: 0 | J8: 0 | K8: =M8-H8 -> 0 | L8: 69.18 | M8: 64.178 | N8: =D8-M8 -> -0.178 | O8: 0 | P8: 0 | Q8: =+O8-P8 -> 0
A9: 2 | B9: Check Survey | C9: Kms | D9: 64 | E9: 45474 | F9: 45565 | G9: 69.18 | H9: =H8 -> 64.178 | I9: 0 | J9: 0 | K9: =M9-H9 -> 0 | L9: 69.18 | M9: =M8 -> 64.178 | N9: =D9-M9 -> -0.178 | Q9: =+O9-P9 -> 0
A10: 3 | B10: Foundation | C10: Nos. | D10: 201 | E10: 45505 | F10: 45688 | G10: 184 | H10: 196 | I10: 1 | J10: 0 | K10: =M10-H10 -> 0 | L10: 184 | M10: ='Progress-220kV'!AM405 -> 196 | N10: =D10-M10 -> 5 | O10: 0 | P10: 0 | Q10: =+O10-P10 -> 0 | R10: NH approval Pending for 1C/0 Route Approval pending at Neemuch bay
A11: 4 | B11: Earthing | C11: Nos. | D11: 201 | E11: 45505 | F11: 45688 | G11: 184 | H11: 196 | I11: 1 | J11: 0 | K11: =M11-H11 -> 0 | L11: 184 | M11: ='Progress-220kV'!AV405 -> 196 | N11: =D11-M11 -> 5
A12: 5 | B12: Tower Erection | C12: Nos. | D12: 201 | E12: 45555 | F12: 45716 | G12: 184 | H12: 195 | I12: 2 | J12: 0 | K12: =M12-H12 -> 0 | L12: 184 | M12: ='Progress-220kV'!BB405 -> 195 | N12: =D12-M12 -> 6 | O12: 0 | P12: 0 | Q12: =+O12-P12 -> 0 | AQ12: 12500
A13: 6 | B13: Tack Welding | C13: Nos. | D13: 201 | E13: 45555 | F13: 45716 | G13: 184 | H13: 167 | I13: 26 | J13: 0 | K13: =M13-H13 -> 0 | L13: 184 | M13: 167 | N13: =D13-M13 -> 34 | O13: 1 | P13: 0 | Q13: =+O13-P13 -> 1
A14: 7 | B14: Stringing | C14: Kms | K14: =M14-H14 -> 0 | AQ14: =9 -> 9
A15: i | B15: Paying Out | C15: Kms | D15: 64 | E15: 45607 | F15: 45777 | G15: 64 | H15: 54.1 | I15: 10 | J15: 0 | K15: =M15-H15 -> 0.011128 | L15: 64 | M15: ='Stringing-220kV'!I3 -> 54.111128 | N15: =D15-M15 -> 9.888872 | O15: 2 | P15: 1 | Q15: =+O15-P15 -> 1 | AQ15: 15
A16: ii | B16: Final Sag | C16: Kms | D16: 64 | E16: 45607 | F16: 45777 | G16: 64 | H16: 54.1 | I16: 10 | J16: 0 | K16: =M16-H16 -> 0.011128 | L16: 64 | M16: ='Stringing-220kV'!L3 -> 54.111128 | N16: =D16-M16 -> 9.888872
A17: iii | B17: OPGW | C17: Kms | D17: 64 | E17: 45627 | F17: 45777 | G17: 64 | H17: 39.3 | I17: 15 | J17: 0 | K17: =M17-H17 -> 0.001041 | L17: 64 | M17: ='Stringing-220kV'!Y3 -> 39.301041 | N17: =D17-M17 -> 24.698959 | O17: 1 | P17: 0 | Q17: =+O17-P17 -> 1
A19: Progress of 132kV Line | Q19: Date: | R19: =+R5 -> 46030
A20: Sr. No. | B20: Activity | C20: UoM | D20: Total Quantity | E20: As per L2 | G20: Cumm. Progress up to last Month | I20: =+I6 -> Progress of Current Month (Jan'26) | L20: Cumulative till current month | O20: Resources Status | R20: Critical Issues, if any & Remark
E21: Start Date | F21: End Date | G21: L2 | H21: Actual | I21: Plan | J21: Today | K21: Progress in Month | L21: Target (L2) | M21: Completed | N21: Balance | O21: Targeted Gang | P21: Available Gang | Q21: Shortfall Gang
A22: 1 | B22: Detailed Survey | C22: Kms | D22: 8.18 | E22: 45461 | F22: 45535 | G22: 9 | H22: 8.18 | J22: 0 | K22: =M22-H22 -> 0 | L22: =+G22+I22 -> 9 | M22: 8.18 | N22: =D22-M22 -> 0 | Q22: =+O22-P22 -> 0 | R22: Detailed survey completed at site.
A23: 2 | B23: Check Survey | C23: Kms | D23: 8.18 | E23: 45474 | F23: 45565 | G23: 9 | H23: 8.18 | J23: 0 | K23: =M23-H23 -> 0 | L23: =+G23+I23 -> 9 | M23: 8.18 | N23: =D23-M23 -> 0 | Q23: =+O23-P23 -> 0
A24: 3 | B24: Foundation | C24: Nos. | D24: 35 | E24: 45505 | F24: 45688 | G24: 34 | H24: 13 | I24: 9 | J24: 0 | K24: =M24-H24 -> 0 | L24: 35 | M24: ='Progress-132kV'!AF79 -> 13 | N24: =D24-M24 -> 22 | O24: 2 | P24: 2 | Q24: =+O24-P24 -> 0 | R24: 12/1 Excavation U/P 13/1 Prop setting ,PCC U/P 13/2 RCC U/P
A25: 4 | B25: Earthing | C25: Nos. | D25: 35 | E25: 45505 | F25: 45688 | G25: 34 | H25: 10 | I25: 9 | J25: 3 | K25: =M25-H25 -> 3 | L25: 35 | M25: 13 | N25: =D25-M25 -> 22
A26: 5 | B26: Tower Erection | C26: Nos. | D26: 35 | E26: 45555 | F26: 45716 | G26: 34 | H26: 8 | I26: 8 | J26: 1 | K26: =M26-H26 -> 3 | L26: 35 | M26: ='Progress-132kV'!AQ79 -> 11 | N26: =D26-M26 -> 24 | O26: 1 | P26: 1 | Q26: =+O26-P26 -> 0 | R26: 12/0 Erection Completed
A27: 6 | B27: Tack Welding | C27: Nos. | D27: 35 | E27: 45555 | F27: 45716 | G27: 34 | H27: 0 | I27: 5 | J27: 0 | K27: =M27-H27 -> 0 | L27: 35 | N27: =D27-M27 -> 35 | Q27: =+O27-P27 -> 0
A28: 7 | B28: Stringing | J28: 0 | K28: =M28-H28 -> 0
A29: i | B29: Paying Out | C29: Kms | D29: 9 | E29: 45607 | F29: 45777 | G29: 0 | H29: 0 | J29: 0 | K29: =M29-H29 -> 0 | L29: =+G29+I29 -> 0 | N29: =D29-M29 -> 9 | Q29: =+O29-P29 -> 0
A30: ii | B30: Final Sag | C30: Kms | D30: 9 | E30: 45607 | F30: 45777 | G30: 0 | H30: 0 | J30: 0 | K30: =M30-H30 -> 0 | L30: =+G30+I30 -> 0 | N30: =D30-M30 -> 9
A31: iii | B31: OPGW | C31: Kms | D31: 9 | E31: 45627 | F31: 45777 | G31: 0 | H31: 0 | J31: 0 | K31: =M31-H31 -> 0 | L31: =+G31+I31 -> 0 | N31: =D31-M31 -> 9 | Q31: =+O31-P31 -> 0

Sheet Statutory
A1: =+Summary!A2 -> Name of the Line: 220KV DC AL59 line from Neemuch - Chanderiya + 132KV DC ACSS Line from Chanderiya to Hindustan Zinc
A2: SI No | B2: Name of Existing Line/Croccing | C2: Name of the owner of existing line | D2: Crossing Type | E2: Existing Crossing Span (M) | F2: Existing Tower/K MP No | G2: AP | H2: Tower Type | I2: RC if any | J2: Crossing Angle | K2: Crossing Span Length | L2: Electrical Clearance | M2: Proposal Preparation | N2: Proposal Submission to Sterlite on | O2: Submission to concerned office | P2: Joint site inspection | Q2: Submission of charges (if any) | R2: NOC Received on | S2: Remarks
A3: Statutory/Crossing Tracker - 220KV D/C Line
A4: 1 | B4: NH-27 | C4: NHAI | D4: NH | G4: 1B/0-1C/0 | H4: 1B/0(DD+3)-1C/0(DD+3) | I4: - | K4: 248
A5: 2 | B5: NH-27 | C5: NHAI | D5: NH | G5: 3/0-4/0 | H5: 3/0(DD+3)-4/0(DB+9) | I5: - | K5: 229.73
A6: 3 | B6: 220KV S/C LINE | C6: PGCIL | D6: PLC | E6: 179-180 | G6: 24/0-25/0 | H6: 24/0(DD+9)-25/0(DD+18) | I6: 3M & 2M | K6: 190.52
A7: 4 | B7: 220KV D/C RPB-CGH LINE | C7: PGCIL | D7: PLC | E7: 179-180 | G7: 26/0-27/0 | H7: 26/0(DD+18)-27/0(DD+18) | I7: 3M & 0M | K7: 142.38
A8: 5 | B8: 400KV T/L | D8: PLC | G8: 28/1-28/2 | H8: 28/1(Gantry)-28/2(Gantry) | I8: - | K8: 44
A9: 6 | B9: WATER RESERVOIR BOUNDARY | G9: 31/0-31/1 | H9: 31/0(DB+0)-31/1(DA+6) | I9: 0M & 4M | K9: 361
A11: Statutory/Crossing Tracker - 132KV D/C Line
A12: 1 | B12: Gas Pipeline | D12: Pipeline | G12: Tapping Tower -DE | H12: Tapping Tower(DD+0 ) - DE (DD+0) | I12: - | K12: 25.92
A13: 2 | B13: Pipeline, Cable | D13: Pipeline | G13: 3/1-3/2 | H13: 3/1(DA+6)-3/2(DA+3) | I13: - | K13: 260
A14: 3 | B14: River | D14: River | G14: 4/0-4/1 | H14: 4/0(DB-3)-4/1(DB-3) | I14: - | K14: 302
A15: 4 | B15: 220KV D/C LINE | D15: PLC | G15: 5/1-5/2 | H15: 5/1(Gantry)-5/2(Gantry) | I15: - | K15: 50
A16: 5 | B16: RAILWAY TRACK | D16: Railway | G16: 10/0-11/0 | H16: 10/0(DD+6)-11/0(DD+6) | I16: - | K16: 215.13
A17: 6 | B17: 220KV S/C LINE | D17: PLC | G17: 13/1-13/2 | H17: 13/1(Gantry)-13/2(Gantry) | I17: - | K17: 53
A18: 7 | B18: NH-27 | C18: NHAI | D18: NH | G18: 14/0-15/0 | H18: 14/0(DD+6)-15/0(DD-3) | I18: - | K18: 250
A22: Name of Existing Line/Croccing | B22: Name of the owner of existing line | C22: Crossing Type | D22: Section | E22: Submission | F22: JVR | G22: Remarks
A23: NH-27 | B23: NHAI | C23: NH | D23: 1B/0-1C/0 | F23: 45654 | G23: After submission one observation regarding overbridge making has circulated, revised proposal as +3MRC was submitted.
A24: NH-27 | B24: NHAI | C24: NH | D24: 3/0-4/0 | F24: 45586 | G24: Approval Recieved
A25: 220KV S/C LINE | B25: PGCIL | C25: PLC | D25: 24/0-25/0 | E25: 06-01-2025 (2nd Submission) | G25: Approval Recieved
A26: 220KV D/C RPB-CGH LINE | B26: PGCIL | C26: PLC | D26: 26/0-27/0 | E26: 06-01-2025 (2nd Submission) | G26: Approval Recieved
A27: 400KV T/L | C27: PLC | D27: 28/1-28/2 | E27: 06-01-2025 (2nd Submission) | G27: Approval Recieved
A29: 132KV
A31: Name of Existing Line/Croccing | B31: Name of the owner of existing line | C31: Crossing Type | D31: Section | E31: Submission | F31: JVR | G31: Remarks
A32: 220KV D/C LINE | B32: PLC | D32: 5/1-5/2 | E32: 45667 | F32: 45667 | G32: Proposal will be submitted in Chittorgarh.
A33: RAILWAY TRACK | B33: Railway | D33: 10/0-11/0 | E33: 45659 | F33: 45666 | G33: Proposal is in KOTA
A34: 220KV S/C LINE | B34: PLC | D34: 13/1-13/2 | F34: 45648 | G34: Proposal will be submitted in Chittorgarh.
A35: 765KV S/C LINE | B35: PLC | D35: 16/1-16/2 | E35: 45637 | G35: After submission request of Tower position changing was received. Revised proposal is received from our engg. Will be submitted.

Sheet Progress-132kV
A1: =+Summary!A2 -> Name of the Line: 220KV DC AL59 line from Neemuch - Chanderiya + 132KV DC ACSS Line from Chanderiya to Hindustan Zinc
A2: =+Summary!A5 -> Progress of 220kV Line
A3: 220 KV D/C Neemuch - TS | T3: Foundation | AL3: Earthing | AQ3: Erection | AU3: Tower Checking-1 | AV3: Tack-Welding | BA3: Tower Checking-2
A4: Sl. No. | B4: LOC NO | C4: Tower Type | G4: Tower Weight | K4: Stub Weight | O4: Chimney Extension | S4: Span Length(m) | T4: Classification | U4: Excavation Volume (m3) | V4: Concreting Volume | Y4: 8mm Steel | Z4: 10mm Steel | AA4: 12mm Steel | AB4: 16mm Steel | AC4: 20mm Steel | AD4: 25mmSteel | AE4: Total Steel (MT) | AF4: Status (C/WIP) | AG4: Excavation | AI4: Concreting | AK4: Sub-Contractor Name | AL4: Status C/WIP | AM4: Type | AN4: DOS | AO4: DOC | AP4: Sub-Contractor Name | AQ4: Status C/WIP | AR4: DOS | AS4: DOC | AT4: Sub-Contractor Name | AV4: Status C/WIP | AW4: DOS | AX4: DOC | AY4: Painting | AZ4: Sub-Contractor Name
G5: HT | H5: MS | I5: BnA | J5: Total | K5: HT | L5: MS | M5: BnA | N5: Total | O5: A | P5: B | Q5: C | R5: D | S5: m | V5: M10 (1:3:6) (m3) | W5: M20 (1:1.5:3) (m3) | X5: Total | AG5: DOS | AH5: DOC | AI5: DOS | AJ5: DOC
B6: Tapping Tower
S7: 25.92
A8: 1 | B8: 1/0 | C8: DD+0 | D8: 9.654 | E8: =D8*4 -> 38.616 | F8: =E8*8 -> 308.928 | G8: =4.906+1.456+0.596 -> 6.958 | H8: =0.066+0.717+0.272 -> 1.055 | I8: =0.274+0.083+0.043 -> 0.4 | J8: =SUM(G8:I8) -> 8.413 | K8: 0.532 | M8: 0.011 | N8: =K8+M8 -> 0.543 | T8: DFR | U8: 75.36 | V8: 1.35 | W8: 13.06 | X8: =V8+W8 -> 14.41 | Y8: 89.9 | AA8: 1287.27 | AB8: 193.64 | AE8: 1.571
S9: 230.15
A10: 2 | B10: 2/0 | C10: DD+0 | D10: 9.654 | E10: =D10*4 -> 38.616 | F10: =E10*8 -> 308.928 | G10: =4.906+1.456+0.596 -> 6.958 | H10: =0.066+0.717+0.272 -> 1.055 | I10: =0.274+0.083+0.043 -> 0.4 | J10: =SUM(G10:I10) -> 8.413 | K10: 0.532 | M10: 0.011 | N10: =K10+M10 -> 0.543 | T10: DFR | U10: 75.36 | V10: 1.35 | W10: 13.06 | X10: =V10+W10 -> 14.41 | Y10: 89.9 | AA10: 1287.27 | AB10: 193.64 | AE10: 1.571
S11: 234.56
A12: 3 | B12: 2/1 | C12: DD+6 | D12: 11.987 | E12: =D12*4 -> 47.948 | F12: =E12*8 -> 383.584 | G12: =4.906+4.424+0.596 -> 9.926 | H12: =0.066+1.053+0.272 -> 1.391 | I12: =0.274+0.181+0.043 -> 0.498 | J12: =SUM(G12:I12) -> 11.815 | K12: 0.532 | M12: 0.011 | N12: =K12+M12 -> 0.543 | T12: DFR | U12: 75.36 | V12: 1.35 | W12: 13.06 | X12: =V12+W12 -> 14.41 | Y12: 89.9 | AA12: 1287.27 | AB12: 193.64 | AE12: 1.571
S13: 251.12
A14: 4 | B14: 3/0 | C14: DD+0 | D14: 9.654 | E14: =D14*4 -> 38.616 | F14: =E14*8 -> 308.928 | G14: =4.906+1.456+0.596 -> 6.958 | H14: =0.066+0.717+0.272 -> 1.055 | I14: =0.274+0.083+0.043 -> 0.4 | J14: =SUM(G14:I14) -> 8.413 | K14: 0.532 | M14: 0.011 | N14: =K14+M14 -> 0.543 | T14: DFR | U14: 75.36 | V14: 1.35 | W14: 13.06 | X14: =V14+W14 -> 14.41 | Y14: 89.9 | AA14: 1287.27 | AB14: 193.64 | AE14: 1.571
S15: 183
A16: 5 | B16: 3/1 | C16: DA+3 | D16: 6.992 | E16: =D16*4 -> 27.968 | F16: =E16*8 -> 223.744 | G16: =1.267+0.234+1.276 -> 2.777 | H16: =1.137+0.487+0.273 -> 1.897 | I16: =0.182+0.074+0.032 -> 0.288 | J16: =SUM(G16:I16) -> 4.962 | K16: 0.271 | M16: 0.007 | N16: =M16+K16 -> 0.278 | T16: DFR | U16: 41.44 | V16: 0.8 | W16: 7.73 | X16: =W16+V16 -> 8.53 | Y16: 73.75 | Z16: 235.38 | AB16: 201.4 | AE16: 0.51
S17: 182.07
A18: 6 | B18: 4/0 | C18: DD+0 | D18: 9.654 | E18: =D18*4 -> 38.616 | F18: =E18*8 -> 308.928 | G18: =4.906+1.456+0.596 -> 6.958 | H18: =0.066+0.717+0.272 -> 1.055 | I18: =0.274+0.083+0.043 -> 0.4 | J18: =SUM(G18:I18) -> 8.413 | K18: 0.532 | M18: 0.011 | N18: =K18+M18 -> 0.543 | T18: DFR | U18: 75.36 | V18: 1.35 | W18: 13.06 | X18: =V18+W18 -> 14.41 | Y18: 89.9 | AA18: 1287.27 | AB18: 193.64 | AE18: 1.571
S19: 328.09
A20: 7 | B20: 5/0 | C20: DD+3 | D20: 10.82 | E20: =D20*4 -> 43.28 | F20: =E20*8 -> 346.24 | G20: =4.906+2.484+0.596 -> 7.986 | H20: =0.066+1.044+0.272 -> 1.382 | I20: =0.274+0.132+0.043 -> 0.449 | J20: =SUM(G20:I20) -> 9.817 | K20: 0.532 | M20: 0.011 | N20: =K20+M20 -> 0.543 | T20: DFR | U20: 75.36 | V20: 1.35 | W20: 13.06 | X20: =V20+W20 -> 14.41 | Y20: 89.9 | AA20: 1287.27 | AB20: 193.64 | AE20: 1.571
S21: 40
A22: 8 | B22: 5/1 | C22: GANTRY UC(+2) | F22: 54 | H22: 4.106 | I22: 0.23 | J22: =SUM(G22:I22) -> 4.336 | L22: =0.12+0.219 -> 0.339 | M22: =0.003+0.003 -> 0.006 | N22: =SUM(K22:M22) -> 0.345 | U22: 315 | V22: 4.1 | W22: 42 | X22: =W22+V22 -> 46.1 | AE22: 3.95
S23: 57.415
A24: 9 | B24: 5/2 | C24: GANTRY UC(+2) | F24: 54 | H24: 4.106 | I24: 0.23 | J24: =SUM(G24:I24) -> 4.336 | L24: =0.12+0.219 -> 0.339 | M24: =0.003+0.003 -> 0.006 | N24: =SUM(K24:M24) -> 0.345 | U24: 315 | V24: 4.1 | W24: 42 | X24: =W24+V24 -> 46.1 | AE24: 3.95
S25: 38.566
A26: 10 | B26: 6/0 | C26: DD+0 | D26: 9.654 | E26: =D26*4 -> 38.616 | F26: =E26*8 -> 308.928 | G26: =4.906+1.456+0.596 -> 6.958 | H26: =0.066+0.717+0.272 -> 1.055 | I26: =0.274+0.083+0.043 -> 0.4 | J26: =SUM(G26:I26) -> 8.413 | K26: 0.532 | M26: 0.011 | N26: =K26+M26 -> 0.543 | T26: DFR | U26: 75.36 | V26: 1.35 | W26: 13.06 | X26: =V26+W26 -> 14.41 | Y26: 89.9 | AA26: 1287.27 | AB26: 193.64 | AE26: 1.571
S27: 182.043
A28: 11 | B28: 6A/0 | C28: DD+0 | D28: 9.654 | E28: =D28*4 -> 38.616 | F28: =E28*8 -> 308.928 | G28: =4.906+1.456+0.596 -> 6.958 | H28: =0.066+0.717+0.272 -> 1.055 | I28: =0.274+0.083+0.043 -> 0.4 | J28: =SUM(G28:I28) -> 8.413 | K28: 0.532 | M28: 0.011 | N28: =K28+M28 -> 0.543 | T28: DFR | U28: 75.36 | V28: 1.35 | W28: 13.06 | X28: =V28+W28 -> 14.41 | Y28: 89.9 | AA28: 1287.27 | AB28: 193.64 | AE28: 1.571
S29: 204.148
A30: 12 | B30: 7/0 | C30: DD+0 | D30: 9.654 | E30: =D30*4 -> 38.616 | F30: =E30*8 -> 308.928 | G30: =4.906+1.456+0.596 -> 6.958 | H30: =0.066+0.717+0.272 -> 1.055 | I30: =0.274+0.083+0.043 -> 0.4 | J30: =SUM(G30:I30) -> 8.413 | K30: 0.532 | M30: 0.011 | N30: =K30+M30 -> 0.543 | T30: DFR | U30: 75.36 | V30: 1.35 | W30: 13.06 | X30: =V30+W30 -> 14.41 | Y30: 89.9 | AA30: 1287.27 | AB30: 193.64 | AE30: 1.571
S31: 254
A32: 13 | B32: 7/1 | C32: DA+3 | D32: 6.992 | E32: =D32*4 -> 27.968 | F32: =E32*8 -> 223.744 | G32: =1.267+0.234+1.276 -> 2.777 | H32: =1.137+0.487+0.273 -> 1.897 | I32: =0.182+0.074+0.032 -> 0.288 | J32: =SUM(G32:I32) -> 4.962 | K32: 0.271 | M32: 0.007 | N32: =M32+K32 -> 0.278 | T32: DFR | U32: 41.44 | V32: 0.8 | W32: 7.73 | X32: =W32+V32 -> 8.53 | Y32: 73.75 | Z32: 235.38 | AB32: 201.4 | AE32: 0.51
S33: 294
A34: 14 | B34: 7/2 | C34: DA+3 | D34: 6.992 | E34: =D34*4 -> 27.968 | F34: =E34*8 -> 223.744 | G34: =1.267+0.234+1.276 -> 2.777 | H34: =1.137+0.487+0.273 -> 1.897 | I34: =0.182+0.074+0.032 -> 0.288 | J34: =SUM(G34:I34) -> 4.962 | K34: 0.271 | M34: 0.007 | N34: =M34+K34 -> 0.278 | T34: DFR | U34: 41.44 | V34: 0.8 | W34: 7.73 | X34: =W34+V34 -> 8.53 | Y34: 73.75 | Z34: 235.38 | AB34: 201.4 | AE34: 0.51
S35: 249.82
A36: 15 | B36: 8/0 | C36: DD+3 | D36: 10.82 | E36: =D36*4 -> 43.28 | F36: =E36*8 -> 346.24 | G36: =4.906+2.484+0.596 -> 7.986 | H36: =0.066+1.044+0.272 -> 1.382 | I36: =0.274+0.132+0.043 -> 0.449 | J36: =SUM(G36:I36) -> 9.817 | K36: 0.532 | M36: 0.011 | N36: =K36+M36 -> 0.543 | T36: DFR | U36: 75.36 | V36: 1.35 | W36: 13.06 | X36: =V36+W36 -> 14.41 | Y36: 89.9 | AA36: 1287.27 | AB36: 193.64 | AE36: 1.571
S37: 329.66
A38: 16 | B38: 9/0 | C38: DD+3 | D38: 10.82 | E38: =D38*4 -> 43.28 | F38: =E38*8 -> 346.24 | G38: =4.906+2.484+0.596 -> 7.986 | H38: =0.066+1.044+0.272 -> 1.382 | I38: =0.274+0.132+0.043 -> 0.449 | J38: =SUM(G38:I38) -> 9.817 | K38: 0.532 | M38: 0.011 | N38: =K38+M38 -> 0.543 | T38: DFR | U38: 75.36 | V38: 1.35 | W38: 13.06 | X38: =V38+W38 -> 14.41 | Y38: 89.9 | AA38: 1287.27 | AB38: 193.64 | AE38: 1.571
S39: 170
A40: 17 | B40: 9/1 | C40: DA+6 | D40: 7.622 | E40: =D40*4 -> 30.488 | F40: =E40*8 -> 243.904 | G40: =1.267+1.845+0.234 -> 3.346 | H40: =1.137+0.646+0.273 -> 2.056 | I40: =0.182+0.091+0.032 -> 0.305 | J40: =SUM(G40:I40) -> 5.707 | K40: 0.271 | M40: 0.007 | N40: =M40+K40 -> 0.278 | T40: DFR | U40: 41.44 | V40: 0.8 | W40: 7.73 | X40: =W40+V40 -> 8.53 | Y40: 73.75 | Z40: 235.38 | AB40: 201.4 | AE40: 0.51
...

Sheet Progress-220kV
Y1: =SUBTOTAL(109,Y9:Y406) -> 268.209 | Z1: =SUBTOTAL(109,Z9:Z406) -> 2391.919 | AA1: =SUBTOTAL(109,AA9:AA406) -> 2660.128 | AB1: =SUBTOTAL(109,AB9:AB406) -> 19262.775 | AC1: =SUBTOTAL(109,AC9:AC406) -> 841980.65 | AD1: =SUBTOTAL(109,AD9:AD406) -> 15848.03 | AE1: =SUBTOTAL(109,AE9:AE406) -> 75028.21 | AF1: =SUBTOTAL(109,AF9:AF406) -> 31392.42 | ... AK1: =SUBTOTAL(109,AK9:AK406) -> 173.56078
A2: =+Summary!A2 -> Name of the Line: 220KV DC AL59 line from Neemuch - Chanderiya + 132KV DC ACSS Line from Chanderiya to Hindustan Zinc
A3: =+Summary!A5 -> Progress of 220kV Line
A4: 220 KV D/C Neemuch - TS | H4: RC Portion | L4: Tower Weight | Q4: Stub Weight | W4: Foundation | AV4: Earthing | BB4: Erection | BI4: Tack-Welding | BN4: Remarks | BO4: Remarks
P5: =SUBTOTAL(109,P8:P406) -> 1268.1002 | S5: =SUBTOTAL(109,S8:S406) -> 64.196 | V5: =SUBTOTAL(109,V8:V406) -> 0 | X5: =SUBTOTAL(109,X8:X406) -> 17610.65 | Y5: =SUBTOTAL(109,Y8:Y406) -> 268.209 | Z5: =SUBTOTAL(109,Z8:Z406) -> 2391.919 | AA5: =SUBTOTAL(109,AA8:AA406) -> 2660.128 | AB5: =SUBTOTAL(109,AB8:AB406) -> 19262.775 | AK5: =SUBTOTAL(109,AK8:AK406) -> 173.56078 | AM5: =SUBTOTAL(109,AM8:AM406) -> 0 | AV5: =SUBTOTAL(109,AV8:AV406) -> 0 | BB5: =SUBTOTAL(109,BB8:BB406) -> 0 | BI5: =SUBTOTAL(109,BI8:BI406) -> 0
A6: Sl. No. | B6: LOC NO | C6: Tower Type | H6: A | I6: B | J6: C | K6: D | L6: HT | M6: MS | N6: pack Washar | O6: BnA | P6: Total Tower Weight | Q6: HT | R6: BnA | S6: Total Stub Weight | T6: Deviation of Angle | U6: State | V6: Span Length(m) | W6: Classification | X6: Excavation Volume (m3) | Y6: Concreting Volume | AB6: Cement Required | AD6: Total Steel (Kgs) per Tower | AM6: Fnd Status (C/WIP) | AN6: Manual Checklist | AO6: JMC | AP6: Excavation | AR6: Concreting | AT6: Sub-Contractor Name | AV6: Earthing Status C/WIP | AW6: Earthing Type | AX6: DOS | AY6: DOC | AZ6: S/C | BB6: Erection Status C/WIP | BC6: Manual Checklist | BD6: JMC | BE6: DOS | BF6: DOC | BG6: S/C | BI6: Status C/WIP | BJ6: DOS | BK6: DOC | BL6: NB qty | BM6: Sub-Contractor Name
D7: B2B | E7: B2B x 4 | F7: Barbed Wire | G7: RC Portion | L7: MT | M7: MT | N7: MT | O7: MT | P7: MT | Q7: MT | R7: MT | S7: MT | T7: DMS | V7: m | Y7: M10 (1:3:6) (m3) | Z7: M20 (1:1.5:3) (m3) | AA7: Total | AB7: nos of bags | AC7: in kg | AD7: 8mm | AE7: 10mm | AF7: 12mm | AG7: 16mm | AH7: 20mm | AI7: 25mm | AJ7: Total Steel (Kgs) | AK7: Total Steel (MT) | AP7: DOS | AQ7: DOC | AR7: DOS | AS7: 9
A8: 0 | B8: GANTRY | C8: GANTRY | P8: 13 | AD8: 70.93 | AE8: 1040.06 | AG8: 98.08 | AH8: 153.24 | AJ8: 1362.31 | AK8: 1.36231
V9: 47
A10: 1 | B10: 0/0 | C10: DD+0 | D10: 9.654 | E10: =D10*4 -> 38.616 | F10: =E10*8 -> 308.928 | L10: 4.807 | M10: 4.016 | N10: 0.007 | O10: 0.431 | P10: =SUM(L10:O10) -> 9.261 | Q10: 0.557 | R10: 0.01 | S10: =SUM(Q10:R10) -> 0.567 | T10: 16° 50' 9"RT | U10: RJ | W10: WFR | X10: 220.64 | Y10: 3.61 | Z10: 27.92 | AA10: 31.53 | AB10: 241.0636 | AC10: 12053.18 | AD10: 77.93 | AF10: 1601.75 | AG10: 96.72 | AH10: 151.11 | AJ10: 1927.51 | AK10: 1.92751 | AM10: C | AN10: =AO10 -> D | AO10: D | AP10: =AQ10-1 -> 45703 | AQ10: =AR10-2 -> 45704 | AR10: =AS10-2 -> 45706 | AS10: 45708 | AT10: Ram Singh | AV10: C | AW10: CP | AX10: 45737 | AY10: =AX10 -> 45737 | AZ10: Ram Singh-1 | BB10: C | BC10: EE | BD10: D | BE10: =BF10-2 -> 45754 | BF10: 45756 | BG10: Ramesh Kumar | BI10: C | BJ10: 45824 | BK10: 45824 | BL10: 1202 | BM10: Asit Baran Pal
V11: 196
A12: 2 | B12: 0/1 | C12: DA+3 | D12: 6.992 | E12: =D12*4 -> 27.968 | F12: =E12*8 -> 223.744 | L12: 2.607 | M12: 2.657 | N12: 0.002 | O12: 0.213 | P12: =SUM(L12:O12) -> 5.479 | Q12: 0.244 | R12: 0.005 | S12: =SUM(Q12:R12) -> 0.249 | U12: RJ | W12: WET | X12: 121.84 | Y12: 1.4 | Z12: 12.03 | AA12: =Y12+Z12 -> 13.43 | AB12: 66.42 | AC12: 3321 | AD12: 73.73 | AE12: 301.5 | AG12: 206.46 | AJ12: 581.69 | AK12: 0.803 | AM12: C | AN12: =AO12 -> D | AO12: D | AP12: =AQ12-2 -> 45693 | AQ12: =AR12-1 -> 45695 | AR12: =AS12-1 -> 45696 | AS12: 45697 | AT12: Ram Singh | AV12: C | AW12: CP | AX12: 45709 | AY12: =AX12 -> 45709 | AZ12: Ram Singh-1 | BB12: C | BC12: EE | BD12: D | BE12: =BF12-2 -> 45749 | BF12: 45751 | BG12: Ramesh Kumar | BI12: C | BJ12: 45824 | BK12: 45824 | BL12: 1330 | BM12: Asit Baran Pal
P13: =SUM(L13:O13) -> 0 | V13: 196.743
A14: 3 | B14: 1/0 | C14: DC+0 | D14: 7.708 | E14: =D14*4 -> 30.832 | F14: =E14*8 -> 246.656 | L14: 4.057 | M14: 2.48 | N14: 0.006 | O14: 0.365 | P14: =SUM(L14:O14) -> 6.908 | Q14: 0.436 | R14: 0.01 | S14: =SUM(Q14:R14) -> 0.446 | T14: 15° 52' 12"RT | U14: RJ | W14: DFR | X14: 75.36 | Y14: 1.35 | Z14: 12.85 | AA14: 14.2 | AB14: 109.565 | AC14: 5478.25 | AD14: 81.82 | AE14: 599.6 | AG14: 201.4 | AJ14: 882.82 | AK14: 0.88282 | AM14: C | AN14: =AO14 -> D | AO14: D | AP14: =AQ14-3 -> 45736 | AQ14: =AR14-2 -> 45739 | AR14: =AS14-2 -> 45741 | AS14: 45743 | AT14: Ram Singh | AV14: C | AW14: CP | AX14: 45709 | AY14: =AX14 -> 45709 | AZ14: Ram Singh-1 | BB14: C | BC14: EE SUB | BD14: D | BE14: =BF14-2 -> 45758 | BF14: 45760 | BG14: Ramesh Kumar | BI14: C | BJ14: 45824 | BK14: 45824 | BL14: 1001 | BM14: Asit Baran Pal
P15: =SUM(L15:O15) -> 0 | V15: 334
A16: 4 | B16: 1/1 | C16: DA+0 | D16: 6.362 | E16: =D16*4 -> 25.448 | F16: =E16*8 -> 203.584 | L16: 2.25 | M16: 2.188 | N16: 0.002 | O16: 0.183 | P16: =SUM(L16:O16) -> 4.623 | Q16: 0.244 | R16: 0.005 | S16: =SUM(Q16:R16) -> 0.249 | U16: RJ | W16: WET | X16: 121.84 | Y16: 1.4 | Z16: 12.03 | AA16: =Y16+Z16 -> 13.43 | AB16: 66.42 | AC16: 3321 | AD16: 73.73 | AE16: 301.5 | AG16: 206.46 | AJ16: 581.69 | AK16: 0.803 | AM16: C | AN16: =AO16 -> D | AO16: D | AP16: =AQ16-2 -> 45706 | AQ16: =AR16-1 -> 45708 | AR16: =AS16-2 -> 45709 | AS16: 45711 | AT16: Ram Singh | AV16: C | AW16: Pipe | AX16: 45709 | AY16: =AX16 -> 45709 | AZ16: Ram Singh-1 | BB16: C | BC16: EE | BD16: D | BE16: =BF16-2 -> 45747 | BF16: 45749 | BG16: Ramesh Kumar | BI16: C | BJ16: 45825 | BK16: 45825 | BL16: 980 | BM16: Asit Baran Pal
P17: =SUM(L17:O17) -> 0 | V17: 319
A18: 5 | B18: 1/2 | C18: DA+3 | D18: 6.992 | E18: =D18*4 -> 27.968 | F18: =E18*8 -> 223.744 | L18: 2.607 | M18: 2.657 | N18: 0.002 | O18: 0.213 | P18: =SUM(L18:O18) -> 5.479 | Q18: 0.244 | R18: 0.005 | S18: =SUM(Q18:R18) -> 0.249 | U18: RJ | W18: DFR | X18: 41.44 | Y18: 0.8 | Z18: 7.8 | AA18: 8.6 | AB18: 66.42 | AC18: 3321 | AD18: 73.73 | AE18: 301.5 | AG18: 206.46 | AJ18: 581.69 | AK18: 0.58169 | AM18: C | AN18: =AO18 -> D | AO18: D | AP18: =AQ18-1 -> 45691 | AQ18: =AR18-1 -> 45692 | AR18: =AS18-1 -> 45693 | AS18: 45694 | AT18: Ram Singh | AV18: C | AW18: CP | AX18: 45709 | AY18: =AX18 -> 45709 | AZ18: Ram Singh-1 | BB18: C | BC18: EE SUB | BD18: D | BE18: =BF18-2 -> 45745 | BF18: 45747 | BG18: Ramesh Kumar | BI18: C | BJ18: 45825 | BK18: 45825 | BL18: 1330 | BM18: Asit Baran Pal
P19: =SUM(L19:O19) -> 0 | V19: 384.318
A20: 6 | B20: 1A/0 | C20: DC+3 | D20: 8.626 | E20: =D20*4 -> 34.504 | F20: =E20*8 -> 276.032 | L20: 4.538 | M20: 3.23 | N20: 0.0064 | O20: 0.429 | P20: =SUM(L20:O20) -> 8.2034 | Q20: 0.436 | R20: 0.01 | S20: =SUM(Q20:R20) -> 0.446 | T20: 18° 59' 57"LT | U20: RJ | W20: DFR | X20: 75.36 | Y20: 1.35 | Z20: 12.85 | AA20: 14.2 | AB20: 109.565 | AC20: 5478.25 | AD20: 81.82 | AE20: 599.6 | AG20: 201.4 | AJ20: 882.82 | AK20: 0.88282 | AM20: C | AN20: =AO20 -> D | AO20: D | AP20: =AQ20-3 -> 45698 | AQ20: =AR20-2 -> 45701 | AR20: =AS20-2 -> 45703 | AS20: 45705 | AT20: Ram Singh | AV20: C | AW20: CP | AX20: 45733 | AY20: =AX20 -> 45733 | AZ20: Ram Singh-1 | BB20: C | BC20: EE SUB | BD20: D | BE20: =BF20-2 -> 45768 | BF20: 45770 | BG20: Ramesh Kumar | BI20: C | BJ20: 45827 | BK20: 45827 | BL20: 1433 | BM20: Asit Baran Pal
P21: =SUM(L21:O21) -> 0 | V21: 329
A22: 7 | B22: 1A/1 | C22: DA+3 | D22: 6.992 | E22: =D22*4 -> 27.968 | F22: =E22*8 -> 223.744 | L22: 2.607 | M22: 2.657 | N22: 0.002 | O22: 0.213 | P22: =SUM(L22:O22) -> 5.479 | Q22: 0.244 | R22: 0.005 | S22: =SUM(Q22:R22) -> 0.249 | U22: RJ | W22: DFR | X22: 41.44 | Y22: 0.8 | Z22: 7.8 | AA22: 8.6 | AB22: 66.42 | AC22: 3321 | AD22: 73.73 | AE22: 301.5 | AG22: 206.46 | AJ22: 581.69 | AK22: 0.58169 | AM22: C | AN22: =AO22 -> D | AO22: D | AP22: 45688 | AQ22: =AP22+2 -> 45690 | AR22: =AS22-2 -> 45691 | AS22: 45693 | AT22: Ram Singh-1 | AV22: C | AW22: CP | AX22: 45709 | AY22: =AX22 -> 45709 | AZ22: Ram Singh-1 | BB22: C | BC22: EE | BD22: D | BE22: =BF22-2 -> 45751 | BF22: 45753 | BG22: Ramesh Kumar | BI22: C | BJ22: 45827 | BK22: 45827 | BL22: 1330 | BM22: Asit Baran Pal
P23: =SUM(L23:O23) -> 0 | V23: 280
A24: 8 | B24: 1A/2 | C24: DC+0 | D24: 7.708 | E24: =D24*4 -> 30.832 | F24: =E24*8 -> 246.656 | L24: 4.057 | M24: 2.48 | N24: 0.006 | O24: 0.365 | P24: =SUM(L24:O24) -> 6.908 | Q24: 0.436 | R24: 0.01 | S24: =SUM(Q24:R24) -> 0.446 | U24: RJ | W24: WFR | X24: 148.8 | Y24: 2.51 | Z24: 19.47 | AA24: 21.98 | AB24: 168.0726 | AC24: 8403.63 | AD24: 70.93 | AE24: 914.33 | AG24: 98.08 | AH24: 153.24 | AJ24: 1236.58 | AK24: 1.23658 | AM24: C | AN24: =AO24 -> D | AO24: D | AP24: 45681 | AQ24: =AP24+2 -> 45683 | AR24: =AS24-2 -> 45688 | AS24: 45690 | AT24: Ram Singh-1 | AV24: C | AW24: CP | AX24: 45733 | AY24: =AX24 -> 45733 | AZ24: Ram Singh-1 | BB24: C | BC24: EE SUB | BD24: D | BE24: =BF24-2 -> 45761 | BF24: 45763 | BG24: Ramesh Kumar | BI24: C | BJ24: 45830 | BK24: 45830 | BL24: 1001 | BM24: Asit Baran Pal
P25: =SUM(L25:O25) -> 0 | V25: 232.098
A26: 9 | B26: 1B/0 | C26: DD+3 | D26: 10.82 | E26: =D26*4 -> 43.28 | F26: =E26*8 -> 346.24 | L26: 5.492 | M26: 5.097 | N26: 0.0074 | O26: 0.502 | P26: =SUM(L26:O26) -> 11.0984 | Q26: 0.557 | R26: 0.01 | S26: =SUM(Q26:R26) -> 0.567 | T26: 57° 18' 17"LT | U26: RJ | W26: WFR | X26: 220.64 | Y26: 3.61 | Z26: 27.92 | AA26: 31.53 | AB26: 241.0636 | AC26: 12053.18 | AD26: 77.93 | AF26: 1601.75 | AG26: 96.72 | AH26: 151.11 | AJ26: 1927.51 | AK26: 1.92751 | AM26: C | AN26: =AO26 -> D | AO26: D | AP26: =AQ26-2 -> 45717 | AQ26: =AR26-1 -> 45719 | AR26: =AS26-1 -> 45720 | AS26: 45721 | AT26: Ram Singh-1 | AV26: C | AW26: CP | AX26: 45733 | AY26: =AX26 -> 45733 | AZ26: Ram Singh-1 | BB26: C | BC26: EE | BD26: D | BE26: =BF26-2 -> 45772 | BF26: 45774 | BG26: Ramesh Kumar | BI26: C | BJ26: 45830 | BK26: 45830 | BL26: 1552 | BM26: Asit Baran Pal
P27: =SUM(L27:O27) -> 0 | V27: 237.783
A28: 10 | B28: 1C/0 | C28: DD+9 | D28: 13.258 | E28: =D28*4 -> 53.032 | F28: =E28*8 -> 424.256 | L28: 6.058 | M28: 5.874 | N28: 0.0077 | O28: 0.563 | P28: =SUM(L28:O28) -> 12.5027 | Q28: 0.557 | R28: 0.01 | S28: =SUM(Q28:R28) -> 0.567 | T28: 44° 32' 20"RT | U28: RJ | W28: DFR | X28: 119.36 | Y28: 2.05 | Z28: 18.37 | AA28: 20.42 | AB28: 157.1642 | AC28: 7858.21 | AD28: 89.9 | AF28: 1115.34 | AG28: 198.68 | AJ28: 1403.92 | AK28: 1.40392 | AT28: SS | AW28: CP | BL28: 2008
P29: =SUM(L29:O29) -> 0 | V29: 334
A30: 11 | B30: 1C/1 | C30: DA+6 | D30: 7.622 | E30: =D30*4 -> 30.488 | F30: =E30*8 -> 243.904 | L30: 2.679 | M30: 3.133 | N30: 0.0023 | O30: 0.233 | P30: =SUM(L30:O30) -> 6.0473 | Q30: 0.244 | R30: 0.005 | S30: =SUM(Q30:R30) -> 0.249 | U30: RJ | W30: Sandy Wet | X30: 143.36 | Y30: 1.68 | Z30: 11.97 | AA30: 13.65 | AB30: =+Y30*4.44+Z30*8.06 -> 103.9374 | AC30: =+AB30*50 -> 5196.87 | AD30: 63.93 | AE30: 535.23 | AG30: 100.6 | AH30: 157.18 | AJ30: 856.94 | AK30: 0.85694 | AM30: C | AN30: =AO30 -> D | AO30: D | AP30: =AQ30-2 -> 45707 | AQ30: =AR30-2 -> 45709 | AR30: =AS30-2 -> 45711 | AS30: 45713 | AT30: Shree Shyam | AV30: C | AW30: Pipe | AX30: =AY30 -> 45720 | AY30: 45720 | AZ30: Ram Singh-1 | BB30: C | BC30: EE | BD30: D | BE30: =BF30-2 -> 45794 | BF30: 45796 | BG30: Shree Karni Entp | BI30: C | BJ30: 45830 | BK30: 45830 | BL30: 1545 | BM30: Asit Baran Pal
P31: =SUM(L31:O31) -> 0 | V31: 341.209
A32: 12 | B32: 1D/0 | C32: DC+0 | D32: 7.708 | E32: =D32*4 -> 30.832 | F32: =E32*8 -> 246.656 | L32: 4.057 | M32: 2.48 | N32: 0.006 | O32: 0.365 | P32: =SUM(L32:O32) -> 6.908 | Q32: 0.436 | R32: 0.01 | S32: =SUM(Q32:R32) -> 0.446 | T32: 28° 26' 27"RT | U32: RJ | W32: Sandy Wet | X32: 229.64 | Y32: 2.81 | Z32: 21.11 | AA32: 23.92 | AB32: 182.623 | AC32: 9131.15 | AD32: 70.93 | AE32: 1040.06 | AG32: 98.08 | AH32: 153.24 | AJ32: 1362.31 | AK32: 1.36231 | AM32: C | AN32: EG | AO32: D | AP32: 45679 | AQ32: =AR32-2 -> 45684 | AR32: =AS32-2 -> 45686 | AS32: 45688 | AT32: Ram Singh-1 | AV32: C | AW32: Pipe | AX32: 45703 | AY32: 45703 | AZ32: Ram Singh-1 | BB32: C | BC32: EE | BD32: D | BE32: =BF32-1 -> 45745 | BF32: 45746 | BG32: Ramesh Kumar | BI32: C | BJ32: 45831 | BK32: 45831 | BL32: 1001 | BM32: Asit Baran Pal
P33: =SUM(L33:O33) -> 0 | V33: 306.001
A34: 13 | B34: 1D/1 | C34: DA+0 | D34: 6.362 | E34: =D34*4 -> 25.448 | F34: =E34*8 -> 203.584 | L34: 2.25 | M34: 2.188 | N34: 0.002 | O34: 0.183 | P34: =SUM(L34:O34) -> 4.623 | Q34: 0.244 | R34: 0.005 | S34: =SUM(Q34:R34) -> 0.249 | U34: RJ | W34: Sandy Wet | X34: 143.36 | Y34: 1.68 | Z34: 11.97 | AA34: 13.65 | AB34: =+Y34*4.44+Z34*8.06 -> 103.9374 | AC34: =+AB34*50 -> 5196.87 | AD34: 63.93 | AE34: 535.23 | AG34: 100.6 | AH34: 157.18 | AJ34: 856.94 | AK34: 0.85694 | AM34: C | AN34: =AO34 -> D | AO34: D | AP34: =AQ34-2 -> 45704 | AQ34: =AR34-2 -> 45706 | AR34: =AS34-2 -> 45708 | AS34: 45710 | AT34: Shree Shyam | AV34: C | AW34: Pipe | AX34: 45703 | AY34: 45703 | AZ34: Ram Singh-1 | BB34: C | BC34: EE | BD34: D | BE34: =BF34-1 -> 45743 | BF34: 45744 | BG34: Ramesh Kumar | BI34: C | BJ34: 45831 | BK34: 45831 | BL34: 980 | BM34: Asit Baran Pal
P35: =SUM(L35:O35) -> 0 | V35: 393.92
A36: 14 | B36: 1E/0 | C36: DD+6 | D36: 11.987 | E36: =D36*4 -> 47.948 | F36: =E36*8 -> 383.584 | L36: 5.904 | M36: 5.541 | N36: 0.0075 | O36: 0.535 | P36: =SUM(L36:O36) -> 11.9875 | Q36: 0.557 | R36: 0.01 | S36: =SUM(Q36:R36) -> 0.567 | T36: 42° 49' 3"RT | U36: RJ | W36: WFR | X36: 220.64 | Y36: 3.61 | Z36: 27.92 | AA36: 31.53 | AB36: 241.0636 | AC36: 12053.18 | AD36: 77.93 | AF36: 1601.75 | AG36: 96.72 | AH36: 151.11 | AJ36: 1927.51 | AK36: 1.92751 | AM36: C | AN36: D | AO36: D | AP36: =AQ36-2 -> 45731 | AQ36: =AR36-2 -> 45733 | AR36: =AS36-3 -> 45735 | AS36: 45738 | AT36: Shree Shyam | AV36: C | AW36: CP | AX36: =AY36 -> 45661 | AY36: 45661 | AZ36: Ram Singh-1 | BB36: C | BC36: EE | BD36: D | BE36: =BF36-2 -> 45802 | BF36: 45804 | BG36: Dudhnath Kumar | BI36: C | BJ36: 45837 | BK36: 45837 | BL36: 1750 | BM36: Asit Baran Pal
P37: =SUM(L37:O37) -> 0 | V37: 356.664
A38: 15 | B38: 2/0 | C38: DC+6 | D38: 9.544 | E38: =D38*4 -> 38.176 | F38: =E38*8 -> 305.408 | L38: 4.938 | M38: 3.609 | N38: 0.0063 | O38: 0.424 | P38: =SUM(L38:O38) -> 8.9773 | Q38: 0.436 | R38: 0.01 | S38: =SUM(Q38:R38) -> 0.446 | T38: 27° 13' 43"RT | U38: RJ | W38: WET | X38: 184.48 | Y38: 2.22 | Z38: 17.65 | AA38: =Y38+Z38 -> 19.87 | AD38: 70.93 | AE38: 848.79 | AG38: 98.08 | AH38: 153.24 | AJ38: =SUM(AD38:AH38) -> 1171.04 | AK38: 0.88282 | AM38: C | AN38: =AO38 -> D | AO38: D | AP38: 45679 | AQ38: =AP38+2 -> 45681 | AR38: =AS38-2 -> 45688 | AS38: 45690 | AT38: Shree Shyam | AV38: C | AW38: Pipe | AX38: 45703 | AY38: 45703 | AZ38: Ram Singh-1 | BB38: C | BC38: EE SUB | BD38: D | BE38: =BF38-2 -> 45766 | BF38: 45768 | BG38: Ramesh Kumar | BI38: C | BJ38: 45831 | BK38: 45831 | BL38: 1657 | BM38: Asit Baran Pal
P39: =SUM(L39:O39) -> 0 | V39: 174.205
A40: 16 | B40: 3/0 | C40: DD+3 | D40: 10.82 | E40: =D40*4 -> 43.28 | F40: =E40*8 -> 346.24 | L40: 5.492 | M40: 5.097 | N40: 0.0074 | O40: 0.502 | P40: =SUM(L40:O40) -> 11.0984 | Q40: 0.557 | R40: 0.01 | S40: =SUM(Q40:R40) -> 0.567 | T40: 49° 56' 13"RT | U40: RJ | W40: WET | X40: 268.58 | Y40: 3.33 | Z40: 26.1 | AA40: 29.43 | AB40: 225.1512 | AC40: 11257.56 | AD40: 77.93 | AF40: 1484.97 | AG40: 96.72 | AH40: 151.11 | AJ40: 1810.73 | AK40: 1.81073 | AM40: C | AN40: =AO40 -> D | AO40: D | AP40: =AQ40-2 -> 45700 | AQ40: =AR40-2 -> 45702 | AR40: =AS40-2 -> 45704 | AS40: 45706 | AT40: Shree Shyam | AV40: C | AW40: Pipe | AX40: 45703 | AY40: 45703 | AZ40: Ram Singh-1 | BB40: C | BC40: EE SUB | BD40: D | BE40: =BF40-2 -> 45778 | BF40: 45780 | BG40: Ramesh Kumar | BI40: C | BJ40: 45802 | BK40: 45802 | BL40: 1552 | BM40: Asit Baran Pal
...

Sheet Erection Compiled
A1: Sl. No. | B1: Location No. | C1: Type | D1: Type of Tower | E1: Starting Date | F1: Revenue | G1: Tower Weight | H1: Status | I1: Completion Date | J1: Gang Name | K1: No. | L1: District | M1: Remarks | N1: Ageing
A2: 1 | B2: 10/0 | D2: DD+6 | E2: 28/12/25 | G2: 11.815 | H2: Completed | I2: 30/12/25 | J2: Suman
A3: 2 | B3: 12/0 | D3: DD+0 | E3: 46028 | G3: 8.413 | H3: Completed | I3: 46029 | J3: Suman
A4: 3 | B4: 13/0 | D4: DD+0 | E4: 46025 | G4: 8.413 | H4: Completed | I4: 46027 | J4: Suman
A5: 4 | B5: 15/1 | D5: DA+0 | E5: 31/12/25 | G5: 4.339 | H5: Completed | I5: 46024 | J5: Suman
A6: 5 | B6: 15/2 | D6: DA+0 | E6: 46018 | G6: 4.339 | H6: Completed | I6: 46018 | J6: Suman
A7: 6 | B7: 15/3 | D7: DA+0 | E7: 46016 | G7: 4.339 | H7: Completed | I7: 46017 | J7: Suman
A8: 7 | B8: 16/0 | D8: DD+0 | E8: 45973 | G8: 8.413 | H8: Completed | I8: 13/12/25 | J8: Suman
A9: 8 | B9: 16/1 | D9: GANTRY UC(+2) | E9: 45975 | G9: 4.336 | H9: Completed | I9: 45978 | J9: Harsh vivek
A10: 9 | B10: 16/2 | D10: GANTRY UC(+2) | E10: 45978 | G10: 4.336 | H10: Completed | I10: 45981 | J10: Harsh vivek
A11: 10 | B11: 17/0 | D11: DD+0 | E11: 45897 | G11: 8.413 | H11: Completed | I11: 45900 | J11: Suman
A12: 11 | B12: 18/0 | D12: DD AUX | E12: 15/12/25 | G12: 11.517 | H12: Completed | I12: 17/12/2025 | J12: Suman
A13: 12 | B13: 0/0 | D13: DD+0 | E13: 45754 | G13: 9.261 | H13: Completed | I13: 45756 | J13: Ramesh Kumar
A14: 13 | B14: 0/1 | D14: DA+3 | E14: 45749 | G14: 5.479 | H14: Completed | I14: 45751 | J14: Ramesh Kumar
A15: 14 | B15: 1/0 | D15: DC+0 | E15: 45758 | G15: 6.908 | H15: Completed | I15: 45760 | J15: Ramesh Kumar
A16: 15 | B16: 1/1 | D16: DA+0 | E16: 45747 | G16: 4.623 | H16: Completed | I16: 45749 | J16: Ramesh Kumar
A17: 16 | B17: 1/2 | D17: DA+3 | E17: 45745 | G17: 5.479 | H17: Completed | I17: 45747 | J17: Ramesh Kumar
A18: 17 | B18: 1A/0 | D18: DC+3 | E18: 45768 | G18: 8.2034 | H18: Completed | I18: 45770 | J18: Ramesh Kumar
A19: 18 | B19: 1A/1 | D19: DA+3 | E19: 45751 | G19: 5.479 | H19: Completed | I19: 45753 | J19: Ramesh Kumar
A20: 19 | B20: 1A/2 | D20: DC+0 | E20: 45761 | G20: 6.908 | H20: Completed | I20: 45763 | J20: Ramesh Kumar
A21: 20 | B21: 1B/0 | D21: DD+3 | E21: 45772 | G21: 11.0984 | H21: Completed | I21: 45774 | J21: Ramesh Kumar
A22: 21 | B22: 1C/1 | D22: DA+6 | E22: 45794 | G22: 6.0473 | H22: Completed | I22: 45796 | J22: Shree Karni Entp
A23: 22 | B23: 1D/0 | D23: DC+0 | E23: 45745 | G23: 6.908 | H23: Completed | I23: 45746 | J23: Ramesh Kumar
A24: 23 | B24: 1D/1 | D24: DA+0 | E24: 45743 | G24: 4.623 | H24: Completed | I24: 45744 | J24: Ramesh Kumar
... A207: 206 | B207: 32/2 | D207: DA+0 | E207: 45801 | G207: 4.623 | H207: Completed | I207: 45803 | J207: Ramesh Kumar (M)

Sheet Stringing-220kV
A1: =+Summary!A2 -> Name of the Line: 220KV DC AL59 line from Neemuch - Chanderiya + 132KV DC ACSS Line from Chanderiya to Hindustan Zinc
A2: =+Summary!A5 -> Progress of 220kV Line | F2: Stringing Progress (Conductor & Earthwire) | T2: OPGW Progress
A3: Stringing Section | D3: =Summary!R5 -> 46030 | E3: =SUMIF(E6:E212,"C",$D$6:$D$212)/1000 -> 54.854478 | H3: =SUMIF(G6:G212,"WIP",$D$6:$D$212)/1000 -> 0 | I3: =SUMIF(G6:G212,"C",$D$6:$D$212)/1000 -> 54.111128 | K3: =SUMIF(J6:J212,"WIP",$D$6:$D$212)/1000 -> 0 | L3: =SUMIF(J6:J212,"C",$D$6:$D$212)/1000 -> 54.111128 | U3: =SUMIF(T6:T212,"WIP",$D$6:$D$212)/1000 -> 0 | V3: =SUMIF(T6:T212,"C",$D$6:$D$212)/1000 -> 39.301041 | X3: =SUMIF(W6:W212,"WIP",$D$6:$D$212)/1000 -> 0 | Y3: =SUMIF(W6:W212,"C",$D$6:$D$212)/1000 -> 39.301041
A4: Sl. No. | B4: Section | D4: Section Length (m) | E4: Stretch Readiness | F4: Insulator Hoisting | G4: Conductor Paying Out | J4: Final Sag | M4: Clipping | N4: Spacer | O4: Jumper | P4: Sub-Contractor Name | Q4: MP | R4: Remarks | T4: OPGW Paying Out | W4: OPGW Final Sag | Z4: Sub-Contractor Name
B5: From | C5: To | G5: Status | H5: DOS | I5: DOC | J5: Status | K5: DOS | L5: DOC | M5: Status | N5: Status | O5: Status | T5: Status | U5: DOS | V5: DOC | W5: Status | X5: DOS | Y5: DOC
A6: 1 | B6: 0/0 | C6: 1/0 | D6: 439.47 | E6: C | F6: C | G6: C | H6: 45796 | I6: 45801 | J6: C | K6: 45803 | L6: =K6+2 -> 45805 | M6: C | N6: C | O6: C | P6: National
A7: 2 | B7: =C6 -> 1/0 | C7: 1A/0 | D7: 1037.32 | E7: C | F7: C | G7: C | H7: 45796 | I7: 45801 | J7: C | K7: 45803 | L7: =K7+2 -> 45805 | M7: C | N7: C | O7: C | P7: National
A8: 3 | B8: =C7 -> 1A/0 | C8: 1A/2 | D8: 609 | E8: C | F8: C | G8: C | H8: =I8 -> 45837 | I8: 45837 | J8: C | K8: 45838 | L8: =K8 -> 45838 | M8: C | N8: C | O8: C | P8: National
A9: 4 | B9: =C8 -> 1A/2 | C9: 1B/0 | D9: 232.098 | E9: C | F9: C | G9: C | H9: =I9 -> 45837 | I9: 45837 | J9: C | K9: 45837 | L9: =K9 -> 45837 | M9: C | N9: C | P9: National
A10: 5 | B10: =C9 -> 1B/0 | C10: 1C/0 | D10: 237.783
A11: 6 | B11: =C10 -> 1C/0 | C11: 1D/0 | D11: 675.21
A12: 7 | B12: =C11 -> 1D/0 | C12: 1E/0 | D12: 699.92 | E12: C | F12: C | G12: C | H12: =I12-1 -> 45870 | I12: =K12-2 -> 45871 | J12: C | K12: =L12-3 -> 45873 | L12: 45876 | M12: C | N12: C | O12: C | P12: Dilruba Bibi
A13: 8 | B13: =C12 -> 1E/0 | C13: 2/0 | D13: 356.664 | E13: C | F13: C | G13: C | H13: =I13-3 -> 45864 | I13: =K13-2 -> 45867 | J13: C | K13: =L13-3 -> 45869 | L13: 45872 | M13: C | N13: C | P13: Dilruba Bibi
A14: 9 | B14: =C13 -> 2/0 | C14: 3/0 | D14: 174.205
A15: 10 | B15: =C14 -> 3/0 | C15: 4/0 | D15: 229.73
A16: 11 | B16: =C15 -> 4/0 | C16: 4/5 | D16: 1733 | E16: C | F16: C | G16: C | H16: =I16-3 -> 45849 | I16: =K16-2 -> 45852 | J16: C | K16: =L16-2 -> 45854 | L16: 45856 | M16: C | N16: C | O16: C | P16: Dilruba Bibi
A17: 12 | B17: =C16 -> 4/5 | C17: 4/6 | D17: 349 | E17: C | F17: C | G17: C | H17: =I17-3 -> 45849 | I17: =K17-2 -> 45852 | J17: C | K17: =L17-2 -> 45854 | L17: 45856 | M17: C | N17: C | P17: Dilruba Bibi
A18: 13 | B18: =C17 -> 4/6 | C18: 4/7 | D18: 360
A19: 14 | B19: =C18 -> 4/7 | C19: 4/8 | D19: 460
