Workbook
Name \0: #REF!
Name \2: #REF!
Name \3: #REF!
Name \4: #REF!
Name \A: #REF!
Name \A_1: "#REF!"
Name \a1: #REF!
Name \B: #REF!
Name \C: #REF!
Name \c1: #REF!
Name \d: #N/A
Name \E: #REF!
Name \f: #REF!
Name \g: #REF!
Name \H: #REF!
Name \I: #REF!
Name \j: #REF!
Name \k: #REF!
Name \KWS123: #N/A
Name \l: #REF!
Name \M: #REF!
Name \N: #REF!
Name \P: #REF!
Name \q: #N/A
Name \R: #REF!
Name \S: #REF!
Name \t: #N/A
Name \U: #REF!
Name \V: #REF!
Name \z: #REF!
Name _: #REF!
Name _________________________________________________________dol12: #REF!
Name _________________________________________________________in18900: #REF!
Name _________________________________________________________iv19000: #REF!
Name ________________________________________________________dol12: #REF!
Name ________________________________________________________dol6: #REF!
Name ________________________________________________________in18900: #REF!
Name ________________________________________________________iv19000: #REF!
Name _______________________________________________________dol12: #REF!
Name _______________________________________________________dol6: #REF!
Name _______________________________________________________in18900: #REF!
Name _______________________________________________________iv19000: #REF!
Name ______________________________________________________dol12: #REF!
Name ______________________________________________________dol6: #REF!
Name _____________________________________________________dol12: #REF!
Name _____________________________________________________dol6: #REF!
Name _____________________________________________________in18900: #REF!
Name _____________________________________________________iv19000: #REF!
Name ____________________________________________________dol12: #REF!
Name ____________________________________________________dol6: #REF!
Name ____________________________________________________in18900: #REF!
Name ____________________________________________________iv19000: #REF!
Name ___________________________________________________dol12: #REF!
Name ___________________________________________________dol6: #REF!
Name ___________________________________________________in18900: #REF!
Name ___________________________________________________iv19000: #REF!
Name __________________________________________________dol12: #REF!
Name __________________________________________________dol6: #REF!
Name __________________________________________________in18900: #REF!
Name __________________________________________________iv19000: #REF!

Sheet TB401 DPR.....
B1: Project Code | D1: TB-401 | F1: Date | H1: =TODAY() -> 46119 | I1: LOA Start Date | L1: 45041 | M1: Business Head (T&D)- India & Sri Lanka | P1: Rajinder Gupta
B2: Project Name | D2: 765KV D/C Fategarh-III Beawar Transmission Line | I2: LOA End Date | L2: 45498 | M2: PCH | P2: Sivaraman Nataraajan
B3: Client Name | D3: Strelite Power | I3: Time Extn | L3: 45498 | M3: Regional Manager | P3: Sandeep Singh Kumar
B4: LE Value | D4: Rs 312 Cr -Supply -Rs 227.5 Cr.; Service.-Rs 84.4 Cr | I4: Planning | L4: Shah Ali Khan | M4: Project Manager | P4: Virender Gupta
A5: Activity | B5: Unit | C5: LOA Qty. | D5: LE Qty | E5: Progress till Last Month | F5: Balance | G5: L2 for Dec'23 | H5: Plan for Dec.'23 | I5: Today's Progress | J5: Month Progress | K5: WIP | L5: Gangs at Present | M5: L2 Till Month-Dec.23 | N5: Progress Till Date | O5: Balance Work | P5: Remarks
A6: Route Alignment | B6: km | C6: 215 | D6: 202 | E6: 167 | F6: =D6-E6 -> 35 | G6: 0 | H6: 35 | M6: 215 | N6: =E6+J6 -> 167 | O6: =D6-N6 -> 35 | P6: 35 Km is hold due to ROW issues
A7: Detailed Survey | B7: km | C7: 215 | D7: 202 | E7: 202 | F7: =D7-E7 -> 0 | G7: 0 | M7: 215 | N7: =E7+J7 -> 202 | O7: =D7-N7 -> 0 | P7: SPTL Approved -202/202-Kms
A8: Check Survey | B8: km | C8: 215 | D8: 202 | E8: 92.704 | F8: =D8-E8 -> 109.296 | G8: 20 | H8: 50 | J8: 17.852 | M8: 160 | N8: =E8+J8 -> 110.556 | O8: =D8-N8 -> 91.444 | P8: 1. Total 7.854 Km is under review of SPTL. 2. Total check survey completed (Field work) 167 Km. 3. Total 60 Km check survey is hold due to row issues & Other issues.
A9: Foundation | B9: Nos | C9: 534 | D9: 521 | E9: 109 | F9: =D9-E9 -> 412 | G9: 75 | H9: 30 | J9: 1 | K9: 4 | L9: 3 | M9: 399 | N9: =E9+J9 -> 110 | O9: =D9-N9 -> 411 | AA9: =65/D9 -> 0.12476008 | AC9: =(D11-C9)/C9 -> -0.024344569 | AD9: =C9*AC9 -> -13 | AE9: =366-318 -> 48 | AF9: =318-12 -> 306
A10: Earthing | B10: Nos | C10: 534 | D10: 521 | E10: 106 | F10: =D10-E10 -> 415 | G10: 75 | H10: 30 | J10: 2 | M10: 399 | N10: =E10+J10 -> 108 | O10: =D10-N10 -> 413 | AA10: =65/D10 -> 0.12476008
A11: Tower Erection | B11: Nos | C11: 534 | D11: 521 | E11: 45 | F11: =D11-E11 -> 476 | G11: 75 | H11: 40 | I11: 2 | J11: 6 | K11: 5 | L11: 5 | M11: 260 | N11: =E11+J11 -> 51 | O11: =D11-N11 -> 470 | P11: 56/2 58/15 Complete | AA11: =65/D11 -> 0.12476008
A12: Tack welding | B12: Nos | C12: 534 | D12: 521 | E12: 15 | F12: =D12-E12 -> 506 | G12: 75 | H12: 40 | I12: 1 | J12: 3 | K12: 1 | L12: 1 | M12: 260 | N12: =E12+J12 -> 18 | O12: =D12-N12 -> 503 | P12: 56/7 complete | AA12: =65/D12 -> 0.12476008
A13: Stringing | B13: Km | C13: 215 | D13: 202 | E13: 0 | F13: =D13-E13 -> 202 | G13: 20 | M13: 25 | N13: =E13+J13 -> 0 | O13: =D13-N13 -> 202 | AA13: =20.635/D13 -> 0.10215347 | AD13: =103/151 -> 0.68211921
AA14: =20.635/D14 -> #DIV/0!

Sheet Eng.
A2: Tower | B2: Tower Design | D2: Test Tower | F2: Balance Structural Drawing. | H2: Tower | I2: Stub & Template Drawings | J2: Foundation
A3: Types | D3: Structural Drawing(BTB+0) | F3: (3M/6M/9M) | H3: Testing | J3: Design/Drg
B4: Target | C4: Status | D4: Target | E4: Status | F4: Target | G4: Status | J4: Target | K4: Status
A5: DA Tower | B5: 45058 | C5: Approved | D5: 45081 | E5: Approved | F5: 45101 | G5: Approved for proto | H5: Completed | I5: Approved | J5: 15-July | K5: Approved
A6: DB Tower | B6: 45076 | C6: Approved | D6: 45137 | E6: Approved | F6: 45126 | G6: Approvedin Cat-B | H6: Completed | I6: Approved for Proto | J6: DB all Fdn. By 25 -July | K6: Approved
A8: DD Tower | B8: 45098 | C8: Approved | D8: 30-Sept. | E8: Approved in Cat -B | F8: 45158 | G8: Approved in Cat -B | H8: Completed | I8: Approved in Cat -B | J8: 45138 | K8: Approved
A9: DC Tower | B9: 45123 | C9: Approved | D9: 45207 | E9: Approved in Cat -B | F9: 45188 | G9: Approved in Cat -B | H9: Completed | I9: Approved in Cat -B | J9: 45163 | K9: Approved

Sheet Fdn (Pkg -G Section -I)
A1: KEC INTERNATIONAL LIMITED | L1: Date: | M1: =TODAY() -> 46119
A2: LILO of 765 Kv DV Fatehgarh 3 Beawar TL
A3: FOUNDATION
A4: Sl. No. | B4: Month Sl. No. | C4: JMC No. | D4: Location No. | E4: Tower Type | F4: Classification | G4: Excavation Start | H4: Dt. of Start | I4: Dt. of Concrete | J4: Name of Sub-Contractor | K4: KEC representative | L4: KEC Section In-Charge | M4: Remarks
A6: 1 | B6: 1 | D6: 32/7 | E6: DA+0 | F6: SANDY | G6: 23.10.23 | H6: 25.10.23 | I6: 28.10.23 | J6: Shakti Construction | K6: Kumar Nayak | L6: Jish C Verghese | M6: Complete
A7: 2 | B7: 2 | D7: 32/5 | E7: DA+6 | F7: SANDY | G7: 29.10.23 | H7: 31.10.23 | I7: 04.11.2023 | J7: Shakti Construction | K7: Kumar Nayak | L7: Jish C Verghese | M7: Complete
A8: 3 | B8: 3 | D8: 32/1 | E8: DA+9 | F8: SANDY | G8: 03.11.23 | H8: 06.11.23 | I8: 10.11.23 | J8: Shakti Construction | K8: Kumar Nayak | L8: Jish C Verghese | M8: Complete
A9: 4 | B9: 4 | D9: 30/2 | E9: DA+0 | F9: SANDY | G9: 13.11.23 | H9: 15.11.23 | I9: 16.11.23 | J9: Shakti Construction | K9: Kumar Nayak | L9: Jish C Verghese | M9: Complete
A10: 5 | B10: 5 | D10: 32/0 | E10: DB2+6 | F10: SANDY | G10: 18.11.23 | H10: 20.11.23 | I10: 28.11.23 | J10: Shakti Construction | K10: Dipesh | L10: Jish C Verghese | M10: Complete
B11: Dec-23
A12: 1 | B12: 6 | D12: 31/3 | E12: DA+0 | F12: SANDY | G12: 28.11.23 | H12: 30.11.23 | I12: 04.12.23 | J12: Shakti Construction | K12: Dipesh | L12: Jish C Verghese | M12: Complete

Sheet Sheet2
C2: S.No | D2: Line | E2: Activity | F2: UOM | G2: LOA Qty | H2: L2 till Sep'25 | I2: Completed till Date | J2: Balance | K2: WIP | L2: Gangs | M2: Remarks
C3: 1 | D3: Samba- Jalandhar | E3: Survey | F3: Km | G3: 144 | H3: 70 | I3: 129.36 | J3: =G3-I3 -> 14.64 | L3: 2
E4: Foundation | F4: Nos | G4: 434 | H4: 17 | I4: 2 | J4: =G4-I4 -> 432 | K4: 4 | L4: 3
C5: 2 | D5: Kishepur- Samba | E5: Survey | F5: Km | G5: 33.103 | H5: 20 | I5: 8.56 | J5: =G5-I5 -> 24.543 | K5: 0.3 | L5: 1
E6: Foundation | F6: Nos | G6: 129 | J6: =G6-I6 -> 129
C7: 3 | D7: LILO-Kisthwar | E7: Survey | F7: Km | G7: 2.18 | H7: 2.18 | I7: 2.18 | J7: =G7-I7 -> 0
E8: Foundation | F8: Nos | G8: 14 | H8: 6 | J8: =G8-I8 -> 14
D9: Total | E9: Survey | F9: Km | G9: =G7+G5+G3 -> 179.283 | H9: =H7+H5+H3 -> 92.18 | I9: =I7+I5+I3 -> 140.1 | J9: =G9-I9 -> 39.183 | K9: =K7+K5+K3 -> 0.3 | L9: =L7+L5+L3 -> 3
E10: Foundation | F10: Nos | G10: =G8+G6+G4 -> 577 | H10: =H8+H6+H4 -> 23 | I10: =I8+I6+I4 -> 2 | J10: =G10-I10 -> 575 | K10: =K8+K6+K4 -> 4 | L10: =L8+L6+L4 -> 3
P13: S.No | Q13: Loc | R13: TOT | S13: S.No | T13: Loc | U13: TOT
P14: 1 | Q14: AP156 | R14: DC+0 | S14: =10+1 -> 11 | T14: AP91 | U14: DD+25
P15: =P14+1 -> 2 | Q15: 70/2 | R15: DA+0 | S15: =S14+1 -> 12 | T15: 153/2 | U15: DA+3
P16: =P15+1 -> 3 | Q16: 153/1 | R16: DA+0
P17: =P16+1 -> 4 | Q17: AP111 | R17: DC+0
P18: =P17+1 -> 5 | Q18: 136/3 | R18: DA+0
P19: =P18+1 -> 6 | Q19: 157/1 | R19: DA+0
P20: =P19+1 -> 7 | Q20: AP150 | R20: DC+0
P21: =P20+1 -> 8 | Q21: AP70 | R21: DC+3
P22: =P21+1 -> 9 | Q22: 136/4 | R22: DA+3
P23: =P22+1 -> 10 | Q23: AP68 | R23: DB+0

Sheet Sheet3
B2: Line | C2: Activity | D2: Section | E2: L2 Oct'25 | F2: Plan Oct'25 | G2: L2 Nov'25 | H2: Plan Nov'25 | I2: L2 Dec'25 | J2: Plan Dec'25 | K2: L2 (Oct'25-Dec'25) | L2: Plan (Oct'25-Dec'25)
B3: Samba-Jalandhar | C3: FDN | D3: Jammu | E3: 25 | F3: 10 | G3: 35 | H3: 10 | I3: 40 | J3: 20 | K3: =E3+G3+I3 -> 100 | L3: =F3+H3+J3+F5+H5+J5 -> 110
C4: Gangs | F4: 3 | H4: 3 | J4: 6
C5: FDN | D5: Punjab | F5: 15 | H5: 25 | J5: 30
C6: Gangs | F6: 5 | H6: 6 | J6: 6
B7: Kishenpur-Samba | C7: FDN | D7: Jammu | E7: 2 | G7: 7 | H7: 5 | I7: 10 | J7: 8 | K7: =E7+G7+I7 -> 19 | L7: =F7+H7+J7 -> 13
C8: Gangs | H8: 3 | J8: 4
B9: LILO-Kishtwar | C9: FDN | D9: Kishtwar | E9: 2 | G9: 2 | H9: 1 | J9: 1 | K9: =E9+G9+I9 -> 4 | L9: =F9+H9+J9 -> 2
C10: Gangs | H10: 1 | J10: 1
B11: Total | C11: FDN | E11: =E9+E7+E3 -> 29 | F11: =F3+F5+F7+F9 -> 25 | G11: =G9+G7+G3 -> 44 | H11: =H3+H5+H7+H9 -> 41 | I11: =I9+I7+I3 -> 50 | J11: =J3+J5+J7+J9 -> 59 | K11: =K9+K7+K3 -> 123 | L11: =L9+L7+L3 -> 125
C12: Gangs | F12: =F6+F4+F8+F10 -> 8 | H12: =H6+H4+H8+H10 -> 13 | J12: =J6+J4+J8+J10 -> 17

Sheet Sheet4
D6: Line | E6: Portion | F6: Section | G6: Length | H6: ROW Lead | I6: ROW Team | J6: Remarks
G7: Km | I7: Currently Working
D8: Samba-Jalandhar | E8: Jammu | F8: Gantry-AP52 | G8: 47 | H8: Karmanya Pathania | I8: ROW Team-1 Akhil S ( Engineer) / Radhe Shyam (Supervisor) | J8: At site since the works are in initial phase , hence we have engaged site engineer/supervisor for ROW document collection for time being , further we can engage separate ROW team as per requirement
E9: Punjab | F9: AP52 - AP115 | G9: 47 | I9: ROW Team -2 K Govind ( Section In charge) / Kuldeep Singh ( DET)
F10: AP115 - AP187 | G10: 48 | I10: ROW Team -3 Manish Nirala (Section In charge) / Govardhan (DET)
D11: Kishenpur-Samba | F11: Gantry- AP109 | G11: 33 | I11: ROW Team -4 Mukesh ( Admin) /Yadhuveer (Supervisor) | J11: Due to heavy rains/landslides local administration blocked the roads
D12: LILO | E12: Kishtewar | F12: AP1-Tapping Point | G12: 2.1 | J12: Due to heavy rains/landslides local administration blocked the roads

Sheet Sheet5

Sheet ROW
A1: KEC INTERNATIONAL LIMITED | F1: Date | G1: 46083
A2: 400kv D/C Samba-Jalandhar T/L-Punjab Portion
D4: Submitted | E4: =COUNTIF(E7:E247,"Submitted") -> 109 | F4: =COUNTIF(F7:F247,"Submitted") -> 90
D5: File Ready | E5: =COUNTIF(E7:E247,"File Ready") -> 10 | F5: =COUNTIF(F7:F247,"File Ready") -> 8
A6: S.No | B6: Tower | C6: TOT | D6: Foundation Completion Status | E6: Crop | F6: Land | G6: Remarks
A7: 1 | B7: AP53 | C7: DC+0
A8: =A7+1 -> 2 | B8: AP54 | C8: DC+6
A9: =A8+1 -> 3 | B9: AP55 | C9: DD+3
A10: =A9+1 -> 4 | B10: 55/1 | C10: DA+6
A11: =A10+1 -> 5 | B11: AP56 | C11: DC+3
A12: =A11+1 -> 6 | B12: 56/1 | C12: DA+6
A13: =A12+1 -> 7 | B13: 56/2 | C13: DA+3
A14: =A13+1 -> 8 | B14: 56/3 | C14: DA+6 | D14: WIP
A15: =A14+1 -> 9 | B15: 56/4 | C15: DA+6
A16: =A15+1 -> 10 | B16: AP57 | C16: DD+3
A17: =A16+1 -> 11 | B17: 57/1 | C17: DA+0
A18: =A17+1 -> 12 | B18: 57/2 | C18: DA+0
A19: =A18+1 -> 13 | B19: AP58 | C19: DC+0
A20: =A19+1 -> 14 | B20: AP59 | C20: DD+6
A21: =A20+1 -> 15 | B21: 59/1 | C21: DA+3
A22: =A21+1 -> 16 | B22: AP60 | C22: DB+6
A23: =A22+1 -> 17 | B23: 60/1 | C23: DA+0
A24: =A23+1 -> 18 | B24: AP61 | C24: DC+0
A25: =A24+1 -> 19 | B25: 61/1 | C25: DA+0
A26: =A25+1 -> 20 | B26: AP62 | C26: DB+0
... A40: =A39+1 -> 34 | B40: 67/1 | C40: DA+0
A41: =A40+1 -> 35 | B41: 67/2 | C41: DA+0 | D41: WIP
A42: =A41+1 -> 36 | B42: 67/3 | C42: DA+0 | D42: C
A43: =A42+1 -> 37 | B43: AP68 | C43: DB+0 | D43: C | E43: Submitted | F43: Submitted
A44: =A43+1 -> 38 | B44: AP69 | C44: DB+0 | D44: C
A45: =A44+1 -> 39 | B45: 69/1 | C45: DA+0 | D45: C | E45: Submitted | F45: Submitted
A46: =A45+1 -> 40 | B46: 69/2 | C46: DA+0 | D46: C | E46: Submitted | F46: Submitted
A47: =A46+1 -> 41 | B47: 69/3 | C47: DA+0 | D47: C | E47: Submitted | F47: Submitted
A48: =A47+1 -> 42 | B48: AP70 | C48: DC+3 | D48: C | E48: File Ready | F48: File Ready
A49: =A48+1 -> 43 | B49: 70/1 | C49: DA+9 | D49: C | E49: File Ready
A50: =A49+1 -> 44 | B50: 70/2 | C50: DA+0 | D50: C | E50: File Ready
A51: =A50+1 -> 45 | B51: AP70/3 | C51: DD+18
A52: =A51+1 -> 46 | B52: AP71 | C52: DC+9 | D52: WIP
A53: =A52+1 -> 47 | B53: 71/1 | C53: DA+3 | E53: Submitted | F53: Submitted
A54: =A53+1 -> 48 | B54: 71/2 | C54: DA+9 | D54: C
...

Sheet Sheet13 (2)
C2: Paticulars | D2: Plain Terrain | E2: Hilly Terrain
C3: Line Length (KM) | D3: 137 KM | E3: 36 KM
D4: =137/173 -> 0.79190751 | E4: =36/173 -> 0.20809249

Sheet TB-605
A1: s | B1: Project Code | C1: TB-605 | D1: Date | E1: 46118 | H1: President-T & D | I1: Ganesh Srinivasan
B2: Project Name | C2: Transmission Line Portion for “Transmission scheme for evacuation of power from Ratle HEP (850 MW) & Kiru HEP (624 MW): Part-A” | F2: LOA Start Date | G2: 45793 | H2: SBU Head- T&D | I2: Rajinder Gupta
B3: Client Name | C3: Ratle Kiru Power Transmission Ltd | F3: LOA End Date | G3: 46461 | H3: PCH | I3: Dhiraj Vashisth
B4: Revised End Date | F4: Planning | G4: Aditya. M | H4: Project Manager | I4: Mithu Dutta
A5: Progress Summary - Ratle Kiru Power Transmission Ltd
A6: Activity | B6: Final Estimated Qty | C6: Cumulative L2 till Last Month | D6: Cumulative Progress till Last Month | E6: L2 for present Month | F6: Plan for the Month | G6: Today's Progress | H6: Progress till Date for the Month | I6: L2 till Current Month | J6: Completed till Date | K6: Balance Work | L6: Under Progress | M6: Gangs at Present | N6: Remarks | T6: =84 -> 84
A7: Check Survey | B7: =B16+B24+B32+B40 -> 173.438 | C7: =C16+C24+C32+C40 -> 179.203 | D7: =D16+D24+D32+D40 -> 167.958 | E7: =E16+E24+E32+E40 -> 0 | F7: =F16+F24+F32+F40 -> 0 | G7: =G16+G24+G32+G40 -> 0 | H7: =H16+H24+H32+H40 -> 0 | I7: =+C7+E7 -> 179.203 | J7: =+H7+D7 -> 167.958 | L7: =L16+L24+L32+L40 -> 0 | M7: =M16+M24+M32+M40 -> 3 | T7: 101.77
A8: Foundation | B8: =B17+B25+B33+B41 -> 523 | C8: =C17+C25+C33+C41 -> 316 | D8: =D17+D25+D33+D41 -> 274 | E8: =E17+E25+E33+E41 -> 54 | F8: =F17+F25+F33+F41 -> 87 | G8: =G17+G25+G33+G41 -> 1 | H8: =H17+H25+H33+H41 -> 3 | I8: =+C8+E8 -> 370 | J8: =+H8+D8 -> 277 | K8: =+B8-J8 -> 246 | L8: =L17+L25+L33+L41 -> 24 | M8: =M17+M25+M33+M41 -> 27 | T8: 946.43
A9: Earthing | B9: =B18+B26+B34+B42 -> 523 | C9: =C18+C26+C34+C42 -> 316 | D9: =D18+D26+D34+D42 -> 235 | E9: =E18+E26+E34+E42 -> 54 | F9: =F18+F26+F34+F42 -> 87 | G9: =G18+G26+G34+G42 -> 0 | H9: =H18+H26+H34+H42 -> 5 | I9: =+C9+E9 -> 370 | J9: =+H9+D9 -> 240 | K9: =+B9-J9 -> 283 | L9: =L18+L26+L34+L42 -> 0 | M9: =M18+M26+M34+M42 -> 0 | T9: 1200
A10: Tower Erection | B10: =B19+B27+B35+B43 -> 523 | C10: =C19+C27+C35+C43 -> 177 | D10: =D19+D27+D35+D43 -> 105 | E10: =E19+E27+E35+E43 -> 62 | F10: =F19+F27+F35+F43 -> 87 | G10: =G19+G27+G35+G43 -> 2 | H10: =H19+H27+H35+H43 -> 8 | I10: =+C10+E10 -> 239 | J10: =+H10+D10 -> 113 | K10: =+B10-J10 -> 410 | L10: =L19+L27+L35+L43 -> 12 | M10: =M19+M27+M35+M43 -> 12
A11: Tack welding | B11: =B20+B28+B36+B44 -> 523 | C11: =C20+C28+C36+C44 -> 177 | D11: =D20+D28+D36+D44 -> 0 | E11: =E20+E28+E36+E44 -> 62 | F11: =F20+F28+F36+F44 -> 87 | G11: =G20+G28+G36+G44 -> 0 | H11: =H20+H28+H36+H44 -> 0 | I11: =+C11+E11 -> 239 | J11: =+H11+D11 -> 0 | K11: =+B11-J11 -> 523 | L11: =L20+L28+L36+L44 -> 0 | M11: =M20+M28+M36+M44 -> 0
A12: Stringing | B12: =B21+B29+B37+B45 -> 173.438 | C12: =C21+C29+C37+C45 -> 0 | D12: =D21+D29+D37+D45 -> 0 | E12: =E21+E29+E37+E45 -> 0 | F12: =F21+F29+F37+F45 -> 0 | G12: =G21+G29+G37+G45 -> 0 | H12: =H21+H29+H37+H45 -> 0 | I12: =+C12+E12 -> 0 | J12: =+H12+D12 -> 0 | K12: =+B12-J12 -> 173.438 | L12: =L21+L29+L37+L45 -> 0 | M12: =M21+M29+M37+M45 -> 0
A13: Line Wise Progress
A14: 400 kV Samba- Jalandhar D/C Line(Quad) - Wind Zone - 5-Jammu Portion
A15: Activity | B15: Final Estimated Qty | C15: Cumulative L2 till Last Month | D15: Cumulative Progress till Last Month | E15: L2 for present Month | F15: Plan for the Month | G15: Today's Progress | H15: Progress till Date for the Month | I15: L2 till Current Month | J15: Completed till Date | K15: Balance Work | L15: Under Progress | M15: Gangs at Present | N15: Remarks
A16: Check Survey | B16: 46.92 | C16: 49 | D16: 46.44 | I16: =+C16+E16 -> 49 | J16: =+H16+D16 -> 46.44 | K16: =+B16-J16 -> 0.48 | N16: Submitted - 46 Km Approved - 46 Km
A17: Foundation | B17: 127 | C17: 85 | D17: 80 | E17: 15 | F17: 30 | H17: 1 | I17: =+C17+E17 -> 100 | J17: =+H17+D17 -> 81 | K17: =+B17-J17 -> 46 | L17: 8 | M17: 9
A18: Earthing | B18: 127 | C18: 85 | D18: 71 | E18: 15 | F18: 30 | I18: =+C18+E18 -> 100 | J18: =+H18+D18 -> 71 | K18: =+B18-J18 -> 56
A19: Tower Erection | B19: 127 | C19: 58 | D19: 43 | E19: 15 | F19: 30 | G19: 2 | H19: 5 | I19: =+C19+E19 -> 73 | J19: =+H19+D19 -> 48 | K19: =+B19-J19 -> 79 | L19: 5 | M19: 5
A20: Tack welding | B20: 127 | C20: 58 | D20: 0 | E20: 15 | F20: 30 | I20: =+C20+E20 -> 73 | J20: =+H20+D20 -> 0 | K20: =+B20-J20 -> 127 | L20: 0 | M20: 0
A21: Stringing | B21: 46.92 | C21: 0 | D21: 0 | I21: =+C21+E21 -> 0 | J21: =+H21+D21 -> 0 | K21: =+B21-J21 -> 46.92 | L21: 0 | M21: 0
A22: 400 kV Samba- Jalandhar D/C Line(Quad) - Wind Zone - 5- Punjab Portion
A23: Activity | B23: Final Estimated Qty | C23: Cumulative L2 till Last Month | D23: Cumulative Progress till Last Month | E23: L2 for present Month | F23: Plan for the Month | G23: Today's Progress | H23: Progress till Date for the Month | I23: L2 till Current Month | J23: Completed till Date | K23: Balance Work | L23: Under Progress | M23: Gangs at Present | N23: Remarks
A24: Check Survey | B24: 90 | C24: 95 | D24: 85 | I24: =+C24+E24 -> 95 | J24: 85 | K24: =+B24-J24 -> 5 | M24: 2 | N24: Submitted - 90 Km Approved - 90 Km
A25: Foundation | B25: 262 | C25: 167 | D25: 150 | E25: 30 | F25: 40 | G25: 1 | H25: 2 | I25: =+C25+E25 -> 197 | J25: =+H25+D25 -> 152 | K25: =+B25-J25 -> 110 | L25: 9 | M25: 10
A26: Earthing | B26: 262 | C26: 167 | D26: 132 | E26: 30 | F26: 40 | H26: 5 | I26: =+C26+E26 -> 197 | J26: =+H26+D26 -> 137 | K26: =+B26-J26 -> 125 | L26: 0
A27: Tower Erection | B27: 262 | C27: 112 | D27: 60 | E27: 30 | F27: 45 | H27: 3 | I27: =+C27+E27 -> 142 | J27: =+H27+D27 -> 63 | K27: =+B27-J27 -> 199 | L27: 6 | M27: 6 | S27: 157405
A28: Tack welding | B28: 262 | C28: 112 | D28: 0 | E28: 30 | F28: 45 | I28: =+C28+E28 -> 142 | J28: =+H28+D28 -> 0 | K28: =+B28-J28 -> 262 | L28: 0 | M28: 0 | Q28: =97200/12 -> 8100 | R28: =67500 -> 67500 | S28: =R28*12% -> 8100
A29: Stringing | B29: 90 | C29: 0 | D29: 0 | I29: =+C29+E29 -> 0 | J29: =+H29+D29 -> 0 | K29: =+B29-J29 -> 90 | L29: 0 | M29: 0 | S29: =S27-S28 -> 149305
A30: 400 kV Kishenpur-Samba D/C Line (Quad) - Wind Zone-5
A31: Activity | B31: Final Estimated Qty | C31: Cumulative L2 till Last Month | D31: Cumulative Progress till Last Month | E31: L2 for present Month | F31: Plan for the Month | G31: Today's Progress | H31: Progress till Date for the Month | I31: L2 till Current Month | J31: Completed till Date | K31: Balance Work | L31: Under Progress | M31: Gangs at Present | N31: Remarks
A32: Check Survey | B32: 33.103 | C32: 33.103 | D32: 33.103 | I32: =+C32+E32 -> 33.103 | J32: =+H32+D32 -> 33.103 | K32: =+B32-J32 -> 0 | M32: 1 | N32: Submitted -30.26 Km Approved - 30.26 Km
A33: Foundation | B33: 116 | C33: 50 | D33: 44 | E33: 9 | F33: 12 | I33: =+C33+E33 -> 59 | J33: =+H33+D33 -> 44 | K33: =+B33-J33 -> 72 | L33: 5 | M33: 5
A34: Earthing | B34: 116 | C34: 50 | D34: 32 | E34: 9 | F34: 12 | I34: =+C34+E34 -> 59 | J34: =+H34+D34 -> 32 | K34: =+B34-J34 -> 84 | L34: 0
A35: Tower Erection | B35: 116 | C35: 5 | D35: 2 | E35: 15 | F35: 12 | I35: =+C35+E35 -> 20 | J35: =+H35+D35 -> 2 | K35: =+B35-J35 -> 114 | L35: 1 | M35: 1
A36: Tack welding | B36: 116 | C36: 5 | D36: 0 | E36: 15 | F36: 12 | I36: =+C36+E36 -> 20 | J36: =+H36+D36 -> 0 | K36: =+B36-J36 -> 116 | L36: 0 | M36: 0
A37: Stringing | B37: 33.103 | C37: 0 | D37: 0 | I37: =+C37+E37 -> 0 | J37: =+H37+D37 -> 0 | K37: =+B37-J37 -> 33.103 | L37: 0 | M37: 0
A38: 400kV DC LILO at Kistwar(Twin) Line - Wind Zone-2
A39: Activity | B39: Final Estimated Qty | C39: Cumulative L2 till Last Month | D39: Cumulative Progress till Last Month | E39: L2 for present Month | F39: Plan for the Month | G39: Today's Progress | H39: Progress till Date for the Month | I39: L2 till Current Month | J39: Completed till Date | K39: Balance Work | L39: Under Progress | M39: Gangs at Present | N39: Remarks
A40: Check Survey | B40: 3.415 | C40: 2.1 | D40: 3.415 | I40: =+C40+F40 -> 2.1 | J40: =+H40+D40 -> 3.415 | K40: =+B40-J40 -> 0
...

Sheet Sheet16
C2: S.No | D2: Gang | E2: Line | F2: Remarks
C3: 1 | D3: Pawan Kumar Sharma | E3: J-S (Jammu) | F3: Gang idle since 4-4-26 at Loc: 40/3 due to ROW
C4: =C3+1 -> 2 | D4: Md. Ikrar | E4: J-S(Punjab) | F4: Loc: 144/4 completed on 5-4-2026 and no work front available due to crop harvesting
C5: =C4+1 -> 3 | D5: Ms. Hussain | E5: J-S(Punjab) | F5: Loc: 144/3 will be completed on 6-4-2026 and no work front availabl due to crop harvesting
C6: =C5+1 -> 4

Sheet Sheet14
B1: S.No | C1: Month | D1: Concreting | F1: Cement | G1: TMT
D2: M10 | E2: M20
D3: M3 | E3: M3 | F3: Bags | G3: MT
B4: 1 | C4: 45901 | D4: 14.664 | E4: 135.088 | F4: =ROUND((D4*4.4)+(E4*8),0) -> 1145 | G4: 8.44
B5: =B4+1 -> 2 | C5: 45931 | D5: 76.132 | E5: 667.004 | F5: =ROUND((D5*4.4)+(E5*8),0) -> 5671 | G5: 47.8
B6: =B5+1 -> 3 | C6: 45962 | D6: 283.933 | E6: 2687.36 | F6: =ROUND((D6*4.4)+(E6*8),0) -> 22748 | G6: 176.38
B7: =B6+1 -> 4 | C7: 45992 | D7: 415.90302 | E7: 3983.996 | F7: =ROUND((D7*4.4)+(E7*8),0) -> 33702 | G7: 264.63 | L7: Concreting (M3) | M7: Tower Erection(MT)
B8: =B7+1 -> 5 | C8: 46023 | D8: 411.1974 | E8: 4750.4 | F8: =ROUND((D8*4.4)+(E8*8),0) -> 39812 | G8: 164.07 | L8: 21381 | M8: 2332
B9: =B8+1 -> 6 | C9: 46054 | D9: 411.1974 | E9: 4300.4 | F9: =ROUND((D9*4.4)+(E9*8),0) -> 36212 | G9: 264.45
B10: =B9+1 -> 7 | C10: 46082 | D10: 296.343 | E10: 2947.484 | F10: =ROUND((D10*4.4)+(E10*8),0) -> 24884 | G10: 199.54
B11: Total | D11: =SUM(D4:D10) -> 1909.3698 | E11: =SUM(E4:E10) -> 19471.732 | F11: =SUM(F4:F10) -> 164174 | G11: =SUM(G4:G10) -> 1125.31

Sheet Sheet12
C1: Supply Portion
C2: S.No | D2: Material | E2: UOM | F2: BOQ Qty | G2: Final Estimated Qty | H2: L2 till Mar'26 | I2: Supplied Qty | J2: Balance to Supply
C3: 1 | D3: Stubs | E3: EA | F3: 434 | G3: 389 | H3: 434 | I3: 353 | J3: =G3-I3 -> 36
C4: 2 | D4: Towers | E4: EA | F4: 434 | G4: 389 | H4: 216 | I4: 314 | J4: =G4-I4 -> 75
C7: S.No | D7: Activity | E7: UOM | F7: BOQ Qty | G7: Final Estimated Qty | H7: L2 till Feb'26 | I7: Completed till Feb'26 | J7: L2 Mar'26 | K7: Progress in Mar'26 | L7: Cumm L2 till Mar'26 | M7: Cumm. Progress till Mar'26 | N7: Balance | O7: Remarks
C8: 400 kV D/C Samba - Jalandhar TL
C9: 1 | D9: Survey | E9: Km | F9: 143 | G9: 137 | H9: 143 | I9: 136 | L9: =H9+J9 -> 143 | M9: =I9+K9 -> 136 | N9: =G9-M9 -> 1
C10: 2 | D10: Foundation | E10: EA | F10: 434 | G10: 389 | H10: 207 | I10: 202 | J10: 45 | K10: 28 | L10: =H10+J10 -> 252 | M10: =I10+K10 -> 230 | N10: =G10-M10 -> 159 | O10: 19 Gangs
C11: 3 | D11: Tower Erection | E11: EA | F11: 434 | G11: 389 | H11: 125 | I11: 55 | J11: 45 | K11: 48 | L11: =H11+J11 -> 170 | M11: =I11+K11 -> 103 | N11: =G11-M11 -> 286 | O11: 10 Gangs
C12: 4 | D12: Stringing | E12: Km | F12: 143 | G12: 137 | N12: =G12-M12 -> 137
C13: 400kV D/C Samba -Kishenpur TL
C14: 1 | D14: Survey | E14: Km | F14: 33 | G14: 33 | H14: 33 | I14: 33 | L14: =H14+J14 -> 33 | M14: =I14+K14 -> 33
C15: 2 | D15: Foundation | E15: EA | F15: 129 | G15: 116 | H15: 39 | I15: 37 | J15: 11 | K15: 7 | L15: =H15+J15 -> 50 | M15: =I15+K15 -> 44 | N15: =G15-M15 -> 72 | O15: 6 Gangs
C16: 3 | D16: Tower Erection | E16: EA | F16: 129 | G16: 116 | J16: 5 | K16: 2 | L16: =H16+J16 -> 5 | M16: =I16+K16 -> 2 | N16: =G16-M16 -> 114 | O16: 1 Gang
C17: 4 | D17: Stringing | E17: Km | F17: 33 | G17: 33 | N17: =G17-M17 -> 33
C18: LILO-Kisthwar
C19: 1 | D19: Survey | E19: Km | F19: 2 | G19: 3.4 | H19: 2 | I19: 3.4 | L19: =H19+J19 -> 2 | M19: =I19+K19 -> 3.4
C20: 2 | D20: Foundation | E20: EA | F20: 14 | G20: 18 | H20: 14 | L20: =H20+J20 -> 14 | N20: =G20-M20 -> 18 | O20: 3 Gangs
C21: 3 | D21: Tower Erection | E21: EA | F21: 14 | G21: 18 | J21: 2 | L21: =H21+J21 -> 2 | N21: =G21-M21 -> 18
C22: 4 | D22: Stringing | E22: Km | F22: 2 | G22: 3.4 | N22: =G22-M22 -> 3.4
C27: Supply Portion
C28: S.No | D28: Material | E28: UOM | F28: BOQ Qty | G28: Final Estimated Qty | H28: L2 till Mar'26 | I28: Supplied Qty | J28: Balance to Supply
C29: 1 | D29: Stubs | E29: EA | F29: 129 | G29: 116 | H29: 129 | I29: 64 | J29: =G29-I29 -> 52
C30: 2 | D30: Towers | E30: EA | F30: 129 | G30: 116 | H30: 129 | I30: 41 | J30: =G30-I30 -> 75
C32: Service Portion
C33: S.No | D33: Activity | E33: UOM | F33: BOQ Qty | G33: Final Estimated Qty | H33: L2 till Feb'26 | I33: Completed till Feb'26 | J33: L2 Mar'26 | K33: Progress in Mar'26 | L33: Cumm L2 till Mar'26 | M33: Cumm. Progress till Mar'26 | N33: Balance | O33: Remarks
C39: Supply Portion
C40: S.No | D40: Material | E40: UOM | F40: BOQ Qty | G40: Final Estimated Qty | H40: L2 till Mar'26 | I40: Supplied Qty | J40: Balance to Supply
C41: 1 | D41: Stubs | E41: EA | F41: 14 | G41: 18 | H41: 14 | I41: 10 | J41: =G41-I41 -> 8
C42: 2 | D42: Towers | E42: EA | F42: 14 | G42: 18 | H42: 14 | J42: =G42-I42 -> 18
C45: S.No | D45: Activity | E45: UOM | F45: BOQ Qty | G45: Final Estimated Qty | H45: L2 till Feb'26 | I45: Completed till Feb'26 | J45: L2 Mar'26 | K45: Progress in Mar'26 | L45: Cumm L2 till Mar'26 | M45: Cumm. Progress till Mar'26 | N45: Balance | O45: Remarks

Sheet Sheet13
C2: Paticulars | D2: Jammu Portion | E2: Punjab Portion
C3: Line Length (KM) | D3: 83 KM | E3: 90 KM
D4: =83/173 -> 0.47976879 | E4: =90/173 -> 0.52023121

Sheet Sheet15
C2: Supply Portion
C3: S.No | D3: Line | E3: LOA Cr | F3: Billed till date Cr | G3: Balance Cr
C4: 1 | D4: 400 kV Samba- Jalandhar D/C line (Quad) | E4: 155.09 | F4: 88.06 | G4: =E4-F4 -> 67.03
C5: 2 | D5: 400 kV Kishenpur-Samba D/C line (Quad) | E5: 67.47 | F5: =176387266/10^7 -> 17.638727 | G5: =E5-F5 -> 49.831273
C6: 3 | D6: LILO of 400 kV Kishenpur- Dulhasti line (Twin) at Kishtwar S/s | E6: 6.43 | F6: =1439185/10^7 -> 0.1439185 | G6: =E6-F6 -> 6.2860815
C7: Total | E7: =SUM(E4:E6) -> 228.99 | F7: =SUM(F4:F6) -> 105.84265 | G7: =SUM(G4:G6) -> 123.14735
C9: Service Portion
C10: S.No | D10: Line | E10: LOA Cr | F10: Billed till date Cr | G10: Balance Cr
C11: 1 | D11: 400 kV Samba- Jalandhar D/C line (Quad) | E11: 119.32273 | F11: =305299128/10^7 -> 30.529913 | G11: =E11-F11 -> 88.792813
C12: =C11+1 -> 2 | D12: 400 kV Kishenpur-Samba D/C line (Quad) | E12: 50.13038 | F12: =46321408/10^7 -> 4.6321408 | G12: =E12-F12 -> 45.498239 | J12: =88.06+17.64+0.14 -> 105.84
C13: =C12+1 -> 3 | D13: LILO of 400 kV Kishenpur- Dulhasti line (Twin) at Kishtwar S/s | E13: 4.4045142 | G13: =E13-F13 -> 4.4045142
C14: =C13+1 -> 4 | D14: Unit Rate Schedule for Services | E14: 6.4654119 | G14: =E14-F14 -> 6.4654119
C15: =C14+1 -> 5 | D15: ROW Schedule | E15: 5.9322034 | G15: =E15-F15 -> 5.9322034
C16: Total | E16: =SUM(E11:E15) -> 186.25524 | F16: =SUM(F11:F15) -> 35.162054 | G16: =SUM(G11:G15) -> 151.09318
F17: 1.5

Sheet TB401 DPR
A1: Project Progress for TB-401/408,Section-II
A2: 765KV D/C Fategarh-III Beawar Transmission Line | D2: TB-401 | G2: LOA Date | I2: Pkg-G -26.04.23 | L2: Completion Period | N2: 45747 | Q2: Date: | R2: =TODAY() -> 46119
D3: TB-408 | I3: Pkg-F - 11.09.23 | L3: Completion Period | N3: 45747
A4: .
A5: Activity | B5: Qty as per LOA | C5: Qty Received | D5: L2 | F5: Overall Progress | H5: Mar'25 | J5: Balance | K5: Apr'25 | O5: Plan | Q5: Remarks
D6: 45656 | E6: Till Mar-25 | F6: As on date | G6: Till Mar-25 | H6: Plan | I6: Actual | J6: As on date | K6: Plan | L6: WIP | M6: Today comp | N6: Actual | O6: 45536 | P6: 45474
A7: Details Survey | B7: 215 | C7: =C8+C9 -> 189.53 | E7: =E8+E9 -> 203 | F7: =F8+F9 -> 199.841 | G7: =G8+G9 -> 199.841
A8: Pkg-G (Section-II) | C8: 101.1 | E8: =215/2 -> 107.5 | F8: 101.1 | G8: 101.1
A9: Pkg-F (Section-II) | C9: 88.43 | E9: =(65+65+41+20)/2 -> 95.5 | F9: 98.741 | G9: 98.741
A10: Check Survey | B10: 215 | C10: =C11+C12 -> 189.53 | D10: =D11+D12 -> 0 | E10: =E11+E12 -> 203 | F10: =F11+F12 -> 189.526 | G10: =G11+G12 -> 184.552 | H10: =H11+H12 -> 14.88 | I10: =I11+I12 -> 6.08 | J10: =J11+J12 -> 0.004 | ... L10: =L11+L12 -> 0 | N10: =N11+N12 -> 4.974 | O10: =O11+O12 -> 0
A11: Pkg-G (Section-II) | C11: 101.1 | E11: =215/2 -> 107.5 | F11: =G11+N11 -> 101.096 | G11: 101.096 | H11: 6.08 | I11: 6.08 | J11: =C11-G11-N11 -> 0.004
A12: Pkg-F (Section-II) | C12: 88.43 | E12: =(65+65+41+20)/2 -> 95.5 | F12: =G12+N12 -> 88.43 | G12: =79.653+3.803 -> 83.456 | H12: 8.8 | J12: =C12-G12-N12 -> 0 | N12: 4.974
A13: Foundation | B13: 534 | C13: =C14+C15 -> 488 | D13: =D14+D15 -> 0 | E13: =E14+E15 -> 488 | F13: =F14+F15 -> 485 | G13: =G14+G15 -> 485 | H13: =H14+H15 -> 9 | I13: =I14+I15 -> 6 | J13: =J14+J15 -> 3 | ... L13: =L14+L15 -> 3 | N13: =N14+N15 -> 0 | O13: =O14+O15 -> 0 | P13: =P14+P15 -> 0
A14: Pkg-G (Section-II) | C14: 265 | E14: 265 | F14: =G14+N14 -> 265 | G14: 265 | H14: 5 | I14: 5 | J14: =C14-G14-N14 -> 0 | S14: 9649905358 | T14: D S Jangid
A15: Pkg-F (Section-II) | C15: 223 | E15: 223 | F15: =G15+N15 -> 220 | G15: 220 | H15: 4 | I15: 1 | J15: =C15-G15-N15 -> 3 | L15: 3 | S15: 7014675307 | T15: jangid
A16: Gang / Worker | K16: 10/180 | L16: 02/55
A17: Erection | B17: 534 | C17: =C18+C19 -> 488 | D17: =D18+D19 -> 0 | E17: =E18+E19 -> 488 | F17: =F18+F19 -> 367 | G17: =G18+G19 -> 365 | H17: =H18+H19 -> 36 | I17: =I18+I19 -> 24 | J17: =J18+J19 -> 121 | ... P17: =P18+P19 -> 0
A18: Pkg-G (Section-II) | C18: 265 | E18: 265 | F18: =G18+N18 -> 201 | G18: 201 | H18: 20 | I18: 11 | J18: =C18-G18-N18 -> 64 | L18: 0
A19: Pkg-F (Section-II) | C19: 223 | E19: 223 | F19: =G19+N19 -> 166 | G19: 164 | H19: 16 | I19: 13 | J19: =C19-G19-N19 -> 57 | L19: 4 | M19: 1 | N19: 2 | Q19: 70/10 Complete
A20: Gang / Worker | K20: 7/240 | L20: 4/241
A21: Stringing Payout | B21: 215 | C21: =C22+C23 -> 189.53 | D21: =D22+D23 -> 0 | E21: =E22+E23 -> 189.53 | F21: =F22+F23 -> 94.743 | G21: =G22+G23 -> 94.743 | H21: =H22+H23 -> 0 | I21: =I22+I23 -> 9.18 | J21: =J22+J23 -> 94.787 | ... O21: =O22+O23 -> 0 | P21: 15
A22: Pkg-G (Section-II) | C22: 101.1 | E22: 101.1 | F22: =G22+N22 -> 52.284 | G22: 52.284 | J22: =C22-G22-N22 -> 48.816
A23: Pkg-F (Section-II) | C23: 88.43 | E23: 88.43 | F23: =G23+N23 -> 42.459 | G23: 42.459 | I23: 9.18 | J23: =C23-G23-N23 -> 45.971 | L23: 1.881
A24: Gang / Worker | L24: 2/154
A25: Stringing Final sag | B25: 215 | C25: =C26+C27 -> 189.53 | D25: =D26+D27 -> 0 | E25: =E26+E27 -> 189.53 | F25: =F26+F27 -> 88.935 | G25: =G26+G27 -> 88.935 | H25: =H26+H27 -> 0 | I25: =I26+I27 -> 14.161 | J25: =J26+J27 -> 100.595 | ... O25: =O26+O27 -> 0 | P25: 15
A26: Pkg-G (Section-II) | C26: 101.1 | E26: 101.1 | F26: =G26+N26 -> 49.703 | G26: 49.703 | I26: 4.981 | J26: =C26-G26-N26 -> 51.397 | L26: =7.562-4.981 -> 2.581
A27: Pkg-F (Section-II) | C27: 88.43 | E27: 88.43 | F27: =G27+N27 -> 39.232 | G27: 39.232 | I27: 9.18 | J27: =C27-G27-N27 -> 49.198 | L27: 3.227
A28: Gang / Worker | L28: 2/154

Sheet Survey-Summary
B1: PROJECT NAME | C1: INDIGRID - 400kV D/C QUAD WZ-5 SAMBA-JALANDHAR & KISHENPUR-SAMBA TL | Z1: COMP | AA1: APPROVED
B2: START DATE (NOA DATE) | C2: 16-MAY-2025 | Z2: PENDING | AA2: UNDER REVIEW
B3: KEC PROJECT | C3: TB-605 | AA3: PENDING
B4: NAME OF CLIENT | C4: RATLE KIRU POWER TRANSMISSION LIMITED
B5: TITLE | C5: SITE SURVEY STATUS
B7: TEAM FORMATION | H7: CHECK SURVEY SUMMARY (KM)
B8: Portion | C8: SURVEY LEAD | D8: TEAM MEMBERS | E8: MACHINE | F8: LINE NAME | G8: SECTION LENGTH | H8: COMPLETED | I8: BALANCE | J8: SUBMITTED | K8: APPROVED | L8: APPROVAL PENDING | M8: REMARK
B9: Jammu | C9: 1)BIPPAN SHARMA | D9: 2) Shiv Kumar( Asst Surveyor) | E9: DGPS-1 TS-02 | F9: 400kV D/C Jalandar - Samba T/L (GANTRY TO AP 52) | G9: 46.915 | H9: =45.61+0.83 -> 46.44 | I9: =G9-H9 -> 0.475 | J9: =39.202+4.505+2.346 -> 46.053 | K9: 46.053 | L9: =J9-K9 -> 0 | M9: 0.48 km is from Sambha Gantyry to AP 4
D10: 3) Sahil Raj(Asst Surveyor) | F10: 400kV D/C Samba - Kishenpur T/L | G10: 33 | H10: =7.63+0.34+0.29+0.3+0.83+2.257+0.79+0.849+1.044+0.76+0.7+0.4+0.3+0.964+0.684+2+3+4 -> 27.138 | I10: =G10-H10 -> 5.862 | J10: 19.6 | K10: 19.6 | L10: =J10-K10 -> 0 | M10: AP4-AP14, AP24-AP55, AP55-AP70, AP70-AP86,AP95-AP109 C/S Completed AP15-AP24 - Re-routing required due to landsliding (Hold) AP86-AP95 - Hold due to under powerline crossing
D11: 4) Sunil (Survey Helper) | F11: LILO at Kistwar | G11: 2.18 | H11: 2.18 | I11: =G11-H11 -> 0 | J11: 2.18 | K11: 2.18 | L11: =J11-K11 -> 0 | M11: Contour completed 12 Locations out of 13 location AP 11 conturing not done due to ROW since 29th Jul'25
D12: 5) Sanjhi Ram((Survey Helper) | I12: =G12-H12 -> 0 | L12: =J12-K12 -> 0
B13: Punjab | C13: 1)RAJ KAMAL GHOSH | D13: 2) Anupam Basak (Survayor DET) | E13: TS-01 | F13: 400kV D/C Jalandar - Samba T/L ( AP 52-115) | G13: 47.25 | H13: 46.474 | I13: =G13-H13 -> 0.776 | J13: 45.892 | K13: =13.05+32.842 -> 45.892 | L13: =J13-K13 -> 0
D14: 3) Kuldeep singh (supervisor DET) | I14: =G14-H14 -> 0 | L14: =J14-K14 -> 0
D15: 4) Vickey Ghosh (Survey DET) | I15: =G15-H15 -> 0 | L15: =J15-K15 -> 0
D16: 5) Rupak Kumar (Survey Helper) | L16: =J16-K16 -> 0
B17: Punjab | C17: 1)SAGAR MAJHI | D17: 2) Surajit Majhi(Asst Surveyor) | E17: TS-01 | F17: 400kV D/C Jalandar - Samba T/L ( AP 115-187) | G17: 47.805 | H17: =34.985+1.456+2.013+2.516 -> 40.97 | I17: =G17-H17 -> 6.835 | J17: 47.81 | K17: 23.519 | L17: =J17-K17 -> 24.291
D18: 3) Rudra Madhav (supervisor DET) | I18: =G18-H18 -> 0 | L18: =J18-K18 -> 0
D19: 4)Gordhan Ram (supervisor DET) | I19: =G19-H19 -> 0 | L19: =J19-K19 -> 0
I20: =G20-H20 -> 0 | L20: =J20-K20 -> 0
B21: TOTAL (KM) | G21: =SUM(G9:G20) -> 177.15 | H21: =SUM(H9:H20) -> 163.202 | I21: =SUM(I9:I20) -> 13.948 | J21: =SUM(J9:J20) -> 161.535 | K21: =SUM(K9:K20) -> 137.244 | L21: =SUM(L9:L20) -> 24.291 | M21: =SUM(M9:M20) -> 0
G26: 400kV D/C Samba-Jalandhar C/S -Details
G27: S.No | H27: Section | I27: Section | J27: Length | K27: Submitted | L27: Approval Date | M27: Remarks
J28: Km | K28: Date
G29: 1 | H29: AP20-AP30 | I29: Jammu | J29: 10.43 | K29: 45846 | L29: 45854
G30: 2 | H30: AP30-AP41 | I30: Jammu | J30: 13.72 | K30: 45857 | L30: 45862
G31: 3 | H31: AP41-AP51 | I31: Jammu | J31: 15.05 | K31: 45868 | L31: 45873
G32: 4 | H32: AP15-AP20 | I32: Jammu | J32: 4.51 | K32: 45908 | L32: 45909
G33: 5 | H33: AP5-AP15 | I33: Jammu | J33: 2.346 | K33: 45918 | L33: 45930
G34: 5 | H34: AP53-AP66 | I34: Punjab | J34: 11.37 | K34: 45875 | L34: 45894
G35: 6 | H35: AP70-AP84 | I35: Punjab | J35: 11.41 | K35: 45885 | L35: 45900
G36: 7 | H36: AP84-AP96 | I36: Punjab | J36: 10.07 | K36: 45890 | L36: 45894
G37: 8 | H37: AP115-AP123 | I37: Punjab | J37: 6.93 | K37: 45888 | L37: 45904
G38: 9 | H38: AP131-AP140 | I38: Punjab | J38: 10.3 | K38: 45888 | L38: 45904
G39: 10 | H39: AP145-AP153 | I39: Punjab | J39: 6.29 | K39: 45892 | L39: 45904
G40: 11 | H40: AP96-AP115 | I40: Punjab | J40: 9.626 | K40: 45913 | L40: 45961
G41: 12 | H41: AP66-AP70 | I41: Punjab | J41: 3.42 | K41: 45919 | L41: 45961
G42: 13 | H42: AP153-AP175 | I42: Punjab | J42: 12.083 | K42: 45922 | M42: Route diversion in between 168-175 to be finalized
G43: Total | J43: =SUM(J29:J42) -> 127.555
G45: 400kV D/C Kishenpur-Samba C/S -Details
G46: S.No | H46: Section | I46: Section | J46: Length | K46: Submitted | L46: Approval Date | M46: Remarks
...

Sheet Sheet6
D2: Survey
D3: Line | E3: Portion | F3: Scope | G3: Completed | H3: Submitted | I3: Approved
D4: S-J | E4: Jammu | F4: 46.92 | G4: 46.44 | H4: 46.44 | I4: 46.44
D5: S-J | E5: Punjab | F5: 95.06 | G5: 95.06 | H5: 84.936 | I5: 72.85
D6: K-S | F6: 33.103 | G6: 23.393 | H6: 16.04 | I6: 10.6
D7: LILO | F7: 2.18 | G7: 2.18 | H7: 2.18 | I7: 2.18
D8: Total | F8: =SUM(F4:F7) -> 177.263 | G8: =SUM(G4:G7) -> 167.073 | H8: =SUM(H4:H7) -> 149.596 | I8: =SUM(I4:I7) -> 132.07
F10: 16.04 | J10: 10.58
F11: 45.892 | J11: 45.892
F12: 46.06 | J12: 46.06
F13: 20.674 | G13: 18.37 | J13: 20.674
F14: 12.08
F15: 2.18
J16: =66.566+6.29 -> 72.856

Sheet Vertical Chart -JS Line Jammu 
A1: KEC INTERNATIONAL LIMITED
A2: 400 kV Samba- Jalandhar D/C Line(Quad) - Wind Zone - 5-Jammu Portion
A3: Vertical Chart
J4: Complete | L4: =COUNTIF($L$8:$L$256,"Clear") -> 91 | M4: =COUNTIF($M$8:$M$256,"C") -> 81 | N4: =COUNTIF($N$8:$N$256,"C") -> 71 | O4: =COUNTIF($O$8:$O$256,"C") -> 48 | P4: =COUNTIF($P$8:$P$256,"C") -> 0
J5: WIP | M5: =COUNTIF($M$8:$M$256,"WIP") -> 8 | N5: =COUNTIF($N$8:$N$256,"WIP") -> 0 | O5: =COUNTIF($O$8:$O$256,"WIP") -> 5 | P5: =COUNTIF($P$8:$P$256,"WIP") -> 0
A6: S.No | B6: Tower | C6: TOT | D6: Angle of Deviation | E6: Raised Chimney | I6: FDN Classification | J6: Span Length (Mtr) | K6: Section Length (m) | L6: ROW | M6: Foundation | N6: Earthing | O6: Tower Erection | P6: Tack Welding | Q6: Stringing | R6: Remarks
E7: LEG A | F7: LEG B | G7: LEG C | H7: LEG D
A8: 1 | B8: AP5 | C8: DD+0 | D8: 47°01'59"LT | E8: 0 | F8: 0 | G8: 0 | H8: 0 | K8: 0
J9: 119.059
A10: =A8+1 -> 2 | B10: AP6 | C10: DD+9 | D10: 40°54'42"RT | E10: 0 | F10: 0 | G10: 0 | H10: 0 | K10: =J9 -> 119.059
J11: 92.496
A12: =A10+1 -> 3 | B12: AP7 | C12: DD+30 | D12: 47°08'48"LT | E12: 4 | F12: 5 | G12: 4 | H12: 3 | I12: WET | K12: =J11 -> 92.496 | L12: Clear | M12: WIP
J13: 134.988 | R13: 400 KV D/C Line Jalandhar to Samba
A14: =A12+1 -> 4 | B14: AP8 | C14: DD+30 | D14: 41°15'08"RT | E14: 4 | F14: 5 | G14: 4 | H14: 3 | K14: =J13 -> 134.988
J15: 365.176
A16: =A14+1 -> 5 | B16: AP9 | C16: DD+9 | D16: 37°05'47"RT | E16: 0 | F16: 0 | G16: 0 | H16: 0 | K16: =J15 -> 365.176
J17: 236.697 | R17: Railway Crossing Electrified (Jammu/Delhi)
A18: =A16+1 -> 6 | B18: AP10 | C18: DD+9 | D18: 20°40'31"LT | E18: 0 | F18: 0 | G18: 0 | H18: 0 | K18: =J17 -> 236.697
J19: 213.252
A20: =A18+1 -> 7 | B20: AP11 | C20: DD+25 | D20: 51°34'02"RT | E20: 0 | F20: 0 | G20: 0 | H20: 0 | K20: =J19 -> 213.252
J21: 206.593 | R21: 400 KV D/C Line Jalandhar to Samba
A22: =A20+1 -> 8 | B22: AP12 | C22: DD+30 | D22: 47°50'13"LT | E22: 0 | F22: 0 | G22: 0 | H22: 0 | I22: WET/PS | K22: =J21 -> 206.593 | L22: Clear | M22: C
J23: 289.862 | R23: 220 KV D/C Line Samba To Hiranagar
A24: =A22+1 -> 9 | B24: AP13 | C24: DD+25 | D24: 39°08'44"LT | E24: 1.5 | F24: 1.5 | G24: 0 | H24: 0 | K24: =J23 -> 289.862
J25: 402.938
A26: =A24+1 -> 10 | B26: AP14 | C26: DB+9 | D26: 14°33'47"RT | E26: 0 | F26: 0 | G26: 2 | H26: 0 | I26: DFR | K26: =J25 -> 402.938 | L26: Clear | M26: C | N26: C
J27: 284.883 | R27: 220 KV D/C Line Bishnah-Hiranagar
A28: =A26+1 -> 11 | B28: AP15 | C28: DD+18 | D28: 4°57'01"LT | E28: 1.5 | F28: 0 | G28: 0 | H28: 0 | I28: WET | K28: =J27 -> 284.883 | L28: Clear | M28: C | N28: C
J29: 412.199
A30: =A28+1 -> 12 | B30: 15/1 | C30: DA+0 | E30: 0 | F30: 0 | G30: 0 | H30: 0 | I30: PS | L30: Clear | M30: C | N30: C | O30: C
J31: 428.128
A32: =A30+1 -> 13 | B32: 15/2 | C32: DA+0 | E32: 0 | F32: 0 | G32: 0 | H32: 0 | I32: FS | L32: Clear | M32: C | N32: C | O32: C
J33: 405.152
A34: =A32+1 -> 14 | B34: 15/3 | C34: DA+9 | E34: 0 | F34: 0 | G34: 0 | H34: 0 | I34: FS | L34: Clear | M34: C
J35: 427.96
A36: =A34+1 -> 15 | B36: AP16 | C36: DC+0 | D36: 22°18'18"LT | E36: 0 | F36: 0 | G36: 0 | H36: 0 | I36: FS | K36: =J29+J31+J33+J35 -> 1673.439 | L36: Clear | M36: C
J37: 285.948
A38: =A36+1 -> 16 | B38: AP17 | C38: DC+3 | D38: 19°02'28"LT | E38: 0 | F38: 0 | G38: 0 | H38: 0 | I38: FS | K38: =J37 -> 285.948 | L38: Clear | M38: C | N38: C | O38: WIP
J39: 401.159 | R39: 66 KV H Pole (Sandhi) Ghagwal To Rajpura
A40: =A38+1 -> 17 | B40: AP18 | C40: DC+0 | D40: 24°05'21"RT | E40: 0 | F40: 0 | G40: 0 | H40: 0 | I40: FS | K40: =J39 -> 401.159 | L40: Clear | M40: C | N40: C | O40: C
...

Sheet Approved Survey
A1: KEC INTERNATIONAL LIMITED
A2: 400 kV Samba- Jalandhar D/C Line(Quad) - Wind Zone - 5 | H2: 400 kV Samba- Kishenpur D/C Line(Quad) - Wind Zone - 5
A3: Approved Check Survey Sections | H3: Approved Check Survey Sections
A4: S.No | B4: Portion | C4: Section | D4: Length Km | H4: S.No | I4: Section | J4: Length Km
A5: 1 | B5: Jammu | C5: AP5-AP6 | D5: =119.059/1000 -> 0.119059 | H5: 1 | I5: AP78-AP86 | J5: 1.945
A6: =A5+1 -> 2 | B6: Jammu | C6: AP6-AP7 | D6: =92.496/1000 -> 0.092496 | H6: 2 | I6: AP95-AP109 | J6: 3.13
A7: =A6+1 -> 3 | B7: Jammu | C7: AP7-AP8 | D7: =134.988/1000 -> 0.134988 | H7: 3 | I7: AP24-AP39 | J7: 5.5
A8: =A7+1 -> 4 | B8: Jammu | C8: AP8-AP9 | D8: =365.176/1000 -> 0.365176 | H8: Total | J8: =SUM(J5:J7) -> 10.575
A9: =A8+1 -> 5 | B9: Jammu | C9: AP9-AP10 | D9: =236.697/1000 -> 0.236697
A10: =A9+1 -> 6 | B10: Jammu | C10: AP10-AP11 | D10: =213.152/1000 -> 0.213152 | H10: LILO-Kishtwar
A11: =A10+1 -> 7 | B11: Jammu | C11: AP11-AP12 | D11: =206.593/1000 -> 0.206593 | H11: Approved Check Survey Sections
A12: =A11+1 -> 8 | B12: Jammu | C12: AP12-AP13 | D12: =289.862/1000 -> 0.289862 | H12: S.No | I12: Section | J12: Length Km
A13: =A12+1 -> 9 | B13: Jammu | C13: AP13-AP14 | D13: =402.938/1000 -> 0.402938 | H13: 1 | I13: AP1-TP | J13: 2.18
A14: =A13+1 -> 10 | B14: Jammu | C14: AP14-AP15 | D14: =284.883/1000 -> 0.284883
A15: =A14+1 -> 11 | B15: Jammu | C15: AP15-AP16 | D15: =1673.439/1000 -> 1.673439
A16: =A15+1 -> 12 | B16: Jammu | C16: AP16-AP17 | D16: =285.948/1000 -> 0.285948
A17: =A16+1 -> 13 | B17: Jammu | C17: AP17-AP18 | D17: =401.159/1000 -> 0.401159
A18: =A17+1 -> 14 | B18: Jammu | C18: AP18-AP19 | D18: =1055.218/1000 -> 1.055218
A19: =A18+1 -> 15 | B19: Jammu | C19: AP19-AP20 | D19: =1088.747/1000 -> 1.088747
A20: =A19+1 -> 16 | B20: Jammu | C20: AP20-AP21 | D20: =485.93/1000 -> 0.48593
A21: =A20+1 -> 17 | B21: Jammu | C21: AP21-AP22 | D21: =712.337/1000 -> 0.712337
A22: =A21+1 -> 18 | B22: Jammu | C22: AP22-AP23 | D22: =1177.079/1000 -> 1.177079
A23: =A22+1 -> 19 | B23: Jammu | C23: AP23-AP24 | D23: =2454.951/1000 -> 2.454951
A24: =A23+1 -> 20 | B24: Jammu | C24: AP24-AP25 | D24: =366.044/1000 -> 0.366044
A25: =A24+1 -> 21 | B25: Jammu | C25: AP25-AP26 | D25: =1028.029/1000 -> 1.028029
A26: =A25+1 -> 22 | B26: Jammu | C26: AP26-AP27 | D26: =442.371/1000 -> 0.442371
A27: =A26+1 -> 23 | B27: Jammu | C27: AP27-AP28 | D27: =739.739/1000 -> 0.739739
A28: =A27+1 -> 24 | B28: Jammu | C28: AP28-AP29 | D28: =445.991/1000 -> 0.445991
A29: =A28+1 -> 25 | B29: Jammu | C29: AP29-AP30 | D29: =2573.629/1000 -> 2.573629
A30: =A29+1 -> 26 | B30: Jammu | C30: AP30-AP31 | D30: =2514.73/1000 -> 2.51473
A31: =A30+1 -> 27 | B31: Jammu | C31: AP31-AP32 | D31: =2374.48/1000 -> 2.37448
A32: =A31+1 -> 28 | B32: Jammu | C32: AP32-AP33 | D32: =836.984/1000 -> 0.836984
A33: =A32+1 -> 29 | B33: Jammu | C33: AP33-AP34 | D33: =967.8/1000 -> 0.9678
A34: =A33+1 -> 30 | B34: Jammu | C34: AP34-AP35 | D34: =819.907/1000 -> 0.819907
A35: =A34+1 -> 31 | B35: Jammu | C35: AP35-AP36 | D35: =820.234/1000 -> 0.820234
A36: =A35+1 -> 32 | B36: Jammu | C36: AP36-AP37 | D36: =439.8/1000 -> 0.4398
A37: =A36+1 -> 33 | B37: Jammu | C37: AP37-AP38 | D37: =1203.4/1000 -> 1.2034
A38: =A37+1 -> 34 | B38: Jammu | C38: AP38-AP39 | D38: =775.272/1000 -> 0.775272
A39: =A38+1 -> 35 | B39: Jammu | C39: AP39-AP40 | D39: =1209.893/1000 -> 1.209893
A40: =A39+1 -> 36 | B40: Jammu | C40: AP40-AP41 | D40: =1760.473/1000 -> 1.760473
...

Sheet Approved CS J-S Line
A1: Line: 400 kV D/C Quad Jalandhar-Samba TL
A2: Approved Check Survey Tower Schedule
A3: AS PER DETAIL SURVEY | J3: AS PER CHECK SURVEY
A4: Sr. No. | B4: Tower No. | C4: Type of Tower | D4: Span Length (m) | E4: Section Length (m) | F4: Angle of Deviation | G4: UTM Coordinates | J4: Sr. No. | K4: Tower No. | L4: Type of Tower | M4: Raised Chimney | Q4: Leg Extension | U4: Span Length (m) | V4: Section Length (m) | W4: Reduced Level | X4: Angle of Deviation | Y4: UTM Coordinates | AA4: Crossing/Remarks
G5: Easting | H5: Northing | M5: LEG A | N5: LEG B | O5: LEG C | P5: LEG D | Q5: LEG A | R5: LEG B | S5: LEG C | T5: LEG D | Y5: Easting | Z5: Northing
A6: 1 | B6: AP 5/0 | C6: DD+18 | E6: 0 | F6: 47°01'57"L | G6: 516661.84 | H6: 3596578.1 | J6: 1 | K6: AP 5/0 | L6: DD+0 | M6: 0 | N6: 0 | O6: 0 | P6: 0 | Q6: 0 | R6: 0 | S6: 0 | T6: 0 | V6: 0 | W6: 384.3 | X6: 47°01'59"LT | Y6: 516472.78 | Z6: 3598642.7
D7: 119.059 | U7: 119.059 | AA7: 2 nos 11 KV,Road Crossing
A8: =A6+1 -> 2 | B8: AP 6/0 | C8: DA+0 | E8: =E6+D7 -> 119.059 | F8: 40°54'41"R | G8: 516805.33 | H8: 3596183.2 | J8: =J6+1 -> 2 | K8: AP 6/0 | L8: DD+9 | M8: 0 | N8: 0 | O8: 0 | P8: 0 | Q8: 0 | R8: 0 | S8: 0 | T8: 0 | V8: =U7 -> 119.059 | W8: 384.202 | X8: 40°54'42"RT | Y8: 516557.85 | Z8: 3598559.4
D9: 92.496 | U9: 92.496
A10: =A8+1 -> 3 | B10: AP 7/0 | C10: DA+0 | E10: =E8+D9 -> 211.555 | F10: 47°08'48"L | G10: 516948.8 | H10: 3595788.3 | J10: =J8+1 -> 3 | K10: AP 7/0 | L10: DD+25 | M10: 0 | N10: 0 | O10: 0 | P10: 0 | Q10: 0 | R10: 0 | S10: 0 | T10: 0 | V10: =V8+U9 -> 211.555 | W10: 382.166 | X10: 47°08'48"LT | Y10: 516565.42 | Z10: 3598467.2
D11: 134.989 | U11: 134.988 | AA11: 400 KV(JAL-SAM) line Crossing
A12: =A10+1 -> 4 | B12: AP 8/0 | C12: DA+6 | E12: =E10+D11 -> 346.544 | F12: 41°15'08"R | G12: 517087.16 | H12: 3595407.5 | J12: =J10+1 -> 4 | K12: AP 8/0 | L12: DD+25 | M12: 0 | N12: 0 | O12: 0 | P12: 0 | Q12: 0 | R12: 0 | S12: 0 | T12: 0 | V12: =V10+U11 -> 346.543 | W12: 377.89 | X12: 41°15'08"RT | Y12: 516671.56 | Z12: 3598383.8
D13: 365.175 | U13: 365.176 | AA13: Nalla Crossing
A14: =A12+1 -> 5 | B14: AP 9/0 | C14: DC+6 | E14: =E12+D13 -> 711.719 | F14: 37°05'47"R | G14: 517233.3 | H14: 3595005.3 | J14: =J12+1 -> 5 | K14: AP 9/0 | L14: DD+9 | M14: 0 | N14: 0 | O14: 0 | P14: 0 | Q14: 0 | R14: 0 | S14: 0 | T14: 0 | V14: =V12+U13 -> 711.719 | W14: 373.28 | X14: 37°05'47"RT | Y14: 516738.65 | Z14: 3598024.8
D15: 236.697 | U15: 236.697 | AA15: 2 nos 25KV,Railway Crossing
A16: =A14+1 -> 6 | B16: AP 10/0 | C16: DC+3 | E16: =E14+D15 -> 948.416 | F16: 20°40'31"L | G16: 517425.65 | H16: 3594793.7 | J16: =J14+1 -> 6 | K16: AP 10/0 | L16: DD+9 | M16: 0 | N16: 0 | O16: 0 | P16: 0 | Q16: 0 | R16: 0 | S16: 0 | T16: 0 | V16: =V14+U15 -> 948.416 | W16: 364.063 | X16: 20°40'31"LT | Y16: 516633 | Z16: 3597813
D17: 213.252 | U17: 213.252
A18: =A16+1 -> 7 | B18: AP 11/0 | C18: DC+3 | E18: =E16+D17 -> 1161.668 | F18: 51°34'01"R | G18: 517777.57 | H18: 3594601.2 | J18: =J16+1 -> 7 | K18: AP 11/0 | L18: DD+25 | M18: 0 | N18: 0 | O18: 0 | P18: 0 | Q18: 0 | R18: 0 | S18: 0 | T18: 0 | V18: =V16+U17 -> 1161.668 | W18: 361.99 | X18: 51°34'02"RT | Y18: 516611.32 | Z18: 3597600.9
D19: 206.592 | U19: 206.593 | AA19: Cannal,11 KV,Road,400 kv(JAL-SAM) Line Crossing
A20: =A18+1 -> 8 | B20: AP 12/0 | C20: DA+0 | E20: =E18+D19 -> 1368.26 | F20: 47°50'12"L | G20: 517986.28 | H20: 3594326.4 | J20: =J18+1 -> 8 | K20: AP 12/0 | L20: DD+30 | M20: 0 | N20: 0 | O20: 0 | P20: 0 | Q20: 0 | R20: 0 | S20: 0 | T20: 0 | V20: =V18+U19 -> 1368.261 | W20: 353.883 | X20: 47°50'13"LT | Y20: 516437.27 | Z20: 3597489.6
D21: 289.862 | U21: 289.862 | AA21: 220 kv(HRN-SAM) Line Crossing
A22: =A20+1 -> 9 | B22: AP 13/0 | C22: DA+0 | E22: =E20+D21 -> 1658.122 | F22: 39°08'44"L | G22: 518204.06 | H22: 3594039.8 | J22: =J20+1 -> 9 | K22: AP 13/0 | L22: DD+25 | M22: 0 | N22: 0 | O22: 0 | P22: 0 | Q22: 1.5 | R22: 1.5 | S22: 0 | T22: 0 | V22: =V20+U21 -> 1658.123 | W22: 348.38 | X22: 39°08'44"LT | Y22: 516389.11 | Z22: 3597203.7
D23: 402.938 | U23: 402.938 | AA23: Cannal,Cart Track Crossing
A24: =A22+1 -> 10 | B24: AP 14/0 | C24: DC+0 | E24: =E22+D23 -> 2061.06 | F24: 14°33'47"R | G24: 518415.92 | H24: 3593760.9 | J24: =J22+1 -> 10 | K24: AP 14/0 | L24: DB+9 | M24: 0 | N24: 0 | O24: 0 | P24: 0 | Q24: 0 | R24: 0 | S24: 2 | T24: 0 | V24: =V22+U23 -> 2061.061 | W24: 345.17 | X24: 14°33'47"RT | Y24: 516588.02 | Z24: 3596853.3
D25: 284.883 | U25: 284.883 | AA25: River,220 KV(BAR-HRN)Line Crossing
A26: =A24+1 -> 11 | B26: AP 15/0 | C26: DA+0 | E26: =E24+D25 -> 2345.943 | F26: 4°57'01"L | G26: 518741.12 | H26: 3593584.5 | J26: =J24+1 -> 11 | K26: AP 15/0 | L26: DD+18 | M26: 0 | N26: 0 | O26: 0 | P26: 0 | Q26: 1.5 | R26: 0 | S26: 0 | T26: 0 | V26: =V24+U25 -> 2345.944 | W26: 341.282 | X26: 4°57'01"LT | Y26: 516661.84 | Z26: 3596578.1
D27: 420.199 | U27: 412.199 | AA27: Canal crosssing
A28: =A26+1 -> 12 | B28: 15/1 | C28: DA+0 | G28: 516805.33 | H28: 3596183.2 | J28: =J26+1 -> 12 | K28: 15/1 | L28: DA+0 | M28: 0 | N28: 0 | O28: 0 | P28: 0 | Q28: 0 | R28: 0 | S28: 0 | T28: 0 | W28: 337.118 | Y28: 516802.6 | Z28: 3596190.7
D29: 420.127 | U29: 428.128
A30: =A28+1 -> 13 | B30: 15/2 | C30: DA+0 | G30: 516948.8 | H30: 3595788.3 | J30: =J28+1 -> 13 | K30: 15/2 | L30: DA+0 | M30: 0 | N30: 0 | O30: 0 | P30: 0 | Q30: 0 | R30: 0 | S30: 0 | T30: 0 | W30: 331.591 | Y30: 516948.8 | Z30: 3595788.3
D31: 405.152 | U31: 405.152 | AA31: Road and LT Line crossing
A32: =A30+1 -> 14 | B32: 15/3 | C32: DA+6 | G32: 517087.16 | H32: 3595407.5 | J32: =J30+1 -> 14 | K32: 15/3 | L32: DA+9 | M32: 0 | N32: 0 | O32: 0 | P32: 0 | Q32: 0 | R32: 0 | S32: 0 | T32: 0 | W32: 327.063 | Y32: 517087.16 | Z32: 3595407.5
D33: 427.96 | U33: 427.96
A34: =A32+1 -> 15 | B34: AP 16/0 | C34: DC+6 | E34: =D27+D29+D31+D33 -> 1673.438 | F34: 22°18'18"LT | G34: 517233.3 | H34: 3595005.3 | J34: =J32+1 -> 15 | K34: AP 16/0 | L34: DC+0 | M34: 0 | N34: 0 | O34: 0 | P34: 0 | Q34: 0 | R34: 0 | S34: 0 | T34: 0 | V34: =U27+U29+U31+U33 -> 1673.439 | W34: 320.406 | X34: 22°18'18"LT | Y34: 517233.3 | Z34: 3595005.3
D35: 285.948 | U35: 285.948 | AA35: 11 KV,Road,LTLine Crossing
A36: =A34+1 -> 16 | B36: AP 17/0 | C36: DC+3 | E36: =D35 -> 285.948 | F36: 19°02'28"LT | G36: 517425.65 | H36: 3594793.7 | J36: =J34+1 -> 16 | K36: AP 17/0 | L36: DC+3 | M36: 0 | N36: 0 | O36: 0 | P36: 0 | Q36: 0 | R36: 0 | S36: 0 | T36: 0 | V36: =U35 -> 285.948 | W36: 317.232 | X36: 19°02'28"LT | Y36: 517425.65 | Z36: 3594793.7 | AA36: LTLine to be shifted
D37: 401.159 | U37: 401.159 | AA37: 11KV,66KV,Road,LTLine Crossing
A38: =A36+1 -> 17 | B38: AP 18/0 | C38: DC+3 | E38: =D37 -> 401.159 | F38: 24°05'21"RT | G38: 517777.57 | H38: 3594601.2 | J38: =J36+1 -> 17 | K38: AP 18/0 | L38: DC+0 | M38: 0 | N38: 0 | O38: 0 | P38: 0 | Q38: 0 | R38: 0 | S38: 0 | T38: 0 | V38: =U37 -> 401.159 | W38: 315.046 | X38: 24°05'21"RT | Y38: 517777.57 | Z38: 3594601.2
D39: 345 | U39: 345 | AA39: LTLine Crossing
A40: =A38+1 -> 18 | B40: 18/1 | C40: DA+0 | G40: 517986.28 | H40: 3594326.4 | J40: =J38+1 -> 18 | K40: 18/1 | L40: DA+0 | M40: 0 | N40: 0 | O40: 0 | P40: 0 | Q40: 0 | R40: 0 | S40: 0 | T40: 0 | W40: 316.217 | Y40: 517986.28 | Z40: 3594326.4
...

Sheet Approved CS K-S Line
A1: Line: 400 kV D/C Quad Kishenpur-Samba TL
A2: Approved Check Survey Tower Schedule
A3: AS PER DETAIL SURVEY | J3: AS PER CHECK SURVEY
A4: Sr. No. | B4: Tower No. | C4: Type of Tower | D4: Span Length (m) | E4: Section Length (m) | F4: Angle of Deviation | G4: UTM Coordinates | J4: Sr. No. | K4: Tower No. | L4: Type of Tower | M4: Raised Chimney | Q4: Leg Extension | U4: Span Length (m) | V4: Section Length (m) | W4: Reduced Level | X4: Angle of Deviation | Y4: UTM Coordinates | AA4: Crossing/Remarks
G5: Easting | H5: Northing | M5: LEG A | N5: LEG B | O5: LEG C | P5: LEG D | Q5: LEG A | R5: LEG B | S5: LEG C | T5: LEG D | Y5: Easting | Z5: Northing
A6: 1 | B6: AP 78/0 | C6: DC+9 | E6: 0 | F6: 28°55'39"L | G6: 515334.47 | H6: 3621567.2 | J6: 1 | K6: AP 78/0 | L6: DC+9 | M6: 0 | N6: 0 | O6: 0 | P6: 0 | Q6: 1 | R6: 0 | S6: 3 | T6: 3 | V6: 0 | W6: 524.77 | X6: 29°55'53"L | Y6: 515334.47 | Z6: 3621567.1
D7: 361.044 | U7: 340.277
A8: 2 | B8: AP 79/0 | C8: DD+9 | E8: =E6+D7 -> 361.044 | F8: 31°39'03"R | G8: 515034.27 | H8: 3621767.7 | J8: 2 | K8: AP 79/0 | L8: DD+9 | M8: 0 | N8: 0 | O8: 0 | P8: 0 | Q8: 0 | R8: 1 | S8: 0 | T8: 0 | V8: =V6+U7 -> 340.277 | W8: 524.982 | X8: 30°11'47"R | Y8: 515048.27 | Z8: 3621751.2 | AA8: LT LINE TO BE SHIFTED
D9: 374.114 | U9: 392.251 | AA9: NALLA CROSSING
A10: 3 | B10: AP 80/0 | C10: DD+3 | E10: =E8+D9 -> 735.158 | F10: 36°56'25"L | G10: 514878.54 | H10: 3622107.9 | J10: 3 | K10: AP 80/0 | L10: DD+3 | M10: 0 | N10: -1.5 | O10: 0 | P10: 0 | Q10: 0 | R10: 0 | S10: 0 | T10: 1 | V10: =V8+U9 -> 732.528 | W10: 532.688 | X10: 30°16'26"L | Y10: 514869.85 | Z10: 3622100.5
D11: 148.51 | U11: 144.77
A12: 4 | B12: AP 81/0 | C12: DD+18 | E12: =E10+D11 -> 883.668 | F12: 49°18'55"L | G12: 514747.98 | H12: 3622178.7 | J12: 4 | K12: AP 81/0 | L12: DD+18 | M12: 0 | N12: 0 | O12: 0 | P12: 0 | Q12: 0 | R12: 0 | S12: 0 | T12: 2 | V12: =V10+U11 -> 877.298 | W12: 535.86 | X12: 53°31'26"L | Y12: 514747.98 | Z12: 3622178.7
D13: 195.926 | U13: 195.926 | AA13: 220 KV S/C CROSSING(KSN-SRN)
A14: 5 | B14: AP 82/0 | C14: DD+18 | E14: =E12+D13 -> 1079.594 | F14: 5°38'12"R | G14: 514564.89 | H14: 3622108.9 | J14: 5 | K14: AP 82/0 | L14: DD+18 | M14: 0 | N14: 0 | O14: 0 | P14: 0 | Q14: 1 | R14: 3 | S14: 4 | T14: 4 | V14: =V12+U13 -> 1073.224 | W14: 532.66 | X14: 5°38'20"R | Y14: 514564.89 | Z14: 3622108.9
D15: 194.627 | U15: 194.623 | AA15: 220 D/C CROSSING(KSN-SRN)
A16: 6 | B16: AP 83/0 | C16: DD+25 | E16: =E14+D15 -> 1274.221 | F16: 46°40'30"R | G16: 514377.09 | H16: 3622057.8 | J16: 6 | K16: AP 83/0 | L16: DD+25 | M16: 0 | N16: 0 | O16: 0 | P16: 0 | Q16: 0 | R16: 0 | S16: 3 | T16: 0 | V16: =V14+U15 -> 1267.847 | W16: 522.13 | X16: 46°40'25"R | Y16: 514377.09 | Z16: 3622057.9
D17: 123.478 | U17: 123.478
A18: 7 | B18: AP 84/0 | C18: DC+9 | E18: =E16+D17 -> 1397.699 | F18: 26°50'39"R | G18: 514271.76 | H18: 3622122.3 | J18: 7 | K18: AP 84/0 | L18: DC+9 | M18: 0 | N18: 0 | O18: 0 | P18: 0 | Q18: 3 | R18: 3 | S18: 3 | T18: 3 | V18: =V16+U17 -> 1391.325 | W18: 525.46 | X18: 26°50'39"R | Y18: 514271.76 | Z18: 3622122.3 | AA18: CONTOUR NOT REQUIRED
D19: 358.138 | U19: 358.134
A20: 8 | B20: AP 85/0 | C20: DC+0 | E20: =E18+D19 -> 1755.837 | F20: 18°33'39"R | G20: 514083.58 | H20: 3622427 | J20: 8 | K20: AP 85/0 | L20: DC+0 | M20: 0 | N20: -1.5 | O20: 0 | P20: 1 | Q20: 0 | R20: 0 | S20: 0 | T20: 0 | V20: =V18+U19 -> 1749.459 | W20: 513.5 | X20: 18°33'34"R | Y20: 514083.58 | Z20: 3622427
D21: 195.995 | U21: 195.99 | AA21: LT LINE,2 NOS 11 KV CROSSING
A22: 9 | B22: AP 86/0 | C22: DD+0 | E22: =E20+D21 -> 1951.832 | F22: 37°33'24"L | G22: 514039.03 | H22: 3622617.9 | J22: 9 | K22: AP 86/0 | L22: DD+0 | M22: 0 | N22: 0 | O22: 1.5 | P22: 0 | Q22: 0 | R22: 0 | S22: 0 | T22: 0 | V22: =V20+U21 -> 1945.449 | W22: 519.05 | Y22: 514039.03 | Z22: 3622617.9
U23: 402.938 | AA23: Cannal,Cart Track Crossing
A25: =A22+1 -> 10 | B25: AP 95/0 | C25: DD+0 | E25: 0 | F25: 49° 37' 37"RT | G25: 511950.67 | H25: 3623917.5 | J25: =J22+1 -> 10 | K25: AP 95/0 | L25: DD+0 | M25: 0 | N25: -1.5 | O25: 0 | P25: 1.5 | Q25: 0 | R25: 0 | S25: 0 | T25: 0 | V25: 0 | W25: 483.848 | X25: 47° 47' 09"RT | Y25: 511953.99 | Z25: 3623920
D26: 216.941 | U26: 215.857 | AA26: LT Line,2 NOS 11KV Line Crossing
A27: =A25+1 -> 11 | B27: AP 96/0 | C27: DC+0 | E27: =E25+D26 -> 216.941 | F27: 23° 11' 17"RT | G27: 511872.02 | H27: 3624119.7 | J27: =J25+1 -> 11 | K27: AP 96/0 | L27: DC-3 | M27: 0 | N27: 0 | O27: 0 | P27: 3 | Q27: 0 | R27: 0 | S27: 1 | T27: 0 | V27: =V25+U26 -> 215.857 | W27: 480.277 | X27: 24° 15' 00"RT | Y27: 511872.02 | Z27: 3624119.7
D28: 166.009 | U28: 166.009 | AA28: LT Line Crossing
A29: =A27+1 -> 12 | B29: AP 97/0 | C29: DC+0 | E29: =E27+D28 -> 382.95 | F29: 25° 05' 24"LT | G29: 511877.62 | H29: 3624285.6 | J29: =J27+1 -> 12 | K29: AP 97/0 | L29: DC-3 | M29: 0 | N29: 0 | O29: 0 | P29: 0 | Q29: 0 | R29: 0 | S29: 0 | T29: 0 | V29: =V27+U28 -> 381.866 | W29: 485.367 | X29: 25° 09' 02"LT | Y29: 511877.62 | Z29: 3624285.6 | AA29: Contour Not Required
D30: 242.696 | U30: 242.696 | AA30: Nalla and LT Line crossing
A31: =A29+1 -> 13 | B31: AP 98/0 | C31: DD+9 | E31: =E29+D30 -> 625.646 | F31: 48° 10' 12"LT | G31: 511782.17 | H31: 3624508.8 | J31: =J29+1 -> 13 | K31: AP 98/0 | L31: DD+9 | M31: 0 | N31: 0 | O31: 0 | P31: 0 | Q31: 2 | R31: 2 | S31: 3 | T31: 2 | V31: =V29+U30 -> 624.562 | W31: 486.733 | X31: 48° 10' 19"LT | Y31: 511782.17 | Z31: 3624508.8
D32: 202.992 | U32: 202.992 | AA32: 132 KV S/C Line Crossing
A33: =A31+1 -> 14 | B33: AP 99/0 | C33: DD+18 | E33: =E31+D32 -> 828.638 | F33: 58° 23' 34"RT | G33: 511589.86 | H33: 3624573.7 | J33: =J31+1 -> 14 | K33: AP 99/0 | L33: DD+18 | M33: 0 | N33: 0 | O33: 0 | P33: 0 | Q33: 0 | R33: 0 | S33: 0 | T33: 0 | V33: =V31+U32 -> 827.554 | W33: 468.882 | X33: 58° 23' 34"RT | Y33: 511589.86 | Z33: 3624573.7 | AA33: Contour Not Required
D34: 155.699 | U34: 155.699
A35: =A33+1 -> 15 | B35: AP 100/0 | C35: DD+9 | E35: =E33+D34 -> 984.337 | F35: 45° 03' 40"RT | G35: 511554.99 | H35: 3624725.5 | J35: =J33+1 -> 15 | K35: AP 100/0 | L35: DD+9 | M35: 0 | N35: 0 | O35: 0 | P35: 0 | Q35: 0 | R35: 0 | S35: 0 | T35: 0 | V35: =V33+U34 -> 983.253 | W35: 468.116 | X35: 45° 03' 40"RT | Y35: 511554.99 | Z35: 3624725.5
D36: 491.503 | U36: 491.503 | AA36: Nalla and LT Line crossing
A37: =A35+1 -> 16 | B37: AP 101/0 | C37: DD+9 | E37: =E35+D36 -> 1475.84 | F37: 34° 37' 48"LT | G37: 511816.34 | H37: 3625141.7 | J37: =J35+1 -> 16 | K37: AP 101/0 | L37: DD+9 | M37: 0 | N37: 0 | O37: 0 | P37: 0 | Q37: 0 | R37: 0 | S37: 0 | T37: 0 | V37: =V35+U36 -> 1474.756 | W37: 482.052 | X37: 34° 37' 48"LT | Y37: 511816.34 | Z37: 3625141.7 | AA37: Contour Not Required
D38: 136.501 | U38: 136.501
A39: =A37+1 -> 17 | B39: AP 102/0 | C39: DD+0 | E39: =E37+D38 -> 1612.341 | F39: 49° 54' 56"LT | G39: 511810.37 | H39: 3625278.1 | J39: =J37+1 -> 17 | K39: AP 102/0 | L39: DD+0 | M39: 0 | N39: 0 | O39: 0 | P39: 0 | Q39: 0 | R39: 1 | S39: 0 | T39: 0 | V39: =V37+U38 -> 1611.257 | W39: 479.213 | X39: 49° 54' 56"LT | Y39: 511810.37 | Z39: 3625278.1
D40: 122.195 | U40: 122.195 | AA40: 11 kv Line Crossing
A41: =A39+1 -> 18 | B41: AP 103/0 | C41: DD+6 | E41: =E39+D40 -> 1734.536 | F41: 37° 03' 00"RT | G41: 511713.53 | H41: 3625352.6 | J41: =J39+1 -> 18 | K41: AP 103/0 | L41: DD+6 | M41: 0 | N41: 0 | O41: 0 | P41: 0 | Q41: 1 | R41: 0 | S41: 0 | T41: 1 | V41: =V39+U40 -> 1733.452 | W41: 476.5 | X41: 37° 03' 00"RT | Y41: 511713.53 | Z41: 3625352.6
...

Sheet Foundation JS-Line -Jammu
A1: KEC INTERNATIONAL LIMITED | O1: Date: | P1: ='TB-605'!E1 -> 46118
A2: 400 kV Samba- Jalandhar D/C Line(Quad) - Wind Zone - 5-Jammu Portion
A3: FOUNDATION
A5: S.No | B5: Loc No. | C5: Tower Type | D5: Classification | E5: Conc Volume | F5: Start Date | G5: Foundation | M5: Earthing | N5: FDN Status | O5: Gang Name | P5: Gang Strength | Q5: Remark
G6: Excavation | H6: Stub Setting | I6: PCC | J6: Rebar Placing | K6: RCC | L6: Completion Date
