Workbook
Name \0: #REF!
Name \0: #REF!
Name \0: #REF!
Name \0: #REF!
Name \0: #REF!
Name \01: #REF!
Name \1: #N/A
Name \2: #REF!
Name \2: #REF!
Name \2: #REF!
Name \2: #REF!
Name \3: #REF!
Name \4: #REF!
Name \A: #REF!
Name \A: #REF!
Name \A: #REF!
Name \A: #REF!
Name \A_1: "#REF!"
Name \a1: #REF!
Name \aa: #REF!
Name \B: #REF!
Name \B: #REF!
Name \B: #REF!
Name \B: #REF!
Name \C: #REF!
Name \C: #REF!
Name \c1: #REF!
Name \d: #N/A
Name \E: #REF!
Name \f: #REF!
Name \f: #REF!
Name \g: #REF!
Name \H: #REF!
Name \H: #REF!
Name \H: #REF!
Name \H: #REF!
Name \I: #REF!
Name \j: #REF!
Name \k: #REF!
Name \KWS123: #N/A
Name \l: #REF!
Name \l: #REF!
Name \l: #REF!
Name \l: #REF!
Name \l: #REF!
Name \M: #REF!
Name \N: #REF!
Name \P: #REF!
Name \Q: #REF!
Name \q: #N/A
Name \R: #REF!
Name \R: #REF!
Name \R: #REF!
Name \R: #REF!
Name \R: #REF!
Name \S: #REF!
Name \t: #N/A
Name \U: #REF!
Name \U: #REF!
Name \U: #REF!

Sheet TA413_PBNTL
A1: TA413 : 765 KV D/C Bikaner III - Neemrana II TL02 | M1: 27.05.2026
A2: Name of Client: PowerGrid Bikaner Neemrana Transmission Limited (Power Grid Corporation of India) | K2: Project Duration : 21 Month EOT -30/06/2026
A3: Name of Line: 765 KV D/C Bikaner III - Neemrana II TL02 LOA Value: 389.96 Crore
A4: NOA No: CC/T/W-TW/DOM/A04/23/10569/NOA-1&2/24-103421/01&02 Date.12/03/2024 Amendment -II Comp Value As on: 390 Crore
A5: Office: Hansera, Bikaner, Rajasthan.
A6: Sl. No. | B6: Activity | C6: LOA Quantity | D6: As per latest Estimate | E6: Cumm. Progress up to last Month | F6: Cumm L2 Schedule till Apr'26 | G6: Plan for this Month | H6: Current Month Achieved (As on dated ) | I6: Today | J6: Cumulative Progress | K6: Balance | L6: No of Gangs | M6: Remarks
A7: 1 | B7: Detail Survey (Km) | C7: 112.611 | D7: 117.85085 | E7: 117.85085 | F7: 112.611 | H7: =D7-E7 -> 0 | I7: 0 | J7: =E7+H7 -> 117.85085 | K7: =D7-J7 -> 0 | M7: Completed
A8: 2 | B8: Soil Investigation (Nos.) | C8: 29 | D8: 29 | E8: 26 | F8: 0 | H8: 0 | I8: 0 | J8: =E8+H8 -> 26 | K8: 0 | M8: Completed
A9: 3 | B9: Check Survey approved(Km) | C9: 112.611 | D9: 117.85085 | E9: 117.85085 | F9: 112.611 | H9: 0 | I9: 0 | J9: =E9+H9 -> 117.85085 | K9: =D9-J9 -> 0 | M9: Completed
A10: 4 | B10: Excavation | C10: 287 | D10: 316 | E10: =17+21+18+41+36+24+32+35+31+19+23+10+4+2+1+1+1 -> 316 | F10: 287 | G10: 0 | H10: 0 | I10: 0 | J10: =E10+H10 -> 316 | K10: =D10-J10 -> 0 | M10: Completed
A11: 5 | B11: Foundation (Nos.) | C11: =C10 -> 287 | D11: 316 | E11: =17+21+18+41+36+24+32+35+31+19+23+10+4+2+1+1+1 -> 316 | F11: 287 | G11: 0 | H11: 0 | I11: 0 | J11: =E11+H11 -> 316 | K11: =D11-J11 -> 0 | M11: Completed
A12: 6 | B12: Earthing (Nos.) | C12: =C11 -> 287 | D12: 309 | E12: =26+70+28+16+29+8+75+25+15+6+6+3 -> 307 | F12: =F11 -> 287 | G12: 0 | H12: 0 | I12: 0 | J12: =E12+H12 -> 307 | K12: =D12-J12 -> 2
A13: 7 | B13: Tower Erection (Nos) | C13: 287 | D13: 306 | E13: 302 | F13: 287 | G13: 1 | H13: 0 | I13: 0 | J13: =E13+H13 -> 302 | K13: =D13-J13 -> 4
A14: 8 | B14: Tack Welding | C14: =C13 -> 287 | D14: 306 | E14: =126+15+30+40+13 -> 224 | F14: 287 | G14: 40 | H14: 31 | I14: 0 | J14: =E14+H14 -> 255 | K14: =D14-J14 -> 51 | L14: 1 | M14: G_1:- M.S Enterprises
A15: 9 | B15: Bird Guard (Set of Three) | C15: 241 | D15: 244 | E15: 0 | G15: 50 | H15: 99 | I15: 0 | J15: =E15+H15 -> 99 | K15: =D15-J15 -> 145 | L15: 2 | M15: G_1:- Jetha Ram - G_2 Mahendra Banjara
A16: 10 | B16: Stringing (Km) | C16: 112.611 | D16: =D7 -> 117.85085 | E16: =21.496+4.922+4.901+8.229+9.801+14.275+4.965 -> 68.589 | F16: 112 | G16: 18 | H16: =2.669+2.379+1.004+2.548 -> 8.6 | I16: 2.548 | J16: =E16+H16 -> 77.189 | K16: =D16-J16 -> 40.661851 | L16: 2 | M16: G_1:- Rahim Khan (15 MP) | O16: =D17-E17 -> 45.588851
A17: a) | B17: Paying Out | C17: =C16 -> 112.611 | D17: =D7 -> 117.85085 | E17: =21.496+4.922+4.901+8.229+9.801+10.151+4.124+8.638 -> 72.262 | F17: 112 | G17: 18 | H17: =2.379+2.548 -> 4.927 | I17: 0 | J17: =E17+H17 -> 77.189 | K17: =D17-J17 -> 40.661851 | M17: G_2:- SK infra (MP 45)
A18: b) | B18: Final Sag | C18: =C17 -> 112.611 | D18: =D7 -> 117.85085 | E18: =21.496+4.922+4.901+8.229+9.801+10.151+4.124+4.965 -> 68.589 | F18: 112 | G18: 18 | H18: =H16 -> 8.6 | I18: =I16 -> 2.548 | J18: =E18+H18 -> 77.189 | K18: =D18-J18 -> 40.661851
A19: 11 | B19: OPGW (Km) | C19: =C18 -> 112.611 | D19: =D7 -> 117.85085 | E19: =13.612+4.6+18.591+22.959 -> 59.762 | F19: 112 | G19: 25 | H19: 0 | I19: 0 | J19: =+E19+H19 -> 59.762 | K19: =D19-J19 -> 58.088851
A24: .
E260: 2MRC Sandy
E261: 2MRC Sandy
E262: 2MRC Sandy

Sheet Visual Chart
B1: KEC INTERNATIONAL LIMITED
B2: =TA413_PBNTL!A3 -> Name of Line: 765 KV D/C Bikaner III - Neemrana II TL02 LOA Value: 389.96 Crore | V2: Visual Chart | AQ2: =TA413_PBNTL!M1 -> 27.05.2026
C4: S. No. | E4: Description | I4: UOM | K4: Total Qty | M4: Completed | P4: Balance | T4: Power Line Crossing | AC4: Stringing U/P | AL4: Stringing completed
C5: 1 | E5: Foundation | I5: Nos | K5: =TA413_PBNTL!D11 -> 316 | M5: =TA413_PBNTL!J11 -> 316 | P5: =K5-M5 -> 0 | AC5: Tack Welding U/P | AL5: Tack Welding completed
C6: 2 | E6: Earthing | I6: Nos | K6: =TA413_PBNTL!D12 -> 309 | M6: =TA413_PBNTL!J12 -> 307 | P6: =K6-M6 -> 2 | T6: NH / SH Crossing | AC6: Erection U/P | AJ6: 4 | AL6: Erection completed
C7: 3 | E7: Tower Erection | I7: Nos | K7: =TA413_PBNTL!D13 -> 306 | M7: =TA413_PBNTL!J13 -> 302 | P7: =K7-M7 -> 4 | AA7: 1 | AC7: Foundation U/P | AL7: Foundation completed
C8: 4 | E8: Rough Sag | I8: KM | K8: =TA413_PBNTL!D17 -> 117.85085 | M8: =TA413_PBNTL!J17 -> 77.189 | P8: =K8-M8 -> 40.661851 | T8: Railway Crossing | AJ8: 3
C9: 5 | E9: Final Sag | I9: KM | K9: =TA413_PBNTL!D18 -> 117.85085 | M9: =TA413_PBNTL!J18 -> 77.189 | P9: =K9-M9 -> 40.661851 | AA9: 1 | AC9: Excavation U/P | AJ9: 2 | AL9: Excavation completed
T10: Canal | AL10: Earthing completed
Q12: =O12+1 -> 1 | S12: 2 | U12: =S12+1 -> 3 | W12: =U12+1 -> 4 | Y12: =W12+1 -> 5 | AA12: =Y12+1 -> 6 | AC12: =AA12+1 -> 7 | AE12: =AC12+1 -> 8 | AG12: =AE12+1 -> 9 | AI12: =AG12+1 -> 10 | AK12: =AI12+1 -> 11 | AM12: =AK12+1 -> 12 | AO12: =AM12+1 -> 13 | AQ12: =AO12+1 -> 14 | AS12: =AQ12+1 -> 15
D13: Hold | O13: Gantry | Q13: 1/0 | S13: 2A/0 | U13: 2A/1 | W13: 2A/2 | Y13: 2A/3 | AA13: 2A/4 | AC13: 2A/5 | AE13: 2A/6 | AG13: 3A/0 | AI13: 3A/1 | AK13: 3A/2 | AM13: 3A/3 | AO13: 3A/4 | AQ13: 3A/5 | AS13: 3A/6
D15: Foundation ROW
K16: Bikaner III Gantry | P16: 150 | Q16: 3 | R16: 290.21 | S16: 3 | T16: =VLOOKUP(S13,'Location Summary'!$G$2:$H$604,2,FALSE) -> 378 | U16: 3 | V16: =VLOOKUP(U13,'Location Summary'!$G$2:$H$604,2,FALSE) -> 381 | W16: 3 | X16: =VLOOKUP(W13,'Location Summary'!$G$2:$H$604,2,FALSE) -> 419 | Y16: 3 | Z16: =VLOOKUP(Y13,'Location Summary'!$G$2:$H$604,2,FALSE) -> 422 | AA16: 3 | AB16: =VLOOKUP(AA13,'Location Summary'!$G$2:$H$604,2,FALSE) -> 399 | AC16: 3 | AD16: =VLOOKUP(AC13,'Location Summary'!$G$2:$H$604,2,FALSE) -> 423 | AE16: 3 | AF16: =VLOOKUP(AE13,'Location Summary'!$G$2:$H$604,2,FALSE) -> 414.992 | AG16: 3 | AH16: =VLOOKUP(AG13,'Location Summary'!$G$2:$H$604,2,FALSE) -> 409 | AI16: 3 | AJ16: =VLOOKUP(AI13,'Location Summary'!$G$2:$H$604,2,FALSE) -> 402 | AK16: 3 | AL16: =VLOOKUP(AK13,'Location Summary'!$G$2:$H$604,2,FALSE) -> 409 | AM16: 3 | AN16: =VLOOKUP(AM13,'Location Summary'!$G$2:$H$604,2,FALSE) -> 337 | AO16: 3 | AP16: =VLOOKUP(AO13,'Location Summary'!$G$2:$H$604,2,FALSE) -> 365 | AQ16: 3 | AR16: =VLOOKUP(AQ13,'Location Summary'!$G$2:$H$604,2,FALSE) -> 378 | AS16: 3 | AT16: =VLOOKUP(AS13,'Location Summary'!$G$2:$H$604,2,FALSE) -> 391.467
D17: Erection ROW | Q17: 2 | S17: 2 | U17: 2 | W17: 2 | Y17: 2 | AA17: 2 | AC17: 2 | AE17: 2 | AG17: 2 | AI17: 2 | AK17: 2 | AM17: 2 | AO17: 2 | AQ17: 2 | AS17: 2
O18: Gantry | Q18: =VLOOKUP(Q13,'Location Summary'!$C$2:$J$604,2,FALSE) -> DD60+0 | S18: =VLOOKUP(S13,'Location Summary'!$C$2:$J$604,2,FALSE) -> DD45+0 | U18: =VLOOKUP(U13,'Location Summary'!$C$2:$J$604,2,FALSE) -> DA+0 | W18: =VLOOKUP(W13,'Location Summary'!$C$2:$J$604,2,FALSE) -> DA+3 | Y18: =VLOOKUP(Y13,'Location Summary'!$C$2:$J$604,2,FALSE) -> DA+3 | AA18: =VLOOKUP(AA13,'Location Summary'!$C$2:$J$604,2,FALSE) -> DA+3 | AC18: =VLOOKUP(AC13,'Location Summary'!$C$2:$J$604,2,FALSE) -> DA+3 | AE18: =VLOOKUP(AE13,'Location Summary'!$C$2:$J$604,2,FALSE) -> DA+6 | AG18: =VLOOKUP(AG13,'Location Summary'!$C$2:$J$604,2,FALSE) -> DD45+3 | AI18: =VLOOKUP(AI13,'Location Summary'!$C$2:$J$604,2,FALSE) -> DA+3 | AK18: =VLOOKUP(AK13,'Location Summary'!$C$2:$J$604,2,FALSE) -> DA+3 | AM18: =VLOOKUP(AM13,'Location Summary'!$C$2:$J$604,2,FALSE) -> DA+0 | AO18: =VLOOKUP(AO13,'Location Summary'!$C$2:$J$604,2,FALSE) -> DA+0 | AQ18: =VLOOKUP(AQ13,'Location Summary'!$C$2:$J$604,2,FALSE) -> DA+3 | AS18: =VLOOKUP(AS13,'Location Summary'!$C$2:$J$604,2,FALSE) -> DA+0
C20: =AS12+1 -> 16 | E20: =C20+1 -> 17 | G20: =E20+1 -> 18 | I20: =G20+1 -> 19 | K20: =I20+1 -> 20 | M20: =K20+1 -> 21 | O20: =M20+1 -> 22 | Q20: =O20+1 -> 23 | S20: =Q20+1 -> 24 | U20: =S20+1 -> 25 | W20: =U20+1 -> 26 | Y20: =W20+1 -> 27 | AA20: =Y20+1 -> 28 | AC20: =AA20+1 -> 29 | AE20: =AC20+1 -> 30 | AG20: =AE20+1 -> 31 | AI20: =AG20+1 -> 32 | AK20: =AI20+1 -> 33 | AM20: =AK20+1 -> 34 | AO20: =AM20+1 -> 35 | AQ20: =AO20+1 -> 36 | AS20: =AQ20+1 -> 37
C21: 3B/0 | E21: 3B/1 | G21: 3B/2 | I21: 3B/3 | K21: 4/0 | M21: 4/5 | O21: 4A/0 | Q21: 4A/1 | S21: 4A/2 | U21: 4A/3 | W21: 4A/4 | Y21: 4A/5 | AA21: 4A/6 | AC21: 5/0 | AE21: 5/1 | AG21: 5/2 | AI21: 5/3 | AK21: 5/4 | AM21: 5/5 | AO21: 5/6 | AQ21: 5/7 | AS21: 5/8
C24: 3 | D24: =VLOOKUP(C21,'Location Summary'!$G$2:$H$604,2,FALSE) -> 356 | E24: 3 | F24: =VLOOKUP(E21,'Location Summary'!$G$2:$H$604,2,FALSE) -> 439 | G24: 3 | H24: =VLOOKUP(G21,'Location Summary'!$G$2:$H$604,2,FALSE) -> 377 | I24: 3 | J24: =VLOOKUP(I21,'Location Summary'!$G$2:$H$604,2,FALSE) -> 455.07 | K24: 3 | L24: =VLOOKUP(K21,'Location Summary'!$G$2:$H$604,2,FALSE) -> 344.163 | M24: 3 | N24: =VLOOKUP(M21,'Location Summary'!$G$2:$H$604,2,FALSE) -> 365 | O24: 3 | P24: =VLOOKUP(O21,'Location Summary'!$G$2:$H$604,2,FALSE) -> 340 | Q24: 3 | R24: =VLOOKUP(Q21,'Location Summary'!$G$2:$H$604,2,FALSE) -> 420 | S24: 3 | T24: =VLOOKUP(S21,'Location Summary'!$G$2:$H$604,2,FALSE) -> 415 | U24: 3 | V24: =VLOOKUP(U21,'Location Summary'!$G$2:$H$604,2,FALSE) -> 365 | W24: 3 | X24: =VLOOKUP(W21,'Location Summary'!$G$2:$H$604,2,FALSE) -> 330 | Y24: 3 | Z24: =VLOOKUP(Y21,'Location Summary'!$G$2:$H$604,2,FALSE) -> 457 | AA24: 3 | AB24: =VLOOKUP(AA21,'Location Summary'!$G$2:$H$604,2,FALSE) -> 354.611 | AC24: 3 | AD24: =VLOOKUP(AC21,'Location Summary'!$G$2:$H$604,2,FALSE) -> 428.389 | AE24: 3 | AF24: =VLOOKUP(AE21,'Location Summary'!$G$2:$H$604,2,FALSE) -> 340 | AG24: 3 | AH24: =VLOOKUP(AG21,'Location Summary'!$G$2:$H$604,2,FALSE) -> 375 | AI24: 3 | AJ24: =VLOOKUP(AI21,'Location Summary'!$G$2:$H$604,2,FALSE) -> 365 | AK24: 3 | AL24: =VLOOKUP(AK21,'Location Summary'!$G$2:$H$604,2,FALSE) -> 460 | AM24: 3 | AN24: =VLOOKUP(AM21,'Location Summary'!$G$2:$H$604,2,FALSE) -> 380 | AO24: 3 | AP24: =VLOOKUP(AO21,'Location Summary'!$G$2:$H$604,2,FALSE) -> 410 | AQ24: 3 | AR24: =VLOOKUP(AQ21,'Location Summary'!$G$2:$H$604,2,FALSE) -> 400 | AS24: 3 | AT24: =VLOOKUP(AS21,'Location Summary'!$G$2:$H$604,2,FALSE) -> 420
C25: 2 | E25: 2 | G25: 2 | I25: 2 | K25: 2 | M25: 2 | O25: 2 | Q25: 2 | S25: 2 | U25: 2 | W25: 2 | Y25: 2 | AA25: 2 | AC25: 2 | AE25: 2 | AG25: 2 | AI25: 2 | AK25: 2 | AM25: 2 | AO25: 2 | AQ25: 2 | AS25: 2
C26: =VLOOKUP(C21,'Location Summary'!$C$2:$J$604,2,FALSE) -> DB1+9 | E26: =VLOOKUP(E21,'Location Summary'!$C$2:$J$604,2,FALSE) -> DA+3 | G26: =VLOOKUP(G21,'Location Summary'!$C$2:$J$604,2,FALSE) -> DA+9 | I26: =VLOOKUP(I21,'Location Summary'!$C$2:$J$604,2,FALSE) -> DA+6 | K26: =VLOOKUP(K21,'Location Summary'!$C$2:$J$604,2,FALSE) -> DB2+9 | M26: =VLOOKUP(M21,'Location Summary'!$C$2:$J$604,2,FALSE) -> DA+6 | O26: =VLOOKUP(O21,'Location Summary'!$C$2:$J$604,2,FALSE) -> DB1+3 | Q26: =VLOOKUP(Q21,'Location Summary'!$C$2:$J$604,2,FALSE) -> DA+6 | S26: =VLOOKUP(S21,'Location Summary'!$C$2:$J$604,2,FALSE) -> DA+6 | U26: =VLOOKUP(U21,'Location Summary'!$C$2:$J$604,2,FALSE) -> DA+9 | W26: =VLOOKUP(W21,'Location Summary'!$C$2:$J$604,2,FALSE) -> DA+6 | Y26: =VLOOKUP(Y21,'Location Summary'!$C$2:$J$604,2,FALSE) -> DA+9 | AA26: =VLOOKUP(AA21,'Location Summary'!$C$2:$J$604,2,FALSE) -> DA+9 | AC26: =VLOOKUP(AC21,'Location Summary'!$C$2:$J$604,2,FALSE) -> DB1+6 | AE26: =VLOOKUP(AE21,'Location Summary'!$C$2:$J$604,2,FALSE) -> DA+6 | AG26: =VLOOKUP(AG21,'Location Summary'!$C$2:$J$604,2,FALSE) -> DA+9 | AI26: =VLOOKUP(AI21,'Location Summary'!$C$2:$J$604,2,FALSE) -> DA+9 | AK26: =VLOOKUP(AK21,'Location Summary'!$C$2:$J$604,2,FALSE) -> DA-1.5 | AM26: =VLOOKUP(AM21,'Location Summary'!$C$2:$J$604,2,FALSE) -> DA+6 | AO26: =VLOOKUP(AO21,'Location Summary'!$C$2:$J$604,2,FALSE) -> DA+3 | AQ26: =VLOOKUP(AQ21,'Location Summary'!$C$2:$J$604,2,FALSE) -> DA+9 | AS26: =VLOOKUP(AS21,'Location Summary'!$C$2:$J$604,2,FALSE) -> DA+6
C28: =AS20+1 -> 38 | E28: =C28+1 -> 39 | G28: =E28+1 -> 40 | I28: =G28+1 -> 41 | K28: =I28+1 -> 42 | M28: =K28+1 -> 43 | O28: =M28+1 -> 44 | Q28: =O28+1 -> 45 | S28: =Q28+1 -> 46 | U28: =S28+1 -> 47 | W28: =U28+1 -> 48 | Y28: =W28+1 -> 49 | AA28: =Y28+1 -> 50 | AC28: =AA28+1 -> 51 | AE28: =AC28+1 -> 52 | AG28: =AE28+1 -> 53 | AI28: =AG28+1 -> 54 | AK28: =AI28+1 -> 55 | AM28: =AK28+1 -> 56 | AO28: =AM28+1 -> 57 | AQ28: =AO28+1 -> 58 | AS28: =AQ28+1 -> 59
C29: 5/9 | E29: 5/10 | G29: 5A/0 | I29: 6/0 | K29: 6/1 | M29: 6/2 | O29: 6/3 | Q29: 6/4 | S29: 6/5 | U29: 6/6 | W29: 6/7 | Y29: 6/8 | AA29: 6/9 | AC29: 6/10 | AE29: 6/11 | AG29: 6/12 | AI29: 7/0 | AK29: 7/1 | AM29: 7/2 | AO29: 7/3 | AQ29: 7/4 | AS29: 7/5
C32: 3 | D32: =VLOOKUP(C29,'Location Summary'!$G$2:$H$604,2,FALSE) -> 345 | E32: 3 | F32: =VLOOKUP(E29,'Location Summary'!$G$2:$H$604,2,FALSE) -> 495 | G32: 3 | H32: =VLOOKUP(G29,'Location Summary'!$G$2:$H$604,2,FALSE) -> 419.48 | I32: 3 | J32: =VLOOKUP(I29,'Location Summary'!$G$2:$H$604,2,FALSE) -> 350.52 | K32: 3 | L32: =VLOOKUP(K29,'Location Summary'!$G$2:$H$604,2,FALSE) -> 445 | M32: 3 | N32: =VLOOKUP(M29,'Location Summary'!$G$2:$H$604,2,FALSE) -> 390 | O32: 3 | P32: =VLOOKUP(O29,'Location Summary'!$G$2:$H$604,2,FALSE) -> 350 | Q32: 3 | R32: =VLOOKUP(Q29,'Location Summary'!$G$2:$H$604,2,FALSE) -> 490 | S32: 3 | T32: =VLOOKUP(S29,'Location Summary'!$G$2:$H$604,2,FALSE) -> 350 | U32: 3 | V32: =VLOOKUP(U29,'Location Summary'!$G$2:$H$604,2,FALSE) -> 347 | W32: 3 | X32: =VLOOKUP(W29,'Location Summary'!$G$2:$H$604,2,FALSE) -> 373 | Y32: 3 | Z32: =VLOOKUP(Y29,'Location Summary'!$G$2:$H$604,2,FALSE) -> 380 | AA32: 3 | AB32: =VLOOKUP(AA29,'Location Summary'!$G$2:$H$604,2,FALSE) -> 335 | AC32: 3 | AD32: =VLOOKUP(AC29,'Location Summary'!$G$2:$H$604,2,FALSE) -> 315 | AE32: 3 | AF32: =VLOOKUP(AE29,'Location Summary'!$G$2:$H$604,2,FALSE) -> 410 | AG32: 3 | AH32: =VLOOKUP(AG29,'Location Summary'!$G$2:$H$604,2,FALSE) -> 365.716 | AI32: 3 | AJ32: =VLOOKUP(AI29,'Location Summary'!$G$2:$H$604,2,FALSE) -> 319.284 | AK32: 3 | AL32: =VLOOKUP(AK29,'Location Summary'!$G$2:$H$604,2,FALSE) -> 465 | AM32: 3 | AN32: =VLOOKUP(AM29,'Location Summary'!$G$2:$H$604,2,FALSE) -> 375 | AO32: 3 | AP32: =VLOOKUP(AO29,'Location Summary'!$G$2:$H$604,2,FALSE) -> 355 | AQ32: 3 | AR32: =VLOOKUP(AQ29,'Location Summary'!$G$2:$H$604,2,FALSE) -> 420 | AS32: 3 | AT32: =VLOOKUP(AS29,'Location Summary'!$G$2:$H$604,2,FALSE) -> 315
C33: 2 | E33: 2 | G33: 2 | I33: 2 | K33: 2 | M33: 2 | O33: 2 | Q33: 2 | S33: 2 | U33: 2 | W33: 2 | Y33: 2 | AA33: 2 | AC33: 2 | AE33: 2 | AG33: 2 | AI33: 2 | AK33: 2 | AM33: 2 | AO33: 2 | AQ33: 2 | AS33: 2
C34: =VLOOKUP(C29,'Location Summary'!$C$2:$J$604,2,FALSE) -> DA+6 | E34: =VLOOKUP(E29,'Location Summary'!$C$2:$J$604,2,FALSE) -> DA+9 | G34: =VLOOKUP(G29,'Location Summary'!$C$2:$J$604,2,FALSE) -> DB1+12 | I34: =VLOOKUP(I29,'Location Summary'!$C$2:$J$604,2,FALSE) -> DB1+9 | K34: =VLOOKUP(K29,'Location Summary'!$C$2:$J$604,2,FALSE) -> DA+9 | M34: =VLOOKUP(M29,'Location Summary'!$C$2:$J$604,2,FALSE) -> DA+6 | O34: =VLOOKUP(O29,'Location Summary'!$C$2:$J$604,2,FALSE) -> DA+3 | Q34: =VLOOKUP(Q29,'Location Summary'!$C$2:$J$604,2,FALSE) -> DA+9 | S34: =VLOOKUP(S29,'Location Summary'!$C$2:$J$604,2,FALSE) -> DA+9 | U34: =VLOOKUP(U29,'Location Summary'!$C$2:$J$604,2,FALSE) -> DA-3 | W34: =VLOOKUP(W29,'Location Summary'!$C$2:$J$604,2,FALSE) -> DA+1.5 | Y34: =VLOOKUP(Y29,'Location Summary'!$C$2:$J$604,2,FALSE) -> DA+3 | AA34: =VLOOKUP(AA29,'Location Summary'!$C$2:$J$604,2,FALSE) -> DA+6 | AC34: =VLOOKUP(AC29,'Location Summary'!$C$2:$J$604,2,FALSE) -> DA+1.5 | AE34: =VLOOKUP(AE29,'Location Summary'!$C$2:$J$604,2,FALSE) -> DA-1.5 | AG34: =VLOOKUP(AG29,'Location Summary'!$C$2:$J$604,2,FALSE) -> DA+1.5 | AI34: =VLOOKUP(AI29,'Location Summary'!$C$2:$J$604,2,FALSE) -> DB2+0 | AK34: =VLOOKUP(AK29,'Location Summary'!$C$2:$J$604,2,FALSE) -> DA-3 | AM34: =VLOOKUP(AM29,'Location Summary'!$C$2:$J$604,2,FALSE) -> DA+6 | AO34: =VLOOKUP(AO29,'Location Summary'!$C$2:$J$604,2,FALSE) -> DA+9 | AQ34: =VLOOKUP(AQ29,'Location Summary'!$C$2:$J$604,2,FALSE) -> DA+6 | AS34: =VLOOKUP(AS29,'Location Summary'!$C$2:$J$604,2,FALSE) -> DA+6
C36: =AS28+1 -> 60 | E36: =C36+1 -> 61 | G36: =E36+1 -> 62 | I36: =G36+1 -> 63 | K36: =I36+1 -> 64 | M36: =K36+1 -> 65 | O36: =M36+1 -> 66 | Q36: =O36+1 -> 67 | S36: =Q36+1 -> 68 | U36: =S36+1 -> 69 | W36: =U36+1 -> 70 | Y36: =W36+1 -> 71 | AA36: =Y36+1 -> 72 | AC36: =AA36+1 -> 73 | AE36: =AC36+1 -> 74 | AG36: =AE36+1 -> 75 | AI36: =AG36+1 -> 76 | AK36: =AI36+1 -> 77 | AM36: =AK36+1 -> 78 | AO36: =AM36+1 -> 79 | AQ36: =AO36+1 -> 80 | AS36: =AQ36+1 -> 81
C37: 7/6 | E37: 7A/0 | G37: 7A/1 | I37: 7A/2 | K37: 7A/3 | M37: 7A/4 | O37: 7A/5 | Q37: 8/0 | S37: 8/1 | U37: 8/2 | W37: 8/3 | Y37: 8/4 | AA37: 8/5 | AC37: 8/6 | AE37: 8/7 | AG37: 8/8 | AI37: 8/9 | AK37: 8/10 | AM37: 8/11 | AO37: 8A/0 | AQ37: 9/0 | AS37: 9/1
C40: 3 | D40: =VLOOKUP(C37,'Location Summary'!$G$2:$H$604,2,FALSE) -> 450 | E40: 3 | F40: =VLOOKUP(E37,'Location Summary'!$G$2:$H$604,2,FALSE) -> 435 | G40: 3 | H40: =VLOOKUP(G37,'Location Summary'!$G$2:$H$604,2,FALSE) -> 385 | I40: 3 | J40: =VLOOKUP(I37,'Location Summary'!$G$2:$H$604,2,FALSE) -> 390 | K40: 3 | L40: =VLOOKUP(K37,'Location Summary'!$G$2:$H$604,2,FALSE) -> 405 | M40: 3 | N40: =VLOOKUP(M37,'Location Summary'!$G$2:$H$604,2,FALSE) -> 390 | O40: 3 | P40: =VLOOKUP(O37,'Location Summary'!$G$2:$H$604,2,FALSE) -> 429.77 | Q40: 3 | R40: =VLOOKUP(Q37,'Location Summary'!$G$2:$H$604,2,FALSE) -> 350 | S40: 3 | T40: =VLOOKUP(S37,'Location Summary'!$G$2:$H$604,2,FALSE) -> 330 | U40: 3 | V40: =VLOOKUP(U37,'Location Summary'!$G$2:$H$604,2,FALSE) -> 390 | W40: 3 | X40: =VLOOKUP(W37,'Location Summary'!$G$2:$H$604,2,FALSE) -> 400 | Y40: 3 | Z40: =VLOOKUP(Y37,'Location Summary'!$G$2:$H$604,2,FALSE) -> 338 | AA40: 3 | AB40: =VLOOKUP(AA37,'Location Summary'!$G$2:$H$604,2,FALSE) -> 357 | AC40: 3 | AD40: =VLOOKUP(AC37,'Location Summary'!$G$2:$H$604,2,FALSE) -> 335 | AE40: 3 | AF40: =VLOOKUP(AE37,'Location Summary'!$G$2:$H$604,2,FALSE) -> 415 | AG40: 3 | AH40: =VLOOKUP(AG37,'Location Summary'!$G$2:$H$604,2,FALSE) -> 375 | AI40: 3 | AJ40: =VLOOKUP(AI37,'Location Summary'!$G$2:$H$604,2,FALSE) -> 375 | AK40: 3 | AL40: =VLOOKUP(AK37,'Location Summary'!$G$2:$H$604,2,FALSE) -> 375 | AM40: 3 | AN40: =VLOOKUP(AM37,'Location Summary'!$G$2:$H$604,2,FALSE) -> 415 | AO40: 3 | AP40: =VLOOKUP(AO37,'Location Summary'!$G$2:$H$604,2,FALSE) -> 466.63 | AQ40: 3 | AR40: =VLOOKUP(AQ37,'Location Summary'!$G$2:$H$604,2,FALSE) -> 418.372 | AS40: 3 | AT40: =VLOOKUP(AS37,'Location Summary'!$G$2:$H$604,2,FALSE) -> 410
C41: 2 | E41: 2 | G41: 2 | I41: 2 | K41: 2 | M41: 2 | O41: 2 | Q41: 2 | S41: 2 | U41: 2 | W41: 2 | Y41: 2 | AA41: 2 | AC41: 2 | AE41: 2 | AG41: 2 | AI41: 2 | AK41: 2 | AM41: 2 | AO41: 2 | AQ41: 2 | AS41: 2
C42: =VLOOKUP(C37,'Location Summary'!$C$2:$J$604,2,FALSE) -> DA-1.5 | E42: =VLOOKUP(E37,'Location Summary'!$C$2:$J$604,2,FALSE) -> DB1+6 | G42: =VLOOKUP(G37,'Location Summary'!$C$2:$J$604,2,FALSE) -> DA+1.5 | I42: =VLOOKUP(I37,'Location Summary'!$C$2:$J$604,2,FALSE) -> DA+3 | K42: =VLOOKUP(K37,'Location Summary'!$C$2:$J$604,2,FALSE) -> DA+3 | M42: =VLOOKUP(M37,'Location Summary'!$C$2:$J$604,2,FALSE) -> DA+3 | O42: =VLOOKUP(O37,'Location Summary'!$C$2:$J$604,2,FALSE) -> DA+3 | Q42: =VLOOKUP(Q37,'Location Summary'!$C$2:$J$604,2,FALSE) -> DB1+0 | S42: =VLOOKUP(S37,'Location Summary'!$C$2:$J$604,2,FALSE) -> DA-3 | U42: =VLOOKUP(U37,'Location Summary'!$C$2:$J$604,2,FALSE) -> DA+6 | W42: =VLOOKUP(W37,'Location Summary'!$C$2:$J$604,2,FALSE) -> DA+9 | Y42: =VLOOKUP(Y37,'Location Summary'!$C$2:$J$604,2,FALSE) -> DA+6 | AA42: =VLOOKUP(AA37,'Location Summary'!$C$2:$J$604,2,FALSE) -> DA+9 | AC42: =VLOOKUP(AC37,'Location Summary'!$C$2:$J$604,2,FALSE) -> DA+3 | AE42: =VLOOKUP(AE37,'Location Summary'!$C$2:$J$604,2,FALSE) -> DA+3 | AG42: =VLOOKUP(AG37,'Location Summary'!$C$2:$J$604,2,FALSE) -> DA+9 | AI42: =VLOOKUP(AI37,'Location Summary'!$C$2:$J$604,2,FALSE) -> DA+3 | AK42: =VLOOKUP(AK37,'Location Summary'!$C$2:$J$604,2,FALSE) -> DA+0 | AM42: =VLOOKUP(AM37,'Location Summary'!$C$2:$J$604,2,FALSE) -> DA+9 | AO42: =VLOOKUP(AO37,'Location Summary'!$C$2:$J$604,2,FALSE) -> DB1+12 | AQ42: =VLOOKUP(AQ37,'Location Summary'!$C$2:$J$604,2,FALSE) -> DB1+12 | AS42: =VLOOKUP(AS37,'Location Summary'!$C$2:$J$604,2,FALSE) -> DA+3
C44: =AS36+1 -> 82 | E44: =C44+1 -> 83 | G44: =E44+1 -> 84 | I44: =G44+1 -> 85 | K44: =I44+1 -> 86 | M44: =K44+1 -> 87 | O44: =M44+1 -> 88 | Q44: =O44+1 -> 89 | S44: =Q44+1 -> 90 | U44: =S44+1 -> 91 | W44: =U44+1 -> 92 | Y44: =W44+1 -> 93 | AA44: =Y44+1 -> 94 | AC44: =AA44+1 -> 95 | AE44: =AC44+1 -> 96 | AG44: =AE44+1 -> 97 | AI44: =AG44+1 -> 98 | AK44: =AI44+1 -> 99 | AM44: =AK44+1 -> 100 | AO44: =AM44+1 -> 101 | AQ44: =AO44+1 -> 102 | AS44: =AQ44+1 -> 103
C45: 9/2 | E45: 9/3 | G45: 9/4 | I45: 9/5 | K45: 9/6 | M45: 9/7 | O45: 9/8 | Q45: 9/9 | S45: 9/10 | U45: 9/11 | W45: 10/0 | Y45: 10/1 | AA45: 10/2 | AC45: 11/0 | AE45: 12/0 | AG45: 13/0 | AI45: 13A/0 | AK45: 14/0 | AM45: 15/0 | AO45: 15/1 | AQ45: 15/2 | AS45: 15/3
AF46: 132kV | AL46: 400kV
C48: 3 | D48: =VLOOKUP(C45,'Location Summary'!$G$2:$H$604,2,FALSE) -> 395 | E48: 3 | F48: =VLOOKUP(E45,'Location Summary'!$G$2:$H$604,2,FALSE) -> 395 | G48: 3 | H48: =VLOOKUP(G45,'Location Summary'!$G$2:$H$604,2,FALSE) -> 425 | I48: 3 | J48: =VLOOKUP(I45,'Location Summary'!$G$2:$H$604,2,FALSE) -> 415 | K48: 3 | L48: =VLOOKUP(K45,'Location Summary'!$G$2:$H$604,2,FALSE) -> 405 | M48: 3 | N48: =VLOOKUP(M45,'Location Summary'!$G$2:$H$604,2,FALSE) -> 435 | O48: 3 | P48: =VLOOKUP(O45,'Location Summary'!$G$2:$H$604,2,FALSE) -> 405 | Q48: 3 | R48: =VLOOKUP(Q45,'Location Summary'!$G$2:$H$604,2,FALSE) -> 435 | S48: 3 | T48: =VLOOKUP(S45,'Location Summary'!$G$2:$H$604,2,FALSE) -> 395 | U48: 3 | V48: =VLOOKUP(U45,'Location Summary'!$G$2:$H$604,2,FALSE) -> 431.548 | W48: 3 | X48: =VLOOKUP(W45,'Location Summary'!$G$2:$H$604,2,FALSE) -> 363.452 | Y48: 3 | Z48: =VLOOKUP(Y45,'Location Summary'!$G$2:$H$604,2,FALSE) -> 295 | AA48: 3 | AB48: =VLOOKUP(AA45,'Location Summary'!$G$2:$H$604,2,FALSE) -> 345.731 | AC48: 3 | AD48: =VLOOKUP(AC45,'Location Summary'!$G$2:$H$604,2,FALSE) -> 242.89 | AE48: 3 | AF48: =VLOOKUP(AE45,'Location Summary'!$G$2:$H$604,2,FALSE) -> 329.73 | AG48: 3 | AH48: =VLOOKUP(AG45,'Location Summary'!$G$2:$H$604,2,FALSE) -> 416.88 | AI48: 3 | AJ48: =VLOOKUP(AI45,'Location Summary'!$G$2:$H$604,2,FALSE) -> 480.27 | AK48: 3 | AL48: =VLOOKUP(AK45,'Location Summary'!$G$2:$H$604,2,FALSE) -> 223.82 | AM48: 3 | AN48: =VLOOKUP(AM45,'Location Summary'!$G$2:$H$604,2,FALSE) -> 405.915 | AO48: 3 | AP48: =VLOOKUP(AO45,'Location Summary'!$G$2:$H$604,2,FALSE) -> 405 | AQ48: 3 | AR48: =VLOOKUP(AQ45,'Location Summary'!$G$2:$H$604,2,FALSE) -> 420 | AS48: 3 | AT48: =VLOOKUP(AS45,'Location Summary'!$G$2:$H$604,2,FALSE) -> 415
C49: 2 | E49: 2 | G49: 2 | I49: 2 | K49: 2 | M49: 2 | O49: 2 | Q49: 2 | S49: 2 | U49: 2 | W49: 2 | Y49: 2 | AA49: 2 | AC49: 2 | AE49: 2 | AG49: 2 | AI49: 2 | AK49: 2 | AM49: 2 | AO49: 2 | AQ49: 2 | AS49: 2
C50: =VLOOKUP(C45,'Location Summary'!$C$2:$J$604,2,FALSE) -> DA+3 | E50: =VLOOKUP(E45,'Location Summary'!$C$2:$J$604,2,FALSE) -> DA+0 | G50: =VLOOKUP(G45,'Location Summary'!$C$2:$J$604,2,FALSE) -> DA+6 | I50: =VLOOKUP(I45,'Location Summary'!$C$2:$J$604,2,FALSE) -> DA+3 | K50: =VLOOKUP(K45,'Location Summary'!$C$2:$J$604,2,FALSE) -> DA+3 | M50: =VLOOKUP(M45,'Location Summary'!$C$2:$J$604,2,FALSE) -> DA+9 | O50: =VLOOKUP(O45,'Location Summary'!$C$2:$J$604,2,FALSE) -> DA+0 | Q50: =VLOOKUP(Q45,'Location Summary'!$C$2:$J$604,2,FALSE) -> DA+0 | S50: =VLOOKUP(S45,'Location Summary'!$C$2:$J$604,2,FALSE) -> DA+3 | U50: =VLOOKUP(U45,'Location Summary'!$C$2:$J$604,2,FALSE) -> DA+3 | W50: =VLOOKUP(W45,'Location Summary'!$C$2:$J$604,2,FALSE) -> DB1+6 | Y50: =VLOOKUP(Y45,'Location Summary'!$C$2:$J$604,2,FALSE) -> DA+3 | AA50: =VLOOKUP(AA45,'Location Summary'!$C$2:$J$604,2,FALSE) -> DA+3 | AC50: =VLOOKUP(AC45,'Location Summary'!$C$2:$J$604,2,FALSE) -> DD45+0 | AE50: =VLOOKUP(AE45,'Location Summary'!$C$2:$J$604,2,FALSE) -> DB1+9 | AG50: =VLOOKUP(AG45,'Location Summary'!$C$2:$J$604,2,FALSE) -> DD60+9 | AI50: =VLOOKUP(AI45,'Location Summary'!$C$2:$J$604,2,FALSE) -> DB1+9 | AK50: =VLOOKUP(AK45,'Location Summary'!$C$2:$J$604,2,FALSE) -> DD60+18 | AM50: =VLOOKUP(AM45,'Location Summary'!$C$2:$J$604,2,FALSE) -> DD60+25 | AO50: =VLOOKUP(AO45,'Location Summary'!$C$2:$J$604,2,FALSE) -> DA+6 | AQ50: =VLOOKUP(AQ45,'Location Summary'!$C$2:$J$604,2,FALSE) -> DA+3 | AS50: =VLOOKUP(AS45,'Location Summary'!$C$2:$J$604,2,FALSE) -> DA+3
AC51: NH-62 | AJ51: RC 4 Leg
C52: =AS44+1 -> 104 | E52: =C52+1 -> 105 | G52: =E52+1 -> 106 | I52: =G52+1 -> 107 | K52: =I52+1 -> 108 | M52: =K52+1 -> 109 | O52: =M52+1 -> 110 | Q52: =O52+1 -> 111 | S52: =Q52+1 -> 112 | U52: =S52+1 -> 113 | W52: =U52+1 -> 114 | Y52: =W52+1 -> 115 | AA52: =Y52+1 -> 116 | AC52: =AA52+1 -> 117 | AE52: =AC52+1 -> 118 | AG52: =AE52+1 -> 119 | AI52: =AG52+1 -> 120 | AK52: =AI52+1 -> 121 | AM52: =AK52+1 -> 122 | AO52: =AM52+1 -> 123 | AQ52: =AO52+1 -> 124 | AS52: =AQ52+1 -> 125
C53: 15/4 | E53: 15/5 | G53: 15/6 | I53: 15/7 | K53: 15/8 | M53: 15/9 | O53: 15/10 | Q53: 15/11 | S53: 15/12 | U53: 16/0 | W53: 17/0 | Y53: 18/0 | AA53: 18/1 | AC53: 18/2 | AE53: 18/3 | AG53: 18/4 | AI53: 18/5 | AK53: 18/6 | AM53: 18/7 | AO53: 19/0 | AQ53: 20/0 | AS53: 20/1
C56: 3 | D56: =VLOOKUP(C53,'Location Summary'!$G$2:$H$604,2,FALSE) -> 410 | E56: 3 | F56: =VLOOKUP(E53,'Location Summary'!$G$2:$H$604,2,FALSE) -> 285 | G56: 3 | H56: =VLOOKUP(G53,'Location Summary'!$G$2:$H$604,2,FALSE) -> 355 | I56: 3 | J56: =VLOOKUP(I53,'Location Summary'!$G$2:$H$604,2,FALSE) -> 355 | K56: 3 | L56: =VLOOKUP(K53,'Location Summary'!$G$2:$H$604,2,FALSE) -> 410 | M56: 3 | N56: =VLOOKUP(M53,'Location Summary'!$G$2:$H$604,2,FALSE) -> 430 | O56: 3 | P56: =VLOOKUP(O53,'Location Summary'!$G$2:$H$604,2,FALSE) -> 385 | Q56: 3 | R56: =VLOOKUP(Q53,'Location Summary'!$G$2:$H$604,2,FALSE) -> 455 | S56: 3 | T56: =VLOOKUP(S53,'Location Summary'!$G$2:$H$604,2,FALSE) -> 288.425 | U56: 3 | V56: =VLOOKUP(U53,'Location Summary'!$G$2:$H$604,2,FALSE) -> 392.69 | W56: 3 | X56: =VLOOKUP(W53,'Location Summary'!$G$2:$H$604,2,FALSE) -> 398.4 | Y56: 3 | Z56: =VLOOKUP(Y53,'Location Summary'!$G$2:$H$604,2,FALSE) -> 307.595 | AA56: 3 | AB56: =VLOOKUP(AA53,'Location Summary'!$G$2:$H$604,2,FALSE) -> 390 | AC56: 3 | AD56: =VLOOKUP(AC53,'Location Summary'!$G$2:$H$604,2,FALSE) -> 380 | AE56: 3 | AF56: =VLOOKUP(AE53,'Location Summary'!$G$2:$H$604,2,FALSE) -> 405 | AG56: 3 | AH56: =VLOOKUP(AG53,'Location Summary'!$G$2:$H$604,2,FALSE) -> 335 | AI56: 3 | AJ56: =VLOOKUP(AI53,'Location Summary'!$G$2:$H$604,2,FALSE) -> 425 | AK56: 3 | AL56: =VLOOKUP(AK53,'Location Summary'!$G$2:$H$604,2,FALSE) -> 402 | AM56: 3 | AN56: =VLOOKUP(AM53,'Location Summary'!$G$2:$H$604,2,FALSE) -> 385.434 | AO56: 3 | AP56: =VLOOKUP(AO53,'Location Summary'!$G$2:$H$604,2,FALSE) -> 279.36 | AQ56: 3 | AR56: =VLOOKUP(AQ53,'Location Summary'!$G$2:$H$604,2,FALSE) -> 388.515 | AS56: 3 | AT56: =VLOOKUP(AS53,'Location Summary'!$G$2:$H$604,2,FALSE) -> 330
...

Sheet Stringing
A1: =Erection!A1 -> KEC International Limited
A2: =Erection!A2 -> TA413 : 765 KV D/C Bikaner III - Neemrana II TL02
A3: Details of Stringing | U3: =TA413_PBNTL!M1 -> 27.05.2026
A4: CUMM. SR.NO | B4: MONTH SR.NO. | C4: Section | R4: =SUM(R6:R33)/10^7 -> 7.1955488
C5: From | D5: To | E5: Length in Km's | F5: Cum. Length in Km's | G5: TSE/Manual | H5: Insulator hoisting Start | I5: Insulator Hoisting Complete | J5: Paying Out Start | K5: Paying Out Completed | L5: Final sag start | M5: Final sag complete | N5: Earthwire Final Sag | O5: Jumpuring | P5: Spacering | Q5: Clipping | R5: Revenue | S5: JMC Status | T5: Name of the Contractor | U5: Remarks
A6: 1 | B6: 1 | C6: AP-34 | D6: AP-35 | E6: 4.898588 | F6: =E6 -> 4.898588 | G6: TSE | H6: =I6-2 -> 45694 | I6: 45696 | J6: 45709 | K6: 45714 | L6: =M6-3 -> 45717 | M6: 45720 | N6: 45721 | O6: complete | P6: complete | Q6: complete | R6: =958667.19*E6 -> 4696115.6 | S6: Received | T6: SK Infratech | U6: Completed | V6: Gang Engauged on : 18-01-25
A7: 2 | B7: 1 | C7: 37A/0 | D7: AP-38/0 | E7: =2583.589/1000 -> 2.583589 | F7: =E7+F6 -> 7.482177 | G7: TSE | H7: =I7-2 -> 45727 | I7: 45729 | J7: 45733 | K7: 45736 | L7: =M7-3 -> 45760 | M7: 45763 | N7: 45764 | O7: 45768 | P7: 45783 | Q7: complete | R7: =958667.19*E7 -> 2476802 | S7: Received | T7: SK Infratech | U7: Completed
A8: 3 | B8: 2 | C8: AP-38 | D8: AP-39 | E8: 4.163677 | F8: =E8+F7 -> 11.645854 | G8: TSE | H8: =I8-2 -> 45742 | I8: 45744 | J8: 45745 | K8: 45752 | L8: =M8-1 -> 45762 | M8: 45763 | N8: 45764 | O8: complete | P8: complete | Q8: complete | R8: =958667.19*E8 -> 3991580.5 | S8: Received | T8: SK Infratech | U8: Completed | V8: =R10+R11 -> 4921849.1 | X8: =V8/10^7 -> 0.49218491
A9: 4 | B9: 3 | C9: AP-39 | D9: AP-40 | E9: 4.716 | F9: =E9+F8 -> 16.361854 | G9: TSE | H9: =I9-2 -> 45751 | I9: 45753 | J9: 45772 | K9: 45776 | L9: =M9-1 -> 45776 | M9: 45777 | N9: 45804 | O9: complete | P9: 46014 | Q9: 46014 | R9: =958667.19*E9 -> 4521074.5 | S9: Received | T9: SK Infratech | U9: Completed
A10: 5 | B10: 4 | C10: AP-7 | D10: AP-7A | E10: =2699.284/1000 -> 2.699284 | F10: =E10+F9 -> 19.061138 | G10: TSE | H10: =I10-2 -> 45890 | I10: 45892 | J10: 45896 | K10: 45904 | L10: =M10-1 -> 45917 | M10: 45918 | N10: 45918 | O10: complete | P10: complete | Q10: complete | R10: =958667.19*E10 -> 2587715 | S10: Received | T10: Rahim Khan | U10: Completed | V10: Gang Engauged on: 16.08.25
A11: 6 | B11: 4 | C11: AP-7A | D11: AP-8 | E11: =2434.77/1000 -> 2.43477 | F11: =E11+F10 -> 21.495908 | G11: TSE | H11: =I11-2 -> 45908 | I11: 45910 | J11: 45912 | K11: 45916 | L11: =M11-1 -> 45924 | M11: 45925 | N11: 45925 | O11: complete | P11: complete | Q11: complete | R11: =958667.19*E11 -> 2334134.1 | S11: Received | T11: Rahim Khan | U11: Completed
A12: 7 | B12: 5 | C12: AP-8 | D12: AP-8A | E12: =4455/1000 -> 4.455 | F12: =E12+F11 -> 25.950908 | G12: TSE | H12: =I12-2 -> 45929 | I12: 45931 | J12: 45935 | K12: 45945 | L12: =M12-1 -> 45951 | M12: 45952 | N12: 45952 | O12: 45958 | P12: complete | Q12: complete | R12: =958667.19*E12 -> 4270862.3 | S12: Received | T12: Rahim Khan | U12: Completed
A13: 8 | B13: 6 | C13: AP-8A | D13: AP-9/0 | E13: =466.629/1000 -> 0.466629 | F13: =E13+F12 -> 26.417537 | G13: Manual | H13: =I13-2 -> 45929 | I13: 45931 | J13: 45933 | K13: 45935 | L13: =M13-1 -> 45956 | M13: 45957 | N13: 45957 | O13: 9/0 Balance | P13: complete | Q13: complete | R13: =958667.19*E13 -> 447341.91 | S13: Received | T13: Rahim Khan | U13: Completed
A14: 9 | B14: 7 | C14: AP-6 | D14: AP-7 | E14: =4901.236/1000 -> 4.901236 | F14: =E14+F13 -> 31.318773 | G14: TSE | H14: =I14-2 -> 45973 | I14: 45975 | J14: 45980 | K14: 45984 | L14: =M14-1 -> 45988 | M14: 45989 | N14: 45991 | O14: 46015 | P14: 46010 | Q14: complete | R14: =958667.19*E14 -> 4698654.1 | S14: Received | T14: Rahim Khan | U14: Completed | V14: Gang Engauged 03/09/25
A15: 10 | B15: 8 | C15: AP-5A | D15: AP-6 | E15: =419.48/1000 -> 0.41948 | F15: =E15+F14 -> 31.738253 | G15: Manual | H15: =I15-2 -> 45986 | I15: 45988 | J15: 45966 | K15: 45970 | L15: =M15-1 -> 46002 | M15: 46003 | N15: =M15 -> 46003 | O15: 46033 | P15: 46010 | Q15: complete | R15: =958667.19*E15 -> 402141.71 | S15: Received | T15: Rahim Khan | U15: Completed
A16: 11 | B16: 9 | C16: AP-5 | D16: AP-5A | E16: =4418.389/1000 -> 4.418389 | F16: =E16+F15 -> 36.156642 | G16: TSE | H16: 45985 | I16: 45996 | J16: 45998 | K16: 46003 | L16: =M16-1 -> 46012 | M16: 46013 | N16: 46027 | O16: 46069 | P16: 46031 | Q16: complete | R16: =958667.19*E16 -> 4235764.6 | S16: Received | T16: Rahim Khan | U16: Completed
A17: 12 | B17: 10 | C17: AP-4A | D17: AP-5/0 | E17: =2681.611/1000 -> 2.681611 | F17: =E17+F16 -> 38.838253 | G17: TSE | H17: =I17-2 -> 46003 | I17: 46005 | J17: 46006 | K17: 46013 | L17: =M17-1 -> 46021 | M17: 46022 | N17: 46024 | O17: 46074 | P17: 46041 | Q17: 46033 | R17: =958667.19*E17 -> 2570772.5 | S17: Received | T17: Rahim Khan | U17: Completed
A18: 13 | B18: 1 | C18: AP-4 | D18: AP4A/0 | E18: =709.163/1000 -> 0.709163 | F18: =E18+F17 -> 39.547416 | G18: TSE | H18: =I18-2 -> 46014 | I18: 46016 | J18: 46018 | K18: 46022 | L18: 46036 | M18: 46040 | N18: 46040 | O18: complete | P18: complete | Q18: complete | R18: =958667.19*E18 -> 679851.3 | S18: Received | T18: Rahim Khan | U18: Completed
A19: 14 | B19: 2 | C19: =D21 -> AP-33 | D19: AP-34 | E19: =4049.764/1000 -> 4.049764 | F19: =E19+F18 -> 43.59718 | G19: TSE | H19: =I19-5 -> 46021 | I19: 46026 | J19: 46029 | K19: 46035 | L19: 46043 | M19: 46046 | N19: 46047 | O19: complete | P19: complete | Q19: complete | R19: =958667.19*E19 -> 3882375.9 | S19: Received | T19: SK Infratech | U19: Completed | V19: Noor Alam
A20: 15 | B20: 3 | C20: AP3B/0 | D20: AP4/0 | E20: 1.627 | F20: =E20+F19 -> 45.22418 | G20: TSE | H20: 46032 | I20: 46034 | J20: 46036 | K20: 46039 | L20: 46046 | M20: 46049 | N20: 46050 | O20: complete | P20: complete | Q20: 46054 | R20: =958667.19*E20 -> 1559751.5 | S20: Received | T20: Rahim Khan | U20: Completed
A21: 16 | B21: 4 | C21: AP-32A | D21: AP-33 | E21: 0.84 | F21: =E21+F20 -> 46.06418 | G21: TSE | H21: =I21-3 -> 46038 | I21: =J21+3 -> 46041 | J21: 46038 | K21: 46041 | L21: 46053 | M21: 46059 | N21: =M21+1 -> 46060 | O21: complete | P21: complete | Q21: complete | R21: =958667.19*E21 -> 805280.44 | S21: Received | T21: SK Infratech | U21: Completed
A22: 17 | B22: 5 | C22: AP32/0 | D22: AP32A/0 | E22: 3.284 | F22: =E22+F21 -> 49.34818 | G22: TSE | H22: =J22-4 -> 46043 | I22: =H22+3 -> 46046 | J22: 46047 | K22: 46052 | L22: 46053 | M22: 46059 | N22: =M22+1 -> 46060 | O22: complete | P22: complete | Q22: complete | R22: =958667.19*E22 -> 3148263.1 | S22: Received | T22: SK Infratech | U22: Completed
A23: 18 | B23: 1 | C23: 2A/0 | D23: 3A/0 | E23: 2.837 | F23: =E23+F22 -> 52.18518 | G23: TSE | H23: 46062 | I23: =J23-3 -> 46068 | J23: 46071 | K23: 46079 | L23: 46080 | M23: 46084 | N23: 46086 | O23: Half side balance | P23: complete | Q23: complete | R23: =958667.19*E23 -> 2719738.8 | S23: Received | T23: Rahim Khan | U23: Completed
A24: 19 | B24: 2 | C24: 3A/0 | D24: 3B/0 | E24: =2691.467/1000 -> 2.691467 | F24: =E24+F23 -> 54.876647 | G24: TSE | H24: 46053 | I24: =J24-2 -> 46059 | J24: 46061 | K24: 46066 | L24: 46080 | M24: 46084 | N24: 46086 | O24: complete | P24: complete | Q24: complete | R24: =958667.19*E24 -> 2580221.1 | S24: Received | T24: Rahim Khan | U24: Completed
A25: 20 | B25: 4 | C25: 1/0 | D25: 2A/0 | E25: 0.29 | F25: =E25+F24 -> 55.166647 | G25: Manual | H25: =I25-2 -> 46063 | I25: =J25-2 -> 46065 | J25: 46067 | K25: 46071 | L25: 46090 | M25: 46094 | N25: =M25+1 -> 46095 | O25: Balance | P25: complete | Q25: complete | R25: =958667.19*E25 -> 278013.49 | S25: Received | T25: Rahim Khan | U25: Completed
A26: 21 | B26: 3 | C26: 31/0 | D26: 32/0 | E26: 4.333 | F26: =E26+F25 -> 59.499647 | G26: TSE | H26: 46024 | I26: =J26-2 -> 46061 | J26: 46063 | K26: 46068 | L26: 46083 | M26: 46091 | N26: =M26+1 -> 46092 | O26: complete | P26: complete | Q26: complete | R26: =958667.19*E26 -> 4153904.9 | S26: Received | T26: SK Infratech | U26: Completed
A27: 22 | B27: 1 | C27: 30/0 | D27: 31/0 | E27: 4.124 | F27: =E27+F26 -> 63.623647 | G27: TSE | H27: 46069 | I27: =J27-2 -> 46078 | J27: 46080 | K27: 46087 | L27: 46093 | M27: 46097 | N27: =M27+1 -> 46098 | O27: complete | P27: complete | Q27: complete | R27: =958667.19*E27 -> 3953543.5 | S27: Received | T27: SK Infratech | U27: Completed
A28: 23 | B28: 1 | C28: 9/0 | D28: 10/0 | E28: =4964.92/1000 -> 4.96492 | F28: =E28+F27 -> 68.588567 | G28: TSE | H28: 46084 | I28: 46101 | J28: 46109 | K28: 46114 | L28: 46118 | M28: 46122 | N28: 46122 | O28: complete | P28: complete | Q28: complete | R28: =958667.19*E28 -> 4759705.9 | T28: Rahim Khan | U28: Completed
A29: 24 | B29: 1 | C29: 29A/0 | D29: 30/0 | E29: =2669.007/1000 -> 2.669007 | F29: =E29+F28 -> 71.257574 | G29: TSE | H29: =I29-3 -> 46118 | I29: 46121 | J29: 46134 | K29: 46140 | L29: 46142 | M29: 46145 | N29: 46146 | Q29: complete | R29: =958667.19*E29 -> 2558689.4 | T29: SK Infratech | U29: Completed
A30: 25 | B30: 2 | C30: 10/0 | D30: 11/0 | E30: =1004.183/1000 -> 1.004183 | F30: =E30+F29 -> 72.261757 | G30: TSE | H30: =I30-4 -> 46112 | I30: =J30-3 -> 46116 | J30: 46119 | K30: 46121 | L30: 46154 | M30: 46158 | N30: 46158 | P30: complete | Q30: complete | R30: =958667.19*E30 -> 962677.29 | T30: Rahim Khan | U30: Completed
A31: 26 | B31: 3 | C31: 29/0 | D31: 29A/0 | E31: =2379.204/1000 -> 2.379204 | F31: =E31+F30 -> 74.640961 | G31: TSE | H31: =I31-4 -> 46140 | I31: =J31-6 -> 46144 | J31: 46150 | K31: 46154 | L31: 46155 | M31: 46158 | N31: 46158 | Q31: 3 balance | R31: =958667.19*E31 -> 2280864.8 | T31: SK Infratech | U31: Completed
A32: 27 | C32: 27/0 | D32: 28/0 | E32: =2548.275/1000 -> 2.548275 | F32: =E32+F31 -> 77.189236 | G32: TSE | H32: 46159 | I32: 46162 | J32: 46162 | K32: 46165 | L32: 46166 | T32: SK Infratech | U32: Final sag U/P
A33: 28 | C33: 13/0 | D33: 13A/0 | E33: =416.878/1000 -> 0.416878 | F33: =E33+F31 -> 75.057839 | G33: Manual | H33: 46082 | I33: 46087 | R33: =958667.19*E33 -> 399647.26 | T33: BSPL | U33: Rough sag arangment (Work Hold) | V33: 20
A34: 29 | C34: 11/0 | D34: 12/0 | E34: =242.89/1000 -> 0.24289 | F34: =E34+F33 -> 75.300729 | G34: Manual | T34: Rahim Khan | U34: Bit cutting
A35: 30
A36: 31
A37: 32
A38: 33
A39: 34

Sheet Stretch readiness 
A2: Stretch Readiness Status - 765 KV D/C Bikaner III - Neemrana II TL02 TA-413
B4: Description | C4: Stringing Type | D4: Line length | E4: TSE/Manual Completed | F4: Stringing Compl | G4: Balanced | H4: Remarks
B5: Stringing | C5: 62 | D5: =SUM(C11:C72)/1000 -> 117.85605 | E5: =SUM(E6:E7) -> 27 | F5: =SUM(F6:F7) -> 77.19087 | G5: =D5-F5 -> 40.665184
B6: TSE | C6: 37 | D6: =D5-D7 -> 109.28516 | E6: =COUNTIFS($D$11:$D$72,"TSE",$L$11:$L$72,"Completed") -> 24 | F6: =SUMIFS($C$11:$C$72,$D$11:$D$72,"TSE",$L$11:$L$72,"Completed")/1000 -> 76.01455 | G6: =D6-F6 -> 33.270609 | H6: 2 | M6: =C6-E6 -> 13 | N6: =D6-F6 -> 33.270609
B7: Manual | C7: 25 | D7: =ROUNDUP(SUMIF($D$11:$D$72,$B7,$C$11:$C$72),3)/1000 -> 8.570895 | E7: =COUNTIFS($D$11:$D$72,"Manual",$L$11:$L$72,"Completed") -> 3 | F7: =SUMIFS($C$11:$C$72,$D$11:$D$72,"Manual",$L$11:$L$72,"Completed")/1000 -> 1.17632 | G7: =D7-F7 -> 7.394575 | H7: 0 | M7: =C7-E7 -> 22 | N7: =D7-F7 -> 7.394575
A9: Sl No. | B9: Section | C9: Section Length (M) | D9: Type | E9: Crossing details | F9: No. of Locations (Including for end twr) | G9: Foundation | I9: Erection | L9: Stringing
G10: Completed | H10: Balance | I10: Completed | J10: Balance | K10: Month | L10: Remarks
A11: =IF(B11="","",SUBTOTAL(3,$B$11:B11)) -> 1 | B11: Gantry - AP-1 | C11: 150.014 | D11: Manual | F11: 1 | G11: 1 | H11: =F11-G11 -> 0 | I11: 1 | J11: =F11-I11 -> 0 | K11: mar'26 | L11: pending due to gy not yet ready
A12: =IF(B12="","",SUBTOTAL(3,$B$11:B12)) -> 2 | B12: AP-1 - AP-2A | C12: 290.21 | D12: Manual | F12: 1 | G12: 1 | H12: =F12-G12 -> 0 | I12: 1 | J12: =F12-I12 -> 0 | K12: Jan'26 | L12: Completed
A13: =IF(B13="","",SUBTOTAL(3,$B$11:B13)) -> 3 | B13: AP/2A - AP/3A | C13: 2836.992 | D13: TSE | F13: 7 | G13: 7 | H13: =F13-G13 -> 0 | I13: 7 | J13: =F13-I13 -> 0 | K13: Jan'26 | L13: Completed
A14: =IF(B14="","",SUBTOTAL(3,$B$11:B14)) -> 4 | B14: AP3A/0-AP3B/0 | C14: 2691.467 | D14: TSE | F14: 7 | G14: 7 | H14: =F14-G14 -> 0 | I14: 7 | J14: =F14-I14 -> 0 | K14: Jan'26 | L14: Completed
A15: =IF(B15="","",SUBTOTAL(3,$B$11:B15)) -> 5 | B15: AP3B/0-AP4/0 | C15: 1627.07 | D15: TSE | F15: 4 | G15: 4 | H15: =F15-G15 -> 0 | I15: 4 | J15: =F15-I15 -> 0 | K15: Jan'26 | L15: Completed | M15: Stringing for stringing
A16: =IF(B16="","",SUBTOTAL(3,$B$11:B16)) -> 6 | B16: AP-4 - AP-4A/0 | C16: 709.163 | D16: TSE | F16: 2 | G16: 2 | H16: =F16-G16 -> 0 | I16: 2 | J16: =F16-I16 -> 0 | K16: comp | L16: Completed
A17: =IF(B17="","",SUBTOTAL(3,$B$11:B17)) -> 7 | B17: AP-4A/0 - AP-5 | C17: 2681.611 | D17: TSE | F17: 7 | G17: 7 | H17: =F17-G17 -> 0 | I17: 7 | J17: =F17-I17 -> 0 | K17: comp | L17: Completed
A18: =IF(B18="","",SUBTOTAL(3,$B$11:B18)) -> 8 | B18: AP-5 - AP-5A/0 | C18: 4418.389 | D18: TSE | F18: 11 | G18: 11 | H18: =F18-G18 -> 0 | I18: 11 | J18: =F18-I18 -> 0 | K18: comp | L18: Completed
A19: =IF(B19="","",SUBTOTAL(3,$B$11:B19)) -> 9 | B19: AP-5A/0 - AP-6 | C19: 419.48 | D19: Manual | F19: 1 | G19: 1 | H19: =F19-G19 -> 0 | I19: 1 | J19: =F19-I19 -> 0 | K19: comp | L19: Completed
A20: =IF(B20="","",SUBTOTAL(3,$B$11:B20)) -> 10 | B20: AP-6 - AP-7 | C20: 4901.236 | D20: TSE | F20: 13 | G20: 13 | H20: =F20-G20 -> 0 | I20: 13 | J20: =F20-I20 -> 0 | K20: comp | L20: Completed
A21: =IF(B21="","",SUBTOTAL(3,$B$11:B21)) -> 11 | B21: AP-7 - AP-7A/0 | C21: 2699.284 | D21: TSE | F21: 7 | G21: 7 | H21: =F21-G21 -> 0 | I21: 7 | J21: =F21-I21 -> 0 | K21: comp | L21: Completed
A22: =IF(B22="","",SUBTOTAL(3,$B$11:B22)) -> 12 | B22: AP-7A/0 - AP-8/0 | C22: 2434.77 | D22: TSE | F22: 6 | G22: 6 | H22: =F22-G22 -> 0 | I22: 6 | J22: =F22-I22 -> 0 | K22: comp | L22: Completed
A23: =IF(B23="","",SUBTOTAL(3,$B$11:B23)) -> 13 | B23: AP-8/0 - AP-8A/0 | C23: 4455 | D23: TSE | F23: 12 | G23: 12 | H23: =F23-G23 -> 0 | I23: 12 | J23: =F23-I23 -> 0 | K23: comp | L23: Completed
A24: =IF(B24="","",SUBTOTAL(3,$B$11:B24)) -> 14 | B24: AP-8A/0 - AP-9/0 | C24: 466.63 | D24: Manual | F24: 1 | G24: 1 | H24: =F24-G24 -> 0 | I24: 1 | J24: =F24-I24 -> 0 | K24: comp | L24: Completed
A25: =IF(B25="","",SUBTOTAL(3,$B$11:B25)) -> 15 | B25: AP-9/0 - AP-10/0 | C25: 4964.92 | D25: TSE | F25: 12 | G25: 12 | H25: =F25-G25 -> 0 | I25: 12 | J25: =F25-I25 -> 0 | K25: Jan'26 | L25: Completed
A26: =IF(B26="","",SUBTOTAL(3,$B$11:B26)) -> 16 | B26: AP-10/0 - AP-11/0 | C26: 1004.183 | D26: TSE | F26: 3 | G26: 3 | H26: =F26-G26 -> 0 | I26: 3 | J26: =F26-I26 -> 0 | K26: Feb'26 | L26: Completed
A27: =IF(B27="","",SUBTOTAL(3,$B$11:B27)) -> 17 | B27: AP-11/0 - AP-12/0 | C27: 242.89 | D27: Manual | E27: NH-62 | F27: 1 | G27: 1 | H27: =F27-G27 -> 0 | I27: 1 | J27: =F27-I27 -> 0 | K27: Feb'26 | L27: WIP | M27: Stringing for stringing
A28: =IF(B28="","",SUBTOTAL(3,$B$11:B28)) -> 18 | B28: AP-12/0 - AP-13/0 | C28: 329.73 | D28: Manual | E28: 132 KV | F28: 1 | G28: 1 | H28: =F28-G28 -> 0 | I28: 1 | J28: =F28-I28 -> 0 | K28: Feb'26 | L28: Ready for stringing
A29: =IF(B29="","",SUBTOTAL(3,$B$11:B29)) -> 19 | B29: AP-13/0 - AP-13A/0 | C29: 416.88 | D29: Manual | F29: 1 | G29: 1 | H29: =F29-G29 -> 0 | I29: 1 | J29: =F29-I29 -> 0 | K29: Feb'26 | L29: Insulator hoisting complete
A30: =IF(B30="","",SUBTOTAL(3,$B$11:B30)) -> 20 | B30: AP-13A/0 - AP-14/0 | C30: 480.27 | D30: Manual | F30: 1 | G30: 1 | H30: =F30-G30 -> 0 | I30: 1 | J30: =F30-I30 -> 0 | K30: Feb'26 | L30: Ready for stringing
A31: =IF(B31="","",SUBTOTAL(3,$B$11:B31)) -> 21 | B31: AP-14/0 - AP-15/0 | C31: 223.82 | D31: Manual | E31: 400KV | F31: 1 | G31: 1 | H31: =F31-G31 -> 0 | I31: 1 | J31: =F31-I31 -> 0 | K31: Feb'26 | L31: Ready for stringing
A32: =IF(B32="","",SUBTOTAL(3,$B$11:B32)) -> 22 | B32: AP-15/0 - AP-16/0 | C32: 5019.34 | D32: TSE | F32: 13 | G32: 13 | H32: =F32-G32 -> 0 | I32: 12 | J32: =F32-I32 -> 1 | K32: Feb'26 | L32: Strech Not Ready
A33: =IF(B33="","",SUBTOTAL(3,$B$11:B33)) -> 23 | B33: AP-16/0 - AP-17/0 | C33: 392.69 | D33: Manual | F33: 1 | G33: 1 | H33: =F33-G33 -> 0 | I33: 1 | J33: =F33-I33 -> 0 | K33: Feb'26
A34: =IF(B34="","",SUBTOTAL(3,$B$11:B34)) -> 24 | B34: AP-17/0 - AP-18/0 | C34: 398.4 | D34: Manual | F34: 1 | G34: 1 | H34: =F34-G34 -> 0 | I34: 1 | J34: =F34-I34 -> 0 | K34: Feb'26
A35: =IF(B35="","",SUBTOTAL(3,$B$11:B35)) -> 25 | B35: AP-18/0 - AP-19/0 | C35: 3030.029 | D35: TSE | F35: 8 | G35: 8 | H35: =F35-G35 -> 0 | I35: 8 | J35: =F35-I35 -> 0 | K35: Feb'26
A36: =IF(B36="","",SUBTOTAL(3,$B$11:B36)) -> 26 | B36: AP-19/0 - AP-20/0 | C36: 279.36 | D36: Manual | E36: Railway | F36: 1 | G36: 1 | H36: =F36-G36 -> 0 | I36: 1 | J36: =F36-I36 -> 0 | K36: Feb'26
A37: =IF(B37="","",SUBTOTAL(3,$B$11:B37)) -> 27 | B37: AP-20/0 - AP-21/0 | C37: 2550.167 | D37: TSE | F37: 7 | G37: 7 | H37: =F37-G37 -> 0 | I37: 7 | J37: =F37-I37 -> 0 | K37: mar'26
A38: =IF(B38="","",SUBTOTAL(3,$B$11:B38)) -> 28 | B38: AP-21/0 - AP-22/0 | C38: 2283.535 | D38: TSE | F38: 6 | G38: 6 | H38: =F38-G38 -> 0 | I38: 6 | J38: =F38-I38 -> 0 | K38: mar'26
A39: =IF(B39="","",SUBTOTAL(3,$B$11:B39)) -> 29 | B39: AP-22/0 - AP-23/0 | C39: 259.05 | D39: Manual | E39: 220KV | F39: 1 | G39: 1 | H39: =F39-G39 -> 0 | I39: 1 | J39: =F39-I39 -> 0 | K39: mar'26
A40: =IF(B40="","",SUBTOTAL(3,$B$11:B40)) -> 30 | B40: AP-23/0 - AP-23A/0 | C40: 440.46 | D40: Manual | F40: 1 | G40: 1 | H40: =F40-G40 -> 0 | I40: 1 | J40: =F40-I40 -> 0 | K40: mar'26
A41: =IF(B41="","",SUBTOTAL(3,$B$11:B41)) -> 31 | B41: AP-23A/0 - AP-24/0 | C41: 496.69 | D41: Manual | F41: 1 | G41: 1 | H41: =F41-G41 -> 0 | I41: 1 | J41: =F41-I41 -> 0 | K41: mar'26
A42: =IF(B42="","",SUBTOTAL(3,$B$11:B42)) -> 32 | B42: AP-24/0 - AP-25/0 | C42: 244.03 | D42: Manual | E42: 400KV | F42: 1 | G42: 1 | H42: =F42-G42 -> 0 | I42: 1 | J42: =F42-I42 -> 0 | K42: mar'26
A43: =IF(B43="","",SUBTOTAL(3,$B$11:B43)) -> 33 | B43: AP-25/0 - AP-26/0 | C43: 237.43 | D43: Manual | F43: 1 | G43: 1 | H43: =F43-G43 -> 0 | I43: 1 | J43: =F43-I43 -> 0 | K43: mar'26
...

Sheet Erection
A1: KEC International Limited
A2: TA413 : 765 KV D/C Bikaner III - Neemrana II TL02
A3: Details of Erection | H3: =SUBTOTAL(9,H5:H307) -> 14162.896 | I3: =SUBTOTAL(9,I5:I307) -> 1319.5343 | K3: =TA413_PBNTL!M1 -> 27.05.2026
A4: CUMM. SR.NO | B4: MONTH SR.NO. | C4: Loc. No. | D4: Type of Tower | E4: Start | F4: Complete | G4: Gang name | H4: Weight | I4: Revenue | J4: Name of Supervisor | K4: Remarks | L4: JMC Status
A5: 1 | B5: 1 | C5: 29A/2 | D5: =IFERROR(VLOOKUP(C5,Foundation!$C$5:$D$554,2,0),"") -> DA+6 | E5: 45547 | F5: 45556 | G5: Bhagwan construction | H5: =VLOOKUP(D5,$D$313:$I$342,6,0) -> 43.804424 | I5: =IFERROR(VLOOKUP(D5,$D$313:$K$342,8,0)/10^5,"") -> 4.0811881 | J5: Manoj Kumar Gupta | K5: Completed | L5: Received
A6: =A5+1 -> 2 | B6: 2 | C6: 29/5 | D6: =IFERROR(VLOOKUP(C6,Foundation!$C$5:$D$554,2,0),"") -> DA+0 | E6: =F5 -> 45556 | F6: 45562 | G6: Bhagwan construction | H6: =VLOOKUP(D6,$D$313:$I$342,6,0) -> 36.159756 | I6: =IFERROR(VLOOKUP(D6,$D$313:$K$342,8,0)/10^5,"") -> 3.3689466 | J6: Manoj Kumar Gupta | K6: Completed | L6: Received
A7: =A6+1 -> 3 | B7: 1 | C7: 29/3 | D7: =IFERROR(VLOOKUP(C7,Foundation!$C$5:$D$554,2,0),"") -> DA+0 | E7: =F6+1 -> 45563 | F7: 45568 | G7: Bhagwan construction | H7: =VLOOKUP(D7,$D$313:$I$342,6,0) -> 36.159756 | I7: =IFERROR(VLOOKUP(D7,$D$313:$K$342,8,0)/10^5,"") -> 3.3689466 | J7: Manoj Kumar Gupta | K7: Completed | L7: Received
A8: =A7+1 -> 4 | B8: 2 | C8: 29/4 | D8: =IFERROR(VLOOKUP(C8,Foundation!$C$5:$D$554,2,0),"") -> DA+3 | E8: 45568 | F8: 45573 | G8: Bhagwan construction | H8: =VLOOKUP(D8,$D$313:$I$342,6,0) -> 37.931088 | I8: =IFERROR(VLOOKUP(D8,$D$313:$K$342,8,0)/10^5,"") -> 3.5339788 | J8: Manoj Kumar Gupta | K8: Completed | L8: Received
A9: =A8+1 -> 5 | B9: 3 | C9: 29A/6 | D9: =IFERROR(VLOOKUP(C9,Foundation!$C$5:$D$554,2,0),"") -> DA+9 | E9: 45568 | F9: 45579 | G9: Bhagwan construction | H9: =VLOOKUP(D9,$D$313:$I$342,6,0) -> 45.697022 | I9: =IFERROR(VLOOKUP(D9,$D$313:$K$342,8,0)/10^5,"") -> 4.2575184 | J9: Manoj Kumar Gupta | K9: Completed | L9: Received
A10: =A9+1 -> 6 | B10: 4 | C10: 30/1 | D10: =IFERROR(VLOOKUP(C10,Foundation!$C$5:$D$554,2,0),"") -> DA+0 | E10: 45574 | F10: 45582 | G10: Bhagwan construction | H10: =VLOOKUP(D10,$D$313:$I$342,6,0) -> 36.159756 | I10: =IFERROR(VLOOKUP(D10,$D$313:$K$342,8,0)/10^5,"") -> 3.3689466 | J10: Kartik Mahto | K10: Completed | L10: Received
A11: =A10+1 -> 7 | B11: 5 | C11: 29A/1 | D11: =IFERROR(VLOOKUP(C11,Foundation!$C$5:$D$554,2,0),"") -> DA+6 | E11: =F9 -> 45579 | F11: 45590 | G11: Bhagwan construction | H11: =VLOOKUP(D11,$D$313:$I$342,6,0) -> 43.804424 | I11: =IFERROR(VLOOKUP(D11,$D$313:$K$342,8,0)/10^5,"") -> 4.0811881 | J11: Manoj Kumar Gupta | K11: Completed | L11: Received
A12: =A11+1 -> 8 | B12: 1 | C12: 34/8 | D12: =IFERROR(VLOOKUP(C12,Foundation!$C$5:$D$554,2,0),"") -> DA+0 | E12: 45608 | F12: 45620 | G12: Vasu dev singh-1 | H12: =VLOOKUP(D12,$D$313:$I$342,6,0) -> 36.159756 | I12: =IFERROR(VLOOKUP(D12,$D$313:$K$342,8,0)/10^5,"") -> 3.3689466 | J12: Raju Mahto | K12: Completed | L12: Received
A13: =A12+1 -> 9 | B13: 2 | C13: 34/12 | D13: =IFERROR(VLOOKUP(C13,Foundation!$C$5:$D$554,2,0),"") -> DA+3 | E13: 45610 | F13: 45621 | G13: Vasu dev singh-2 | H13: =VLOOKUP(D13,$D$313:$I$342,6,0) -> 37.931088 | I13: =IFERROR(VLOOKUP(D13,$D$313:$K$342,8,0)/10^5,"") -> 3.5339788 | J13: Mustak | K13: Completed | L13: Received
A14: =A13+1 -> 10 | B14: 1 | C14: 34/4 | D14: =IFERROR(VLOOKUP(C14,Foundation!$C$5:$D$554,2,0),"") -> DA+6 | E14: 45621 | F14: 45630 | G14: Vasu dev singh-1 | H14: =VLOOKUP(D14,$D$313:$I$342,6,0) -> 43.804424 | I14: =IFERROR(VLOOKUP(D14,$D$313:$K$342,8,0)/10^5,"") -> 4.0811881 | J14: Raju Mahto | K14: Completed | L14: Received
A15: =A14+1 -> 11 | B15: 2 | C15: 34/7 | D15: =IFERROR(VLOOKUP(C15,Foundation!$C$5:$D$554,2,0),"") -> DA+0 | E15: 45622 | F15: 45638 | G15: Vasu dev singh-2 | H15: =VLOOKUP(D15,$D$313:$I$342,6,0) -> 36.159756 | I15: =IFERROR(VLOOKUP(D15,$D$313:$K$342,8,0)/10^5,"") -> 3.3689466 | J15: Raju Mahto | K15: Completed | L15: Received
A16: =A15+1 -> 12 | B16: 3 | C16: 34/3 | D16: =IFERROR(VLOOKUP(C16,Foundation!$C$5:$D$554,2,0),"") -> DA+1.5 | E16: 45631 | F16: 45642 | G16: Vasu dev singh-1 | H16: =VLOOKUP(D16,$D$313:$I$342,6,0) -> 37.138324 | I16: =IFERROR(VLOOKUP(D16,$D$313:$K$342,8,0)/10^5,"") -> 3.4601182 | J16: Manoj Kumar Gupta | K16: Completed | L16: Received
A17: =A16+1 -> 13 | B17: 4 | C17: 8/1 | D17: =IFERROR(VLOOKUP(C17,Foundation!$C$5:$D$554,2,0),"") -> DA-3 | E17: 45633 | F17: 45642 | G17: Punam Devi-2 | H17: =VLOOKUP(D17,$D$313:$I$342,6,0) -> 34.78981 | I17: =IFERROR(VLOOKUP(D17,$D$313:$K$342,8,0)/10^5,"") -> 3.2413109 | J17: Sanjay Kumar | K17: Completed | L17: Received
A18: =A17+1 -> 14 | B18: 5 | C18: 34/9 | D18: =IFERROR(VLOOKUP(C18,Foundation!$C$5:$D$554,2,0),"") -> DA+1.5 | E18: 45639 | F18: 45647 | G18: Vasu dev singh-2 | H18: =VLOOKUP(D18,$D$313:$I$342,6,0) -> 37.138324 | I18: =IFERROR(VLOOKUP(D18,$D$313:$K$342,8,0)/10^5,"") -> 3.4601182 | J18: Mustak & Abul | K18: Completed | L18: Received
A19: =A18+1 -> 15 | B19: 6 | C19: 35/7 | D19: =IFERROR(VLOOKUP(C19,Foundation!$C$5:$D$554,2,0),"") -> DA+3 | E19: 45639 | F19: 45648 | G19: Punam Devi-2 | H19: =VLOOKUP(D19,$D$313:$I$342,6,0) -> 37.931088 | I19: =IFERROR(VLOOKUP(D19,$D$313:$K$342,8,0)/10^5,"") -> 3.5339788 | J19: Kartik Mahto | K19: Completed | L19: Received
A20: =A19+1 -> 16 | B20: 7 | C20: 7A/5 | D20: =IFERROR(VLOOKUP(C20,Foundation!$C$5:$D$554,2,0),"") -> DA+3 | E20: 45643 | F20: 45650 | G20: Punam Devi-2 | H20: =VLOOKUP(D20,$D$313:$I$342,6,0) -> 37.931088 | I20: =IFERROR(VLOOKUP(D20,$D$313:$K$342,8,0)/10^5,"") -> 3.5339788 | J20: Sanjay Kumar | K20: Completed | L20: Received
A21: =A20+1 -> 17 | B21: 8 | C21: 36A/1 | D21: =IFERROR(VLOOKUP(C21,Foundation!$C$5:$D$554,2,0),"") -> DA+3 | E21: 45639 | F21: 45651 | G21: Punam Devi-3 | H21: =VLOOKUP(D21,$D$313:$I$342,6,0) -> 37.931088 | I21: =IFERROR(VLOOKUP(D21,$D$313:$K$342,8,0)/10^5,"") -> 3.5339788 | J21: Haridas | K21: Completed | L21: Received
A22: =A21+1 -> 18 | B22: 9 | C22: 7/1 | D22: =IFERROR(VLOOKUP(C22,Foundation!$C$5:$D$554,2,0),"") -> DA-3 | E22: 45641 | F22: 45652 | G22: Punam Devi-1 | H22: =VLOOKUP(D22,$D$313:$I$342,6,0) -> 34.78981 | I22: =IFERROR(VLOOKUP(D22,$D$313:$K$342,8,0)/10^5,"") -> 3.2413109 | J22: Raju Mahto | K22: Completed | L22: Received
A23: =A22+1 -> 19 | B23: 10 | C23: 35/8 | D23: =IFERROR(VLOOKUP(C23,Foundation!$C$5:$D$554,2,0),"") -> DA+6 | E23: 45649 | F23: 45654 | G23: Punam Devi-2 | H23: =VLOOKUP(D23,$D$313:$I$342,6,0) -> 43.804424 | I23: =IFERROR(VLOOKUP(D23,$D$313:$K$342,8,0)/10^5,"") -> 4.0811881 | J23: Kartik Mahto | K23: Completed | L23: Received
... A44: =A43+1 -> 40 | B44: 18 | C44: 35/9 | D44: =IFERROR(VLOOKUP(C44,Foundation!$C$5:$D$554,2,0),"") -> DA+1.5 | E44: 45674 | F44: 45681 | G44: Punam Devi-2 | H44: =VLOOKUP(D44,$D$313:$I$342,6,0) -> 37.138324 | I44: =IFERROR(VLOOKUP(D44,$D$313:$K$342,8,0)/10^5,"") -> 3.4601182 | J44: Kartik Mahto | K44: Completed | L44: Received
A45: =A44+1 -> 41 | B45: 19 | C45: 8/8 | D45: =IFERROR(VLOOKUP(C45,Foundation!$C$5:$D$554,2,0),"") -> DA+9 | E45: =F40 -> 45677 | F45: 45682 | G45: Punam Devi-1 | H45: =VLOOKUP(D45,$D$313:$I$342,6,0) -> 45.697022 | I45: =IFERROR(VLOOKUP(D45,$D$313:$K$342,8,0)/10^5,"") -> 4.2575184 | J45: Gangadin sahoo | K45: Completed | L45: Received
A46: =A45+1 -> 42 | B46: 20 | C46: 34/1 | D46: =IFERROR(VLOOKUP(C46,Foundation!$C$5:$D$554,2,0),"") -> DA+9 | E46: =F41 -> 45678 | F46: 45686 | G46: Vasu dev singh-1 | H46: =VLOOKUP(D46,$D$313:$I$342,6,0) -> 45.697022 | I46: =IFERROR(VLOOKUP(D46,$D$313:$K$342,8,0)/10^5,"") -> 4.2575184 | J46: Manoj Kumar Gupta | K46: Completed | L46: Received
A47: =A46+1 -> 43 | B47: 21 | C47: 38/3 | D47: =IFERROR(VLOOKUP(C47,Foundation!$C$5:$D$554,2,0),"") -> DA+3 | E47: 45681 | F47: 45686 | G47: Punam Devi-2 | H47: =VLOOKUP(D47,$D$313:$I$342,6,0) -> 37.931088 | I47: =IFERROR(VLOOKUP(D47,$D$313:$K$342,8,0)/10^5,"") -> 3.5339788 | J47: Kartik Mahto | K47: Completed | L47: Received
A48: =A47+1 -> 44 | B48: 22 | C48: 8/9 | D48: =IFERROR(VLOOKUP(C48,Foundation!$C$5:$D$554,2,0),"") -> DA+3 | E48: 45682 | F48: 45687 | G48: Punam Devi-4 | H48: =VLOOKUP(D48,$D$313:$I$342,6,0) -> 37.931088 | I48: =IFERROR(VLOOKUP(D48,$D$313:$K$342,8,0)/10^5,"") -> 3.5339788 | J48: Gangadin sahoo | K48: Completed | L48: Received
A49: =A48+1 -> 45 | B49: 23 | C49: 37/5 | D49: =IFERROR(VLOOKUP(C49,Foundation!$C$5:$D$554,2,0),"") -> DA+3 | E49: =F42 -> 45679 | F49: 45687 | G49: Punam Devi-3 | H49: =VLOOKUP(D49,$D$313:$I$342,6,0) -> 37.931088 | I49: =IFERROR(VLOOKUP(D49,$D$313:$K$342,8,0)/10^5,"") -> 3.5339788 | J49: Haridas | K49: Completed | L49: Received
A50: =A49+1 -> 46 | B50: 24 | C50: 7A/0 | D50: =IFERROR(VLOOKUP(C50,Foundation!$C$5:$D$554,2,0),"") -> DB1+6 | E50: =F43 -> 45679 | F50: 45688 | G50: Punam Devi-2 | H50: =VLOOKUP(D50,$D$313:$I$342,6,0) -> 65.027779 | I50: =IFERROR(VLOOKUP(D50,$D$313:$K$342,8,0)/10^5,"") -> 6.0585341 | J50: Raju Mahto | K50: Completed | L50: Received
A51: =A50+1 -> 47 | B51: 25 | C51: 34/0 | D51: =IFERROR(VLOOKUP(C51,Foundation!$C$5:$D$554,2,0),"") -> DB1+6 | E51: 45674 | F51: 45688 | G51: Vasu dev singh-1 | H51: =VLOOKUP(D51,$D$313:$I$342,6,0) -> 65.027779 | I51: =IFERROR(VLOOKUP(D51,$D$313:$K$342,8,0)/10^5,"") -> 6.0585341 | J51: Mustak & Abul | K51: Completed | L51: Received
A52: =A51+1 -> 48 | B52: 1 | C52: 8/10 | D52: =IFERROR(VLOOKUP(C52,Foundation!$C$5:$D$554,2,0),"") -> DA+0 | E52: 45687 | F52: 45691 | G52: Punam Devi-4 | H52: =VLOOKUP(D52,$D$313:$I$342,6,0) -> 36.159756 | I52: =IFERROR(VLOOKUP(D52,$D$313:$K$342,8,0)/10^5,"") -> 3.3689466 | J52: Gangadin sahoo | K52: Completed | L52: Received
A53: =A52+1 -> 49 | B53: 2 | C53: 38/6 | D53: =IFERROR(VLOOKUP(C53,Foundation!$C$5:$D$554,2,0),"") -> DA+6 | E53: 45686 | F53: 45692 | G53: Punam Devi-1 | H53: =VLOOKUP(D53,$D$313:$I$342,6,0) -> 43.804424 | I53: =IFERROR(VLOOKUP(D53,$D$313:$K$342,8,0)/10^5,"") -> 4.0811881 | J53: Kartik Mahto | K53: Completed | L53: Received
A54: =A53+1 -> 50 | B54: 3 | C54: 37A/2 | D54: =IFERROR(VLOOKUP(C54,Foundation!$C$5:$D$554,2,0),"") -> DA+1.5 | E54: 45686 | F54: 45695 | G54: Punam Devi-3 | H54: =VLOOKUP(D54,$D$313:$I$342,6,0) -> 37.138324 | I54: =IFERROR(VLOOKUP(D54,$D$313:$K$342,8,0)/10^5,"") -> 3.4601182 | J54: Haridas | K54: Completed | L54: Received
A55: =A54+1 -> 51 | B55: 4 | C55: 33/6 | D55: =IFERROR(VLOOKUP(C55,Foundation!$C$5:$D$554,2,0),"") -> DA+6 | E55: 45686 | F55: 45696 | G55: Vasu dev singh-2 | H55: =VLOOKUP(D55,$D$313:$I$342,6,0) -> 43.804424 | I55: =IFERROR(VLOOKUP(D55,$D$313:$K$342,8,0)/10^5,"") -> 4.0811881 | J55: Manoj Kumar Gupta | K55: Completed | L55: Received
A56: =A55+1 -> 52 | B56: 5 | C56: 8/2 | D56: =IFERROR(VLOOKUP(C56,Foundation!$C$5:$D$554,2,0),"") -> DA+6 | E56: 45691 | F56: 45696 | G56: Punam Devi-4 | H56: =VLOOKUP(D56,$D$313:$I$342,6,0) -> 43.804424 | I56: =IFERROR(VLOOKUP(D56,$D$313:$K$342,8,0)/10^5,"") -> 4.0811881 | J56: Gangadin sahoo | K56: Completed | L56: Received
A57: =A56+1 -> 53 | B57: 6 | C57: 7/6 | D57: =IFERROR(VLOOKUP(C57,Foundation!$C$5:$D$554,2,0),"") -> DA-1.5 | E57: 45688 | F57: 45698 | G57: Punam Devi-2 | H57: =VLOOKUP(D57,$D$313:$I$342,6,0) -> 35.601762 | I57: =IFERROR(VLOOKUP(D57,$D$313:$K$342,8,0)/10^5,"") -> 3.3169592 | J57: Raju Mahto | K57: Completed | L57: Received
A58: =A57+1 -> 54 | B58: 7 | C58: 38/4 | D58: =IFERROR(VLOOKUP(C58,Foundation!$C$5:$D$554,2,0),"") -> DA+1.5 | E58: 45693 | F58: 45698 | G58: Punam Devi-1 | H58: =VLOOKUP(D58,$D$313:$I$342,6,0) -> 37.138324 | I58: =IFERROR(VLOOKUP(D58,$D$313:$K$342,8,0)/10^5,"") -> 3.4601182 | J58: Kartik Mahto | K58: Completed | L58: Received
A59: =A58+1 -> 55 | B59: 8 | C59: 8/0 | D59: =IFERROR(VLOOKUP(C59,Foundation!$C$5:$D$554,2,0),"") -> DB1+0 | E59: 45697 | F59: 45702 | G59: Punam Devi-4 | H59: =VLOOKUP(D59,$D$313:$I$342,6,0) -> 55.450851 | I59: =IFERROR(VLOOKUP(D59,$D$313:$K$342,8,0)/10^5,"") -> 5.1662671 | J59: Gangadin sahoo | K59: Completed | L59: Received
A60: =A59+1 -> 56 | B60: 9 | C60: 38/5 | D60: =IFERROR(VLOOKUP(C60,Foundation!$C$5:$D$554,2,0),"") -> DA+3 | E60: 45699 | F60: 45703 | G60: Punam Devi-1 | H60: =VLOOKUP(D60,$D$313:$I$342,6,0) -> 37.931088 | I60: =IFERROR(VLOOKUP(D60,$D$313:$K$342,8,0)/10^5,"") -> 3.5339788 | J60: Kartik Mahto | K60: Completed | L60: Received
...

Sheet L2 Plan vs Actual
A1: Project :- TL02 for Bikaner-III - Neemrana-II 765 KV DC Line Part-I associated with Transmission system for excavation of power from Rajasthan REZ Ph-IV (Part-I) (Bikaner Complex: 7.7 GW)
A2: Ref. :- CC/T/W-TW/DOM/A04/23/10569/NOA-1 & 2/24-103421/01 & 02 Date. 12/03/2024
A3: Line Length :- 112 KM | E3: Status as on | F3: =TA413_PBNTL!M1 -> 27.05.2026
A4: S.No. | B4: Activity / Description | C4: UOM | D4: Qty | E4: Start Date | F4: End Date | G4: L2 | H4: Cumm. Till date | I4: Balance | J4: 0 | K4: =J4+1 -> 1 | L4: =K4+1 -> 2 | M4: =L4+1 -> 3 | N4: =M4+1 -> 4 | O4: =N4+1 -> 5 | P4: =O4+1 -> 6 | Q4: =P4+1 -> 7 | R4: =Q4+1 -> 8 | ... AE4: =AD4+1 -> 21
G5: Till date | J5: 45352 | K5: 45383 | L5: 45413 | M5: 45444 | N5: 45474 | O5: 45505 | P5: 45536 | Q5: 45566 | R5: 45597 | S5: 45627 | T5: 45658 | U5: 45689 | V5: 45717 | W5: 45748 | X5: 45778 | Y5: 45809 | Z5: 45839 | AA5: 45870 | AB5: 45901 | AC5: 45931 | AD5: 45962 | AE5: 45992
B6: Supplies
A7: 1 | B7: Line Materials | C7: % | D7: 100 | E7: 45371 | F7: 45738
A8: a | B8: Vendor Finalisation | C8: % | D8: 100 | E8: 45371 | F8: 45406
A9: b | B9: Submission / Approval of Drawings | C9: % | D9: 100 | E9: 45383 | F9: 45411 | K9: 1
A10: c | B10: Receipt at site of Stubs & Earthing | C10: EA | D10: 287 | E10: 45400 | F10: 45616 | G10: =SUM(K10:V10) -> 287 | K10: 25 | L10: 50 | M10: 50 | N10: 50 | P10: 80 | R10: 32
B11: Stubs - Actual Status | H11: 313 | I11: =D10-H11 -> -26 | K11: 0 | L11: 5 | M11: =105+25 -> 130 | N11: 10 | P11: 40 | Q11: 16 | S11: 44 | T11: 34
