Workbook
Name \0: #REF!
Name \0: #REF!
Name \0: #REF!
Name \2: #REF!
Name \A: #REF!
Name \A: #REF!
Name \A_1: "#REF!"
Name \B: #REF!
Name \B: #REF!
Name \B: #REF!
Name \C: #REF!
Name \C: #REF!
Name \c1: #REF!
Name \c1: #REF!
Name \d: #N/A
Name \D: #REF!
Name \g: #REF!
Name \g: #REF!
Name \H: #REF!
Name \H: #REF!
Name \i: #REF!
Name \i: #REF!
Name \KWS123: #N/A
Name \l: #REF!
Name \M: #REF!
Name \M: #REF!
Name \N: #REF!
Name \N: #REF!
Name \P: #REF!
Name \q: #N/A
Name \R: #REF!
Name \R: #REF!
Name \S: #REF!
Name \S: #REF!
Name \t: #N/A
Name \U: #REF!
Name \U: #REF!
Name \V: #REF!
Name \V: #REF!
Name \z: #REF!
Name \z: #REF!
Name _: #REF!
Name _: "tcap"
Name _________________________________________________________dol12: #REF!
Name _________________________________________________________in18900: #REF!
Name _________________________________________________________iv19000: #REF!
Name ________________________________________________________dol12: #REF!
Name ________________________________________________________dol6: #REF!
Name ________________________________________________________in18900: #REF!
Name ________________________________________________________iv19000: #REF!
Name _______________________________________________________dol12: #REF!
Name _______________________________________________________dol6: #REF!
Name _______________________________________________________in18900: #REF!
Name _______________________________________________________iv19000: #REF!
Name ______________________________________________________dol12: #REF!
Name ______________________________________________________dol6: #REF!
Name _____________________________________________________dol12: #REF!
Name _____________________________________________________dol6: #REF!
Name _____________________________________________________in18900: #REF!
Name _____________________________________________________iv19000: #REF!

Sheet VC-765kV MKTL
A1: =[2]TS!A1 -> Name of Line:- 765 KV D/C Mandsaur - Kurawar (Part-1)Transmission Line(WZ-4)
T2: Visual Chart of 765kV Line | AK2: Date | AN2: 46171 | AV2: FDN | AW2: EARTH | AX2: EREC | AY2: T/W | AZ2: Strng | BA2: Length in MTR
AV3: =SUM(AV6:AV182) -> 268 | AW3: =SUM(AW6:AW182) -> 247 | AX3: =SUM(AX6:AX182) -> 208 | AY3: =SUM(AY6:AY182) -> 0 | AZ3: =SUM(AZ6:AZ182) -> 0 | BA3: =SUM(BA6:BA182) -> 118387.01
T5: RC | W5: RC
AV6: 11 | AW6: 11 | AX6: 2 | AY6: 0 | AZ6: 0 | BA6: =+A7+D7+G7+J7+M7+P7+S7+V7+Y7+AB7+AE7+AH7+AK7+AN7+AQ7 -> 5498.422
A7: 107.961 | B7: DD60+0 | D7: 148.478 | E7: DD60+0 | G7: 408.832 | H7: DD45+3 | J7: 380 | K7: DA(-)1.5 | M7: 422 | N7: DA+6 | P7: 408.352 | Q7: DC1+0 | S7: 419.453 | T7: DA+9 | V7: 381 | W7: DA+9 | Y7: 417 | Z7: DA(-)3 | AB7: 417 | AC7: DA+6 | AE7: 417 | AF7: DA(-)3 | AH7: 388.003 | AI7: DA+6 | AK7: 452.343 | AL7: DB1+0 | AN7: 401 | AO7: DA(-)3 | AQ7: 330
B8: 1/0 | E8: 2/0 | H8: 3/0 | K8: 3/1 | N8: 3/2 | Q8: 4/0 | T8: 4/1 | W8: 4/2 | Z8: 4/3 | AC8: 4/4 | AF8: 4/5 | AI8: 4/6 | AL8: 5/0 | AO8: 5/1
B9: MP | E9: MP | H9: MP | K9: MP | N9: MP | Q9: MP | T9: MP | W9: MP | Z9: MP | AC9: MP | AF9: MP | AI9: MP | AL9: MP | AO9: MP
AV14: 14 | AW14: 14 | AX14: 14 | AY14: 0 | AZ14: 0 | BA14: =+A15+D15+G15+J15+M15+P15+S15+V15+Y15+AB15+AE15+AH15+AK15+AN15+AQ15 -> 5348
B15: DA+0 | D15: 413 | E15: DA+3 | G15: 422 | H15: DA+1.5 | J15: 396 | K15: DA+0 | M15: 385 | N15: DA+0 | P15: 338 | Q15: DA(-)3 | S15: 324 | T15: DC2+0 | V15: 380 | W15: DA(-)1.5 | Y15: 374 | Z15: DA+1.5 | AB15: 415 | AC15: DA+1.5 | AE15: 386 | AF15: DC2+0 | AH15: 352 | AI15: DA+0 | AK15: 392 | AL15: DA+0 | AN15: 381 | AO15: DA+0 | AQ15: 390
B16: 5/2 | E16: 5/3 | H16: 5/4 | K16: 5/5 | N16: 5/6 | Q16: 5/7 | T16: 6/0 | W16: 6/1 | Z16: 6/2 | AC16: 6/3 | AF16: 7/0 | AI16: 7/1 | AL16: 7/2 | AO16: 7/3
B17: MP | E17: MP | I17: MP | L17: MP | O17: MP | R17: MP | U17: MP | X17: MP | Z17: MP | AC17: MP | AG17: MP | AI17: MP | AM17: MP | AO17: MP
AV22: 14 | AW22: 14 | AX22: 14 | AY22: 0 | AZ22: 0 | BA22: =+A23+D23+G23+J23+M23+P23+S23+V23+Y23+AB23+AE23+AH23+AK23+AN23+AQ23 -> 5480
B23: DA+0 | D23: 391 | E23: DB1+0 | G23: 331 | H23: DA+0 | J23: 404 | K23: DA+3 | M23: 410 | N23: DA+3 | P23: 398 | Q23: DA+3 | S23: 432 | T23: DA+0 | V23: 356 | W23: DA+0 | Y23: 408 | Z23: DA+0 | AB23: 415 | AC23: DA+3 | AE23: 371 | AF23: DA(-)3 | AH23: 364 | AI23: DA+0 | AK23: 415 | AL23: DB2+0 | AN23: 389 | AO23: DA+3 | AQ23: 396
B24: 7/4 | E24: 8/0 | H24: 8/1 | K24: 8/2 | N24: 8/3 | Q24: 8/4 | T24: 8/5 | W24: 8/6 | Z24: 8/7 | AC24: 8/8 | AF24: 8/9 | AI24: 8/10 | AL24: 9/0 | AO24: 9/1
B25: MP | F25: MP | H25: MP | K25: MP | N25: MP | R25: MP | T25: MP | W25: MP | Z25: MP | AD25: MP | AG25: MP | AJ25: MP | AM25: MP | AO25: MP
T26: Stub Requerd
V27: 400KV D/C
W29: E. RC
AV30: 13 | AW30: 13 | AX30: 13 | AY30: 0 | AZ30: 0 | BA30: =+A31+D31+G31+J31+M31+P31+S31+V31+Y31+AB31+AE31+AH31+AK31+AN31+AQ31 -> 5326
B31: DA+0 | D31: 439 | E31: DA+6 | G31: 381 | H31: DB1+0 | J31: 386 | K31: DA+0 | M31: 356 | N31: DA(-)3 | P31: 365 | Q31: DA+3 | S31: 475 | T31: DD60+25 | V31: 196 | W31: DD60+25 | Y31: 477 | Z31: DA+3 | AB31: 363 | AC31: DA(-)3 | AE31: 328 | AF31: DA(-)3 | AH31: 376 | AI31: DA+0 | AK31: 393 | AL31: DA+1.5 | AN31: 397 | AO31: DA+0 | AQ31: 394
B32: 9/2 | E32: 9/3 | H32: 10/0 | K32: 10/1 | N32: 10/2 | Q32: 10/3 | T32: 11/0 | W32: 12/0 | Z32: 12/1 | AC32: 12/2 | AF32: 12/3 | AI32: 12/4 | AL32: 12/5 | AO32: 12/6
B33: MP | F33: MP | I33: MP | L33: MP | O33: MP | R33: MP | U33: MP | X33: MP | AA33: MP | AD33: MP | AG33: MP | AJ33: MP | AM33: MP | AO33: MP
AV38: 14 | AW38: 14 | AX38: 13 | AY38: 0 | AZ38: 0 | BA38: =+A39+D39+G39+J39+M39+P39+S39+V39+Y39+AB39+AE39+AH39+AK39+AN39+AQ39 -> 5154
B39: DA+0 | D39: 373 | E39: DB2+0 | G39: 357 | H39: DA(-)1.5 | J39: 374 | K39: DA+0 | M39: 380 | N39: DA+0 | P39: 344 | Q39: DA(-)3 | S39: 330 | T39: DA+0 | V39: 367 | W39: DC1+0 | Y39: 385 | Z39: DA+0 | AB39: 355 | AC39: DA+0 | AE39: 357 | AF39: DA(-)3 | AH39: 393 | AI39: DA+3 | AK39: 383 | AL39: DA+0 | AN39: 388 | AO39: DB2+0 | AQ39: 368
B40: 12/7 | E40: 13/0 | H40: 13/1 | K40: 13/2 | N40: 13/3 | Q40: 13/4 | T40: 13/5 | W40: 14/0 | Z40: 14/1 | AC40: 14/2 | AF40: 14/3 | AI40: 14/4 | AL40: 14/5 | AO40: 15/0
C41: MP | F41: MP | I41: MP | L41: MP | N41: MP | R41: MP | U41: MP | X41: MP | AA41: MP | AD41: MP | AG41: MP | AJ41: MP | AL41: MP | AO41: MP
Q45: RC
AV46: 13 | AW46: 13 | AX46: 13 | BA46: =+A47+D47+G47+J47+M47+P47+S47+V47+Y47+AB47+AE47+AH47+AK47+AN47+AQ47 -> 5549
B47: DA+0 | D47: 412 | E47: DA+3 | G47: 416 | H47: DA+0 | J47: 407 | K47: DA+6 | M47: 425 | N47: DA(-)3 | P47: 386 | Q47: DA+0 | S47: 359 | T47: DA+0 | V47: 368 | W47: DA+0 | Y47: 390 | Z47: DA+3 | AB47: 410 | AC47: DB1+0 | AE47: 380 | AF47: DA+0 | AH47: 367 | AI47: DA+0 | AK47: 433 | AL47: DA+9 | AN47: 400 | AO47: DA+0 | AQ47: 396
B48: 15/1 | E48: 15/2 | H48: 15/3 | K48: 15/4 | N48: 15/5 | Q48: 15/6 | T48: 15/7 | W48: 15/8 | Z48: 15/9 | AC48: 16/0 | AF48: 16/1 | AI48: 16/2 | AL48: 16/3 | AO48: 16/4
B49: MP | F49: MP | I49: MP | L49: MP | O49: MP | R49: MP | U49: MP | X49: MP | AA49: MP | AC49: MP | AF49: MP | AI49: MP | AL49: MP | AP49: MP
W50: NH Crossing
AF53: RC | AI53: RC
AV54: 12 | AW54: 12 | AX54: 12 | BA54: =+A55+D55+G55+J55+M55+P55+S55+V55+Y55+AB55+AE55+AH55+AK55+AN55+AQ55 -> 5373
B55: DA+6 | D55: 420 | E55: DA(-)3 | G55: 354 | H55: DA+0 | J55: 348 | K55: DA(-)3 | M55: 319 | N55: DA+0 | P55: 379 | Q55: DA+6 | S55: 428 | T55: DA+0 | V55: 397 | W55: DB2+3 | Y55: 247 | Z55: DD45+0 | AB55: 423 | AC55: DA+6 | AE55: 395 | AF55: DD45+9 | AH55: 499 | AI55: DD60+6 | AK55: 377 | AL55: DA(-)3 | AN55: 443 | AO55: DA(-)3 | AQ55: 344
B56: 16/5 | E56: 16/6 | H56: 16/7 | K56: 16/8 | N56: 16/9 | Q56: 16/10 | T56: 16/11 | W56: 17/0 | Z56: 18/0 | AC56: 18/1 | AF56: 19/0 | AI56: 20/0 | AL56: 20/1 | AO56: 20/2
C57: MP | F57: MP | I57: MP | L57: MP | N57: MP | R57: MP | U57: MP | X57: MP | AA57: MP | AC57: MP | AG57: MP | AJ57: MP | AL57: MP | AO57: MP
Q61: RC | AC61: RC
AV62: 12 | AW62: 12 | AX62: 7 | AY62: 0 | AZ62: 0 | BA62: =+A63+D63+G63+J63+M63+P63+S63+V63+Y63+AB63+AE63+AH63+AK63+AN63+AQ63 -> 5451
...

Sheet DPR
B1: Project Code - | C1: TA-509 | D1: Date | E1: 46171 | G1: Head - T&D | H1: Rajinder Gupta | J1: Head T&D-Central | K1: Nabajit Baruah | Q1: Shortcut for previous of Full description
B2: Client Name- | C2: PGCIL | G2: Project Manager | H2: Prithviraj Dutta Choudhury | L2: Planning Engineer | M2: Shuvayu Das | Q2: Link for go through
B3: Project Name- | C3: 765KV D/C Mandsaur-Kurawar TL line | G3: Effective Date | H3: 26/11/24 | J3: End Date | K3: 25/10/26 | L3: LOA Value | M3: Rs 474. Cr | Q3: X-ing Status'!A1
A4: Sr. No. | B4: Activity | C4: As per L2 (till May'26) | D4: Cumm. Progress up to last Month | E4: Opening Balance (L2) | F4: Plan for this Month | G4: Today Progress | H4: MTD (Loc) | I4: WIP (Loc) | J4: Cumulative Progress | K4: Balance | L4: Gangs at present | M4: Remarks | N4: Support Required | O4: % Completion | Q4: L2 Schedule'!A1
A5: 1 | B5: Check Survey (Kms) | C5: 118.397 | D5: 118.397 | E5: =C5-D5 -> 0 | F5: =E5 -> 0 | J5: =D5+H5 -> 118.397 | K5: =C5-J5 -> 0 | L5: - | O5: =(J5/C5) -> 1 | Q5: Hindrance Register (Row)'!A1
A6: 2 | B6: Foundation (Nos.) | C6: 306 | D6: 258 | E6: =C6-D6 -> 48 | F6: 25 | H6: =SUMMARY!K7 -> 10 | I6: 3 | J6: =D6+H6 -> 268 | K6: =C6-J6 -> 38 | L6: 3 | M6: WIP- 47/0, 47/5, 51/0, 63/0 Today Completed - | N6: ROW- 61/1, 59/1, 47/0, 41/6, 61/0, 60/0, 65/6 | O6: =(J6/C6) -> 0.87581699 | Q6: Survey!A1
A7: 3 | B7: Earthing (Nos.) | C7: 306 | D7: 228 | E7: =C7-D7 -> 78 | F7: 0 | H7: =SUMMARY!K8 -> 19 | I7: 0 | J7: =D7+H7 -> 247 | K7: =C7-J7 -> 59 | M7: WIP- Today Completed - | O7: =(J7/C7) -> 0.80718954 | Q7: Foundation!A1
A8: 4 | B8: Tower Erection (Nos) | C8: 290 | D8: 180 | E8: =C8-D8 -> 110 | F8: 45 | H8: =SUMMARY!K9 -> 28 | I8: 5 | J8: =D8+H8 -> 208 | K8: =C8-J8 -> 82 | L8: 3 | M8: WIP- 21/0, 41/1, 48/6 Today Completed - 49/2 | O8: =(J8/C8) -> 0.71724138 | Q8: Earthing!A1
A9: 5 | B9: Tack Welding (Nos) | C9: 290 | E9: =C9-D9 -> 290 | F9: 45 | J9: =D9+H9 -> 0 | K9: =C9-J9 -> 290 | M9: WIP- Today Completed - | O9: =(J9/C9) -> 0 | Q9: Erection!A1
A10: 6 | B10: Paying Out (Kms) | C10: 12 | E10: =C10-D10 -> 12 | F10: 12.364 | J10: =D10+H10 -> 0 | K10: =+E10-H10 -> 12 | M10: WIP- Today Completed - | O10: =(J10/C10) -> 0 | Q10: Tackwelding!A1
A11: 7 | B11: Final Sag (Kms) | C11: =C10 -> 12 | E11: =C11-D11 -> 12 | J11: =D11+H11 -> 0 | K11: =+E11-H11 -> 12 | M11: WIP- Today Completed - | O11: =(J11/C11) -> 0 | Q11: Stringing!A1
A12: 8 | B12: OPGW (Kms) | C12: =C11 -> 12 | E12: =C12-D12 -> 12 | J12: =D12+H12 -> 0 | K12: =+E12-H12 -> 12 | M12: WIP- Today Completed - | O12: =(J12/C12) -> 0 | Q12: Stringing associated works'!A1
Q13: OPGW!A1
A14: Workfront Status | Q14: Visual chart'!A1
Q15: Page Chart'!A1
A16: A. Foundation | Q16: Benching F'!A1
A17: Balance on 1st of this month | B17: Progress MTD | C17: WIP | D17: Clear/Yet to attempt | E17: ROW | F17: Remarks
A18: =E6 -> 48 | B18: =H6 -> 10 | C18: =I6 -> 3 | E18: =A18-B18-C18-D18 -> 35
A20: B. Erection
A21: Balance on 1st of this month | B21: Progress MTD | C21: WIP | D21: Clear/Yet to attempt | E21: ROW | F21: Linked With Fnd | G21: Remarks
A22: =E8 -> 110 | B22: =H8 -> 28 | C22: =I8 -> 5 | E22: ='[3]Page Chart'!X4 -> 5 | F22: =E18 -> 35
A24: C. Stringing
A25: STR P/Out Bal. on starting of this month | B25: Progress MTD | C25: WIP | D25: Clear/Yet to attempt | E25: ROW | F25: Readiness awaited due to Erec. | G25: Readiness awaited due to Tower Inspection
A26: =E10 -> 12 | B26: =H10 -> 0 | C26: =I10 -> 0
A30: FDN (WIP) | B30: Pit A | C30: Pit B | D30: Pit C | E30: Pit D | F30: Gang name | G30: Gang man power | H30: Gang leader contact | I30: Start date | J30: Target Finish Date | K30: Remarks
A31: 3/0 | B31: Frustum & Step box 1, Step Box 2 completed | C31: Chimney completed | D31: Chimney completed | E31: Steel binding | F31: Musauddin Sk | G31: 15 | H31: 7863971676 | I31: 46149 | J31: 46333
A32: 47/9 | B32: Excavation | C32: Excavation | D32: Excavation | E32: Excavation | F32: Afflux Construction
A33: 51/0 | B33: Excavation | C33: Excavation | D33: Excavation | E33: Excavation | F33: Balaji Cons.
A35: Erection (WIP) | B35: MT | C35: Status | D35: Gange name | E35: Gang man power | F35: Gang leader contact | G35: Start date | H35: Target Finish Date | I35: Completed today (MT) | J35: Completed So far (MT) | K35: Remarks
A36: 21/2 | B36: 36.159756 | C36: Erection completed | D36: Jwala Singh | E36: 25 | K36: Next loc - 24/3
A37: 29/0 | B37: 125.8496 | C37: Cage 1 WIP | E37: 25 | J37: =67243.564/1000 -> 67.243564

Sheet SUMMARY
A1: Name of Line: 765 kV D/C Mandsaur - Kurawar (Part-1)Transmission Line(WZ-4)
A2: Agency: - M/s KEC INTERNATIONAL LIMITED
A3: NOA No.: CC/T/W-TW/DOM/A00/23/13147/NOA-1/24-114171/01 Dated 26/11/2024
N4: Date: | O4: 46171
A5: Activity | D5: LOA Quantity | E5: Final Estimated Quantity | F5: Cum. L2 till Last Month | G5: Cum Progress till Last Month | H5: L2 for present Month | I5: Plan for the Month | J5: Progress for Today | K5: Progress for the Month | L5: Cum. L2 till date | M5: Cum. Progress till date | N5: Balance Work | O5: Under Progress | P5: Gangs at Present | Q5: Completed LOC. (Today) | R5: Remarks
A7: Foundation (Loc) | D7: 309 | E7: 309 | F7: 306 | G7: 258 | H7: 0 | I7: 25 | K7: =M7-G7 -> 10 | L7: =F7+H7 -> 306 | M7: ='VC-765kV MKTL'!AV3 -> 268 | N7: =E7-M7 -> 41 | O7: 47/0, 47/5, 51/0, 63/0 | P7: 3
A8: Earthing (Loc) | D8: 309 | E8: 309 | F8: 262 | G8: 228 | H8: 25 | I8: 25 | K8: =M8-G8 -> 19 | L8: =F8+H8 -> 287 | M8: ='VC-765kV MKTL'!AW3 -> 247 | N8: =D8-M8 -> 62
A9: Erection (Loc) | D9: 309 | E9: 309 | F9: 270 | G9: 180 | H9: 20 | I9: 45 | K9: =M9-G9 -> 28 | L9: =F9+H9 -> 290 | M9: ='VC-765kV MKTL'!AX3 -> 208 | N9: =E9-M9 -> 101 | O9: 21/0, 41/1, 48/6 | P9: 3
A10: Stringing (Km) | C10: Rough Sag | D10: 118.397 | E10: 118.397 | H10: 0 | L10: =F10+H10 -> 0 | M10: =K10+G10 -> 0 | N10: =E10-M10 -> 118.397 | P10: 0
C11: Final Sag | D11: =D10 -> 118.397 | E11: =E10 -> 118.397 | H11: 0 | L11: =L10 -> 0 | M11: =K11+G11 -> 0 | N11: =E11-M11 -> 118.397 | P11: 0
B13: S. No. | C13: Item | D13: Anticipated Qty | E13: UPTO July-25 L2 Schedule | F13: Completed | G13: Balance
B14: 1 | C14: Detailed Survey | D14: 118.397 | E14: 118.397 | F14: 118.397 | G14: =D14-F14 -> 0
B15: 2 | C15: Check Survey | D15: 118.397 | E15: 118.397 | F15: 118.397 | G15: =D15-F15 -> 0

Sheet FDN pivot
A4: Count of LOC No. | B4: Column Labels
A5: Row Labels | B5: A,B,C,D steel binding u/p | C5: COMPLETED | D5: COMPLETED | E5: Excavation u/p | F5: Grand Total
A6: AP39/1 - 47/10 | B6: 1 | C6: 22 | D6: 21 | E6: 2 | F6: 46
A7: Grand Total | B7: 1 | C7: 22 | D7: 21 | E7: 2 | F7: 46

Sheet Erc pivot
A3: Count of LOC No. | B3: Column Labels
A4: Row Labels | B4: 1st sec u/p | C4: COMPLETED | D4: Ground assy | E4: Grand Total
A5: AP 47/11 - AP68 | B5: 1 | C5: 32 | D5: 1 | E5: 34
A6: Grand Total | B6: 1 | C6: 32 | D6: 1 | E6: 34

Sheet XING
A2: Sl. No. | B2: Location No. | C2: Affected Towers/ Locations (Nos) | D2: Area of concern | E2: Name of Transmission Line/Section in between stations | F2: Authority | G2: Type | H2: Proposal Submission date | I2: Status as on date | J2: Place of follow up | K2: Expected date for Work Permission | L2: Responsibility KEC | M2: Responsibility Power Grid | N2: Remarks
A3: 1 | B3: Power Line Crossing
A4: i) | B4: 11/0-12/0 | C4: 2 | D4: Power Line Crossing of Power Grid | E4: EXISTING 400 KV DC NEEMUCH-MANDSAUR TRANSMISSION LINE | F4: Power Grid | G4: OH | H4: 22.05.2025 | I4: Joint inspection Done date on- 04.06.25 | J4: Power Grid Vadodara (RHQ), Neemuch Sub-station of Powergrid | K4: Approved On 21.07.2025 | L4: Devesh | M4: Onkar singh Bharti(DGM)
A5: ii) | B5: 25/0-26/0 | C5: 2 | D5: Power Line Crossing of MPPTCL | E5: 220 KV DC MANDSAUR - NIPANIA TL | F5: Power Grid | G5: OH | H5: 22.05.2025 (Revised submission on 12.06 25) | I5: Joint inspection Done date on- 04.06.25 | J5: Office of Chief Enginneer, MPPTCL, Jabalpur | K5: Approved On 18.08.2025
A6: iii) | B6: 28/0-29/0 | C6: 2 | E6: 220 KV DC SITAMAU-SUWASRA OHTL MPPTCL | F6: Power Grid | G6: OH | H6: 22.05.2025 (Revised submission on 12.06 25, 04.07.2025) | I6: Joint inspection Done date on- 04.06.25 | K6: Approved On 18.08.2025
A7: iv) | B7: 33/0-34/0 | C7: 2 | E7: 132KV D/C SUWASARA - BADOD TL (Joint joint inspection Done) | F7: Power Grid | G7: OH | H7: 22.05.2025 (Revised submission on 12.06 25) | I7: Joint inspection Done date on- 04.06.25 | K7: Approved On 18.08.2025
A8: v) | B8: 37/0-38/0 | C8: 2 | E8: 220 KV OHTL DC BHANPUR-BAROD MPPTCL | F8: Power Grid | G8: OH | H8: 22.05.2025 (Revised submission on 12.06 25) | I8: Joint inspection Done date on- 04.06.25 | K8: Approved On 18.08.2025
A9: vi) | B9: 54/0-55/0 | C9: 2 | E9: 220kV D/C Badod-Nalkheda T/Line | F9: Power Grid | G9: OH | H9: Submission on 18.09.2025 | I9: pending due to finalization of survey for avoiding forest in between section 52/0 - 58/0 | J9: - | K9: - | L9: - | M9: -
A10: vii) | B10: 62/0-63/0 | C10: 2 | E10: 132 KV DC CKT-1 AGAR -SUSNER , CKT-2 AGAR - NALKHEDA OHTL | F10: Power Grid | G10: OH | H10: 22.05.2025 (Revised submission on 12.06 25) | I10: Joint inspection Pending | J10: - | K10: - | L10: - | M10: -
A11: viii) | B11: 42/0-43/0 | C11: 2 | D11: Power Line Crossing of RVPNL | E11: 132 KV SC BHAWANI MANDI - DAG T/L (RRVPNL) | F11: Power Grid | G11: OH | H11: 22.05.2025 | I11: Approved on 04.07.2025 | J11: Office of Chief Enginneer, RVPNL, Jaipur | K11: Approved on 04.07.2025 | L11: Devesh | M11: Onkar singh Bharti(DGM)
A12: ix) | B12: 50/0-51/0 | C12: 2 | D12: Power Line Crossing of RTL | E12: 220 KV S/C SUSNER - PACHORA T/L | F12: Power Grid | G12: OH | H12: 22.05.2025 (Revised submission on 12.06 25) | I12: Joint inspection Pending | J12: Office of Chief Enginneer, RTL, Bhopal | L12: Devesh | M12: Onkar singh Bharti(DGM)
A13: 2 | B13: NH - Crossing
A14: i) | B14: 17/0-18/0 | C14: 2 | D14: NHAI | E14: NE-4 DELHI MUMBAI EXPRESSWAY | F14: Power Grid | G14: OH | H14: 02.06.2025 | I14: Joint inspection Pending | J14: Power Grid Suwasra/Mandsaur | K14: Approved on 07.11.2027 | L14: Devesh | M14: Onkar singh Bharti(DGM)
A15: ii) | B15: 35/0-36/0 | C15: 2 | D15: NHAI | E15: NATIONAL HIGHWAY-752D | F15: Power Grid | G15: OH | H15: 02.06.2025 | I15: joint inspection Done on 22-07-2025 | J15: Power Grid Suwasra/Mandsaur | K15: - | L15: Devesh | M15: Onkar singh Bharti(DGM)
A16: iii) | B16: 60/0-61/0 | C16: 2 | D16: NHAI | E16: NATIONAL HIGHWAY-552G | F16: Power Grid | G16: OH | H16: 02.06.2025 | I16: Joint inspection Pending | J16: Power Grid Suwasra/Mandsaur | K16: - | L16: Devesh | M16: Onkar singh Bharti(DGM)
A17: 3 | B17: Railway Crossing
A18: i) | B18: 31/0-32/0 | C18: 2 | D18: Indian Railway Kota Division | E18: Between Suwasra & Nathukheri Railway station BG | F18: Power Grid | G18: OH | H18: 17.06.2025(Revised submission on 30.06 25) | I18: Joint inspection Done date on- 27.06.2025 revised inspection date pending | J18: Power Grid Suwasra/Mandsaur | K18: Approved on 10.12.2025 | L18: Devesh | M18: Onkar singh Bharti(DGM)
B19: Total | C19: =SUM(C4:C18) -> 26

Sheet ERECTION
A1: ERECTION-STATUS
A2: SL NO. | B2: LOC No. | C2: Tower Type | D2: District wise section | E2: STATUS | F2: STARTING DATE | G2: ENDING DATE | H2: Work starting month | I2: Work completion Month | J2: Sub-Contractor | K2: JMC
A3: 1 | B3: 16/4 | C3: =VLOOKUP(B3,'CST Gantry To AP 68 Common Poin'!C:D,2,0) -> DA+0 | D3: Gantry - AP39/0 | E3: COMPLETED | F3: 22/08/2025 | G3: 45903 | J3: DEVI CONST.-I
A4: 2 | B4: 13/2 | C4: =VLOOKUP(B4,'CST Gantry To AP 68 Common Poin'!C:D,2,0) -> DA+0 | D4: Gantry - AP39/0 | E4: COMPLETED | F4: 22/08/2025 | G4: 45915 | J4: DEONATH MAHATO
A5: 3 | B5: 8/5 | C5: =VLOOKUP(B5,'CST Gantry To AP 68 Common Poin'!C:D,2,0) -> DA+0 | D5: Gantry - AP39/0 | E5: COMPLETED | F5: 25/08/2025 | G5: 45908 | J5: JAWALA SINGH
A6: 4 | B6: 12/6 | C6: =VLOOKUP(B6,'CST Gantry To AP 68 Common Poin'!C:D,2,0) -> DA+0 | D6: Gantry - AP39/0 | E6: COMPLETED | F6: 25/08/2025 | G6: 45918 | J6: MODINA INDIA
A7: 5 | B7: 12/1 | C7: =VLOOKUP(B7,'CST Gantry To AP 68 Common Poin'!C:D,2,0) -> DA+3 | D7: Gantry - AP39/0 | E7: COMPLETED | F7: 02.09.2025 | G7: 45923 | J7: OM CONSTRUCTION
A8: 6 | B8: 15/2 | C8: =VLOOKUP(B8,'CST Gantry To AP 68 Common Poin'!C:D,2,0) -> DA+3 | D8: Gantry - AP39/0 | E8: COMPLETED | F8: 02.09.2025 | G8: 45912 | J8: HEMLAL MAHATO-I (Anita Devi)
A9: 7 | B9: 20/1 | C9: =VLOOKUP(B9,'CST Gantry To AP 68 Common Poin'!C:D,2,0) -> DA(-)3 | D9: Gantry - AP39/0 | E9: COMPLETED | F9: 07.09.2025 | G9: 45914 | J9: DEVI CONST.-I
A10: 8 | B10: 16/1 | C10: =VLOOKUP(B10,'CST Gantry To AP 68 Common Poin'!C:D,2,0) -> DA+0 | D10: Gantry - AP39/0 | E10: COMPLETED | F10: 07.09.2025 | G10: 45912 | J10: DEVI CONST.-II
A11: 9 | B11: 8/6 | C11: =VLOOKUP(B11,'CST Gantry To AP 68 Common Poin'!C:D,2,0) -> DA+0 | D11: Gantry - AP39/0 | E11: COMPLETED | F11: 25/08/2025 | G11: 45914 | J11: JAWALA SINGH
A12: 10 | B12: 13/4 | C12: =VLOOKUP(B12,'CST Gantry To AP 68 Common Poin'!C:D,2,0) -> DA(-)3 | D12: Gantry - AP39/0 | E12: COMPLETED | F12: 13.09.2025 | G12: 45927 | J12: DEONATH MAHATO
A13: 11 | B13: 15/5 | C13: =VLOOKUP(B13,'CST Gantry To AP 68 Common Poin'!C:D,2,0) -> DA(-)3 | D13: Gantry - AP39/0 | E13: COMPLETED | F13: 11.09.2025 | G13: 45919 | J13: HEMLAL MAHATO-I (Anita Devi)
A14: 12 | B14: 16/8 | C14: =VLOOKUP(B14,'CST Gantry To AP 68 Common Poin'!C:D,2,0) -> DA(-)3 | D14: Gantry - AP39/0 | E14: COMPLETED | F14: 13.09.2025 | G14: 45919 | J14: DEVI CONST.-I
... A37: 35 | B37: 16/2 | C37: =VLOOKUP(B37,'CST Gantry To AP 68 Common Poin'!C:D,2,0) -> DA+0 | D37: Gantry - AP39/0 | E37: COMPLETED | F37: 13.11.2025 | G37: 45985 | J37: Arawali infra-2
A38: 36 | B38: 21/4 | C38: =VLOOKUP(B38,'CST Gantry To AP 68 Common Poin'!C:D,2,0) -> DA+3 | D38: Gantry - AP39/0 | E38: COMPLETED | F38: 27.11.2025 | G38: 46000 | I38: Dec'25 | J38: Kaushlya Devi | K38: 44
A39: 37 | B39: 12/3 | C39: =VLOOKUP(B39,'CST Gantry To AP 68 Common Poin'!C:D,2,0) -> DA(-)3 | D39: Gantry - AP39/0 | E39: COMPLETED | F39: 11.11.2025 | G39: 45977 | J39: DEVI CONST.
A40: 38 | B40: 13/0 | C40: =VLOOKUP(B40,'CST Gantry To AP 68 Common Poin'!C:D,2,0) -> DB2+0 | D40: Gantry - AP39/0 | E40: COMPLETED | F40: 16.11.2025 | G40: 45988 | J40: DEVI CONST.
A41: 39 | B41: 5/1 | C41: =VLOOKUP(B41,'CST Gantry To AP 68 Common Poin'!C:D,2,0) -> DA(-)3 | D41: Gantry - AP39/0 | E41: COMPLETED | F41: 20.11.2025 | G41: 45986 | J41: JAWALA SINGH
A42: 40 | B42: 5/3 | C42: =VLOOKUP(B42,'CST Gantry To AP 68 Common Poin'!C:D,2,0) -> DA+3 | D42: Gantry - AP39/0 | E42: COMPLETED | F42: 26.11.2025 | G42: 45991 | J42: JAWALA SINGH
A43: 41 | B43: 15/9 | C43: =VLOOKUP(B43,'CST Gantry To AP 68 Common Poin'!C:D,2,0) -> DA+3 | D43: Gantry - AP39/0 | E43: COMPLETED | F43: 26.11.2025 | G43: 45995 | I43: Dec'25 | J43: Arawali infra-2
A44: 42 | B44: 15/3 | C44: =VLOOKUP(B44,'CST Gantry To AP 68 Common Poin'!C:D,2,0) -> DA+0 | D44: Gantry - AP39/0 | E44: COMPLETED | F44: 27.11.2025 | G44: 45996 | I44: Dec'25 | J44: Arawali infra-1
A45: 43 | B45: 8/1 | C45: =VLOOKUP(B45,'CST Gantry To AP 68 Common Poin'!C:D,2,0) -> DA+0 | D45: Gantry - AP39/0 | E45: COMPLETED | F45: 28.11.2025 | G45: 45994 | I45: Dec'25 | J45: DEVI CONST.
A46: 44 | B46: 5/5 | C46: =VLOOKUP(B46,'CST Gantry To AP 68 Common Poin'!C:D,2,0) -> DA+0 | D46: Gantry - AP39/0 | E46: COMPLETED | F46: 01.12.2025 | G46: 45996 | I46: Dec'25 | J46: JAWALA SINGH
A47: 45 | B47: 15/1 | C47: =VLOOKUP(B47,'CST Gantry To AP 68 Common Poin'!C:D,2,0) -> DA+0 | D47: Gantry - AP39/0 | E47: COMPLETED | F47: 07.12.2025 | G47: 46006 | I47: Dec'25 | J47: Arawali infra-1
A48: 46 | B48: 15/8 | C48: =VLOOKUP(B48,'CST Gantry To AP 68 Common Poin'!C:D,2,0) -> DA+0 | D48: Gantry - AP39/0 | E48: COMPLETED | F48: 04.12.2025 | G48: 46003 | I48: Dec'25 | J48: Arawali infra-2
A49: 47 | B49: 5/7 | C49: =VLOOKUP(B49,'CST Gantry To AP 68 Common Poin'!C:D,2,0) -> DA(-)3 | D49: Gantry - AP39/0 | E49: COMPLETED | F49: 06.12.2025 | G49: 46002 | I49: Dec'25 | J49: JAWALA SINGH
A50: 48 | B50: 8/0 | C50: =VLOOKUP(B50,'CST Gantry To AP 68 Common Poin'!C:D,2,0) -> DB1+0 | D50: Gantry - AP39/0 | E50: COMPLETED | F50: 05.12.2025 | G50: 46007 | I50: Dec'25 | J50: DEVI CONST.
A51: 49 | B51: 15/7 | C51: =VLOOKUP(B51,'CST Gantry To AP 68 Common Poin'!C:D,2,0) -> DA+0 | D51: Gantry - AP39/0 | E51: COMPLETED | F51: 11.12.2025 | G51: 46010 | I51: Dec'25 | J51: Arawali infra-2
A52: 50 | B52: 65/7 | C52: =VLOOKUP(B52,'CST Gantry To AP 68 Common Poin'!C:D,2,0) -> DA(-)3 | D52: AP 47/11 - AP68 | E52: COMPLETED | F52: 11.12.2025 | G52: 46008 | I52: Dec'25 | J52: Anita Devi
A53: 51 | B53: 7/3 | C53: =VLOOKUP(B53,'CST Gantry To AP 68 Common Poin'!C:D,2,0) -> DA+0 | D53: Gantry - AP39/0 | E53: COMPLETED | F53: 12.12.2025 | G53: 46007 | I53: Dec'25 | J53: JAWALA SINGH
A54: 52 | B54: 18/1 | C54: =VLOOKUP(B54,'CST Gantry To AP 68 Common Poin'!C:D,2,0) -> DA+6 | D54: Gantry - AP39/0 | E54: COMPLETED | F54: 14.12.2025 | G54: 46028 | I54: Jan'26 | J54: Kaushlya Devi
... A136: 134 | B136: 30/2 | C136: =VLOOKUP(B136,'CST Gantry To AP 68 Common Poin'!C:D,2,0) -> DA+0 | D136: Gantry - AP39/0 | E136: COMPLETED | F136: 23.03.2026 | G136: 46109 | I136: Mar'26 | J136: Splicenet construction
A137: 135 | B137: 40/1 | C137: =VLOOKUP(B137,'CST Gantry To AP 68 Common Poin'!C:D,2,0) -> DA+3 | D137: AP39/1 - 47/10 | E137: COMPLETED | F137: 24.03.2026 | G137: 46121 | H137: Mar'26 | I137: Apr'26 | J137: ARAVALI INFRA-3
A138: 136 | B138: 27/4 | C138: =VLOOKUP(B138,'CST Gantry To AP 68 Common Poin'!C:D,2,0) -> DA(-)3 | D138: Gantry - AP39/0 | E138: COMPLETED | F138: 25.03.2026 | G138: 46113 | I138: Apr'26 | J138: DEVI CONST.
A139: 137 | B139: 66/6 | C139: =VLOOKUP(B139,'CST Gantry To AP 68 Common Poin'!C:D,2,0) -> DA(-)1.5 | D139: AP 47/11 - AP68 | E139: COMPLETED | F139: 26.03.2026 | G139: 46110 | I139: Mar'26 | J139: Anita Devi
A140: 138 | B140: 48/8 | C140: =VLOOKUP(B140,'CST Gantry To AP 68 Common Poin'!C:D,2,0) -> DA+0 | D140: AP 47/11 - AP68 | E140: COMPLETED | F140: 25.03.2026 | G140: 46112 | I140: Mar'26 | J140: DEVI CONST.-2
A141: 139 | B141: 29/2 | C141: =VLOOKUP(B141,'CST Gantry To AP 68 Common Poin'!C:D,2,0) -> DA+1.5 | D141: Gantry - AP39/0 | E141: COMPLETED | F141: 25.03.2026 | G141: 46116 | I141: Apr'26 | J141: Splicenet construction-II
A142: 140 | B142: 30/1 | C142: =VLOOKUP(B142,'CST Gantry To AP 68 Common Poin'!C:D,2,0) -> DA+1.5 | D142: Gantry - AP39/0 | E142: COMPLETED | F142: 30.03.2026 | G142: 46117 | I142: Apr'26 | J142: Splicenet construction
A143: 141 | B143: 13/3 | C143: =VLOOKUP(B143,'CST Gantry To AP 68 Common Poin'!C:D,2,0) -> DA+0 | D143: Gantry - AP39/0 | E143: COMPLETED | F143: 30.03.2026 | G143: 46114 | I143: Apr'26 | J143: JAWALA SINGH
...

Sheet FOUNDATION
A1: FOUNDATION-STATUS
A2: SL NO. | B2: LOC No. | C2: District wise section | D2: TOWER-TYPE | E2: CLASSIFICATION | F2: STATUS | G2: Man. P | H2: STARTING DATE | I2: ENDING DATE | J2: Work started month | K2: Completed month | L2: Sub-Contractor | M2: JMC | N2: EARTHING | O2: TFR
A3: 1 | B3: 8/1 | C3: Gantry - AP39/0 | D3: DA+0 | E3: DFR | F3: COMPLETED | I3: 45658 | L3: JSC Enterprises | M3: DONE | N3: COMPLETED
A4: 2 | B4: 8/3 | C4: Gantry - AP39/0 | D4: DA+3 | E4: DFR | F4: COMPLETED | I4: 45658 | L4: JSC Enterprises | M4: DONE | N4: COMPLETED
A5: 3 | B5: 8/4 | C5: Gantry - AP39/0 | D5: DA+3 | E5: DFR | F5: COMPLETED | I5: 45658 | L5: JSC Enterprises | M5: DONE | N5: COMPLETED
A6: 4 | B6: 8/6 | C6: Gantry - AP39/0 | D6: DA+0 | E6: DFR | F6: COMPLETED | I6: 45658 | L6: Afflux Construction | M6: DONE | N6: COMPLETED
A7: 5 | B7: 16/4 | C7: Gantry - AP39/0 | D7: DA+0 | E7: DFR | F7: COMPLETED | I7: 45658 | L7: JSC Enterprises | M7: DONE
A8: 6 | B8: 8/5 | C8: Gantry - AP39/0 | D8: DA+0 | E8: DFR | F8: COMPLETED | I8: 45689 | L8: JSC Enterprises | M8: DONE | N8: COMPLETED
A9: 7 | B9: 8/7 | C9: Gantry - AP39/0 | D9: DA+0 | E9: WC | F9: COMPLETED | I9: 45689 | L9: Afflux Construction | M9: DONE | N9: COMPLETED
A10: 8 | B10: 8/8 | C10: Gantry - AP39/0 | D10: DA+3 | E10: WC | F10: COMPLETED | I10: 45689 | L10: Afflux Construction | M10: DONE | N10: COMPLETED
A11: 9 | B11: 8/2 | C11: Gantry - AP39/0 | D11: DA+3 | E11: DFR | F11: COMPLETED | I11: 45689 | L11: JSC Enterprises | M11: DONE | N11: COMPLETED
A12: 10 | B12: 16/1 | C12: Gantry - AP39/0 | D12: DA+0 | E12: DFR | F12: COMPLETED | I12: 45689 | L12: Surya Group | M12: DONE | N12: COMPLETED
A13: 11 | B13: 15/7 | C13: Gantry - AP39/0 | D13: DA+0 | E13: DFR | F13: COMPLETED | I13: 45689 | L13: Surya Group | M13: DONE | N13: COMPLETED
A14: 12 | B14: 7/3 | C14: Gantry - AP39/0 | D14: DA+0 | E14: DFR | F14: COMPLETED | I14: 45689 | L14: Afflux Construction | M14: DONE | N14: COMPLETED
A15: 13 | B15: 9/3 | C15: Gantry - AP39/0 | D15: DA+6 | E15: DFR | F15: COMPLETED | I15: 45689 | L15: JSC Enterprises | M15: DONE
A16: 14 | B16: 15/8 | C16: Gantry - AP39/0 | D16: DA+0 | E16: DFR | F16: COMPLETED | I16: 45689 | L16: Surya Group | M16: DONE | N16: COMPLETED
A17: 15 | B17: 13/1 | C17: Gantry - AP39/0 | D17: DA-1.5 | E17: DFR | F17: COMPLETED | I17: 45689 | L17: Urmila Bibi | M17: DONE | N17: COMPLETED
A18: 16 | B18: 15/2 | C18: Gantry - AP39/0 | D18: DA+3 | E18: DFR | F18: COMPLETED | I18: 45689 | L18: Shree Shyam Granite | M18: DONE | N18: COMPLETED
A19: 17 | B19: 15/9 | C19: Gantry - AP39/0 | D19: DA+3 | E19: DFR | F19: COMPLETED | I19: 45689 | L19: Surya Group | M19: DONE | N19: COMPLETED
A20: 18 | B20: 9/2 | C20: Gantry - AP39/0 | D20: DA+0 | E20: DFR | F20: COMPLETED | I20: 45689 | L20: JSC Enterprises | M20: DONE | N20: COMPLETED
A21: 19 | B21: 13/2 | C21: Gantry - AP39/0 | D21: DA+0 | E21: DFR | F21: COMPLETED | I21: 45689 | L21: Urmila Bibi | M21: DONE | N21: COMPLETED
A22: 20 | B22: 7/4 | C22: Gantry - AP39/0 | D22: DA+0 | E22: DFR | F22: COMPLETED | I22: 45717 | L22: Afflux Construction | M22: DONE | N22: COMPLETED
A23: 21 | B23: 15/4 | C23: Gantry - AP39/0 | D23: DA+6 | E23: DFR | F23: COMPLETED | I23: 45717 | L23: Shree Shyam Granite | M23: DONE | N23: COMPLETED
A24: 22 | B24: 16/2 | C24: Gantry - AP39/0 | D24: DA-3 | E24: WFR | F24: COMPLETED | I24: 45717 | L24: Surya Group | M24: DONE | N24: COMPLETED
A25: 23 | B25: 13/4 | C25: Gantry - AP39/0 | D25: DA-3 | E25: DFR | F25: COMPLETED | I25: 45717 | L25: Urmila Bibi | M25: DONE
A26: 24 | B26: 16/8 | C26: Gantry - AP39/0 | D26: DA-3 | E26: DFR | F26: COMPLETED | I26: 45717 | L26: Surya Group | M26: DONE | N26: COMPLETED
A27: 25 | B27: 7/2 | C27: Gantry - AP39/0 | D27: DA+0 | E27: DFR | F27: COMPLETED | I27: 45717 | L27: Afflux Construction | M27: DONE | N27: COMPLETED
A28: 26 | B28: 13/3 | C28: Gantry - AP39/0 | D28: DA+0 | E28: DFR | F28: COMPLETED | I28: 45717 | L28: Urmila Bibi | M28: DONE
A29: 27 | B29: 10/2 | C29: Gantry - AP39/0 | D29: DA(-)3 | E29: DFR | F29: COMPLETED | I29: 45717 | L29: JSC Enterprises | M29: DONE
A30: 28 | B30: 15/1 | C30: Gantry - AP39/0 | D30: DA+0 | E30: WFR | F30: COMPLETED | I30: 45717 | L30: Shree Shyam Granite | M30: DONE
A31: 29 | B31: 15/5 | C31: Gantry - AP39/0 | D31: DA(-)3 | E31: WFR | F31: COMPLETED | I31: 45717 | L31: Surya Group | M31: DONE | N31: COMPLETED
A32: 30 | B32: 13/5 | C32: Gantry - AP39/0 | D32: DA+0 | E32: DFR | F32: COMPLETED | I32: 45717 | L32: Urmila Bibi | M32: DONE
A33: 31 | B33: 10/1 | C33: Gantry - AP39/0 | D33: DA+0 | E33: DFR | F33: COMPLETED | I33: 45717 | L33: JSC Enterprises | M33: DONE
A34: 32 | B34: 16/3 | C34: Gantry - AP39/0 | D34: DA+9 | E34: WFR | F34: COMPLETED | I34: 45717 | L34: Surya Group | M34: DONE | N34: COMPLETED
A35: 33 | B35: 15/3 | C35: Gantry - AP39/0 | D35: DA+0 | E35: DFR | F35: COMPLETED | I35: 45717 | L35: Shree Shyam Granite | M35: DONE | N35: COMPLETED
A36: 34 | B36: 14/1 | C36: Gantry - AP39/0 | D36: DA+0 | E36: DFR | F36: COMPLETED | I36: 45717 | L36: Urmila Bibi | M36: DONE
A37: 35 | B37: 16/7 | C37: Gantry - AP39/0 | D37: DA+0 | E37: DFR | F37: COMPLETED | I37: 45717 | L37: Surya Group | M37: DONE | N37: COMPLETED
A38: 36 | B38: 12/2 | C38: Gantry - AP39/0 | D38: DA-3 | E38: DFR | F38: COMPLETED | I38: 45717 | L38: Afflux Construction | M38: DONE | N38: COMPLETED
A39: 37 | B39: 14/3 | C39: Gantry - AP39/0 | D39: DA(-)3 | E39: DFR | F39: COMPLETED | I39: 45717 | L39: Urmila Bibi | M39: DONE
A40: 38 | B40: 12/5 | C40: Gantry - AP39/0 | D40: DA+1.5 | E40: DFR | F40: COMPLETED | I40: 45717 | L40: Shree Shyam Granite | M40: DONE
...

Sheet EARTHING
A1: EARTHING
A2: SL NO. | B2: LOC NO. | C2: TYPE OF TOWER | D2: TODAY'S PLAN | E2: TODAY'S PROGRESS | F2: TOMMOROW'S PLAN | G2: START DATE | H2: COMPLETION DATE | I2: GANG
A3: 1 | B3: 8/1 | C3: DA+0 | D3: COMPLETED | G3: 13.05.2025 | H3: 13.05.2025 | I3: JSC CONST.
A4: 2 | B4: 8/2 | C4: DA+3 | D4: COMPLETED | G4: 13.05.2025 | H4: 13.05.2025 | I4: JSC CONST.
A5: 3 | B5: 8/3 | C5: DA+3 | D5: COMPLETED | G5: 13.05.2025 | H5: 13.05.2025 | I5: JSC CONST.
A6: 4 | B6: 20/1 | C6: DA(-)3 | D6: COMPLETED | G6: 13.05.2025 | H6: 13.05.2025 | I6: YATHATHART
A7: 5 | B7: 20/2 | C7: DA(-)3 | D7: COMPLETED | G7: 13.05.2025 | H7: 13.05.2025 | I7: YATHATHART
A8: 6 | B8: 5/3 | C8: DA+3 | D8: COMPLETED | G8: 14.05.2025 | H8: 14.05.2025 | I8: GM CONST.
A9: 7 | B9: 5/4 | C9: DA+1.5 | D9: COMPLETED | G9: 14.05.2025 | H9: 14.05.2025 | I9: GM CONST.
A10: 8 | B10: 6/1 | C10: DA(-)1.5 | D10: COMPLETED | G10: 16.05.2025 | H10: 16.05.2025
A11: 9 | B11: 38/1 | C11: DA(-)3 | D11: COMPLETED | G11: 17.05.2025 | H11: 17.05.2025
A12: 10 | B12: 38/3 | C12: DA(-)3 | D12: COMPLETED | G12: 17.05.2025 | H12: 17.05.2025
A13: 11 | B13: 16/3 | C13: DA+9 | D13: COMPLETED | G13: 19.05.2025 | H13: 19.05.2025
A14: 12 | B14: 16/6 | C14: DA(-)3 | D14: COMPLETED | G14: 19.05.2025 | H14: 19.05.2025
A15: 13 | B15: 16/7 | C15: DA+0 | D15: COMPLETED | G15: 19.05.2025 | H15: 19.05.2025
A16: 14 | B16: 16/8 | C16: DA(-)3 | D16: COMPLETED | G16: 19.05.2025 | H16: 19.05.2025
A17: 15 | B17: 16/9 | C17: DA+0 | D17: COMPLETED | G17: 19.05.2025 | H17: 19.05.2025
A18: 16 | B18: 66/8 | C18: DA(-)3 | D18: COMPLETED | G18: 13.06.2025 | H18: 13.06.2025
A19: 17 | B19: 49/6 | C19: DA+6 | D19: COMPLETED | G19: 17.06.2025 | H19: 17.06.2025 | I19: YATHATHART
A20: 18 | B20: 49/0 | C20: DB1+0 | D20: COMPLETED | G20: 17.06.2025 | H20: 17.06.2025 | I20: GM CONST.
A21: 19 | B21: 66/5 | C21: DA+3 | D21: COMPLETED | G21: 45827 | H21: 45827 | I21: SREE SAI BRICKS
A22: 20 | B22: 65/1 | C22: DA(-)1.5 | D22: COMPLETED | G22: 20.06.2025 | H22: 20.06.2025
A23: 21 | B23: 65/2 | C23: DA+0 | D23: COMPLETED | G23: 30.06.2025 | H23: 30.06.2025
A24: 22 | B24: 65/9 | C24: DA(-)3 | D24: COMPLETED | G24: 10.07.2025 | H24: 10.07.2025
A25: 23 | B25: 63/1 | C25: DA(-)3 | D25: COMPLETED | G25: 15.07.2025 | H25: 15.07.2025
A26: 24 | B26: 65/7 | C26: DA(-)3 | D26: COMPLETED | G26: 17.07.2025 | H26: 17.07.2025
A27: 25 | B27: 21/0 | C27: DC2+0 | D27: COMPLETED | G27: 13/08/2025 | H27: 13/08/2025 | I27: Shakhina Bibi
A28: 26 | B28: 46/0 | C28: DD45+0 | D28: COMPLETED | G28: 16/08/2025 | H28: 16/08/2025
A29: 27 | B29: 15/0 | C29: DB2+0 | D29: COMPLETED | G29: 20.08.2025 | H29: 20.08.2025
A30: 28 | B30: 5/1 | C30: DA(-)3 | D30: COMPLETED
A31: 29 | B31: 5/2 | C31: DA+0 | D31: COMPLETED
A32: 30 | B32: 7/1 | C32: DA+0 | D32: COMPLETED
A33: 31 | B33: 7/2 | C33: DA+0 | D33: COMPLETED
A34: 32 | B34: 7/3 | C34: DA+0 | D34: COMPLETED
A35: 33 | B35: 7/4 | C35: DA+0 | D35: COMPLETED
A36: 34 | B36: 8/4 | C36: DA+3 | D36: COMPLETED
A37: 35 | B37: 8/5 | C37: DA+0 | D37: COMPLETED
A38: 36 | B38: 8/6 | C38: DA+0 | D38: COMPLETED
A39: 37 | B39: 8/7 | C39: DA+0 | D39: COMPLETED
A40: 38 | B40: 8/8 | C40: DA+3 | D40: COMPLETED
...

Sheet SUPPLY
B2: Line Name: | C2: 765KV D/C Mandsaur- Kurawar Transmission Line
B3: Package: | C3: TA-509
B4: Agency: | C4: M/s KEC International Limited
B5: Status as on: | C5: 46166
B6: Supply Status
B7: S. No. | C7: Item Name | D7: Supplier Name | E7: Anticipated Qty | F7: UPTO Dec-25 L2 Schedule | G7: Supplied Qty | H7: Supply In progress | I7: Balance supply | J7: Remarks
B8: 1 | C8: Stub | D8: KEC Int'l Ltd. | E8: 309 | F8: 306 | G8: =272+9 -> 281 | I8: =E8-G8 -> 28
B9: 2 | C9: Tower | D9: KEC Int'l Ltd. | E9: 309 | F9: 230 | G9: 271 | I9: =E9-G9 -> 38
B10: 3 | C10: Conductor | D10: Sterlite | E10: 4343 | F10: 3900 | G10: 4300.418 | I10: =E10-G10 -> 42.582 | J10: Conductor Qty in KM
B11: 4 | C11: H/W fittings | D11: Mosdorfer | E11: 2432 | F11: 0.9 | G11: =E11/100*90 -> 2188.8 | I11: =E11-G11 -> 243.2 | J11: H/W Fitting Qty in Sets
B12: 5 | C12: Insulator | D12: Aditya Birla | E12: 13552 | F12: 11388 | G12: 12832 | I12: =E12-G12 -> 720 | J12: Insulator Qty in Nos | K12: 160KN=5536 | L12: 210KN=7296
B13: 6 | C13: E/W | D13: GK Wires | E13: 121 | F13: 0.85 | G13: 84 | I13: =E13-G13 -> 37 | J13: E/W Qty in KM.
B14: 7 | C14: OPGW | D14: Nirmal Wire Pvt. Ltd. | E14: 126 | F14: 63 | G14: 0 | I14: 126 | J14: OPGW Qty in KM.

Sheet CST Gantry To AP 68 Common Poin
A1: CLIENT :- POWER GRID CORPORATION OF INDIA LIMITED
A2: NAME OF PROJECT :- 765 KV D/C Mandsaur - Kurawar (Part 1) Transmission Line
A3: M/s. KEC INTERNATIONAL LIMITED
A4: TOWER SCHEDULE SECTION:- GANTRY TO AP 68 LENGTH:- 118.386 KM
A5: KEC/TA509/MKTL/CS/AS ON Dt-06.03.2026
A6: Sl.No | B6: AP NO. | C6: TOWER NO. | D6: TYPE OF TOWER | E6: DEVIATION ANGLE (Deg) | F6: SPAN (Mtr) | G6: Section Length (m) | H6: CUMULATIVE SPAN | I6: R.L (Mtr) | J6: HT of Tower (Mtr) | K6: Sum of Adjacent Spans | L6: WIND SPAN (Mtr) | M6: WEIGHT SPAN IN Mtr (Cold) | P6: WEIGHT SPAN IN Mtr (Hot) | S6: Spherical Coordinate | U6: UTM Coordinates | W6: CROSSING DETAILS | X6: NAME OF VILLAGE | Y6: NAME OF TEHSIL | Z6: NAME OF STATAT | AA6: LEG EXTENSION
M7: Left | N7: Right | O7: Total | P7: Left | Q7: Right | R7: Total | S7: Longitude (Easting) | T7: Latitude (Northing) | U7: Easting | V7: Northing | AA7: A | AB7: B | AC7: C | AD7: D
A8: 0 | C8: Mandsur Gantry | D8: Gantry | H8: 0 | I8: 435.03 | J8: 46.3 | K8: 107.961 | L8: 53.9805 | M8: 0 | N8: 6 | O8: 6 | P8: 0 | Q8: 11 | R8: 11 | S8: 75°10'24.829"E | T8: 24°12'17.524"N | U8: 517625.3 | V8: 2676919.5
F9: 107.961 | W9: BOUNDARY WALL
A10: 1 | B10: AP1/0 | C10: 1/0 | D10: DD60+0 | E10: 7° 41' 29"LT | G10: =F9 -> 107.961 | H10: =F9 -> 107.961 | I10: 434.455 | J10: 70.72 | K10: 256.439 | L10: 128.2195 | M10: 33 | N10: 141 | O10: 174 | P10: 35 | Q10: 95 | R10: 130 | S10: 75°10'21.828"E | T10: 24°12'15.345"N | U10: 517540.72 | V10: 2676852.4 | W10: Tower cast at 0deg w.r.t. Gantry | X10: Talabpipalya | Y10: Malhargarh | Z10: MP
F11: 148.478
A12: 2 | B12: AP2/0 | C12: 2/0 | D12: DD60+0 | E12: 58° 40' 0"LT | G12: =F11 -> 148.478 | H12: =H10+F11 -> 256.439 | I12: 431.101 | J12: 70.72 | K12: 557.31 | L12: 278.655 | M12: 7 | N12: 220 | O12: 227 | P12: 53 | Q12: 215 | R12: 268 | S12: 75°10'18.175"E | T12: 24°12'11.87"N | U12: 517437.8 | V12: 2676745.4 | X12: Talabpipalya | Y12: Malhargarh | Z12: MP
F13: 408.832 | W13: NALA/LT LINE
A14: 3 | B14: AP3/0 | C14: 3/0 | D14: DD45+3 | E14: 42° 45' 44"LT | G14: =F13 -> 408.832 | H14: =H12+F13 -> 665.271 | I14: 425.18 | J14: 73.72 | K14: 788.832 | L14: 394.416 | M14: 190 | N14: 213 | O14: 403 | P14: 194 | Q14: 206 | R14: 400 | S14: 75°10'21.856"E | T14: 24°11'59.012"N | U14: 517542.14 | V14: 2676350.1 | X14: Talabpipalya | Y14: Malhargarh | Z14: MP
F15: 380 | W15: ROAD/WELL
A16: 4 | C16: 3/1 | D16: DA(-)1.5 | H16: =H14+F15 -> 1045.271 | I16: 425.63 | J16: 71 | K16: 802 | L16: 401 | M16: 167 | N16: 198 | O16: 365 | P16: 175 | Q16: 202 | R16: 377 | S16: 75°10'33.214"E | T16: 24°11'52.369"N | U16: 517862.8 | V16: 2676146.2 | X16: Talabpipalya | Y16: Malhargarh | Z16: MP
F17: 422 | W17: LT/CT, WELL/NALA
A18: 5 | C18: 3/2 | D18: DA+6 | H18: =H16+F17 -> 1467.271 | I18: 420.86 | J18: 78.5 | K18: 830.352 | L18: 415.176 | M18: 225 | N18: 237 | O18: 462 | P18: 221 | Q18: 228 | R18: 449 | S18: 75°10'45.827"E | T18: 24°11'44.992"N | U18: 518218.91 | V18: 2675919.7 | X18: Talabpipalya | Y18: Malhargarh | Z18: MP
F19: 408.352 | W19: LT LINE, LT T POINT, WELL, CT, NALA/11KV LINE/ LT/CT/ WELL/ SAMADHI
A20: 6 | B20: AP4/0 | C20: 4/0 | D20: DC1+0 | E20: 19° 8' 15"LT | G20: =SUM(F15:F19) -> 1210.352 | H20: =H18+F19 -> 1875.623 | I20: 420.532 | J20: 70.72 | K20: 827.805 | L20: 413.9025 | M20: 171 | N20: 124 | O20: 295 | P20: 182 | Q20: 149 | R20: 331 | S20: 75°10'58.032"E | T20: 24°11'37.853"N | U20: 518563.49 | V20: 2675700.6 | X20: Kachariya | Y20: Malhargarh | Z20: MP
F21: 419.453 | W21: NALA, POND, WELL
A22: 7 | C22: 4/1 | D22: DA+9 | H22: =H20+F21 -> 2295.076 | I22: 429.129 | J22: 81.5 | K22: 800.453 | L22: 400.2265 | M22: 297 | N22: 175 | O22: 472 | P22: 272 | Q22: 179 | R22: 451 | S22: 75°11'12.496"E | T22: 24°11'34.694"N | U22: 518971.67 | V22: 2675604 | W22: Benching / Raised Chimney Expected | X22: Kachariya | Y22: Malhargarh | Z22: MP | AA22: 1.5 | AD22: 0.5
F23: 381 | W23: CT
A24: 8 | C24: 4/2 | D24: DA+9 | H24: =H22+F23 -> 2676.076 | I24: 432.129 | J24: 81.5 | K24: 798.002 | L24: 399.001 | M24: 207 | N24: 312 | O24: 519 | P24: 203 | Q24: 282 | R24: 485 | S24: 75°11'25.634"E | T24: 24°11'31.825"N | U24: 519342.43 | V24: 2675516.3 | W24: Benching / Raised Chimney Expected | X24: Kachariya | Y24: Malhargarh | Z24: MP | AA24: 1.5 | AB24: 2
F25: 417.002
A26: 9 | C26: 4/3 | D26: DA(-)3 | H26: =H24+F25 -> 3093.078 | I26: 423.427 | J26: 69.5 | K26: 834.004 | L26: 417.002 | M26: 107 | N26: 196 | O26: 303 | P26: 136 | Q26: 200 | R26: 336 | S26: 75°11'40.014"E | T26: 24°11'28.684"N | U26: 519748.22 | V26: 2675420.2 | X26: Sohangara | Y26: Malhargarh | Z26: MP
F27: 417.002 | W27: METAL ROAD, CT, 11KV, LT
A28: 10 | C28: 4/4 | D28: DA+6 | H28: =H26+F27 -> 3510.08 | I28: 416.978 | J28: 78.5 | K28: 834.004 | L28: 417.002 | M28: 221 | N28: 270 | O28: 491 | P28: 218 | Q28: 253 | R28: 471 | S28: 75°11'54.393"E | T28: 24°11'25.543"N | U28: 520154.02 | V28: 2675324.2 | X28: Sohangara | Y28: Malhargarh | Z28: MP
F29: 417.002 | W29: WELL, LT
A30: 11 | C30: 4/5 | D30: DA(-)3 | H30: =H28+F29 -> 3927.082 | I30: 413.573 | J30: 69.5 | K30: 805.005 | L30: 402.5025 | M30: 148 | N30: 163 | O30: 311 | P30: 166 | Q30: 172 | R30: 338 | S30: 75°12'8.772"E | T30: 24°11'22.402"N | U30: 520559.81 | V30: 2675228.2 | X30: Sohangara | Y30: Malhargarh | Z30: MP
F31: 388.003 | W31: CT
A32: 12 | C32: 4/6 | D32: DA+6 | H32: =H30+F31 -> 4315.085 | I32: 410.487 | J32: 78.5 | K32: 840.346 | L32: 420.173 | M32: 226 | N32: 248 | O32: 474 | P32: 217 | Q32: 242 | R32: 459 | S32: 75°12'22.151"E | T32: 24°11'19.479"N | U32: 520937.38 | V32: 2675138.8 | X32: Sohangara | Y32: Malhargarh | Z32: MP
F33: 452.343 | W33: 11 KV LINE/SHIVNA RIVER/CART TRACK
A34: 13 | B34: AP5/0 | C34: 5/0 | D34: DB1+0 | E34: 0° 56' 36"LT | G34: =SUM(F21:F33) -> 2891.805 | H34: =H32+F33 -> 4767.428 | I34: 411.761 | J34: 70.72 | K34: 853.343 | L34: 426.6715 | M34: 205 | N34: 239 | O34: 444 | P34: 212 | Q34: 227 | R34: 439 | S34: 75°12'37.748"E | T34: 24°11'16.07"N | U34: 521377.57 | V34: 2675034.7 | X34: Aabakhedi | Y34: Sitamau | Z34: MP
F35: 401 | W35: NALA, PIPAL TREE
A36: 14 | C36: 5/1 | D36: DA(-)3 | H36: =H34+F35 -> 5168.428 | I36: 407.682 | J36: 69.5 | K36: =F35+F37 -> 731 | L36: =K36/2 -> 365.5 | M36: 162 | N36: 118 | O36: 280 | P36: 175 | Q36: 134 | R36: 309 | S36: 75°12'51.627"E | T36: 24°11'13.257"N | U36: 521769.26 | V36: 2674948.7 | X36: Aabakhedi | Y36: Sitamau | Z36: MP
F37: 330 | W37: LT LINE, HUT, CART TRACK
A38: 15 | C38: 5/2 | D38: DA+0 | H38: =H36+F37 -> 5498.428 | I38: 411.854 | J38: 72.5 | K38: =F37+F39 -> 743 | L38: =K38/2 -> 371.5 | M38: 212 | N38: 194 | O38: 406 | P38: 197 | Q38: 199 | R38: 396 | S38: 75°13'3.049"E | T38: 24°11'10.942"N | U38: 522091.59 | V38: 2674878 | X38: Nahargarh | Y38: Sitamau | Z38: MP
F39: 413 | W39: LT LINE, 11KV LINE, CART TRACK, WELL, LT T POINT
A40: 16 | C40: 5/3 | D40: DA+3 | H40: =H38+F39 -> 5911.428 | I40: 411.285 | J40: 75.5 | K40: =F39+F41 -> 835 | L40: =K40/2 -> 417.5 | M40: 220 | N40: 223 | O40: 443 | P40: 216 | Q40: 219 | R40: 435 | S40: 75°13'17.343"E | T40: 24°11'8.045"N | U40: 522495.01 | V40: 2674789.6 | X40: Nahargarh | Y40: Sitamau | Z40: MP
...

Sheet Sheet1
D3: VC-765kV MKTL'!A1
E5: FOUNDATION!A1
E6: EARTHING!A1
E7: ERECTION!A1
E8: TS!A1

Sheet SURVEY SUMMARY
A1: Original Route alignment | B1: KM | C1: 118.288 | D1: 106.341 | E1: 106.341
A2: Detailed Survey | B2: KM | C2: 118.288 | D2: 106.341 | E2: 106.341
A3: Diverted Route Alignment | B3: KM | C3: 0 | D3: 1.558 | E3: Pending | G3: TRUE
A4: Check Survey | B4: KM | C4: 118.288 | D4: 106.341 | E4: 106.341
A5: Crossing Proposals
A6: Power line Crossings | B6: Nos | C6: 9 | D6: 8 | E6: 8
A7: NH Crossing | B7: Nos | C7: 3 | D7: 1 | E7: 1
A8: Railway crossing | B8: Nos | C8: 1 | D8: 1 | E8: NOC Received
A9: Aviation/Defence proposal | B9: Nos | C9: 1 | D9: 1 | E9: NOC Received
A10: Major river crossing | B10: Nos | C10: 1 | D10: 0 | E10: 0
A11: Forest | B11: Nos | C11: 0 | D11: 1 | H11: TRUE
A12: Other Crossings (Specify) | B12: Nos
A13: Original Route alignment | B13: KM | C13: 117.85085 | D13: 117.85085 | E13: 117.85085
A14: Detailed Survey | B14: KM | C14: 117.85085 | D14: 117.85085 | E14: 117.85085
A15: Diverted Route Alignment | B15: KM | C15: 0 | D15: 0 | E15: 0
A16: Check Survey | B16: KM | C16: =C13 -> 117.85085 | D16: =D13 -> 117.85085 | E16: =E13 -> 117.85085
A17: Crossing Proposals
A18: Power line Crossings | B18: Nos | C18: 6 | D18: 6 | E18: 6
A19: NH Crossing | B19: Nos | C19: 2 | D19: 2 | E19: 1 | G19: TRUE
A20: Railway crossing | B20: Nos | C20: 1 | D20: 1 | E20: 0 | G20: TRUE
A21: Aviation/Defence proposal | B21: Nos | C21: 1 | D21: 1 | E21: 1
A22: Major river crossing | B22: Nos | C22: 0 | D22: 0 | E22: 0
A23: Forest | B23: Nos | C23: 2 | D23: 2 | E23: 0 | G23: TRUE
A24: Other Crossings (Specify) | B24: Nos
A25: Original Route alignment | B25: KM | C25: 78.579 | D25: 78.579 | E25: 78.579
A26: Detailed Survey | B26: KM | C26: 78.579 | D26: 78.579 | E26: 78.579 | F26: TRUE
A27: Diverted Route Alignment | B27: KM | C27: 0 | D27: 0 | E27: 0
A28: Check Survey | B28: KM | C28: 66.683 | D28: 53.932 | E28: 53.932 | F28: TRUE
A29: Crossing Proposals
A30: Power line Crossings | B30: Nos | C30: 2 | D30: 1 | E30: 1 | F30: TRUE
A31: NH Crossing | B31: Nos | C31: 0 | D31: 0 | E31: 0
A32: Railway crossing | B32: Nos | C32: 0 | D32: 0 | E32: 0
A33: Aviation/Defence proposal | B33: Nos | C33: 0 | D33: 0 | E33: 0 | F33: TRUE
A34: Major river crossing | B34: Nos | C34: 0 | D34: 0 | E34: 0
A35: Forest | B35: Nos | C35: 1 | D35: 1 | E35: 0 | F35: TRUE
A36: Other Crossings (Specify) | B36: Nos
A37: Original Route alignment | B37: KM | C37: 136.706 | D37: 136.706 | E37: 136.706
A38: Detailed Survey | B38: KM | C38: 136.706 | D38: 136.706 | E38: 133.729 | F38: TRUE
A39: Diverted Route Alignment | B39: KM | C39: 0 | D39: 0 | E39: 0
A40: Check Survey | B40: KM | C40: 136.706 | D40: 133.729 | E40: 133.083 | F40: TRUE
...

Sheet SURVEY STATUS 
A1: TA-509 765 KV D/C Mandsaur - Kurawar (Part-1)Transmission Line(WZ-4)
A2: Sl No | B2: SL NO. | C2: AP NO | D2: Towe Type | E2: AP No | F2: Tower Type | G2: Type of Crossings | H2: Line Name | I2: LINE OWNER | J2: Status | K2: Proposal Submitted (Y/N) | L2: Inspection Status (Y/N) | M2: Remarks
A3: 1 | B3: 1 | C3: 11/0 | D3: DD60+25 | E3: 12/0 | F3: DD60+25 (1 MRC) | G3: POWERLINE-XING | H3: EXISTING 400 KV DC NEEMUCH-MANDSAUR TRANSMISSION LINE | I3: Power Grid | J3: APPROVAL-AWAITED | K3: SUBMITTED | L3: JOINT INSPECTION DONE BY 04.06.2025
A4: =A3+1 -> 2 | B4: 2 | C4: 25/0 | D4: DC2+1 | E4: 26/0 | F4: DC2+12 | G4: POWERLINE-XING | H4: 220 KV DC MANDSAUR - NIPANIA TL | I4: MPPTCL | J4: APPROVAL-AWAITED | K4: SUBMITTED | L4: JOINT INSPECTION DONE BY 04.06.2025
A5: =A4+1 -> 3 | B5: 3 | C5: 28/0 | D5: DD45+6 | E5: 29/0 | F5: DD45+18 | G5: POWERLINE-XING | H5: 220 KV DC SITAMAU-SUWASRA OHTL MPPTCL | I5: MPPTCL | J5: APPROVAL-AWAITED | K5: SUBMITTED | L5: JOINT INSPECTION DONE BY 04.06.2025
A6: =A5+1 -> 4 | B6: 4 | C6: 33/0 | D6: DD45+9 | E6: 34/0 | F6: DC1+3 | G6: POWERLINE-XING | H6: 132KV D/C SUWASARA - BADOD TL (Joint joint inspection Done) | I6: MPPTCL | J6: APPROVAL-AWAITED | K6: SUBMITTED | L6: JOINT INSPECTION DONE BY 04.06.2025
A7: =A6+1 -> 5 | B7: 5 | C7: 37/0 | D7: DD45+12 | E7: 38/0 | F7: DD45+9 | G7: POWERLINE-XING | H7: 220 KV OHTL DC BHANPUR-BAROD MPPTCL | I7: MPPTCL | J7: APPROVAL-AWAITED | K7: SUBMITTED | L7: JOINT INSPECTION DONE BY 04.06.2025
A8: =A11+1 -> 8 | B8: 6 | C8: 42/0 | D8: DC1+3 | E8: 43/0 | F8: DC1+6 | G8: POWERLINE-XING | H8: 132 KV SC BHAWANI MANDI - DAG T/L (RRVPNL) | I8: RVPNL | J8: APPROVAL-AWAITED | K8: SUBMITTED | L8: JOINT INSPECTION DONE BY 26.06.2025
B9: 7 | C9: 50/0 | D9: DC2+18 | E9: 51/0 | F9: DD60+9 | G9: POWERLINE-XING | H9: 220 KV S/C SUSNER - PACHORA T/L | I9: RTL | J9: APPROVAL-AWAITED | K9: SUBMITTED | L9: JOINT INSPECTION PENDING
A10: =A7+1 -> 6 | B10: 8 | C10: 54/0 | D10: DD45+9 | E10: 55/0 | F10: DC2+2 | G10: POWERLINE-XING | H10: 220kV D/C Badod-Nalkheda T/Line | I10: MPPTCL | J10: - | K10: NOT SUBMITTED YET | L10: PENDING DUE TO FINALIZATION OF SURVEY FOR AVOIDING FOREST IN B/T 52/0-58/0
A11: =A10+1 -> 7 | B11: 9 | C11: 62/0 | D11: DB1+12 | E11: 63/0 | F11: DC2+2 | G11: POWERLINE-XING | H11: 132 KV DC CKT-1 AGAR -SUSNER , CKT-2 AGAR - NALKHEDA OHTL | I11: MPPTCL | J11: APPROVAL-AWAITED | K11: SUBMITTED | L11: JOINT INSPECTION PENDING
A12: =A8+1 -> 9 | B12: 10 | C12: 17/0 | D12: DB2+3 | E12: 18/0 | F12: DD45+0 | G12: NH-XING | H12: NE-4 DELHI MUMBAI EXPRESSWAY | I12: NHAI | J12: APPROVAL-AWAITED | K12: SUBMITTED | L12: JOINT INSPECTION PENDING
A13: =A12+1 -> 10 | B13: 11 | C13: 35/0 | D13: DB2+3 | E13: 36/0 | F13: DC2+0 | G13: NH-XING | H13: NATIONAL HIGHWAY-752D | I13: NHAI | J13: APPROVAL-AWAITED | K13: SUBMITTED | L13: JOINT INSPECTION PENDING
A14: =A13+1 -> 11 | B14: 12 | C14: 60/0 | D14: DC2+0 | E14: 61/0 | F14: DB1+0 | G14: NH-XING | H14: NATIONAL HIGHWAY-552G | I14: NHAI | J14: APPROVAL-AWAITED | K14: SUBMITTED | L14: JOINT INSPECTION PENDING
A15: =A14+1 -> 12 | B15: 13 | C15: 31/0 | D15: DD60+0 | E15: 32/0 | F15: DD60+9 | G15: RAILWAY-XING | H15: Between Suwasra & Nathukheri Railway station BG | I15: INDIAN-RAILWAY KOTA DIVISION | J15: APPROVAL-AWAITED | K15: SUBMITTED | L15: JOINT INSPECTION DONE BY 27.06.2025 & REVISE INSPECTION PENDING

Sheet Erection productivity
A1: KEC International Limited - Gurgaon.
A2: Erection Productivity Gang wise - Nov'25
A3: Sr. No. | B3: Sub-Contractor Name | C3: Loc. No. | D3: Type of Tower | E3: Tower Weight (MT) | F3: Previous Month | G3: 01.11.25 (MT) | H3: 02.11.25 (MT) | I3: 03.11.25 (MT) | J3: 04.11.25 (MT) | K3: 05.11.25 (MT) | L3: 06.11.25 (MT) | M3: 07.11.25 (MT) | N3: 08.11.25 (MT) | O3: 09.11.25 (MT) | P3: 10.11.25 (MT) | Q3: 11.11.25 (MT) | R3: 12.11.25 (MT) | S3: 13.11.25 (MT) | T3: 14.11.25 (MT) | U3: 15.11.25 (MT) | V3: 16.11.25 (MT) | W3: 17.11.25 (MT) | X3: 18.11.25 (MT) | Y3: 19.11.25 (MT) | Z3: 20.11.25 (MT) | AA3: 21.11.25 (MT) | AB3: 22.11.25 (MT) | AC3: 23.11.25 (MT) | AD3: 24.11.25 (MT) | AE3: 25.11.25 (MT) | AF3: 26.11.25 (MT) | AG3: 27.11.25 (MT) | AH3: 28.11.25 (MT) | AI3: 29.11.25 (MT) | AJ3: 30.11.25 (MT) | AK3: Cumulative Till dated | AL3: Status | AM3: Manpower/Gang
AM4: Plan | AN4: Actual | AO4: Shotfall
A5: 1 | B5: Devi Construction | C5: 9/2 | D5: DA+0 | E5: =36159.756/1000 -> 36.159756 | F5: 27.12 | G5: 4.519 | H5: 4.519 | AK5: =SUM(G5:AJ5) -> 9.038 | AL5: Completed | AM5: 10 | AN5: 5 | AO5: 6
A6: 2 | B6: Devi Construction | C6: 8/4 | D6: DA+3 | E6: =37931.088/1000 -> 37.931088 | I6: 7 | J6: 8 | K6: 7 | L6: 7.5 | M6: 7.7 | AK6: =SUM(G6:AJ6) -> 37.2 | AL6: Completed
A7: 3 | B7: Devi Construction | C7: 10/2 | D7: DA(-)3 | E7: =34789.81/1000 -> 34.78981 | N7: 6.78 | O7: 11 | P7: 9 | Q7: 8 | AK7: =SUM(G7:AJ7) -> 34.78 | AL7: Completed
A8: 4 | B8: Devi Construction | C8: 12/3 | D8: DA(-)3 | E8: =34789.81/1000 -> 34.78981 | R8: 5.78 | S8: 7 | T8: 8 | U8: 7 | V8: 7 | AK8: =SUM(G8:AJ8) -> 34.78 | AL8: Completed
A9: 5 | B9: Devi Construction | C9: 13/0 | D9: DB2+0 | E9: =59500.628/1000 -> 59.500628 | W9: 8 | X9: 3 | Y9: 3 | Z9: 4 | AA9: 1.5 | AB9: 3 | AC9: 4 | AD9: 8 | AE9: 8 | AF9: 8 | AG9: 9 | AK9: =SUM(G9:AJ9) -> 59.5 | AL9: Completed
A10: 6 | B10: Aravali Infra-1 | C10: 15/4 | D10: DA+6 | E10: =43804.424/1000 -> 43.804424 | V10: 6 | W10: 8 | X10: 4 | Y10: 4 | Z10: 4 | AA10: 2 | AB10: 2 | AC10: 4 | AD10: 4 | AE10: 5.8 | AK10: =SUM(G10:AJ10) -> 43.8 | AL10: Completed
A11: 7 | B11: Aravali Infra-2 | C11: 16/2 | D11: DA+0 | E11: =36159.756/1000 -> 36.159756 | V11: 2 | W11: 5 | X11: 3.8 | Y11: 5 | Z11: 3 | AA11: 5 | AB11: 3 | AC11: 4 | AD11: 5.359 | AK11: =SUM(G11:AJ11) -> 36.159 | AL11: Completed
A12: 8 | B12: Aravali Infra-3 | C12: 24/1 | D12: DA+0 | E12: =36159.756/1000 -> 36.159756 | AG12: 3 | AH12: 5 | AI12: 3 | AJ12: 1 | AK12: =SUM(G12:AJ12) -> 12
A13: 9 | B13: Jawala singh | C13: 5/1 | D13: DA(-)3 | E13: =34789.81/1000 -> 34.78981 | Z13: 8 | AA13: 8 | AB13: 5 | AC13: 6 | AD13: 3 | AE13: 4.78 | AK13: =SUM(G13:AJ13) -> 34.78 | AL13: Completed
A14: 10 | B14: Arawali infra-2 | C14: 15/9 | D14: DA+3 | E14: =37931.088/1000 -> 37.931088 | AF14: 3 | AG14: 5 | AH14: 5 | AI14: 3 | AJ14: 5 | AK14: =SUM(G14:AJ14) -> 21
A15: 11 | B15: Arawali infra-1 | C15: 15/3 | D15: DA+0 | E15: =36159.756/1000 -> 36.159756 | AG15: 3 | AH15: 6 | AI15: 5 | AJ15: 4 | AK15: =SUM(G15:AJ15) -> 18
A16: 12 | B16: DEVI CONST. | C16: 8/1 | D16: DA+0 | E16: =36159.756/1000 -> 36.159756 | AH16: 4 | AI16: 3 | AJ16: 3 | AK16: =SUM(G16:AJ16) -> 10
A17: 13 | B17: Jawala singh | C17: 5/5 | D17: DA+0 | E17: =36159.756/1000 -> 36.159756 | AK17: =SUM(G17:AJ17) -> 0
A18: 14 | AK18: =SUM(G18:AJ18) -> 0
AK19: =SUM(G19:AJ19) -> 0
A20: Total | AK20: =SUM(G20:AJ20) -> 0
