Workbook
Name \0: #REF!
Name \0: #REF!
Name \2: #REF!
Name \2: #REF!
Name \3: #REF!
Name \4: #REF!
Name \A: #REF!
Name \A: #REF!
Name \A_1: "#REF!"
Name \a1: #REF!
Name \aa: #REF!
Name \B: #REF!
Name \B: #REF!
Name \C: #REF!
Name \C: #REF!
Name \c1: #REF!
Name \c1: #REF!
Name \d: #N/A
Name \dd: #REF!
Name \dd: #REF!
Name \DFC: #REF!
Name \E: #REF!
Name \f: #REF!
Name \f: #REF!
Name \g: #REF!
Name \g: #REF!
Name \H: #REF!
Name \H: #REF!
Name \I: #REF!
Name \I: #REF!
Name \j: #REF!
Name \j: #REF!
Name \jmns: #REF!
Name \k: #REF!
Name \k: #REF!
Name \KWS123: #N/A
Name \l: #REF!
Name \l: #REF!
Name \LK: #REF!
Name \LKM: #REF!
Name \M: #REF!
Name \M: #REF!
Name \N: #REF!
Name \N: #REF!
Name \P: #REF!
Name \P: #REF!
Name \q: #N/A
Name \R: #REF!
Name \R: #REF!
Name \S: #REF!
Name \S: #REF!
Name \Sv: #REF!
Name \t: #N/A
Name \U: #REF!
Name \U: #REF!
Name \V: #REF!
Name \V: #REF!
Name \x: #REF!
Name \z: #REF!
Name \z: #REF!

Sheet Summary
A1: Project -TA513-Powergrid Bikaner IV Transmission Limited | O1: 46202
A2: LOA DT Completion Schedule DT 21.12.2026 Project Value 666 Cr(S-530,F&I-12Cr.,C-124 Cr.) | B2: 45678 | E2: Project Period (Months):- | G2: 23 | I2: P.Completion | J2: 46378 | L2: No. of Days Delayed:- | M2: =J2-O1 -> 176 | Q2: F&I | R2: 12
A3: Progress Summary -Power Grid Bikaner IV Transmission limited
A4: Activity | B4: BOQ Qty | C4: Final Estimated Qty | D4: Cumulative L2 till Last Month | E4: Cumulative Progress till Last Month | F4: L2 for present Month | G4: Plan for the Month | H4: Today's Progress | I4: Progress till Date for the Month | J4: L2 till Current Month | K4: Completed till Date | L4: Balance Work | M4: Under Progress | N4: Gangs at Present | O4: Remarks
A5: Detailed Survey | B5: =B16+B27 -> 222.93 | C5: =C16+C27 -> 230.36 | D5: =D16+D27 -> 222.93 | E5: =E16+E27 -> 230.36 | F5: =F16+F27 -> 0 | G5: =G16+G27 -> 0 | H5: =H16+H27 -> 0 | I5: =I16+I27 -> 0 | ... N5: =N16+N27 -> 0
A6: Check Survey | B6: =B17+B28 -> 222.93 | C6: =C17+C28 -> 230.36 | D6: 222.93 | E6: 230.36 | F6: 0 | G6: 0 | H6: 0 | I6: 0 | J6: 222.93 | K6: 230.36 | L6: =L17+L28 -> 0 | M6: =M17+M28 -> 0 | N6: =N17+N28 -> 0 | O6: 13km check Survey Approval Awaited
A7: Foundation | B7: =B18+B29 -> 597 | C7: =C18+C29 -> 619 | D7: 547 | E7: 89 | F7: 28 | G7: 35 | H7: 0 | I7: 11 | J7: 575 | K7: 100 | L7: =L18+L29 -> 519 | M7: =M18+M29 -> 0 | N7: =N18+N29 -> 1
A8: Earthing | B8: =B19+B30 -> 597 | C8: =C19+C30 -> 619 | D8: 547 | E8: 17 | F8: 28 | G8: 0 | H8: 0 | I8: 0 | J8: 575 | K8: 17 | L8: =L19+L30 -> 601 | M8: =M19+M30 -> 0 | N8: =N19+N30 -> 0
A9: Tower Erection | B9: =B20+B31 -> 597 | C9: =C20+C31 -> 619 | D9: 465 | E9: 31 | F9: 35 | G9: 16 | H9: 0 | I9: 4 | J9: 500 | K9: 35 | L9: =L20+L31 -> 584 | M9: =M20+M31 -> 0 | N9: =N20+N31 -> 0
A10: Tack welding | B10: =B21+B32 -> 597 | C10: =C21+C32 -> 619 | D10: 465 | E10: 0 | F10: 35 | G10: 0 | H10: 0 | I10: 0 | J10: 500 | K10: 0 | L10: =L21+L32 -> 619 | M10: =M21+M32 -> 0 | N10: =N21+N32 -> 0
A11: Stringing | B11: =B22+B33 -> 222.93 | C11: =C22+C33 -> 230.56 | D11: 140 | E11: 0 | F11: 13 | G11: 0 | H11: 0 | I11: 0 | J11: 153 | K11: 0 | L11: =L22+L33 -> 230.56 | M11: =M22+M33 -> 0 | N11: =N22+N33 -> 0
A12: OPGW | B12: =B23+B34 -> 222.93 | C12: =C23+C34 -> 230.56 | D12: 50 | E12: 0 | F12: 35 | G12: 0 | H12: 0 | I12: 0 | J12: 85 | K12: 0 | L12: =L23+L34 -> 230.56 | M12: =M23+M34 -> 0 | N12: =N23+N34 -> 0
A13: Line Wise Progress
A14: 400 kV Siwani-Fatehabad Transmission Limited
A15: Activity | B15: BOQ Qty | C15: Final Estimated Qty | D15: Cumulative L2 till Last Month | E15: Cumulative Progress till Last Month | F15: L2 for present Month | G15: Plan for the Month | H15: Today's Progress | I15: Progress till Date for the Month | J15: L2 till Current Month | K15: Completed till Date | L15: Balance Work | M15: Under Progress | N15: Gangs at Present | O15: Remarks
A16: Detailed Survey | B16: 78.73 | C16: 82.8 | D16: 78.73 | E16: 82.8 | F16: 0 | G16: 0 | J16: 78.73 | K16: =E16+I16 -> 82.8 | L16: =+C16-K16 -> 0
A17: Check Survey | B17: =B16 -> 78.73 | C17: 82.8 | D17: 78.73 | E17: 82.8 | F17: 0 | G17: 0 | J17: 78.73 | K17: =E17+I17 -> 82.8 | L17: =+C17-K17 -> 0 | O17: Gantry to AP3-Approval Awaited , Submitted on date 24.12.2025
A18: Foundation | B18: 210 | C18: 220 | D18: 197 | E18: 25 | F18: 8 | G18: 10 | I18: 1 | J18: 205 | K18: =E18+I18 -> 26 | L18: =+C18-K18 -> 194 | M18: 0 | N18: 0
A19: Earthing | B19: =B18 -> 210 | C19: 220 | D19: 197 | E19: 10 | F19: 8 | G19: 0 | J19: 205 | K19: =E19+I19 -> 10 | L19: =+C19-K19 -> 210
A20: Tower Erection | B20: =B19 -> 210 | C20: 220 | D20: 155 | E20: 7 | F20: 20 | G20: 5 | J20: 175 | K20: =E20+I20 -> 7 | L20: =+C20-K20 -> 213 | M20: 0 | N20: 0
A21: Tack welding | B21: =B20 -> 210 | C21: 220 | D21: 155 | E21: 0 | F21: 20 | G21: 0 | J21: 175 | K21: =E21+I21 -> 0 | L21: =+C21-K21 -> 220
A22: Stringing | B22: =B16 -> 78.73 | C22: 83 | D22: 40 | E22: 0 | F22: 8 | G22: 0 | J22: 48 | K22: =E22+I22 -> 0 | L22: =+C22-K22 -> 83
A23: OPGW | B23: =B22 -> 78.73 | C23: =C22 -> 83 | D23: 15 | E23: 0 | F23: 15 | G23: 0 | J23: 30 | K23: =E23+I23 -> 0 | L23: =+C23-K23 -> 83
A25: 400 kV Siwani-Patran Transmission Limited
A26: Activity | B26: BOQ Qty | C26: Final Estimated Qty | D26: Cumulative L2 till Last Month | E26: Cumulative Progress till Last Month | F26: L2 for present Month | G26: Plan for the Month | H26: Today's Progress | I26: Progress till Date for the Month | J26: L2 till Current Month | K26: Completed till Date | L26: Balance Work | M26: Under Progress | N26: Gangs at Present | O26: Remarks
A27: Detailed Survey | B27: 144.2 | C27: 147.56 | D27: 144.2 | E27: 147.56 | F27: 0 | G27: 0 | J27: 0 | K27: =E27+I27 -> 147.56 | L27: =+C27-K27 -> 0
A28: Check Survey | B28: =B27 -> 144.2 | C28: 147.56 | D28: 144.2 | E28: 147.56 | F28: 0 | G28: 0 | J28: 144.2 | K28: =E28+I28 -> 147.56 | L28: =+C28-K28 -> 0 | O28: Gantry to AP3-Approval Awaited , Submitted on date 06.02.2026
A29: Foundation | B29: 387 | C29: 399 | D29: 350 | E29: 64 | F29: 20 | G29: 25 | I29: 10 | J29: 370 | K29: =E29+I29 -> 74 | L29: =+C29-K29 -> 325 | N29: 1 | O29: Loc-46/1-Excavation WIP
A30: Earthing | B30: =B29 -> 387 | C30: =C29 -> 399 | D30: 350 | E30: 8 | F30: 20 | G30: 0 | J30: 370 | K30: =E30+I30 -> 8 | L30: =+C30-K30 -> 391
A31: Tower Erection | B31: =B30 -> 387 | C31: =C30 -> 399 | D31: 310 | E31: 24 | F31: 15 | G31: 11 | I31: 4 | J31: 325 | K31: =E31+I31 -> 28 | L31: =+C31-K31 -> 371 | M31: 0 | N31: 0
A32: Tack welding | B32: =B31 -> 387 | C32: =C31 -> 399 | D32: =D31 -> 310 | E32: 0 | F32: =F31 -> 15 | G32: 0 | J32: =+D32+F32 -> 325 | K32: =E32+I32 -> 0 | L32: =+C32-K32 -> 399
A33: Stringing | B33: =B27 -> 144.2 | C33: =C27 -> 147.56 | D33: 100 | E33: 0 | F33: 5 | G33: 0 | J33: =+D33+F33 -> 105 | K33: =E33+I33 -> 0 | L33: =+C33-K33 -> 147.56
A34: OPGW | B34: =B33 -> 144.2 | C34: =C33 -> 147.56 | D34: 35 | E34: 0 | F34: 20 | G34: 0 | J34: =+D34+F34 -> 55 | K34: =E34+I34 -> 0 | L34: =+C34-K34 -> 147.56

Sheet SF Village Wise
A2: (Siwani-Fatehabad TL)Village Wise | I2: =SUBTOTAL(9,I4:I403) -> 8 | J2: =SUBTOTAL(9,J4:J403) -> 6 | K2: =SUBTOTAL(9,K4:K403) -> 4 | L2: =SUBTOTAL(3,L4:L1048576) -> 26 | M2: =SUBTOTAL(3,M4:M1048576) -> 10 | N2: =SUBTOTAL(3,N4:N1048576) -> 7
A3: S. No. | B3: Location | C3: Type of | D3: Wind Zone | E3: Span | F3: District | G3: Tehsil | H3: Village | I3: PL | J3: NH | K3: RL | L3: Foundation compl | M3: Earthing Complete | N3: Erection compl
A4: =SUBTOTAL(103,$B$4:B4) -> 1 | B4: 1/0 | C4: DD60+0 | D4: 4 | E4: 151.994 | F4: Bhiwani | G4: Siwani | H4: Jhuppa Kalan
A5: =SUBTOTAL(103,$B$4:B5) -> 2 | B5: 1/1 | C5: DA+6 | D5: 4 | E5: 410 | F5: Bhiwani | G5: Siwani | H5: Jhuppa Kalan
A6: =SUBTOTAL(103,$B$4:B6) -> 3 | B6: 1A/0 | C6: DD60+0 | D6: 4 | E6: 429.494 | F6: Bhiwani | G6: Siwani | H6: Jhuppa Kalan | J6: 1
A7: =SUBTOTAL(103,$B$4:B7) -> 4 | B7: 1B/0 | C7: DD60+6 | D7: 4 | E7: 228.257 | F7: Bhiwani | G7: Siwani | H7: Jhuppa Kalan | J7: 1 | K7: 1
A8: =SUBTOTAL(103,$B$4:B8) -> 5 | B8: 2/0 | C8: DD60+3 | D8: 4 | E8: 230.92 | F8: Bhiwani | G8: Siwani | H8: Jhuppa Kalan | K8: 1
A9: =SUBTOTAL(103,$B$4:B9) -> 6 | B9: 2A/0 | C9: DC1+0 | D9: 4 | E9: 373.098 | F9: Bhiwani | G9: Siwani | H9: Jhuppa Kalan
A10: =SUBTOTAL(103,$B$4:B10) -> 7 | B10: 2A/1 | C10: DA+0 | D10: 4 | E10: 343 | F10: Bhiwani | G10: Siwani | H10: Jhuppa Kalan
A11: =SUBTOTAL(103,$B$4:B11) -> 8 | B11: 2A/2 | C11: DA+0 | D11: 4 | E11: 414 | F11: Bhiwani | G11: Siwani | H11: Jhuppa Kalan
A12: =SUBTOTAL(103,$B$4:B12) -> 9 | B12: 2A/3 | C12: DA+0 | D12: 4 | E12: 397 | F12: Bhiwani | G12: Siwani | H12: Jhuppa Kalan
A13: =SUBTOTAL(103,$B$4:B13) -> 10 | B13: 2B/0 | C13: DB2+0 | D13: 4 | E13: 350.278 | F13: Bhiwani | G13: Siwani | H13: Jhuppa Kalan
A14: =SUBTOTAL(103,$B$4:B14) -> 11 | B14: 2B/1 | C14: DA+3 | D14: 4 | E14: 338 | F14: Bhiwani | G14: Siwani | H14: Jhuppa Kalan
A15: =SUBTOTAL(103,$B$4:B15) -> 12 | B15: 2C/0 | C15: DD60+6 | D15: 4 | E15: 343.261 | F15: Bhiwani | G15: Siwani | H15: Jhuppa Kalan | I15: 1
A16: =SUBTOTAL(103,$B$4:B16) -> 13 | B16: 2D/0 | C16: DD60+6 | D16: 4 | E16: 152.793 | F16: Bhiwani | G16: Siwani | H16: Jhuppa Kalan | I16: 1
A17: =SUBTOTAL(103,$B$4:B17) -> 14 | B17: 2D/1 | C17: DA+0 | D17: 4 | E17: 445 | F17: Bhiwani | G17: Siwani | H17: Jhuppa Kalan
A18: =SUBTOTAL(103,$B$4:B18) -> 15 | B18: 2D/2 | C18: DA+6 | D18: 4 | E18: 383 | F18: Bhiwani | G18: Siwani | H18: Lilas
A19: =SUBTOTAL(103,$B$4:B19) -> 16 | B19: 2D/3 | C19: DA+6 | D19: 4 | E19: 368.645 | F19: Bhiwani | G19: Siwani | H19: Lilas
A20: =SUBTOTAL(103,$B$4:B20) -> 17 | B20: 2D/4 | C20: DA+0 | D20: 4 | E20: 349.87 | F20: Bhiwani | G20: Siwani | H20: Lilas
A21: =SUBTOTAL(103,$B$4:B21) -> 18 | B21: 2D/5 | C21: DA+6 | D21: 4 | E21: 415 | F21: Bhiwani | G21: Siwani | H21: Lilas
A22: =SUBTOTAL(103,$B$4:B22) -> 19 | B22: 3/0 | C22: DB1+0 | D22: 4 | E22: 404.484 | F22: Bhiwani | G22: Siwani | H22: Lilas
A23: =SUBTOTAL(103,$B$4:B23) -> 20 | B23: 3/1 | C23: DA+0 | D23: 4 | E23: 325 | F23: Bhiwani | G23: Siwani | H23: Lilas
A24: =SUBTOTAL(103,$B$4:B24) -> 21 | B24: 3/2 | C24: DA+3 | D24: 4 | E24: 386 | F24: Bhiwani | G24: Siwani | H24: Lilas
A25: =SUBTOTAL(103,$B$4:B25) -> 22 | B25: 3/3 | C25: DA+0 | D25: 4 | E25: 434 | F25: Bhiwani | G25: Siwani | H25: Lilas
A26: =SUBTOTAL(103,$B$4:B26) -> 23 | B26: 3/4 | C26: DA+3 | D26: 4 | E26: 392 | F26: Bhiwani | G26: Siwani | H26: Siwani
A27: =SUBTOTAL(103,$B$4:B27) -> 24 | B27: 3/5 | C27: DA+3 | D27: 4 | E27: 404 | F27: Bhiwani | G27: Siwani | H27: Siwani
A28: =SUBTOTAL(103,$B$4:B28) -> 25 | B28: 3/6 | C28: DA+6 | D28: 4 | E28: 398 | F28: Bhiwani | G28: Siwani | H28: Siwani
... A111: =SUBTOTAL(103,$B$4:B111) -> 108 | B111: 17/7 | C111: DA+3 | D111: 4 | E111: 398 | F111: Hisar | G111: Hisar | H111: Mattarsham
A112: =SUBTOTAL(103,$B$4:B112) -> 109 | B112: 18/0 | C112: DB1+0 | D112: 4 | E112: 405.185 | F112: Hisar | G112: Hisar | H112: Mattarsham | L112: Compl
A113: =SUBTOTAL(103,$B$4:B113) -> 110 | B113: 18/1 | C113: DA+0 | D113: 4 | E113: 396 | F113: Hisar | G113: Hisar | H113: Mattarsham
A114: =SUBTOTAL(103,$B$4:B114) -> 111 | B114: 18/2 | C114: DA+0 | D114: 4 | E114: 386 | F114: Hisar | G114: Hisar | H114: Mattarsham
A115: =SUBTOTAL(103,$B$4:B115) -> 112 | B115: 18/3 | C115: DA-1.5 | D115: 4 | E115: 373 | F115: Hisar | G115: Hisar | H115: Mattarsham
A116: =SUBTOTAL(103,$B$4:B116) -> 113 | B116: 18/4 | C116: DA-1.5 | D116: 4 | E116: 363 | F116: Hisar | G116: Hisar | H116: Mattarsham | L116: Compl
A117: =SUBTOTAL(103,$B$4:B117) -> 114 | B117: 19/0 | C117: DC2+3 | D117: 4 | E117: 383.043 | F117: Hisar | G117: Hisar | H117: Mattarsham | L117: Compl
A118: =SUBTOTAL(103,$B$4:B118) -> 115 | B118: 19/1 | C118: DA+3 | D118: 4 | E118: 425 | F118: Hisar | G118: Hisar | H118: Mattarsham
A119: =SUBTOTAL(103,$B$4:B119) -> 116 | B119: 19/2 | C119: DA-3 | D119: 4 | E119: 388 | F119: Hisar | G119: Hisar | H119: Mattarsham
A120: =SUBTOTAL(103,$B$4:B120) -> 117 | B120: 20/0 | C120: DC2+0 | D120: 4 | E120: 351.545 | F120: Hisar | G120: Hisar | H120: Mattarsham
A121: =SUBTOTAL(103,$B$4:B121) -> 118 | B121: 21/0 | C121: DB2+0 | D121: 4 | E121: 373.161 | F121: Hisar | G121: Hisar | H121: Mattarsham
A122: =SUBTOTAL(103,$B$4:B122) -> 119 | B122: 21/1 | C122: DA+0 | D122: 4 | E122: 344.001 | F122: Hisar | G122: Hisar | H122: Mattarsham
A123: =SUBTOTAL(103,$B$4:B123) -> 120 | B123: 21/2 | C123: DA-3 | D123: 4 | E123: 317 | F123: Hisar | G123: Hisar | H123: Mattarsham
...

Sheet SP Village Wise
A2: Siwani-Patran Village Wise | I2: =SUBTOTAL(9,I4:I403) -> 41 | J2: =SUBTOTAL(9,J4:J403) -> 10 | K2: =SUBTOTAL(9,K4:K403) -> 8 | L2: =SUBTOTAL(3,L4:L1048576) -> 74 | M2: =SUBTOTAL(3,M4:M1048576) -> 8 | N2: =SUBTOTAL(3,N4:N1048576) -> 28
A3: S. No. | B3: Location | C3: Type of | D3: Wind Zone | E3: Span | F3: District | G3: Tehsil | H3: Village | I3: PL | J3: NH | K3: RL | L3: Foundation compl | M3: Earthing Complete | N3: Erection Compl
A4: =SUBTOTAL(103,$B$4:B4) -> 1 | B4: 1/0 | C4: DD60+0 | D4: 4 | E4: 100.36 | F4: Bhiwani | G4: Siwani | H4: Jhuppa Kalan
A5: =SUBTOTAL(103,$B$4:B5) -> 2 | B5: 1A/0 | C5: DD60+25 | D5: 4 | E5: 268.44 | F5: Bhiwani | G5: Siwani | H5: Jhuppa Kalan
A6: =SUBTOTAL(103,$B$4:B6) -> 3 | B6: 1B/0 | C6: DD60+25 | D6: 4 | E6: 161.36 | F6: Bhiwani | G6: Siwani | H6: Jhuppa Kalan
A7: =SUBTOTAL(103,$B$4:B7) -> 4 | B7: 1B/1 | C7: DA+9 | D7: 4 | E7: 400 | F7: Bhiwani | G7: Siwani | H7: Jhuppa Kalan
A8: =SUBTOTAL(103,$B$4:B8) -> 5 | B8: 1C/0 | C8: DC1+0 | D8: 4 | E8: 419.03 | F8: Bhiwani | G8: Siwani | H8: Jhuppa Kalan
A9: =SUBTOTAL(103,$B$4:B9) -> 6 | B9: 1C/1 | C9: DA+0 | D9: 4 | E9: 418 | F9: Bhiwani | G9: Siwani | H9: Jhuppa Kalan
A10: =SUBTOTAL(103,$B$4:B10) -> 7 | B10: 1C/2 | C10: DA+0 | D10: 4 | E10: 386.78 | F10: Bhiwani | G10: Siwani | H10: Jhuppa Kalan
A11: =SUBTOTAL(103,$B$4:B11) -> 8 | B11: 1C/3 | C11: DA+0 | D11: 4 | E11: 319.22 | F11: Bhiwani | G11: Siwani | H11: Jhuppa Kalan
A12: =SUBTOTAL(103,$B$4:B12) -> 9 | B12: 1D/0 | C12: DC2+6 | D12: 4 | E12: 390.8 | F12: Bhiwani | G12: Siwani | H12: Jhuppa Kalan
A13: =SUBTOTAL(103,$B$4:B13) -> 10 | B13: 1D/1 | C13: DA+3 | D13: 4 | E13: 438 | F13: Bhiwani | G13: Siwani | H13: Jhuppa Kalan
A14: =SUBTOTAL(103,$B$4:B14) -> 11 | B14: 1D/2 | C14: DA+9 | D14: 4 | E14: 406 | F14: Bhiwani | G14: Siwani | H14: Jhuppa Kalan
A15: =SUBTOTAL(103,$B$4:B15) -> 12 | B15: 2/0 | C15: DD60+3 | D15: 4 | E15: 436.42 | F15: Bhiwani | G15: Siwani | H15: Jhuppa Kalan | J15: 1
A16: =SUBTOTAL(103,$B$4:B16) -> 13 | B16: 2A/0 | C16: DD60+6 | D16: 4 | E16: 193.59 | F16: Bhiwani | G16: Siwani | H16: Jhuppa Kalan | J16: 1 | K16: 1
A17: =SUBTOTAL(103,$B$4:B17) -> 14 | B17: 2B/0 | C17: DD60+9 | D17: 4 | E17: 205.24 | F17: Bhiwani | G17: Siwani | H17: Jhuppa Kalan | K17: 1
A18: =SUBTOTAL(103,$B$4:B18) -> 15 | B18: 2B/1 | C18: DA+0 | D18: 4 | E18: 356 | F18: Bhiwani | G18: Siwani | H18: Jhuppa Kalan
A19: =SUBTOTAL(103,$B$4:B19) -> 16 | B19: 2B/2 | C19: DA+0 | D19: 4 | E19: 300 | F19: Bhiwani | G19: Siwani | H19: Lilas
A20: =SUBTOTAL(103,$B$4:B20) -> 17 | B20: 2B/3 | C20: DA+0 | D20: 4 | E20: 318 | F20: Bhiwani | G20: Siwani | H20: Lilas
A21: =SUBTOTAL(103,$B$4:B21) -> 18 | B21: 2B/3 | C21: DA+0 | D21: 4 | E21: 375 | F21: Bhiwani | G21: Siwani | H21: Lilas
A22: =SUBTOTAL(103,$B$4:B22) -> 19 | B22: 2C/0 | C22: DD45+9 | D22: 4 | E22: 371.02 | F22: Bhiwani | G22: Siwani | H22: Lilas | I22: 1
A23: =SUBTOTAL(103,$B$4:B23) -> 20 | B23: 2D/0 | C23: DD60+9 | D23: 4 | E23: 204.05 | F23: Bhiwani | G23: Siwani | H23: Lilas | I23: 1
A24: =SUBTOTAL(103,$B$4:B24) -> 21 | B24: 3/0 | C24: DA+0 | D24: 4 | E24: 377.97 | F24: Bhiwani | G24: Siwani | H24: Gaindwas
A25: =SUBTOTAL(103,$B$4:B25) -> 22 | B25: 3/1 | C25: DA+1.5 | D25: 4 | E25: 420.897 | F25: Bhiwani | G25: Siwani | H25: Gaindwas
A26: =SUBTOTAL(103,$B$4:B26) -> 23 | B26: 3/2 | C26: DA+3 | D26: 4 | E26: 393 | F26: Bhiwani | G26: Siwani | H26: Gaindwas
A27: =SUBTOTAL(103,$B$4:B27) -> 24 | B27: 3/3 | C27: DA-3 | D27: 4 | E27: 393 | F27: Bhiwani | G27: Siwani | H27: Gaindwas
A28: =SUBTOTAL(103,$B$4:B28) -> 25 | B28: 3/4 | C28: DA+0 | D28: 4 | E28: 383 | F28: Bhiwani | G28: Siwani | H28: Gaindwas
A29: =SUBTOTAL(103,$B$4:B29) -> 26 | B29: 3/5 | C29: DA+3 | D29: 4 | E29: 391 | F29: Bhiwani | G29: Siwani | H29: Gaindwas | L29: Compl
A30: =SUBTOTAL(103,$B$4:B30) -> 27 | B30: 3/6 | C30: DA+0 | D30: 4 | E30: 429 | F30: Bhiwani | G30: Siwani | H30: Gaindwas | L30: Compl
A31: =SUBTOTAL(103,$B$4:B31) -> 28 | B31: 3/7 | C31: DA+0 | D31: 4 | E31: 389 | F31: Bhiwani | G31: Siwani | H31: Gaindwas
A32: =SUBTOTAL(103,$B$4:B32) -> 29 | B32: 3/8 | C32: DA-3 | D32: 4 | E32: 413 | F32: Bhiwani | G32: Siwani | H32: Gaindwas
A33: =SUBTOTAL(103,$B$4:B33) -> 30 | B33: 3/9 | C33: DA+0 | D33: 4 | E33: 365 | F33: Bhiwani | G33: Siwani | H33: Siwani
A34: =SUBTOTAL(103,$B$4:B34) -> 31 | B34: 3/10 | C34: DA+3 | D34: 4 | E34: 438 | F34: Bhiwani | G34: Siwani | H34: Siwani | L34: Compl
A35: =SUBTOTAL(103,$B$4:B35) -> 32 | B35: 4/0 | C35: DB2+0 | D35: 4 | E35: 393.115 | F35: Bhiwani | G35: Siwani | H35: Siwani
A36: =SUBTOTAL(103,$B$4:B36) -> 33 | B36: 4/1 | C36: DA-3 | D36: 4 | E36: 356 | F36: Bhiwani | G36: Siwani | H36: Siwani
A37: =SUBTOTAL(103,$B$4:B37) -> 34 | B37: 4/2 | C37: DA+0 | D37: 4 | E37: 359 | F37: Bhiwani | G37: Siwani | H37: Siwani
A38: =SUBTOTAL(103,$B$4:B38) -> 35 | B38: 4/3 | C38: DA+3 | D38: 4 | E38: 410 | F38: Bhiwani | G38: Siwani | H38: Siwani
A39: =SUBTOTAL(103,$B$4:B39) -> 36 | B39: 4/4 | C39: DA+3 | D39: 4 | E39: 361 | F39: Bhiwani | G39: Siwani | H39: Siwani
A40: =SUBTOTAL(103,$B$4:B40) -> 37 | B40: 5/0 | C40: DB1+0 | D40: 4 | E40: 418.331 | F40: Bhiwani | G40: Siwani | H40: Siwani
A41: =SUBTOTAL(103,$B$4:B41) -> 38 | B41: 5/1 | C41: DA+6 | D41: 4 | E41: 424 | F41: Bhiwani | G41: Siwani | H41: Siwani
...

Sheet Earthing S-P
A1: KEC International Limited
A2: 400 KV D/C (Quad) Siwani-Patran TL
A3: Details of Earthing
I4: TFR
A5: CUMM. SR.NO | B5: MONTH SR.NO. | C5: Loc. No. | D5: Type of Tower | E5: Type of Classification | F5: Start | G5: Complete | H5: Type of Earthing | I5: Before Earthing Value | J5: After Earthing Value | K5: Remarks
A6: 1 | B6: 1 | C6: 29/1 | D6: =VLOOKUP(C6,'FDN S-P'!$C$5:$E$83,2,0) -> DA+0 | E6: =VLOOKUP(C6,'FDN S-P'!$C$5:$E$83,3,0) -> Sandy | F6: 45880 | G6: 45880 | H6: Pipe type | I6: 1.33 | J6: 0.99
A7: 2 | B7: 2 | C7: 28/2 | D7: =VLOOKUP(C7,'FDN S-P'!$C$5:$E$83,2,0) -> DA+3 | E7: =VLOOKUP(C7,'FDN S-P'!$C$5:$E$83,3,0) -> Sandy | F7: 45880 | G7: 45880 | H7: Pipe type | I7: 1.31 | J7: 0.78
A8: 3 | B8: 3 | C8: 28/3 | D8: =VLOOKUP(C8,'FDN S-P'!$C$5:$E$83,2,0) -> DA+6 | E8: =VLOOKUP(C8,'FDN S-P'!$C$5:$E$83,3,0) -> Sandy | F8: 45880 | G8: 45880 | H8: Pipe type | I8: 4.07 | J8: 3.44
A9: 4 | B9: 4 | C9: 28/4 | D9: =VLOOKUP(C9,'FDN S-P'!$C$5:$E$83,2,0) -> DA+3 | E9: =VLOOKUP(C9,'FDN S-P'!$C$5:$E$83,3,0) -> WET | F9: 45880 | G9: 45880 | H9: Pipe type | I9: 3.35 | J9: 1.79
A10: 5 | B10: 5 | C10: 29/4 | D10: =VLOOKUP(C10,'FDN S-P'!$C$5:$E$83,2,0) -> DA+6 | E10: =VLOOKUP(C10,'FDN S-P'!$C$5:$E$83,3,0) -> Sandy | F10: 45883 | G10: 45883 | H10: Pipe type | I10: 1.38 | J10: 0.9
A11: 6 | B11: 6 | C11: 29/5 | D11: =VLOOKUP(C11,'FDN S-P'!$C$5:$E$83,2,0) -> DA+0 | E11: =VLOOKUP(C11,'FDN S-P'!$C$5:$E$83,3,0) -> WET | F11: 45883 | G11: 45883 | H11: Pipe type | I11: 1.4 | J11: 1.09
A12: 7 | B12: 7 | C12: 30/1 | D12: =VLOOKUP(C12,'FDN S-P'!$C$5:$E$83,2,0) -> DA+3 | E12: =VLOOKUP(C12,'FDN S-P'!$C$5:$E$83,3,0) -> WET | F12: 45883 | G12: 45883 | H12: Pipe type | I12: 1.01 | J12: 0.89
A13: 8 | B13: 8 | C13: 29/3 | D13: =VLOOKUP(C13,'FDN S-P'!$C$5:$E$83,2,0) -> DA+3 | E13: =VLOOKUP(C13,'FDN S-P'!$C$5:$E$83,3,0) -> WET | F13: 45883 | G13: 45883 | H13: Pipe type | I13: 1.3 | J13: 1.27

Sheet T.Marking
A1: Client-Powergrid Bikaner IV Tranmission Limited | G1: Line | H1: Line Length | I1: Compl | J1: ROW
A2: Project-Siwani-Patran TL & Siwani-Fatehabad TL | G2: SP | H2: =D20 -> 147.586 | I2: =SUMIFS($D$8:$D$19,$E$8:$E$19,E9) -> 103.806 | J2: =H2-I2 -> 43.78
A3: Tree Marking Details | G3: SF | H3: =J20 -> 82.798 | I3: =SUMIFS($J$8:$J$13,K8:K13,K9) -> 61.252 | J3: =H3-I3 -> 21.546
A5: 400 Kv Siwani-Patran TL | G5: 400 Kv Siwani-fatehabad TL
A6: S.NO | B6: Section | D6: Section Length (KM) | E6: Status | G6: S.NO | H6: Section | J6: Section Length (KM) | K6: Status
B7: From | C7: To | H7: From | I7: To
A8: 1 | B8: S.Gantry | C8: AP-5 | D8: 13.157 | E8: The farmer has refused to allow the commencement of work due to ROW | G8: 1 | H8: S.Gantry | I8: AP-3 | J8: 6.528 | K8: The farmer has refused to allow the commencement of work due to ROW
A9: 2 | B9: AP-5 | C9: AP-7 | D9: 2.616 | E9: Completed | G9: 2 | H9: AP-3 | I9: 5/1 | J9: 7.398 | K9: Completed
A10: 3 | B10: AP-7 | C10: 19/3 | D10: 19.915 | E10: The farmer has refused to allow the commencement of work due to ROW | G10: 3 | H10: 5/1 | I10: 9/0 | J10: 13.009 | K10: The farmer has refused to allow the commencement of work due to ROW
A11: 4 | B11: 19/3 | C11: 26/0 | D11: 9.563 | E11: Completed | G11: 4 | H11: 9/1 | I11: 14/0 | J11: 6.018 | K11: Completed
A12: 5 | B12: AP26 | C12: AP29 | D12: 3.335 | E12: The farmer has refused to allow the commencement of work due to ROW | G12: 5 | H12: 14/0 | I12: 15/3 | J12: 2.009 | K12: The farmer has refused to allow the commencement of work due to ROW
A13: 6 | B13: AP29 | C13: 36/1 | D13: 10.027 | E13: Completed | G13: 6 | H13: =I12 -> 15/3 | I13: F.Gantry | J13: 47.836 | K13: Completed
A14: 7 | B14: 36/1 | C14: 36/3 | D14: 0.805 | E14: The farmer has refused to allow the commencement of work due to ROW
A15: 8 | B15: 36/3 | C15: AP43 | D15: 4.742 | E15: Completed
A16: 9 | B16: AP43 | C16: AP50 | D16: 7.294 | E16: Completed
A17: 10 | B17: AP50 | C17: 106/1 | D17: 65.96 | E17: Completed
A18: 11 | B18: 106/1 | C18: 115/0 | D18: 6.568 | E18: The farmer has refused to allow the commencement of work due to ROW
A19: 12 | B19: AP115 | C19: AP120 | D19: 3.604 | E19: Completed
A20: Total | D20: =SUBTOTAL(9,D8:D19) -> 147.586 | G20: Total | J20: =SUBTOTAL(9,J8:J19) -> 82.798

Sheet ERT
A1: Client-Powergrid Bikaner IV Tranmission Limited
A2: Project-Siwani-Patran TL & Siwani-Fatehabad TL
A3: Soil Resistivity Details
A5: Soil Resitivity-Siwani-Fatehabad TL | H5: Soil Resitivity-Siwani-Patran TL
A6: S.No | B6: Approx. Distance (3Kms) | C6: Chainage in Kms | D6: Instrument Reading (R) (Ohm) | E6: S.R. Value (P=2πARX1) (ohm-m) | F6: Remarks | H6: S.No | I6: Approx. Distance (3Kms) | J6: Chainage in Kms | K6: Instrument Reading (R) (Ohm) | L6: S.R. Value (P=2πARX1) (ohm-m) | M6: Remarks
A7: 1 | B7: AP1A/0 | C7: 0.2 | D7: 0.075 | E7: =D7*2*50*(22/7)*1 -> 23.571429 | F7: Completed | H7: 1 | I7: GANTY SS SIWANI | J7: 0
A8: 2 | B8: AP1B/0 | C8: 1.219 | D8: 0.185 | E8: =D8*2*50*(22/7)*1 -> 58.142857 | F8: Completed | H8: 2 | I8: 1C/0 | J8: 1.349 | K8: 0.0655 | L8: 20.585714 | M8: Completed
A9: 3 | B9: 2C/0 | C9: 4.009 | D9: 0.14 | E9: =D9*2*50*(22/7)*1 -> 44 | F9: Completed | H9: 3 | I9: 2A/0 | J9: 4.337 | K9: 0.01 | L9: 3.1428571 | M9: Completed
A10: 4 | B10: 3/0 | C10: 6.527 | D10: 0.13 | E10: =D10*2*50*(22/7)*1 -> 40.857143 | F10: Completed | H10: 4 | I10: 2D/0 | J10: 6.47 | K10: 0.11 | L10: 34.571429 | M10: Completed
A11: 5 | B11: 3/7 | C11: 9.307 | D11: 0.135 | E11: =D11*2*50*(22/7)*1 -> 42.428571 | F11: Completed | H11: 5 | I11: 3/6 | J11: 9.248 | K11: 0.1 | L11: 31.428571 | M11: Completed
A12: 6 | B12: 4/3 | C12: 12.112 | D12: 0.0515 | E12: =D12*2*50*(22/7)*1 -> 16.185714 | F12: Completed | H12: 6 | I12: 4/2 | J12: 11.961 | K12: 0.0115 | L12: 3.6142857 | M12: Completed
A13: 7 | B13: 5/3 | C13: 14.727 | D13: 0.0535 | E13: =D13*2*50*(22/7)*1 -> 16.814286 | F13: Completed | H13: 7 | I13: 5/4 | J13: 14.556 | K13: 0.0275 | L13: 8.6428571 | M13: Completed
A14: 8 | B14: 6/2 | C14: 17.447 | D14: 0.08 | E14: =D14*2*50*(22/7)*1 -> 25.142857 | F14: Completed | H14: 8 | I14: 8/2 | J14: 17.254 | K14: 0.0295 | L14: 9.2714286 | M14: Completed
A15: 9 | B15: 6/9 | C15: 20.296 | D15: 0.27 | E15: =D15*2*50*(22/7)*1 -> 84.857143 | F15: Completed | H15: 9 | I15: 10/0 | J15: 20.09 | K15: 0.0195 | L15: 6.1285714 | M15: Completed
A16: 10 | B16: 8/0 | C16: 22.988 | D16: 0.18 | E16: =D16*2*50*(22/7)*1 -> 56.571429 | F16: Completed | H16: 10 | I16: 11/4 | J16: 22.888 | K16: 0.016 | L16: 5.0285714 | M16: Completed
A17: 11 | B17: 8/7 | C17: 25.684 | D17: 0.015 | E17: =D17*2*50*(22/7)*1 -> 4.7142857 | F17: Completed | H17: 11 | I17: 12/6 | J17: 25.8 | K17: 0.0125 | L17: 3.9285714 | M17: Completed
A18: 12 | B18: 10/0 | C18: 28.106 | D18: 0.0315 | E18: =D18*2*50*(22/7)*1 -> 9.9 | F18: Completed | H18: 12 | I18: 14/5 | J18: 28.484 | K18: 0.025 | L18: 7.8571429 | M18: Completed
A19: 13 | B19: 12/0 | C19: 30.53 | D19: 0.018 | E19: =D19*2*50*(22/7)*1 -> 5.6571429 | F19: Completed | H19: 13 | I19: 15B/0 | J19: 30.069 | K19: 0.008 | L19: 2.5142857 | M19: Completed
... A43: 37 | B43: 63/0 | C43: 82.957 | D43: 0.2275 | E43: =D43*2*50*(22/7)*1 -> 71.5 | F43: Completed | H43: 37 | I43: 56/0 | J43: 84.533 | K43: 0.036 | L43: 11.314286 | M43: Completed
H44: 38 | I44: 57/0 | J44: 86.532 | K44: 0.05 | L44: 15.714286 | M44: Completed
H45: 39 | I45: 59/0 | J45: 88.534 | K45: 0.083 | L45: 26.085714 | M45: Completed
H46: 40 | I46: 63/0 | J46: 90.965 | K46: 0.053 | L46: 16.657143 | M46: Completed
H47: 41 | I47: 65/0 | J47: 93.888 | K47: 0.074 | L47: 23.257143 | M47: Completed
H48: 42 | I48: 68/0 | J48: 96.586 | K48: 0.132 | L48: 41.485714 | M48: Completed
H49: 43 | I49: 70/0 | J49: 99.611 | K49: 0.074 | L49: 23.257143 | M49: Completed
E50: =37*2 -> 74 | H50: 44 | I50: 73/0 | J50: 100.894 | K50: 0.078 | L50: 24.514286 | M50: Completed
H51: 45 | I51: 74/7 | J51: 104.041 | K51: 0.1925 | L51: 60.5 | M51: Completed
H52: 46 | I52: 76/0 | J52: 105.301 | K52: 0.255 | L52: 80.142857 | M52: Completed
H53: 47 | I53: 78/0 | J53: 107.679 | K53: 0.237 | L53: 74.485714 | M53: Completed
H54: 48 | I54: 80/0 | J54: 110.449 | K54: 0.4255 | L54: 133.72857 | M54: Completed
H55: 49 | I55: 84/0 | J55: 111.682 | K55: 0.677 | L55: 212.77143 | M55: Completed
H56: 50 | I56: 87/0 | J56: 113.838 | K56: 0.2315 | L56: 72.757143 | M56: Completed
H57: 51 | I57: 91/0 | J57: 115.068 | K57: 0.483 | L57: 151.8 | M57: Completed
H58: 52 | I58: 92/6 | J58: 117.682 | K58: 0.405 | L58: 127.28571 | M58: Completed
H59: 53 | I59: 94/0 | J59: 120.421 | K59: 0.64 | L59: 201.14286 | M59: Completed
H60: 54 | I60: 94/7 | J60: 123.231 | K60: 0.271 | L60: 85.171429 | M60: Completed
H61: 55 | I61: 96/0 | J61: 125.138 | K61: 0.217 | L61: 68.2 | M61: Completed
H62: 56 | I62: 98/4 | J62: 127.582 | K62: 0.038 | L62: 11.942857 | M62: Completed
... H70: 64 | I70: 120/0 | J70: 147.428 | K70: 0.641 | L70: 201.45714 | M70: Completed

Sheet VC SF 
B1: Visual Chart | AK1: =Summary!O1 -> 46202
B3: Progress | H3: WXMIDNC | AC3: LEGEND
B4: Foundation | E4: Nos. | F4: =CONCATENATE(AK122," ","/"," ",H4) -> 26 / 220 | H4: 220 | M4: TL03: Siwani– Fatehabad (PG) 400 kV TL | AC4: Crossings | AH4: Status
B5: Earthing | E5: Nos. | F5: =CONCATENATE(AN122," ","/"," ",H5) -> 10 / 220 | H5: 220 | M5: Client: Powergrid Bikaner IV Transmission limited | AC5: #VALUE! | AD5: Powerline Crossing | AI5: In Progress
B6: Erection | E6: Nos. | F6: =CONCATENATE(AL122," ","/"," ",H6) -> 7 / 220 | H6: 220 | M6: Executing Agency:M/s KEC International Limited | AC6: #VALUE! | AD6: Rail Crossing | AI6: Completed
B7: Tack Welding | E7: Nos. | F7: 0/220 | H7: 220 | AC7: #VALUE! | AD7: Road Crossing | AI7: Right of Way
B8: Stringing Paying Out | E8: Km. | F8: =CONCATENATE(AM122," ","/"," ",H8) -> 0 / 82.801 | H8: 82.801 | AD8: Gas Pipe line | AI8: Earthing Compl
B9: Stringing Final sag | E9: Km. | F9: =CONCATENATE(AM122," ","/"," ",H9) -> 0 / 82.801 | H9: 82.801
AI11: Row Length | AJ11: Cum Length | AK11: Fdns Comp | AL11: TE Comp | AM11: STG Comp | AN11: Earthing
B14: Siwani-Gantry | D14: 151.994 | F14: 410 | H14: 429.494 | J14: 228.257 | L14: 230.92 | N14: 373.098 | P14: 343 | R14: 414 | T14: 397 | V14: 350.278 | X14: 338 | Z14: 343.261 | AB14: 152.793 | AD14: 445 | AF14: 383 | AI14: =SUM(B14:AH14) -> 4990.095 | AJ14: =+AI14 -> 4990.095 | AK14: =COUNTA(B15:AG15) -> 0 | AL14: =COUNTA(B13:AG13) -> 0
E16: 1/0 | G16: 1/1 | I16: 1A/0 | J16: NH | K16: 1B/0 | L16: Rly Xing | M16: 2/0 | O16: 2A/0 | Q16: 2A/1 | S16: 2A/2 | U16: 2A/3 | W16: 2B/0 | Y16: 2B/1 | AA16: 2C/0 | AB16: 132KV | AC16: 2D/0 | AE16: 2D/1 | AG16: 2D/2
E17: DD60+0 | G17: DA+6 | I17: DD60+0 | K17: DD60+6 | M17: DD60+3 | O17: DC1+0 | Q17: DA+0 | S17: DA+0 | U17: DA+0 | W17: DB2+0 | Y17: DA+3 | AA17: DD60+6 | AB17: S/C | AC17: DD60+6 | AE17: DA+0 | AG17: DA+6
B22: 368.645 | D22: 349.87 | F22: 415 | H22: 404.484 | J22: 325 | L22: 386 | N22: 434 | P22: 392 | R22: 404 | T22: 398 | V22: 441 | X22: 385 | Z22: 434 | AB22: 402 | AD22: 391.079 | AF22: 392 | AI22: =SUM(B22:AH22) -> 6322.078 | AJ22: =+AI22+AJ14 -> 11312.173 | AK22: =COUNTA(B23:AG23) -> 0 | AL22: =COUNTA(B21:AG21) -> 0
C24: 2D/3 | E24: 2D/4 | G24: 2D/5 | I24: 3/0 | K24: 3/1 | M24: 3/2 | O24: 3/3 | Q24: 3/4 | S24: 3/5 | U24: 3/6 | W24: 3/7 | Y24: 3/8 | AA24: 3/9 | AC24: 3/10 | AE24: 4/0 | AG24: 4/1
C25: DA+6 | E25: DA+0 | G25: DA+6 | I25: DB1+0 | K25: DA+0 | M25: DA+3 | O25: DA+0 | Q25: DA+3 | S25: DA+3 | U25: DA+6 | W25: DA+9 | Y25: DA+3 | AA25: DA+0 | AC25: DA+6 | AE25: DB2+3 | AG25: DA+3
B30: 400 | D30: 401 | F30: 386 | H30: 322 | J30: 301 | L30: 374.546 | N30: 430 | P30: 401 | R30: 401 | T30: 439 | V30: 362 | X30: 397 | Z30: 337 | AB30: 344.26 | AD30: 409 | AF30: 432 | AI30: =SUM(B30:AH30) -> 6136.806 | AJ30: =+AI30+AJ22 -> 17448.979 | AK30: =COUNTA(B31:AG31) -> 0 | AL30: =COUNTA(B29:AG29) -> 0
C32: 4/2 | E32: 4/3 | G32: 4/4 | I32: 4/5 | K32: 4/6 | M32: 5/0 | O32: 5/1 | Q32: 5/2 | S32: 5/3 | U32: 5/4 | W32: 5/5 | Y32: 5/6 | AA32: 5/7 | AC32: 6/0 | AE32: 6/1 | AG32: 6/2
C33: DA+6 | E33: DA+3 | G33: DA+0 | I33: DA+0 | K33: DA+0 | M33: DC2+0 | O33: DA+9 | Q33: DA+0 | S33: DA+3 | U33: DA+6 | W33: DA+9 | Y33: DA-3 | AA33: DA-3 | AC33: DB1+0 | AE33: DA+6 | AG33: DA+0
B38: 393 | D38: 451 | F38: 387 | H38: 382 | J38: 414 | L38: 385 | N38: 437 | P38: 376 | R38: 316.217 | T38: 384 | V38: 387 | X38: 389 | Z38: 424 | AB38: 416.069 | AD38: 364 | AF38: 337 | AI38: =SUM(B38:AH38) -> 6242.286 | AJ38: =+AI38+AJ30 -> 23691.265 | AK38: =COUNTA(B39:AG39) -> 0 | AL38: =COUNTA(B37:AG37) -> 0
C40: 6/3 | E40: 6/4 | G40: 6/5 | I40: 6/6 | K40: 6/7 | M40: 6/8 | O40: 6/9 | Q40: 6/10 | S40: 7/0 | U40: 7/1 | W40: 7/2 | Y40: 7/3 | AA40: 7/4 | AC40: 8/0 | AE40: 8/1 | AG40: 8/2
C41: DA+6 | E41: DA+0 | G41: DA+9 | I41: DA+0 | K41: DA+0 | M41: DA+9 | O41: DA+3 | Q41: DA+0 | S41: DB1+0 | U41: DA+3 | W41: DA+0 | Y41: DA+6 | AA41: DA+6 | AC41: DB2+0 | AE41: DA+0 | AG41: DA+0
B46: 434 | D46: 401 | F46: 372 | H46: 368 | J46: 420 | L46: 411 | N46: 423 | P46: 416.365 | R46: 402 | T46: 388 | V46: 382.444 | X46: 405 | Z46: 416 | AB46: 407 | AD46: 385.937 | AF46: 398 | AI46: =SUM(B46:AH46) -> 6429.746 | AJ46: =+AI46+AJ38 -> 30121.011 | AK46: =COUNTA(B47:AG47) -> 0 | AL46: =COUNTA(B45:AG45) -> 0
C48: 8/3 | E48: 8/4 | G48: 8/5 | I48: 8/6 | K48: 8/7 | M48: 8/8 | O48: 8/9 | Q48: 9/0 | S48: 9/1 | U48: 9/2 | W48: 10/0 | Y48: 10/1 | AA48: 10/2 | AC48: 10/3 | AE48: 11/0 | AG48: 11/1
C49: DA+6 | E49: DA+3 | G49: DA-3 | I49: DA+0 | K49: DA+6 | M49: DA+0 | O49: DA+3 | Q49: DC2+0 | S49: DA+3 | U49: DA+0 | W49: DD45+0 | Y49: DA+3 | AA49: DA+0 | AC49: DA+3 | AE49: DC2+0 | AG49: DA+3
B54: 412.384 | D54: 411 | F54: 432 | H54: 369 | J54: 425 | L54: 384.259 | N54: 400.558 | P54: 413 | R54: 388.988 | T54: 433 | V54: 408 | X54: 367 | Z54: 391.859 | AB54: 406 | AD54: 402 | AF54: 409 | AI54: =SUM(B54:AH54) -> 6453.048 | AJ54: =+AI54+AJ46 -> 36574.059 | AK54: =COUNTA(B55:AG55) -> 0 | AL54: =COUNTA(B53:AG53) -> 0
C56: 12/0 | E56: 12/1 | G56: 12/2 | I56: 12/3 | K56: 12/4 | M56: 13/0 | O56: 14/0 | Q56: 14/1 | S56: 15/0 | U56: 15/1 | W56: 15/2 | Y56: 15/3 | AA56: 16/0 | AC56: 16/1 | AE56: 16/2 | AG56: 16/3
C57: DC2+3 | E57: DA+9 | G57: DA+0 | I57: DA+0 | K57: DA+6 | M57: DC1+3 | O57: DC1+0 | Q57: DA+3 | S57: DC2+0 | U57: DA+9 | W57: DA+0 | Y57: DA-3 | AA57: DC2+3 | AC57: DA+6 | AE57: DA+0 | AG57: DA+3
B62: 432 | D62: 401 | F62: 424 | H62: 392 | J62: 367 | L62: 362.955 | N62: 346 | P62: 384 | R62: 406 | T62: 419 | V62: 381 | X62: 408 | Z62: 398 | AB62: 405.185 | AD62: 396 | AF62: 386 | AI62: =SUM(B62:AH62) -> 6308.14 | AJ62: =+AI62+AJ54 -> 42882.199 | AK62: =COUNTA(B63:AG63) -> 1 | AL62: =COUNTA(B61:AG61) -> 0
AC63: DRY
C64: 16/4 | E64: 16/5 | G64: 16/6 | I64: 16/7 | K64: 16/8 | M64: 17/0 | O64: 17/1 | Q64: 17/2 | S64: 17/3 | U64: 17/4 | W64: 17/5 | Y64: 17/6 | AA64: 17/7 | AC64: 18/0 | AE64: 18/1 | AG64: 18/2
C65: DA+3 | E65: DA+6 | G65: DA+0 | I65: DA+0 | K65: DA+0 | M65: DB2+0 | O65: DA+0 | Q65: DA+0 | S65: DA+3 | U65: DA+0 | W65: DA+3 | Y65: DA+0 | AA65: DA+3 | AC65: DB1+0 | AE65: DA+0 | AG65: DA+0
B70: 373 | D70: 363 | F70: 383.043 | H70: 425 | J70: 388 | L70: 351.545 | N70: 373.161 | P70: 344.001 | R70: 317 | T70: 322 | V70: 380.273 | X70: 250.503 | Z70: 394 | AB70: 383 | AD70: 412 | AF70: 396 | AI70: =SUM(B70:AH70) -> 5855.526 | AJ70: =+AI70+AJ62 -> 48737.725 | AK70: =COUNTA(B71:AG71) -> 3 | AL70: =COUNTA(B69:AG69) -> 0
E71: Sandy | G71: WET | AE71: Wet
C72: 18/3 | E72: 18/4 | G72: 19/0 | I72: 19/1 | K72: 19/2 | M72: 20/0 | O72: 21/0 | Q72: 21/1 | S72: 21/2 | U72: 21/3 | W72: 22/0 | X72: Rly Xing | Y72: 23/0 | AA72: 23/1 | AC72: 23/2 | AE72: 23/3 | AG72: 23/4
C73: DA-1.5 | E73: DA-1.5 | G73: DC2+3 | I73: DA+3 | K73: DA-3 | M73: DC2+0 | O73: DB2+0 | Q73: DA+0 | S73: DA-3 | U73: DA-3 | W73: DD60+9 | Y73: DD60+6 | AA73: DA-3 | AC73: DA+3 | AE73: DA+0 | AG73: DA+0
Q75: Ready for stringing
O77: A | Q77: A | S77: A | U77: A | W77: A | AA77: A | AC77: A
B78: 435 | D78: 409 | F78: 359.991 | H78: 394 | J78: 393 | L78: 406 | N78: 403 | P78: 403.728 | R78: 403.001 | T78: 397 | V78: 374.01 | X78: 388 | Z78: 436 | AB78: 381.286 | AD78: 281.969 | AF78: 386 | AI78: =SUM(B78:AH78) -> 6250.985 | AJ78: =+AI78+AJ70 -> 54988.71 | AK78: =COUNTA(B79:AG79) -> 15 | AL78: =COUNTA(B77:AG77) -> 7 | AN78: 9
C79: WET | E79: WET | G79: WPS | I79: WET | K79: WET | M79: Sandy | O79: Sandy | Q79: Sandy | S79: WET | U79: WET | W79: Sandy | AA79: WET | AC79: Sandy | AE79: DRY | AG79: DRY
C80: 23/5 | E80: 23/6 | G80: 24/0 | I80: 24/1 | K80: 24/2 | M80: 24/3 | O80: 24/4 | Q80: 25/0 | S80: 25/1 | U80: 25/2 | W80: 26/0 | Y80: 26/1 | AA80: 26/2 | AC80: 27/0 | AE80: 28/0 | AG80: 28/1
...

Sheet VC SP
A1: Visual Chart | AJ1: =Summary!O1 -> 46202
A3: Progress | G3: WXMIDNC | AB3: LEGEND
A4: Foundation | D4: Nos. | E4: =CONCATENATE(AJ210," ","/"," ",G4) -> 74 / 399 | G4: 399 | L4: TL03: Siwani– Patran (Indi Grid) 400 kV TL | AB4: Crossings | AG4: Status
A5: Earthing | D5: Nos. | E5: =CONCATENATE(AM210," ","/"," ",G5) -> 8 / 399 | G5: 399 | L5: Client: Powergrid Bikaner IV Transmission limited | AB5: #VALUE! | AC5: Powerline Crossing | AH5: In Progress
A6: Erection | D6: Nos. | E6: =CONCATENATE(AK210," ","/"," ",G6) -> 28 / 399 | G6: 399 | L6: Executing Agency:M/s KEC International Limited | AB6: #VALUE! | AC6: Rail Crossing | AH6: Completed
A7: Tack Welding | D7: Nos. | E7: 0/220 | G7: 399 | AB7: #VALUE! | AC7: Road Crossing | AH7: Right of Way
A8: Stringing Paying Out | D8: Km. | E8: =CONCATENATE(AL210," ","/"," ",G8) -> 0 / 147.56 | G8: 147.56 | AC8: Oil/Gas Pipe line | AH8: Earthing
A9: Stringing Final sag | D9: Km. | E9: =CONCATENATE(AL121," ","/"," ",G9) -> / 147.56 | G9: 147.56
AH11: Row Length | AI11: Cum Length | AJ11: Fdns Comp | AK11: TE Comp | AL11: STG Comp | AM11: Earthing
A14: Siwani-Gantry | C14: 100.36 | E14: 268.44 | G14: 161.36 | I14: 400 | K14: 419.03 | M14: 418 | O14: 386.78 | Q14: 319.22 | S14: 390.8 | U14: 438 | W14: 406 | Y14: 436.42 | AA14: 193.59 | AC14: 205.24 | AE14: 356 | AH14: =SUM(A14:AG14) -> 4899.24 | AI14: =+AH14 -> 4899.24 | AJ14: =COUNTA(A15:AF15) -> 0 | AK14: =COUNTA(A13:AF13) -> 0
D16: 1/0 | F16: 1A/0 | H16: 1B/0 | J16: 1B/1 | L16: 1C/0 | N16: 1C/1 | P16: 1C/2 | R16: 1C/3 | T16: 1D/0 | V16: 1D/1 | X16: 1D/2 | Z16: 2/0 | AA16: NH Xing | AB16: 2A/0 | AC16: Rly Xing | AD16: 2B/0 | AF16: 2B/1
D17: DD60+0 | F17: DD60+25 | H17: DD60+25 | J17: DA+9 | L17: DC1+0 | N17: DA+0 | P17: DA+0 | R17: DA+0 | T17: DC2+6 | V17: DA+3 | X17: DA+9 | Z17: DD60+3 | AB17: DD60+6 | AD17: DD60+9 | AF17: DA+0
A22: 300 | C22: 318 | E22: 375 | G22: 371.02 | I22: 204.05 | K22: 377.97 | M22: 420.897 | O22: 393 | Q22: 393 | S22: 383 | U22: 391 | W22: 429 | Y22: 389 | AA22: 413 | AC22: 365 | AE22: 438 | AH22: =SUM(A22:AG22) -> 5960.937 | AI22: =+AH22+AI14 -> 10860.177 | AJ22: =COUNTA(A23:AF23) -> 3 | AK22: =COUNTA(A21:AF21) -> 0
V23: sandy | X23: sandy | AF23: sandy
B24: 2B/2 | D24: 2B/3 | F24: 2B/3 | H24: 2C/0 | I24: 132KV | J24: 2D/0 | L24: 3/0 | N24: 3/1 | P24: 3/2 | R24: 3/3 | T24: 3/4 | V24: 3/5 | X24: 3/6 | Z24: 3/7 | AB24: 3/8 | AD24: 3/9 | AF24: 3/10
B25: DA+0 | D25: DA+0 | F25: DA+0 | H25: DD45+9 | I25: S/C | J25: DD60+9 | L25: DA+0 | N25: DA+1.5 | P25: DA+3 | R25: DA-3 | T25: DA+0 | V25: DA+3 | X25: DA+0 | Z25: DA+0 | AB25: DA-3 | AD25: DA+0 | AF25: DA+3
H26: 132 KV RVNL
A30: 393.115 | C30: 356 | E30: 359 | G30: 410 | I30: 361 | K30: 418.331 | M30: 424 | O30: 318.001 | Q30: 319.999 | S30: 344 | U30: 411 | W30: 393.887 | Y30: 405.25 | AA30: 350 | AC30: 370.747 | AE30: 376 | AH30: =SUM(A30:AG30) -> 6010.33 | AI30: =+AH30+AI22 -> 16870.507 | AJ30: =COUNTA(A31:AF31) -> 0 | AK30: =COUNTA(A29:AF29) -> 0
B32: 4/0 | D32: 4/1 | F32: 4/2 | H32: 4/3 | J32: 4/4 | L32: 5/0 | N32: 5/1 | P32: 5/2 | R32: 5/3 | T32: 5/4 | V32: 5/5 | X32: 5/6 | Z32: 7/0 | AB32: 7/1 | AD32: 8/0 | AF32: 8/1
B33: DB2+0 | D33: DA-3 | F33: DA+0 | H33: DA+3 | J33: DA+3 | L33: DB1+0 | N33: DA+6 | P33: DA+3 | R33: DA+0 | T33: DA+0 | V33: DA+3 | X33: DA+3 | Z33: DB2+0 | AB33: DA+3 | AD33: DB1+0 | AF33: DA+6
A38: 391 | C38: 401 | E38: 402 | G38: 442 | I38: 387.599 | K38: 414 | M38: 418 | O38: 371.223 | Q38: 407 | S38: 377 | U38: 405.674 | W38: 368 | Y38: 427 | AA38: 401 | AC38: 413 | AE38: 403.193 | AH38: =SUM(A38:AG38) -> 6428.689 | AI38: =+AH38+AI30 -> 23299.196 | AJ38: =COUNTA(A39:AF39) -> 0 | AK38: =COUNTA(A37:AF37) -> 0
B40: 8/2 | D40: 8/3 | F40: 8/4 | H40: 8/5 | J40: 9/0 | L40: 9/1 | N40: 9/2 | P40: 10/0 | R40: 10/1 | T40: 10/2 | V40: 11/0 | X40: 11/1 | Z40: 11/2 | AB40: 11/3 | AD40: 11/4 | AF40: 12/0
B41: DA+3 | D41: DA+3 | F41: DA+9 | H41: DA+6 | J41: DC2+3 | L41: DA+0 | N41: DA+3 | P41: DC1+3 | R41: DA+6 | T41: DA+0 | V41: DB1+3 | X41: DA+3 | Z41: DA+3 | AB41: DA+3 | AD41: DA+3 | AF41: DB2+0
A46: 433.474 | C46: 338.526 | E46: 418 | G46: 412 | I46: 425 | K46: 361 | M46: 402.251 | O46: 403.51 | Q46: 418 | S46: 403 | U46: 415 | W46: 385 | Y46: 378 | AA46: 370.903 | AC46: 370 | AE46: 435.958 | AH46: =SUM(A46:AG46) -> 6369.622 | AI46: =+AH46+AI38 -> 29668.818 | AJ46: =COUNTA(A47:AF47) -> 3 | AK46: =COUNTA(A45:AF45) -> 0
T47: Sandy | V47: DRY | X47: Sandy
B48: 12/1 | D48: 12/2 | F48: 12/3 | H48: 12/4 | J48: 12/5 | L48: 12/6 | N48: 13/0 | P48: 14/0 | R48: 14/1 | T48: 14/2 | V48: 14/3 | X48: 14/4 | Z48: 14/5 | AB48: 15/0 | AD48: 15/1 | AF48: 15A/0
B49: DA+6 | D49: DA+6 | F49: DA+0 | H49: DA+6 | J49: DA+6 | L49: DA+0 | N49: DB2+9 | P49: DC1+3 | R49: DA+0 | T49: DA+6 | V49: DA+3 | X49: DA+3 | Z49: DA+0 | AB49: DB2+0 | AD49: DA+0 | AF49: DC2+6
A54: 407.011 | C54: 415 | E54: 395.995 | G54: 404.005 | I54: 395 | K54: 423.118 | M54: 376 | O54: 427.627 | Q54: 417 | S54: 382 | U54: 366 | W54: 446.464 | Y54: 408 | AA54: 407 | AC54: 350 | AE54: 376.934 | AH54: =SUM(A54:AG54) -> 6397.154 | AI54: =+AH54+AI46 -> 36065.972 | AJ54: =COUNTA(A55:AF55) -> 1 | AK54: =COUNTA(A53:AF53) -> 0
J55: DRY
B56: 15B/0 | D56: 15B/1 | F56: 15B/2 | H56: 15B/3 | J56: 15B/4 | L56: 16/0 | N56: 16/1 | P56: 17/0 | R56: 17/1 | T56: 17/2 | V56: 17/3 | X56: 19/0 | Z56: 19/1 | AB56: 19/2 | AD56: 19/3 | AF56: 20/0
B57: DC1+9 | D57: DA+0 | F57: DA+3 | H57: DA+0 | J57: DA+6 | L57: DC2+0 | N57: DA+0 | P57: DC2+6 | R57: DA+0 | T57: DA+0 | V57: DA+6 | X57: DC2+9 | Z57: DA+0 | AB57: DA+3 | AD57: DA+3 | AF57: DC2-3
A62: 355 | C62: 383 | E62: 330.223 | G62: 377 | I62: 382 | K62: 380 | M62: 376 | O62: 390 | Q62: 397 | S62: 380 | U62: 398 | W62: 362.442 | Y62: 348 | AA62: 372 | AC62: 422 | AE62: 420 | AH62: =SUM(A62:AG62) -> 6072.665 | AI62: =+AH62+AI54 -> 42138.637 | AJ62: =COUNTA(A63:AF63) -> 6 | AK62: =COUNTA(A61:AF61) -> 0
R63: PS | T63: Wet | Z63: Wet | AB63: Wet | AD63: Wet | AF63: Wet
B64: 20/1 | D64: 20/2 | F64: 21/0 | H64: 21/1 | J64: 21/2 | L64: 21/3 | N64: 21/4 | P64: 21/5 | R64: 21/6 | T64: 21/7 | V64: 21/8 | X64: 23/0 | Z64: 23/1 | AB64: 23/2 | AD64: 23/3 | AF64: 23/4
B65: DA+0 | D65: DA+3 | F65: DB2+0 | H65: DA+0 | J65: DA+0 | L65: DA+0 | N65: DA+0 | P65: DA+3 | R65: DA+0 | T65: DA+3 | V65: DA+0 | X65: DB1-3 | Z65: DA-1.5 | AB65: DA+0 | AD65: DA+6 | AF65: DA+0
B67: 112 | D67: 113 | F67: 114 | H67: 115 | J67: 116 | L67: 117 | N67: 118 | P67: 119 | R67: 120 | T67: 121 | V67: 122 | X67: 123 | Z67: 124 | AB67: 125 | AD67: 126 | AF67: 127
AB69: A | AD69: A | AF69: A
A70: 358.141 | C70: 466 | E70: 320 | G70: 378.053 | I70: 411 | K70: 378 | M70: 401 | O70: 400.805 | Q70: 350 | S70: 384 | U70: 430.959 | W70: 201.147 | Y70: 420 | AA70: 398.239 | AC70: 385.761 | AE70: 374 | AH70: =SUM(A70:AG70) -> 6057.105 | AI70: =+AH70+AI62 -> 48195.742 | AJ70: =COUNTA(A71:AF71) -> 4 | AK70: =COUNTA(A69:AF69) -> 3 | AM70: 3
R71: WPS | AB71: sandy | AD71: sandy | AF71: Wet
B72: 24/0 | D72: 24/1 | F72: 24/2 | H72: 25/0 | J72: 25/1 | L72: 25/2 | N72: 25/3 | P72: 26/0 | R72: 26/1 | T72: 26/2 | V72: 27/0 | W72: Rly Xing | X72: 28/0 | Z72: 28/1 | AB72: 28/2 | AD72: 28/3 | AF72: 28/4
...

Sheet LS
A1: Client-Powergrid Bikaner IV Tranmission Limited
A2: Project-Siwani-Patran TL & Siwani-Fatehabad TL
A3: Land Schedule Data
A5: Land Schedule Verified
B6: State | C6: District | D6: Tehsil | E6: Line Length (Km) | F6: Total Locations | G6: Corridor Data Submitted (Km) | H6: Verified from Patwari | I6: Sketch Prepared | J6: Balance Sketch
A8: Siwani-Patran | B8: Haryana | C8: Bhiwani | D8: Siwani | E8: 22.072 | F8: 60 | G8: 22.072 | H8: 59 | I8: 39 | J8: =F8-I8 -> 21
C9: Hisar | D9: Balsamand | E9: 4.048 | F9: 10 | G9: 4.048 | H9: 10 | I9: 10 | J9: =F9-I9 -> 0
D10: Hisar | E10: 41.98 | F10: 110 | G10: 41.98 | H10: 110 | I10: 106 | J10: =F10-I10 -> 4
D11: Uklana | E11: 10.358 | F11: 27 | G11: 10.358 | H11: 27 | I11: 27 | J11: =F11-I11 -> 0
D12: Adampur | E12: 4.39 | F12: 11 | G12: 4.39 | H12: 11 | I12: 11 | J12: =F12-I12 -> 0
C13: Fatehabad | D13: Bhuna | E13: 5.664 | F13: 15 | G13: 5.66 | H13: 15 | I13: 15 | J13: =F13-I13 -> 0
D14: Tohana | E14: 25.551 | F14: 72 | G14: 25.55 | H14: 71 | I14: 70 | J14: =F14-I14 -> 2
C15: Jind | D15: Narwana | E15: 2.804 | F15: 8 | G15: 2.804 | H15: 6 | I15: 8 | J15: =F15-I15 -> 0
B16: Punjab | C16: Sangrur | D16: Moonak | E16: 5.101 | F16: 13 | G16: 5.101 | H16: 13 | I16: 13 | J16: =F16-I16 -> 0
D17: Khanauri | E17: 12.832 | F17: 35 | G17: 12.832 | H17: 35 | I17: 35 | J17: =F17-I17 -> 0
C18: Patiala | D18: Patran | E18: 12.761 | F18: 38 | G18: 12.76 | H18: 38 | I18: 37 | J18: =F18-I18 -> 1
C19: Total | E19: =SUM(E8:E18) -> 147.561 | F19: =SUM(F8:F18) -> 399 | G19: =SUM(G8:G18) -> 147.555 | H19: =SUM(H8:H18) -> 395 | I19: =SUM(I8:I18) -> 371 | J19: =SUM(J8:J18) -> 28
A20: Siwani To Fatehabad | B20: Haryana | C20: Bhiwani | D20: Siwani | E20: 21.374 | F20: 57 | G20: 21.37 | H20: 57 | I20: 38 | J20: =F20-I20 -> 19
C21: Hisar | D21: Balsamand | E21: 15.976 | F21: 40 | G21: 15.98 | H21: 40 | I21: 40 | J21: =F21-I21 -> 0
D22: Hisar | E22: 9.17 | F22: 24 | G22: 9.17 | H22: 24 | I22: 24 | J22: =F22-I22 -> 0
D23: Adampur | E23: 18.287 | F23: 48 | G23: 18.28 | H23: 48 | I23: 48 | J23: =F23-I23 -> 0
C24: Fatehabad | D24: Fatehabad | E24: 17.981 | F24: 51 | G24: 17.98 | H24: 51 | I24: 49 | J24: =F24-I24 -> 2
C25: Total | E25: 82.8 | F25: 220 | G25: 82.8 | H25: =SUM(H20:H24) -> 220 | I25: =SUM(I20:I24) -> 199 | J25: =SUM(J20:J24) -> 21
A26: G Total | E26: =SUM(E19+E25) -> 230.361 | F26: =SUM(F19+F25) -> 619 | G26: =SUM(G19+G25) -> 230.355 | H26: =SUM(H19+H25) -> 615 | I26: =SUM(I19+I25) -> 570 | J26: =SUM(J19+J25) -> 49

Sheet Survey 
A1: KEC International Limited | J1: KEC International Limited
A2: 400 KV D/C Siwani To Fatehabad | J2: 400 KV D/C Siwani To Patran
A3: Detailed Survey | J3: Detailed Survey
A4: Sl.No. | B4: SPAN | D4: Section Length (Km) | E4: Submitted For Approval | F4: Approved Date | G4: Approved Status | H4: Remarks | J4: Sl.No. | K4: SPAN | M4: Section Length (Km) | N4: Submitted For Approval | O4: PGCIL Letter Date | P4: PGCIL Aprroval Mail Date | Q4: Approved Status
B5: From Section | C5: To Section | K5: From Section | L5: To Section
A6: 1 | B6: 3/0 | C6: 14/0 | D6: 26.427 | E6: 24.05.2025 | F6: 26.05.2025 | G6: Approved | J6: 1 | K6: 3/0 | L6: 5/0 | M6: 6.312 | N6: 15.05.2025 | O6: 17.05.2025 | Q6: Approved
A7: 2 | B7: 14/0 | C7: 24/0 | D7: =16.986 -> 16.986 | E7: 03.04.2025 | F7: 01.05.2025 | G7: Approved | J7: 2 | K7: 14/0 | L7: 29/0 | M7: 22.093 | N7: 10.04.2025 | O7: 17.05.2025 | Q7: Approved
A8: 3 | B8: 24/0 | C8: 30/0 | D8: 5.64 | E8: 07.03.2025 | F8: 05.4.2025 | G8: Approved | J8: 3 | K8: 29/0 | L8: 33/0 | M8: 8.699 | N8: 10.04.2025 | O8: 17.05.2025 | Q8: Approved
A9: 4 | B9: 30/0 | C9: 32/0 | D9: 2.21 | E9: 28.03.2025 | F9: 05.04.2025 | G9: Approved | J9: 4 | K9: 35/0 | L9: 58/0 | M9: 28.735 | N9: 15.05.2025 | O9: 15.05.2025 | Q9: Approved
A10: 5 | B10: 32/0 | C10: 33/0 | D10: 2.01 | E10: 28.03.2025 | F10: 05.04.2025 | G10: Approved | J10: 5 | K10: 58/0 | L10: 101/0 | M10: 45.55 | N10: 18.05.2025 | O10: 19.05.2025 | P10: 29.05.2025 | Q10: Approved
A11: 6 | B11: 33/0 | C11: 40/0 | D11: 5.412 | E11: 28.03.2025 | F11: 05.04.2025 | G11: Approved | J11: 6 | K11: 101/0 | L11: Gantry | M11: 15.283 | N11: 20.05.2025 | O11: 11.06.2025 | Q11: Approved
A12: 7 | B12: 40/0 | C12: Gantry | D12: 17.582 | E12: 12.04.2025 02.06.2025 | F12: 09.06.2025 | G12: Approved | J12: 7 | K12: 33/0 | L12: 35/0 | M12: 0.721 | N12: 10.04.2025 | Q12: Approved
A13: 8 | B13: Gantry | C13: AP-3 | D13: 6.528 | E13: 29.10.2025 | F13: 11.12.2025 | G13: Approved | J13: 8 | K13: AP5 | L13: AP14 | M13: 13.34 | N13: 17.07.2025 | O13: 45860 | Q13: Approved
J14: 9 | K14: Gantry | L14: AP-3 | M14: 6.853 | N14: 18.11.2025, 09.01.2025 | Q14: Approved
A16: Approved Total Qty | D16: =SUBTOTAL(9,D6:D13) -> 82.795 | J16: Approved Total Qty | M16: =SUM(M6:M14) -> 147.586
A19: 400 KV D/C Siwani To Fatehabad | J19: 400 KV D/C Siwani To Patran
A20: Check Survey | J20: Check survey
A21: Sl.No. | B21: SPAN | D21: Section Length (Km) | E21: Submitted For Approval | F21: Approval Date | G21: Status | H21: Remarks | J21: Sl.No. | K21: SPAN | M21: Section Length (Km) | N21: Submitted For Approval | O21: PGCIL Letter Date | P21: PGCIL Aprroval Mail Date | Q21: Approval Date
B22: From Section | C22: To Section | K22: From Section | L22: To Section
A23: 1 | B23: 3/0 | C23: 14/0 | D23: 26.427 | E23: 4.06.2025 | F23: 3.06.2025 | G23: Approved | J23: 1 | K23: 3/0 | L23: 5/0 | M23: 6.312 | N23: 17.05.2025 | O23: 17.05.2025 | Q23: Approved
A24: 2 | B24: 14/0 | C24: 18/0 | D24: 9.145 | E24: 2.06.2025 | F24: 3.06.2025 | G24: Approved | J24: 2 | K24: 14/0 | L24: 29/0 | M24: 22.093 | N24: 14.05.2025 | O24: 15.05.2025 | Q24: Approved
A25: 3 | B25: 18/0 | C25: 23/0 | D25: 5.05253 | E25: 12.04.2025 | F25: 13.04.2025 | G25: Approved | J25: 3 | K25: 29/0 | L25: 33/0 | M25: 8.699 | N25: 19.04.2025 | O25: 01.05.2025 | Q25: Approved
A26: 4 | B26: 23/0 | C26: 24/0 | D26: 2.789 | E26: 05.04.2025 | F26: 07.04.2025 | G26: Approved | J26: 4 | K26: 35/0 | L26: 58/0 | M26: 28.735 | N26: 15.05.2025 | O26: 15.05.2025 | Q26: Approved
A27: 5 | B27: 24/0 | C27: 30/0 | D27: 5.64 | E27: 07.03.2025 | F27: 04.04.2025 | G27: Approved | J27: 5 | K27: 87/0 | L27: 101/0 | M27: 45.55 | N27: 06.06.2025 | Q27: Approved
A28: 6 | B28: 30/0 | C28: 32/0 | D28: 2.21 | E28: 28.03.2025 | F28: 05.04.2025 | G28: Approved | J28: 6 | K28: 58/0 | L28: 87/0 | N28: 08.06.2025 | Q28: Approved
A29: 7 | B29: 33/0 | C29: 40/0 | D29: 5.41 | E29: 28.03.2025 | F29: 05.04.2025 | G29: Approved | J29: 7 | K29: 101/0 | L29: 119/0 | M29: 15.286 | N29: 17.07.2025 | O29: 26.07.2025 | Q29: Approved
A30: 8 | B30: 32/0 | C30: 33/0 | D30: 2.01 | E30: 28.03.2025 | F30: 05.04.2025 | G30: Approved | J30: 8 | K30: AP5 | L30: AP14 | M30: 13.34 | N30: 05.08.2025 | Q30: Approved
A31: 9 | B31: 41/0 | C31: Gantry | D31: 15.6 | E31: 12.06.2025 | F31: 04.07.2025 | G31: Approved | J31: 9 | K31: AP32 | L31: AP33 | M31: 0.72 | N31: 05.08.2025 | Q31: Approved
A32: 10 | B32: 40/0 | C32: 41/0 | D32: 1.98 | E32: 16.07.2025 | F32: 18.07.2025 | G32: Approved | J32: 10 | K32: Gantry | L32: AP-3 | M32: 6.85 | N32: 06.02.2026 | Q32: Approval Pending
A33: 11 | B33: Gantry | C33: AP-3 | D33: 6.528 | E33: 24.12.2025 | G33: Approval Pending
A34: Approved Total Qty | D34: =SUM(D23:D32) -> 76.26353 | J34: Approved Total Qty | M34: =SUM(M23:M31) -> 140.735
A36: 400 KV D/C Siwani To Fatehabad
A37: Land Schedule
A38: Sl.No. | B38: SPAN | D38: Submitted For Approval | G38: Status | H38: Remarks
B39: From Section | C39: To Section | F39: Approval Date
A40: 1 | B40: 18/0 | C40: 40/0 | D40: 17.05.2025 | G40: 53
A41: 2 | B41: 14/0 | C41: 17/0 | D41: 29.05.2025 | G41: 16
A42: 3 | B42: 3/0 | C42: 7/0 | D42: 06.06.2025 | G42: 38
A43: 4 | B43: 7/0 | C43: 14/0 | D43: 10.06.2025 | G43: 29

Sheet FDN S-P
A1: KEC International Limited | L1: WET | M1: WP | O1: SANDY | P1: PS | Q1: DRY
A2: 400 KV D/C (Quad) Siwani-Patran TL | L2: 3 | P2: 1 | Q2: 9
A3: Details of Foundation
A4: CUMM. SR.NO | B4: MONTH SR.NO. | C4: Location No. | D4: Type of Tower | E4: Type of Classification | F4: Starting Date | G4: Completion Date | H4: Remarks | I4: Village | J4: Tehsil
A5: 1 | B5: 1 | C5: 30/3 | D5: DA-3 | E5: WET | F5: 21.04.2025 | G5: 22.04.2025 | H5: Template | I5: Durjanpur | J5: Hisar
A6: 2 | B6: 2 | C6: 30/1 | D6: DA+3 | E6: WET | F6: 22.04.2025 | G6: 25.04.2025 | H6: Template | I6: Durjanpur | J6: Hisar | K6: S.NO | L6: Tower | M6: Type | N6: Windzone | O6: Classification( Excecuted Locations)
A7: 3 | B7: 3 | C7: 30/2 | D7: DA+3 | E7: WET | F7: 24.04.2025 | G7: 28.04.2025 | H7: Template | I7: Durjanpur | J7: Hisar | O7: WET | P7: WP | Q7: SANDY | R7: PS | S7: DRY | T7: Total
A8: 45778 | K8: 1 | L8: DA | M8: -3M TO 0M | N8: 4 | O8: 13 | P8: 1 | Q8: 4 | R8: 2 | T8: =SUM(O8:S8) -> 20 | U8: 8
A9: 4 | B9: 1 | C9: 29/5 | D9: DA+0 | E9: WET | F9: 29.04.2025 | G9: 01.05.2025 | H9: Template | I9: Kaijlan | J9: Adampur | K9: 2 | L9: DA | M9: +1.5M To 9M | N9: 4 | O9: 11 | Q9: 9 | S9: 1 | T9: =SUM(O9:S9) -> 21 | U9: 4
A10: 5 | B10: 2 | C10: 29/2 | D10: DA+9 | E10: WET | F10: 1.05.2025 | G10: 03.05.2025 | H10: Template | I10: Inchha kharkheri | J10: Adampur | K10: 3 | L10: DB | M10: -3M TO 0M | N10: 4 | P10: 1 | S10: 3 | T10: =SUM(O10:S10) -> 4
A11: 6 | B11: 3 | C11: 29/4 | D11: DA+6 | E11: Sandy | F11: 02.05.2025 | G11: 04.05.2025 | H11: Template | I11: Inchha kharkheri | J11: Adampur | K11: 4 | L11: DC | M11: -3M TO 0M | N11: 4 | S11: 4 | T11: =SUM(O11:S11) -> 4
A12: 7 | B12: 4 | C12: 29/1 | D12: DA+0 | E12: Sandy | F12: 03.05.2025 | G12: 06.05.2025 | H12: Prop | I12: Inchha kharkheri | J12: Adampur | K12: 5 | L12: DC | M12: +1.5M To 9M | N12: 4 | O12: 1 | T12: =SUM(O12:S12) -> 1
A13: 8 | B13: 5 | C13: 29/3 | D13: DA+3 | E13: WET | F13: 03.05.2025 | G13: 05.05.2025 | H13: Template | I13: Inchha kharkheri | J13: Adampur | K13: 6 | L13: 5DA | M13: -3M TO 0M | N13: 5 | O13: 2 | P13: 1 | R13: 1 | S13: 3 | T13: =SUM(O13:S13) -> 7
A14: 9 | B14: 6 | C14: 28/4 | D14: DA+3 | E14: WET | F14: 07.05.2025 | G14: 09.05.2025 | H14: Prop | I14: Neoli khurd | J14: Adampur | K14: 7 | L14: 5DA | M14: +1.5M To 9M | N14: 5 | O14: 3 | R14: 1 | S14: 9 | T14: =SUM(O14:S14) -> 13
A15: 10 | B15: 7 | C15: 28/3 | D15: DA+6 | E15: Sandy | F15: 07.05.2025 | G15: 09.05.2025 | H15: Prop | I15: Neoli khurd | J15: Adampur | K15: 8 | L15: 5DB | M15: +1.5M To 9M | N15: 5 | S15: 1 | T15: =SUM(O15:S15) -> 1
A16: 11 | B16: 8 | C16: 28/2 | D16: DA+3 | E16: Sandy | F16: 09.05.2025 | G16: 11.05.2025 | H16: Template | I16: Neoli khurd | J16: Adampur | K16: Total | O16: =SUM(O8:O15) -> 30 | P16: =SUM(P8:P15) -> 3 | Q16: =SUM(Q8:Q15) -> 13 | R16: =SUM(R8:R15) -> 4 | S16: =SUM(S8:S15) -> 21 | T16: =SUM(T8:T15) -> 71
A17: 12 | B17: 9 | C17: 3/5 | D17: DA+3 | E17: Sandy | F17: 16.05.2025 | G17: 20.05.2025 | H17: Prop | I17: Gaindwas | J17: Siwani
A18: 13 | B18: 10 | C18: 3/6 | D18: DA+0 | E18: Sandy | F18: 20.05.2025 | G18: 24.05.2025 | H18: Prop | I18: Gaindwas | J18: Siwani
A19: 14 | B19: 11 | C19: 3/10 | D19: DA+3 | E19: Sandy | F19: 24.05.2025 | G19: 27.05.2025 | H19: Prop | I19: Siwani | J19: Siwani
A20: 45809
A21: 15 | B21: 1 | C21: 21/7 | D21: DA+3 | E21: WET | F21: 30.05.2025 | G21: 02.06.2025 | H21: Template | I21: Shahpur | J21: Hisar
A22: 16 | B22: 2 | C22: 21/6 | D22: DA+0 | E22: PS | F22: 30.05.2025 | G22: 05.06.2025 | H22: Prop | I22: Hindwan | J22: Hisar
A23: 17 | B23: 3 | C23: 23/1 | D23: DA-1.5 | E23: WET | F23: 03.06.2025 | G23: 07.06.2025 | H23: Prop | I23: Shahpur | J23: Hisar
A24: 18 | B24: 4 | C24: 23/3 | D24: DA+6 | E24: WET | F24: 05.06.2025 | G24: 09.06.2025 | H24: Prop | I24: Shahpur | J24: Hisar
A25: 19 | B25: 5 | C25: 23/2 | D25: DA+0 | E25: WET | F25: 07.06.2025 | G25: 11.06.2025 | H25: Prop | I25: Shahpur | J25: Hisar
A26: 20 | B26: 6 | C26: 23/4 | D26: DA+0 | E26: WET | F26: 11.06.2025 | G26: 15.06.2025 | H26: Prop | I26: Shahpur | J26: Hisar
A27: 21 | B27: 7 | C27: 56/1 | D27: 5DA+3 | E27: Dry | F27: 21.06.2025 | G27: 28.06.2025 | H27: Prop | I27: Pabra | J27: Uklana
A28: 45839
A29: 22 | B29: 1 | C29: 14/4 | D29: DA+3 | E29: Sandy | F29: 20.06.2025 | G29: 01.07.2025 | H29: Prop | I29: Panihari Chak | J29: Hisar
A30: 23 | B30: 2 | C30: 26/1 | D30: DA+0 | E30: Wet Paddy | F30: 28.06.2025 | G30: 03.07.2025 | H30: Prop | I30: Mattarsham | J30: Hisar
A31: 24 | B31: 3 | C31: 56/2 | D31: 5DA+6 | E31: DRY | F31: 02.07.2025 | G31: 05.07.2025 | H31: Prop | I31: Pabra | J31: Uklana
A32: 25 | B32: 4 | C32: 14/3 | D32: DA+3 | E32: Sandy | F32: 02.07.2025 | G32: 07.07.2025 | H32: Prop | I32: Panihari Chak | J32: Hisar
A33: 26 | B33: 5 | C33: 56/4 | D33: 5DA+9 | E33: Dry | F33: 05.07.2025 | G33: 10.07.2025 | H33: Prop | I33: Chamar khera | J33: Uklana
A34: 27 | B34: 6 | C34: 14/2 | D34: DA+6 | E34: Sandy | F34: 07.07.2025 | G34: 45851 | H34: Prop | I34: Chaudhriwas | J34: Hisar
A35: 28 | B35: 7 | C35: 56/0 | D35: 5DB1+6 | E35: Dry | F35: 12.07.2026 | G35: 45853 | H35: Prop | I35: Pabra | J35: Uklana
A36: 29 | B36: 8 | C36: 55/5 | D36: 5DA+6 | E36: Dry | F36: 45854 | G36: 20.07.2025 | H36: Prop | I36: Pabra | J36: Uklana
A37: 30 | B37: 9 | C37: 15B/4 | D37: DA+6 | E37: Dry | F37: 15.07.2025 | G37: 21.07.2025 | H37: Prop | I37: Rawalwas kalan | J37: Balsamand
A38: 31 | B38: 10 | C38: 55/0 | D38: 5DB2+3 | E38: Dry | F38: 20-07.2025 | G38: 24.07.2025 | H38: Prop | I38: Pabra | J38: Uklana
A39: 32 | B39: 11 | C39: 55/6 | D39: 5DA+3 | E39: Dry | F39: 45862 | G39: 28.07.2025 | H39: Prop | I39: Pabra | J39: Uklana
A40: Aug'25
...

Sheet LS Physical
A1: M/S KEC International Limited
A2: 400 KV D/C Siwani To Fatehabad & Siwani-Patran TL
A3: Tower Base Measurement | K3: =COUNTA(K5:K1048576) -> 43
A4: S.NO | B4: Line | C4: Date of Measurement | D4: Location | E4: Type of Tower | F4: District | G4: Tehsil | H4: Village | I4: KEC representatives | J4: PGCIL Representatives | K4: Remarks
A5: 1 | B5: SP Line | C5: 19.06.2026 | D5: 37/1 | E5: =VLOOKUP(D5,[294]SP!$B$4:$I$402,2,0) -> 5DA+0 | F5: =VLOOKUP(D5,[294]SP!$B$4:$I$402,6,0) -> Hisar | G5: =VLOOKUP(D5,[294]SP!$B$4:$I$402,7,0) -> Hisar | H5: =VLOOKUP(D5,[294]SP!$B$4:$I$402,8,0) -> Landhari sukh nambran | I5: Mr.Debashish Sarkar | J5: Mr.Jai Shankar | K5: Compl
A6: 2 | B6: SP Line | C6: 19.06.2026 | D6: 39/0 | E6: 5DC2+9 | F6: Hisar | G6: Hisar | H6: Landhari sukh nambran | I6: Mr.Debashish Sarkar | J6: Mr.Jai Shankar | K6: Compl
A7: 3 | B7: SP Line | C7: 20.06.2026 | D7: 36/1 | E7: 5DA+3 | F7: Hisar | G7: Hisar | H7: Landhari sukh nambran | I7: Mr.Ujjjwal Ghosh | J7: Mr.Jai Shankar | K7: Compl
A8: 4 | B8: SP Line | C8: 20.06.2026 | D8: 36/4 | E8: 5DA-3 | F8: Hisar | G8: Hisar | H8: Landhari sukh nambran | I8: Mr.Ujjjwal Ghosh | J8: Mr.Jai Shankar | K8: Compl
A9: 5 | B9: SP Line | C9: 20.06.2026 | D9: 36/5 | E9: 5DA+6 | F9: Hisar | G9: Hisar | H9: Landhari sukh nambran | I9: Mr.Ujjjwal Ghosh | J9: Mr.Jai Shankar | K9: Compl
A10: 6 | B10: SP Line | C10: 22.06.2026 | D10: 39/1 | E10: 5DA+3 | F10: Hisar | G10: Hisar | H10: Nangthala | I10: Mr.Ujjjwal Ghosh | K10: Marking done
A11: 7 | B11: SP Line | C11: 22.06.2026 | D11: 39/2 | E11: 5DA+3 | F11: Hisar | G11: Hisar | H11: Nangthala | I11: Mr.Ujjjwal Ghosh | K11: Marking done
A12: 8 | B12: SP Line | C12: 23.06.2026 | D12: 45/0 | E12: 5DD60+0 | F12: Hisar | G12: Hisar | H12: Nangthala | I12: Mr.Ujjjwal Ghosh | J12: Mr.Jai Shankar | K12: Compl
A13: 9 | B13: SP Line | C13: 23.06.2026 | D13: 45/1 | E13: 5DA+6 | F13: Hisar | G13: Hisar | H13: Nangthala | I13: Mr.Ujjjwal Ghosh | J13: Mr.Jai Shankar | K13: Compl
A14: 10 | B14: SP Line | C14: 26.06.2026 | D14: 44/2 | E14: 5DA+6 | F14: Hisar | G14: Hisar | H14: Nangthala | I14: Mr.Ujjjwal Ghosh | J14: Mr.Jai Shankar | K14: Compl
A15: 11 | B15: SP Line | C15: 27.06.2026 | D15: 29/3 | E15: DA+3 | F15: Hisar | G15: Adampur | H15: Inchha kharkheri | I15: Mr.Debashish Sarkar | J15: Mr.Jai Shankar | K15: Compl
A16: 12 | B16: SP Line | C16: 27.06.2026 | D16: 29/2 | E16: DA+9 | F16: Hisar | G16: Adampur | H16: Inchha kharkheri | I16: Mr.Debashish Sarkar | J16: Mr.Jai Shankar | K16: Compl
A17: 13 | B17: SP Line | C17: 27.06.2026 | D17: 44/0 | E17: 5DD45+0 | F17: Hisar | G17: Hisar | H17: Nangthala | I17: Mr.Ujjjwal Ghosh | J17: Mr.Jai Shankar | K17: Compl
A18: 14 | B18: SP Line | C18: 27.06.2026 | D18: 46/0 | E18: 5DD45+6 | F18: Hisar | G18: Hisar | H18: Nangthala | I18: Mr.Ujjjwal Ghosh | J18: Mr.Jai Shankar | K18: Compl
A19: 15 | B19: SP Line | C19: 27.06.2026 | D19: 47/1 | E19: 5DA+9 | F19: Hisar | G19: Hisar | H19: Nangthala | I19: Mr.Ujjjwal Ghosh | J19: Mr.Jai Shankar | K19: Compl
A20: 16 | B20: SF Line | C20: 29.06.2026 | D20: 28/0 | E20: DC1-3 | F20: Hisar | G20: Adampur | H20: Ashrawan | I20: Mr.Lavkush | J20: Mr.Deepak kumar | K20: Compl
A21: 17 | B21: SF Line | C21: 29.06.2026 | D21: 28/1 | E21: DA+9 | F21: Hisar | G21: Adampur | H21: Ashrawan | I21: Mr.Lavkush | J21: Mr.Deepak kumar | K21: Compl
A22: 18 | B22: SF Line | C22: 29.06.2026 | D22: 30/0 | E22: DC1+6 | F22: Hisar | G22: Adampur | H22: Ashrawan | I22: Mr.Lavkush | J22: Mr.Deepak kumar | K22: Compl
A23: 19 | B23: SF Line | C23: 29.06.2026 | D23: 31/1 | E23: DA+0 | F23: Hisar | G23: Adampur | H23: Kaliravan | I23: Mr.Lavkush | J23: Mr.Deepak kumar | K23: Compl
... A25: 21 | B25: SF Line | C25: 29.06.2026 | D25: 32B/1 | E25: DA+3 | F25: Hisar | G25: Adampur | H25: Kaliravan | I25: Mr.Lavkush | J25: Mr.Deepak kumar | K25: Compl
A26: 22 | B26: SP Line | C26: 29.06.2026 | D26: 56/1 | E26: 5DA+3 | F26: Hisar | G26: Uklana | H26: Pabra | I26: Mr.Piyush | K26: Compl | L26: Client not available
A27: 23 | B27: SP Line | C27: 29.06.2026 | D27: 55/3 | E27: 5DA+0 | F27: Hisar | G27: Uklana | H27: Pabra | I27: Mr.Piyush | K27: Compl | L27: Client not available
A28: 24 | B28: SP Line | C28: 29.06.2026 | D28: 55/5 | E28: 5DA+6 | F28: Hisar | G28: Uklana | H28: Pabra | I28: Mr.Piyush | K28: Compl | L28: Client not available
A29: 25 | B29: SP Line | D29: 42/0 | E29: 5DC2+6 | F29: Hisar | G29: Hisar | H29: Nangthala | I29: Mr.Ujjjwal Ghosh | J29: Mr.Jai Shankar | K29: Compl
A30: 26 | B30: SP Line | D30: 43/0 | E30: 5DC1+0 | F30: Hisar | G30: Hisar | H30: Nangthala | I30: Mr.Ujjjwal Ghosh | J30: Mr.Jai Shankar | K30: Compl
A31: 27 | B31: SP Line | D31: 44/1 | E31: 5DA+0 | F31: Hisar | G31: Hisar | H31: Nangthala | I31: Mr.Ujjjwal Ghosh | J31: Mr.Jai Shankar | K31: Compl
A32: 28 | B32: SP Line | D32: 47/0 | E32: 5DC1+3 | F32: Hisar | G32: Hisar | H32: Nangthala | I32: Mr.Ujjjwal Ghosh | J32: Mr.Jai Shankar | K32: Compl
A33: 29 | B33: SP Line | D33: 51/3 | E33: 5DA+0 | F33: Fatehabad | G33: Bhuna | H33: Nehla | I33: Mr.Sushil kushwaha | J33: Mr.Rahul | K33: Compl
