Workbook
Name \A: #REF!
Name \A: #REF!
Name \A: #REF!
Name \aa: #REF!
Name \aa: #REF!
Name \aa: #REF!
Name \B: #REF!
Name \B: #REF!
Name \B: #REF!
Name \C: #REF!
Name \C: #REF!
Name \C: #REF!
Name \DFC: #REF!
Name \DFC: #REF!
Name \DFC: #REF!
Name \E: #REF!
Name \E: #REF!
Name \E: #REF!
Name \H: #REF!
Name \H: #REF!
Name \H: #REF!
Name \jmns: #REF!
Name \jmns: #REF!
Name \jmns: #REF!
Name \L: #REF!
Name \L: #REF!
Name \L: #REF!
Name \LK: #REF!
Name \LK: #REF!
Name \LK: #REF!
Name \LKM: #REF!
Name \LKM: #REF!
Name \LKM: #REF!
Name \M: #REF!
Name \M: #REF!
Name \M: #REF!
Name \N: #REF!
Name \N: #REF!
Name \N: #REF!
Name \P: #REF!
Name \P: #REF!
Name \P: #REF!
Name \Q: #REF!
Name \Q: #REF!
Name \Q: #REF!
Name \R: #REF!
Name \R: #REF!
Name \R: #REF!
Name \S: #REF!
Name \S: #REF!
Name \S: #REF!
Name \Sv: #REF!
Name \Sv: #REF!
Name \Sv: #REF!
Name \U: #REF!
Name \U: #REF!
Name \U: #REF!
Name \V: #REF!
Name \V: #REF!
Name \V: #REF!

Sheet 765KV TA 414 VNTL
B1: Project Code | C1: TA 414 | D1: Date | F1: =TODAY()-1 -> 46207 | H1: President-T&D | I1: Mr. Ganesh Srinivasan
B2: Project Name | C2: 765KV D/C HEXA VATAMAN - NAVSARI TL (PKG 04) | F2: NOA Start Date | G2: 45363 | H2: PCH | I2: Mr. Arun Felbin
B3: Client Name | C3: Powergrid Vataman Transmission Ltd | F3: LOA End Date | G3: 46002 | H3: Regional Manager | I3: Mr. Nitin Bandale
B4: Revised End Date | C4: 46153 | F4: Planning Engineer | G4: Nishant Giri | H4: Project Manger | I4: Mr. Vivek Kumar Gupta
A5: \
A6: Check Survey
A7: Activity | B7: Unit | C7: Final Est. Qty | D7: L2 till Last Month | E7: Submitted till Last Month | F7: Approved till Last Month | G7: Balance to Submit | H7: Balance to Approve | I7: L2 Submission Plan for Current Month | J7: Progress For Month | K7: Approved till Current Month | L7: Remarks
A8: Rout Alignment | B8: km | C8: 127.854 | D8: =C8 -> 127.854 | E8: =D8 -> 127.854 | F8: =E8 -> 127.854 | K8: =F8+J8 -> 127.854 | L8: Completed
A9: Detailed Survey | B9: km | C9: =C8 -> 127.854 | D9: =C9 -> 127.854 | E9: =D9 -> 127.854 | F9: =E9 -> 127.854 | K9: =E9+J9 -> 127.854 | L9: Completed
A10: Check Survey | B10: km | C10: =C9 -> 127.854 | D10: =C10 -> 127.854 | E10: =D10 -> 127.854 | F10: =E10 -> 127.854 | K10: =E10+J10 -> 127.854 | L10: Completed
A12: Progress Status
A13: Activity | B13: Final Estimated Quantity | C13: Cumulative L2 till Last Month (Jan'26) | D13: Cumulative Progress till Last Month(Feb'26) | E13: L2 for present Month | F13: Plan for the Month | G13: Today's Progress | H13: Progress till Date for the Month | I13: L2 till Current Month | J13: Completed till Date | K13: Balance Work | L13: Under Progress | M13: Gangs at Present | N13: Remarks
A14: Soil Investigation | B14: 28 | D14: =C14 -> 0 | E14: 0 | F14: 0 | I14: =C14+E14 -> 0 | J14: 28 | K14: =B14-J14 -> 0 | N14: Completed.
A15: Foundation | B15: 351 | D15: 266 | E15: 0 | F15: 45 | G15: ='AOTL - KEC'!G11 -> 0 | H15: ='AOTL - KEC'!H11 -> 0 | I15: =C15+E15 -> 0 | J15: =D15+H15 -> 266 | K15: =B15-J15 -> 85 | L15: ='AOTL - KEC'!K11 -> 0 | M15: ='AOTL - KEC'!L11 -> 0
A16: Earthing | B16: 351 | D16: 236 | E16: 0 | F16: 45 | G16: ='AOTL - KEC'!G13 | H16: ='AOTL - KEC'!H13 -> 0 | I16: =C16+E16 -> 0 | J16: =D16+H16 -> 236 | K16: =B16-J16 -> 115
A17: Tower Erection | B17: 351 | D17: 123 | E17: 0 | F17: 100 | G17: ='AOTL - KEC'!G14 | H17: ='AOTL - KEC'!H14 -> 1 | I17: =C17+E17 -> 0 | J17: =D17+H17 -> 124 | K17: =B17-J17 -> 227 | L17: ='AOTL - KEC'!K14 -> 2 | M17: ='AOTL - KEC'!L14 -> 2
A18: Tack welding | B18: 351 | D18: 35 | E18: 0 | F18: 45 | G18: 1 | H18: ='AOTL - KEC'!H15 -> 0 | I18: =C18+E18 -> 0 | J18: =D18+H18 -> 35 | K18: =B18-J18 -> 316 | L18: 2 | M18: 2
A19: Stringing(Km) | B19: 127.854 | E19: 0 | F19: 8.724 | I19: =C19+E19 -> 0 | J19: =D19+H19 -> 0 | K19: =B19-J19 -> 127.854

Sheet 765KV ASOTL
B1: Project Code | C1: TA 510 | F1: Date | G1: 46208 | H1: President-T&D | I1: Mr. Ganesh Srinivasan
B2: Project Name | C2: 765KV D/C Ahmedabad to South Olpad TL-04 | F2: NOA Start Date | G2: 45622 | H2: PCH | I2: Mr. Arun Felbin
B3: Client Name | C3: PGKTL | F3: LOA End Date | G3: 46320 | H3: Regional Manager | I3: Mr. Nitin Bendale
B4: Revised End Date | F4: Planning Engineer | G4: Mr.Jayant Vaishnav | H4: Project Manger | I4: Mr. Subash .S
A6: Survey
A7: Activity | B7: Unit | C7: Final Est. Qty | D7: L2 till Last Month | E7: Submitted till Last Month | F7: Approved till Last Month | G7: Balance to Submit | H7: Balance to Approve | I7: L2 Submission Plan for Current Month | J7: Progress For Month | K7: Approved till Current Month | L7: Remarks
A8: Rout Alignment | B8: Km | C8: 114.516 | D8: 114.516 | E8: 114.516 | F8: 114.516 | G8: =C8-E8 -> 0 | H8: =E8-K8 -> 0 | I8: =C8-E8 -> 0 | J8: 0 | K8: =F8+J8 -> 114.516 | L8: Completed
A9: Detailed Survey | B9: Km | C9: 114.516 | D9: 114.516 | E9: ='Survey Anx'!E39 -> 114.38448 | F9: ='Survey Anx'!F39 -> 107.971 | G9: =D9-E9 -> 0.13152 | H9: =D9-F9 -> 6.545 | I9: 0 | J9: 0 | K9: ='Survey Anx'!F39 -> 107.971
A10: Check Survey | B10: Km | C10: 114.516 | D10: 114.516 | E10: ='Survey Anx'!G39 -> 103.457 | F10: 94.519 | G10: ='Survey Anx'!H44 -> 10.92748 | H10: ='Survey Anx'!I44 -> 8.938 | I10: 0 | J10: 0 | K10: ='Survey Anx'!I39 -> 94.519
A12: Progress Status
A13: Activity | B13: Final Estimated Quantity | C13: Cumulative L2 till Last Month June'26) | D13: Cumulative Progress till Last Month(June 26) | E13: L2 for present Month | F13: Plan for the Month | G13: Today's Progress | H13: Progress till Date for the Month | I13: L2 till Current Month | J13: Completed till Date | K13: Balance Work | L13: Under Progress | M13: Gangs at Present | N13: Remarks
A14: Soil Investigation | B14: 30 | C14: 0 | D14: 30 | E14: 0 | F14: 0 | I14: 24 | J14: 30 | K14: =B14-J14 -> 0
A15: Foundation | B15: 299 | C15: 16 | D15: 95 | E15: 0 | F15: 20 | I15: 293 | J15: 95 | K15: =B15-J15 -> 204 | L15: 1 | M15: 1
A16: Earthing | B16: 299 | C16: 16 | D16: 89 | E16: 0 | F16: 26 | I16: 293 | J16: 89 | K16: =B16-J16 -> 210
A17: Tower Erection | B17: 299 | C17: 30 | D17: 45 | E17: 0 | F17: 15 | H17: 1 | I17: 293 | J17: 46 | K17: =B17-J17 -> 253 | L17: 2 | M17: 2
A18: Tack welding | B18: 299 | C18: 30 | D18: 13 | E18: 0 | F18: 15 | I18: 293 | J18: 13 | K18: =B18-J18 -> 286 | M18: `
A19: Stringing(Km) | B19: 114.516 | C19: 11 | D19: 0 | E19: 9 | F19: 0 | I19: 90 | J19: =D19+H19 -> 0 | K19: =B19-J19 -> 114.516
I47: ='Survey Anx'!H44 -> 10.92748

Sheet Project Details
A1: Project Code | B1: Project Name | C1: Client Name | D1: NOA Start Date | E1: LOA End Date | F1: Planning Engineer | G1: PCH | H1: Regional Manager | I1: Project Manager | J1: Section Incharge | K1: Supervisor
A2: TA 510 | B2: 765kV D/C Ahmedabad South Olpad TL04 | C2: Powergrid South Olpad Transmission Limited | D2: 45363 | E2: 46002 | F2: Mr.Jayant Vaishnav | G2: Mr.Arun Felbin | H2: Mr. Nitin Ashok Bendale | I2: Mr. Subash.S | J2: Mr.Sahil Khan | K2: Mr.B Nagarajan
K3: Mr.Praveen Singh Rathore
K4: Mr.Vidhya Saker upadya
K5: Mr.Mohan Kumar
K6: Mr.Mohit Kumar Mahto
K7: Mr.Dhananjay Kumar Srivastava
K8: Mr.Ajay Mahato
K9: Mr.Pramod Singh
K10: Mr.Jitender Kumar

Sheet AOTL - KEC
A1: KEC INTERNATIONAL LIMITED | M1: ='765KV ASOTL'!G1 -> 46208
A2: Name of Client: | C2: Powergrid South Olpad Transmission Limited
A3: Name of Line: | C3: TL-04 , 765 kV D/C Ahmedabad - South Olpad Transmission Line
A4: NOA Ref. No.: | C4: CC/T/W-TW/DOM/A10/23/12603/NOA-2/24-114169/01, Dt.26-11-24
A5: Sr No. | B5: Activity | C5: Estimated Quantity | D5: Cumm. Progress up to till last Month June'26) | E5: Target as per L2 Schedule Cummulative (upto June'26) | F5: L3 Plan for the month (July'26 ) | G5: Today's Progress | H5: Progress in this month | I5: Cumm. Progress till date | J5: Cumm. Balance | K5: WIP | L5: No of Gangs | M5: Remark
A6: 1 | B6: Route Alignment (Km) | C6: 114.516 | D6: 114.516 | E6: 0 | F6: =C6-D6 -> 0 | I6: =D6+H6 -> 114.516 | J6: =C6-I6 -> 0
A7: 2 | B7: Detailed Survey (Km) | C7: 114.516 | D7: ='Survey Anx'!F39 -> 107.971 | E7: 0 | F7: =C7-D7 -> 6.545 | I7: =D7+H7 -> 107.971 | J7: =C7-I7 -> 6.545
A8: 3 | B8: Profiling (Km) | C8: 114.516 | D8: ='Survey Anx'!C39-'Survey Anx'!C38 -> 107.65648 | E8: 0 | F8: =C8-D8 -> 6.85952 | I8: =D8+H8 -> 107.65648 | J8: =C8-I8 -> 6.85952
A9: 4 | B9: Check Survey (Km) | C9: 114.516 | D9: ='Survey Anx'!I39 -> 94.519 | E9: 0 | F9: =C9-D9 -> 19.997 | I9: =D9+H9 -> 94.519 | J9: =C9-I9 -> 19.997
A10: 5 | B10: Soil Investigation (Nos.) | C10: 30 | D10: 30 | E10: 0 | F10: =C10-D10 -> 0 | I10: 30 | J10: =C10-I10 -> 0
A11: 6 | B11: Excavation | C11: 293 | D11: 96 | E11: 0 | F11: 34 | I11: 92 | J11: =C11-I11 -> 201
A12: 7 | B12: Foundation (Nos.) | C12: 293 | D12: 95 | E12: 293 | F12: 20 | I12: 95 | J12: =C12-I12 -> 198 | K12: 1 | L12: 1 | M12: ROW & Fronts are not cleared for further work 3Teams are idle due to ROWand unvailability of clear front
A13: 8 | B13: Earthing (Nos.) | C13: 293 | D13: 89 | E13: 293 | F13: 26 | I13: 89 | J13: =C13-I13 -> 204
A14: 9 | B14: Tower Erection (Nos) | C14: 293 | D14: 45 | E14: 285 | F14: 15 | H14: 1 | I14: 46 | J14: =C14-I14 -> 247 | K14: 2 | L14: 2
A15: 10 | B15: Tack Welding | C15: 293 | D15: 13 | E15: 285 | F15: 15 | I15: 13 | J15: =C15-I15 -> 280
A16: 11 | B16: Stringing (Km) | C16: 114.516 | D16: 0 | E16: 95 | F16: 0 | I16: =D16+H16 -> 0 | J16: =C16-I16 -> 114.516
A17: a) | B17: Paying Out | C17: 114.516 | D17: 0 | E17: 95 | F17: 0 | I17: =D17+H17 -> 0 | J17: =C17-I17 -> 114.516
A18: b) | B18: Final Sag | C18: 114.516 | D18: 0 | E18: 95 | F18: 0 | I18: =D18+H18 -> 0 | J18: =C18-I18 -> 114.516
A19: 12 | B19: OPGW (Km) | C19: 114.516 | D19: 0 | E19: 75.27 | F19: 0 | I19: =D19+H19 -> 0 | J19: =C19-I19 -> 114.516

Sheet DPR Sheet
B2: KEC INTERNATIONAL LIMITED
B3: DAILY PROGRESS REPORT : SUBMISSION STATUS AS ON | G3: =+'AOTL - KEC'!M1 -> 46208
B4: Name of the Project: | D4: TL-04 , 765 kV D/C Ahmedabad - South Olpad Transmission Line
B5: Contract No. & Date : | D5: CC/T/W-TW/DOM/A10/23/12603/NOA-2/24-114169/01, Dt.26-11-24
B7: ROUTE ALIGNMENT PROGRESS SUMMARY
B8: TOTAL QTY (Tentative) | C8: COMPLETED UP TO PREV MONTH | D8: COMP. IN CURRENT MONTH | E8: CUMULATIVE | F8: BAL.QTY
B9: ='AOTL - KEC'!C7 -> 114.516 | C9: ='AOTL - KEC'!D6 -> 114.516 | D9: ='AOTL - KEC'!F6 -> 0 | E9: ='AOTL - KEC'!I6 -> 114.516 | F9: ='AOTL - KEC'!J6 -> 0
B10: SOIL INVESTIGATION PROGRESS SUMMARY
B11: TOTAL QTY (Tentative) | C11: COMPLETED UP TO PREV MONTH | D11: COMP. IN CURRENT MONTH | E11: CUMULATIVE | F11: BAL.QTY
B12: 30 | C12: 30 | D12: 0 | E12: =C12+D12 -> 30 | F12: =B12-E12 -> 0
B13: DETAILED SURVEY PROGRESS SUMMARY
B14: TOTAL QTY (Tentative) | C14: COMPLETED UP TO PREV MONTH | D14: COMP. IN CURRENT MONTH | E14: CUMULATIVE | F14: BAL.QTY
B15: ='AOTL - KEC'!C7 -> 114.516 | C15: ='Survey Anx'!F39 -> 107.971 | D15: ='AOTL - KEC'!H7 -> 0 | E15: =D15+C15 -> 107.971 | F15: =B15-E15 -> 6.545
B16: CHECK SURVEY PROGRESS SUMMARY
B17: TOTAL QTY (Tentative) | C17: COMPLETED UP TO PREV MONTH | D17: COMP. IN CURRENT MONTH | E17: CUMULATIVE | F17: BAL.QTY
B18: ='AOTL - KEC'!C9 -> 114.516 | C18: ='Survey Anx'!I39 -> 94.519 | D18: 0 | E18: =C18+D18 -> 94.519 | F18: =B18-E18 -> 19.997
B19: FOUNDATION PROGRESS SUMMARY
B20: TOTAL QTY (Tentative) | C20: COMPLETED UP TO PREV MONTH | D20: COMP. IN CURRENT MONTH | E20: CUMULATIVE | F20: BAL.QTY
B21: ='AOTL - KEC'!C12 -> 293 | C21: 95 | E21: 95 | F21: =B21-E21 -> 198
B22: EARTHING PROGRESS SUMMARY
B23: TOTAL QTY | C23: COMPLETED UP TO PREV MONTH | D23: COMP. IN CURRENT MONTH | E23: CUMULATIVE | F23: BAL.QTY
B24: ='AOTL - KEC'!C13 -> 293 | C24: 89 | E24: 89 | F24: =B24-E24 -> 204
B25: TOWER ERECTION PROGRESS SUMMARY
B26: TOTAL QTY | C26: COMPLETED UP TO PREV MONTH | D26: COMP. IN CURRENT MONTH | E26: CUMULATIVE | F26: BAL.QTY
B27: ='AOTL - KEC'!C14 -> 293 | C27: 45 | D27: 1 | E27: 46 | F27: =B27-E27 -> 247
B28: STRINGING PROGRESS SUMMARY
B29: TOTAL QTY | C29: COMPLETED UP TO PREV MONTH | D29: COMP. IN CURRENT MONTH | E29: CUMULATIVE | F29: BAL.QTY(KM)
B30: ='AOTL - KEC'!C16 -> 114.516 | C30: 0 | D30: 0 | E30: 0 | F30: =B30-E30 -> 114.516
B31: OPGW STRINGING PROGRESS SUMMARY
B32: TOTAL QTY | C32: COMPLETED UP TO PREV MONTH | D32: COMP. IN CURRENT MONTH | E32: CUMULATIVE | F32: BAL.QTY
B33: ='AOTL - KEC'!C18 -> 114.516 | C33: 0 | D33: 0 | E33: 0 | F33: =B33-E33 -> 114.516

Sheet Sheet5
B7: 127/1
B8: 135/0
B9: 139/1
B10: 139/2
B11: 139/3
B12: 140/0
B13: 167/0
B14: 173/0
B15: 174/0
B16: 174/2
B17: 178/2
B18: 179/0
... B77: 199/0

Sheet Sheet3
A1: A
A2: 127/2 | D2: =_xlfn.CONCAT(A2,A3,A4,A5,A6,A7,A8,A9,A10,A11,A12,A13,A14,A15,A16,A17,A18,A19,A20,A21,A22,A23,A24,A25,A26) -> 127/2128/0135/0139/0139/2141/1141/2145/5145/6148/3161/0166/0175/1182/0183/0183/1183/3194/0214/3214/6217/4225/3244/0244/2250/2
A3: 128/0
A4: 135/0
A5: 139/0 | D5: 127/2128/0135/0139/0139/2141/1141/2145/5145/6148/3161/0166/0175/1182/0183/0183/1183/3194/0214/3214/6217/4225/3244/0244/2250/2
A6: 139/2
A7: 141/1
A8: 141/2
A9: 145/5
A10: 145/6
A11: 148/3
A12: 161/0
A13: 166/0
A14: 175/1
A15: 182/0
A16: 183/0
A17: 183/1
... A26: 250/2

Sheet Sheet1
A2: District | B2: Till Dec'24 | C2: Jan'25 | D2: Feb'25 | E2: Mar'25 | F2: Apr'25 | G2: May'25
A3: Bharuch | B3: 14 | C3: 9 | D3: 14 | E3: 4 | F3: 1
A4: Surat | E4: 4 | F4: 17 | G4: 4
A5: Navsari | B5: 4 | C5: 7 | D5: 6 | E5: 2

Sheet Soil Inv.
A1: ASOTL PROJECT - SOIL INVESTIGATION LOCATIONS
A2: Sl. No. | B2: Loc. No. | C2: TOT | D2: RC | E2: Depth In Mtr | F2: Status | G2: Classification | H2: Approval Letter Status | I2: Remarks | J2: Agency | K2: PO
A3: 1 | B3: AP118 | C3: 5DD60+25 | E3: 10 | F3: Approved | G3: Sandy Dry | H3: 45802 | J3: Geo Design | K3: Done.
A4: =A3+1 -> 2 | B4: 124/0 | C4: 5DD60+9 | E4: 20 | F4: Approved | G4: WET | H4: 46173 | I4: Instead of 127/0 | J4: Geo Design | K4: To be Done.
A5: =A4+1 -> 3 | B5: 124/3 | C5: 5DB1+0 | E5: 20 | F5: Approved | G5: Sandy Dry/ WET | H5: 46173 | I5: New Location | J5: Geo Design | K5: To be Done.
A6: =A5+1 -> 4 | B6: 124/7 | C6: 5DB1+0 | E6: 20 | F6: Approved | G6: Sandy Dry/ Normal Dry | H6: 46173 | I6: Instead of 130/0 | J6: Geo Design | K6: To be Done.
A7: =A6+1 -> 5 | B7: 124/10 | C7: 5DA+0 | E7: 20 | F7: Approved | G7: Sandy Dry/ Normal Dry | H7: 46173 | I7: New Location | J7: Geo Design | K7: To be Done.
A8: =A7+1 -> 6 | B8: AP127 | E8: 10 | F8: Approved | G8: Sandy Dry | H8: 45802 | I8: Eliminated | J8: Geo Design | K8: Done.
B9: AP130 | I9: Eliminated | J9: Geo Design
A10: =A8+1 -> 7 | B10: AP131 | C10: DD60+35(S) | E10: 10 | F10: Approved | G10: WET | H10: 46160 | J10: Geo Design | K10: Done.
A11: =A10+1 -> 8 | B11: AP131/1 (Pile) | C11: DD45+9 | E11: 40 | F11: Approved | G11: Pile | H11: 46092 | J11: Geo Design | K11: Done.
A12: =A11+1 -> 9 | B12: AP131/2 (Pile) | C12: DD60+55 | E12: 40 | F12: Approved | G12: Pile | H12: 46160 | J12: Geo Design | K12: Done.
A13: =A12+1 -> 10 | B13: AP132 | C13: DD60+55 | E13: 10 | F13: Approved | G13: Sandy Dry | J13: Geo Design | K13: Done.
A14: =A13+1 -> 11 | B14: AP139 | C14: DD60+0 | E14: 10 | F14: Approved | G14: Sandy Dry | H14: 45802 | J14: Geo Design | K14: Done.
A15: =A14+1 -> 12 | B15: AP142 | C15: DB2+0 | E15: 10 | F15: Approved | G15: Sandy Dry | H15: 45802 | J15: Geo Design | K15: Done.
A16: =A15+1 -> 13 | B16: AP146 | C16: DD45+0 | E16: 10 | F16: Approved | G16: Black Cotton | H16: 45802 | J16: Geo Design | K16: Done.
A17: =A16+1 -> 14 | B17: AP150 | C17: DD60+6 | E17: 10 | F17: Approved | G17: Normal dry/wet | H17: 45802 | J17: Geo Design | K17: Done.
A18: =A17+1 -> 15 | B18: AP155 | C18: DB2+0 | E18: 10 | F18: Approved | G18: Black Cotton | H18: 45802 | J18: Geo Design | K18: Done.
A19: =A18+1 -> 16 | B19: AP158 | C19: DC1+3 | E19: 10 | F19: Approved | G19: Black Cotton | H19: 45802 | J19: Geo Design | K19: Done.
A20: =A19+1 -> 17 | B20: AP162 | C20: DD60+6 | E20: 10 | F20: Approved | G20: Black Cotton | H20: 45802 | J20: Geo Design | K20: Done.
A21: =A20+1 -> 18 | B21: AP166 | C21: DD60+6 | E21: 10 | F21: Approved | G21: Black Cotton | H21: 45802 | J21: Geo Design | K21: Done.
A22: =A21+1 -> 19 | B22: AP174 | E22: 10 | F22: Approved | G22: Black Cotton | H22: 45802 | J22: Geo Design | K22: Done.
A23: =A22+1 -> 20 | B23: AP176 | E23: 10 | F23: Approved | G23: Black Cotton | H23: 45802 | J23: Geo Design | K23: Done.
A24: =A23+1 -> 21 | B24: AP180 | C24: DD60+35(S) | E24: 10 | F24: Approval Awaiting from PGCIL | J24: Bhoomi | K24: To be Done.
A25: =A24+1 -> 22 | B25: AP180/1(Pile) | C25: DD45+35(S) | E25: 40 | F25: Approved | G25: Pile | H25: 46094 | J25: Geo Design | K25: Done.
A26: =A25+1 -> 23 | B26: AP181 (Pile) | C26: DD60+25(S) | E26: 40 | F26: Approved | G26: Pile | H26: 46095 | J26: Geo Design | K26: Done.
A27: =A26+1 -> 24 | B27: AP182 (Pile) | C27: DB2+6 | E27: 40 | F27: Approved | G27: Pile | H27: 46095 | J27: Geo Design | K27: Done.
A28: =A27+1 -> 25 | B28: AP183 | C28: DC1+9 | E28: 10 | F28: Approval Awaiting from PGCIL | G28: Black Cotton | J28: Geo Design | K28: To be Done.
A29: =A28+1 -> 26 | B29: AP184 | C29: DD45+6 | E29: 10 | F29: Approval Awaiting from PGCIL | G29: Sandy Dry/ WET | J29: Geo Design | K29: To be Done.
B30: AP185 | I30: Interchanged
A31: =A29+1 -> 27 | B31: AP186 | C31: DC1+0 | E31: 10 | F31: Approved | G31: Black Cotton | H31: 46099 | I31: Instead of 185/0 | J31: Geo Design | K31: Done.
A32: =A31+1 -> 28 | B32: AP187 | C32: DB2+0 | E32: 10 | F32: Approved | G32: Black Cotton | H32: 46099 | J32: Geo Design | K32: Done.
A33: =A32+1 -> 29 | B33: AP191 | C33: DC1+0 | E33: 10 | F33: Approved | G33: Black Cotton | H33: 46099 | J33: Geo Design | K33: Done.
A34: =A33+1 -> 30 | B34: AP192 | C34: DB1+0 | E34: 10 | F34: Approved | G34: Black Cotton | H34: 46099 | J34: Geo Design | K34: Done.
J35: Geo Design | K35: Done.

Sheet Survey Anx
A1: TL-04 , 765 kV D/C Ahmedabad - South Olpad Transmission Line
A2: District | B2: Section | C2: Total | D2: Detail Survey | G2: Check Survey
D3: Completed | E3: Submitted | F3: Approved | G3: Completed | H3: Submitted | I3: Approved
A4: Anand | B4: 117/0-119/0 | C4: 0.62 | D4: 0.62 | E4: 0.62 | F4: 0.62 | G4: 0.62 | H4: 0.62 | I4: 0.62
A5: Anand | B5: 119/0-124/0 | C5: 1.572 | D5: 1.572 | E5: 1.572 | F5: 1.572 | G5: 1.572 | H5: 1.572 | I5: 1.572
A6: Anand | B6: 124/0-124/3 | C6: 1.228 | D6: 1.228 | E6: 1.228 | F6: 1.228 | G6: =F6 -> 1.228 | H6: =G6 -> 1.228 | I6: =H6 -> 1.228
A7: Anand | B7: 124/3-131/0 | C7: 3.994 | D7: =C7 -> 3.994 | E7: =D7 -> 3.994 | F7: =E7 -> 3.994 | G7: =F7 -> 3.994 | H7: =G7 -> 3.994 | I7: =H7 -> 3.994
A8: Vadodara | B8: 131/0-133/0 | C8: 2.694 | D8: 2.694 | E8: 2.694 | F8: 2.694 | G8: 2.694 | H8: 2.694 | I8: 2.694
A9: Vadodara | B9: 133/0-135/0 | C9: 1.555 | D9: 1.555 | E9: 1.555 | F9: 1.555 | G9: 1.555 | H9: 1.555 | I9: 1.555
A10: Bharuch | B10: 135/0-136/0 | C10: 0.422 | D10: 0.422 | E10: 0.422 | F10: 0.422 | G10: 0.422 | H10: 0.422 | I10: 0.422
A11: Bharuch | B11: 136/0-139/5 | C11: 3.881 | D11: 3.881 | E11: 3.881 | F11: 3.881 | G11: 3.881 | H11: 3.881 | I11: 3.881
A12: Bharuch | B12: 139/5-144/0 | C12: 4.328 | D12: 4.328 | E12: 4.328 | F12: 4.328 | G12: 4.328 | H12: 4.328 | I12: 4.328
A13: Bharuch | B13: 144/0-146/0 | C13: 2.9 | D13: 2.9 | E13: 2.9 | F13: 2.9 | G13: 2.9 | H13: 2.9 | I13: 2.9
A14: Bharuch | B14: 146/0-148/1 | C14: 3.526 | D14: 3.526 | E14: 3.526 | F14: 3.526 | G14: 3.526 | H14: 3.526 | I14: 3.526
A15: Bharuch | B15: 148/1-148/7 | C15: 2.312 | D15: 2.312 | E15: 2.312 | F15: 2.312 | G15: 2.312 | H15: 2.312 | I15: 2.312
A16: Bharuch | B16: 148/7-153/0 | C16: 4.704 | D16: 4.704 | E16: 4.704 | F16: 4.704 | G16: 4.704 | H16: 4.704 | I16: 4.704
A17: Bharuch | B17: 153/0-155/0 | C17: 1.557 | D17: 1.557 | E17: 1.557 | F17: 1.557 | G17: 1.557 | H17: 1.557 | I17: 1.557
A18: Bharuch | B18: 155/0-155/5 | C18: 1.947 | D18: 1.947 | E18: 1.947 | F18: 1.947 | G18: 1.947 | H18: 1.947 | I18: 1.947
A19: Bharuch | B19: 155/5-156/0 | C19: 0.405 | D19: 0.405 | E19: 0.405 | F19: 0.405 | G19: 0.405 | H19: 0.405 | I19: 0.405
A20: Bharuch | B20: 156/0-160/1 | C20: =5.966+2.39 -> 8.356 | D20: =5.966+2.39 -> 8.356 | E20: =5.966+2.39 -> 8.356 | F20: =5.966+2.39 -> 8.356 | G20: =5.966+2.39 -> 8.356 | H20: =5.966+2.39 -> 8.356 | I20: =5.966+2.39 -> 8.356
A21: Bharuch | B21: 160/1-160/3 | C21: 0.817 | D21: 0.817 | E21: 0.817 | F21: 0.817 | G21: 0.817 | H21: 0.817 | I21: 0.817
A22: Bharuch | B22: 160/3-162/0 | C22: 5.219 | D22: 5.219 | E22: 5.219 | F22: 5.219 | G22: 5.219 | H22: 5.219 | I22: 5.219
A23: Bharuch | B23: 162/0-167/5 | C23: =2.845+3.405 -> 6.25 | D23: =C23 -> 6.25 | E23: =D23 -> 6.25 | F23: =E23 -> 6.25 | G23: =F23 -> 6.25 | H23: =F23 -> 6.25 | I23: =H23 -> 6.25 | J23: 162/0-165/0 | K23: 2.845
A24: Bharuch | B24: 167/5-174A/0 | C24: 5.01148 | D24: =C24 -> 5.01148 | E24: =D24 -> 5.01148 | J24: 165/0-167/5 | K24: 3.405
A25: Bharuch | B25: 174A/0- 175/0 | C25: 5.301 | D25: =C25 -> 5.301 | E25: =D25 -> 5.301 | F25: =E25 -> 5.301 | G25: 5.301 | H25: 5.301 | I25: 4.49
A26: Bharuch | B26: 175/0-177/0 | C26: 3.992 | D26: 3.992 | E26: 3.992 | F26: =E26 -> 3.992 | G26: =F26 -> 3.992 | H26: =G26 -> 3.992
A27: Bharuch | B27: 177/0-179/0 | C27: 3.142 | D27: 3.142 | E27: 3.142 | F27: 3.142 | G27: 3.142 | H27: 3.142 | I27: 3.142
A28: Bharuch | B28: 179/0-183/0 | C28: 2.477 | D28: 2.477 | E28: 2.477 | F28: 2.477 | G28: 2.477 | H28: 2.477 | I28: 2.477 | K28: 353.55
A29: Bharuch | B29: 183/0-184/0 | C29: 1.128 | D29: 1.128 | E29: 1.128 | F29: 1.128 | G29: 1.128 | H29: 1.128 | I29: 1.128 | K29: 362.84
A30: Bharuch | B30: 184/0-185/0 | C30: 5.916 | D30: 5.916 | E30: 5.916 | F30: 4.514 | K30: 410.43
A31: Bharuch | B31: 185/0-186/0 | C31: 0.244 | D31: 0.244 | E31: 0.244 | F31: 0.244 | G31: 0.244 | H31: 0.244 | I31: 0.244 | K31: 406.38
A32: Bharuch | B32: 186/0-189/0 | C32: 6.597 | D32: 6.597 | E32: 6.597 | F32: 6.597 | G32: 6.597 | H32: 6.597 | I32: 6.597 | K32: 413.88
A33: Bharuch | B33: 189/0-190/0 | C33: 0.243 | D33: 0.243 | E33: 0.243 | F33: 0.243 | G33: 0.243 | H33: 0.243 | I33: 0.243 | K33: 397.98
A34: Bharuch | B34: 190/0-192/1 | C34: 5.061 | D34: 5.061 | E34: 5.061 | F34: 5.061 | G34: 5.061 | H34: 5.061 | I34: 5.061 | K34: 444.34
A35: Bharuch | B35: 192/1-192/13 | C35: 4.712 | D35: 4.712 | E35: 4.712 | F35: 4.712 | G35: 4.712 | H35: 4.712 | I35: 4.712 | K35: 163.1
A36: Bharuch | B36: 192/13-194/0 | C36: 2.794 | D36: 2.794 | E36: 2.794 | F36: 2.794 | G36: 2.794 | H36: 2.794 | I36: 2.794 | K36: 516.34
A37: Surat | B37: 194/0-195/0 | C37: 2.751 | D37: 2.751 | E37: 2.751 | F37: 2.751 | G37: 2.751 | H37: 2.751 | I37: 2.751 | K37: 300.73
A38: Surat | B38: 195/0-Gantry | C38: 6.728 | D38: 6.728 | E38: 6.728 | F38: 6.728 | G38: =F38 -> 6.728 | H38: =G38 -> 6.728 | I38: 2.593 | K38: 491.39
C39: =SUM(C4:C38) -> 114.38448 | D39: =SUM(D4:D38) -> 114.38448 | E39: =SUM(E4:E38) -> 114.38448 | F39: =SUM(F4:F38) -> 107.971 | G39: =SUM(G4:G38) -> 103.457 | H39: =SUM(H4:H38) -> 103.457 | I39: =SUM(I4:I38) -> 94.519 | K39: =SUM(K26:K38) -> 4260.96
E40: Balance | F40: =C39-F39 -> 6.41348 | I40: =F39-I39 -> 13.452
...

Sheet Survey
D1: Date | E1: =+'AOTL - KEC'!M1 -> 46208
A3: TA-510 | ASOTL PROJECT | SURVEY STATUS |
A4: Sl. No. | B4: Particulars | C4: UoM | D4: Qty. | E4: Remarks
A5: 1 | B5: Total Line Length | C5: Kms. | D5: ='Survey Anx'!C39 -> 114.38448
A6: 2 | B6: Detail Survey Submitted | C6: Kms. | D6: ='Survey Anx'!D39 -> 114.38448
A7: 3 | B7: Balance to Submit | C7: Kms. | D7: =D5-D6 -> 0 | E7: AP171/0-175/0 GETCO- SS
A8: 4 | B8: Detail Survey Approved | C8: Kms. | D8: ='Survey Anx'!F39 -> 107.971
A9: 5 | B9: Balance to Approve | C9: Kms. | D9: 16.839 | E9: AP175-177 & 184-185
A10: 6 | B10: Check Survey Submitted | C10: Kms. | D10: ='Survey Anx'!G39 -> 103.457
A11: 7 | B11: Check Survey Approved | C11: Kms. | D11: ='Survey Anx'!I39 -> 94.519 | F11: =D10-D11 -> 8.938
A12: 8 | B12: Balance to Approve | C12: Kms. | D12: =D10-D11 -> 8.938
A13: 9 | B13: Balanceto Submit due to Crossing Section | C13: Kms. | D13: =D8-D11 -> 13.452

Sheet FDN
A1: ASOTL Foundation | N1: ='765KV ASOTL'!G1 -> 46208 | P1: `
A2: Sl. No. | B2: Location No. | C2: Tower Type | D2: Classification | E2: Concreting Volume in M3 | F2: Starting Date | G2: Todays Status | H2: Cumulative Status | I2: Completion Date | J2: Remarks | K2: Gang name | L2: Earthing Status | M2: Earthing Completion Date
A3: =A2+1 -> #VALUE! | B3: 155/1 | C3: DA+0 | D3: WET | E3: =5.618+57.728 -> 63.346 | F3: 45700 | H3: Completed | I3: 45705 | K3: Arya Enterprises | L3: Done | M3: 45720
A4: =A3+1 -> #VALUE! | B4: 155/4 | C4: DA+0 | D4: WPS | E4: =3.264+35.862 -> 39.126 | F4: 45706 | H4: Completed | I4: 45710 | K4: B.K.Traders | L4: Done | M4: 45717
A5: 1 | B5: 155/3 | C5: DA+0 | D5: WPS | E5: =3.264+35.862 -> 39.126 | F5: 45706 | H5: Completed | I5: 45713 | K5: Arya Enterprises | L5: Done | M5: 45715
A6: =A5+1 -> 2 | B6: 155/5 | C6: DA+3 | D6: WPS | E6: =3.486+37.148 -> 40.634 | F6: 45711 | H6: Completed | I6: 45715 | K6: B.K.Traders | L6: Done | M6: 45717
A7: =A6+1 -> 3 | B7: 156/0 | C7: DB2+0 | D7: WPS | E7: =5.294+57.588 -> 62.882 | F7: 45721 | H7: Completed | I7: 45728 | K7: B.K.Traders | L7: Done | M7: 45732
A8: =A7+1 -> 4 | B8: 156/1 | C8: DA+3 | D8: WET | E8: =5.951+59.68 -> 65.631 | F8: 45721 | H8: Completed | I8: 45729 | K8: Arya Enterprises | L8: Done | M8: 45731
A9: =A8+1 -> 5 | B9: 156/3 | C9: DA+0 | D9: WPS | E9: =3.264+35.862 -> 39.126 | F9: 45729 | H9: Completed | I9: 45732 | K9: B.K.Traders | L9: Done | M9: 45733
A10: =A9+1 -> 6 | B10: 156/4 | C10: DA+3 | D10: WPS | E10: =3.486+37.148 -> 40.634 | F10: 45737 | H10: Completed | I10: 45741 | K10: Arya Enterprises | L10: Done | M10: 45744
A11: =A10+1 -> 7 | B11: 156/2 | C11: DA+0 | D11: WPS | E11: =3.264+35.862 -> 39.126 | F11: 45742 | H11: Completed | I11: 45746 | K11: Arya Enterprises | L11: Done | M11: 45750
A12: =A11+1 -> 8 | B12: 139/1 | C12: DA+0 | D12: WPS | E12: =3.264+35.862 -> 39.126 | F12: 45742 | H12: Completed | I12: 45763 | K12: Om Infra | L12: Done | M12: 45783
A13: =A12+1 -> 9 | B13: 138/0 | C13: DD60+0 | D13: WPS | E13: =11.31+166.88 -> 178.19 | F13: 45752 | H13: Completed | I13: 45768 | K13: Om Infra | L13: Done | M13: 45788
A14: =A13+1 -> 10 | B14: 139/5 | C14: DA+0 | D14: WPS | E14: =3.264+35.862 -> 39.126 | F14: 45761 | H14: Completed | I14: 45768 | K14: B.K.Traders | L14: Done | M14: 45770
A15: =A14+1 -> 11 | B15: 137/0 | C15: DD45+0 | D15: WPS | E15: =9.059+119.368 -> 128.427 | F15: 45761 | H15: Completed | I15: 45774 | K15: Om Infra | L15: Done | M15: 45788
A16: =A15+1 -> 12 | B16: 139/4 | C16: DA+0 | D16: WPS | E16: =3.264+35.862 -> 39.126 | F16: 45770 | H16: Completed | I16: 45775 | K16: B.K.Traders | L16: Done | M16: 45779
A17: =A16+1 -> 13 | B17: 138/1 | C17: DA+0 | D17: WPS | E17: =3.264+35.862 -> 39.126 | F17: 45761 | H17: Completed | I17: 45776 | K17: Om Infra | L17: Done | M17: 45783
A18: =A17+1 -> 14 | B18: 136/0 | C18: DD60+0 | D18: WPS | E18: =11.31+166.88 -> 178.19 | F18: 45772 | H18: Completed | I18: 45791 | K18: Om Infra | L18: Done | M18: 45791
A19: =A18+1 -> 15 | B19: 148/5 | C19: DA+0 | D19: WET | E19: =5.618+57.728 -> 63.346 | F19: 45780 | H19: Completed | I19: 45792 | K19: B.K.Traders | L19: Not Done
A20: =A19+1 -> 16 | B20: 148/4 | C20: DA+3 | D20: WPS | E20: =3.486+37.148 -> 40.634 | F20: 45790 | H20: Completed | I20: 45798 | K20: B.K.Traders | L20: Done | M20: 45801
A21: =A20+1 -> 17 | B21: 148/2 | C21: DA+0 | D21: WPS | E21: =3.264+35.862 -> 39.126 | F21: 45792 | H21: Completed | I21: 45800 | K21: B.K.Traders | L21: Not Done
A22: =A21+1 -> 18 | B22: 134/0 | C22: DC2+0 | D22: WPS | E22: =7.224+85.068 -> 92.292 | F22: 45792 | H22: Completed | I22: 45802 | K22: Om Infra | L22: Done | M22: 45803
A23: =A22+1 -> 19 | B23: 148/7 | C23: DA+0 | D23: WPS | E23: =3.264+35.862 -> 39.126 | F23: 45794 | H23: Completed | I23: 45805 | K23: B.K.Traders | L23: Not Done
A24: =A23+1 -> 20 | B24: 148/6 | C24: DA+0 | D24: WET | E24: =5.618+57.728 -> 63.346 | F24: 45796 | H24: Completed | I24: 45808 | K24: B.K.Traders | L24: Not Done
A25: =A24+1 -> 21 | B25: 143/1 | C25: DA+3 | D25: WPS | E25: =3.486+37.148 -> 40.634 | F25: 45802 | H25: Completed | I25: 45810 | K25: Jyoti Construction | L25: Done | M25: 45818
A26: =A25+1 -> 22 | B26: 143/2 | C26: DA+0 | D26: WPS | E26: =3.264+35.862 -> 39.126 | F26: 45807 | H26: Completed | I26: 45813 | K26: Jyoti Construction | L26: Done | M26: 45818
A27: =A26+1 -> 23 | B27: 144/0 | C27: DB1+0 | D27: WPS | E27: =4.343+50.332 -> 54.675 | F27: 45809 | H27: Completed | I27: 45875 | K27: Jyoti Construction | L27: Done | M27: 45816
A28: =A27+1 -> 24 | B28: 141/0 | C28: DB2+0 | D28: WPS | E28: =5.294+57.588 -> 62.882 | F28: 45861 | H28: Completed | I28: 45916 | L28: Done | M28: 45921
A29: =A28+1 -> 25 | B29: 133/2 | C29: DA+0 | D29: WPS | E29: =3.264+35.862 -> 39.126 | F29: 45900 | H29: Completed | I29: 45918 | K29: B.K.Traders | L29: Done | M29: 45922
A30: =A29+1 -> 26 | B30: 141/1 | C30: DA+0 | D30: WPS | E30: =3.264+35.862 -> 39.126 | F30: 45921 | H30: Completed | I30: 45934 | K30: Shakaldev | L30: Done | M30: 45938
A31: =A30+1 -> 27 | B31: 138/2 | C31: DA+0 | D31: WPS | E31: =3.264+35.862 -> 39.126 | F31: 45919 | H31: Completed | I31: 45935 | K31: Vihan | L31: Done | M31: 45941
A32: =A31+1 -> 28 | B32: 140/1 | C32: DA+3 | D32: WPS | E32: =3.486+37.148 -> 40.634 | F32: 45924 | H32: Completed | I32: 45940 | K32: Shakaldev | L32: Done | M32: 45921
A33: =A32+1 -> 29 | B33: 145/0 | C33: DB2+9 | D33: WPS | E33: =5.555+59.58 -> 65.135 | F33: 45925 | H33: Completed | I33: 45949 | K33: Vihan | L33: Done | M33: 45969
A34: =A33+1 -> 30 | B34: 139/2 | C34: DA+3 | D34: WPS | E34: =3.486+37.148 -> 40.634 | F34: 45945 | H34: Completed | I34: 45954 | K34: Shakaldev | L34: Done | M34: 46022
A35: =A34+1 -> 31 | B35: 140/2 | C35: DA+0 | D35: WPS | E35: =3.264+35.862 -> 39.126 | F35: 45910 | H35: Completed | I35: 45980 | K35: Shakaldev | L35: Done | M35: 45987
A36: =A35+1 -> 32 | B36: 135/0 | C36: DB1+6 | D36: WPS | E36: =4.38+50.612 -> 54.992 | F36: 45972 | H36: Completed | I36: 45985 | K36: B.K.Traders | L36: Done | M36: 45989
A37: =A36+1 -> 33 | B37: 145/1 | C37: DB1+9 | D37: WPS | E37: =4.38+50.612 -> 54.992 | F37: 45972 | H37: Completed | I37: 45985 | K37: MD Hussain | L37: Done | M37: 45988
A38: =A37+1 -> 34 | B38: 138/3 | C38: DA-3 | D38: WPS | E38: =3.264+35.862 -> 39.126 | F38: 45979 | H38: Completed | I38: 45988 | K38: Shakaldev | L38: Done | M38: 45989
A39: =A38+1 -> 35 | B39: 192/11 | C39: DA+3 | D39: WET | E39: =5.951+59.68 -> 65.631 | F39: 45976 | H39: Completed | I39: 45991 | K39: Rudra | L39: Done | M39: 46013
A40: =A39+1 -> 36 | B40: 141/2 | C40: DA+6 | D40: WPS | E40: =3.486+37.148 -> 40.634 | F40: 45991 | H40: Completed | I40: 45998 | K40: MD Hussain | L40: Done | M40: 46000
...

Sheet Erection 
A2: AOTL Tower Erection | P2: =FDN!N1 -> 46208
A3: Sl. No. | B3: Location Number | C3: Type of Tower | D3: Starting Date | E3: Tower Weight (MT) | F3: Status | G3: Completion Date | H3: Gang Name | I3: Tower Tightening | J3: Manpower | K3: Hindarnce Days | L3: Remarks | M3: Tackweldng Status | N3: Tackwelding start date | O3: Tackwelding Completion date | P3: Sub Contractor name
A4: 1 | B4: 141/1 | C4: DA+0 | D4: 46023 | E4: 37.73 | F4: Completed | G4: 46029 | H4: Dhaneshwar Mahato | I4: Complete
A5: 2 | B5: 139/2 | C5: DA+3 | D5: 46027 | E5: 39.458 | F5: Completed | G5: 46034 | H5: Lalan Mehta
A6: 3 | B6: 141/0 | C6: DB2+0 | D6: 46030 | E6: 54.418 | F6: Completed | G6: 46035 | H6: Dhaneshwar Mahato | I6: Complete
A7: 5 | B7: 140/1 | C7: DA+3 | D7: 46036 | E7: 39.458 | F7: Completed | G7: 46043 | H7: Dhaneshwar Mahato | I7: Complete
A8: 4 | B8: 135/0 | C8: DB1+6 | D8: 46035 | E8: 63.509 | F8: Completed | G8: 46047 | H8: Lalan Mehta
A9: 7 | B9: 145/4 | C9: DA+0 | D9: 46040 | E9: 37.73 | F9: Completed | G9: 46050 | H9: Lalan Mehta
A10: 6 | B10: 143/1 | C10: DA+3 | D10: 46038 | E10: 39.458 | F10: Completed | G10: 46051 | H10: Hoque Construction | M10: Completed | N10: 46090 | O10: 46090 | P10: Asmina Power
A11: 8 | B11: 145/0 | C11: DB2+9 | D11: 46044 | E11: 65.757 | F11: Completed | G11: 46052 | H11: Dhaneshwar Mahato | I11: Complete | M11: Completed | N11: 46091 | O11: 46091 | P11: Asmina Power
A12: 9 | B12: 145/5 | C12: DA+0 | D12: 46049 | E12: 37.73 | F12: Completed | G12: 46053 | H12: Lalan Mehta
A13: 11 | B13: 134/0 | C13: DC2+0 | D13: 46054 | E13: 64.254 | F13: Completed | G13: 46060 | H13: Dhaneshwar Mahato | I13: Complete
A14: 10 | B14: 145/1 | C14: DB1+9 | D14: 46052 | E14: 65.757 | F14: Completed | G14: 46064 | H14: Hoque Construction
A15: 12 | B15: 140/2 | C15: DA+0 | D15: 46061 | E15: 37.73 | F15: Completed | G15: 46066 | H15: Dhaneshwar Mahato | I15: Complete
A16: 13 | B16: 148/3 | C16: DA+0 | D16: 46066 | E16: 37.73 | F16: Completed | G16: 46070 | H16: Dhaneshwar Mahato | I16: Complete | M16: Completed | N16: 46155 | O16: 46155 | P16: Asmina Power
A17: 14 | B17: 143/0 | C17: DC2+0 | D17: 46065 | E17: 64.254 | F17: Completed | G17: 46073 | H17: Hoque Construction
A18: 15 | B18: 148/2 | C18: DA+0 | D18: 46071 | E18: 37.73 | F18: Completed | G18: 46075 | H18: Dhaneshwar Mahato | I18: Complete | M18: Completed | N18: 46155 | O18: 46155 | P18: Asmina Power
A19: 16 | B19: 148/1 | C19: DA+0 | D19: 46076 | E19: 37.73 | F19: Completed | G19: 46080 | H19: Dhaneshwar Mahato | I19: Complete | M19: Completed | N19: 46157 | O19: 46157 | P19: Asmina Power
A20: 17 | B20: 192/13 | C20: DA+0 | D20: 46075 | E20: 37.73 | F20: Completed | G20: 46081 | H20: Hoque Construction
A21: 18 | B21: 148/4 | C21: DA+3 | D21: 46080 | E21: 39.458 | F21: Completed | G21: 46086 | H21: Dhaneshwar Mahato | I21: Complete | M21: Completed | N21: 46155 | O21: 46155 | P21: Asmina Power
A22: 19 | B22: 192/11 | C22: DA+3 | D22: 46082 | E22: 39.458 | F22: Completed | G22: 46090 | H22: Hoque Construction
A23: 20 | B23: 141/2 | C23: DA+6 | D23: 46089 | E23: 44.727 | F23: Completed | G23: 46097 | H23: Dhaneshwar Mahato | I23: Complete
A24: 21 | B24: 186/1 | C24: DA+0 | D24: 46091 | E24: 37.73 | F24: Completed | G24: 46098 | H24: Hoque Construction
A25: 22 | B25: 140/0 | C25: DD45+0 | D25: 46097 | E25: 72.234 | F25: Completed | G25: 46105 | H25: Dhaneshwar Mahato | I25: Complete
A26: 23 | B26: 194/1 | C26: DA+6 | D26: 46098 | E26: 44.727 | F26: Completed | G26: 46107 | H26: Hoque Construction
A27: 24 | B27: 146A/0 | C27: DB2+0 | D27: 46105 | E27: 54.418 | F27: Completed | G27: 46111 | H27: Dhaneshwar Mahato | I27: Complete | M27: Completed | N27: 46161 | O27: 46161 | P27: Asmina Power
A28: 25 | B28: 192/10 | C28: DA+0 | D28: 46107 | E28: 37.73 | F28: Completed | G28: 46112 | H28: Hoque Construction
A29: 26 | B29: 146/0 | C29: DD45+0 | D29: 46114 | E29: 72.234 | F29: Completed | G29: 46121 | H29: Dhaneshwar Mahato | I29: Complete | M29: Completed | N29: 46158 | O29: 46158 | P29: Asmina Power
A30: 27 | B30: 146/1 | C30: DA+0 | D30: 46121 | E30: 37.796 | F30: Completed | G30: 46127 | H30: Dhaneshwar Mahato | I30: Complete | M30: Completed | N30: 46159 | O30: 46159 | P30: Asmina Power
A31: 28 | B31: 146/2 | C31: DA+0 | D31: 46127 | E31: 37.796 | F31: Completed | G31: 46133 | H31: Dhaneshwar Mahato | I31: Complete | M31: Completed | N31: 46160 | O31: 46160 | P31: Asmina Power
A32: 29 | B32: 146/3 | C32: DA+0 | D32: 46134 | E32: 37.796 | F32: Completed | G32: 46141 | H32: Dhaneshwar Mahato | I32: Complete | M32: Completed | N32: 46160 | O32: 46160 | P32: Asmina Power
A33: 30 | B33: 145/3 | C33: DA+0 | D33: 46142 | E33: 37.796 | F33: Completed | G33: 46148 | H33: Dhaneshwar Mahato | I33: Complete | M33: Completed | N33: 46163 | O33: 46163 | P33: Asmina Power
A34: 31 | B34: 148/5 | C34: DA+0 | D34: 46145 | E34: 37.796 | F34: Completed | G34: 46149 | H34: Gauri Shankar
A35: 32 | B35: 146A/1 | C35: DA+0 | D35: 46149 | E35: 37.796 | F35: Completed | G35: 46155 | H35: Dhaneshwar Mahato | I35: Complete | M35: Completed | N35: 46162 | O35: 46162 | P35: Asmina Power
A36: 33 | B36: 148/6 | C36: DA+0 | D36: 46150 | E36: 37.796 | F36: Completed | G36: 46154 | H36: Gauri Shankar
A37: 34 | B37: 148/7 | C37: DA+0 | D37: 46155 | E37: 37.796 | F37: Completed | G37: 46159 | H37: Gauri Shankar
A38: 35 | B38: 147/1 | C38: DA-3 | D38: 46156 | E38: 36.044 | F38: Completed | G38: 46160 | H38: Dhaneshwar Mahato | I38: Complete
A39: 36 | B39: 139/3 | C39: DA+3 | D39: 46151 | E39: 39.458 | F39: Completed | G39: 46163 | H39: Hoque Construction
A40: 37 | B40: 147/2 | C40: DA-3 | D40: 46160 | E40: 36.044 | F40: Completed | G40: 46164 | H40: Dhaneshwar Mahato | I40: Complete
A41: 38 | B41: 148/0 | C41: DC1+0 | D41: 46161 | E41: 64.254 | F41: Completed | G41: 46167 | H41: Gauri Shankar
...

Sheet Visual chart 1 
A1: Visual Chart
A2: Name of the Line : | E2: TL04 765 kV D/C Ahmedabad - South Olpad Transmission Line | T2: \
A3: Client | E3: Power Grid Corporation of India Limited | AG3: FOUNDATION | AJ3: TOWER ERECTION | AM3: STR P/O | AN3: STR F/S | AO3: OPGW STR
A4: Agency | E4: KEC International Limited | AG4: TOTAL | AH4: COMP. | AI4: BAL. | AJ4: TOTAL | AK4: COMP. | AL4: BAL.
AD5: Date | AE5: ='765KV ASOTL'!G1 -> 46208
A6: PROGRESS AT A GLANCE : | L6: CROSSING PROPOSAL STATUS :
A8: Sl. No. | B8: Activity | E8: UoM | F8: Total Qty | H8: Completed Till Date | J8: Balance | L8: Sl. No. | M8: Type of Crossing | O8: No. of X-ing | P8: Apprd. | Q8: Bal
A10: 1 | B10: Detailed Survey | E10: Kms | F10: 114.516 | H10: ='Survey Anx'!F39 -> 107.971 | J10: =F10-H10 -> 6.545 | L10: 1 | M10: PL X-ing
A11: 2 | B11: Check Survey | E11: Kms | F11: 114.516 | H11: ='Survey Anx'!I39 -> 94.519 | J11: =F11-H11 -> 19.997 | L11: =L10+1 -> 2 | M11: 66 kV
A12: 3 | B12: Soil Investigation | E12: Nos. | F12: 30 | H12: 30 | J12: =F12-H12 -> 0 | L12: =L11+1 -> 3 | M12: 132 kV
A13: 4 | B13: Foundation | E13: Nos. | F13: 293 | H13: =BV20 -> 95 | J13: =F13-H13 -> 198 | L13: =L12+1 -> 4 | M13: 220 kV
A14: 5 | B14: Earthing | E14: Nos. | F14: 293 | H14: 89 | J14: =F14-H14 -> 204 | L14: =L13+1 -> 5 | M14: 400 kV
A15: 6 | B15: Erection | E15: Nos. | F15: 293 | H15: =BW20 -> 46 | J15: =F15-H15 -> 247 | L15: =L14+1 -> 6 | M15: 765 kV
A16: 7 | B16: Tack Welding | E16: Nos. | F16: 293 | H16: 13 | J16: =F16-H16 -> 280 | L16: =L15+1 -> 7
A17: 8 | B17: Stringing (P/O) | E17: Kms | F17: 114.516 | H17: 0 | J17: =F17-H17 -> 114.516 | L17: =L16+1 -> 8
A18: 9 | B18: Stringing (F/S) | E18: Kms | F18: 114.516 | H18: 0 | J18: =F18-H18 -> 114.516 | L18: =L17+1 -> 9
A19: 10 | B19: OPGW Stringing | E19: Kms | F19: 114.516 | H19: 0 | J19: =F19-H19 -> 114.516 | L19: =L18+1 -> 10 | BV19: FDN | BW19: ERC
BV20: 95 | BW20: 46
B21: 1 | D21: 2 | F21: 3 | H21: 4 | J21: 5 | L21: 6 | N21: 7 | P21: 8 | R21: 9 | T21: 10 | V21: 11 | X21: 12 | Z21: 13 | AB21: 14 | AD21: 15
B23: 117/0 | D23: 118/0 | F23: 119/0 | H23: 119/1 | J23: 120/0 | L23: 121/0 | N23: 122/0 | P23: 123/0 | R23: 124/0 | T23: 124/1 | V23: 124/2 | X23: 124/3 | Z23: 124/4 | AB23: 124/5 | AD23: 124/6
N27: Stub N/A | P27: Stub N/A
B28: Stub N/A | C28: 393.72 | D28: Stub N/A | E28: 225.97 | F28: Stub N/A | G28: 193.84 | H28: Stub N/A | I28: 401.38 | J28: Stub N/A | K28: 284.73 | L28: Stub N/A | M28: 238.17 | O28: 164.96 | Q28: 343 | R28: Stub N/A | S28: 453 | T28: Stub N/A | U28: 369 | V28: Stub N/A | W28: 405 | X28: Stub N/A | Y28: 416 | Z28: Stub N/A | AA28: 420 | AB28: Stub N/A | AC28: 364 | AD28: Stub N/A | AE28: 401
B30: 5DB2+3 | D30: 5DD60+25 | F30: 5DD60+25 | H30: 5DB1+9 | J30: CDDN+55 | L30: CDDN+55 | N30: CDDN+55 | P30: CDDN+55 | R30: 5DD45+9 | T30: 5DA+0 | V30: 5DA-3 | X30: 5DB1+0 | Z30: 5DA+0 | AB30: 5DA+0 | AD30: 5DA+0
K31: 765KV ANTL Line | O31: 765KV VNTL Line,
O32: Nilgiri Garden
B33: 16 | D33: 17 | F33: 18 | H33: 19 | J33: 20 | L33: 21 | N33: 22 | P33: 23 | R33: 24 | T33: 25 | V33: 26 | X33: 27 | Z33: 28 | AB33: 29 | AD33: 30
B34: 124/7 | D34: 124/8 | F34: 124/9 | H34: 124/10 | J34: 124/11 | L34: 124/12 | N34: 131/0 | P34: 131/1 | R34: 131/2 | T34: 132/0 | V34: 132/1 | X34: 133/0 | Z34: 133/1 | AB34: 133/2 | AD34: 134/0
BV38: 4 | BW38: =1 -> 1
B39: Stub N/A | C39: 412 | D39: Stub N/A | E39: 405 | F39: Stub N/A | G39: 391 | H39: Stub N/A | I39: 397 | J39: Stub N/A | K39: 390 | L39: Stub N/A | M39: 397.5 | N39: Stub N/A | O39: 591 | P39: Stub N/A | Q39: 534 | R39: Stub N/A | S39: 799 | T39: Stub N/A | U39: 321 | V39: Stub N/A | W39: 449 | Y39: 412.999 | AA39: 390 | AC39: 377.199 | AE39: 374.428
B41: 5DB1+0 | D41: 5DA+0 | F41: 5DA+0 | H41: 5DA+0 | J41: 5DA+0 | L41: 5DA+9 | N41: DD60+35(S) | P41: DD45+9 | R41: DD60+55 | T41: DD60+55 | V41: DB1+18 | X41: DC2+0 | Z41: DA+3 | AB41: DA+0 | AD41: DC2+0
H42: Reserve Forest Approval Pending | R42: Mahi River
AG44: 10 | AH44: 2 | AI44: =AG44-AH44 -> 8 | AJ44: =AG44 -> 10 | AK44: 1 | AL44: =AJ44-AK44 -> 9
B45: 31 | D45: 32 | F45: 33 | H45: 34 | J45: 35 | L45: 36 | N45: 37 | P45: 38 | R45: 39 | T45: 40 | V45: 41 | X45: 42 | Z45: 43 | AB45: 44 | AD45: 45
B46: 135/0 | D46: 136/0 | F46: 137/0 | H46: 138/0 | J46: 138/1 | L46: 138/2 | N46: 138/3 | P46: 139/0 | R46: 139/1 | T46: 139/2 | V46: 139/3 | X46: 139/4 | Z46: 139/5 | AB46: 140/0 | AD46: 140/1
BV50: =15 -> 15 | BW50: 10
C51: 421.994 | E51: 232.608 | G51: 216.641 | I51: 355.998 | K51: 384 | M51: 362 | O51: 307.028 | Q51: 379.002 | S51: 412 | U51: 429 | W51: 408 | Y51: 395 | AA51: 380.686 | AC51: 410.997 | AE51: 413
B53: DB1+6 | D53: DD60+0 | F53: DD45+0 | H53: DD60+0 | J53: DA+0 | L53: DA+0 | N53: DA-3 | P53: DD60+0 | R53: DA+0 | T53: DA+3 | V53: DA+3 | X53: DA+0 | Z53: DA+0 | AB53: DD45+0 | AD53: DA+3
AG55: 10 | AH55: 10 | AI55: =AG55-AH55 -> 0 | AJ55: =AG55 -> 10 | AK55: 10 | AL55: =AJ55-AK55 -> 0 | AM55: 1.273 | AN55: 1.273
B57: 46 | D57: 47 | F57: 48 | H57: 49 | J57: 50 | L57: 51 | N57: 52 | P57: 53 | R57: 54 | T57: 55 | V57: 56 | X57: 57 | Z57: 58 | AB57: 59 | AD57: 60
B58: 140/2 | D58: 141/0 | F58: 141/1 | H58: 141/2 | J58: 142/0 | L58: 143/0 | N58: 143/1 | P58: 143/2 | R58: 144/0 | T58: 145/0 | V58: 145/1 | X58: 145/2 | Z58: 145/3 | AB58: 145/4 | AD58: 145/5
...

Sheet Pile Foundation
A1: ASOTL Pile
A2: Sl. No. | B2: Location No. | C2: Tower Type | D2: Classification | E2: Concreting Volume in M3 | F2: Starting Date | G2: Todays Status | H2: Cumulative Status | I2: Completion Date | J2: Remarks | K2: Gang name | L2: Earthing Status | M2: Earthing Completion Date | N2: Manpower
A3: 1 | B3: 131/1 | C3: DD45+9 | D3: Pile | F3: 46125 | G3: work hampered due to forest dept. approval pending | K3: Chowdhary Const. | N3: 25

Sheet Sheet6
A2: Sr No. | B2: Location | C2: TOT | D2: Start | E2: End
A3: 1 | B3: 117/1 | C3: =VLOOKUP(B3,Sheet4!$A:$B,2,FALSE) -> DA-3 | D3: 46037 | E3: 46043
A4: =A3+1 -> 2 | B4: 119/1 | C4: =VLOOKUP(B4,Sheet4!$A:$B,2,FALSE) -> DA-3 | D4: 46031 | E4: 46037
A5: =A4+1 -> 3 | B5: 120/0 | C5: =VLOOKUP(B5,Sheet4!$A:$B,2,FALSE) -> DD60+3 | D5: 46043 | E5: 46053
A6: =A5+1 -> 4 | B6: 120/4 | C6: =VLOOKUP(B6,Sheet4!$A:$B,2,FALSE) -> DA+0 | D6: 46019 | E6: 46024
A7: =A6+1 -> 5 | B7: 120/7 | C7: =VLOOKUP(B7,Sheet4!$A:$B,2,FALSE) -> DA+3 | D7: 46019 | E7: 46031
A8: =A7+1 -> 6 | B8: 121/2 | C8: =VLOOKUP(B8,Sheet4!$A:$B,2,FALSE) -> DA+9 | D8: 46021 | E8: 46041
A9: =A8+1 -> 7 | B9: 121/3 | C9: =VLOOKUP(B9,Sheet4!$A:$B,2,FALSE) -> DA+0 | D9: 46041 | E9: 46052
A10: =A9+1 -> 8 | B10: 126/1 | C10: =VLOOKUP(B10,Sheet4!$A:$B,2,FALSE) -> DA+3 | D10: 46021 | E10: 46040
A11: =A10+1 -> 9 | B11: 137/0 | C11: =VLOOKUP(B11,Sheet4!$A:$B,2,FALSE) -> DB2+3 | D11: 46026 | E11: 46034
A12: =A11+1 -> 10 | B12: 137/1 | C12: =VLOOKUP(B12,Sheet4!$A:$B,2,FALSE) -> DA+6 | D12: 46044 | E12: 46053
A13: =A12+1 -> 11 | B13: 137/2 | C13: =VLOOKUP(B13,Sheet4!$A:$B,2,FALSE) -> DA-3 | D13: 46019 | E13: 46026
A14: =A13+1 -> 12 | B14: 138/0 | C14: =VLOOKUP(B14,Sheet4!$A:$B,2,FALSE) -> DC2+6 | D14: 46034 | E14: 46044
A15: =A14+1 -> 13 | B15: 141/2 | C15: =VLOOKUP(B15,Sheet4!$A:$B,2,FALSE) -> DA+0 | D15: 46024 | E15: 46026
... A47: =A46+1 -> 45 | B47: 252/5 | C47: =VLOOKUP(B47,Sheet4!$A:$B,2,FALSE) -> DB1+9 | D47: 46024 | E47: 46041

Sheet Sheet4
C3: 117/1 | D3: 117/2 | E3: 118/0 | F3: 119/0 | G3: 119/1 | H3: 119/2 | I3: 119/3 | J3: 120/0 | K3: 120/1 | L3: 120/2 | M3: 120/3 | N3: 120/4 | O3: 120/5 | P3: 120/6 | Q3: 120/7 | R3: 121/0 | S3: 121/1 | T3: 121/2 | U3: 121/3 | V3: 121/4 | W3: 121/5 | X3: 121/6 | Y3: 121/7 | Z3: 121/8 | AA3: 121/9 | AB3: 121/10 | AC3: 121/11 | AD3: 124/0 | AE3: 124/1 | AF3: 124/2 | AG3: 124/3 | AH3: 125/0 | AI3: 125/1 | AJ3: 125/2 | AK3: 126/0 | AL3: 126/1 | AM3: 126/2 | AN3: 126/3 | AO3: 127/0 | AP3: 127/1 | AQ3: 127/2 | AR3: 128/0 | AS3: 129/0 | AT3: 130/0 | AU3: 131/0 | AV3: 131/1 | AW3: 131/2 | AX3: 131/3 | AY3: 131/4 | AZ3: 131/5 | BA3: 132/0 | BB3: 132/1 | BC3: 132/2 | BD3: 132/3 | BE3: 133/0 | BF3: 133/1 | BG3: 133/2 | BH3: 133/3 | BI3: 133/4 | BJ3: 134/0 | BK3: 135/0 | BL3: 136/0 | BM3: 136/1 | BN3: 137/0 | BO3: 137/1 | BP3: 137/2 | BQ3: 138/0 | BR3: 139/0 | BS3: 139/1 | BT3: 139/2 | BU3: 139/3 | BV3: 140/0 | BW3: 141/0 | BX3: 141/1 | BY3: 141/2 | BZ3: 141/3 | CA3: 141/4 | CB3: 141/5 | CC3: 141/6 | CD3: 142/0 | CE3: 143/0 | CF3: 144/0 | CG3: 145/0 | CH3: 145/1 | CI3: 145/2 | CJ3: 145/3 | CK3: 145/4 | CL3: 145/5 | CM3: 145/6 | CN3: 145/7 | CO3: 147/0 | CP3: 148/0 | CQ3: 148/1 | CR3: 148/2 | CS3: 148/3 | CT3: 148/4 | CU3: 148/5 | CV3: 149/0 | CW3: 150/0 | CX3: 150/1 | CY3: 151/0 | CZ3: 151A/0 | DA3: 152/0 | DB3: 153/0 | DC3: 153/1 | DD3: 153/2 | DE3: 153A/0 | DF3: 154/0 | DG3: 155/0 | DH3: 156/0 | DI3: 156/1 | DJ3: 157/0 | DK3: 158/0 | DL3: 159/0 | DM3: 160/0 | DN3: 161/0 | DO3: 162/0 | DP3: 163/0 | DQ3: 163/1 | DR3: 164/0 | DS3: 165/0 | DT3: 165/1 | DU3: 165/2 | DV3: 165/3 | DW3: 165/4 | DX3: 165/5 | DY3: 165/6 | DZ3: 165/7 | EA3: 166/0 | EB3: 167/0 | EC3: 168/0 | ED3: 169/0 | EE3: 170/0 | EF3: 171/0 | EG3: 172/0 | EH3: 172/1 | EI3: 173/0 | EJ3: 174/0 | EK3: 174/1 | EL3: 174/2 | EM3: 174/3 | EN3: 174/4 | EO3: 174/5 | EP3: 174/6 | EQ3: 175/0 | ER3: 175/1 | ES3: 176/0 | ET3: 176/1 | EU3: 176/2 | EV3: 177/0 | EW3: 178/0 | EX3: 178/1 | EY3: 178/2 | EZ3: 178/3 | FA3: 179/0 | FB3: 179/1 | FC3: 179/2 | FD3: 179/3 | FE3: 180/0 | FF3: 180/1 | FG3: 180/2 | FH3: 180/3 | FI3: 180/4 | FJ3: 180/5 | FK3: 180/6 | FL3: 180/7 | FM3: 182/0 | FN3: 183/0 | FO3: 183/1 | FP3: 183/2 | FQ3: 183/3 | FR3: 184/0 | FS3: 185/0 | FT3: 186/0 | FU3: 187/0 | FV3: 188/0 | FW3: 189/0 | FX3: 189/1 | FY3: 190/0 | FZ3: 191/0 | GA3: 191/1 | GB3: 192/0 | GC3: 193/0 | GD3: 194/0 | GE3: 194/1 | GF3: 195/0 | GG3: 196/0 | GH3: 196/1 | GI3: 196/2 | GJ3: 197/0 | GK3: 197/1 | GL3: 197/2 | GM3: 198/0 | GN3: 199/0 | GO3: 199/1 | GP3: 199/2 | GQ3: 200/0 | GR3: 200/1 | GS3: 201/0 | GT3: 202/0 | GU3: 203/0 | GV3: 203/1 | GW3: 204/0 | GX3: 205/0 | GY3: 205/1 | GZ3: 205/2 | HA3: 206/0 | HB3: 206/1 | HC3: 207/0 | HD3: 208/0 | HE3: 209/0 | HF3: 209/1 | HG3: 209/2 | HH3: 210/0 | HI3: 211/0 | HJ3: 211/1 | HK3: 211/2 | HL3: 211/3 | HM3: 211/4 | HN3: 211/5 | HO3: 212/0 | HP3: 213/0 | HQ3: 214/0 | HR3: 214/1 | HS3: 214/2 | HT3: 214/3 | HU3: 214/4 | HV3: 214/5 | HW3: 214/6 | HX3: 214/7 | HY3: 215/0 | HZ3: 216/0 | IA3: 216/1 | IB3: 216/2 | IC3: 216/3 | ID3: 217/0 | IE3: 217/1 | IF3: 217/2 | IG3: 217/3 | IH3: 217/4 | II3: 217/5 | IJ3: 218/0 | IK3: 219/0 | IL3: 219/1 | IM3: 220/0 | IN3: 220/1 | IO3: 221/0 | IP3: 222/0 | IQ3: 223/0 | IR3: 223/1 | IS3: 223/2 | IT3: 223/3 | IU3: 224/0 | IV3: 224/1 | IW3: 224/2 | IX3: 225/0 | IY3: 225/1 | IZ3: 225/2 | JA3: 225/3 | JB3: 225/4 | JC3: 225/5 | JD3: 225/6 | JE3: 225/7 | JF3: 226/0 | JG3: 226/1 | JH3: 226/2 | JI3: 226/3 | JJ3: 227/0 | JK3: 227/1 | JL3: 227/2 | JM3: 228/0 | JN3: 228/1 | JO3: 229/0 | JP3: 229/1 | JQ3: 229A/0 | JR3: 229B/0 | JS3: 230/0 | JT3: 230/1 | JU3: 230A/0 | JV3: 231/0 | JW3: 232/0 | JX3: 232/1 | JY3: 232/2 | JZ3: 232/3 | KA3: 232/4 | KB3: 233/0 | KC3: 234/0 | KD3: 235/0 | KE3: 235/1 | KF3: 235/2 | KG3: 235/3 | KH3: 235/4 | KI3: 236/0 | KJ3: 237/0 | KK3: 238/0 | KL3: 239/0 | KM3: 239/1 | KN3: 240/0 | KO3: 240/1 | KP3: 241/0 | KQ3: 241/1 | KR3: 241/2 | KS3: 241/3 | KT3: 241/4 | KU3: 242/0 | KV3: 243/0 | KW3: 243/1 | KX3: 243/2 | KY3: 243/3 | KZ3: 244/0 | LA3: 244/1 | LB3: 244/2 | LC3: 244/3 | LD3: 244/4 | LE3: 244/5 | LF3: 244/6 | LG3: 245/0 | LH3: 245/1 | LI3: 246/0 | LJ3: 247/0 | LK3: 248/0 | LL3: 248/1 | LM3: 248/2 | LN3: 249/0 | LO3: 249/1 | LP3: 249/2 | LQ3: 249/3 | LR3: 250/0 | LS3: 250/1 | LT3: 250/2 | LU3: 250/3 | LV3: 250A/0 | LW3: 250A/1 | LX3: 250A/2 | LY3: 251/0 | LZ3: 251/1 | MA3: 252/0 | MB3: 252/1 | MC3: 252/2 | MD3: 252/3 | ME3: 252/4 | MF3: 252/5 | MG3: 253/0 | MH3: 254/0 | MI3: 254/1 | MJ3: 255/0 | MK3: 255/1 | ML3: 256/0 | MM3: 256/1 | MN3: 257/0 | MO3: 258/0
C4: DA-3 | D4: DA+6 | E4: DB2+0 | F4: DD60+0 | G4: DA-3 | H4: DA-3 | I4: DA+9 | J4: DD60+3 | K4: DA-3 | L4: DA+0 | M4: DA+6 | N4: DA+0 | O4: DA-3 | P4: DA+0 | Q4: DA+3 | R4: DB2+9 | S4: DB1+25 | T4: DA+9 | U4: DA+0 | V4: DA+0 | W4: DA-3 | X4: DA+0 | Y4: DB1+0 | Z4: DA+0 | AA4: DA+0 | AB4: DA+0 | AC4: DA+9 | AD4: DD45+3 | AE4: DA-3 | AF4: DA+0 | AG4: DA+0 | AH4: DC2+3 | AI4: DA+9 | AJ4: DA+9 | AK4: DD45+3 | AL4: DA+3 | AM4: DA+0 | AN4: DA+0 | AO4: DB2+0 | AP4: DA-3 | AQ4: DB1+9 | AR4: DD60+25 (2MRC) | AS4: DD45+25 (15.87MRC) | AT4: DD45+25 (11.9MRC) | AU4: DD60+9 (7MRC) | AV4: DA+3 | AW4: DA+0 | AX4: DA+3 | AY4: DA-3 | AZ4: DA-3 | BA4: DB2+0 | BB4: DA-3 | BC4: DA-3 | BD4: DA-3 | BE4: DC1+0 | BF4: DA+0 | BG4: DB1+0 | BH4: DB1+0 | BI4: DA+3 | BJ4: DD45+0 | BK4: DD60+3 | BL4: DD60+6 | BM4: DB1+9 | BN4: DB2+3 | BO4: DA+6 | BP4: DA-3 | BQ4: DC2+6 | BR4: DD45+6 | BS4: DA+6 | BT4: DB2+0 | BU4: DB1+0 | BV4: DD60+25 | BW4: DD60+25 | BX4: DA+0 | BY4: DA+0 | BZ4: DA+0 | CA4: DA-3 | CB4: DA-3 | CC4: DA+3 | CD4: DC1+9 | CE4: DD60+18 | CF4: DD60+18 | CG4: DD45+9 | CH4: DA+0 | CI4: DA+0 | CJ4: DA-3 | CK4: DA+0 | CL4: DA+3 | CM4: DA+3 | CN4: DB1+0 | CO4: DD60+25 | CP4: DD60+25 | CQ4: DA+3 | CR4: DA+0 | CS4: DA+6 | CT4: DA+3 | CU4: DB1+3 | CV4: DD60+25 | CW4: DD60+25 | CX4: DB1+0 | CY4: DD60+6 | CZ4: DD60+18 | DA4: DD60+3 | DB4: DD60+3 | DC4: DA+3 | DD4: DA+0 | DE4: DD45+9 | DF4: DD60+9 | DG4: DD60+18 | DH4: DD45+18 | DI4: DB2+9 | DJ4: DD60+41 | DK4: DD60+41 | DL4: DD60+9 (2MRC) | DM4: DC2+0 | DN4: DB1+3 | DO4: DD60+25 | DP4: DD60+30 | DQ4: DB1+6 | DR4: DC2+6 | DS4: DB1+25 | DT4: DA+9 | DU4: DA+6 | DV4: DA+6 | DW4: DA-3 | DX4: DA-3 | DY4: DCT+0 | DZ4: DA+0 | EA4: DD60+0 | EB4: DD60+9 | EC4: DD60+30 | ED4: DD60+25 | EE4: DD60+6 | EF4: DB1+18 | EG4: DD45+9 | EH4: DA+9 | EI4: DC2+18 | EJ4: DD60+9 (2MRC) | EK4: DA+3 | EL4: DA+0 | EM4: DA+0 | EN4: DA+0 | EO4: DA+0 | EP4: DA+3 | EQ4: DC2+6 | ER4: DB1+9 | ES4: DD45+0 | ET4: DA+0 | EU4: DA-3 | EV4: DD60+6 | EW4: DD60+6 | EX4: DA+0 | EY4: DA+0 | EZ4: DA-3 | FA4: DB1+0 | FB4: DA+3 | FC4: DA+3 (A,B 1.5 RC) | FD4: DA+0 | FE4: DD45+0LE (3 Leg)+1.5LE (1 Leg) & (B1MRC & C0.5MRS) | FF4: DA+3 | FG4: DB1+3 | FH4: DA+9 | FI4: DA-3 | FJ4: DA+3 | FK4: DA+0 | FL4: DA+0 | FM4: DD45+0 | FN4: DD60+0 | FO4: DA+0 | FP4: DA+0 | FQ4: DA+3 | FR4: DB1+18 | FS4: DD45+25 | FT4: DC1+18 | FU4: DC1+0 | FV4: DD60+35 | FW4: DD60+35 | FX4: DA+9 | FY4: DD60+9 | FZ4: DD60+9 | GA4: DB1+3 | GB4: DC2+9 | GC4: DD60+30 | GD4: DD60+30 | GE4: DB1+9 | GF4: DC1+18 | GG4: DB2+18 | GH4: DA+9 | GI4: DA+3 | GJ4: DB1+0 | GK4: DA-3 | GL4: DA-3 | GM4: DD60+6 | GN4: DD60+6 | GO4: DA+3 | GP4: DA+6 | GQ4: DC2+0 | GR4: DA+6 | GS4: DC1+9 | GT4: DC1+18 | GU4: DC1+18 | GV4: DB1+0 | GW4: DD60+25 (2MRC) | GX4: DD60+25 (3MRC) | GY4: DB2+9 | GZ4: DA+9 | HA4: DC2+0 | HB4: DB1+6 | HC4: DD60+25 | HD4: DD45+35 | HE4: DD60+9 | HF4: DA+0 | HG4: DA-3 | HH4: DB2+9 (2MRC) | HI4: DB2+9 | HJ4: DA-3 | HK4: DA+0 | HL4: DA+9 | HM4: DA-3 | HN4: DB1+9 | HO4: DD45+30 (2MRC) | HP4: DD60+35 | HQ4: DD60+25 | HR4: DA+6 | HS4: DA-3 | HT4: DA-3 | HU4: DA-3 | HV4: DA+0 | HW4: DA+3 | HX4: DA+3 | HY4: DD60+3 | HZ4: DD60+3 | IA4: DA+9 (2MRC) | IB4: DB1+18 (2MRC) | IC4: DA+9 | ID4: DC2+9 | IE4: DA+3 | IF4: DA+0 | IG4: DA+9 | IH4: DA+9 | II4: DA+0 | IJ4: DD60+3 | IK4: DD45+3 | IL4: DA+9 | IM4: DD45+0 | IN4: DA+6 | IO4: DD60+18 | IP4: DD60+25 | IQ4: DC1+6 | IR4: DA+0 | IS4: DA+0 | IT4: DA-3 | IU4: DC1+0 | IV4: DA+3 | IW4: DB1+6 | IX4: DB2+0 | IY4: DA+9 | IZ4: DA-3 | JA4: DA-3 | JB4: DA+3 | JC4: DA+0 | JD4: DA+0 | JE4: DA+6 | JF4: DB2+3 | JG4: DA+6 | JH4: DA+0 | JI4: DA+0 | JJ4: DD45+0 | JK4: DA+6 | JL4: DA+3 | JM4: DD45+0 | JN4: DA+0 | JO4: DD45+0 | JP4: DA+9 | JQ4: DB1+25 | JR4: DB2+25 | JS4: DC1+6 | JT4: DA+9 | JU4: DD45+0 | JV4: DB1+0 | JW4: DB1+0 | JX4: DA+0 | JY4: DA+0 | JZ4: DA+0 | KA4: DA+3 | KB4: DC1+0 | KC4: DD60+18 | KD4: DD60+9 (2MRC) | KE4: DA+9 | KF4: DA+0 | KG4: DA+0 | KH4: DA+3 | KI4: DB2+18 | KJ4: DB1+25 (2MRC) | KK4: DC1+25 | KL4: DD45+0 | KM4: DA+0 | KN4: DB2+0 | KO4: DA+3 | KP4: DD60+0 | KQ4: DA+0 | KR4: DA+0 | KS4: DA+0 | KT4: DA+3 | KU4: DD60+3 | KV4: DD60+3 | KW4: DA+0 | KX4: DA+0 | KY4: DA+0 | KZ4: DD45+0 | LA4: DA+0 | LB4: DA+0 | LC4: DA+3 | LD4: DA+3 | LE4: DA+0 | LF4: DA+3 | LG4: DD45+0 | LH4: DA+0 | LI4: DD45+9 | LJ4: DD60+35 (2MRC) | LK4: DD60+35 (2MRC) | LL4: DB1+9 | LM4: DA+6 | LN4: DD60+3 | LO4: DA+9 | LP4: DA+3 | LQ4: DA+3 | LR4: DD45+3 | LS4: DA+9 (1MRC) | LT4: DA+0 | LU4: DA+9 | LV4: DB1+3 (3MRC) | LW4: DA+6 | LX4: DA+0 | LY4: DD45+0 | LZ4: DA+6 (1MRC) | MA4: DB2+0 | MB4: DA+0 | MC4: DA+3 | MD4: DA+6 | ME4: DA+0 | MF4: DB1+9 | MG4: DD45+35 (2MRC) | MH4: DD45+35 (2MRC) | MI4: DB1+9 | MJ4: DD60+0 | MK4: DA+0 | ML4: DD60+0 | MM4: DA+9 | MN4: DC1+9 | MO4: DD60+0 (1.5MRC)
A9: Loc No | B9: Tower Type
I10: 118/0
A11: 117/1 | B11: DA-3 | H11: =A11 -> 117/1
A12: 117/2 | B12: DA+6 | H12: =A12 -> 117/2
A13: 118/0 | B13: DB2+0 | H13: =A13 -> 118/0
A14: 119/0 | B14: DD60+0 | H14: =A14 -> 119/0
A15: 119/1 | B15: DA-3 | H15: =A15 -> 119/1
A16: 119/2 | B16: DA-3 | H16: =A16 -> 119/2
A17: 119/3 | B17: DA+9 | H17: =A17 -> 119/3
A18: 120/0 | B18: DD60+3 | H18: =A18 -> 120/0
A19: 120/1 | B19: DA-3 | H19: =A19 -> 120/1
A20: 120/2 | B20: DA+0 | H20: =A20 -> 120/2
A21: 120/3 | B21: DA+6 | H21: =A21 -> 120/3
A22: 120/4 | B22: DA+0 | I22: 174/1
A23: 120/5 | B23: DA-3 | I23: 174/2
A24: 120/6 | B24: DA+0 | I24: 174/3
A25: 120/7 | B25: DA+3 | I25: 174/4
A26: 121/0 | B26: DB2+9 | I26: 174/5
A27: 121/1 | B27: DB1+25 | I27: 174/6
A28: 121/10 | B28: DA+0 | I28: 178/2
A29: 121/11 | B29: DA+9 | H29: =A29 -> 121/11
A30: 121/2 | B30: DA+9 | I30: 175/0
A31: 121/3 | B31: DA+0 | I31: 175/1
A32: 121/4 | B32: DA+0 | I32: 176/0
A33: 121/5 | B33: DA-3 | I33: 176/1
A34: 121/6 | B34: DA+0 | I34: 176/2
A35: 121/7 | B35: DB1+0 | I35: 177/0
A36: 121/8 | B36: DA+0 | I36: 178/0
A37: 121/9 | B37: DA+0 | I37: 178/1
A38: 124/0 | B38: DD45+3 | I38: 178/3
A39: 124/1 | B39: DA-3 | H39: =A39 -> 124/1
A40: 124/2 | B40: DA+0 | H40: =A40 -> 124/2
A41: 124/3 | B41: DA+0 | H41: =A41 -> 124/3
A42: 125/0 | B42: DC2+3 | I42: 180/1
A43: 125/1 | B43: DA+9 | I43: 180/2
A44: 125/2 | B44: DA+9 | I44: 180/3
A45: 126/0 | B45: DD45+3 | I45: 180/4
A46: 126/1 | B46: DA+3 | I46: 180/5
...

Sheet Sheet7
B3: kfvnk
B4: 117/1
B5: 117/2
B6: 118/0
B7: 119/0
B8: 119/1
B9: 119/2
B10: 119/3
B11: 120/0
B12: 120/1
B13: 120/2
B14: 120/3
... B380: 178/2

Sheet Stringing Compiled
D1: Number of TSE
A3: S.no | B3: Sec | C3: From AP | D3: To AP | E3: Span (M) | F3: Method | G3: Section Readiness | H3: Insulator Hoisting | I3: P/O Starting Date | J3: P/O Completion Date | K3: P/O | L3: F/S Starting Date | M3: F/S/ Completion Date | N3: Jumpering | O3: Spacering | P3: Clipping | Q3: Length | R3: Status | S3: Gang Name | T3: Gang Strength | U3: Number of Fitters | V3: Hindrance | W3: Remarks
D6: Total | E6: =SUM(E4:E5)/1000 -> 0

Sheet String
A1: ASOTL Stringing
A2: Sr. No. | B2: Section | C2: length | D2: Manual/TSE | E2: Engaged Date | F2: Paying Out | H2: Final Sag | J2: P/O Completed | K2: F/S Completed | L2: Stringing Status As on Today | M2: Cumulative Status | N2: Sub Contractor name | O2: Manpower | P2: Hindarnce Days | Q2: Remarks
F3: Start Date | G3: End Date | H3: Start Date | I3: End Date

Sheet Crossing
A1: TL-04 , 765 kV D/C Ahmedabad - South Olpad Transmission Line
A2: Sl No | B2: AP NO | C2: Towe Type | D2: AP No | E2: Tower Type | F2: Type of Crossings | G2: Span Length | H2: LINE OWNER | I2: Line Name | J2: Nos. | K2: Work Portion | L2: Status | M2: Submitted to Client for Review | N2: Proposal Submitted (Y/N) | O2: Inspection Status (Y/N) | P2: Remarks
A3: 1 | B3: 118/0 | C3: 5DD60+25 | D3: 119/0 | E3: DD60+25 | F3: Powerline crossing | G3: 225.97 | H3: GETCO | I3: 400 kV D/C Twin Chorniya/Pancham To Kosamba TL | J3: 1 | K3: Anand | L3: Submitted | M3: 46129 | N3: Y | P3: Approval Not Received from PGCIL
A4: 2 | B4: 120/0 | C4: CDDN+55 | D4: 121/0 | E4: CDDN+25 | F4: Powerline crossing | G4: 284.73 | H4: PGCIL | I4: 765 kV D/C Ahmedabad-Navsari | J4: 1 | K4: Anand | L4: Submitted | M4: 46129 | N4: Y | P4: Approval Not Received from PGCIL
A5: 3 | B5: 122/0 | C5: CDDN+55 | D5: 123/0 | E5: CDDN+25 | F5: Powerline crossing | G5: 164.96 | H5: PGCIL | I5: 765 kV D/C Vataman-Navsari | J5: 1 | K5: Anand | L5: Submitted | M5: 46129 | N5: Y | P5: Approval Not Received from PGCIL
A6: 4 | B6: 145/1 | C6: DB1+9 | D6: 145/2 | E6: DA+3 | F6: Powerline crossing | G6: 448 | H6: GETCO | I6: 66 kV D/C Gavasad-Sterling/Sarod | J6: 1 | K6: Bharuch | L6: Submitted | M6: 45859 | N6: Y | O6: Y | P6: Approval Not Received from PGCIL
A7: 5 | B7: 147/0 | C7: DD60+0 | D7: 147/1 | E7: DA-3 | F7: GAS PIPELINE | G7: 323 | H7: ONGC | I7: GGS Jambusar-GGS Dabka | J7: 1 | K7: Bharuch | L7: Submitted | M7: 45887 | N7: Y | O7: Y | P7: Approval Not Received from PGCIL
A8: 6 | B8: 148A/0 | C8: DC2+0 | D8: 148B/0 | E8: DC1+0 | F8: GAS PIPELINE | G8: 259.34 | H8: GAIL | I8: Dabka-Gandhar | J8: 1 | K8: Bharuch | L8: Submitted | M8: 45915 | N8: Y | O8: Y | P8: Approval Not Received from PGCIL
A9: 7 | B9: 148A/0 | C9: DC2+0 | D9: 148B/0 | E9: DC1+0 | F9: GAS PIPELINE | G9: 259.34 | H9: GSPL | I9: Uchchhad-Jambusar | J9: 1 | K9: Bharuch | L9: Submitted | M9: 45915 | N9: Y | O9: Y | P9: Approval Not Received from PGCIL
A10: 8 | B10: 149/0 | C10: DD60+6 | D10: 150/0 | E10: DD60+6 | F10: Railway Crossing | G10: 275.39 | H10: IR WR | I10: BG U/C electrified single Vishamitri-Jambusar | J10: 1 | K10: Bharuch | L10: Submitted | M10: 45930 | N10: Y | O10: Y | P10: Approval Not Received from PGCIL
A11: 9 | B11: 150/5 | C11: DA+3 | D11: 151/0 | E11: DD60+3 | F11: Powerline crossing | G11: 375.54 | H11: GETCO | I11: 66 kV (H FRAME) Masar Road to Jambusar | J11: 1 | K11: Bharuch | L11: Submitted | M11: 45911 | N11: Y | O11: Y | P11: Approval received on 25-04-2026
A12: 10 | B12: 151/0 | C12: DD60+3 | D12: 152/0 | E12: DD60+6 | F12: NH | G12: 297.52 | H12: NHAI | I12: Jambusar-Bharuch Section (NH 64) | J12: 1 | K12: Bharuch | L12: Submitted | M12: 45909 | N12: Y | O12: Y | P12: Approval Not Received from PGCIL
A13: 11 | B13: 151/0 | C13: DD60+3 | D13: 152/0 | E13: DD60+6 | F13: Railway Crossing | G13: 297.52 | H13: IR WR | I13: BG U/C electrified single Bharuch-Jambusar | J13: 1 | K13: Bharuch | L13: Submitted | M13: 45930 | N13: Y | O13: Y | P13: Approval Not Received from PGCIL
A14: 12 | B14: 153/1 | C14: DA+0 | D14: 154/0 | E14: DC2+0 | F14: GAS PIPELINE | G14: 234.98 | H14: Reliance | I14: Dahej-Vadodara | J14: 1 | K14: Bharuch | L14: Submitted | M14: 45750 | N14: Y | O14: Y | P14: Approval Not Received from PGCIL
A15: 13 | B15: 154/0 | C15: DC2+0 | D15: 154/1 | E15: DA+0 | F15: GAS PIPELINE | G15: 375.72 | H15: ONGC | I15: GNAQ-Magnad | J15: 1 | K15: Bharuch | L15: Submitted | M15: 45751 | N15: Y | O15: Y | P15: Approval Not Received from PGCIL
A16: 14 | B16: 157A/0 | C16: DC2+0 | D16: 157B/0 | E16: DD45+9 | F16: GAS PIPELINE | G16: 378.53 | H16: ONGC | I16: G763 Station to EPS253 Station | J16: 1 | K16: Bharuch | L16: Submitted | M16: 45913 | N16: Y | O16: Y | P16: Approval Not Received from PGCIL
A17: 15 | B17: 157A/0 | C17: DC2+0 | D17: 157B/0 | E17: DD45+9 | F17: Powerline crossing | G17: 378.53 | H17: GETCO | I17: U/C 66 k/V D/C Amod-Muler | J17: 1 | K17: Bharuch | L17: Submitted | M17: 45902 | N17: Y | O17: Y | P17: Approval Not Received from PGCIL
... A32: 30 | B32: 170/2 | C32: DA+0 | D32: 170/3 | E32: DA+0 | F32: GAS PIPELINE | G32: 378 | H32: GAIL | I32: Dahej-Vemar | J32: 2 | K32: Bharuch | L32: Submitted | M32: 45756 | N32: Y | O32: Y | P32: Approval received on 25.04.2026
