Workbook
Name \0: #REF!
Name \A: #REF!
Name \A: #REF!
Name \A: #REF!
Name \A_1: "#REF!"
Name \aa: #REF!
Name \aa: #REF!
Name \aa: #REF!
Name \B: #REF!
Name \B: #REF!
Name \B: #REF!
Name \C: #REF!
Name \C: #REF!
Name \C: #REF!
Name \c1: #REF!
Name \D: #REF!
Name \DFC: #REF!
Name \DFC: #REF!
Name \DFC: #REF!
Name \E: #REF!
Name \E: #REF!
Name \E: #REF!
Name \g: #REF!
Name \H: #REF!
Name \H: #REF!
Name \H: #REF!
Name \i: #REF!
Name \jmns: #REF!
Name \jmns: #REF!
Name \jmns: #REF!
Name \L: #REF!
Name \L: #REF!
Name \L: #REF!
Name \LK: #REF!
Name \LK: #REF!
Name \LK: #REF!
Name \LKM: #REF!
Name \LKM: #REF!
Name \LKM: #REF!
Name \M: #REF!
Name \M: #REF!
Name \M: #REF!
Name \N: #REF!
Name \N: #REF!
Name \N: #REF!
Name \P: #REF!
Name \P: #REF!
Name \P: #REF!
Name \Q: #REF!
Name \Q: #REF!
Name \Q: #REF!
Name \R: #REF!
Name \R: #REF!
Name \R: #REF!
Name \S: #REF!
Name \S: #REF!
Name \S: #REF!
Name \Sv: #REF!
Name \Sv: #REF!
Name \Sv: #REF!

Sheet Completion Plan
B1: Construction Plan-TA-602
B3: PARTICULARS | D3: Unit | E3: Final | F3: Till 30 June’26 | G3: Bal | H3: June | K3: Jun’26 | L3: July'26 | M3: Aug'26 | N3: Sept'26 | O3: Oct'26 | P3: Nov'26 | Q3: Dec'26 | R3: Jan'27 | S3: Feb'27 | T3: Mar'27 | U3: Apri'27 | V3: Q2-27 | W3: Q3-27 | X3: Q4-27 | Y3: Q1-28 | Z3: Q2-28 | AA3: Remarks
E4: Qty | G4: 1st July | H4: Plan | I4: Act | J4: WIP
B5: TOWER Fdn | C5: Fdn | D5: Nos | E5: 494 | F5: 169 | G5: =E5-F5 -> 325 | H5: 30 | I5: 15 | J5: 0 | L5: 20 | M5: 40 | N5: 40 | O5: 40 | P5: 40 | Q5: 33 | R5: 33 | S5: 30 | T5: 34 | AA5: =SUM(K5:Z5)+I5+F5 -> 494
C6: Gangs | D6: Nos | H6: 6 | I6: 6 | J6: - | L6: 6 | M6: 8 | N6: 8 | O6: 8 | P6: 8 | Q6: 8 | R6: 8 | S6: 8 | T6: 8
B7: TOWER ERECTION | C7: Location | D7: Nos | E7: 494 | F7: 73 | G7: =E7-F7 -> 421 | H7: 40 | I7: 8 | J7: 3 | L7: 25 | M7: 35 | N7: 40 | O7: 40 | P7: 40 | Q7: 40 | R7: 40 | S7: 35 | T7: 35 | U7: 35 | V7: 48 | AA7: =SUM(K7:Z7)+I7+F7 -> 494
C8: Volume | D8: MT
C9: Gang | D9: No | F9: 2 | H9: 8 | I9: 4 | J9: 4 | L9: 8 | M9: 8 | N9: 10 | O9: 10 | P9: 10 | Q9: 10 | R9: 10 | S9: 10 | T9: 8 | U9: 8 | V9: 10
B10: STRINGING | C10: Stringing - P/O | D10: KMs | E10: 186 | F10: - | G10: - | H10: - | I10: - | J10: - | K10: - | L10: - | M10: - | N10: - | P10: 5 | Q10: 12 | R10: 18 | S10: 18 | T10: 18 | U10: 20 | V10: 20 | W10: 20 | X10: 20 | Y10: 18 | Z10: 17 | AA10: =SUM(O10:Z10) -> 186
C11: Stringing F/S | D11: Kms | E11: 186 | F11: - | G11: - | H11: - | I11: - | J11: - | K11: - | L11: - | M11: - | N11: - | P11: 5 | Q11: 12 | R11: 18 | S11: 18 | T11: 18 | U11: 20 | V11: 20 | W11: 20 | X11: 20 | Y11: 18 | Z11: 17 | AA11: =SUM(O11:Z11) -> 186
C12: Gang | D12: No | F12: - | G12: - | H12: - | I12: - | J12: - | K12: - | L12: - | M12: - | N12: - | P12: 2 | Q12: 4 | R12: 5 | S12: 5 | T12: 5 | U12: 5 | V12: 5 | W12: 5 | X12: 5 | Y12: 5 | Z12: 5
B13: OPGW | C13: Stringing | D13: KMs | E13: 186 | F13: - | G13: - | H13: - | I13: - | J13: - | K13: - | L13: - | M13: - | N13: - | P13: 5 | Q13: 12 | R13: 18 | S13: 18 | T13: 18 | U13: 20 | V13: 20 | W13: 20 | X13: 20 | Y13: 18 | Z13: 17 | AA13: =SUM(O13:Z13) -> 186
C14: Gang | D14: No | F14: - | G14: - | H14: - | I14: - | J14: - | K14: - | L14: - | M14: - | N14: - | P14: 2 | Q14: 4 | R14: 5 | S14: 5 | T14: 5 | U14: 5 | V14: 5 | W14: 5 | X14: 5 | Y14: 5 | Z14: 5

Sheet Project Details
A1: Project Code | B1: Project Name | C1: Client Name | D1: NOA Start Date | E1: LOA End Date | F1: Planning Engineer | G1: PCH | H1: Regional Manager | I1: Project Manager | J1: Section Incharge | K1: Employee Name | L1: Designation
A2: TA-602 | B2: Name of Line: Package TL-06 for ±800kV HVDC Bipole Line (Hexa Lapwing) between KPS2 (HVDC) & Nagpur (HVDC) (with dedicated metallic Return) -Part- 6 Transmission Line | C2: Powergrid West Central Transmission Ltd. | D2: 45790 | E2: 47069 | F2: Mr. Rishi Shukla | G2: Mr Arun Felbin R | H2: Mr. Vijay Govindrao Kute | I2: Mr. Minarul Alam | J2: Mr. Ajaya Kumar | K2: Mr. Vishnu R Nair | L2: Sr. Engineer
K3: Mr. Tapash Das | L3: Sr. Surveyour
K4: Mr. Rakesh Debnath | L4: Survey Officer
K5: Mr. Monnesh C.K. | L5: Syrvey Assist.
K6: Mr. Deep kumar Das | L6: Sr. Supervisor
K7: Mr. Soumen Khan | L7: Survey Officer
K8: Mr. Khokan Mandal | L8: Assit. Surveyour
J9: Mr. Tanmay Nayak | K9: Mr. Madhu Saran Prashad | L9: Supervisor
K10: Jaynta Ghosh | L10: Supervisor
K11: Uttam das | L11: Supervisor
K12: Md. Wahiddujaman Biswash | L12: Officer Project
K13: Mijanur Rahaman | L13: Officer Project
K14: Saddam Hossain | L14: Officer Project
K15: Sanjit Singh | L15: Erection Supervisor
K16: Hulash mahato | L16: Erection Supervisor
K17: Bhim mahato | L17: Erection Supervisor
K18: M Ganesan | L18: Assistant Officer - project

Sheet PGCIL - KEC
A1: TA-602 KEC INTERNATIONAL LIMITED | M1: =TODAY() -> 46204
A2: ='Project Details'!C2 -> Powergrid West Central Transmission Ltd.
A3: ='Project Details'!B2 -> Name of Line: Package TL-06 for ±800kV HVDC Bipole Line (Hexa Lapwing) between KPS2 (HVDC) & Nagpur (HVDC) (with dedicated metallic Return) -Part- 6 Transmission Line
A4: NOA No.: CC/T/W-TW/DOM/A06/24/04774/NOA-2/25-105721/01&02 Dt:13-05-2025
A5: Sr No. | B5: Activity | C5: Estimated Quantity | D5: Cumm. Progress up to till last Month (June'26) | E5: Target as per L2 Schedule Cummulative (upto July'26) | F5: L3 Plan for the month (July26 ) | G5: Today's Progress | H5: Progress in this month | I5: Cumm. Progress till date | J5: Cumm. Balance | K5: WIP | L5: No of Gangs | M5: Remark
A6: 1 | B6: Route Alignment (Km) | C6: ='800kV HVDC TA-602'!C8 -> 185.149 | D6: =C6 -> 185.149 | E6: =C6 -> 185.149 | F6: =C6-E6 -> 0 | I6: =D6+H6 -> 185.149 | J6: =C6-I6 -> 0
A7: 2 | B7: Detailed Survey (Km) | C7: 184.986 | D7: ='800kV HVDC TA-602'!K9 -> 178.3635 | E7: =C7 -> 184.986 | F7: =C7-D7 -> 6.6225 | I7: =D7 -> 178.3635 | J7: =C7-I7 -> 6.6225
A8: 3 | B8: Profiling (Km) | C8: =C7 -> 184.986 | D8: =C8 -> 184.986 | E8: =D8 -> 184.986 | F8: =C8-E8 -> 0 | I8: =D8+H8 -> 184.986 | J8: =C8-I8 -> 0
A9: 4 | B9: Check Survey (Km) | C9: =C8 -> 184.986 | D9: 178.364 | E9: =C9 -> 184.986 | F9: =C9-D9 -> 6.622 | I9: =D9+H9 -> 178.364 | J9: =C9-I9 -> 6.622
A10: 5 | B10: Soil Investigation (Nos.) | C10: 31 | D10: 17 | I10: =D10+H10 -> 17 | J10: =C10-I10 -> 14
A11: 6 | B11: Excavation | C11: 480 | D11: 169 | E11: 182 | F11: 25 | I11: =D11+H11 -> 169 | J11: =C11-I11 -> 311 | K11: 2
A12: 7 | B12: Foundation (Nos.) | C12: =C11 -> 480 | D12: 167 | E12: 182 | F12: =F11 -> 25 | I12: =D12+H12 -> 167 | J12: =C12-I12 -> 313 | K12: 3 | L12: 2 | M12: ROW"67/3"(10/06/2026)
A13: 8 | B13: Earthing (Nos.) | C13: =C12 -> 480 | D13: 107 | E13: =E12 -> 182 | F13: =F12 -> 25 | I13: =D13+H13 -> 107 | J13: =C13-I13 -> 373
A14: 9 | B14: Tower Erection (Nos) | C14: =C13 -> 480 | D14: 78 | E14: 120 | F14: 30 | I14: =D14+H14 -> 78 | J14: =C14-I14 -> 402 | K14: 4 | L14: 4
A15: 10 | B15: Tack Welding | C15: =C14 -> 480 | D15: 0 | E15: =E14 -> 120 | F15: =F14 -> 30 | H15: 0 | I15: =D15+H15 -> 0 | J15: =C15-I15 -> 480 | K15: 0 | L15: 0
A16: 11 | B16: Stringing (Km) | C16: =$C$9 -> 184.986 | D16: 0 | E16: 16 | F16: 0 | H16: 0 | I16: =H16+D16 -> 0 | J16: =C16-I16 -> 184.986 | K16: 0 | L16: 0
A17: a) | B17: Paying Out | C17: =$C$9 -> 184.986 | D17: 0 | E17: 16 | F17: 0 | H17: 0 | I17: =H17+D17 -> 0 | J17: =C17-I17 -> 184.986
A18: b) | B18: Final Sag | C18: =$C$9 -> 184.986 | D18: 0 | E18: 16 | F18: 0 | H18: 0 | I18: =H18+D18 -> 0 | J18: =C18-I18 -> 184.986
A19: 12 | B19: OPGW (Km) | C19: =$C$9 -> 184.986 | D19: 0 | E19: 0 | F19: 0 | I19: =D19+H19 -> 0 | J19: =C19-I19 -> 184.986

Sheet PPT-Erection Part
A1: LOA DT -13-May-2026 Completion Schedule 12-Nov-2028 Project Value-613.31Cr
A2: Sl No | B2: PARTICULARS | D2: Unit | E2: Total | F2: Comp Till 31-May’26 | G2: Balance Till 01-Jun’26 | H2: June’26 | K2: July’26 | L2: Aug’26 | M2: Support / Issue
E3: Qty | H3: Plan | I3: Actual | J3: WIP | K3: Plan | L3: Plan
A4: 1 | B4: Survey | C4: Details | D4: KMs | E4: 185.149 | F4: 166.531 | G4: 18.455 | H4: 18.455 | J4: 8.123 | K4: - | L4: -
C5: Check | D5: Kms | E5: 185.149 | F5: 136.139 | G5: 48.847 | H5: =G5 -> 48.847 | J5: =F4-F5 -> 30.392
A6: 2 | B6: FOUNDATION | C6: Location | D6: Nos | E6: 480 | F6: 154 | G6: =E6-F6 -> 326 | H6: 30 | I6: 4 | J6: 5 | K6: 20 | L6: 40
C7: Gang | D7: No | H7: 6 | I7: 5 | J7: 5 | K7: 5 | L7: 6
C8: Earthing | D8: No | E8: 480 | F8: 96 | G8: =E8-F8 -> 384 | H8: 40 | I8: 4 | J8: - | K8: 20 | L8: 30
A9: 3 | B9: TOWER ERECTION | C9: Location | D9: Nos | E9: 480 | F9: 52 | G9: =E9-F9 -> 428 | H9: 35 | I9: 4 | J9: 5 | K9: 25 | L9: 35
C10: Volume | D10: MT | E10: 13208 | F10: 1321 | G10: =E10-F10 -> 11887 | H10: =H9*24 -> 840 | I10: =I9*26 -> 104 | J10: =J9*24 -> 120 | K10: =K9*25 -> 625 | L10: =L9*24 -> 840
C11: Gang | D11: No | H11: 5 | I11: 5 | J11: 5 | K11: 5 | L11: 5
C12: Tack Welding | D12: No | E12: 480 | G12: =E12-F12 -> 480
A13: 4 | B13: STRINGING | C13: Stringing - P/O | D13: KMs | E13: 185.1 | G13: =E13-F13 -> 185.1
C14: Stringing Final Sag | D14: Kms | E14: =E13 -> 185.1 | G14: 185.1
C15: TSE - Section | D15: No | E15: =E14-E16 -> 166.083 | G15: =E15-F15 -> 166.083
C16: Manual - Section | D16: No | E16: 19.017 | G16: =E16 -> 19.017
C17: Gang | D17: No
A18: 5 | B18: OPGW | C18: Stringing | D18: KMs | E18: 185.1 | G18: =E18-F18 -> 185.1
B19: STRINGING | C19: Gang | D19: No
A20: 6 | B20: Revenue | D20: CR. | E20: 100.47 | F20: 10 | G20: 10

Sheet CMD-1
A1: Activity | B1: UoM | C1: As Per LOA (Qty) | D1: Revised | E1: As per L2 | F1: Completed | G1: Balance | H1: Front Availability | J1: Gangs Available | L1: Plan | O1: Plan | P1: Plan | Q1: Remarks
D2: (Qty) | E2: (June'26) | F2: (as on 30.06.26) | G2: (Up to 01.06.26) | L2: 46204 | O2: 46204 | P2: 46235
L3: Plan | N3: Act
A4: Check Survey | B4: Km | C4: 186 | D4: 185 | E4: 185 | F4: 178.36 | G4: =D4-F4 -> 6.64 | H4: - | J4: - | L4: 48.85 | N4: 42.22 | O4: 6.622 | P4: - | Q4: Narmada River Approval WIP(6.622 Kms)
A5: Foundation | B5: No | C5: 494 | D5: 480 | E5: 177 | F5: 169 | G5: =D5-F5 -> 311 | H5: 1 | J5: 3 | L5: 35 | N5: 15 | O5: 20 | P5: 30
A6: Erection | B6: No | C6: 494 | D6: 480 | E6: 112 | F6: 77 | G6: =D6-F6 -> 403 | H6: 7 | J6: 4 | L6: 40 | N6: 25 | O6: 25 | P6: 35
A7: Stringing | B7: Km | C7: 186 | D7: 185 | E7: 15 | F7: - | G7: 185 | H7: - | J7: - | L7: - | N7: - | O7: - | P7: - | Q7: -
A8: OPGW Stringing | B8: Km | C8: 186 | D8: 185 | E8: - | F8: - | G8: - | H8: - | J8: - | L8: - | N8: - | O8: - | P8: - | Q8: L2 Schedule from Oct’26
A9: Supply Status:
A10: Item | B10: UoM | C10: As Per LOA (Qty) | D10: Revised | E10: As per L2 | F10: Actual Supplied | G10: Balance | H10: Plan for June'26 | I10: Plan for July'26 | K10: Plan for Aug'26 | M10: Remarks
D11: (Qty) | E11: (July'26)
A12: Stub | B12: Nos | C12: 494 | D12: 480 | E12: 410 | F12: 282 | G12: =D12-F12 -> 198 | H12: =117-40 -> 77
A13: Tower | B13: Nos | C13: 494 | D13: 480 | E13: 330 | F13: 193 | G13: =D13-F13 -> 287 | H13: 45 | I13: 48
A14: Conductor | B14: Km | C14: 3030 | D14: 3030 | E14: 2121 | F14: 1209.512 | G14: =D14-F14 -> 1820.488 | H14: 70 | K14: 500
A15: Earthwire | B15: Km | C15: 192 | D15: 192 | E15: 135 | F15: 77 | G15: 115 | K15: 60
A16: 160KN CLR | B16: Nos | C16: 1202 | D16: 1202 | E16: 842 | F16: - | G16: 1202 | H16: - | I16: - | K16: - | M16: Insulator being delayed due to delay in Design/Type Testing Stage Cat-II
A17: 210KN CLR | B17: Nos | C17: 1438 | D17: 1438 | E17: 1006 | F17: - | G17: 1438 | H17: - | I17: - | K17: - | M17: Insulator being delayed due to delay in Design/Type Testing Stage Cat-II
A18: 410 KN CLR | B18: Nos | C18: 10142 | D18: 10142 | E18: 7100 | F18: - | G18: =D18 -> 10142 | M18: Insulator being delayed due to delay in Design/Type Testing Stage Cat-II
A19: HW Fittings | B19: % | C19: 100 | D19: 100 | E19: 70 | F19: - | G19: 100
A20: Front Availability Status
A21: Activity | B21: UoM | C21: Mar’26 | F21: April’26 | I21: May’26
C22: Front | D22: Completed | E22: Gang | F22: Front | G22: Completed | H22: Gang | I22: Front | J22: Completed | K22: Gang
A23: Foundation | B23: No | C23: 10 | D23: 5 | E23: 3 | F23: 25 | G23: 22 | H23: 2 | I23: 25 | J23: 22 | K23: 4
A24: Tower Erection | B24: No | C24: 15 | D24: 12 | E24: 2 | F24: 12 | G24: 8 | H24: 2 | I24: 20 | J24: 18 | K24: 4
A25: Stringing | B25: Km | C25: - | D25: - | E25: - | F25: - | G25: - | H25: - | I25: - | J25: - | K25: -

Sheet CMD-2
A1: No. of month from NOA | C1: UoM | D1: Qty. | E1: Upto June-26 | F1: July-26 | G1: 46235 | H1: 46266 | I1: Oct-26 | J1: 46327 | K1: Dec-26 | L1: Jan-27 | M1: Feb-27 | N1: Mar-27 | O1: Apr-28 | P1: May-28 | Q1: June-27
A2: Activity
A3: Foundation | B3: As per L2 | C3: Nos | D3: 494 | E3: 177 | F3: 5 | G3: 5 | H3: 5 | I3: 15 | J3: 20 | K3: 25 | L3: 25 | M3: 25 | N3: 25 | O3: 25 | P3: 25 | Q3: 10
B4: Completion Plan | C4: Nos | D4: 494 | E4: 184 | F4: 25 | G4: 25 | H4: 40 | I4: 40 | J4: 40 | K4: 40 | L4: 36 | M4: 36 | N4: =D4-466 -> 28
B5: Front Required from POWERGRID | C5: Nos | D5: 494 | E5: 184 | F5: 22 | G5: 25 | H5: 40 | I5: 40 | J5: 40 | K5: 40 | L5: 36 | M5: 36 | N5: =D5-466 -> 28
B6: Gangs Planned | C6: Nos | F6: 6 | G6: 8 | H6: 8 | I6: 8 | J6: 8 | K6: 10 | L6: 10 | M6: 10 | N6: 10
B7: Stubs Supply as per L2 | C7: Nos | D7: 515 | E7: 290 | F7: 120 | I7: 105
B8: Stub Supply Actual | C8: Nos | D8: 515 | E8: 282
A10: Erection | B10: As per L2 | C10: Nos | D10: 494 | E10: 77 | F10: 8 | G10: 8 | H10: 8 | I10: 15 | J10: 20 | K10: 25 | L10: 25 | M10: 25 | N10: 25 | O10: 25 | P10: 25 | Q10: 10
B11: Completion Plan | C11: Nos | D11: 494 | E11: 77 | F11: 25 | G11: 35 | H11: 36 | I11: 40 | J11: 40 | K11: 40 | L11: 40 | M11: 35 | N11: 35 | O11: 35 | P11: 30 | Q11: 18
B12: Front Required from POWERGRID | C12: Nos | D12: 494 | E12: 77 | F12: 25 | G12: 35 | H12: 36 | I12: 40 | J12: 40 | K12: 40 | L12: 40 | M12: 35 | N12: 35 | O12: 35 | P12: 30 | Q12: 18
B13: Gangs Planned | C13: Nos | F13: 6 | G13: 8 | H13: 8 | I13: 8 | J13: 8 | K13: 10 | L13: 10 | M13: 10 | N13: 10 | O13: 10 | P13: 10 | Q13: 8
B14: Tower Supply as per L2 | C14: Nos | D14: 515 | E14: 230 | F14: 100 | J14: 100 | N14: 85
B15: Tower Supply Actual | C15: Nos | D15: 515 | E15: 192
A17: Stringing | B17: As per L2 | C17: Kms | D17: 186.3 | E17: 15 | F17: 1 | G17: 1 | H17: 1 | I17: 6 | J17: 8 | K17: 8 | L17: 10 | M17: 10 | N17: 10 | O17: 10 | P17: 10 | Q17: 10
B18: Completion Plan | C18: Kms | D18: 186.3 | L18: 5 | M18: 12 | N18: 18 | O18: 18 | P18: 18 | Q18: 5
B19: Front Required from POWERGRID | C19: Kms | D19: 186.3 | L19: 5 | M19: 12 | N19: 18 | O19: 18 | P19: 18 | Q19: 5
B20: Gangs Planned | C20: TSE (Nos) | D20: 186.3 | L20: 5 | M20: 12 | N20: 18 | O20: 18 | P20: 18 | Q20: 5
C21: Manual (Nos)
B22: Conductor Supply as per L2 | C22: Nos | D22: 3030 | E22: 1212 | F22: 909 | K22: 606
B23: Conductor Supply Actual | C23: Nos | D23: 3030 | E23: 1209.519
B24: Insulator Supply as per L2 | C24: Nos | D24: 12782 | E24: 5113 | F24: 3835 | K24: 2556
B25: Insulator Supply Actual | C25: Nos | D25: 12782 | E25: - | F25: - | G25: - | H25: - | I25: - | J25: - | K25: - | L25: - | M25: - | N25: - | O25: - | P25: - | Q25: -
B26: Hardware Supply as per L2 | C26: % | D26: 1 | E26: 0.4 | F26: 0.3 | I26: 0.3 | K26: 0.2
B27: Hardware Supply Actual | C27: % | D27: 1 | E27: - | F27: - | G27: - | H27: - | I27: - | J27: - | K27: - | L27: - | M27: - | N27: - | O27: - | P27: - | Q27: -

Sheet PPT _Statutory
A1: Statuary Clearances :
A2: Sl No | B2: Name Statuary Clearances | C2: Total | D2: Submitted | E2: Approved | F2: Balance to Submit | G2: Balance to Approve | H2: Status of submitted Proposals
A3: 1 | B3: Railway X-ing | C3: 2 | D3: 0 | E3: 0 | F3: =C3-D3 -> 2 | G3: =C3-E3 -> 2 | H3: • AP50–AP51: Foundation drawing awaited (D60+6, D60+9) • 111A–111B: Railway crossing – details awaited
A4: 2 | B4: Powerline X-ing | C4: 12 | D4: 12 | E4: 0 | F4: =C4-D4 -> 0 | G4: =C4-E4 -> 12 | H4: 11 No's Location Site Visit done.
A5: 3 | B5: NH X-ing | C5: 4 | D5: 4 | E5: 0 | F5: =C5-D5 -> 0 | G5: =C5-F5 -> 4 | H5: Two No's Site Visit Done( AP 118 to AP119 & AP133 to AP34).
A6: 4 | B6: River X-ing | C6: 1 | D6: 1 | E6: 0 | F6: =C6-E6 -> 1 | G6: 0 | H6: Awaitiing/Dependency @ Approval of Detail Survey & Soil Investigation Testing Underprocess.
A7: 5 | B7: Civil Aviation Proposal | C7: 1 | D7: 0 | E7: 0 | F7: =C7-E7 -> 1 | G7: 1 | H7: Under Process
A8: 6 | B8: Defence Aviation | C8: 1 | D8: 0 | E8: 0 | F8: =C8-E8 -> 1 | G8: 1 | H8: Under Process
A9: 7 | B9: PTCC Proposal | C9: 1 | D9: 0 | E9: 0 | F9: =C9-E9 -> 1 | G9: 1
A10: 8 | B10: Pipe line X-ings | C10: 1 | D10: 1 | E10: 0 | F10: =C10-D10 -> 0 | G10: 1

Sheet PPT Supply
A1: Supply & BOI Details
A2: SL No. | B2: Type of Tower | C2: UOM | D2: BOQ Qty | E2: Final line Qty (Amended) | F2: Received as on dated | G2: Balance to be supply | H2: Remark
A3: 1 | B3: Stubs | C3: Nos | D3: 494 | E3: U/P | F3: 282 | G3: =D3-F3 -> 212
A4: 2 | B4: Towers | C4: Nos | D4: 494 | E4: U/P | F4: 193 | G4: =D4-F4 -> 301
A5: 3 | B5: Conductor | C5: Km | D5: 3030.64 | E5: U/P | F5: 1209.519 | G5: =D5-F5 -> 1821.121
A6: 4 | B6: Insulators | C6: Nos | D6: 12782 | E6: U/P | F6: 0 | G6: =D6-F6 -> 12782
A7: 5 | B7: Earthwire | C7: Km | D7: 192.165 | E7: U/P | F7: 77 | G7: =D7-F7 -> 115.165
A8: 6 | B8: HW for Cond & EW | C8: % | D8: 100 | E8: U/P | F8: 0 | G8: =D8-F8 -> 100 | H8: 25% Material under dispatch
A9: 7 | B9: OPGW Cable | C9: Km | D9: 199 | E9: U/P | F9: 0 | G9: =D9-F9 -> 199
A10: 8 | B10: OPGW Accessories | C10: % | D10: 100 | E10: U/P | F10: 0 | G10: =D10-F10 -> 100

Sheet Supply Status
A1: Supply & BOI Details
A2: SL No. | B2: Type of Tower | C2: UOM | D2: BOQ Qty | E2: DSL | F2: PRS Released | G2: Balance to Release | H2: Remark's
A3: 1 | B3: Stubs | C3: Nos | D3: 494 | E3: 410 | F3: 351 | G3: =E3-F3 -> 59 | H3: DSL UPTO-July
A4: 2 | B4: Towers | C4: Nos | D4: 494 | E4: 330 | F4: 286 | G4: =E4-F4 -> 44 | H4: DSL UPTO-July
A5: 3 | B5: Conductor | C5: Km | D5: 3030.64 | E5: 2121 | F5: 2200 | G5: =E5-F5 -> -79 | H5: DSL UPTO-July
A6: 4 | B6: Insulators | C6: Nos | D6: 12782 | E6: 8948 | F6: 8948 | G6: =E6-F6 -> 0 | H6: DSL UPTO-July
A7: 5 | B7: Earthwire | C7: Km | D7: 192.165 | E7: 135 | F7: 188 | G7: =E7-F7 -> -53 | H7: DSL UPTO-July
A8: 6 | B8: HW for Cond & EW | C8: % | D8: 100 | E8: 0.25 | F8: 0.7 | G8: =E8-F8 -> -0.45 | H8: DSL UPTO-July
A9: 7 | B9: OPGW Cable | C9: Km | D9: 199 | E9: 100 | F9: 0 | G9: =E9-F9 -> 100 | H9: DSL UPTO-July
A10: 8 | B10: OPGW Accessories | C10: % | D10: 100 | E10: 0.5 | F10: 0.7 | G10: =E10-F10 -> -0.2 | H10: DSL UPTO-June

Sheet 800kV HVDC TA-602
B1: Project Code | C1: ='Project Details'!A2 -> TA-602 | D1: Date | E1: =TODAY() -> 46204 | H1: President-T&D | I1: Mr. Ganesh Srinivasan
B2: Project Name | C2: ='Project Details'!B2 -> Name of Line: Package TL-06 for ±800kV HVDC Bipole Line (Hexa Lapwing) between KPS2 (HVDC) & Nagpur (HVDC) (with dedicated metallic Return) -Part- 6 Transmission Line | F2: NOA Start Date | G2: ='Project Details'!D2 -> 45790 | H2: PCH | I2: Mr. Arun Felbin
B3: Client Name | C3: ='Project Details'!C2 -> Powergrid West Central Transmission Ltd. | F3: LOA End Date | G3: ='Project Details'!E2 -> 47069 | H3: Regional Manager | I3: ='Project Details'!H2 -> Mr. Vijay Govindrao Kute
F4: Planning Engineer | G4: ='Project Details'!F2 -> Mr. Rishi Shukla | H4: Project Manger | I4: ='Project Details'!I2 -> Mr. Minarul Alam
A5: \
A6: Check Survey
A7: Activity | B7: Unit | C7: Final Est. Qty | D7: L2 till Last Month | E7: Submitted till Last Month | F7: Approved till Last Month | G7: Balance to Submit | H7: Balance to Approve | I7: L2 Submission Plan for Current Month | J7: Progress For Month | K7: Approved till Current Month | L7: Remarks
A8: Rout Alignment | B8: km | C8: 185.149 | D8: =C8 -> 185.149 | E8: =D8 -> 185.149 | F8: =E8 -> 185.149 | G8: =C8-E8 -> 0 | H8: =C8-F8 -> 0 | I8: - | K8: =F8 -> 185.149
A9: Detailed Survey | B9: km | C9: 184.986 | D9: =C9 -> 184.986 | E9: =D9 -> 184.986 | F9: 166.531 | G9: =D9-E9 -> 0 | H9: =C9-F9 -> 18.455 | I9: - | J9: ='Survey details 11-06-2026'!F5 -> 11.8325 | K9: =J9+F9 -> 178.3635
A10: Check Survey | B10: km | C10: =C9 -> 184.986 | D10: =C10 -> 184.986 | E10: 166.531 | F10: 136.139 | G10: =D10-E10 -> 18.455 | H10: =C10-F10 -> 48.847 | I10: - | K10: =F10 -> 136.139
A12: Progress Status
A13: Activity | B13: Final Estimated Quantity | C13: Cumulative L2 till Last Month (May'26) | D13: Cumulative Progress till Last Month(May'26) | E13: L2 for present Month | F13: Plan for the Month | G13: Today's Progress | H13: Progress till Date for the Month | I13: L2 till Current Month | J13: Completed till Date | K13: Balance Work | L13: Under Progress | M13: Gangs at Present | N13: Remarks
A14: Soil Investigation | B14: 31 | D14: 16 | E14: 0 | F14: 0 | I14: =C14+E14 -> 0 | J14: 17 | K14: =B14-J14 -> 14 | L14: 1
A15: Foundation | B15: 480 | C15: 167 | D15: 154 | E15: 10 | F15: ='PGCIL - KEC'!F12 -> 25 | G15: ='PGCIL - KEC'!G12 -> 0 | H15: ='PGCIL - KEC'!H12 -> 0 | I15: =C15+E15 -> 177 | J15: ='PGCIL - KEC'!I12 -> 167 | K15: =B15-J15 -> 313 | L15: ='PGCIL - KEC'!K12 -> 3 | M15: ='PGCIL - KEC'!L12 -> 2
A16: Earthing | B16: =B15 -> 480 | C16: =C15 -> 167 | D16: ='PGCIL - KEC'!D13 -> 107 | E16: =E15 -> 10 | F16: ='PGCIL - KEC'!F13 -> 25 | G16: ='PGCIL - KEC'!G13 -> 0 | H16: ='PGCIL - KEC'!H13 -> 0 | I16: =C16+E16 -> 177 | J16: ='PGCIL - KEC'!I13 -> 107 | K16: =B16-J16 -> 373
A17: Tower Erection | B17: =B16 -> 480 | C17: 102 | D17: ='PGCIL - KEC'!D14 -> 78 | E17: 10 | F17: ='PGCIL - KEC'!F14 -> 30 | G17: 2 | H17: ='PGCIL - KEC'!H14 -> 0 | I17: =C17+E17 -> 112 | J17: ='PGCIL - KEC'!I14 -> 78 | K17: =B17-J17 -> 402 | L17: ='PGCIL - KEC'!K14 -> 4 | M17: ='PGCIL - KEC'!L14 -> 4
A18: Tack welding | B18: =B17 -> 480 | C18: =C17 -> 102 | D18: ='PGCIL - KEC'!D15 -> 0 | E18: =E17 -> 10 | F18: ='PGCIL - KEC'!F15 -> 30 | G18: 0 | H18: ='PGCIL - KEC'!H15 -> 0 | I18: =C18+E18 -> 112 | J18: ='PGCIL - KEC'!I15 -> 0 | K18: =B18-J18 -> 480 | L18: 2 | M18: 2
A19: Stringing(Km) | B19: =C9 -> 184.986 | C19: 10 | D19: ='PGCIL - KEC'!D16 -> 0 | E19: 5 | F19: 0 | H19: ='PGCIL - KEC'!H16 -> 0 | I19: =C19+E19 -> 15 | J19: ='PGCIL - KEC'!I16 -> 0 | K19: =B19-J19 -> 184.986 | L19: ='PGCIL - KEC'!K16 -> 0 | M19: ='PGCIL - KEC'!L16 -> 0

Sheet DPR Sheet
B2: contract No. & Date :
B3: DAILY PROGRESS REPORT : SUBMISSION STATUS AS ON | G3: ='PGCIL - KEC'!M1 -> 46204
B4: Name of the Project: | D4: ±800kV HVDC Bipole Line (Hexa Lapwing) between KPS2 (HVDC) & Nagpur (HVDC) (with dedicated metallic Return) -Part- 6
B5: Contract No. & Date : | D5: CC/T/W/-TW/DOM/A06/24/04774/CA-1/25-105721,01&02 Dt.13.05.25
B7: ROUTE ALIGNMENT PROGRESS SUMMARY
B8: TOTAL QTY (Tentative) | C8: COMPLETED UP TO PREV MONTH | D8: COMP. IN CURRENT MONTH | E8: CUMULATIVE | F8: BAL.QTY
B9: ='PGCIL - KEC'!C7 -> 184.986 | C9: ='PGCIL - KEC'!D6 -> 185.149 | D9: ='PGCIL - KEC'!F6 -> 0 | E9: ='PGCIL - KEC'!I6 -> 185.149 | F9: ='PGCIL - KEC'!J6 -> 0
B10: SOIL INVESTIGATION PROGRESS SUMMARY
B11: TOTAL QTY (Tentative) | C11: COMPLETED UP TO PREV MONTH | D11: COMP. IN CURRENT MONTH | E11: CUMULATIVE | F11: BAL.QTY
B12: ='PGCIL - KEC'!C10 -> 31 | C12: ='PGCIL - KEC'!D10 -> 17 | D12: ='PGCIL - KEC'!H10 -> 0 | E12: ='PGCIL - KEC'!I10 -> 17 | F12: ='PGCIL - KEC'!J10 -> 14
B13: DETAILED SURVEY PROGRESS SUMMARY
B14: TOTAL QTY (Tentative) | C14: COMPLETED UP TO PREV MONTH | D14: COMP. IN CURRENT MONTH | E14: CUMULATIVE | F14: BAL.QTY
B15: ='PGCIL - KEC'!C7 -> 184.986 | C15: ='PGCIL - KEC'!D7 -> 178.3635 | D15: ='PGCIL - KEC'!H7 -> 0 | E15: ='PGCIL - KEC'!I7 -> 178.3635 | F15: ='PGCIL - KEC'!J7 -> 6.6225
B16: CHECK SURVEY PROGRESS SUMMARY
B17: TOTAL QTY (Tentative) | C17: COMPLETED UP TO PREV MONTH | D17: COMP. IN CURRENT MONTH | E17: CUMULATIVE | F17: BAL.QTY
B18: ='PGCIL - KEC'!C9 -> 184.986 | C18: ='PGCIL - KEC'!D9 -> 178.364 | D18: ='PGCIL - KEC'!H9 -> 0 | E18: ='PGCIL - KEC'!I9 -> 178.364 | F18: ='PGCIL - KEC'!J9 -> 6.622
B19: FOUNDATION PROGRESS SUMMARY
B20: TOTAL QTY (Tentative) | C20: COMPLETED UP TO PREV MONTH | D20: COMP. IN CURRENT MONTH | E20: CUMULATIVE | F20: BAL.QTY
B21: ='PGCIL - KEC'!C12 -> 480 | C21: ='PGCIL - KEC'!D12 -> 167 | D21: ='PGCIL - KEC'!H12 -> 0 | E21: ='PGCIL - KEC'!I12 -> 167 | F21: ='PGCIL - KEC'!J12 -> 313
B22: EARTHING PROGRESS SUMMARY
B23: TOTAL QTY | C23: COMPLETED UP TO PREV MONTH | D23: COMP. IN CURRENT MONTH | E23: CUMULATIVE | F23: BAL.QTY
B24: ='PGCIL - KEC'!C13 -> 480 | C24: ='PGCIL - KEC'!D13 -> 107 | D24: ='PGCIL - KEC'!H13 -> 0 | E24: ='PGCIL - KEC'!I13 -> 107 | F24: ='PGCIL - KEC'!J13 -> 373
B25: TOWER ERECTION PROGRESS SUMMARY
B26: TOTAL QTY | C26: COMPLETED UP TO PREV MONTH | D26: COMP. IN CURRENT MONTH | E26: CUMULATIVE | F26: BAL.QTY
B27: ='PGCIL - KEC'!C14 -> 480 | C27: ='PGCIL - KEC'!D14 -> 78 | D27: ='PGCIL - KEC'!H14 -> 0 | E27: ='PGCIL - KEC'!I14 -> 78 | F27: ='PGCIL - KEC'!J14 -> 402
B28: STRINGING PROGRESS SUMMARY
B29: TOTAL QTY | C29: COMPLETED UP TO PREV MONTH | D29: COMP. IN CURRENT MONTH | E29: CUMULATIVE | F29: BAL.QTY(KM)
B30: ='PGCIL - KEC'!C16 -> 184.986 | C30: ='PGCIL - KEC'!D16 -> 0 | D30: ='PGCIL - KEC'!H16 -> 0 | E30: =C30+D30 -> 0 | F30: =B30-E30 -> 184.986
B31: OPGW STRINGING PROGRESS SUMMARY
B32: TOTAL QTY | C32: COMPLETED UP TO PREV MONTH | D32: COMP. IN CURRENT MONTH | E32: CUMULATIVE | F32: BAL.QTY
B33: ='PGCIL - KEC'!C18 -> 184.986 | C33: 0 | D33: 0 | E33: 0 | F33: =B33-E33 -> 184.986

Sheet Survey details 11-06-2026
A1: Survey Status | L1: Date: 10-06-2026 | M1: 46092
A2: Project Name & Code | D2: TA-602
A3: Sl No | B3: Section | C3: Kms | D3: Detailed Survey | I3: Check Survey
D4: Completed | E4: Submitted | F4: Approved | G4: Remarks | H4: Surveyor | I4: Completed | J4: Submitted | K4: Approved | L4: Remarks | M4: Surveyor
A5: 1 | B5: AP0 to AP16 | C5: 11.8325 | D5: 11.8325 | E5: 11.8325 | F5: 11.8325 | G5: Approved | I5: 11.8325 | J5: 11.8325 | K5: 11.833 | L5: Approved
A6: 3 | B6: AP16 to AP29 | C6: 7.454 | D6: 7.454 | E6: =D6 -> 7.454 | F6: =E6 -> 7.454 | G6: Approved | H6: Mr. Hemanta/Mr. Tapas Das | I6: 30.3921 | J6: =I6 -> 30.3921 | K6: =J6 -> 30.3921 | L6: Approved
A7: 4 | B7: AP29 to AP35 | C7: 4.653 | D7: 4.6525 | E7: =D7 -> 4.6525 | F7: =E7 -> 4.6525 | G7: Approved | H7: Mr. Hemanta/Mr. Tapas Das
A8: 5 | B8: AP35 to AP 40 | C8: 6.557 | D8: 6.557 | E8: =D8 -> 6.557 | F8: =E8 -> 6.557 | G8: Approved | H8: Mr. Hemanta/Mr. Tapas Das
A9: 6 | B9: AP 40 to AP 51 | C9: 11.729 | D9: 11.7286 | E9: =D9 -> 11.7286 | F9: =E9 -> 11.7286 | G9: Approved | H9: Mr. Hemanta/Mr. Tapas Das | P9: =D6+D8+#REF!+#REF! -> #REF!
A10: 10 | E10: =D10 -> 0 | F10: =E10 -> 0
A11: 11 | B11: AP0 to AP23 | E11: =D11 -> 0 | F11: =E11 -> 0 | G11: Route Diversion due to Newly under constrction house (Alternate Route Submitted) | H11: Hemanta Malik/Tapas Das/Rakesh Debnath | I11: =D11 -> 0 | K11: =J11 -> 0
A12: 12 | B12: AP33 to AP38A | E12: =D12 -> 0 | F12: =E12 -> 0 | H12: Hemanta Malik/Tapas Das/Rakesh Debnath | I12: =D12 -> 0 | K12: =J12 -> 0
A13: 13 | B13: AP38 to AP51 | E13: =D13 -> 0 | F13: =E13 -> 0 | H13: Hemanta Malik/Tapas Das/Rakesh Debnath | I13: =D13 -> 0 | K13: =J13 -> 0
A14: 7 | B14: AP51 to AP62 | C14: 8.344 | D14: 8.345 | E14: =D14 -> 8.345 | F14: =E14 -> 8.345 | G14: Approved | H14: Hemanta Malik/Tapas Das/Rakesh Debnath | I14: =F14 -> 8.345 | J14: =I14 -> 8.345 | K14: =J14 -> 8.345 | L14: Approved | M14: Hemanta Malik/Tapas Das/Rakesh Debnath
A15: 8 | B15: AP62 to AP 64 | C15: 3.615 | D15: 3.615 | E15: =D15 -> 3.615 | F15: =E15 -> 3.615 | G15: Approved | H15: Hemanta Malik/Tapas Das/Rakesh Debnath | I15: =F15 -> 3.615 | J15: =I15 -> 3.615 | K15: =J15 -> 3.615 | L15: Approved | M15: Hemanta Malik/Tapas Das/Rakesh Debnath
A16: 9 | B16: AP64 to AP71 | C16: 9.709 | D16: 9.71 | E16: =D16 -> 9.71 | F16: =E16 -> 9.71 | G16: Approved | H16: Hemanta Malik/Tapas Das/Rakesh Debnath | I16: =F16 -> 9.71 | J16: =I16 -> 9.71 | K16: =J16 -> 9.71 | L16: Approved | M16: Hemanta Malik/Tapas Das/Rakesh Debnath
A17: 13 | B17: AP71 to AP75 | C17: 3.714 | D17: 3.787 | E17: =D17 -> 3.787 | F17: =E17 -> 3.787 | G17: Approved | H17: Hemanta Malik/Tapas Das/Rakesh Debnath | I17: =F17 -> 3.787 | J17: =I17 -> 3.787 | K17: =J17 -> 3.787 | L17: Approved | M17: Hemanta Malik/Tapas Das/Rakesh Debnath
A18: 14 | B18: AP75 to AP76 | C18: 1.238 | D18: 1.178 | E18: =D18 -> 1.178 | F18: =E18 -> 1.178 | G18: Approved | H18: Hemanta Malik/Tapas Das/Rakesh Debnath | I18: =F18 -> 1.178 | J18: =I18 -> 1.178 | K18: =J18 -> 1.178 | L18: Approved | M18: Hemanta Malik/Tapas Das/Rakesh Debnath
A19: 15 | B19: AP76 to AP83 | C19: 7.242 | D19: 7.241 | E19: =D19 -> 7.241 | F19: =E19 -> 7.241 | G19: Approved | H19: Hemanta Malik/Tapas Das/Rakesh Debnath | I19: =F19 -> 7.241 | J19: =I19 -> 7.241 | K19: =J19 -> 7.241 | L19: Approved | M19: Hemanta Malik/Tapas Das/Rakesh Debnath
A20: 16 | B20: AP83 to AP92 | C20: 22.602 | D20: 22.602 | E20: =D20 -> 22.602 | F20: =E20 -> 22.602 | G20: Approved | H20: Hemanta Malik/Tapas Das/Rakesh Debnath | I20: =F20 -> 22.602 | J20: =I20 -> 22.602 | K20: =J20 -> 22.602 | L20: Approved | M20: Hemanta Malik/Tapas Das/Rakesh Debnath
A21: 17 | B21: AP92 to AP94 | C21: 4.351 | D21: 4.351 | E21: =D21 -> 4.351 | F21: =E21 -> 4.351 | G21: Approved | H21: Hemanta Malik/Tapas Das/Rakesh Debnath | I21: =F21 -> 4.351 | J21: =I21 -> 4.351 | K21: =J21 -> 4.351 | L21: Approved | M21: Hemanta Malik/Tapas Das/Rakesh Debnath
A22: 18 | B22: AP94 to AP99 | C22: 6.622 | D22: 6.622 | E22: =D22 -> 6.622 | G22: Narmada River Crossing | H22: Hemanta Malik/Tapas Das | I22: 0 | J22: 0 | K22: =J22 -> 0
A23: 19 | B23: AP 99 to AP 106 | C23: 11.413 | D23: 11.413 | E23: =D23 -> 11.413 | F23: =E23 -> 11.413 | G23: Approved | H23: Hemanta Malik/Tapas Das/Rakesh Debnath | I23: =D23 -> 11.413 | J23: =I23 -> 11.413 | K23: =J23 -> 11.413 | L23: Approved | M23: Hemanta Malik/Tapas Das/Rakesh Debnath
A24: 20 | B24: AP106 to AP110 | C24: 10.77 | D24: 10.77 | E24: =D24 -> 10.77 | F24: =E24 -> 10.77 | G24: Approved | H24: Hemanta Malik/Tapas Das/Rakesh Debnath | I24: =D24 -> 10.77 | J24: =I24 -> 10.77 | K24: =J24 -> 10.77 | L24: Approved | M24: Hemanta Malik/Tapas Das/Rakesh Debnath
A25: 21 | B25: AP110 to AP118 | C25: 10.198 | D25: 10.198 | E25: =D25 -> 10.198 | F25: =E25 -> 10.198 | G25: Approved | H25: Hemanta Malik/Tapas Das/Rakesh Debnath | I25: =D25 -> 10.198 | J25: =I25 -> 10.198 | K25: =J25 -> 10.198 | L25: Approved | M25: Hemanta Malik/Tapas Das/Rakesh Debnath
A26: 22 | B26: AP118 to AP 123 | C26: 6.502 | D26: 6.502349 | E26: =D26 -> 6.502349 | F26: =E26 -> 6.502349 | G26: Approved | H26: Hemanta Malik/Tapas Das/Rakesh Debnath | I26: =D26 -> 6.502349 | J26: =I26 -> 6.502349 | K26: =J26 -> 6.502349 | L26: Approved | M26: Hemanta Malik/Tapas Das/Rakesh Debnath
A27: 23 | B27: AP123 to AP126 | C27: 6.516 | D27: 6.516 | E27: =D27 -> 6.516 | F27: =E27 -> 6.516 | G27: Approved | H27: Hemanta Malik/Tapas Das/Rakesh Debnath | I27: =D27 -> 6.516 | J27: =I27 -> 6.516 | K27: =J27 -> 6.516 | L27: Approved | M27: Hemanta Malik/Tapas Das/Rakesh Debnath
A28: 24 | B28: AP126 to Ap127 | C28: 4.34 | D28: 4.34 | E28: =D28 -> 4.34 | F28: =E28 -> 4.34 | G28: Approved | H28: Hemanta Malik/Rakesh Debnath | I28: =D28 -> 4.34 | J28: =I28 -> 4.34 | K28: =J28 -> 4.34 | L28: Approved | M28: Hemanta Malik/Rakesh Debnath
A29: 25 | B29: AP127 to AP129A | C29: 4.836 | D29: 4.836 | E29: =D29 -> 4.836 | F29: =E29 -> 4.836 | G29: Approved | H29: Hemanta Malik/Tapas Das/Rakesh Debnath | I29: =D29 -> 4.836 | J29: =I29 -> 4.836 | K29: =J29 -> 4.836 | L29: Approved | M29: Hemanta Malik/Tapas Das/Rakesh Debnath
A30: 26 | B30: AP129A to AP130 | C30: 4.41 | D30: 4.41 | E30: =D30 -> 4.41 | F30: =E30 -> 4.41 | G30: Approved | H30: Hemanta Malik/Tapas Das/Rakesh Debnath | I30: =D30 -> 4.41 | J30: =I30 -> 4.41 | K30: =J30 -> 4.41 | L30: Approved | M30: Hemanta Malik/Tapas Das/Rakesh Debnath
A31: 27 | B31: AP130 to AP134 | C31: 4.122 | D31: 4.122 | E31: =D31 -> 4.122 | F31: =E31 -> 4.122 | G31: Approved | H31: Hemanta Malik/Tapas Das/Rakesh Debnath | I31: =D31 -> 4.122 | J31: =I31 -> 4.122 | K31: =J31 -> 4.122 | L31: Approved | M31: Hemanta Malik/Tapas Das/Rakesh Debnath
A32: 28 | B32: AP134 to AP141 | C32: 12.203 | D32: 12.203 | E32: =D32 -> 12.203 | F32: =E32 -> 12.203 | G32: Approved | H32: Hemanta Malik/Tapas Das/Rakesh Debnath | I32: =D32 -> 12.203 | J32: =I32 -> 12.203 | K32: =J32 -> 12.203 | L32: Approved | M32: Hemanta Malik/Tapas Das/Rakesh Debnath
C33: =SUM(C5:C32) -> 184.9725 | D33: =SUM(D5:D32) -> 184.98595 | E33: =SUM(E5:E32) -> 184.98595 | F33: =SUM(F5:F32) -> 178.36395 | I33: =SUM(I5:I32) -> 178.36395 | J33: =SUM(J5:J32) -> 178.36395 | K33: =SUM(K5:K32) -> 178.36445

Sheet FDN
A1: ±800kV HVDC Bipole Line (Hexa Lapwing) between KPS2 (HVDC) & Nagpur (HVDC) (Part- 6) Foundation
A2: Sl. No. | B2: Location No. | C2: Tower Type | D2: Classification | E2: Concreting Volume in M3 | F2: Starting Date | G2: Todays Status | H2: Pit A | I2: Pit B | J2: Pit C | K2: Pit D | L2: Cummulative Status | M2: Completion Date | N2: Remarks | O2: Gang name | P2: Earthing Status | Q2: Earthing Completion Date
A3: 1 | B3: 125/2 | C3: A+3 | D3: DFR | F3: 45902 | H3: RCC Complete | I3: RCC Complete | J3: RCC Complete | K3: RCC Complete | L3: Completed | M3: 45915 | O3: Balaji Enterprises | R3: 11
A4: 2 | B4: 125/3 | C4: A+6 | D4: DFR | F4: 45909 | H4: RCC Complete | I4: RCC Complete | J4: RCC Complete | K4: RCC Complete | L4: Completed | M4: 45933 | O4: Balaji Enterprises | R4: 11
A5: 3 | B5: 123/1 | C5: A+0 | D5: WFR | F5: 45931 | H5: RCC Complete | I5: RCC Complete | J5: RCC Complete | K5: RCC Complete | L5: Completed | M5: 45937 | O5: R.K . Enterprises | P5: C | Q5: 45940 | R5: 11
A6: 4 | B6: 124/1 | C6: A+6 | D6: WET Paddy | F6: 45921 | H6: RCC Complete | I6: RCC Complete | J6: RCC Complete | K6: RCC Complete | L6: Completed | M6: 45938 | O6: Balaji Enterprises | P6: C | Q6: 45982 | R6: 11
A7: 5 | B7: 124/2 | C7: A+6 | D7: WFR | F7: 45907 | H7: RCC Complete | I7: RCC Complete | J7: RCC Complete | K7: RCC Complete | L7: Completed | M7: 45945 | O7: Jai Shri Ram Enterprises | P7: C | Q7: 45950 | R7: 11
A8: 6 | B8: 121/7 | C8: A+0 | D8: WFR | F8: 45924 | H8: RCC Complete | I8: RCC Complete | J8: RCC Complete | K8: RCC Complete | L8: Completed | M8: 45946 | O8: Pawan enterprises | P8: C | Q8: 45968 | R8: 11
A9: 7 | B9: 121/2 | C9: A+6 | D9: DFR | F9: 45938 | H9: RCC Complete | I9: RCC Complete | J9: RCC Complete | K9: RCC Complete | L9: Completed | M9: 45949 | O9: Balaji Enterprises | P9: C | Q9: 45950 | R9: 11
A10: 8 | B10: 123/3 | C10: A+9 | D10: DFR | F10: 45938 | H10: RCC Complete | I10: RCC Complete | J10: RCC Complete | K10: RCC Complete | L10: Completed | M10: 45949 | O10: R.K . Enterprises | P10: C | Q10: 45952 | R10: 11
A11: 9 | B11: 122/2 | C11: A+0 | D11: WFR | F11: 45940 | H11: RCC Complete | I11: RCC Complete | J11: RCC Complete | K11: RCC Complete | L11: Completed | M11: 45955 | O11: Jai Shri Ram Enterprises | P11: C | Q11: 45963 | R11: 11
A12: 10 | B12: 126/5 | C12: A+3 | D12: DFR | F12: 45941 | H12: RCC Complete | I12: RCC Complete | J12: RCC Complete | K12: RCC Complete | L12: Completed | M12: 45958 | O12: Rajiya Infra. | P12: C | Q12: 45964 | R12: 11
A13: 11 | B13: 116/1 | C13: A+3 | D13: DFR | F13: 45942 | H13: RCC Complete | I13: RCC Complete | J13: RCC Complete | K13: RCC Complete | L13: Completed | M13: 45962 | O13: B.L Construction | P13: C | Q13: 45965 | R13: 11
A14: 12 | B14: 126/4 | C14: A+0 | D14: DFR | F14: 45942 | H14: RCC Complete | I14: RCC Complete | J14: RCC Complete | K14: RCC Complete | L14: Completed | M14: 45962 | O14: Rajiya Infra. | P14: C | Q14: 45968 | R14: 11
A15: 13 | B15: 116/2 | C15: A+3 | D15: DFR | F15: 45942 | H15: RCC Complete | I15: RCC Complete | J15: RCC Complete | K15: RCC Complete | L15: Completed | M15: 45964 | O15: B.L Construction | P15: C | Q15: 45969 | R15: 11
A16: 14 | B16: 124/3 | C16: A+9 | D16: WFR | F16: 45910 | H16: RCC Complete | I16: RCC Complete | J16: RCC Complete | K16: RCC Complete | L16: Completed | M16: 45965 | O16: Jai Shri Ram Enterprises | R16: 11
A17: 15 | B17: 123/4 | C17: A+0 | D17: WET | F17: 45930 | H17: RCC Complete | I17: RCC Complete | J17: RCC Complete | K17: RCC Complete | L17: Completed | M17: 45967 | O17: Shri Balaji Construction | P17: C | Q17: 45969 | R17: 11
A18: 16 | B18: 126/3 | C18: A+3 | D18: DFR | F18: 45960 | H18: RCC Complete | I18: RCC Complete | J18: RCC Complete | K18: RCC Complete | L18: Completed | M18: 45967 | O18: Rajiya Infra. | P18: C | Q18: 45974 | R18: 11
A19: 17 | B19: 130/1 | C19: A+0 | D19: DFR | F19: 45957 | H19: RCC Complete | I19: RCC Complete | J19: RCC Complete | K19: RCC Complete | L19: Completed | M19: 45969 | O19: R.K . Enterprises | P19: C | Q19: 45995 | R19: 11
A20: 18 | B20: 111/1 | C20: A+0 | D20: DFR | F20: 45961 | H20: RCC Complete | I20: RCC Complete | J20: RCC Complete | K20: RCC Complete | L20: Completed | M20: 45970 | O20: B.L Construction | R20: 11
A21: 19 | B21: 126/9 | C21: A+3 | D21: DFR | F21: 45941 | H21: RCC Complete | I21: RCC Complete | J21: RCC Complete | K21: RCC Complete | L21: Completed | M21: 45972 | O21: Rajiya Infra. | P21: C | Q21: 45985 | R21: 11
A22: 20 | B22: 123/2 | C22: A+0 | D22: WFR | F22: 45958 | H22: RCC Complete | I22: RCC Complete | J22: RCC Complete | K22: RCC Complete | L22: Completed | M22: 45974 | O22: Jai Shri Ram Enterprises | P22: C | Q22: 45981 | R22: 11
A23: 21 | B23: 111/2 | C23: A+3 | D23: DFR | F23: 45969 | H23: RCC Complete | I23: RCC Complete | J23: RCC Complete | K23: RCC Complete | L23: Completed | M23: 45975 | O23: B.L Construction | P23: C | Q23: 45985 | R23: 11
A24: 22 | B24: 126/10 | C24: A+0 | D24: DFR | F24: 45940 | H24: RCC Complete | I24: RCC Complete | J24: RCC Complete | K24: RCC Complete | L24: Completed | M24: 45975 | O24: Rajiya Infra. | P24: C | Q24: 45986 | R24: 11
A25: 23 | B25: 121/6 | C25: A+0 | D25: DFR | F25: 45968 | H25: RCC Complete | I25: RCC Complete | J25: RCC Complete | K25: RCC Complete | L25: Completed | M25: 45976 | O25: Pawan enterprises | R25: 11
A26: 24 | B26: 121/1 | C26: A+0 | D26: DFR | F26: 45968 | H26: RCC Complete | I26: RCC Complete | J26: RCC Complete | K26: RCC Complete | L26: Completed | M26: 45977 | O26: Shri Balaji Construction | P26: C | Q26: 45980 | R26: 11
A27: 25 | B27: 111/3 | C27: A+0 | D27: WFR | F27: 45968 | H27: RCC Complete | I27: RCC Complete | J27: RCC Complete | K27: RCC Complete | L27: Completed | M27: 45980 | O27: B.L Construction | P27: C | Q27: 45987 | R27: 11
A28: 26 | B28: 130/3 | C28: A+3 | D28: WFR | F28: 45970 | H28: RCC Complete | I28: RCC Complete | J28: RCC Complete | K28: RCC Complete | L28: Completed | M28: 45980 | O28: R.K . Enterprises | P28: C | Q28: 45987 | R28: 11
A29: 27 | B29: 103/2 | C29: A+0 | D29: WET PADDY | F29: 45970 | H29: RCC Complete | I29: RCC Complete | J29: RCC Complete | K29: RCC Complete | L29: Completed | M29: 45981 | O29: MUKESH MEHTA | P29: C | Q29: 45984 | R29: 11
A30: 28 | B30: 124/4 | C30: A+3 | D30: WFR | F30: 45969 | H30: RCC Complete | I30: RCC Complete | J30: RCC Complete | K30: RCC Complete | L30: Completed | M30: 45982 | O30: Jai Shri Ram Enterprises | P30: C | Q30: 45984 | R30: 11
A31: 29 | B31: 126/2 | C31: A+9 | D31: WFR | F31: 45974 | H31: RCC Complete | I31: RCC Complete | J31: RCC Complete | K31: RCC Complete | L31: Completed | M31: 45982 | O31: Rajiya Infra. | P31: C | Q31: 45984 | R31: 11
A32: 30 | B32: 121/4 | C32: A+0 | D32: DFR | F32: 45977 | H32: RCC Complete | I32: RCC Complete | J32: RCC Complete | K32: RCC Complete | L32: Completed | M32: 45983 | O32: Pawan enterprises | P32: C | Q32: 45986 | R32: 11
A33: 31 | B33: 111/4 | C33: A+0 | D33: DFR | F33: 45975 | H33: RCC Complete | I33: RCC Complete | J33: RCC Complete | K33: RCC Complete | L33: Completed | M33: 45984 | O33: B.L Construction | P33: C | Q33: 45986 | R33: 11
A34: 32 | B34: 103/3 | C34: A+3 | D34: WET PADDY | F34: 45968 | H34: RCC Complete | I34: RCC Complete | J34: RCC Complete | K34: RCC Complete | L34: Completed | M34: 45985 | O34: MUKESH MEHTA | P34: C | Q34: 45987 | R34: 11
A35: 33 | B35: 134/2 | C35: A+3 | D35: WFR | F35: 45976 | H35: RCC Complete | I35: RCC Complete | J35: RCC Complete | K35: RCC Complete | L35: Completed | M35: 45985 | O35: R.K . Enterprises | R35: 11
A36: 34 | B36: 103/1 | C36: A+6 | D36: WET PADDY | F36: 45984 | H36: RCC Complete | I36: RCC Complete | J36: RCC Complete | K36: RCC Complete | L36: Completed | M36: 45989 | O36: MUKESH MEHTA | P36: C | Q36: 45993 | R36: 11
A37: 35 | B37: 111/5 | C37: A+6 | D37: DFR | F37: 45981 | H37: RCC Complete | I37: RCC Complete | J37: RCC Complete | K37: RCC Complete | L37: Completed | M37: 45989 | O37: B.L Construction | P37: C | Q37: 45991 | R37: 11
A38: 36 | B38: 134/3 | C38: A+6 | D38: WFR | F38: 45985 | H38: RCC Complete | I38: RCC Complete | J38: RCC Complete | K38: RCC Complete | L38: Completed | M38: 45989 | O38: R.K . Enterprises | R38: 11
A39: 37 | B39: 102/7 | C39: A+0 | D39: WET PADDY | F39: 45968 | H39: RCC Complete | I39: RCC Complete | J39: RCC Complete | K39: RCC Complete | L39: Completed | M39: 45991 | O39: Rajiya Infra. | P39: C | Q39: 46000 | R39: 11
A40: 38 | B40: 110/2 | C40: A+0 | D40: DFR | F40: 45984 | H40: RCC Complete | I40: RCC Complete | J40: RCC Complete | K40: RCC Complete | L40: Completed | M40: 45991 | O40: Shri Balaji Construction | P40: C | Q40: 45996 | R40: 11
...

Sheet FDN Completed
A1: Foundation
A2: Sl. No. | B2: Location No. | C2: Tower Type | D2: Classification | E2: Starting Date | F2: Cumulative Status | G2: Completion Date | H2: Remarks | I2: Gang name | J2: Earthing Status | K2: Earthing Completion Date
A3: 1 | B3: =FDN!B3 -> 125/2 | C3: =VLOOKUP($B3,FDN!$B3:D166,2,0) -> A+3 | D3: =VLOOKUP($B3,FDN!$B3:E166,3,0) -> DFR | E3: =VLOOKUP(B3,FDN!B3:F166,5,0) -> 45902 | F3: =VLOOKUP(B3,FDN!B3:L166,11,0) -> Completed | G3: =VLOOKUP(B3,FDN!B3:M166,12,0) -> 45915 | I3: =VLOOKUP(B3,FDN!B3:O166,14,0) -> Balaji Enterprises
A4: =A3+1 -> 2 | B4: =FDN!B4 -> 125/3 | C4: =VLOOKUP(B4,FDN!B4:D166,2,0) -> A+6 | D4: =VLOOKUP($B4,FDN!$B4:E166,3,0) -> DFR | E4: =VLOOKUP(B4,FDN!B4:F166,5,0) -> 45909 | F4: =VLOOKUP(B4,FDN!B4:L166,11,0) -> Completed | G4: =VLOOKUP(B4,FDN!B4:M166,12,0) -> 45933 | I4: =VLOOKUP(B4,FDN!B4:O166,14,0) -> Balaji Enterprises
A5: =A4+1 -> 3 | B5: =FDN!B5 -> 123/1 | C5: =VLOOKUP(B5,FDN!B5:D172,2,0) -> A+0 | D5: =VLOOKUP($B5,FDN!$B5:E172,3,0) -> WFR | E5: =VLOOKUP(B5,FDN!B5:F172,5,0) -> 45931 | F5: =VLOOKUP(B5,FDN!B5:L172,11,0) -> Completed | G5: =VLOOKUP(B5,FDN!B5:M172,12,0) -> 45937 | I5: =VLOOKUP(B5,FDN!B5:O172,14,0) -> R.K . Enterprises | J5: C | K5: 45940
A6: =A5+1 -> 4 | B6: =FDN!B6 -> 124/1 | C6: =VLOOKUP(B6,FDN!B6:D176,2,0) -> A+6 | D6: =VLOOKUP($B6,FDN!$B6:E176,3,0) -> WET Paddy | E6: =VLOOKUP(B6,FDN!B6:F176,5,0) -> 45921 | F6: =VLOOKUP(B6,FDN!B6:L176,11,0) -> Completed | G6: =VLOOKUP(B6,FDN!B6:M176,12,0) -> 45938 | I6: =VLOOKUP(B6,FDN!B6:O176,14,0) -> Balaji Enterprises | J6: C | K6: 45982
A7: =A6+1 -> 5 | B7: =FDN!B7 -> 124/2 | C7: =VLOOKUP(B7,FDN!B7:D177,2,0) -> A+6 | D7: =VLOOKUP($B7,FDN!$B7:E177,3,0) -> WFR | E7: =VLOOKUP(B7,FDN!B7:F177,5,0) -> 45907 | F7: =VLOOKUP(B7,FDN!B7:L177,11,0) -> Completed | G7: =VLOOKUP(B7,FDN!B7:M177,12,0) -> 45945 | I7: =VLOOKUP(B7,FDN!B7:O177,14,0) -> Jai Shri Ram Enterprises | J7: C | K7: 45950
A8: =A7+1 -> 6 | B8: =FDN!B8 -> 121/7 | C8: =VLOOKUP(B8,FDN!B8:D178,2,0) -> A+0 | D8: =VLOOKUP($B8,FDN!$B8:E178,3,0) -> WFR | E8: =VLOOKUP(B8,FDN!B8:F178,5,0) -> 45924 | F8: =VLOOKUP(B8,FDN!B8:L178,11,0) -> Completed | G8: =VLOOKUP(B8,FDN!B8:M178,12,0) -> 45946 | I8: =VLOOKUP(B8,FDN!B8:O178,14,0) -> Pawan enterprises | J8: C | K8: 45968
A9: =A8+1 -> 7 | B9: =FDN!B9 -> 121/2 | C9: =VLOOKUP(B9,FDN!B9:D179,2,0) -> A+6 | D9: =VLOOKUP($B9,FDN!$B9:E179,3,0) -> DFR | E9: =VLOOKUP(B9,FDN!B9:F179,5,0) -> 45938 | F9: =VLOOKUP(B9,FDN!B9:L179,11,0) -> Completed | G9: =VLOOKUP(B9,FDN!B9:M179,12,0) -> 45949 | I9: =VLOOKUP(B9,FDN!B9:O179,14,0) -> Balaji Enterprises | J9: C | K9: 45950
A10: =A9+1 -> 8 | B10: =FDN!B10 -> 123/3 | C10: =VLOOKUP(B10,FDN!B10:D180,2,0) -> A+9 | D10: =VLOOKUP($B10,FDN!$B10:E180,3,0) -> DFR | E10: =VLOOKUP(B10,FDN!B10:F180,5,0) -> 45938 | F10: =VLOOKUP(B10,FDN!B10:L180,11,0) -> Completed | G10: =VLOOKUP(B10,FDN!B10:M180,12,0) -> 45949 | I10: =VLOOKUP(B10,FDN!B10:O180,14,0) -> R.K . Enterprises | J10: C | K10: 45952
A11: =A10+1 -> 9 | B11: =FDN!B11 -> 122/2 | C11: =VLOOKUP(B11,FDN!B11:D181,2,0) -> A+0 | D11: =VLOOKUP($B11,FDN!$B11:E181,3,0) -> WFR | E11: =VLOOKUP(B11,FDN!B11:F181,5,0) -> 45940 | F11: =VLOOKUP(B11,FDN!B11:L181,11,0) -> Completed | G11: =VLOOKUP(B11,FDN!B11:M181,12,0) -> 45955 | I11: =VLOOKUP(B11,FDN!B11:O181,14,0) -> Jai Shri Ram Enterprises | J11: C | K11: 45963
A12: =A11+1 -> 10 | B12: =FDN!B12 -> 126/5 | C12: =VLOOKUP(B12,FDN!B12:D182,2,0) -> A+3 | D12: =VLOOKUP($B12,FDN!$B12:E182,3,0) -> DFR | E12: =VLOOKUP(B12,FDN!B12:F182,5,0) -> 45941 | F12: =VLOOKUP(B12,FDN!B12:L182,11,0) -> Completed | G12: =VLOOKUP(B12,FDN!B12:M182,12,0) -> 45958 | I12: =VLOOKUP(B12,FDN!B12:O182,14,0) -> Rajiya Infra. | J12: C | K12: 45964
A13: =A12+1 -> 11 | B13: =FDN!B13 -> 116/1 | C13: =VLOOKUP(B13,FDN!B13:D183,2,0) -> A+3 | D13: =VLOOKUP($B13,FDN!$B13:E183,3,0) -> DFR | E13: =VLOOKUP(B13,FDN!B13:F183,5,0) -> 45942 | F13: =VLOOKUP(B13,FDN!B13:L183,11,0) -> Completed | G13: =VLOOKUP(B13,FDN!B13:M183,12,0) -> 45962 | I13: =VLOOKUP(B13,FDN!B13:O183,14,0) -> B.L Construction | J13: C | K13: 45965
A14: =A13+1 -> 12 | B14: =FDN!B14 -> 126/4 | C14: =VLOOKUP(B14,FDN!B14:D184,2,0) -> A+0 | D14: =VLOOKUP($B14,FDN!$B14:E184,3,0) -> DFR | E14: =VLOOKUP(B14,FDN!B14:F184,5,0) -> 45942 | F14: =VLOOKUP(B14,FDN!B14:L184,11,0) -> Completed | G14: =VLOOKUP(B14,FDN!B14:M184,12,0) -> 45962 | I14: =VLOOKUP(B14,FDN!B14:O184,14,0) -> Rajiya Infra. | J14: C | K14: 45968
A15: =A14+1 -> 13 | B15: =FDN!B15 -> 116/2 | C15: =VLOOKUP(B15,FDN!B15:D185,2,0) -> A+3 | D15: =VLOOKUP($B15,FDN!$B15:E185,3,0) -> DFR | E15: =VLOOKUP(B15,FDN!B15:F185,5,0) -> 45942 | F15: =VLOOKUP(B15,FDN!B15:L185,11,0) -> Completed | G15: =VLOOKUP(B15,FDN!B15:M185,12,0) -> 45964 | I15: =VLOOKUP(B15,FDN!B15:O185,14,0) -> B.L Construction | J15: C | K15: 45969
A16: =A15+1 -> 14 | B16: =FDN!B16 -> 124/3 | C16: =VLOOKUP(B16,FDN!B16:D186,2,0) -> A+9 | D16: =VLOOKUP($B16,FDN!$B16:E186,3,0) -> WFR | E16: =VLOOKUP(B16,FDN!B16:F186,5,0) -> 45910 | F16: =VLOOKUP(B16,FDN!B16:L186,11,0) -> Completed | G16: =VLOOKUP(B16,FDN!B16:M186,12,0) -> 45965 | I16: =VLOOKUP(B16,FDN!B16:O186,14,0) -> Jai Shri Ram Enterprises
A17: =A16+1 -> 15 | B17: =FDN!B17 -> 123/4 | C17: =VLOOKUP(B17,FDN!B17:D187,2,0) -> A+0 | D17: =VLOOKUP($B17,FDN!$B17:E187,3,0) -> WET | E17: =VLOOKUP(B17,FDN!B17:F187,5,0) -> 45930 | F17: =VLOOKUP(B17,FDN!B17:L187,11,0) -> Completed | G17: =VLOOKUP(B17,FDN!B17:M187,12,0) -> 45967 | I17: =VLOOKUP(B17,FDN!B17:O187,14,0) -> Shri Balaji Construction | J17: C | K17: 45969
A18: =A17+1 -> 16 | B18: =FDN!B18 -> 126/3 | C18: =VLOOKUP(B18,FDN!B18:D188,2,0) -> A+3 | D18: =VLOOKUP($B18,FDN!$B18:E188,3,0) -> DFR | E18: =VLOOKUP(B18,FDN!B18:F188,5,0) -> 45960 | F18: =VLOOKUP(B18,FDN!B18:L188,11,0) -> Completed | G18: =VLOOKUP(B18,FDN!B18:M188,12,0) -> 45967 | I18: =VLOOKUP(B18,FDN!B18:O188,14,0) -> Rajiya Infra. | J18: C | K18: 45974
A19: =A18+1 -> 17 | B19: =FDN!B19 -> 130/1 | C19: =VLOOKUP(B19,FDN!B19:D189,2,0) -> A+0 | D19: =VLOOKUP($B19,FDN!$B19:E189,3,0) -> DFR | E19: =VLOOKUP(B19,FDN!B19:F189,5,0) -> 45957 | F19: =VLOOKUP(B19,FDN!B19:L189,11,0) -> Completed | G19: =VLOOKUP(B19,FDN!B19:M189,12,0) -> 45969 | I19: =VLOOKUP(B19,FDN!B19:O189,14,0) -> R.K . Enterprises | J19: C | K19: 45995
A20: =A19+1 -> 18 | B20: =FDN!B20 -> 111/1 | C20: =VLOOKUP(B20,FDN!B20:D190,2,0) -> A+0 | D20: =VLOOKUP($B20,FDN!$B20:E190,3,0) -> DFR | E20: =VLOOKUP(B20,FDN!B20:F190,5,0) -> 45961 | F20: =VLOOKUP(B20,FDN!B20:L190,11,0) -> Completed | G20: =VLOOKUP(B20,FDN!B20:M190,12,0) -> 45970 | I20: =VLOOKUP(B20,FDN!B20:O190,14,0) -> B.L Construction
A21: =A20+1 -> 19 | B21: =FDN!B21 -> 126/9 | C21: =VLOOKUP(B21,FDN!B21:D191,2,0) -> A+3 | D21: =VLOOKUP($B21,FDN!$B21:E191,3,0) -> DFR | E21: =VLOOKUP(B21,FDN!B21:F191,5,0) -> 45941 | F21: =VLOOKUP(B21,FDN!B21:L191,11,0) -> Completed | G21: =VLOOKUP(B21,FDN!B21:M191,12,0) -> 45972 | I21: =VLOOKUP(B21,FDN!B21:O191,14,0) -> Rajiya Infra. | J21: C | K21: 45985
A22: =A21+1 -> 20 | B22: =FDN!B22 -> 123/2 | C22: =VLOOKUP(B22,FDN!B22:D192,2,0) -> A+0 | D22: =VLOOKUP($B22,FDN!$B22:E192,3,0) -> WFR | E22: =VLOOKUP(B22,FDN!B22:F192,5,0) -> 45958 | F22: =VLOOKUP(B22,FDN!B22:L192,11,0) -> Completed | G22: =VLOOKUP(B22,FDN!B22:M192,12,0) -> 45974 | I22: =VLOOKUP(B22,FDN!B22:O192,14,0) -> Jai Shri Ram Enterprises | J22: C | K22: 45981
A23: =A22+1 -> 21 | B23: =FDN!B23 -> 111/2 | C23: =VLOOKUP(B23,FDN!B23:D193,2,0) -> A+3 | D23: =VLOOKUP($B23,FDN!$B23:E193,3,0) -> DFR | E23: =VLOOKUP(B23,FDN!B23:F193,5,0) -> 45969 | F23: =VLOOKUP(B23,FDN!B23:L193,11,0) -> Completed | G23: =VLOOKUP(B23,FDN!B23:M193,12,0) -> 45975 | I23: =VLOOKUP(B23,FDN!B23:O193,14,0) -> B.L Construction | J23: C | K23: 45985
A24: =A23+1 -> 22 | B24: =FDN!B24 -> 126/10 | C24: =VLOOKUP(B24,FDN!B24:D194,2,0) -> A+0 | D24: =VLOOKUP($B24,FDN!$B24:E194,3,0) -> DFR | E24: =VLOOKUP(B24,FDN!B24:F194,5,0) -> 45940 | F24: =VLOOKUP(B24,FDN!B24:L194,11,0) -> Completed | G24: =VLOOKUP(B24,FDN!B24:M194,12,0) -> 45975 | I24: =VLOOKUP(B24,FDN!B24:O194,14,0) -> Rajiya Infra. | J24: C | K24: 45986
A25: =A24+1 -> 23 | B25: =FDN!B25 -> 121/6 | C25: =VLOOKUP(B25,FDN!B25:D195,2,0) -> A+0 | D25: =VLOOKUP($B25,FDN!$B25:E195,3,0) -> DFR | E25: =VLOOKUP(B25,FDN!B25:F195,5,0) -> 45968 | F25: =VLOOKUP(B25,FDN!B25:L195,11,0) -> Completed | G25: =VLOOKUP(B25,FDN!B25:M195,12,0) -> 45976 | I25: =VLOOKUP(B25,FDN!B25:O195,14,0) -> Pawan enterprises
A26: =A25+1 -> 24 | B26: =FDN!B26 -> 121/1 | C26: =VLOOKUP(B26,FDN!B26:D196,2,0) -> A+0 | D26: =VLOOKUP($B26,FDN!$B26:E196,3,0) -> DFR | E26: =VLOOKUP(B26,FDN!B26:F196,5,0) -> 45968 | F26: =VLOOKUP(B26,FDN!B26:L196,11,0) -> Completed | G26: =VLOOKUP(B26,FDN!B26:M196,12,0) -> 45977 | I26: =VLOOKUP(B26,FDN!B26:O196,14,0) -> Shri Balaji Construction | J26: C | K26: 45980
A27: =A26+1 -> 25 | B27: =FDN!B27 -> 111/3 | C27: =VLOOKUP(B27,FDN!B27:D197,2,0) -> A+0 | D27: =VLOOKUP($B27,FDN!$B27:E197,3,0) -> WFR | E27: =VLOOKUP(B27,FDN!B27:F197,5,0) -> 45968 | F27: =VLOOKUP(B27,FDN!B27:L197,11,0) -> Completed | G27: =VLOOKUP(B27,FDN!B27:M197,12,0) -> 45980 | I27: =VLOOKUP(B27,FDN!B27:O197,14,0) -> B.L Construction | J27: C | K27: 45987
A28: =A27+1 -> 26 | B28: =FDN!B28 -> 130/3 | C28: =VLOOKUP(B28,FDN!B28:D198,2,0) -> A+3 | D28: =VLOOKUP($B28,FDN!$B28:E198,3,0) -> WFR | E28: =VLOOKUP(B28,FDN!B28:F198,5,0) -> 45970 | F28: =VLOOKUP(B28,FDN!B28:L198,11,0) -> Completed | G28: =VLOOKUP(B28,FDN!B28:M198,12,0) -> 45980 | I28: =VLOOKUP(B28,FDN!B28:O198,14,0) -> R.K . Enterprises | J28: C | K28: 45987
A29: =A28+1 -> 27 | B29: =FDN!B29 -> 103/2 | C29: =VLOOKUP(B29,FDN!B29:D199,2,0) -> A+0 | D29: =VLOOKUP($B29,FDN!$B29:E199,3,0) -> WET PADDY | E29: =VLOOKUP(B29,FDN!B29:F199,5,0) -> 45970 | F29: =VLOOKUP(B29,FDN!B29:L199,11,0) -> Completed | G29: =VLOOKUP(B29,FDN!B29:M199,12,0) -> 45981 | I29: =VLOOKUP(B29,FDN!B29:O199,14,0) -> MUKESH MEHTA | J29: C | K29: 45984
A30: =A29+1 -> 28 | B30: =FDN!B30 -> 124/4 | C30: =VLOOKUP(B30,FDN!B30:D200,2,0) -> A+3 | D30: =VLOOKUP($B30,FDN!$B30:E200,3,0) -> WFR | E30: =VLOOKUP(B30,FDN!B30:F200,5,0) -> 45969 | F30: =VLOOKUP(B30,FDN!B30:L200,11,0) -> Completed | G30: =VLOOKUP(B30,FDN!B30:M200,12,0) -> 45982 | I30: =VLOOKUP(B30,FDN!B30:O200,14,0) -> Jai Shri Ram Enterprises | J30: C | K30: 45984
A31: =A30+1 -> 29 | B31: =FDN!B31 -> 126/2 | C31: =VLOOKUP(B31,FDN!B31:D201,2,0) -> A+9 | D31: =VLOOKUP($B31,FDN!$B31:E201,3,0) -> WFR | E31: =VLOOKUP(B31,FDN!B31:F201,5,0) -> 45974 | F31: =VLOOKUP(B31,FDN!B31:L201,11,0) -> Completed | G31: =VLOOKUP(B31,FDN!B31:M201,12,0) -> 45982 | I31: =VLOOKUP(B31,FDN!B31:O201,14,0) -> Rajiya Infra. | J31: C | K31: 45984
A32: =A31+1 -> 30 | B32: =FDN!B32 -> 121/4 | C32: =VLOOKUP(B32,FDN!B32:D202,2,0) -> A+0 | D32: =VLOOKUP($B32,FDN!$B32:E202,3,0) -> DFR | E32: =VLOOKUP(B32,FDN!B32:F202,5,0) -> 45977 | F32: =VLOOKUP(B32,FDN!B32:L202,11,0) -> Completed | G32: =VLOOKUP(B32,FDN!B32:M202,12,0) -> 45983 | I32: =VLOOKUP(B32,FDN!B32:O202,14,0) -> Pawan enterprises | J32: C | K32: 45986
A33: =A32+1 -> 31 | B33: =FDN!B33 -> 111/4 | C33: =VLOOKUP(B33,FDN!B33:D203,2,0) -> A+0 | D33: =VLOOKUP($B33,FDN!$B33:E203,3,0) -> DFR | E33: =VLOOKUP(B33,FDN!B33:F203,5,0) -> 45975 | F33: =VLOOKUP(B33,FDN!B33:L203,11,0) -> Completed | G33: =VLOOKUP(B33,FDN!B33:M203,12,0) -> 45984 | I33: =VLOOKUP(B33,FDN!B33:O203,14,0) -> B.L Construction | J33: C | K33: 45986
A34: =A33+1 -> 32 | B34: =FDN!B34 -> 103/3 | C34: =VLOOKUP(B34,FDN!B34:D204,2,0) -> A+3 | D34: =VLOOKUP($B34,FDN!$B34:E204,3,0) -> WET PADDY | E34: =VLOOKUP(B34,FDN!B34:F204,5,0) -> 45968 | F34: =VLOOKUP(B34,FDN!B34:L204,11,0) -> Completed | G34: =VLOOKUP(B34,FDN!B34:M204,12,0) -> 45985 | I34: =VLOOKUP(B34,FDN!B34:O204,14,0) -> MUKESH MEHTA | J34: C | K34: 45987
A35: =A34+1 -> 33 | B35: =FDN!B35 -> 134/2 | C35: =VLOOKUP(B35,FDN!B35:D205,2,0) -> A+3 | D35: =VLOOKUP($B35,FDN!$B35:E205,3,0) -> WFR | E35: =VLOOKUP(B35,FDN!B35:F205,5,0) -> 45976 | F35: =VLOOKUP(B35,FDN!B35:L205,11,0) -> Completed | G35: =VLOOKUP(B35,FDN!B35:M205,12,0) -> 45985 | I35: =VLOOKUP(B35,FDN!B35:O205,14,0) -> R.K . Enterprises
A36: =A35+1 -> 34 | B36: =FDN!B36 -> 103/1 | C36: =VLOOKUP(B36,FDN!B36:D206,2,0) -> A+6 | D36: =VLOOKUP($B36,FDN!$B36:E206,3,0) -> WET PADDY | E36: =VLOOKUP(B36,FDN!B36:F206,5,0) -> 45984 | F36: =VLOOKUP(B36,FDN!B36:L206,11,0) -> Completed | G36: =VLOOKUP(B36,FDN!B36:M206,12,0) -> 45989 | I36: =VLOOKUP(B36,FDN!B36:O206,14,0) -> MUKESH MEHTA | J36: C | K36: 45993
A37: =A36+1 -> 35 | B37: =FDN!B37 -> 111/5 | C37: =VLOOKUP(B37,FDN!B37:D207,2,0) -> A+6 | D37: =VLOOKUP($B37,FDN!$B37:E207,3,0) -> DFR | E37: =VLOOKUP(B37,FDN!B37:F207,5,0) -> 45981 | F37: =VLOOKUP(B37,FDN!B37:L207,11,0) -> Completed | G37: =VLOOKUP(B37,FDN!B37:M207,12,0) -> 45989 | I37: =VLOOKUP(B37,FDN!B37:O207,14,0) -> B.L Construction | J37: C | K37: 45991
A38: =A37+1 -> 36 | B38: =FDN!B38 -> 134/3 | C38: =VLOOKUP(B38,FDN!B38:D208,2,0) -> A+6 | D38: =VLOOKUP($B38,FDN!$B38:E208,3,0) -> WFR | E38: =VLOOKUP(B38,FDN!B38:F208,5,0) -> 45985 | F38: =VLOOKUP(B38,FDN!B38:L208,11,0) -> Completed | G38: =VLOOKUP(B38,FDN!B38:M208,12,0) -> 45989 | I38: =VLOOKUP(B38,FDN!B38:O208,14,0) -> R.K . Enterprises
A39: =A38+1 -> 37 | B39: =FDN!B39 -> 102/7 | C39: =VLOOKUP(B39,FDN!B39:D209,2,0) -> A+0 | D39: =VLOOKUP($B39,FDN!$B39:E209,3,0) -> WET PADDY | E39: =VLOOKUP(B39,FDN!B39:F209,5,0) -> 45968 | F39: =VLOOKUP(B39,FDN!B39:L209,11,0) -> Completed | G39: =VLOOKUP(B39,FDN!B39:M209,12,0) -> 45991 | I39: =VLOOKUP(B39,FDN!B39:O209,14,0) -> Rajiya Infra. | J39: C | K39: 46000
A40: =A39+1 -> 38 | B40: =FDN!B40 -> 110/2 | C40: =VLOOKUP(B40,FDN!B40:D210,2,0) -> A+0 | D40: =VLOOKUP($B40,FDN!$B40:E210,3,0) -> DFR | E40: =VLOOKUP(B40,FDN!B40:F210,5,0) -> 45984 | F40: =VLOOKUP(B40,FDN!B40:L210,11,0) -> Completed | G40: =VLOOKUP(B40,FDN!B40:M210,12,0) -> 45991 | I40: =VLOOKUP(B40,FDN!B40:O210,14,0) -> Shri Balaji Construction | J40: C | K40: 45996
...

Sheet Erection 
A2: ±800kV HVDC Bipole Line (Hexa Lapwing) between KPS2 (HVDC) & Nagpur (HVDC) (Part- 6) Erection
A3: Sl. No. | B3: Location Number | C3: Type of Tower | E3: Starting Date | F3: Tower Weight (MT) | G3: Status | H3: Completion Date | I3: Gang Name | J3: Manpower | K3: Hindarnce Days | L3: Remarks | M3: Tackweldng Status | N3: Tackwelding start date | O3: Tackwelding Completion date | P3: Sub Contractor name
A4: 1 | B4: 125/2 | C4: A+3 | D4: A+3 | E4: 46071 | F4: =VLOOKUP(D4,'[1]Tower Weight Individual'!$S$13:$Y$50,7,0)/1000 -> 24.041023 | G4: C | H4: 46075 | I4: M/S Ratani Devi | J4: 18
A5: 2 | B5: 122/2 | C5: A+0 | D5: A+0 | E5: 46078 | F5: =VLOOKUP(D5,'[1]Tower Weight Individual'!$S$13:$Y$50,7,0)/1000 -> 22.923735 | G5: C | H5: 46081 | I5: M/S Ratani Devi | J5: 18
A6: 3 | B6: 130/1 | C6: A+0 | D6: A+0 | E6: 46075 | F6: =VLOOKUP(D6,'[1]Tower Weight Individual'!$S$13:$Y$50,7,0)/1000 -> 22.923735 | G6: C | H6: 46081 | I6: M/S Jwala | J6: 35
A7: 4 | B7: 126/10 | C7: A+0 | D7: A+0 | E7: 46084 | F7: =VLOOKUP(D7,'[1]Tower Weight Individual'!$S$13:$Y$50,7,0)/1000 -> 22.923735 | G7: C | H7: 46088 | I7: M/s Ratani Devi | J7: 23
A8: 5 | B8: 129A/3 | C8: A+3 | D8: A+3 | E8: 46082 | F8: =VLOOKUP(D8,'[1]Tower Weight Individual'!$S$13:$Y$50,7,0)/1000 -> 24.041023 | G8: C | H8: 46091 | I8: M/s Jwala | J8: 23
A9: 6 | B9: 126/9 | C9: A+3 | D9: A+3 | E9: 46082 | F9: =VLOOKUP(D9,'[1]Tower Weight Individual'!$S$13:$Y$50,7,0)/1000 -> 24.041023 | G9: C | H9: 46092 | I9: M/s Ratani Devi | J9: 38
A10: 7 | B10: 129A/4 | C10: A+6 | D10: A+6 | E10: 46092 | F10: =VLOOKUP(D10,'[1]Tower Weight Individual'!$S$13:$Y$50,7,0)/1000 -> 26.764163 | G10: C | H10: 46095 | I10: M/s Jwala | J10: 35
A11: 8 | B11: 126/5 | C11: A+3 | D11: A+3 | E11: 45717 | F11: =VLOOKUP(D11,'[1]Tower Weight Individual'!$S$13:$Y$50,7,0)/1000 -> 24.041023 | G11: C | H11: 46096 | I11: M/s Ratani Devi | J11: 35
A12: 9 | B12: 126/4 | C12: A+0 | D12: A+0 | E12: 46096 | F12: =VLOOKUP(D12,'[1]Tower Weight Individual'!$S$13:$Y$50,7,0)/1000 -> 22.923735 | G12: C | H12: 46100 | I12: M/s Ratani Devi | J12: 35
A13: 10 | B13: 130/2 | C13: A+6 | D13: A+6 | E13: 46096 | F13: =VLOOKUP(D13,'[1]Tower Weight Individual'!$S$13:$Y$50,7,0)/1000 -> 26.764163 | G13: C | H13: 46100 | I13: M/s Jwala | J13: 18
A14: 11 | B14: 130/3 | C14: A+3 | D14: A+3 | E14: 46100 | F14: =VLOOKUP(D14,'[1]Tower Weight Individual'!$S$13:$Y$50,7,0)/1000 -> 24.041023 | G14: C | H14: 46103 | I14: M/s Jwala | J14: 23
A15: 12 | B15: 126/3 | C15: A+3 | D15: A+3 | E15: 46100 | F15: =VLOOKUP(D15,'[1]Tower Weight Individual'!$S$13:$Y$50,7,0)/1000 -> 24.041023 | G15: C | H15: 46104 | I15: M/s Ratani Devi | J15: 19
... A42: 39 | B42: 111/2 | C42: A+3 | D42: A+3 | E42: 46157 | F42: =VLOOKUP(D42,'[1]Tower Weight Individual'!$S$13:$Y$50,7,0)/1000 -> 24.041023 | G42: C | H42: 46160 | I42: M/s Amrendra Prasad | J42: 26
A43: 40 | B43: 121/6 | C43: A+0 | D43: A+0 | E43: 46038 | F43: =VLOOKUP(D43,'[1]Tower Weight Individual'!$S$13:$Y$50,7,0)/1000 -> 22.923735 | G43: C | H43: 46160 | I43: M/S Gagan Entp.
A44: 41 | B44: 136/8 | C44: A+0 | D44: A+0 | E44: 46158 | F44: =VLOOKUP(D44,'[1]Tower Weight Individual'!$S$13:$Y$50,7,0)/1000 -> 22.923735 | G44: C | H44: 46160 | I44: M/s Jwala Singh | J44: 23
A45: 42 | B45: 121/5 | C45: A+0 | D45: A+0 | E45: 46160 | F45: =VLOOKUP(D45,'[1]Tower Weight Individual'!$S$13:$Y$50,7,0)/1000 -> 22.923735 | G45: C | H45: 46162 | I45: M/S Gagan Entp. | J45: 24
A46: 43 | B46: 109/5 | C46: A+3 | D46: A+3 | E46: 46159 | F46: =VLOOKUP(D46,'[1]Tower Weight Individual'!$S$13:$Y$50,7,0)/1000 -> 24.041023 | G46: C | H46: 46163 | I46: M/s Mukesh Kumar Verma | J46: 32
A47: 44 | B47: 139/1 | C47: A+3 | D47: A+3 | E47: 46160 | F47: =VLOOKUP(D47,'[1]Tower Weight Individual'!$S$13:$Y$50,7,0)/1000 -> 24.041023 | G47: C | H47: 46163 | I47: M/s Jwala Singh | J47: 23
A48: 45 | B48: 111/3 | C48: A+0 | D48: A+0 | E48: 46160 | F48: =VLOOKUP(D48,'[1]Tower Weight Individual'!$S$13:$Y$50,7,0)/1000 -> 22.923735 | G48: C | H48: 46164 | I48: M/s Amrendra Prasad | J48: 26
A49: 46 | B49: 124/5 | C49: A+6 | D49: A+6 | E49: 46163 | F49: =VLOOKUP(D49,'[1]Tower Weight Individual'!$S$13:$Y$50,7,0)/1000 -> 26.764163 | G49: C | H49: 46165 | I49: M/S Gagan Entp. | J49: 35
A50: 47 | B50: 125/1 | C50: A+3 | D50: A+3 | E50: 46165 | F50: =VLOOKUP(D50,'[1]Tower Weight Individual'!$S$13:$Y$50,7,0)/1000 -> 24.041023 | G50: C | H50: 46167 | I50: M/S Gagan Entp. | J50: 24
A51: 48 | B51: 111/4 | C51: A+0 | D51: A+0 | E51: 46165 | F51: =VLOOKUP(D51,'[1]Tower Weight Individual'!$S$13:$Y$50,7,0)/1000 -> 22.923735 | G51: C | H51: 46168 | I51: M/s Amrendra Prasad | J51: 32
A52: 49 | B52: 109/6 | C52: A+3 | D52: A+3 | E52: 46163 | F52: =VLOOKUP(D52,'[1]Tower Weight Individual'!$S$13:$Y$50,7,0)/1000 -> 24.041023 | G52: C | H52: 46170 | I52: M/s Mukesh Kumar Verma | J52: 26
A53: 50 | B53: 125/0 | C53: B2+3 | D53: B+3 | E53: 46168 | F53: =VLOOKUP(D53,'[1]Tower Weight Individual'!$S$13:$Y$50,7,0)/1000 -> 31.667057 | G53: C | H53: 46171 | I53: M/S Gagan Entp. | J53: 23
