Workbook
Name \0: #REF!
Name \A: #REF!
Name \A: #REF!
Name \A: #REF!
Name \A_1: "#REF!"
Name \aa: #REF!
Name \aa: #REF!
Name \aa: #REF!
Name \B: #REF!
Name \B: #REF!
Name \B: #REF!
Name \C: #REF!
Name \C: #REF!
Name \C: #REF!
Name \c1: #REF!
Name \D: #REF!
Name \DFC: #REF!
Name \DFC: #REF!
Name \DFC: #REF!
Name \E: #REF!
Name \E: #REF!
Name \E: #REF!
Name \g: #REF!
Name \H: #REF!
Name \H: #REF!
Name \H: #REF!
Name \i: #REF!
Name \jmns: #REF!
Name \jmns: #REF!
Name \jmns: #REF!
Name \L: #REF!
Name \L: #REF!
Name \L: #REF!
Name \LK: #REF!
Name \LK: #REF!
Name \LK: #REF!
Name \LKM: #REF!
Name \LKM: #REF!
Name \LKM: #REF!
Name \M: #REF!
Name \M: #REF!
Name \M: #REF!
Name \N: #REF!
Name \N: #REF!
Name \N: #REF!
Name \P: #REF!
Name \P: #REF!
Name \P: #REF!
Name \Q: #REF!
Name \Q: #REF!
Name \Q: #REF!
Name \R: #REF!
Name \R: #REF!
Name \R: #REF!
Name \S: #REF!
Name \S: #REF!
Name \S: #REF!
Name \Sv: #REF!
Name \Sv: #REF!
Name \Sv: #REF!

Sheet Project Details
A1: Project Code | B1: Project Name | C1: Client Name | D1: NOA Start Date | E1: LOA End Date | F1: Planning Engineer | G1: PCH | H1: Regional Manager | I1: Project Manager | J1: Section Incharge | K1: Employee Name | L1: Designation
A2: TA-602 | B2: Name of Line: Package TL-06 for ±800kV HVDC Bipole Line (Hexa Lapwing) between KPS2 (HVDC) & Nagpur (HVDC) (with dedicated metallic Return) -Part- 6 Transmission Line | C2: Powergrid West Central Transmission Ltd. | D2: 45790 | E2: 47069 | F2: Mr. Rishi Shukla | G2: Mr Arun Felbin R | H2: Mr. Vijay Govindrao Kute | I2: Mr. Minarul Alam | J2: Mr. Ajaya Kumar | K2: Mr. Vishnu R Nair | L2: Sr. Engineer
K3: Mr. Tapash Das | L3: Sr. Surveyour
K4: Mr. Rakesh Debnath | L4: Survey Officer
K5: Mr. Monnesh C.K. | L5: Syrvey Assist.
K6: Mr. Deep kumar Das | L6: Sr. Supervisor
K7: Mr. Soumen Khan | L7: Survey Officer
K8: Mr. Khokan Mandal | L8: Assit. Surveyour
J9: Mr. Tanmay Nayak | K9: Mr. Madhu Saran Prashad | L9: Supervisor
K10: Jaynta Ghosh | L10: Supervisor
K11: Uttam das | L11: Supervisor
K12: Md. Wahiddujaman Biswash | L12: Officer Project
K13: Mijanur Rahaman | L13: Officer Project
K14: Saddam Hossain | L14: Officer Project
K15: Sanjit Singh | L15: Erection Supervisor
K16: Hulash mahato | L16: Erection Supervisor
K17: Bhim mahato | L17: Erection Supervisor
K18: M Ganesan | L18: Assistant Officer - project

Sheet 800kV HVDC TA-602
B1: Project Code | C1: ='Project Details'!A2 -> TA-602 | D1: Date | E1: =TODAY() -> 46185 | H1: President-T&D | I1: Mr. Ganesh Srinivasan
B2: Project Name | C2: ='Project Details'!B2 -> Name of Line: Package TL-06 for ±800kV HVDC Bipole Line (Hexa Lapwing) between KPS2 (HVDC) & Nagpur (HVDC) (with dedicated metallic Return) -Part- 6 Transmission Line | F2: NOA Start Date | G2: ='Project Details'!D2 -> 45790 | H2: PCH | I2: Mr. Arun Felbin
B3: Client Name | C3: ='Project Details'!C2 -> Powergrid West Central Transmission Ltd. | F3: LOA End Date | G3: ='Project Details'!E2 -> 47069 | H3: Regional Manager | I3: ='Project Details'!H2 -> Mr. Vijay Govindrao Kute
F4: Planning Engineer | G4: ='Project Details'!F2 -> Mr. Rishi Shukla | H4: Project Manger | I4: ='Project Details'!I2 -> Mr. Minarul Alam
A5: \
A6: Check Survey
A7: Activity | B7: Unit | C7: Final Est. Qty | D7: L2 till Last Month | E7: Submitted till Last Month | F7: Approved till Last Month | G7: Balance to Submit | H7: Balance to Approve | I7: L2 Submission Plan for Current Month | J7: Progress For Month | K7: Approved till Current Month | L7: Remarks
A8: Rout Alignment | B8: km | C8: 185.149 | D8: =C8 -> 185.149 | E8: =D8 -> 185.149 | F8: =E8 -> 185.149 | G8: =C8-E8 -> 0 | H8: =C8-F8 -> 0 | I8: - | K8: =F8 -> 185.149
A9: Detailed Survey | B9: km | C9: 184.986 | D9: =C9 -> 184.986 | E9: =D9 -> 184.986 | F9: 166.531 | G9: =D9-E9 -> 0 | H9: =C9-F9 -> 18.455 | I9: - | K9: =F9 -> 166.531 | L9: Due to Brick -kiln Hold B/W Section AP13 to AP14(3.710)
A10: Check Survey | B10: km | C10: =C9 -> 184.986 | D10: =C10 -> 184.986 | E10: 166.531 | F10: 136.139 | G10: =D10-E10 -> 18.455 | H10: =C10-F10 -> 48.847 | I10: - | K10: =F10 -> 136.139
A12: Progress Status
A13: Activity | B13: Final Estimated Quantity | C13: Cumulative L2 till Last Month (May'26) | D13: Cumulative Progress till Last Month(May'26) | E13: L2 for present Month | F13: Plan for the Month | G13: Today's Progress | H13: Progress till Date for the Month | I13: L2 till Current Month | J13: Completed till Date | K13: Balance Work | L13: Under Progress | M13: Gangs at Present | N13: Remarks
A14: Soil Investigation | B14: 31 | D14: 16 | E14: 0 | F14: 0 | I14: =C14+E14 -> 0 | J14: 17 | K14: =B14-J14 -> 14 | L14: 1 | N14: AP96
A15: Foundation | B15: 480 | C15: 167 | D15: 154 | E15: 10 | F15: ='PGCIL - KEC'!F12 -> 30 | G15: 1 | H15: ='PGCIL - KEC'!H12 -> 7 | I15: =C15+E15 -> 177 | J15: ='PGCIL - KEC'!I12 -> 161 | K15: =B15-J15 -> 319 | L15: ='PGCIL - KEC'!K12 -> 5 | M15: ='PGCIL - KEC'!L12 -> 4
A16: Earthing | B16: =B15 -> 480 | C16: =C15 -> 167 | D16: ='PGCIL - KEC'!D13 -> 96 | E16: =E15 -> 10 | F16: ='PGCIL - KEC'!F13 -> 30 | G16: ='PGCIL - KEC'!G13 -> 1 | H16: ='PGCIL - KEC'!H13 -> 9 | I16: =C16+E16 -> 177 | J16: ='PGCIL - KEC'!I13 -> 105 | K16: =B16-J16 -> 375
A17: Tower Erection | B17: =B16 -> 480 | C17: 102 | D17: ='PGCIL - KEC'!D14 -> 52 | E17: 10 | F17: ='PGCIL - KEC'!F14 -> 35 | G17: 2 | H17: ='PGCIL - KEC'!H14 -> 11 | I17: =C17+E17 -> 112 | J17: ='PGCIL - KEC'!I14 -> 63 | K17: =B17-J17 -> 417 | L17: ='PGCIL - KEC'!K14 -> 5 | M17: ='PGCIL - KEC'!L14 -> 4
A18: Tack welding | B18: =B17 -> 480 | C18: =C17 -> 102 | D18: ='PGCIL - KEC'!D15 -> 0 | E18: =E17 -> 10 | F18: ='PGCIL - KEC'!F15 -> 35 | G18: 0 | H18: ='PGCIL - KEC'!H15 -> 0 | I18: =C18+E18 -> 112 | J18: ='PGCIL - KEC'!I15 -> 0 | K18: =B18-J18 -> 480 | L18: 2 | M18: 2
A19: Stringing(Km) | B19: =C9 -> 184.986 | C19: 10 | D19: ='PGCIL - KEC'!D16 -> 0 | E19: 5 | F19: 0 | H19: ='PGCIL - KEC'!H16 -> 0 | I19: =C19+E19 -> 15 | J19: ='PGCIL - KEC'!I16 -> 0 | K19: =B19-J19 -> 184.986 | L19: ='PGCIL - KEC'!K16 -> 0 | M19: ='PGCIL - KEC'!L16 -> 0

Sheet PPT-Erection Part
A1: LOA DT -13-May-2026 Completion Schedule 12-Nov-2028 Project Value-613.31Cr
A2: Sl No | B2: PARTICULARS | D2: Unit | E2: Total | F2: Comp Till 31-May’26 | G2: Balance Till 01-Jun’26 | H2: June’26 | K2: July’26 | L2: Aug’26 | M2: Support / Issue
E3: Qty | H3: Plan | I3: Actual | J3: WIP | K3: Plan | L3: Plan
A4: 1 | B4: Survey | C4: Details | D4: KMs | E4: 185.149 | F4: 166.531 | G4: 18.455 | H4: 18.455 | J4: 8.123 | K4: - | L4: -
C5: Check | D5: Kms | E5: 185.149 | F5: 136.139 | G5: 48.847 | H5: =G5 -> 48.847 | J5: =F4-F5 -> 30.392
A6: 2 | B6: FOUNDATION | C6: Location | D6: Nos | E6: 480 | F6: 154 | G6: =E6-F6 -> 326 | H6: 30 | I6: 4 | J6: 5 | K6: 20 | L6: 40
C7: Gang | D7: No | H7: 6 | I7: 5 | J7: 5 | K7: 5 | L7: 6
C8: Earthing | D8: No | E8: 480 | F8: 96 | G8: =E8-F8 -> 384 | H8: 40 | I8: 4 | J8: - | K8: 20 | L8: 30
A9: 3 | B9: TOWER ERECTION | C9: Location | D9: Nos | E9: 480 | F9: 52 | G9: =E9-F9 -> 428 | H9: 35 | I9: 4 | J9: 5 | K9: 25 | L9: 35
C10: Volume | D10: MT | E10: 13208 | F10: 1321 | G10: =E10-F10 -> 11887 | H10: =H9*24 -> 840 | I10: =I9*26 -> 104 | J10: =J9*24 -> 120 | K10: =K9*25 -> 625 | L10: =L9*24 -> 840
C11: Gang | D11: No | H11: 5 | I11: 5 | J11: 5 | K11: 5 | L11: 5
C12: Tack Welding | D12: No | E12: 480 | G12: =E12-F12 -> 480
A13: 4 | B13: STRINGING | C13: Stringing - P/O | D13: KMs | E13: 185.1 | G13: =E13-F13 -> 185.1
C14: Stringing Final Sag | D14: Kms | E14: =E13 -> 185.1 | G14: 185.1
C15: TSE - Section | D15: No | E15: =E14-E16 -> 166.083 | G15: =E15-F15 -> 166.083
C16: Manual - Section | D16: No | E16: 19.017 | G16: =E16 -> 19.017
C17: Gang | D17: No
A18: 5 | B18: OPGW | C18: Stringing | D18: KMs | E18: 185.1 | G18: =E18-F18 -> 185.1
B19: STRINGING | C19: Gang | D19: No
A20: 6 | B20: Revenue | D20: CR. | E20: 100.47 | F20: 10 | G20: 10

Sheet PPT _Statutory
A1: Statuary Clearances :
A2: Sl No | B2: Name Statuary Clearances | C2: Total | D2: Submitted | E2: Approved | F2: Balance to Submit | G2: Balance to Approve | H2: Status of submitted Proposals
A3: 1 | B3: Railway X-ing | C3: 2 | D3: 0 | E3: 0 | F3: =C3-D3 -> 2 | G3: =C3-E3 -> 2 | H3: • AP50–AP51: Foundation drawing awaited (D60+6, D60+9) • 111A–111B: Railway crossing – details awaited
A4: 2 | B4: Powerline X-ing | C4: 12 | D4: 12 | E4: 0 | F4: =C4-D4 -> 0 | G4: =C4-E4 -> 12 | H4: 11 No's Location Site Visit done.
A5: 3 | B5: NH X-ing | C5: 4 | D5: 4 | E5: 0 | F5: =C5-D5 -> 0 | G5: =C5-F5 -> 4 | H5: Two No's Site Visit Done( AP 118 to AP119 & AP133 to AP34).
A6: 4 | B6: River X-ing | C6: 1 | D6: 1 | E6: 0 | F6: =C6-E6 -> 1 | G6: 0 | H6: Awaitiing/Dependency @ Approval of Detail Survey & Soil Investigation Testing Underprocess.
A7: 5 | B7: Civil Aviation Proposal | C7: 1 | D7: 0 | E7: 0 | F7: =C7-E7 -> 1 | G7: 1 | H7: Under Process
A8: 6 | B8: Defence Aviation | C8: 1 | D8: 0 | E8: 0 | F8: =C8-E8 -> 1 | G8: 1 | H8: Under Process
A9: 7 | B9: PTCC Proposal | C9: 1 | D9: 0 | E9: 0 | F9: =C9-E9 -> 1 | G9: 1
A10: 8 | B10: Pipe line X-ings | C10: 1 | D10: 1 | E10: 0 | F10: =C10-D10 -> 0 | G10: 1

Sheet PPT Supply
A1: Supply & BOI Details
A2: SL No. | B2: Type of Tower | C2: UOM | D2: BOQ Qty | E2: Final line Qty (Amended) | F2: Received as on dated | G2: Balance to be supply | H2: Remark
A3: 1 | B3: Stubs | C3: Nos | D3: 494 | E3: U/P | F3: 242 | G3: =D3-F3 -> 252
A4: 2 | B4: Towers | C4: Nos | D4: 494 | E4: U/P | F4: 193 | G4: =D4-F4 -> 301
A5: 3 | B5: Conductor | C5: Km | D5: 3030.64 | E5: U/P | F5: 1209.519 | G5: =D5-F5 -> 1821.121
A6: 4 | B6: Insulators | C6: Nos | D6: 12782 | E6: U/P | F6: 0 | G6: =D6-F6 -> 12782
A7: 5 | B7: Earthwire | C7: Km | D7: 192.165 | E7: U/P | F7: 77 | G7: =D7-F7 -> 115.165
A8: 6 | B8: HW for Cond & EW | C8: % | D8: 100 | E8: U/P | F8: 0 | G8: =D8-F8 -> 100 | H8: 25% Material under dispatch
A9: 7 | B9: OPGW Cable | C9: Km | D9: 199 | E9: U/P | F9: 0 | G9: =D9-F9 -> 199
A10: 8 | B10: OPGW Accessories | C10: % | D10: 100 | E10: U/P | F10: 0 | G10: =D10-F10 -> 100

Sheet Supply Status
A1: Supply & BOI Details
A2: SL No. | B2: Type of Tower | C2: UOM | D2: BOQ Qty | E2: DSL | F2: PRS Released | G2: Balance to Release | H2: Remark's
A3: 1 | B3: Stubs | C3: Nos | D3: 494 | E3: 410 | F3: 351 | G3: =E3-F3 -> 59 | H3: DSL UPTO-July
A4: 2 | B4: Towers | C4: Nos | D4: 494 | E4: 330 | F4: 286 | G4: =E4-F4 -> 44 | H4: DSL UPTO-July
A5: 3 | B5: Conductor | C5: Km | D5: 3030.64 | E5: 2121 | F5: 2200 | G5: =E5-F5 -> -79 | H5: DSL UPTO-July
A6: 4 | B6: Insulators | C6: Nos | D6: 12782 | E6: 8948 | F6: 8948 | G6: =E6-F6 -> 0 | H6: DSL UPTO-July
A7: 5 | B7: Earthwire | C7: Km | D7: 192.165 | E7: 135 | F7: 188 | G7: =E7-F7 -> -53 | H7: DSL UPTO-July
A8: 6 | B8: HW for Cond & EW | C8: % | D8: 100 | E8: 0.25 | F8: 0.7 | G8: =E8-F8 -> -0.45 | H8: DSL UPTO-July
A9: 7 | B9: OPGW Cable | C9: Km | D9: 199 | E9: 100 | F9: 0 | G9: =E9-F9 -> 100 | H9: DSL UPTO-July
A10: 8 | B10: OPGW Accessories | C10: % | D10: 100 | E10: 0.5 | F10: 0.7 | G10: =E10-F10 -> -0.2 | H10: DSL UPTO-June

Sheet DPR Sheet
B2: KEC INTERNATIONAL LIMITED
B3: DAILY PROGRESS REPORT : SUBMISSION STATUS AS ON | G3: ='PGCIL - KEC'!M1 -> 46185
B4: Name of the Project: | D4: ±800kV HVDC Bipole Line (Hexa Lapwing) between KPS2 (HVDC) & Nagpur (HVDC) (with dedicated metallic Return) -Part- 6
B5: Contract No. & Date : | D5: CC/T/W/-TW/DOM/A06/24/04774/CA-1/25-105721,01&02 Dt.13.05.25
B7: ROUTE ALIGNMENT PROGRESS SUMMARY
B8: TOTAL QTY (Tentative) | C8: COMPLETED UP TO PREV MONTH | D8: COMP. IN CURRENT MONTH | E8: CUMULATIVE | F8: BAL.QTY
B9: ='PGCIL - KEC'!C7 -> 184.986 | C9: ='PGCIL - KEC'!D6 -> 185.149 | D9: ='PGCIL - KEC'!F6 -> 0 | E9: ='PGCIL - KEC'!I6 -> 185.149 | F9: ='PGCIL - KEC'!J6 -> 0
B10: SOIL INVESTIGATION PROGRESS SUMMARY
B11: TOTAL QTY (Tentative) | C11: COMPLETED UP TO PREV MONTH | D11: COMP. IN CURRENT MONTH | E11: CUMULATIVE | F11: BAL.QTY
B12: ='PGCIL - KEC'!C10 -> 31 | C12: ='PGCIL - KEC'!D10 -> 17 | D12: ='PGCIL - KEC'!H10 -> 1 | E12: ='PGCIL - KEC'!I10 -> 18 | F12: ='PGCIL - KEC'!J10 -> 13
B13: DETAILED SURVEY PROGRESS SUMMARY
B14: TOTAL QTY (Tentative) | C14: COMPLETED UP TO PREV MONTH | D14: COMP. IN CURRENT MONTH | E14: CUMULATIVE | F14: BAL.QTY
B15: ='PGCIL - KEC'!C7 -> 184.986 | C15: ='PGCIL - KEC'!D7 -> 166.531 | D15: ='PGCIL - KEC'!H7 -> 0 | E15: ='PGCIL - KEC'!I7 -> 166.531 | F15: ='PGCIL - KEC'!J7 -> 18.455
B16: CHECK SURVEY PROGRESS SUMMARY
B17: TOTAL QTY (Tentative) | C17: COMPLETED UP TO PREV MONTH | D17: COMP. IN CURRENT MONTH | E17: CUMULATIVE | F17: BAL.QTY
B18: ='PGCIL - KEC'!C9 -> 184.986 | C18: ='PGCIL - KEC'!D9 -> 136.139 | D18: ='PGCIL - KEC'!H9 -> 0 | E18: ='PGCIL - KEC'!I9 -> 136.139 | F18: ='PGCIL - KEC'!J9 -> 48.847
B19: FOUNDATION PROGRESS SUMMARY
B20: TOTAL QTY (Tentative) | C20: COMPLETED UP TO PREV MONTH | D20: COMP. IN CURRENT MONTH | E20: CUMULATIVE | F20: BAL.QTY
B21: ='PGCIL - KEC'!C12 -> 480 | C21: ='PGCIL - KEC'!D12 -> 154 | D21: ='PGCIL - KEC'!H12 -> 7 | E21: ='PGCIL - KEC'!I12 -> 161 | F21: ='PGCIL - KEC'!J12 -> 319
B22: EARTHING PROGRESS SUMMARY
B23: TOTAL QTY | C23: COMPLETED UP TO PREV MONTH | D23: COMP. IN CURRENT MONTH | E23: CUMULATIVE | F23: BAL.QTY
B24: ='PGCIL - KEC'!C13 -> 480 | C24: ='PGCIL - KEC'!D13 -> 96 | D24: ='PGCIL - KEC'!H13 -> 9 | E24: ='PGCIL - KEC'!I13 -> 105 | F24: ='PGCIL - KEC'!J13 -> 375
B25: TOWER ERECTION PROGRESS SUMMARY
B26: TOTAL QTY | C26: COMPLETED UP TO PREV MONTH | D26: COMP. IN CURRENT MONTH | E26: CUMULATIVE | F26: BAL.QTY
B27: ='PGCIL - KEC'!C14 -> 480 | C27: ='PGCIL - KEC'!D14 -> 52 | D27: ='PGCIL - KEC'!H14 -> 11 | E27: ='PGCIL - KEC'!I14 -> 63 | F27: ='PGCIL - KEC'!J14 -> 417
B28: STRINGING PROGRESS SUMMARY
B29: TOTAL QTY | C29: COMPLETED UP TO PREV MONTH | D29: COMP. IN CURRENT MONTH | E29: CUMULATIVE | F29: BAL.QTY(KM)
B30: ='PGCIL - KEC'!C16 -> 184.986 | C30: ='PGCIL - KEC'!D16 -> 0 | D30: ='PGCIL - KEC'!H16 -> 0 | E30: =C30+D30 -> 0 | F30: =B30-E30 -> 184.986
B31: OPGW STRINGING PROGRESS SUMMARY
B32: TOTAL QTY | C32: COMPLETED UP TO PREV MONTH | D32: COMP. IN CURRENT MONTH | E32: CUMULATIVE | F32: BAL.QTY
B33: ='PGCIL - KEC'!C18 -> 184.986 | C33: 0 | D33: 0 | E33: 0 | F33: =B33-E33 -> 184.986

Sheet FDN
A1: ±800kV HVDC Bipole Line (Hexa Lapwing) between KPS2 (HVDC) & Nagpur (HVDC) (Part- 6) Foundation
A2: Sl. No. | B2: Location No. | C2: Tower Type | D2: Classification | E2: Concreting Volume in M3 | F2: Starting Date | G2: Todays Status | H2: Pit A | I2: Pit B | J2: Pit C | K2: Pit D | L2: Cummulative Status | M2: Completion Date | N2: Remarks | O2: Gang name | P2: Earthing Status | Q2: Earthing Completion Date
A3: 1 | B3: 125/2 | C3: A+3 | D3: DFR | F3: 45902 | H3: RCC Complete | I3: RCC Complete | J3: RCC Complete | K3: RCC Complete | L3: Completed | M3: 45915 | O3: Balaji Enterprises
A4: 2 | B4: 125/3 | C4: A+6 | D4: DFR | F4: 45909 | H4: RCC Complete | I4: RCC Complete | J4: RCC Complete | K4: RCC Complete | L4: Completed | M4: 45933 | O4: Balaji Enterprises
A5: 3 | B5: 123/1 | C5: A+0 | D5: WFR | F5: 45931 | H5: RCC Complete | I5: RCC Complete | J5: RCC Complete | K5: RCC Complete | L5: Completed | M5: 45937 | O5: R.K . Enterprises | P5: C | Q5: 45940
A6: 4 | B6: 124/1 | C6: A+6 | D6: WET Paddy | F6: 45921 | H6: RCC Complete | I6: RCC Complete | J6: RCC Complete | K6: RCC Complete | L6: Completed | M6: 45938 | O6: Balaji Enterprises | P6: C | Q6: 45982
A7: 5 | B7: 124/2 | C7: A+6 | D7: WFR | F7: 45907 | H7: RCC Complete | I7: RCC Complete | J7: RCC Complete | K7: RCC Complete | L7: Completed | M7: 45945 | O7: Jai Shri Ram Enterprises | P7: C | Q7: 45950
A8: 6 | B8: 121/7 | C8: A+0 | D8: WFR | F8: 45924 | H8: RCC Complete | I8: RCC Complete | J8: RCC Complete | K8: RCC Complete | L8: Completed | M8: 45946 | O8: Pawan enterprises | P8: C | Q8: 45968
A9: 7 | B9: 121/2 | C9: A+6 | D9: DFR | F9: 45938 | H9: RCC Complete | I9: RCC Complete | J9: RCC Complete | K9: RCC Complete | L9: Completed | M9: 45949 | O9: Balaji Enterprises | P9: C | Q9: 45950
A10: 8 | B10: 123/3 | C10: A+9 | D10: DFR | F10: 45938 | H10: RCC Complete | I10: RCC Complete | J10: RCC Complete | K10: RCC Complete | L10: Completed | M10: 45949 | O10: R.K . Enterprises | P10: C | Q10: 45952
A11: 9 | B11: 122/2 | C11: A+0 | D11: WFR | F11: 45940 | H11: RCC Complete | I11: RCC Complete | J11: RCC Complete | K11: RCC Complete | L11: Completed | M11: 45955 | O11: Jai Shri Ram Enterprises | P11: C | Q11: 45963
A12: 10 | B12: 126/5 | C12: A+3 | D12: DFR | F12: 45941 | H12: RCC Complete | I12: RCC Complete | J12: RCC Complete | K12: RCC Complete | L12: Completed | M12: 45958 | O12: Rajiya Infra. | P12: C | Q12: 45964
A13: 11 | B13: 116/1 | C13: A+3 | D13: DFR | F13: 45942 | H13: RCC Complete | I13: RCC Complete | J13: RCC Complete | K13: RCC Complete | L13: Completed | M13: 45962 | O13: B.L Construction | P13: C | Q13: 45965
A14: 12 | B14: 126/4 | C14: A+0 | D14: DFR | F14: 45942 | H14: RCC Complete | I14: RCC Complete | J14: RCC Complete | K14: RCC Complete | L14: Completed | M14: 45962 | O14: Rajiya Infra. | P14: C | Q14: 45968
A15: 13 | B15: 116/2 | C15: A+3 | D15: DFR | F15: 45942 | H15: RCC Complete | I15: RCC Complete | J15: RCC Complete | K15: RCC Complete | L15: Completed | M15: 45964 | O15: B.L Construction | P15: C | Q15: 45969
A16: 14 | B16: 124/3 | C16: A+9 | D16: WFR | F16: 45910 | H16: RCC Complete | I16: RCC Complete | J16: RCC Complete | K16: RCC Complete | L16: Completed | M16: 45965 | O16: Jai Shri Ram Enterprises
A17: 15 | B17: 123/4 | C17: A+0 | D17: WET | F17: 45930 | H17: RCC Complete | I17: RCC Complete | J17: RCC Complete | K17: RCC Complete | L17: Completed | M17: 45967 | O17: Shri Balaji Construction | P17: C | Q17: 45969
A18: 16 | B18: 126/3 | C18: A+3 | D18: DFR | F18: 45960 | H18: RCC Complete | I18: RCC Complete | J18: RCC Complete | K18: RCC Complete | L18: Completed | M18: 45967 | O18: Rajiya Infra. | P18: C | Q18: 45974
A19: 17 | B19: 130/1 | C19: A+0 | D19: DFR | F19: 45957 | H19: RCC Complete | I19: RCC Complete | J19: RCC Complete | K19: RCC Complete | L19: Completed | M19: 45969 | O19: R.K . Enterprises | P19: C | Q19: 45995
A20: 18 | B20: 111/1 | C20: A+0 | D20: DFR | F20: 45961 | H20: RCC Complete | I20: RCC Complete | J20: RCC Complete | K20: RCC Complete | L20: Completed | M20: 45970 | O20: B.L Construction
A21: 19 | B21: 126/9 | C21: A+3 | D21: DFR | F21: 45941 | H21: RCC Complete | I21: RCC Complete | J21: RCC Complete | K21: RCC Complete | L21: Completed | M21: 45972 | O21: Rajiya Infra. | P21: C | Q21: 45985
A22: 20 | B22: 123/2 | C22: A+0 | D22: WFR | F22: 45958 | H22: RCC Complete | I22: RCC Complete | J22: RCC Complete | K22: RCC Complete | L22: Completed | M22: 45974 | O22: Jai Shri Ram Enterprises | P22: C | Q22: 45981
A23: 21 | B23: 111/2 | C23: A+3 | D23: DFR | F23: 45969 | H23: RCC Complete | I23: RCC Complete | J23: RCC Complete | K23: RCC Complete | L23: Completed | M23: 45975 | O23: B.L Construction | P23: C | Q23: 45985
A24: 22 | B24: 126/10 | C24: A+0 | D24: DFR | F24: 45940 | H24: RCC Complete | I24: RCC Complete | J24: RCC Complete | K24: RCC Complete | L24: Completed | M24: 45975 | O24: Rajiya Infra. | P24: C | Q24: 45986
A25: 23 | B25: 121/6 | C25: A+0 | D25: DFR | F25: 45968 | H25: RCC Complete | I25: RCC Complete | J25: RCC Complete | K25: RCC Complete | L25: Completed | M25: 45976 | O25: Pawan enterprises
A26: 24 | B26: 121/1 | C26: A+0 | D26: DFR | F26: 45968 | H26: RCC Complete | I26: RCC Complete | J26: RCC Complete | K26: RCC Complete | L26: Completed | M26: 45977 | O26: Shri Balaji Construction | P26: C | Q26: 45980
A27: 25 | B27: 111/3 | C27: A+0 | D27: WFR | F27: 45968 | H27: RCC Complete | I27: RCC Complete | J27: RCC Complete | K27: RCC Complete | L27: Completed | M27: 45980 | O27: B.L Construction | P27: C | Q27: 45987
A28: 26 | B28: 130/3 | C28: A+3 | D28: WFR | F28: 45970 | H28: RCC Complete | I28: RCC Complete | J28: RCC Complete | K28: RCC Complete | L28: Completed | M28: 45980 | O28: R.K . Enterprises | P28: C | Q28: 45987
A29: 27 | B29: 103/2 | C29: A+0 | D29: WET PADDY | F29: 45970 | H29: RCC Complete | I29: RCC Complete | J29: RCC Complete | K29: RCC Complete | L29: Completed | M29: 45981 | O29: MUKESH MEHTA | P29: C | Q29: 45984
A30: 28 | B30: 124/4 | C30: A+3 | D30: WFR | F30: 45969 | H30: RCC Complete | I30: RCC Complete | J30: RCC Complete | K30: RCC Complete | L30: Completed | M30: 45982 | O30: Jai Shri Ram Enterprises | P30: C | Q30: 45984
A31: 29 | B31: 126/2 | C31: A+9 | D31: WFR | F31: 45974 | H31: RCC Complete | I31: RCC Complete | J31: RCC Complete | K31: RCC Complete | L31: Completed | M31: 45982 | O31: Rajiya Infra. | P31: C | Q31: 45984
A32: 30 | B32: 121/4 | C32: A+0 | D32: DFR | F32: 45977 | H32: RCC Complete | I32: RCC Complete | J32: RCC Complete | K32: RCC Complete | L32: Completed | M32: 45983 | O32: Pawan enterprises | P32: C | Q32: 45986
A33: 31 | B33: 111/4 | C33: A+0 | D33: DFR | F33: 45975 | H33: RCC Complete | I33: RCC Complete | J33: RCC Complete | K33: RCC Complete | L33: Completed | M33: 45984 | O33: B.L Construction | P33: C | Q33: 45986
A34: 32 | B34: 103/3 | C34: A+3 | D34: WET PADDY | F34: 45968 | H34: RCC Complete | I34: RCC Complete | J34: RCC Complete | K34: RCC Complete | L34: Completed | M34: 45985 | O34: MUKESH MEHTA | P34: C | Q34: 45987
A35: 33 | B35: 134/2 | C35: A+3 | D35: WFR | F35: 45976 | H35: RCC Complete | I35: RCC Complete | J35: RCC Complete | K35: RCC Complete | L35: Completed | M35: 45985 | O35: R.K . Enterprises
A36: 34 | B36: 103/1 | C36: A+6 | D36: WET PADDY | F36: 45984 | H36: RCC Complete | I36: RCC Complete | J36: RCC Complete | K36: RCC Complete | L36: Completed | M36: 45989 | O36: MUKESH MEHTA | P36: C | Q36: 45993
A37: 35 | B37: 111/5 | C37: A+6 | D37: DFR | F37: 45981 | H37: RCC Complete | I37: RCC Complete | J37: RCC Complete | K37: RCC Complete | L37: Completed | M37: 45989 | O37: B.L Construction | P37: C | Q37: 45991
A38: 36 | B38: 134/3 | C38: A+6 | D38: WFR | F38: 45985 | H38: RCC Complete | I38: RCC Complete | J38: RCC Complete | K38: RCC Complete | L38: Completed | M38: 45989 | O38: R.K . Enterprises
A39: 37 | B39: 102/7 | C39: A+0 | D39: WET PADDY | F39: 45968 | H39: RCC Complete | I39: RCC Complete | J39: RCC Complete | K39: RCC Complete | L39: Completed | M39: 45991 | O39: Rajiya Infra. | P39: C | Q39: 46000
A40: 38 | B40: 110/2 | C40: A+0 | D40: DFR | F40: 45984 | H40: RCC Complete | I40: RCC Complete | J40: RCC Complete | K40: RCC Complete | L40: Completed | M40: 45991 | O40: Shri Balaji Construction | P40: C | Q40: 45996
...

Sheet FDN Completed
A1: Foundation
A2: Sl. No. | B2: Location No. | C2: Tower Type | D2: Classification | E2: Starting Date | F2: Cumulative Status | G2: Completion Date | H2: Remarks | I2: Gang name | J2: Earthing Status | K2: Earthing Completion Date
A3: 1 | B3: =FDN!B3 -> 125/2 | C3: =VLOOKUP($B3,FDN!$B3:D166,2,0) -> A+3 | D3: =VLOOKUP($B3,FDN!$B3:E166,3,0) -> DFR | E3: =VLOOKUP(B3,FDN!B3:F166,5,0) -> 45902 | F3: =VLOOKUP(B3,FDN!B3:L166,11,0) -> Completed | G3: =VLOOKUP(B3,FDN!B3:M166,12,0) -> 45915 | I3: =VLOOKUP(B3,FDN!B3:O166,14,0) -> Balaji Enterprises
A4: =A3+1 -> 2 | B4: =FDN!B4 -> 125/3 | C4: =VLOOKUP(B4,FDN!B4:D166,2,0) -> A+6 | D4: =VLOOKUP($B4,FDN!$B4:E166,3,0) -> DFR | E4: =VLOOKUP(B4,FDN!B4:F166,5,0) -> 45909 | F4: =VLOOKUP(B4,FDN!B4:L166,11,0) -> Completed | G4: =VLOOKUP(B4,FDN!B4:M166,12,0) -> 45933 | I4: =VLOOKUP(B4,FDN!B4:O166,14,0) -> Balaji Enterprises
A5: =A4+1 -> 3 | B5: =FDN!B5 -> 123/1 | C5: =VLOOKUP(B5,FDN!B5:D167,2,0) -> A+0 | D5: =VLOOKUP($B5,FDN!$B5:E167,3,0) -> WFR | E5: =VLOOKUP(B5,FDN!B5:F167,5,0) -> 45931 | F5: =VLOOKUP(B5,FDN!B5:L167,11,0) -> Completed | G5: =VLOOKUP(B5,FDN!B5:M167,12,0) -> 45937 | I5: =VLOOKUP(B5,FDN!B5:O167,14,0) -> R.K . Enterprises | J5: C | K5: 45940
A6: =A5+1 -> 4 | B6: =FDN!B6 -> 124/1 | C6: =VLOOKUP(B6,FDN!B6:D169,2,0) -> A+6 | D6: =VLOOKUP($B6,FDN!$B6:E169,3,0) -> WET Paddy | E6: =VLOOKUP(B6,FDN!B6:F169,5,0) -> 45921 | F6: =VLOOKUP(B6,FDN!B6:L169,11,0) -> Completed | G6: =VLOOKUP(B6,FDN!B6:M169,12,0) -> 45938 | I6: =VLOOKUP(B6,FDN!B6:O169,14,0) -> Balaji Enterprises | J6: C | K6: 45982
A7: =A6+1 -> 5 | B7: =FDN!B7 -> 124/2 | C7: =VLOOKUP(B7,FDN!B7:D170,2,0) -> A+6 | D7: =VLOOKUP($B7,FDN!$B7:E170,3,0) -> WFR | E7: =VLOOKUP(B7,FDN!B7:F170,5,0) -> 45907 | F7: =VLOOKUP(B7,FDN!B7:L170,11,0) -> Completed | G7: =VLOOKUP(B7,FDN!B7:M170,12,0) -> 45945 | I7: =VLOOKUP(B7,FDN!B7:O170,14,0) -> Jai Shri Ram Enterprises | J7: C | K7: 45950
A8: =A7+1 -> 6 | B8: =FDN!B8 -> 121/7 | C8: =VLOOKUP(B8,FDN!B8:D171,2,0) -> A+0 | D8: =VLOOKUP($B8,FDN!$B8:E171,3,0) -> WFR | E8: =VLOOKUP(B8,FDN!B8:F171,5,0) -> 45924 | F8: =VLOOKUP(B8,FDN!B8:L171,11,0) -> Completed | G8: =VLOOKUP(B8,FDN!B8:M171,12,0) -> 45946 | I8: =VLOOKUP(B8,FDN!B8:O171,14,0) -> Pawan enterprises | J8: C | K8: 45968
A9: =A8+1 -> 7 | B9: =FDN!B9 -> 121/2 | C9: =VLOOKUP(B9,FDN!B9:D172,2,0) -> A+6 | D9: =VLOOKUP($B9,FDN!$B9:E172,3,0) -> DFR | E9: =VLOOKUP(B9,FDN!B9:F172,5,0) -> 45938 | F9: =VLOOKUP(B9,FDN!B9:L172,11,0) -> Completed | G9: =VLOOKUP(B9,FDN!B9:M172,12,0) -> 45949 | I9: =VLOOKUP(B9,FDN!B9:O172,14,0) -> Balaji Enterprises | J9: C | K9: 45950
A10: =A9+1 -> 8 | B10: =FDN!B10 -> 123/3 | C10: =VLOOKUP(B10,FDN!B10:D173,2,0) -> A+9 | D10: =VLOOKUP($B10,FDN!$B10:E173,3,0) -> DFR | E10: =VLOOKUP(B10,FDN!B10:F173,5,0) -> 45938 | F10: =VLOOKUP(B10,FDN!B10:L173,11,0) -> Completed | G10: =VLOOKUP(B10,FDN!B10:M173,12,0) -> 45949 | I10: =VLOOKUP(B10,FDN!B10:O173,14,0) -> R.K . Enterprises | J10: C | K10: 45952
A11: =A10+1 -> 9 | B11: =FDN!B11 -> 122/2 | C11: =VLOOKUP(B11,FDN!B11:D174,2,0) -> A+0 | D11: =VLOOKUP($B11,FDN!$B11:E174,3,0) -> WFR | E11: =VLOOKUP(B11,FDN!B11:F174,5,0) -> 45940 | F11: =VLOOKUP(B11,FDN!B11:L174,11,0) -> Completed | G11: =VLOOKUP(B11,FDN!B11:M174,12,0) -> 45955 | I11: =VLOOKUP(B11,FDN!B11:O174,14,0) -> Jai Shri Ram Enterprises | J11: C | K11: 45963
A12: =A11+1 -> 10 | B12: =FDN!B12 -> 126/5 | C12: =VLOOKUP(B12,FDN!B12:D175,2,0) -> A+3 | D12: =VLOOKUP($B12,FDN!$B12:E175,3,0) -> DFR | E12: =VLOOKUP(B12,FDN!B12:F175,5,0) -> 45941 | F12: =VLOOKUP(B12,FDN!B12:L175,11,0) -> Completed | G12: =VLOOKUP(B12,FDN!B12:M175,12,0) -> 45958 | I12: =VLOOKUP(B12,FDN!B12:O175,14,0) -> Rajiya Infra. | J12: C | K12: 45964
A13: =A12+1 -> 11 | B13: =FDN!B13 -> 116/1 | C13: =VLOOKUP(B13,FDN!B13:D176,2,0) -> A+3 | D13: =VLOOKUP($B13,FDN!$B13:E176,3,0) -> DFR | E13: =VLOOKUP(B13,FDN!B13:F176,5,0) -> 45942 | F13: =VLOOKUP(B13,FDN!B13:L176,11,0) -> Completed | G13: =VLOOKUP(B13,FDN!B13:M176,12,0) -> 45962 | I13: =VLOOKUP(B13,FDN!B13:O176,14,0) -> B.L Construction | J13: C | K13: 45965
A14: =A13+1 -> 12 | B14: =FDN!B14 -> 126/4 | C14: =VLOOKUP(B14,FDN!B14:D177,2,0) -> A+0 | D14: =VLOOKUP($B14,FDN!$B14:E177,3,0) -> DFR | E14: =VLOOKUP(B14,FDN!B14:F177,5,0) -> 45942 | F14: =VLOOKUP(B14,FDN!B14:L177,11,0) -> Completed | G14: =VLOOKUP(B14,FDN!B14:M177,12,0) -> 45962 | I14: =VLOOKUP(B14,FDN!B14:O177,14,0) -> Rajiya Infra. | J14: C | K14: 45968
A15: =A14+1 -> 13 | B15: =FDN!B15 -> 116/2 | C15: =VLOOKUP(B15,FDN!B15:D178,2,0) -> A+3 | D15: =VLOOKUP($B15,FDN!$B15:E178,3,0) -> DFR | E15: =VLOOKUP(B15,FDN!B15:F178,5,0) -> 45942 | F15: =VLOOKUP(B15,FDN!B15:L178,11,0) -> Completed | G15: =VLOOKUP(B15,FDN!B15:M178,12,0) -> 45964 | I15: =VLOOKUP(B15,FDN!B15:O178,14,0) -> B.L Construction | J15: C | K15: 45969
A16: =A15+1 -> 14 | B16: =FDN!B16 -> 124/3 | C16: =VLOOKUP(B16,FDN!B16:D179,2,0) -> A+9 | D16: =VLOOKUP($B16,FDN!$B16:E179,3,0) -> WFR | E16: =VLOOKUP(B16,FDN!B16:F179,5,0) -> 45910 | F16: =VLOOKUP(B16,FDN!B16:L179,11,0) -> Completed | G16: =VLOOKUP(B16,FDN!B16:M179,12,0) -> 45965 | I16: =VLOOKUP(B16,FDN!B16:O179,14,0) -> Jai Shri Ram Enterprises
A17: =A16+1 -> 15 | B17: =FDN!B17 -> 123/4 | C17: =VLOOKUP(B17,FDN!B17:D180,2,0) -> A+0 | D17: =VLOOKUP($B17,FDN!$B17:E180,3,0) -> WET | E17: =VLOOKUP(B17,FDN!B17:F180,5,0) -> 45930 | F17: =VLOOKUP(B17,FDN!B17:L180,11,0) -> Completed | G17: =VLOOKUP(B17,FDN!B17:M180,12,0) -> 45967 | I17: =VLOOKUP(B17,FDN!B17:O180,14,0) -> Shri Balaji Construction | J17: C | K17: 45969
A18: =A17+1 -> 16 | B18: =FDN!B18 -> 126/3 | C18: =VLOOKUP(B18,FDN!B18:D181,2,0) -> A+3 | D18: =VLOOKUP($B18,FDN!$B18:E181,3,0) -> DFR | E18: =VLOOKUP(B18,FDN!B18:F181,5,0) -> 45960 | F18: =VLOOKUP(B18,FDN!B18:L181,11,0) -> Completed | G18: =VLOOKUP(B18,FDN!B18:M181,12,0) -> 45967 | I18: =VLOOKUP(B18,FDN!B18:O181,14,0) -> Rajiya Infra. | J18: C | K18: 45974
A19: =A18+1 -> 17 | B19: =FDN!B19 -> 130/1 | C19: =VLOOKUP(B19,FDN!B19:D182,2,0) -> A+0 | D19: =VLOOKUP($B19,FDN!$B19:E182,3,0) -> DFR | E19: =VLOOKUP(B19,FDN!B19:F182,5,0) -> 45957 | F19: =VLOOKUP(B19,FDN!B19:L182,11,0) -> Completed | G19: =VLOOKUP(B19,FDN!B19:M182,12,0) -> 45969 | I19: =VLOOKUP(B19,FDN!B19:O182,14,0) -> R.K . Enterprises | J19: C | K19: 45995
A20: =A19+1 -> 18 | B20: =FDN!B20 -> 111/1 | C20: =VLOOKUP(B20,FDN!B20:D183,2,0) -> A+0 | D20: =VLOOKUP($B20,FDN!$B20:E183,3,0) -> DFR | E20: =VLOOKUP(B20,FDN!B20:F183,5,0) -> 45961 | F20: =VLOOKUP(B20,FDN!B20:L183,11,0) -> Completed | G20: =VLOOKUP(B20,FDN!B20:M183,12,0) -> 45970 | I20: =VLOOKUP(B20,FDN!B20:O183,14,0) -> B.L Construction
A21: =A20+1 -> 19 | B21: =FDN!B21 -> 126/9 | C21: =VLOOKUP(B21,FDN!B21:D184,2,0) -> A+3 | D21: =VLOOKUP($B21,FDN!$B21:E184,3,0) -> DFR | E21: =VLOOKUP(B21,FDN!B21:F184,5,0) -> 45941 | F21: =VLOOKUP(B21,FDN!B21:L184,11,0) -> Completed | G21: =VLOOKUP(B21,FDN!B21:M184,12,0) -> 45972 | I21: =VLOOKUP(B21,FDN!B21:O184,14,0) -> Rajiya Infra. | J21: C | K21: 45985
A22: =A21+1 -> 20 | B22: =FDN!B22 -> 123/2 | C22: =VLOOKUP(B22,FDN!B22:D185,2,0) -> A+0 | D22: =VLOOKUP($B22,FDN!$B22:E185,3,0) -> WFR | E22: =VLOOKUP(B22,FDN!B22:F185,5,0) -> 45958 | F22: =VLOOKUP(B22,FDN!B22:L185,11,0) -> Completed | G22: =VLOOKUP(B22,FDN!B22:M185,12,0) -> 45974 | I22: =VLOOKUP(B22,FDN!B22:O185,14,0) -> Jai Shri Ram Enterprises | J22: C | K22: 45981
A23: =A22+1 -> 21 | B23: =FDN!B23 -> 111/2 | C23: =VLOOKUP(B23,FDN!B23:D186,2,0) -> A+3 | D23: =VLOOKUP($B23,FDN!$B23:E186,3,0) -> DFR | E23: =VLOOKUP(B23,FDN!B23:F186,5,0) -> 45969 | F23: =VLOOKUP(B23,FDN!B23:L186,11,0) -> Completed | G23: =VLOOKUP(B23,FDN!B23:M186,12,0) -> 45975 | I23: =VLOOKUP(B23,FDN!B23:O186,14,0) -> B.L Construction | J23: C | K23: 45985
A24: =A23+1 -> 22 | B24: =FDN!B24 -> 126/10 | C24: =VLOOKUP(B24,FDN!B24:D187,2,0) -> A+0 | D24: =VLOOKUP($B24,FDN!$B24:E187,3,0) -> DFR | E24: =VLOOKUP(B24,FDN!B24:F187,5,0) -> 45940 | F24: =VLOOKUP(B24,FDN!B24:L187,11,0) -> Completed | G24: =VLOOKUP(B24,FDN!B24:M187,12,0) -> 45975 | I24: =VLOOKUP(B24,FDN!B24:O187,14,0) -> Rajiya Infra. | J24: C | K24: 45986
A25: =A24+1 -> 23 | B25: =FDN!B25 -> 121/6 | C25: =VLOOKUP(B25,FDN!B25:D188,2,0) -> A+0 | D25: =VLOOKUP($B25,FDN!$B25:E188,3,0) -> DFR | E25: =VLOOKUP(B25,FDN!B25:F188,5,0) -> 45968 | F25: =VLOOKUP(B25,FDN!B25:L188,11,0) -> Completed | G25: =VLOOKUP(B25,FDN!B25:M188,12,0) -> 45976 | I25: =VLOOKUP(B25,FDN!B25:O188,14,0) -> Pawan enterprises
A26: =A25+1 -> 24 | B26: =FDN!B26 -> 121/1 | C26: =VLOOKUP(B26,FDN!B26:D189,2,0) -> A+0 | D26: =VLOOKUP($B26,FDN!$B26:E189,3,0) -> DFR | E26: =VLOOKUP(B26,FDN!B26:F189,5,0) -> 45968 | F26: =VLOOKUP(B26,FDN!B26:L189,11,0) -> Completed | G26: =VLOOKUP(B26,FDN!B26:M189,12,0) -> 45977 | I26: =VLOOKUP(B26,FDN!B26:O189,14,0) -> Shri Balaji Construction | J26: C | K26: 45980
A27: =A26+1 -> 25 | B27: =FDN!B27 -> 111/3 | C27: =VLOOKUP(B27,FDN!B27:D190,2,0) -> A+0 | D27: =VLOOKUP($B27,FDN!$B27:E190,3,0) -> WFR | E27: =VLOOKUP(B27,FDN!B27:F190,5,0) -> 45968 | F27: =VLOOKUP(B27,FDN!B27:L190,11,0) -> Completed | G27: =VLOOKUP(B27,FDN!B27:M190,12,0) -> 45980 | I27: =VLOOKUP(B27,FDN!B27:O190,14,0) -> B.L Construction | J27: C | K27: 45987
A28: =A27+1 -> 26 | B28: =FDN!B28 -> 130/3 | C28: =VLOOKUP(B28,FDN!B28:D191,2,0) -> A+3 | D28: =VLOOKUP($B28,FDN!$B28:E191,3,0) -> WFR | E28: =VLOOKUP(B28,FDN!B28:F191,5,0) -> 45970 | F28: =VLOOKUP(B28,FDN!B28:L191,11,0) -> Completed | G28: =VLOOKUP(B28,FDN!B28:M191,12,0) -> 45980 | I28: =VLOOKUP(B28,FDN!B28:O191,14,0) -> R.K . Enterprises | J28: C | K28: 45987
A29: =A28+1 -> 27 | B29: =FDN!B29 -> 103/2 | C29: =VLOOKUP(B29,FDN!B29:D192,2,0) -> A+0 | D29: =VLOOKUP($B29,FDN!$B29:E192,3,0) -> WET PADDY | E29: =VLOOKUP(B29,FDN!B29:F192,5,0) -> 45970 | F29: =VLOOKUP(B29,FDN!B29:L192,11,0) -> Completed | G29: =VLOOKUP(B29,FDN!B29:M192,12,0) -> 45981 | I29: =VLOOKUP(B29,FDN!B29:O192,14,0) -> MUKESH MEHTA | J29: C | K29: 45984
A30: =A29+1 -> 28 | B30: =FDN!B30 -> 124/4 | C30: =VLOOKUP(B30,FDN!B30:D193,2,0) -> A+3 | D30: =VLOOKUP($B30,FDN!$B30:E193,3,0) -> WFR | E30: =VLOOKUP(B30,FDN!B30:F193,5,0) -> 45969 | F30: =VLOOKUP(B30,FDN!B30:L193,11,0) -> Completed | G30: =VLOOKUP(B30,FDN!B30:M193,12,0) -> 45982 | I30: =VLOOKUP(B30,FDN!B30:O193,14,0) -> Jai Shri Ram Enterprises | J30: C | K30: 45984
A31: =A30+1 -> 29 | B31: =FDN!B31 -> 126/2 | C31: =VLOOKUP(B31,FDN!B31:D194,2,0) -> A+9 | D31: =VLOOKUP($B31,FDN!$B31:E194,3,0) -> WFR | E31: =VLOOKUP(B31,FDN!B31:F194,5,0) -> 45974 | F31: =VLOOKUP(B31,FDN!B31:L194,11,0) -> Completed | G31: =VLOOKUP(B31,FDN!B31:M194,12,0) -> 45982 | I31: =VLOOKUP(B31,FDN!B31:O194,14,0) -> Rajiya Infra. | J31: C | K31: 45984
A32: =A31+1 -> 30 | B32: =FDN!B32 -> 121/4 | C32: =VLOOKUP(B32,FDN!B32:D195,2,0) -> A+0 | D32: =VLOOKUP($B32,FDN!$B32:E195,3,0) -> DFR | E32: =VLOOKUP(B32,FDN!B32:F195,5,0) -> 45977 | F32: =VLOOKUP(B32,FDN!B32:L195,11,0) -> Completed | G32: =VLOOKUP(B32,FDN!B32:M195,12,0) -> 45983 | I32: =VLOOKUP(B32,FDN!B32:O195,14,0) -> Pawan enterprises | J32: C | K32: 45986
A33: =A32+1 -> 31 | B33: =FDN!B33 -> 111/4 | C33: =VLOOKUP(B33,FDN!B33:D196,2,0) -> A+0 | D33: =VLOOKUP($B33,FDN!$B33:E196,3,0) -> DFR | E33: =VLOOKUP(B33,FDN!B33:F196,5,0) -> 45975 | F33: =VLOOKUP(B33,FDN!B33:L196,11,0) -> Completed | G33: =VLOOKUP(B33,FDN!B33:M196,12,0) -> 45984 | I33: =VLOOKUP(B33,FDN!B33:O196,14,0) -> B.L Construction | J33: C | K33: 45986
A34: =A33+1 -> 32 | B34: =FDN!B34 -> 103/3 | C34: =VLOOKUP(B34,FDN!B34:D197,2,0) -> A+3 | D34: =VLOOKUP($B34,FDN!$B34:E197,3,0) -> WET PADDY | E34: =VLOOKUP(B34,FDN!B34:F197,5,0) -> 45968 | F34: =VLOOKUP(B34,FDN!B34:L197,11,0) -> Completed | G34: =VLOOKUP(B34,FDN!B34:M197,12,0) -> 45985 | I34: =VLOOKUP(B34,FDN!B34:O197,14,0) -> MUKESH MEHTA | J34: C | K34: 45987
A35: =A34+1 -> 33 | B35: =FDN!B35 -> 134/2 | C35: =VLOOKUP(B35,FDN!B35:D198,2,0) -> A+3 | D35: =VLOOKUP($B35,FDN!$B35:E198,3,0) -> WFR | E35: =VLOOKUP(B35,FDN!B35:F198,5,0) -> 45976 | F35: =VLOOKUP(B35,FDN!B35:L198,11,0) -> Completed | G35: =VLOOKUP(B35,FDN!B35:M198,12,0) -> 45985 | I35: =VLOOKUP(B35,FDN!B35:O198,14,0) -> R.K . Enterprises
A36: =A35+1 -> 34 | B36: =FDN!B36 -> 103/1 | C36: =VLOOKUP(B36,FDN!B36:D199,2,0) -> A+6 | D36: =VLOOKUP($B36,FDN!$B36:E199,3,0) -> WET PADDY | E36: =VLOOKUP(B36,FDN!B36:F199,5,0) -> 45984 | F36: =VLOOKUP(B36,FDN!B36:L199,11,0) -> Completed | G36: =VLOOKUP(B36,FDN!B36:M199,12,0) -> 45989 | I36: =VLOOKUP(B36,FDN!B36:O199,14,0) -> MUKESH MEHTA | J36: C | K36: 45993
A37: =A36+1 -> 35 | B37: =FDN!B37 -> 111/5 | C37: =VLOOKUP(B37,FDN!B37:D200,2,0) -> A+6 | D37: =VLOOKUP($B37,FDN!$B37:E200,3,0) -> DFR | E37: =VLOOKUP(B37,FDN!B37:F200,5,0) -> 45981 | F37: =VLOOKUP(B37,FDN!B37:L200,11,0) -> Completed | G37: =VLOOKUP(B37,FDN!B37:M200,12,0) -> 45989 | I37: =VLOOKUP(B37,FDN!B37:O200,14,0) -> B.L Construction | J37: C | K37: 45991
A38: =A37+1 -> 36 | B38: =FDN!B38 -> 134/3 | C38: =VLOOKUP(B38,FDN!B38:D201,2,0) -> A+6 | D38: =VLOOKUP($B38,FDN!$B38:E201,3,0) -> WFR | E38: =VLOOKUP(B38,FDN!B38:F201,5,0) -> 45985 | F38: =VLOOKUP(B38,FDN!B38:L201,11,0) -> Completed | G38: =VLOOKUP(B38,FDN!B38:M201,12,0) -> 45989 | I38: =VLOOKUP(B38,FDN!B38:O201,14,0) -> R.K . Enterprises
A39: =A38+1 -> 37 | B39: =FDN!B39 -> 102/7 | C39: =VLOOKUP(B39,FDN!B39:D202,2,0) -> A+0 | D39: =VLOOKUP($B39,FDN!$B39:E202,3,0) -> WET PADDY | E39: =VLOOKUP(B39,FDN!B39:F202,5,0) -> 45968 | F39: =VLOOKUP(B39,FDN!B39:L202,11,0) -> Completed | G39: =VLOOKUP(B39,FDN!B39:M202,12,0) -> 45991 | I39: =VLOOKUP(B39,FDN!B39:O202,14,0) -> Rajiya Infra. | J39: C | K39: 46000
A40: =A39+1 -> 38 | B40: =FDN!B40 -> 110/2 | C40: =VLOOKUP(B40,FDN!B40:D203,2,0) -> A+0 | D40: =VLOOKUP($B40,FDN!$B40:E203,3,0) -> DFR | E40: =VLOOKUP(B40,FDN!B40:F203,5,0) -> 45984 | F40: =VLOOKUP(B40,FDN!B40:L203,11,0) -> Completed | G40: =VLOOKUP(B40,FDN!B40:M203,12,0) -> 45991 | I40: =VLOOKUP(B40,FDN!B40:O203,14,0) -> Shri Balaji Construction | J40: C | K40: 45996
...

Sheet PGCIL - KEC
A1: TA-602 KEC INTERNATIONAL LIMITED | M1: =TODAY() -> 46185
A2: ='Project Details'!C2 -> Powergrid West Central Transmission Ltd.
A3: ='Project Details'!B2 -> Name of Line: Package TL-06 for ±800kV HVDC Bipole Line (Hexa Lapwing) between KPS2 (HVDC) & Nagpur (HVDC) (with dedicated metallic Return) -Part- 6 Transmission Line
A4: NOA No.: CC/T/W-TW/DOM/A06/24/04774/NOA-2/25-105721/01&02 Dt:13-05-2025
A5: Sr No. | B5: Activity | C5: Estimated Quantity | D5: Cumm. Progress up to till last Month (May'26) | E5: Target as per L2 Schedule Cummulative (upto May'26) | F5: L3 Plan for the month (May'26 ) | G5: Today's Progress | H5: Progress in this month | I5: Cumm. Progress till date | J5: Cumm. Balance | K5: WIP | L5: No of Gangs | M5: Remark
A6: 1 | B6: Route Alignment (Km) | C6: ='800kV HVDC TA-602'!C8 -> 185.149 | D6: =C6 -> 185.149 | E6: =C6 -> 185.149 | F6: =C6-E6 -> 0 | I6: =D6+H6 -> 185.149 | J6: =C6-I6 -> 0
A7: 2 | B7: Detailed Survey (Km) | C7: 184.986 | D7: ='800kV HVDC TA-602'!K9 -> 166.531 | E7: =C7 -> 184.986 | F7: =C7-D7 -> 18.455 | I7: =D7+H7 -> 166.531 | J7: =C7-I7 -> 18.455 | K7: 3.71 | M7: Hold Due to Brick Kiln(3.71Kms)
A8: 3 | B8: Profiling (Km) | C8: =C7 -> 184.986 | D8: =C8 -> 184.986 | E8: =D8 -> 184.986 | F8: =C8-E8 -> 0 | I8: =D8+H8 -> 184.986 | J8: =C8-I8 -> 0
A9: 4 | B9: Check Survey (Km) | C9: =C8 -> 184.986 | D9: ='800kV HVDC TA-602'!K10 -> 136.139 | E9: =C9 -> 184.986 | F9: =C9-D9 -> 48.847 | I9: =D9+H9 -> 136.139 | J9: =C9-I9 -> 48.847
A10: 5 | B10: Soil Investigation (Nos.) | C10: 31 | D10: 17 | H10: 1 | I10: =D10+H10 -> 18 | J10: =C10-I10 -> 13
A11: 6 | B11: Excavation | C11: 480 | D11: 154 | E11: ='800kV HVDC TA-602'!C15 -> 167 | F11: 30 | H11: 12 | I11: =D11+H11 -> 166 | J11: =C11-I11 -> 314 | K11: 4
A12: 7 | B12: Foundation (Nos.) | C12: =C11 -> 480 | D12: 154 | E12: ='800kV HVDC TA-602'!C16 -> 167 | F12: =F11 -> 30 | H12: 7 | I12: =D12+H12 -> 161 | J12: =C12-I12 -> 319 | K12: 5 | L12: 4 | M12: ROW"67/3"(10/06/2026)
A13: 8 | B13: Earthing (Nos.) | C13: =C12 -> 480 | D13: 96 | E13: =E12 -> 167 | F13: =F12 -> 30 | G13: 1 | H13: 9 | I13: =D13+H13 -> 105 | J13: =C13-I13 -> 375
A14: 9 | B14: Tower Erection (Nos) | C14: =C13 -> 480 | D14: 52 | E14: ='800kV HVDC TA-602'!C17 -> 102 | F14: 35 | G14: 2 | H14: 11 | I14: =D14+H14 -> 63 | J14: =C14-I14 -> 417 | K14: 5 | L14: 4
A15: 10 | B15: Tack Welding | C15: =C14 -> 480 | D15: 0 | E15: =E14 -> 102 | F15: 35 | H15: 0 | I15: =D15+H15 -> 0 | J15: =C15-I15 -> 480 | K15: 0 | L15: 0
A16: 11 | B16: Stringing (Km) | C16: =$C$9 -> 184.986 | D16: 0 | E16: ='800kV HVDC TA-602'!C19 -> 10 | F16: 0 | H16: 0 | I16: =H16+D16 -> 0 | J16: =C16-I16 -> 184.986 | K16: 0 | L16: 0
A17: a) | B17: Paying Out | C17: =$C$9 -> 184.986 | D17: 0 | E17: 10 | F17: 0 | H17: 0 | I17: =H17+D17 -> 0 | J17: =C17-I17 -> 184.986
A18: b) | B18: Final Sag | C18: =$C$9 -> 184.986 | D18: 0 | E18: 10 | F18: 0 | H18: 0 | I18: =H18+D18 -> 0 | J18: =C18-I18 -> 184.986
A19: 12 | B19: OPGW (Km) | C19: =$C$9 -> 184.986 | D19: 0 | E19: 0 | F19: 0 | I19: =D19+H19 -> 0 | J19: =C19-I19 -> 184.986

Sheet Survey details 11-06-2026
A1: Survey Status | L1: Date: 10-06-2026 | M1: 46092
A2: Project Name & Code | D2: TA-602
A3: Sl No | B3: Section | C3: Kms | D3: Detailed Survey | I3: Check Survey
D4: Completed | E4: Submitted | F4: Approved | G4: Remarks | H4: Surveyor | I4: Completed | J4: Submitted | K4: Approved | L4: Remarks | M4: Surveyor
A5: 1 | B5: AP0 to AP11 | C5: 8.123 | D5: 8.1225 | E5: 8.123 | G5: Due to Brick -kiln Hold B/W Section AP13 to AP14(3.710) Submitted 26-05-2026
A6: 2 | B6: AP11 to AP16 | C6: 3.71 | D6: 3.71 | E6: =D6 -> 3.71 | G6: Submitted to PGCIL (25-04-2026) 11.823Kms | H6: Mr. Tapas Das
A7: 3 | B7: AP16 to AP29 | C7: 7.454 | D7: 7.454 | E7: =D7 -> 7.454 | F7: =E7 -> 7.454 | G7: Approved | H7: Mr. Hemanta/Mr. Tapas Das | I7: 30.3921 | J7: =I7 -> 30.3921 | L7: AP33- AP51(19.783) 19-05-2026 AP 16 to AP 33 (10.610 Kms). 28-05-2026
A8: 4 | B8: AP29 to AP35 | C8: 4.653 | D8: 4.6525 | E8: =D8 -> 4.6525 | F8: =E8 -> 4.6525 | G8: Approved | H8: Mr. Hemanta/Mr. Tapas Das
A9: 5 | B9: AP35 to AP 40 | C9: 6.557 | D9: 6.557 | E9: =D9 -> 6.557 | F9: =E9 -> 6.557 | G9: Approved | H9: Mr. Hemanta/Mr. Tapas Das
A10: 6 | B10: AP 40 to AP 51 | C10: 11.729 | D10: 11.7286 | E10: =D10 -> 11.7286 | F10: =E10 -> 11.7286 | G10: Approved | H10: Mr. Hemanta/Mr. Tapas Das | P10: =D7+D9+#REF!+#REF! -> #REF!
A11: 10 | E11: =D11 -> 0 | F11: =E11 -> 0
A12: 11 | B12: AP0 to AP23 | E12: =D12 -> 0 | F12: =E12 -> 0 | G12: Route Diversion due to Newly under constrction house (Alternate Route Submitted) | H12: Hemanta Malik/Tapas Das/Rakesh Debnath | I12: =D12 -> 0 | K12: =J12 -> 0
A13: 12 | B13: AP33 to AP38A | E13: =D13 -> 0 | F13: =E13 -> 0 | H13: Hemanta Malik/Tapas Das/Rakesh Debnath | I13: =D13 -> 0 | K13: =J13 -> 0
A14: 13 | B14: AP38 to AP51 | E14: =D14 -> 0 | F14: =E14 -> 0 | H14: Hemanta Malik/Tapas Das/Rakesh Debnath | I14: =D14 -> 0 | K14: =J14 -> 0
A15: 7 | B15: AP51 to AP62 | C15: 8.344 | D15: 8.345 | E15: =D15 -> 8.345 | F15: =E15 -> 8.345 | G15: Approved | H15: Hemanta Malik/Tapas Das/Rakesh Debnath | I15: =F15 -> 8.345 | J15: =I15 -> 8.345 | K15: =J15 -> 8.345 | L15: \ | M15: Hemanta Malik/Tapas Das/Rakesh Debnath
A16: 8 | B16: AP62 to AP 64 | C16: 3.615 | D16: 3.615 | E16: =D16 -> 3.615 | F16: =E16 -> 3.615 | G16: Approved | H16: Hemanta Malik/Tapas Das/Rakesh Debnath | I16: =F16 -> 3.615 | J16: =I16 -> 3.615 | K16: =J16 -> 3.615 | L16: Approved | M16: Hemanta Malik/Tapas Das/Rakesh Debnath
A17: 9 | B17: AP64 to AP71 | C17: 9.709 | D17: 9.71 | E17: =D17 -> 9.71 | F17: =E17 -> 9.71 | G17: Approved | H17: Hemanta Malik/Tapas Das/Rakesh Debnath | I17: =F17 -> 9.71 | J17: =I17 -> 9.71 | K17: =J17 -> 9.71 | L17: Approved | M17: Hemanta Malik/Tapas Das/Rakesh Debnath
A18: 13 | B18: AP71 to AP75 | C18: 3.714 | D18: 3.787 | E18: =D18 -> 3.787 | F18: =E18 -> 3.787 | G18: Approved | H18: Hemanta Malik/Tapas Das/Rakesh Debnath | I18: =F18 -> 3.787 | J18: =I18 -> 3.787 | K18: =J18 -> 3.787 | L18: Approved | M18: Hemanta Malik/Tapas Das/Rakesh Debnath
A19: 14 | B19: AP75 to AP76 | C19: 1.238 | D19: 1.178 | E19: =D19 -> 1.178 | F19: =E19 -> 1.178 | G19: Approved | H19: Hemanta Malik/Tapas Das/Rakesh Debnath | I19: =F19 -> 1.178 | J19: =I19 -> 1.178 | K19: =J19 -> 1.178 | L19: Approved | M19: Hemanta Malik/Tapas Das/Rakesh Debnath
A20: 15 | B20: AP76 to AP83 | C20: 7.242 | D20: 7.241 | E20: =D20 -> 7.241 | F20: =E20 -> 7.241 | G20: Approved | H20: Hemanta Malik/Tapas Das/Rakesh Debnath | I20: =F20 -> 7.241 | J20: =I20 -> 7.241 | K20: =J20 -> 7.241 | L20: Approved | M20: Hemanta Malik/Tapas Das/Rakesh Debnath
A21: 16 | B21: AP83 to AP92 | C21: 22.602 | D21: 22.602 | E21: =D21 -> 22.602 | F21: =E21 -> 22.602 | G21: Approved | H21: Hemanta Malik/Tapas Das/Rakesh Debnath | I21: =F21 -> 22.602 | J21: =I21 -> 22.602 | K21: =J21 -> 22.602 | L21: Approved | M21: Hemanta Malik/Tapas Das/Rakesh Debnath
A22: 17 | B22: AP92 to AP94 | C22: 4.351 | D22: 4.351 | E22: =D22 -> 4.351 | F22: =E22 -> 4.351 | G22: Approved | H22: Hemanta Malik/Tapas Das/Rakesh Debnath | I22: =F22 -> 4.351 | J22: =I22 -> 4.351 | K22: =J22 -> 4.351 | L22: Approved | M22: Hemanta Malik/Tapas Das/Rakesh Debnath
A23: 18 | B23: AP94 to AP99 | C23: 6.622 | D23: 6.622 | E23: =D23 -> 6.622 | G23: Narmada River Crossing | H23: Hemanta Malik/Tapas Das | I23: 0 | J23: 0 | K23: =J23 -> 0
A24: 19 | B24: AP 99 to AP 106 | C24: 11.413 | D24: 11.413 | E24: =D24 -> 11.413 | F24: =E24 -> 11.413 | G24: Approved | H24: Hemanta Malik/Tapas Das/Rakesh Debnath | I24: =D24 -> 11.413 | J24: =I24 -> 11.413 | K24: =J24 -> 11.413 | L24: Approved | M24: Hemanta Malik/Tapas Das/Rakesh Debnath
A25: 20 | B25: AP106 to AP110 | C25: 10.77 | D25: 10.77 | E25: =D25 -> 10.77 | F25: =E25 -> 10.77 | G25: Approved | H25: Hemanta Malik/Tapas Das/Rakesh Debnath | I25: =D25 -> 10.77 | J25: =I25 -> 10.77 | K25: =J25 -> 10.77 | L25: Approved | M25: Hemanta Malik/Tapas Das/Rakesh Debnath
A26: 21 | B26: AP110 to AP118 | C26: 10.198 | D26: 10.198 | E26: =D26 -> 10.198 | F26: =E26 -> 10.198 | G26: Approved | H26: Hemanta Malik/Tapas Das/Rakesh Debnath | I26: =D26 -> 10.198 | J26: =I26 -> 10.198 | K26: =J26 -> 10.198 | L26: Approved | M26: Hemanta Malik/Tapas Das/Rakesh Debnath
A27: 22 | B27: AP118 to AP 123 | C27: 6.502 | D27: 6.502349 | E27: =D27 -> 6.502349 | F27: =E27 -> 6.502349 | G27: Approved | H27: Hemanta Malik/Tapas Das/Rakesh Debnath | I27: =D27 -> 6.502349 | J27: =I27 -> 6.502349 | K27: =J27 -> 6.502349 | L27: Approved | M27: Hemanta Malik/Tapas Das/Rakesh Debnath
A28: 23 | B28: AP123 to AP126 | C28: 6.516 | D28: 6.516 | E28: =D28 -> 6.516 | F28: =E28 -> 6.516 | G28: Approved | H28: Hemanta Malik/Tapas Das/Rakesh Debnath | I28: =D28 -> 6.516 | J28: =I28 -> 6.516 | K28: =J28 -> 6.516 | L28: Approved | M28: Hemanta Malik/Tapas Das/Rakesh Debnath
A29: 24 | B29: AP126 to Ap127 | C29: 4.34 | D29: 4.34 | E29: =D29 -> 4.34 | F29: =E29 -> 4.34 | G29: Approved | H29: Hemanta Malik/Rakesh Debnath | I29: =D29 -> 4.34 | J29: =I29 -> 4.34 | K29: =J29 -> 4.34 | L29: Approved | M29: Hemanta Malik/Rakesh Debnath
A30: 25 | B30: AP127 to AP129A | C30: 4.836 | D30: 4.836 | E30: =D30 -> 4.836 | F30: =E30 -> 4.836 | G30: Approved | H30: Hemanta Malik/Tapas Das/Rakesh Debnath | I30: =D30 -> 4.836 | J30: =I30 -> 4.836 | K30: =J30 -> 4.836 | L30: Approved | M30: Hemanta Malik/Tapas Das/Rakesh Debnath
A31: 26 | B31: AP129A to AP130 | C31: 4.41 | D31: 4.41 | E31: =D31 -> 4.41 | F31: =E31 -> 4.41 | G31: Approved | H31: Hemanta Malik/Tapas Das/Rakesh Debnath | I31: =D31 -> 4.41 | J31: =I31 -> 4.41 | K31: =J31 -> 4.41 | L31: Approved | M31: Hemanta Malik/Tapas Das/Rakesh Debnath
A32: 27 | B32: AP130 to AP134 | C32: 4.122 | D32: 4.122 | E32: =D32 -> 4.122 | F32: =E32 -> 4.122 | G32: Approved | H32: Hemanta Malik/Tapas Das/Rakesh Debnath | I32: =D32 -> 4.122 | J32: =I32 -> 4.122 | K32: =J32 -> 4.122 | L32: Approved | M32: Hemanta Malik/Tapas Das/Rakesh Debnath
A33: 28 | B33: AP134 to AP141 | C33: 12.203 | D33: 12.203 | E33: =D33 -> 12.203 | F33: =E33 -> 12.203 | G33: Approved | H33: Hemanta Malik/Tapas Das/Rakesh Debnath | I33: =D33 -> 12.203 | J33: =I33 -> 12.203 | K33: =J33 -> 12.203 | L33: Approved | M33: Hemanta Malik/Tapas Das/Rakesh Debnath
C34: =SUM(C5:C33) -> 184.973 | D34: =SUM(D5:D33) -> 184.98595 | E34: =SUM(E5:E33) -> 184.98645 | F34: =SUM(F7:F33) -> 166.53145 | I34: =SUM(I5:I33) -> 166.53145 | J34: =SUM(J5:J33) -> 166.53145 | K34: =SUM(K5:K33) -> 136.13935

Sheet Erection 
A2: ±800kV HVDC Bipole Line (Hexa Lapwing) between KPS2 (HVDC) & Nagpur (HVDC) (Part- 6) Erection
A3: Sl. No. | B3: Location Number | C3: Type of Tower | D3: Starting Date | E3: Tower Weight (MT) | F3: Status | G3: Completion Date | H3: Gang Name | I3: Manpower | J3: Hindarnce Days | K3: Remarks | L3: Tackweldng Status | M3: Tackwelding start date | N3: Tackwelding Completion date | O3: Sub Contractor name
A4: 1 | B4: 125/2 | C4: A+3 | D4: 46071 | E4: 24.042 | F4: C | G4: 46075 | H4: M/S Ratani Devi | I4: 18
A5: 2 | B5: 122/2 | C5: A+0 | D5: 46078 | E5: 22.925 | F5: C | G5: 46081 | H5: M/S Ratani Devi | I5: 18
A6: 3 | B6: 130/1 | C6: A+0 | D6: 46075 | E6: 22.925 | F6: C | G6: 46081 | H6: M/S Jwala | I6: 35
A7: 4 | B7: 126/10 | C7: A+0 | D7: 46084 | E7: 22.925 | F7: C | G7: 46088 | H7: M/s Ratani Devi | I7: 23
A8: 5 | B8: 129A/3 | C8: A+3 | D8: 46082 | E8: 24.042 | F8: C | G8: 46091 | H8: M/s Jwala | I8: 23
A9: 6 | B9: 126/9 | C9: A+3 | D9: 46082 | E9: 24.042 | F9: C | G9: 46092 | H9: M/s Ratani Devi | I9: 38
A10: 7 | B10: 129A/4 | C10: A+6 | D10: 46092 | E10: 26.765 | F10: C | G10: 46095 | H10: M/s Jwala | I10: 35
A11: 8 | B11: 126/5 | C11: A+3 | D11: 45717 | E11: 24.042 | F11: C | G11: 46096 | H11: M/s Ratani Devi | I11: 35
A12: 9 | B12: 126/4 | C12: A+0 | D12: 46096 | E12: 22.925 | F12: C | G12: 46100 | H12: M/s Ratani Devi | I12: 35
A13: 10 | B13: 130/2 | C13: A+6 | D13: 46096 | E13: 26.765 | F13: C | G13: 46100 | H13: M/s Jwala | I13: 18
A14: 11 | B14: 130/3 | C14: A+3 | D14: 46100 | E14: 24.042 | F14: C | G14: 46103 | H14: M/s Jwala | I14: 23
A15: 12 | B15: 126/3 | C15: A+3 | D15: 46100 | E15: 24.042 | F15: C | G15: 46104 | H15: M/s Ratani Devi | I15: 19
... A42: 39 | B42: 111/2 | C42: A+3 | D42: 46157 | E42: 24.042 | F42: C | G42: 46160 | H42: M/s Amrendra Prasad | I42: 26
A43: 40 | B43: 121/6 | C43: A+0 | D43: 46038 | E43: 22.925 | F43: C | G43: 46160 | H43: M/S Gagan Entp.
A44: 41 | B44: 136/8 | C44: A+0 | D44: 46158 | E44: 22.925 | F44: C | G44: 46160 | H44: M/s Jwala Singh | I44: 23
A45: 42 | B45: 121/5 | C45: A+0 | D45: 46160 | E45: 22.925 | F45: C | G45: 46162 | H45: M/S Gagan Entp. | I45: 24
A46: 43 | B46: 109/5 | C46: A+3 | D46: 46159 | E46: 24.042 | F46: C | G46: 46163 | H46: M/s Mukesh Kumar Verma | I46: 32
A47: 44 | B47: 139/1 | C47: A+3 | D47: 46160 | E47: 24.042 | F47: C | G47: 46163 | H47: M/s Jwala Singh | I47: 23
A48: 45 | B48: 111/3 | C48: A+0 | D48: 46160 | E48: 22.925 | F48: C | G48: 46164 | H48: M/s Amrendra Prasad | I48: 26
A49: 46 | B49: 124/5 | C49: A+6 | D49: 46163 | E49: 26.765 | F49: C | G49: 46165 | H49: M/S Gagan Entp. | I49: 35
A50: 47 | B50: 125/1 | C50: A+3 | D50: 46165 | E50: 24.042 | F50: C | G50: 46167 | H50: M/S Gagan Entp. | I50: 24
A51: 48 | B51: 111/4 | C51: A+0 | D51: 46165 | E51: 22.925 | F51: C | G51: 46168 | H51: M/s Amrendra Prasad | I51: 32
A52: 49 | B52: 109/6 | C52: A+3 | D52: 46163 | E52: 24.042 | F52: C | G52: 46170 | H52: M/s Mukesh Kumar Verma | I52: 26
A53: 50 | B53: 125/0 | C53: B2+3 | D53: 46168 | E53: 31.667 | F53: C | G53: 46171 | H53: M/S Gagan Entp. | I53: 23
A54: 51 | B54: 136/0 | C54: C2+9 | D54: 111907 | E54: 42.087 | F54: C | G54: 46171 | H54: M/s Jwala Singh | I54: 22
A55: 52 | B55: 109/7 | C55: A+3 | D55: 46163 | E55: 24.042 | F55: C | G55: 46173 | H55: M/s Mukesh Kumar Verma | I55: 26
... A65: 65.833333 | B65: 127/2 | C65: A+0 | D65: 46180 | E65: 22.925 | F65: C | G65: 46184 | H65: M/S Jwala Singh | I65: 22
A66: 62.833333 | B66: 123/3 | C66: A+9 | D66: 46180 | E66: 30.257 | F66: WIP | H66: M/S Gagan Entp.-2 | I66: 32
A67: 67.333333 | B67: 107/1 | C67: A+0 | D67: 46181 | E67: 22.925 | F67: WIP | H67: M/s Mukesh Kumar Verma | I67: 24
A68: 68.833333 | B68: 89/9 | C68: A+0 | D68: 46181 | E68: 22.925 | F68: WIP | H68: M/s Amrendra Prasad | I68: 26
A69: 70 | B69: 123/0 | C69: B2+0 | D69: 46183 | F69: WIP | H69: M/S Gagan Entp-3
A70: 71 | B70: 126/7 | C70: A+0 | D70: 46185 | E70: 22.925 | F70: WIP | H70: M/S Jwala SIngh

Sheet Erection Completed 
A1: SL No. | B1: Location No. | C1: Tower Type | D1: Starting Date | E1: Tower Weight | F1: Status | G1: Completion Date | H1: Gang Name | I1: Gang Strength | J1: Number of Fitters | K1: Tower Tightening | L1: Remark
A2: 1 | B2: ='Erection '!B4 -> 125/2 | C2: =VLOOKUP(B2,'Erection '!B4:C68,2,0) -> A+3 | D2: =VLOOKUP(B2,'Erection '!B4:D63,3,0) -> 46071 | E2: =VLOOKUP(B3,'Erection '!B4:E63,4,0) -> 22.925 | F2: =VLOOKUP(B2,'Erection '!B4:F63,5,0) -> C | G2: =VLOOKUP(B2,'Erection '!B4:G63,6,0) -> 46075 | H2: =VLOOKUP(B2,'Erection '!B4:H63,7,0) -> M/S Ratani Devi | I2: 32 | K2: Yes
A3: 2 | B3: ='Erection '!B5 -> 122/2 | C3: =VLOOKUP(B3,'Erection '!B5:C69,2,0) -> A+0 | D3: =VLOOKUP(B3,'Erection '!B5:D64,3,0) -> 46078 | E3: =VLOOKUP(B4,'Erection '!B5:E64,4,0) -> 22.925 | F3: =VLOOKUP(B3,'Erection '!B5:F64,5,0) -> C | G3: =VLOOKUP(B3,'Erection '!B5:G64,6,0) -> 46081 | H3: =VLOOKUP(B3,'Erection '!B5:H64,7,0) -> M/S Ratani Devi | I3: 24 | K3: Yes
A4: 3 | B4: ='Erection '!B6 -> 130/1 | C4: =VLOOKUP(B4,'Erection '!B6:C70,2,0) -> A+0 | D4: =VLOOKUP(B4,'Erection '!B6:D65,3,0) -> 46075 | E4: =VLOOKUP(B5,'Erection '!B6:E65,4,0) -> 22.925 | F4: =VLOOKUP(B4,'Erection '!B6:F65,5,0) -> C | G4: =VLOOKUP(B4,'Erection '!B6:G65,6,0) -> 46081 | H4: =VLOOKUP(B4,'Erection '!B6:H65,7,0) -> M/S Jwala | I4: 42 | K4: Yes
A5: 4 | B5: ='Erection '!B7 -> 126/10 | C5: =VLOOKUP(B5,'Erection '!B7:C71,2,0) -> A+0 | D5: =VLOOKUP(B5,'Erection '!B7:D67,3,0) -> 46084 | E5: =VLOOKUP(B6,'Erection '!B7:E67,4,0) -> 24.042 | F5: =VLOOKUP(B5,'Erection '!B7:F67,5,0) -> C | G5: =VLOOKUP(B5,'Erection '!B7:G67,6,0) -> 46088 | H5: =VLOOKUP(B5,'Erection '!B7:H67,7,0) -> M/s Ratani Devi | I5: 32 | K5: Yes
A6: 5 | B6: ='Erection '!B8 -> 129A/3 | C6: =VLOOKUP(B6,'Erection '!B8:C72,2,0) -> A+3 | D6: =VLOOKUP(B6,'Erection '!B8:D68,3,0) -> 46082 | E6: =VLOOKUP(B7,'Erection '!B8:E68,4,0) -> 24.042 | F6: =VLOOKUP(B6,'Erection '!B8:F68,5,0) -> C | G6: =VLOOKUP(B6,'Erection '!B8:G68,6,0) -> 46091 | H6: =VLOOKUP(B6,'Erection '!B8:H68,7,0) -> M/s Jwala | I6: 32 | K6: Yes
A7: 6 | B7: ='Erection '!B9 -> 126/9 | C7: =VLOOKUP(B7,'Erection '!B9:C73,2,0) -> A+3 | D7: =VLOOKUP(B7,'Erection '!B9:D69,3,0) -> 46082 | E7: =VLOOKUP(B8,'Erection '!B9:E69,4,0) -> 26.765 | F7: =VLOOKUP(B7,'Erection '!B9:F69,5,0) -> C | G7: =VLOOKUP(B7,'Erection '!B9:G69,6,0) -> 46092 | H7: =VLOOKUP(B7,'Erection '!B9:H69,7,0) -> M/s Ratani Devi | I7: 26 | K7: Yes
A8: 7 | B8: ='Erection '!B10 -> 129A/4 | C8: =VLOOKUP(B8,'Erection '!B10:C74,2,0) -> A+6 | D8: =VLOOKUP(B8,'Erection '!B10:D70,3,0) -> 46092 | E8: =VLOOKUP(B9,'Erection '!B10:E70,4,0) -> 24.042 | F8: =VLOOKUP(B8,'Erection '!B10:F70,5,0) -> C | G8: =VLOOKUP(B8,'Erection '!B10:G70,6,0) -> 46095 | H8: =VLOOKUP(B8,'Erection '!B10:H70,7,0) -> M/s Jwala | I8: 26 | K8: Yes
A9: 8 | B9: ='Erection '!B11 -> 126/5 | C9: =VLOOKUP(B9,'Erection '!B11:C75,2,0) -> A+3 | D9: =VLOOKUP(B9,'Erection '!B11:D71,3,0) -> 45717 | E9: =VLOOKUP(B10,'Erection '!B11:E71,4,0) -> 22.925 | F9: =VLOOKUP(B9,'Erection '!B11:F71,5,0) -> C | G9: =VLOOKUP(B9,'Erection '!B11:G71,6,0) -> 46096 | H9: =VLOOKUP(B9,'Erection '!B11:H71,7,0) -> M/s Ratani Devi | I9: 26 | K9: Yes
A10: 9 | B10: ='Erection '!B12 -> 126/4 | C10: =VLOOKUP(B10,'Erection '!B12:C76,2,0) -> A+0 | D10: =VLOOKUP(B10,'Erection '!B12:D72,3,0) -> 46096 | E10: =VLOOKUP(B11,'Erection '!B12:E72,4,0) -> 26.765 | F10: =VLOOKUP(B10,'Erection '!B12:F72,5,0) -> C | G10: =VLOOKUP(B10,'Erection '!B12:G72,6,0) -> 46100 | H10: =VLOOKUP(B10,'Erection '!B12:H72,7,0) -> M/s Ratani Devi | I10: 26 | K10: Yes
A11: 10 | B11: ='Erection '!B13 -> 130/2 | C11: =VLOOKUP(B11,'Erection '!B13:C77,2,0) -> A+6 | D11: =VLOOKUP(B11,'Erection '!B13:D73,3,0) -> 46096 | E11: =VLOOKUP(B12,'Erection '!B13:E73,4,0) -> 24.042 | F11: =VLOOKUP(B11,'Erection '!B13:F73,5,0) -> C | G11: =VLOOKUP(B11,'Erection '!B13:G73,6,0) -> 46100 | H11: =VLOOKUP(B11,'Erection '!B13:H73,7,0) -> M/s Jwala | I11: 26 | K11: Yes
A12: 11 | B12: ='Erection '!B14 -> 130/3 | C12: =VLOOKUP(B12,'Erection '!B14:C78,2,0) -> A+3 | D12: =VLOOKUP(B12,'Erection '!B14:D74,3,0) -> 46100 | E12: =VLOOKUP(B13,'Erection '!B14:E74,4,0) -> 24.042 | F12: =VLOOKUP(B12,'Erection '!B14:F74,5,0) -> C | G12: =VLOOKUP(B12,'Erection '!B14:G74,6,0) -> 46103 | H12: =VLOOKUP(B12,'Erection '!B14:H74,7,0) -> M/s Jwala | I12: 26 | K12: Yes
A13: 12 | B13: ='Erection '!B15 -> 126/3 | C13: =VLOOKUP(B13,'Erection '!B15:C79,2,0) -> A+3 | D13: =VLOOKUP(B13,'Erection '!B15:D75,3,0) -> 46100 | E13: =VLOOKUP(B14,'Erection '!B15:E75,4,0) -> 24.042 | F13: =VLOOKUP(B13,'Erection '!B15:F75,5,0) -> C | G13: =VLOOKUP(B13,'Erection '!B15:G75,6,0) -> 46104 | H13: =VLOOKUP(B13,'Erection '!B15:H75,7,0) -> M/s Ratani Devi | I13: 32 | K13: Yes
A14: 13 | B14: ='Erection '!B16 -> 134/2 | C14: =VLOOKUP(B14,'Erection '!B16:C80,2,0) -> A+3 | D14: =VLOOKUP(B14,'Erection '!B16:D76,3,0) -> 46104 | E14: =VLOOKUP(B15,'Erection '!B16:E76,4,0) -> 26.765 | F14: =VLOOKUP(B14,'Erection '!B16:F76,5,0) -> C | G14: =VLOOKUP(B14,'Erection '!B16:G76,6,0) -> 46108 | H14: =VLOOKUP(B14,'Erection '!B16:H76,7,0) -> M/s Jwala | I14: 26 | K14: Yes
A15: 14 | B15: ='Erection '!B17 -> 125/3 | C15: =VLOOKUP(B15,'Erection '!B17:C81,2,0) -> A+6 | D15: =VLOOKUP(B15,'Erection '!B17:D77,3,0) -> 46104 | E15: =VLOOKUP(B16,'Erection '!B17:E77,4,0) -> 26.765 | F15: =VLOOKUP(B15,'Erection '!B17:F77,5,0) -> C | G15: =VLOOKUP(B15,'Erection '!B17:G77,6,0) -> 46109 | H15: =VLOOKUP(B15,'Erection '!B17:H77,7,0) -> M/s Ratani Devi | I15: 28 | K15: Yes
A16: 15 | B16: ='Erection '!B18 -> 134/3 | C16: =VLOOKUP(B16,'Erection '!B18:C82,2,0) -> A+6 | D16: =VLOOKUP(B16,'Erection '!B18:D78,3,0) -> 46108 | E16: =VLOOKUP(B17,'Erection '!B18:E78,4,0) -> 24.042 | F16: =VLOOKUP(B16,'Erection '!B18:F78,5,0) -> C | G16: =VLOOKUP(B16,'Erection '!B18:G78,6,0) -> 46111 | H16: =VLOOKUP(B16,'Erection '!B18:H78,7,0) -> M/s Jwala | I16: 42 | K16: Yes
... A19: 18 | B19: ='Erection '!B21 -> 134/8 | C19: =VLOOKUP(B19,'Erection '!B21:C85,2,0) -> A+3 | D19: =VLOOKUP(B19,'Erection '!B21:D81,3,0) -> 46116 | E19: =VLOOKUP(B20,'Erection '!B21:E81,4,0) -> 22.925 | F19: =VLOOKUP(B19,'Erection '!B21:F81,5,0) -> C | G19: =VLOOKUP(B19,'Erection '!B21:G81,6,0) -> 46119 | H19: =VLOOKUP(B19,'Erection '!B21:H81,7,0) -> M/s Jwala | I19: 24 | K19: Yes
A20: 19 | B20: ='Erection '!B22 -> 134/9 | C20: =VLOOKUP(B20,'Erection '!B22:C86,2,0) -> A+0 | D20: =VLOOKUP(B20,'Erection '!B22:D82,3,0) -> 46119 | E20: =VLOOKUP(B21,'Erection '!B22:E82,4,0) -> 24.042 | F20: =VLOOKUP(B20,'Erection '!B22:F82,5,0) -> C | G20: =VLOOKUP(B20,'Erection '!B22:G82,6,0) -> 46123 | H20: =VLOOKUP(B20,'Erection '!B22:H82,7,0) -> M/s Jwala | K20: Yes
A21: 20 | B21: ='Erection '!B23 -> 134/7 | C21: =VLOOKUP(B21,'Erection '!B23:C87,2,0) -> A+3 | D21: =VLOOKUP(B21,'Erection '!B23:D83,3,0) -> 46124 | E21: =VLOOKUP(B22,'Erection '!B23:E83,4,0) -> 22.925 | F21: =VLOOKUP(B21,'Erection '!B23:F83,5,0) -> C | G21: =VLOOKUP(B21,'Erection '!B23:G83,6,0) -> 46127 | H21: =VLOOKUP(B21,'Erection '!B23:H83,7,0) -> M/s Jwala | I21: 18 | K21: Yes
A22: 21 | B22: ='Erection '!B24 -> 134/5 | C22: =VLOOKUP(B22,'Erection '!B24:C88,2,0) -> A+0 | D22: =VLOOKUP(B22,'Erection '!B24:D84,3,0) -> 46127 | E22: =VLOOKUP(B23,'Erection '!B24:E84,4,0) -> 22.925 | F22: =VLOOKUP(B22,'Erection '!B24:F84,5,0) -> C | G22: =VLOOKUP(B22,'Erection '!B24:G84,6,0) -> 46131 | H22: =VLOOKUP(B22,'Erection '!B24:H84,7,0) -> M/s Jwala | I22: 18 | K22: Yes
A23: 22 | B23: ='Erection '!B25 -> 136/2 | C23: =VLOOKUP(B23,'Erection '!B25:C89,2,0) -> A+3 | D23: =VLOOKUP(B23,'Erection '!B25:D85,3,0) -> 46131 | E23: =VLOOKUP(B24,'Erection '!B25:E85,4,0) -> 22.925 | F23: =VLOOKUP(B23,'Erection '!B25:F85,5,0) -> C | G23: =VLOOKUP(B23,'Erection '!B25:G85,6,0) -> 46135 | H23: =VLOOKUP(B23,'Erection '!B25:H85,7,0) -> M/s Jwala | I23: 23 | K23: Yes
A24: 23 | B24: ='Erection '!B26 -> 136/1 | C24: =VLOOKUP(B24,'Erection '!B26:C90,2,0) -> A+0 | D24: =VLOOKUP(B24,'Erection '!B26:D86,3,0) -> 46136 | E24: =VLOOKUP(B25,'Erection '!B26:E86,4,0) -> 24.042 | F24: =VLOOKUP(B24,'Erection '!B26:F86,5,0) -> C | G24: =VLOOKUP(B24,'Erection '!B26:G86,6,0) -> 46140 | H24: =VLOOKUP(B24,'Erection '!B26:H86,7,0) -> M/s Jwala Singh | I24: 35 | K24: Yes
A25: 24 | B25: ='Erection '!B27 -> 136/3 | C25: =VLOOKUP(B25,'Erection '!B27:C91,2,0) -> A+3 | D25: =VLOOKUP(B25,'Erection '!B27:D87,3,0) -> 46140 | E25: =VLOOKUP(B26,'Erection '!B27:E87,4,0) -> 22.925 | F25: =VLOOKUP(B25,'Erection '!B27:F87,5,0) -> C | G25: =VLOOKUP(B25,'Erection '!B27:G87,6,0) -> 46144 | H25: =VLOOKUP(B25,'Erection '!B27:H87,7,0) -> M/s Jwala Singh | I25: 25 | K25: Yes
A26: 25 | B26: ='Erection '!B28 -> 102/7 | C26: =VLOOKUP(B26,'Erection '!B28:C92,2,0) -> A+0 | D26: =VLOOKUP(B26,'Erection '!B28:D88,3,0) -> 46140 | E26: =VLOOKUP(B27,'Erection '!B28:E88,4,0) -> 24.042 | F26: =VLOOKUP(B26,'Erection '!B28:F88,5,0) -> C | G26: =VLOOKUP(B26,'Erection '!B28:G88,6,0) -> 46146 | H26: =VLOOKUP(B26,'Erection '!B28:H88,7,0) -> M/s Aravali Infrastructure | I26: 21 | K26: Yes
