Workbook
Name __________________________b111121: #REF!
Name __________________________b111121: #REF!
Name _________________________b111121: #REF!
Name _________________________b111121: #REF!
Name ________________________b111121: #REF!
Name ________________________b111121: #REF!
Name _______________________b111121: #REF!
Name _______________________b111121: #REF!
Name ______________________b111121: #REF!
Name ______________________b111121: #REF!
Name ______________________TAB1: #REF!
Name _____________________b111121: #REF!
Name _____________________b111121: #REF!
Name _____________________TAB1: #REF!
Name ____________________b111121: #REF!
Name ____________________b111121: #REF!
Name ____________________KEY3: #REF!
Name ____________________KEY3: #REF!
Name ____________________TAB1: #REF!
Name ___________________b111121: #REF!
Name ___________________b111121: #REF!
Name ___________________KEY3: #REF!
Name ___________________KEY3: #REF!
Name ___________________TAB1: #REF!
Name __________________b111121: #REF!
Name __________________b111121: #REF!
Name __________________KEY3: #REF!
Name __________________KEY3: #REF!
Name __________________TAB1: #REF!
Name _________________b111121: #REF!
Name _________________b111121: #REF!
Name _________________KEY3: #REF!
Name _________________KEY3: #REF!
Name _________________TAB1: #REF!
Name ________________b111121: #REF!
Name ________________b111121: #REF!
Name ________________KEY3: #REF!
Name ________________KEY3: #REF!
Name ________________TAB1: #REF!
Name _______________b111121: #REF!
Name _______________b111121: #REF!
Name _______________KEY3: #REF!
Name _______________KEY3: #REF!
Name _______________TAB1: #REF!
Name ______________b111121: #REF!
Name ______________b111121: #REF!
Name ______________TAB1: #REF!
Name _____________A65537: #REF!
Name _____________A65537: #REF!
Name _____________b111121: #REF!
Name _____________b111121: #REF!
Name _____________TAB1: #REF!
Name ____________A655600: #REF!
Name ____________A655600: #REF!
Name ____________b111121: #REF!
Name ____________b111121: #REF!
Name ____________KEY3: #REF!
Name ____________KEY3: #REF!
Name ____________TAB1: #REF!
Name ___________A65537: #REF!

Sheet Visual Chart 
B1: VISUAL PROGRESS CHART
B2: TL-02 765 KV D/C Kurnool IV - Bidar Transmission Line
B3: Foundation (Nos.):- | D3: =H15 -> 0 | E3: / 297 | F3: Erection (Nos.):- | I3: / 297 | J3: Earthing (Nos.):- | M3: / 297 | N3: Rough Sag (Kms):- | Q3: 113.292 | R3: Final Sag (Kms):- | U3: 113.292 | V3: Date:- | W3: ='Master Sheet'!H2 -> 46167
B4: COMPLETION CHART | C4: -3 | D4: +0 | E4: +3 | F4: +6 | G4: +9 | H4: Total | I4: Line Qty
J5: ERECTION | P5: Rough Sag | R5: SH / NH Road Crossing
J6: WIP | V6: River
B7: DA | H7: =SUM(C7:G7) -> 0 | K7: Type | M7: Angle Tower | R7: Gas Pipeline
B8: DB1 | H8: =SUM(C8:G8) -> 0 | J8: FOUNDATION
B9: DB2 | H9: =SUM(C9:G9) -> 0 | O9: Final Sag
B10: DC1 | H10: =SUM(C10:G10) -> 0
B11: DC2 | H11: =SUM(C11:G11) -> 0 | S11: Railway
B12: DCT | H12: =SUM(C12:G12) -> 0 | Q12: WIP
B13: DD45 | H13: =SUM(C13:G13) -> 0 | J13: Section Tower | K13: SC | S13: Crossing | V13: 110-800 KV
B14: DD60 | H14: =SUM(C14:G14) -> 0 | J14: TP | K14: TT | M14: Earthing | P14: OPGW | V14: Line
B15: Total Completed Foundations | H15: =SUM(H7:H14) -> 0 | I15: =SUM(I7:I14) -> 0
AB16: 110kv OHTL
AA18: SH -122
C19: 411 | E19: 432 | G19: 408 | I19: 433 | K19: 409 | M19: 432 | O19: 375 | Q19: 414 | S19: 403 | U19: 406 | W19: 319 | Y19: 384
B21: 48/0 | D21: 48/1 | F21: 48/2 | H21: 48/3 | J21: 48/4 | L21: 48/5 | N21: 48/6 | P21: 48/7 | R21: 49/0 | T21: 49/1 | V21: 49/2 | X21: 49/3
B22: 3DB1+0 | D22: 3DA+6 | F22: 3DA+0 | H22: 3DA+6 | J22: 3DA+3 | L22: 3DA+3 | N22: 3DA+3 | P22: 3DA+6 | R22: 3DC1+3 | T22: 3DA+0 | V22: 3DA+0 | X22: 3DA+0
C25: 385 | E25: 409 | G25: 369 | I25: 350 | K25: 395 | M25: 412 | O25: 366 | Q25: 383 | S25: 300 | U25: 393 | W25: 414 | Y25: 412
B27: 49/4 | D27: 49/5 | F27: 49/6 | H27: 49/7 | J27: 49/8 | L27: 49/9 | N27: 49/10 | P27: 49/11 | R27: 50/0 | T27: 50/1 | V27: 50/2 | X27: 50/3
B28: 3DA+0 | D28: 3DA+6 | F28: 3DA+0 | H28: 3DA+0 | J28: 3DA+0 | L28: 3DA+0 | N28: 3DA+0 | P28: 3DA+0 | R28: 3DC2+0 | T28: 3DA+0 | V28: 3DA+0 | X28: 3DA+3
C32: 377 | E32: 369 | G32: 369 | I32: 403 | K32: 374 | M32: 416 | O32: 424 | Q32: 401 | S32: 437 | U32: 369 | W32: 361 | Y32: 458
B34: 51/0 | D34: 51/1 | F34: 51/2 | H34: 51/3 | J34: 51/4 | L34: 51/5 | N34: 51/6 | P34: 51/7 | R34: 51/8 | T34: 51/9 | V34: 51/10 | X34: 52/0
B35: 3DC2+0 | D35: 3DA+3 | F35: 3DA+0 | H35: 3DA+0 | J35: 3DA+0 | L35: 3DA+0 | N35: 3DA+3 | P35: 3DA+3 | R35: 3DA+3 | T35: 3DA+3 | V35: 3DA+0 | X35: 3DB2+0
X36: RWY Xing | Y36: TDR-VBD
C39: 355 | E39: 347 | G39: 430 | I39: 408 | K39: 402 | M39: 411 | O39: 397 | Q39: 404 | S39: 398 | U39: 430 | W39: 320 | Y39: 230
B41: 52/1 | D41: 52/2 | F41: 52/3 | H41: 52/4 | J41: 53/0 | L41: 53/1 | N41: 53/2 | P41: 53/3 | R41: 53/4 | T41: 53/5 | V41: 53/6 | X41: 54/0
B42: 3DA+9 | D42: 3DA+0 | F42: 3DA+0 | H42: 3DA+0 | J42: 3DB2+3 | L42: 3DA+3 | N42: 3DA+0 | P42: 3DA+3 | R42: 3DA+3 | T42: 3DA+0 | V42: 3DA+3 | X42: 3DD60+0
C46: 339 | E46: 365 | G46: 409 | I46: 343 | K46: 352 | M46: 419 | O46: 410 | Q46: 413 | S46: 407 | U46: 352 | W46: 405 | Y46: 393
B48: 55/0 | D48: 55/1 | F48: 55/2 | H48: 55/3 | J48: 56/0 | L48: 56/1 | N48: 56/2 | P48: 56/3 | R48: 56/4 | T48: 56/5 | V48: 56/6 | X48: 56/7
B49: 3DD60+0 | D49: 3DA+0 | F49: 3DA+0 | H49: 3DA+0 | J49: 3DC1+0 | L49: 3DA+3 | N49: 3DA+3 | P49: 3DA+0 | R49: 3DA+3 | T49: 3DA+3 | V49: 3DA+0 | X49: 3DA+0
M50: 220KV D/C OHTL
M51: TDR-GBL
C53: 439 | E53: 398 | G53: 445 | I53: 355 | K53: 447 | M53: 215 | O53: 498 | Q53: 325 | S53: 388 | U53: 381 | W53: 349 | Y53: 373
B55: 56/8 | D55: 56/9 | F55: 56/10 | H55: 56/11 | J55: 56/12 | L55: 57/0 | N55: 58/0 | P55: 58/1 | R55: 58/2 | T55: 58/3 | V55: 59/0 | X55: 59/1
B56: 3DA+0 | D56: 3DA+6 | F56: 3DA+0 | H56: 3DA+0 | J56: 3DA+0 | L56: 3DC1+9 | N56: 3DB2+6 | P56: 3DA+6 | R56: 3DA+0 | T56: 3DA+3 | X56: 3DA+0
C60: 386 | E60: 429 | G60: 377 | I60: 405 | K60: 425 | M60: 344 | O60: 399 | Q60: 439 | S60: 403 | U60: 480 | W60: 535 | Y60: 389
B62: 59/2 | D62: 59/3 | F62: 59/4 | H62: 59/5 | J62: 60/0 | L62: 60/1 | N62: 60/2 | P62: 60/3 | R62: 60/4 | T62: 60/5 | V62: 60/6 | X62: 60/7
...

Sheet Master Sheet
C2: Project Code | D2: TA-601 | G2: Date as on | H2: 46167 | I2: SBU Head | J2: Mr. Rajinder Gupta
C3: Project Name | D3: 765kV D/C Kurnool IV - Bidar trnasmission line (Part II) | G3: LOA Start Date | H3: 13.05.2025 | I3: PCH | J3: Mr. Arun Felbin R
C4: Client Name | D4: POWERGRID KURNOOL IV TRANSMISSION LIMITED | G4: LOA End Date | H4: 12.04.2027 | I4: Regional Manager | J4: Mr. Ajith Kumar MG
C5: Duration | D5: 23 Months | G5: Planning Engineer | H5: Mr. Appala Swamy | I5: Chief Manger | J5: Mr. Senthil Jayaraman
B8: Survey Status
B9: Activity | C9: Unit | D9: Final Est. Qty | E9: L2 till Last Month | F9: Completed till Last Month | G9: Approved till Last Month | H9: Balance to Submit | I9: Plan for Current Month | J9: Balance to Approve | K9: L2 Submission Plan for Current Month | L9: Approved till Current Month | M9: Remarks
B10: Detailed Survey | C10: kms | D10: 113.286 | E10: 113.286 | F10: 113.286 | G10: 113.286 | H10: 0 | I10: 0 | J10: 0 | K10: 0 | L10: 113.286
B11: Check Survey | C11: kms | D11: 113.286 | E11: 113.286 | F11: 113.286 | G11: 113.266 | H11: =E11-F11 -> 0 | I11: 0.398 | J11: 0.4 | K11: 0 | L11: 112.266
B14: Foundation Status
B15: Activity | C15: Scope Quantity | D15: Cumulative L2 till Last Month | E15: Cumulative Progress till Last Month | F15: L2 for present Month | G15: Plan for the Month | H15: Today's Progress | I15: Progress for Current Month | J15: L2 till Current Month | K15: Completed till Date | L15: Balance Work | M15: Under Progress | N15: Gangs at Present | O15: Remarks
B16: Foundation | C16: 292 | D16: 252 | E16: 113 | F16: 25 | G16: 40 | H16: 0 | I16: 9 | J16: 277 | K16: =E16+I16 -> 122 | L16: =292-K16 -> 170 | M16: 8 | N16: 6
B17: Earthing | C17: 292 | D17: 252 | E17: 89 | F17: 25 | G17: 40 | H17: 0 | I17: 10 | J17: =J16 -> 277 | K17: =E17+I17 -> 99 | L17: =C17-K17 -> 193
B18: Tower Erection | C18: 292 | D18: 290 | E18: 70 | F18: 35 | G18: 35 | H18: 0 | I18: 1 | J18: 225 | K18: =E18+I18 -> 71 | L18: =C18-K18 -> 221 | M18: 1 | N18: 1
B19: Stringing -R/S | C19: 113.286 | D19: 17 | E19: 0 | F19: 12 | G19: 0 | H19: 0 | I19: 0 | J19: 29 | K19: =E19+I19 -> 0 | L19: =C19-K19 -> 113.286
B20: Stringing -F/S | C20: 113.286 | D20: 17 | E20: 0 | F20: 12 | G20: 0 | H20: 0 | I20: 0 | J20: 29 | K20: =E20+I20 -> 0 | L20: =C20-K20 -> 113.286
B21: OPGW | C21: 113.286 | D21: 17 | E21: 0 | F21: 12 | G21: 0 | H21: 0 | I21: 0 | J21: 29 | K21: =E21+I21 -> 0 | L21: =C21-K21 -> 113.286
B22: NH Crossing | C22: 3 | L22: =C22-K22 -> 3
B23: SH Crossing | C23: 1 | L23: =C23-K23 -> 1
B24: Railway crossing | C24: 2 | L24: =C24-K24 -> 2
B25: Power Line Crossing | C25: 6 | L25: =C25-K25 -> 6
B27: WIP - Foundations | C27: Pit A | D27: Pit B | E27: Pit C | F27: Pit D | G27: Gang | K27: WIP-Erection | L27: Status | M27: Gang
B28: 48/0 | C28: Excavation WIP | D28: Excavation WIP | E28: Excavation WIP | F28: Excavation WIP | G28: BALAJI Services | K28: 59/0 | L28: 2nd Section WIP | M28: NASIRUDDIN
B29: 49/0 | C29: Blasting | D29: Blasting | E29: Blasting | F29: Blasting | G29: AMMU ENGG
B30: 49/4 | C30: Blasting | D30: Blasting | E30: Blasting | F30: Blasting | G30: AMMU ENGG
B31: 56/0 | C31: Excavated | D31: Excavated | E31: Excavated | F31: Excavated | G31: D. Govind Raj
B32: 56/5 | C32: PCC | D32: PCC | E32: PCC | F32: PCC | G32: Veer Teja
B33: 56/10 | C33: Excavation WIP | D33: Excavation WIP | E33: Excavation WIP | F33: Excavation WIP | G33: Veer Teja
B34: 68/0 | C34: Excavated | D34: Steel Binding | E34: Steel Binding | F34: Excavated | G34: ATK
B35: 99/5 | C35: Pit Marking | D35: Pit Marking | E35: Pit Marking | F35: Pit Marking | G35: Trinergy
B37: Supply Status
B38: Activity | C38: Unit | D38: Final Est. Qty | E38: L2 till Last Month | F38: Received till Last Month | G38: Balance | H38: L2 Plan for Current Month | I38: Plan for Current Month | J38: Progress for the Month | K38: Received till Current Month | L38: Gap between Supply & Cumm.L2 | M38: Remarks
B39: Stub | C39: Set | D39: 292 | E39: 292 | F39: 235 | G39: =D39-F39 -> 57 | H39: 0 | I39: 0 | J39: 0 | K39: =F39+J39 -> 235 | L39: =E39+H39-K39 -> 57
B40: Tower | C40: No's | D40: 292 | E40: 230 | F40: 230 | G40: =D40-F40 -> 62 | H40: 60 | I40: 60 | J40: 26 | K40: =F40+J40 -> 256 | L40: =E40+H40-K40 -> 34
B41: AL59 Conductor | C41: kms | D41: 4314 | E41: 3000 | F41: 3285.198 | G41: =D41-F41 -> 1028.802 | H41: 300 | I41: 300 | J41: =206.444+66.289 -> 272.733 | K41: =F41+J41+63.069 -> 3621 | L41: =E41+H41-K41 -> -321
B43: Support Required :
B44: 1) RC Foundation Drawings Required- DC,DD45,DD60 (1MRC,2MRC,3MRC)

Sheet Progress Sheet 
B2: Survey Status
B3: Activity | C3: Unit | D3: Final Est. Qty | E3: L2 till Last Month | G3: Completed till Last Month | H3: Approved till Last Month | I3: Balance to Submit | J3: Balance to Approve | K3: L2 Submission Plan for Current Month | L3: Progress For Month | M3: Approved till Current Month | N3: Remarks
B4: Detailed Survey | C4: kms | D4: ='Master Sheet'!D10 -> 113.286 | E4: ='Master Sheet'!E10 -> 113.286 | G4: 113.286 | H4: ='Master Sheet'!G10 -> 113.286 | I4: ='Master Sheet'!H10 -> 0 | J4: ='Master Sheet'!J10 -> 0 | K4: ='Master Sheet'!K10 -> 0 | L4: ='Master Sheet'!I10 -> 0 | M4: ='Master Sheet'!L10 -> 113.286
B5: Check Survey | C5: kms | D5: ='Master Sheet'!D11 -> 113.286 | E5: ='Master Sheet'!E11 -> 113.286 | G5: ='Master Sheet'!F11 -> 113.286 | H5: ='Master Sheet'!G11 -> 113.266 | I5: ='Master Sheet'!H11 -> 0 | J5: ='Master Sheet'!J11 -> 0.4 | K5: 20 | L5: ='Master Sheet'!I11 -> 0.398 | M5: ='Master Sheet'!L11 -> 112.266
B7: PROGRESS - Check Survey
B8: S.No | C8: Section | E8: Length | G8: Check survey status
L10: =COUNTIFS($I$13:$L$154,"Foundation Completed.") -> 122
B11: PROGRESS - FDN & EREC
B12: S.No | C12: Location No. | D12: Tower Type | E12: Classification | F12: ROW cleared date | G12: Start Date | H12: Conc Volume | I12: Foundation Status | M12: End Date | N12: Gang Name | O12: Erection Status | P12: Gang Strength | Q12: Remarks
B13: 1 | C13: 81/2 | D13: DA+3 | E13: DFR | F13: =G13 -> 45854 | G13: 45854 | H13: 26.43 | I13: Foundation completed. | M13: 45876 | N13: MARC | P13: 10
B14: =B13+1 -> 2 | C14: 82/1 | D14: DA+0 | E14: WC | F14: 45848 | G14: 45849 | H14: 22.4 | I14: Foundation completed. | M14: 45891 | N14: MARC | P14: 10
B15: =B14+1 -> 3 | C15: 81/1 | D15: DA+0 | E15: DFR | F15: =ROW!D6 -> 0 | G15: 45892 | H15: 23.27 | I15: Foundation completed. | M15: 45913 | N15: MARC | P15: 10
B16: =B15+1 -> 4 | C16: 80/5 | D16: DA+0 | E16: DRY | F16: 45898 | G16: 45902 | H16: 21.96 | I16: Foundation completed. | M16: 45918 | N16: MARC | P16: 10
B17: =B16+1 -> 5 | C17: 80/1 | D17: DA+6 | E17: WFR | F17: 45897 | G17: 45898 | H17: 36.66 | I17: Foundation completed. | M17: 45940 | N17: MARC | P17: 10
B18: =B17+1 -> 6 | C18: 59/5 | D18: DA+0 | E18: DRY | F18: 45930 | G18: 45938 | H18: 21.96 | I18: Foundation completed. | M18: 45949 | N18: SHRIARSHINI | P18: 10
B19: =B18+1 -> 7 | C19: 84/3 | D19: DA+0 | E19: DRY | F19: 45919 | G19: 45940 | H19: 21.96 | I19: Foundation completed. | M19: 45949 | N19: SHIVRATHIRI BALRAJ | P19: 10
B20: =B19+1 -> 8 | C20: 59/4 | D20: DA+6 | E20: DRY | F20: 45933 | G20: 45938 | H20: 25.04 | I20: Foundation completed. | M20: 45951 | N20: SHRIARSHINI | P20: 20
B21: =B20+1 -> 9 | C21: 84/4 | D21: DA+0 | E21: DRY | F21: 45925 | G21: 45941 | H21: 21.96 | I21: Foundation completed. | M21: 45954 | N21: SHIVRATHIRI BALRAJ | P21: 10
B22: =B21+1 -> 10 | C22: 60/2 | D22: DA+0 | E22: DFR | G22: 45944 | H22: 23.27 | I22: Foundation completed. | M22: 45955 | N22: SHRIARSHINI | P22: 20
B23: =B22+1 -> 11 | C23: 80/4 | D23: DA+3 | E23: WFR | F23: 45919 | G23: 45923 | H23: 36.66 | I23: Foundation completed. | M23: 45957 | N23: MARC | P23: 10
B24: =B23+1 -> 12 | C24: 77/4 | D24: DA+0 | E24: DRY | F24: 45916 | G24: 45917 | H24: 21.96 | I24: Foundation completed. | M24: 45961 | N24: SHIVRATHIRI BALRAJ | P24: 10
B25: =B24+1 -> 13 | C25: 77/10 | D25: DA+3 | E25: DRY | G25: 45957 | H25: 25.04 | I25: Foundation completed. | M25: 45966 | N25: SHIVRATHIRI BALRAJ | P25: 10
B26: =B25+1 -> 14 | C26: 59/2 | D26: DA+0 | E26: DRY | G26: 45959 | H26: 21.96 | I26: Foundation completed. | M26: 45969 | N26: SHRIARSHINI | P26: 15
B27: =B26+1 -> 15 | C27: 77/7 | D27: DA+0 | E27: DFR | G27: 45963 | H27: 23.27 | I27: Foundation completed. | M27: 45970 | N27: SHIVRATHIRI BALRAJ | P27: 10
B28: =B27+1 -> 16 | C28: 77/8 | D28: DA+0 | E28: DFR | G28: 45963 | H28: 23.27 | I28: Foundation completed. | M28: 45974 | N28: MARC | P28: 10
B29: =B28+1 -> 17 | C29: 60/3 | D29: DA+6 | E29: DRY | G29: 45953 | H29: 25.04 | I29: Foundation completed. | M29: 45976 | N29: SHRIARSHINI | P29: 15
B30: =B29+1 -> 18 | C30: 77/3 | D30: DA+0 | E30: DFR | G30: 45968 | H30: 23.27 | I30: Foundation completed. | M30: 45980 | N30: MARC | P30: 10
B31: =B30+1 -> 19 | C31: 60/8 | D31: DA+3 | E31: DFR | G31: 45973 | H31: 26.43 | I31: Foundation completed. | M31: 45984 | N31: SHRIARSHINI | P31: 10
B32: =B31+1 -> 20 | C32: 77/1 | D32: DA+0 | E32: DRY | G32: 45968 | H32: 21.96 | I32: Foundation completed. | M32: 45986 | N32: MARC | P32: 10
B33: =B32+1 -> 21 | C33: 59/1 | D33: DA+0 | E33: DFR | G33: 45984 | H33: 23.27 | I33: Foundation completed. | M33: 45990 | N33: SHRIARSHINI | P33: 10
B34: =B33+1 -> 22 | C34: 77/2 | D34: DA+0 | E34: DRY | G34: 45979 | H34: 21.96 | I34: Foundation completed. | M34: 45991 | N34: MARC | P34: 10
B35: =B34+1 -> 23 | C35: 58/2 | D35: DA+0 | E35: DRY | G35: 45988 | H35: 21.96 | I35: Foundation completed. | M35: 45994 | N35: SHRIARSHINI | P35: 16
B36: =B35+1 -> 24 | C36: 58/1 | D36: DA+6 | E36: DRY | G36: 45992 | H36: 25.04 | I36: Foundation completed. | M36: 45999 | N36: SHRIARSHINI | P36: 16
... B124: =B123+1 -> 112 | C124: 65/3 | D124: DA+0 | E124: DFR | G124: 46139 | H124: 23.27 | I124: Foundation Completed. | M124: 46141 | N124: ATK | P124: 16
B125: =B124+1 -> 113 | C125: 49/8 | D125: DA+0 | E125: DFR | F125: 46128 | G125: 46136 | H125: 23.27 | I125: Foundation Completed. | M125: 46142 | N125: VEER TEJA CONSTRUCTION | P125: 10
B126: =B125+1 -> 114 | C126: 66/0 | D126: 3DB2+0 | E126: DFR | G126: 46142 | H126: 55.59 | I126: Foundation Completed. | M126: 46145 | N126: ATK | P126: 17
B127: =B126+1 -> 115 | C127: 67/1 | D127: DA+6 | E127: WC | G127: 46141 | H127: 25.77 | I127: Foundation Completed. | M127: 46147 | N127: ATK | P127: 17
B128: =B127+1 -> 116 | C128: 48/7 | D128: DA+0 | E128: DFR | G128: 46132 | H128: 23.27 | I128: Foundation Completed. | M128: 46152 | N128: BALAJI Services | P128: 10
B129: =B128+1 -> 117 | C129: 69/0 | D129: DB2+6 | E129: WET | G129: 46148 | H129: 74.68 | I129: Foundation Completed. | M129: 46155 | N129: ATK | P129: 14
B130: =B129+1 -> 118 | C130: 69/2 | D130: DA+6 | E130: DFR | G130: 46155 | H130: 26.43 | I130: Foundation Completed. | M130: 46158 | N130: ATK | P130: 14
...

Sheet ROW
A1: TL-02 765kV Kurnool IV - Bidar line
A2: Foundation
A3: Sr. No. | B3: Location no. | C3: Type of tower | D3: ISSUE
A4: 1 | B4: 50/0 | C4: DC2+0
A5: =A4+1 -> 2 | B5: 51/1 | C5: DA+3
A6: =A5+1 -> 3 | B6: 51/0 | C6: DC2+0
A7: =A6+1 -> 4 | B7: 51/5 | C7: DA+0
A8: =A7+1 -> 5 | B8: 52/2 | C8: DA+0
A9: =A8+1 -> 6 | B9: 52/3 | C9: DA+0
A10: =A9+1 -> 7 | B10: 52/4 | C10: DA+0
A11: =A10+1 -> 8 | B11: 53/0 | C11: DB1+3
A12: =A11+1 -> 9 | B12: 85/3 | C12: DA+0
A13: =A12+1 -> 10 | B13: 85/4 | C13: DA+0

Sheet SUPPLY
B1: Supply Status - Stubs & Towers
B2: Stub Details
B3: SL No | C3: Description | D3: Unit | E3: Line Qty | F3: Received | G3: Balance
B4: 1 | C4: 3DA Stub | D4: Set | F4: 181
B5: 2 | C5: 3DB Stub | D5: Set | F5: 27
B6: 3 | C6: 3DC Stub | D6: Set | F6: 17
B7: 4 | C7: 3D45 Stub | D7: Set | F7: 6
B8: 5 | C8: 3D60 Stub | D8: Set | F8: 4
C9: Total | D9: Set | E9: =SUM(E4:E8) -> 0 | F9: =SUM(F4:F8) -> 235 | G9: =SUM(G4:G8) -> 0 | H9: =SUM(H4:H8) -> 0 | I9: =SUM(I4:I8) -> 0
B11: Tower Details
B12: SL No | C12: Tower Type | D12: Description | E12: Line Qty | F12: Received | G12: Balance | J12: Remarks
B13: 1 | C13: 3DA Type | D13: Basic body | F13: 195
D14: +0m BE | F14: 154
D15: +3m BE | F15: 41
D16: +6m BE | F16: 18
D17: +9m BE | F17: 12
B18: 2 | C18: 3DB Type | D18: Basic body | F18: 31
D19: +0m BE | F19: 27
D20: +3m BE | F20: 4
D21: +6m BE | F21: 5
D22: +9m BE | F22: 7
B23: 3 | C23: 3DC Type | D23: Basic body | F23: 21
D24: +0m BE | F24: 18
D25: +3m BE | F25: 3
D26: +6m BE | F26: 2
D27: +9m BE | F27: 3
B28: 4 | C28: 3DD45 Type | D28: Basic body | F28: 7
D29: +0m BE | F29: 6
D30: +3m BE | F30: 1
D31: +6m BE | F31: 0
D32: +9m BE | F32: 4
B33: 5 | C33: 3DD60 Type | D33: Basic body | F33: 2
D34: +0m BE | F34: 2
D35: +3m BE | F35: 0
D36: +6m BE | F36: O
D37: +9m BE | F37: 0
D39: Total | F39: =F13+F18+F23+F28+F33 -> 256
B44: Activity | C44: Unit | D44: Final Est. Qty | E44: L2 till Last Month | F44: Received till Last Month | G44: Balance | H44: L2 Plan for Current Month | I44: Plan for Current Month | J44: Progress for the Month | K44: Received till Current Month | L44: Gap between Suppy & Cumm.L2 | M44: Remarks
B45: Stub | C45: Set | D45: ='Master Sheet'!D39 -> 292 | E45: ='Master Sheet'!E39 -> 292 | F45: ='Master Sheet'!F39 -> 235 | G45: ='Master Sheet'!G39 -> 57 | H45: ='Master Sheet'!H39 -> 0 | I45: ='Master Sheet'!I39 -> 0 | J45: ='Master Sheet'!J39 -> 0 | K45: ='Master Sheet'!K39 -> 235 | L45: ='Master Sheet'!L38 -> Gap between Supply & Cumm.L2
B46: Tower | C46: No's | D46: ='Master Sheet'!D40 -> 292 | E46: ='Master Sheet'!E40 -> 230 | F46: ='Master Sheet'!F40 -> 230 | G46: ='Master Sheet'!G40 -> 62 | H46: ='Master Sheet'!H40 -> 60 | I46: ='Master Sheet'!I40 -> 60 | J46: ='Master Sheet'!J40 -> 26 | K46: ='Master Sheet'!K40 -> 256 | L46: ='Master Sheet'!L39 -> 57
...

Sheet Erection Compiled
A2: SL No. | B2: Location No. | C2: Tower Type | D2: Classification | E2: Start Date | F2: MT | G2: Status | H2: End Date | I2: Gang Name | J2: Gang Strength
A3: 1 | B3: 56/7 | C3: DA+0 | D3: DFR | E3: 46006 | F3: 35.089 | G3: Erection Completed. | H3: 46011 | I3: NASIRUDDIN | J3: 35
A4: =A3+1 -> 2 | B4: 59/2 | C4: DA+0 | D4: DRY | E4: 46013 | F4: 35.089 | G4: Erection Completed. | H4: 46018 | I4: NASIRUDDIN | J4: 35
A5: =A4+1 -> 3 | B5: 77/3 | C5: DA+0 | D5: DFR | E5: 46013 | F5: 35.089 | G5: Erection Completed. | H5: 46022 | I5: CRANE | J5: 49
A6: =A5+1 -> 4 | B6: 58/2 | C6: DA+0 | D6: DRY | E6: 46016 | F6: 35.089 | G6: Erection Completed. | H6: 46032 | I6: NASIRUDDIN | J6: 35
A7: =A6+1 -> 5 | B7: 77/2 | C7: DA+0 | D7: DRY | E7: 46016 | F7: 35.089 | G7: Erection Completed. | H7: 46030 | I7: CRANE | J7: 49
A8: =A7+1 -> 6 | B8: 58/1 | C8: DA+6 | D8: DRY | E8: 46024 | F8: 41.88 | G8: Erection Completed. | H8: 46032 | I8: NASIRUDDIN | J8: 35
A9: =A8+1 -> 7 | B9: 77/1 | C9: DA+0 | D9: DRY | E9: 46023 | F9: 35.089 | G9: Erection Completed. | H9: 46035 | I9: CRANE | J9: 49
A10: =A9+1 -> 8 | B10: 58/3 | C10: DA+0 | D10: DRY | E10: 46031 | F10: 35.089 | G10: Erection Completed. | H10: 46036 | I10: NASIRUDDIN | J10: 35
A11: =A10+1 -> 9 | B11: 77/4 | C11: DA+0 | D11: DRY | E11: 46029 | F11: 35.089 | G11: Erection Completed. | H11: 46038 | I11: DK VERMA | J11: 21
A12: =A11+1 -> 10 | B12: 82/1 | C12: DA+0 | D12: WC | E12: 46033 | F12: 35.089 | G12: Erection Completed. | H12: 46038 | I12: SHAKILA KHATUN | J12: 31
A13: =A12+1 -> 11 | B13: 80/5 | C13: DA+0 | D13: DFRY | E13: 46037 | F13: 35.089 | G13: Erection Completed. | H13: 46042 | I13: SHAKILA KHATUN | J13: 31
A14: =A13+1 -> 12 | B14: 59/4 | C14: DA+6 | D14: DRY | E14: 46037 | F14: 41.88 | G14: Erection Completed. | H14: 46043 | I14: NASIRUDDIN | J14: 35
A15: =A14+1 -> 13 | B15: 77/7 | C15: DA+0 | D15: DFR | E15: 46039 | F15: 35.089 | G15: Erection Completed. | H15: 46043 | I15: DK VERMA | J15: 21
... A70: =A69+1 -> 68 | B70: 100/8 | C70: DA+0 | D70: DFR | E70: 46111 | F70: 35.089 | G70: Erection Completed. | H70: 46085 | I70: TNR INFA | J70: 24
A71: =A70+1 -> 69 | B71: 53/5 | C71: DA+0 | D71: DRY | E71: 02.04-2026 | F71: 35.089 | G71: Erection Completed. | H71: 46119 | I71: NASIRUDDIN | J71: 30
A72: =A71+1 -> 70 | B72: 100/0 | C72: DB2+0 | D72: DFR | E72: 46117 | F72: 54.72 | G72: Erection Completed. | H72: 46124 | I72: TNR INFA | J72: 24
A73: =A72+1 -> 71 | B73: 60/0 | C73: DB2+0 | D73: DFR | E73: 46147 | F73: 54.72 | G73: Erection Completed. | H73: 46160 | I73: NASIRUDDIN | J73: 24

Sheet X-ing Details 
B2: CROSSINGS PROPOSAL STATUS : 765 KV D/C Kurnool IV - Bidar TL (Part-2)
B6: Crossing Type | C6: 132 KV | D6: 220kV | E6: SH-Xing | F6: NH-Xing | G6: Railway-Xing | H6: Total
B7: Total Nos | C7: 4 | D7: 2 | E7: 1 | F7: 3 | G7: 2 | H7: 12
B8: Submitted Till Date | C8: 4 | D8: 2 | E8: 0 | F8: 3 | G8: 2 | H8: =C8+D8+F8+G8 -> 11
B9: Approved Till Date | C9: 0 | D9: 0 | E9: 0 | F9: 0 | G9: 0 | H9: 0
B10: Balance to Execute | C10: =C7-C8 -> 0 | D10: =D7-D8 -> 0 | E10: =E7-E8 -> 1 | F10: =F7-F8 -> 0 | G10: =G7-G8 -> 0 | H10: 0
B12: Crossings Details
B13: Sl. No. | C13: FROM (AP) | D13: TO (AP) | E13: Name of the Line | F13: NAME OF CROSSING | G13: Date of First Submission | H13: Joint Inspection Status | I13: Provisional approval status
B14: 1 | C14: AP54 | D14: AP55 | E14: Railway crossing (Tandur - Vikarabad) | F14: Railway crossing | G14: 45987
B15: =B14+1 -> 2 | C15: AP57 | D15: AP58 | E15: 220kV D/C transmission line Tandur - Gachibowli (HYD) | F15: Power line | G15: 45946
B16: =B15+1 -> 3 | C16: AP61 | D16: AP62 | E16: NATIONAL HIGHWAY-163 (Kodangal - Hyderabad) | F16: National highway crossing | G16: 45989
B17: =B16+1 -> 4 | C17: AP71 | D17: AP72 | E17: 132kV D/C transmission line Tandur - Mahabubnagar | F17: Power line | G17: 45944
B18: =B17+1 -> 5 | C18: AP74 | D18: AP75 | E18: NATIONAL HIGHWAY-167N (Kodangal - Kosgi) | F18: National highway crossing | G18: 45989
B19: =B18+1 -> 6 | C19: AP76 | D19: AP77 | E19: 220kV D/C transmission line Kosgi - Pargi | F19: Power line | G19: 45946
B20: =B19+1 -> 7 | C20: AP88 | D20: AP89 | E20: 132kV S/C transmission line Maddur - Mahabubnagar | F20: Power line | G20: 45946
B21: =B20+1 -> 8 | C21: AP95 | D21: AP96 | E21: 132kV S/C transmission line Maddur - Makthal | F21: Power line | G21: 45946
B22: =B21+1 -> 9 | C22: AP98 | D22: AP99 | E22: STATE HIGHWAY-22 (Narayanpet - Marikal) | F22: State highway crossing | G22: Not Required
B23: =B22+1 -> 10 | C23: AP106 | D23: AP107 | E23: Railway crossing (Raichur - Makthal) | F23: Railway crossing | G23: 45988
B24: =B23+1 -> 11 | C24: AP109 | D24: AP110 | E24: 132kV S/C transmission line Makthal - Krishna Railway junction | F24: Power line | G24: 08.12.2025
B25: =B24+1 -> 12 | C25: AP110 | D25: AP111 | E25: NATIONAL HIGHWAY-167N (Raichur - Marikal) | F25: National highway crossing | G25: 08.12.2025

Sheet Visual Chart
A1: VISUAL PROGRESS CHART
A2: 765 kV DC Kurnool IV - Bidar Transmission Line (TL-02)
B3: Foundation (Nos.):- | D3: 122 | E3: /292 | F3: Erection (Nos.):- | H3: 71 | I3: /292 | J3: Earthing (Nos.):- | L3: 99 | M3: /292 | N3: Rough Sag (Kms):- | P3: 0 / | Q3: 113.292 | R3: Final Sag (Kms):- | T3: 0 / | U3: 113.292 | V3: Date:- | W3: =TODAY() -> 46167
B4: COMPLETION CHART | C4: Unit | D4: 0 | E4: +3 | F4: 6 | G4: +9 | H4: Total | I4: Line Qty
J5: ERECTION | P5: Rough Sag | R5: SH / NH Road Crossing
J6: WIP | V6: River
B7: DA | C7: Nos | D7: 135 | E7: 48 | F7: 21 | G7: 12 | H7: =SUM(D7:G7) -> 216 | I7: =H7 -> 216 | J7: FOUNDATION | K7: Type | M7: Angle Tower | R7: Gas Pipeline
B8: DB1 | C8: Nos | D8: 5 | E8: 3 | F8: 1 | G8: 8 | H8: =SUM(D8:G8) -> 17 | I8: =H8 -> 17
B9: DB2 | C9: Nos | D9: 13 | E9: 2 | F9: 4 | G9: 2 | H9: =SUM(D9:G9) -> 21 | I9: =H9 -> 21 | O9: Final Sag
B10: DCT | C10: Nos | D10: 1 | H10: =SUM(D10:G10) -> 1 | I10: =H10 -> 1
B11: DC1 | C11: Nos | D11: 10 | E11: 2 | F11: 1 | G11: 3 | H11: =SUM(D11:G11) -> 16 | I11: =H11 -> 16 | S11: Railway
B12: DC2 | C12: Nos | D12: 3 | E12: 3 | F12: 1 | G12: 0 | H12: =SUM(D12:G12) -> 7 | I12: =H12 -> 7 | Q12: WIP | S12: Crossing
B13: DCT | C13: Nos | D13: 0 | E13: 0 | F13: 0 | G13: 0 | H13: =SUM(D13:G13) -> 0 | I13: =H13 -> 0 | J13: Section Tower | K13: SC | V13: 110kV - 800kV | Z13: Foundation | AA13: Erection | AB13: Earthing
B14: DD45 | C14: Nos | D14: 3 | E14: 1 | F14: 1 | G14: 4 | H14: =SUM(D14:G14) -> 9 | I14: =H14 -> 9 | J14: TP | K14: TT | M14: Earthing | P14: OPGW | V14: Line
B15: DD60 | C15: Nos | D15: 2 | E15: 1 | F15: 1 | G15: 1 | H15: =SUM(D15:G15) -> 5 | I15: =H15 -> 5
B16: Total Completed Foundations | H16: 122 | I16: =292-H16 -> 170 | Z16: =SUM(Z18:Z254) -> 122 | AA16: =SUM(AA18:AA254) -> 71 | AB16: =SUM(AB18:AB254) -> 99
B17: Wind Zone - 3 [AP48 - AP111]
A18: COMMON TOWER (TL-1&2) | AD18: DS | AE18: CS | AF18: SI | AG18: FDN | AH18: EAR | AI18: ERN | AJ18: TW | AK18: PO | AL18: FS | AM18: OPGW
AC19: TOTAL | AD19: =(C21+E21+G21+I21+K21+M21+O21+Q21+S21+U21+W21+Y21)/1000 -> 4.83244 | AE19: =(C21+E21+G21+I21+K21+M21+O21+Q21+S21+U21+W21+Y21)/1000 -> 4.83244 | AG19: 12 | AH19: 12 | AI19: 12 | AJ19: 12 | AL19: =(C21+E21+G21+I21+K21+M21+O21+Q21+S21+U21+W21+Y21)/1000 -> 4.83244
AC20: COMPLETED | AG20: =B21+D21+F21 -> #VALUE!
B21: Balaji Services | C21: 411 | D21: Balaji Service | E21: 432 | F21: Balaji Service | G21: 411 | H21: Balaji Service | I21: 432 | K21: 411 | M21: 432 | O21: 411 | P21: Balaji Service | Q21: 374.437 | R21: AMMU ENGG | S21: 376.003 | U21: 405 | V21: RC | W21: 340 | Y21: 397 | Z21: 3 | AB21: 2 | AC21: BALANCE
B23: AP48/0 | D23: 48/1 | F23: 48/2 | H23: 48/3 | J23: 48/4 | L23: 48/5 | N23: 48/6 | P23: 48/7 | R23: AP49/0 | T23: 49/1 | V23: 49/2 | X23: 49/3
B24: 3DCT+0 | D24: 3DA+6 | F24: 3DA+0 | H24: 3DA+6 | J24: 3DA+3 | L24: 3DA+3 | N24: 3DA+3 | P24: 3DA+3 | Q24: =(Q21+O21+M21+K21+I21+G21+E21+C21)/1000 -> 3.314437 | R24: 3DC1+0 | T24: 3DA+0 | V24: 3DA+0 | X24: 3DA+0
B25: 1st Pit started
H27: Trail pit
B30: AMMU ENGG | C30: 399 | E30: 393 | G30: 370 | H30: VEER TEJA | I30: 350 | J30: VEER TEJA | K30: 395 | L30: VEER TEJA | M30: 413 | N30: VEER TEJA | O30: 366 | P30: VEER TEJA | Q30: 377.77 | R30: VEER TEJA | S30: 300 | T30: SRI HARSH-1 | U30: 393 | V30: SRI HARSH-1 | W30: 415 | X30: SRI HARSH-1 | Y30: 411 | Z30: 8 | AB30: 7
B32: 49/4 | D32: 49/5 | F32: 49/6 | H32: 49/7 | J32: 49/8 | L32: 49/9 | N32: 49/10 | P32: 49/11 | R32: AP50/0 | T32: 50/1 | V32: 50/2 | X32: 50/3
B33: 3DA+0 | D33: 3DA+3 | F33: 3DA+0 | H33: 3DA+0 | J33: 3DA+0 | L33: 3DA+0 | N33: 3DA+0 | P33: 3DA+0 | Q33: =(S21+U21+W21+Y21+Q30+O30+M30+K30+I30+G30+E30+C30)/1000 -> 4.581773 | R33: 3DC2+0 | T33: 3DA+0 | V33: 3DA+0 | X33: 3DA+3 | Y33: =(S30+U30+W30+Y30)/1000 -> 1.519
C39: 378 | E39: 370 | F39: SRI HARSH-1 | G39: 370 | I39: 404 | K39: 374 | M39: 416 | N39: SRI HARSH-1 | O39: 425 | P39: SRI HARSH-1 | Q39: 411 | R39: SRI HARSH-1 | S39: 427 | T39: SRI HARSH-1 | U39: 370 | V39: SRI HARSH-1 | W39: 356 | X39: SRI HARSHI-1 | Y39: 459
Z40: 7 | AA40: 2 | AB40: 7
B41: AP51/0 | D41: 51/1 | F41: 51/2 | H41: 51/3 | J41: 51/4 | L41: 51/5 | N41: 51/6 | P41: 51/7 | R41: 51/8 | T41: 51/9 | V41: 51/10 | X41: AP52/0
B42: 3DC2+0 | D42: 3DA+3 | F42: 3DA+0 | H42: 3DA+0 | J42: 3DA+0 | L42: 3DA+0 | N42: 3DA+3 | P42: 3DA+3 | R42: 3DA+0 | T42: 3DA+3 | V42: 3DA+0 | W42: =(C39+E39+G39+I39+K39+M39+O39+Q39+S39+U39+W39)/1000 -> 4.301 | X42: 3DB2+0
B48: SRI HARSH-1 | C48: 355 | E48: 348 | G48: 434 | I48: 401 | J48: SRI HARSH-1 | K48: 400 | L48: SRI HARSH-1 | M48: 413 | N48: SRI HARSH-1 | O48: 406 | P48: SRI HARSH-1 | Q48: 390 | R48: SRI HARSH-1 | S48: 390 | T48: SRI HARSH-1 | U48: 430 | W48: 332 | Y48: 229.642
Z49: 7 | AA49: 4 | AB49: 7
B50: 52/1 | D50: 52/2 | F50: 52/3 | H50: 52/4 | J50: AP53/0 | L50: 53/1 | N50: 53/2 | P50: 53/3 | R50: 53/4 | T50: 53/5 | V50: 53/6 | X50: AP54/0
B51: 3DA+9 | D51: 3DA+0 | F51: 3DA+0 | H51: 3DA+0 | I51: =(Y39+C48+E48+G48+I48)/1000 -> 1.997 | J51: 3DB1+3 | L51: 3DA+3 | N51: 3DA+0 | P51: 3DA+3 | R51: 3DA+0 | T51: 3DA+0 | V51: 3DA+3 | W51: =(K48+M48+O48+Q48+S48+U48+W48)/1000 -> 2.761 | X51: 3DD60+0 | Y51: =Y48/1000 -> 0.229642
X52: Rly X-ing
C57: 339 | D57: SRI HARSH-1 | E57: 365 | G57: 409 | H57: SRI HARSH-1 | I57: 340.462 | J57: D.Govind Raj | K57: 352 | L57: SRI HARSH-1 | M57: 419 | N57: SRI HARSH-1 | O57: 410 | P57: SRI HARSH-1 | Q57: 413 | R57: SRI HARSH-1 | S57: 407 | T57: RC | U57: 351 | V57: SRI HARSH-1 | W57: 405 | X57: SRI HARSH-1 | Y57: 393
Z58: 8 | AA58: 7 | AB58: 7
B59: AP55/0 | D59: 55/1 | F59: 55/2 | H59: 55/3 | J59: AP56/0 | L59: 56/1 | N59: 56/2 | P59: 56/3 | R59: 56/4 | T59: 56/5 | V59: 56/6 | X59: 56/7
...

Sheet Foundation & Erection
A1: Description | G1: FOUNDATION DETAILS | L1: EARTHING DETAILS | N1: Erection Details
A2: SL. No | B2: Loc No. | C2: Type of Tower | D2: Type of FDN | E2: RC Fdn Y/N | F2: RC Drawing Status | G2: Stub Availbility Y/N | H2: Fdn ROW | I2: Date of Starting | J2: Date of Completion | K2: Gang Name | L2: Type of Earthing Cp/Pipe | M2: Date of Earthing Completed | N2: Tower Parts Availbility | O2: Tonnage MT | P2: Erection ROW | Q2: Date of Starting | R2: Date of Completion | S2: Gang Name
A3: 1 | B3: 48/0 | C3: 3DCT+0 | D3: DFR | E3: No | F3: -
A4: 2 | B4: 48/1 | C4: 3DA+6 | D4: DFR | E4: No | F4: Yes | G4: Yes | H4: Excavated | N4: Yes | O4: 41.88
A5: 3 | B5: 48/2 | C5: 3DA+0 | D5: DFR | E5: No | F5: Yes | G5: Yes | H5: Steel Binding | I5: 46162 | J5: 46166 | K5: Balaji Services | N5: Yes | O5: 35.089
A6: 4 | B6: 48/3 | C6: 3DA+6 | D6: DFR | E6: No | F6: Yes | G6: Yes | H6: Completed | I6: 46153 | J6: 46161 | K6: Balaji Services | L6: C P | M6: 46164 | N6: Yes | O6: 41.88
A7: 5 | B7: 48/4 | C7: 3DA+3 | D7: DFR | E7: No | F7: Yes | G7: Yes | H7: Excavated | N7: Yes | O7: 36.771
A8: 6 | B8: 48/5 | C8: 3DA+3 | D8: DFR | E8: No | F8: Yes | G8: Yes | H8: Wip | N8: Yes | O8: 36.771
A9: 7 | B9: 48/6 | C9: 3DA+3 | D9: DFR | E9: No | F9: Yes | G9: Yes | H9: Pit A&B Row | N9: Yes | O9: 36.771
A10: 8 | B10: 48/7 | C10: 3DA+3 | D10: DFR | E10: No | F10: Yes | G10: Yes | H10: Excavated | I10: 46132 | J10: 46152 | K10: Balaji Services | L10: C P | M10: 46154 | N10: Yes | O10: 36.771
A11: 9 | B11: 49/0 | C11: 3DC1+0 | D11: DFR | E11: No | F11: - | G11: Yes | H11: Clear | N11: Yes | O11: 62.501
A12: 10 | B12: 49/1 | C12: 3DA+0 | D12: DFR | E12: No | F12: Yes | G12: Yes | H12: Trial pit | N12: Yes | O12: 35.089
A13: 11 | B13: 49/2 | C13: 3DA+0 | D13: DFR | E13: Yes | F13: Yes | G13: Yes | H13: Clear | N13: Yes | O13: 35.089
A14: 12 | B14: 49/3 | C14: 3DA+0 | D14: DFR | E14: No | F14: Yes | G14: Yes | H14: Clear | N14: Yes | O14: 35.089
A15: 13 | B15: 49/4 | C15: 3DA+0 | D15: DFR | E15: No | F15: Yes | G15: Yes | H15: Clear | N15: Yes | O15: 35.089
A16: 14 | B16: 49/5 | C16: 3DA+3 | D16: DFR | E16: No | F16: Yes | G16: Yes | H16: Clear | N16: Yes | O16: 36.771
A17: 15 | B17: 49/6 | C17: 3DA+0 | D17: DFR | E17: No | F17: Yes | G17: Yes | H17: Clear | N17: Yes | O17: 35.089
A18: 16 | B18: 49/7 | C18: 3DA+0 | D18: DFR | E18: No | F18: Yes | G18: Yes | H18: Clear | N18: Yes | O18: 35.089
A19: 17 | B19: 49/8 | C19: 3DA+0 | D19: DFR | E19: No | F19: Yes | G19: Yes | H19: Completed | I19: 46136 | J19: 46142 | K19: VEER TEJA CONSTRUCTION | L19: C P | M19: 46142 | N19: Yes | O19: 35.089
A20: 18 | B20: 49/9 | C20: 3DA+0 | D20: DFR | E20: No | F20: Yes | G20: Yes | H20: Completed | I20: 46127 | J20: 46135 | K20: VEER TEJA CONSTRUCTION | N20: Yes | O20: 35.089 | P20: Completed
A21: 19 | B21: 49/10 | C21: 3DA+0 | D21: DFR | E21: No | F21: Yes | G21: Yes | H21: Completed | I21: 46077 | J21: 46092 | K21: VEER TEJA CONSTRUCTION | L21: C P | M21: 46136 | N21: Yes | O21: 35.089 | P21: Completed
A22: 20 | B22: 49/11 | C22: 3DA+0 | D22: WFR | E22: No | F22: Yes | G22: Yes | H22: Completed | I22: 46077 | J22: 46095 | K22: VEER TEJA CONSTRUCTION | L22: C P | M22: 46136 | N22: Yes | O22: 35.089 | P22: Completed
A23: 21 | B23: 50/0 | C23: 3DC2+0 | D23: WFR | E23: No | F23: - | G23: Yes | H23: Completed | I23: 46077 | J23: 46128 | K23: VEER TEJA CONSTRUCTION | L23: C P | M23: 46114 | N23: Yes | O23: 62.501 | P23: Completed
A24: 22 | B24: 50/1 | C24: 3DA+0 | D24: DFR | E24: No | F24: Yes | G24: Yes | H24: Completed | I24: 46060 | J24: 46065 | K24: SHRIARSHINI | L24: C P | M24: 46068 | N24: Yes | O24: 35.089 | P24: Completed
A25: 23 | B25: 50/2 | C25: 3DA+0 | D25: WET | E25: No | F25: Yes | G25: Yes | H25: Completed | I25: 46059 | J25: 46070 | K25: SHRIARSHINI | L25: PTE | M25: 46070 | N25: Yes | O25: 35.089 | P25: Completed
A26: 24 | B26: 50/3 | C26: 3DA+3 | D26: DFR | E26: No | F26: Yes | G26: Yes | H26: Completed | I26: 46101 | J26: 46106 | K26: SHRIARSHINI | L26: C P | M26: 46110 | N26: Yes | O26: 36.771 | P26: Completed
A27: 25 | B27: 51/0 | C27: 3DC2+0 | D27: DFR | E27: No | F27: - | G27: Yes | H27: Row | N27: Yes | O27: 62.501
A28: 26 | B28: 51/1 | C28: 3DA+3 | D28: DFR | E28: No | F28: Yes | G28: Yes | H28: Row | N28: Yes | O28: 36.771
A29: 27 | B29: 51/2 | C29: 3DA+0 | D29: DFR | E29: No | F29: Yes | G29: Yes | H29: Completed | I29: 46102 | J29: 46108 | K29: SHRIARSHINI | L29: C P | M29: 46112 | N29: Yes | O29: 35.089 | P29: Completed
A30: 28 | B30: 51/3 | C30: 3DA+0 | D30: DFR | E30: No | F30: Yes | G30: Yes | H30: Row | N30: Yes | O30: 35.089
A31: 29 | B31: 51/4 | C31: 3DA+0 | D31: WET | E31: No | F31: Yes | G31: Yes | H31: Paddy | N31: Yes | O31: 35.089
A32: 30 | B32: 51/5 | C32: 3DA+0 | D32: DFR | E32: No | F32: Yes | G32: Yes | H32: Paddy | N32: Yes | O32: 35.089
A33: 31 | B33: 51/6 | C33: 3DA+3 | D33: DFR | E33: No | F33: Yes | G33: Yes | H33: Completed | I33: 46092 | J33: 46100 | K33: SHRIARSHINI | L33: C P | M33: 46110 | N33: Yes | O33: 36.771 | P33: Completed
A34: 32 | B34: 51/7 | C34: 3DA+3 | D34: DFR | E34: No | F34: Yes | G34: Yes | H34: Completed | I34: 46087 | J34: 46094 | K34: SHRIARSHINI | L34: C P | M34: 46095 | N34: Yes | O34: 36.771 | P34: Completed
A35: 33 | B35: 51/8 | C35: 3DA+0 | D35: DFR | E35: No | F35: Yes | G35: Yes | H35: Completed | I35: 46088 | J35: 46095 | K35: SHRIARSHINI | L35: C P | M35: 46098 | N35: Yes | O35: 35.089 | P35: Completed
A36: 34 | B36: 51/9 | C36: 3DA+3 | D36: DFR | E36: No | F36: Yes | G36: Yes | H36: Completed | I36: 46054 | J36: 46058 | K36: SHRIARSHINI | L36: C P | M36: 46069 | N36: Yes | O36: 36.771 | P36: Completed | Q36: 46081 | R36: 46086 | S36: =VLOOKUP(B36,#REF!,4,0) -> #REF!
A37: 35 | B37: 51/10 | C37: 3DA+0 | D37: WET | E37: No | F37: Yes | G37: Yes | H37: Completed | I37: 46090 | J37: 46098 | K37: SHRIARSHINI | L37: P T E | M37: 46127 | N37: Yes | O37: 35.089 | P37: Completed
A38: 36 | B38: 52/0 | C38: 3DB2+0 | D38: DFR | E38: No | G38: Yes | H38: Completed | I38: 46045 | J38: 46053 | K38: SHRIARSHINI | L38: C P | M38: 46056 | N38: Yes | O38: 54.72 | P38: Completed | Q38: 46070 | R38: 46074 | S38: =VLOOKUP(B38,#REF!,4,0) -> #REF!
A39: 37 | B39: 52/1 | C39: 3DA+9 | D39: DFR | E39: No | F39: Yes | G39: Yes | H39: Completed | I39: 46098 | J39: 46103 | K39: SHRIARSHINI | L39: C P | M39: 46112 | N39: Yes | O39: 43.575 | P39: Completed
A40: 38 | B40: 52/2 | C40: 3DA+0 | D40: WFR | E40: No | F40: Yes | G40: Yes | H40: Paddy | N40: Yes | O40: 35.089
...

Sheet STRG Stretch 
A1: 765KV D/C K4 - Bidar TL Package -II
A2: Stringing Stretches | M2: Legend | N2: FS Completed | O2: RS Completed | P2: WIP | Q2: Row
A3: S.No | B3: Section From | C3: Section TO | D3: LENGTH (km) | E3: T(T) / M(M) | F3: Total Fdns | G3: Fdn completed | H3: Pending Fdns | I3: Fdn WIP | J3: Total erection | K3: Erection completed | L3: Pending erection | M3: Erection WIP | N3: Stringing Status | O3: Streach Ready Y/N | P3: OPGW Status | Q3: District | R3: POWER/ NH/ Railway crossings | S3: 11kV | T3: 33kV | U3: Tree Cutting status Pending/Clear
A4: 1 | B4: AP48 | C4: AP49 | D4: 3.30661 | E4: M | F4: 8 | H4: =F4-G4 -> 8 | J4: 8 | L4: =J4-K4 -> 8 | Q4: Vikarabad
A5: =A4+1 -> 2 | B5: AP49 | C5: AP50 | D5: 4.58177 | E5: M | F5: 12 | G5: 4 | H5: =F5-G5 -> 8 | J5: 12 | L5: =J5-K5 -> 12 | Q5: Vikarabad
A6: =A5+1 -> 3 | B6: AP50 | C6: AP51 | D6: 1.51904 | E6: M | F6: 4 | G6: 4 | H6: =F6-G6 -> 0 | I6: AP51 | J6: 4 | L6: =J6-K6 -> 4 | Q6: Vikarabad
A7: =A6+1 -> 4 | B7: AP51 | C7: AP52 | D7: 4.30037 | E7: M | F7: 11 | G7: 6 | H7: =F7-G7 -> 5 | J7: 11 | K7: 1 | L7: =J7-K7 -> 10 | O7: Y | Q7: Vikarabad
A8: =A7+1 -> 5 | B8: AP52 | C8: AP53 | D8: 1.995949 | E8: M | F8: 5 | G8: 2 | H8: =F8-G8 -> 3 | J8: 5 | K8: 1 | L8: =J8-K8 -> 4 | Q8: Vikarabad
A9: =A8+1 -> 6 | B9: AP53 | C9: AP54 | D9: 2.77169 | E9: M | F9: 7 | G9: 6 | H9: =F9-G9 -> 1 | I9: AP53 | J9: 7 | K9: 4 | L9: =J9-K9 -> 3 | Q9: Vikarabad
A10: =A9+1 -> 7 | B10: AP54 | C10: AP55 | D10: 0.23844 | E10: T | F10: 1 | G10: 0 | H10: =F10-G10 -> 1 | J10: 1 | L10: =J10-K10 -> 1 | Q10: Vikarabad | R10: Railway Crossing LOC-54/0 | S10: 1
A11: =A10+1 -> 8 | B11: AP55 | C11: AP56 | D11: 1.436452 | E11: M | F11: 4 | G11: 2 | H11: =F11-G11 -> 2 | J11: 4 | K11: 2 | L11: =J11-K11 -> 2 | Q11: Vikarabad | R11: Railway Crossing LOC-55/0
A12: =A11+1 -> 9 | B12: AP56 | C12: AP57 | D12: 5.232645 | E12: M | F12: 13 | G12: 8 | H12: =F12-G12 -> 5 | I12: AP56 | J12: 13 | K12: 7 | L12: =J12-K12 -> 6 | Q12: Vikarabad | T12: 2
A13: =A12+1 -> 10 | B13: AP57 | C13: AP58 | D13: 0.214742 | E13: T | F13: 1 | H13: =F13-G13 -> 1 | J13: 1 | L13: =J13-K13 -> 1 | Q13: Vikarabad | R13: Power Line Crossing LOC-57/0
A14: =A13+1 -> 11 | B14: AP58 | C14: AP59 | D14: 1.588054 | E14: M | F14: 4 | G14: 3 | H14: =F14-G14 -> 1 | J14: 4 | K14: 3 | L14: =J14-K14 -> 1 | Q14: Vikarabad | R14: Power Line Crossing LOC-58/0
A15: =A14+1 -> 12 | B15: AP59 | C15: AP60 | D15: 2.315837 | E15: M | F15: 6 | G15: 5 | H15: =F15-G15 -> 1 | J15: 6 | K15: 4 | L15: =J15-K15 -> 2 | Q15: Vikarabad
A16: =A15+1 -> 13 | B16: AP60 | C16: AP61 | D16: 3.845051 | E16: M | F16: 9 | G16: 4 | H16: =F16-G16 -> 5 | J16: 9 | K16: 1 | L16: =J16-K16 -> 8 | Q16: Vikarabad
A17: =A16+1 -> 14 | B17: AP61 | C17: AP62 | D17: 0.247492 | E17: T | F17: 1 | H17: =F17-G17 -> 1 | J17: 1 | L17: =J17-K17 -> 1 | Q17: Vikarabad | R17: NH Crossing LOC-61/0
A18: =A17+1 -> 15 | B18: AP62 | C18: AP63 | D18: 1.819982 | E18: M | F18: 5 | H18: =F18-G18 -> 5 | J18: 5 | L18: =J18-K18 -> 5 | Q18: Vikarabad | R18: NH Crossing LOC-62/0
A19: =A18+1 -> 16 | B19: AP63 | C19: AP64 | D19: 1.611927 | E19: M | F19: 4 | H19: =F19-G19 -> 4 | J19: 4 | L19: =J19-K19 -> 4 | Q19: Vikarabad
A20: =A19+1 -> 17 | B20: AP64 | C20: AP65 | D20: 0.439047 | E20: T | F20: 1 | H20: =F20-G20 -> 1 | J20: 1 | L20: =J20-K20 -> 1 | Q20: Vikarabad | T20: 2
A21: =A20+1 -> 18 | B21: AP65 | C21: AP66 | D21: 1.39949 | E21: M | F21: 4 | G21: 1 | H21: =F21-G21 -> 3 | J21: 4 | L21: =J21-K21 -> 4 | Q21: Vikarabad | S21: 1
A22: =A21+1 -> 19 | B22: AP66 | C22: AP67 | D22: 0.886818 | E22: M | F22: 2 | G22: 1 | H22: =F22-G22 -> 1 | J22: 2 | L22: =J22-K22 -> 2 | Q22: Vikarabad
A23: =A22+1 -> 20 | B23: AP67 | C23: AP68 | D23: 1.84124 | E23: M | F23: 5 | G23: 1 | H23: =F23-G23 -> 4 | J23: 5 | L23: =J23-K23 -> 5 | Q23: Vikarabad
A24: =A23+1 -> 21 | B24: AP68 | C24: AP69 | D24: 1.160851 | E24: M | F24: 3 | H24: =F24-G24 -> 3 | J24: 3 | L24: =J24-K24 -> 3 | Q24: Vikarabad
A25: =A24+1 -> 22 | B25: AP69 | C25: AP70 | D25: 1.261628 | E25: M | F25: 3 | H25: =F25-G25 -> 3 | J25: 3 | L25: =J25-K25 -> 3 | Q25: Vikarabad
A26: =A25+1 -> 23 | B26: AP70 | C26: AP71 | D26: 1.966984 | E26: M | F26: 5 | G26: 4 | H26: =F26-G26 -> 1 | I26: AP70 | J26: 5 | L26: =J26-K26 -> 5 | Q26: Vikarabad
A27: =A26+1 -> 24 | B27: AP71 | C27: AP72 | D27: 0.248518 | E27: T | F27: 1 | H27: =F27-G27 -> 1 | J27: 1 | L27: =J27-K27 -> 1 | Q27: NarayanPet | R27: Power Line Crossing LOC-71/0
A28: =A27+1 -> 25 | B28: AP72 | C28: AP73 | D28: 0.827684 | E28: M | F28: 2 | H28: =F28-G28 -> 2 | J28: 2 | L28: =J28-K28 -> 2 | Q28: NarayanPet | R28: Power Line Crossing LOC-72/0
A29: =A28+1 -> 26 | B29: AP73 | C29: AP74 | D29: 1.213353 | E29: M | F29: 3 | G29: 2 | H29: =F29-G29 -> 1 | J29: 3 | L29: =J29-K29 -> 3 | Q29: NarayanPet
A30: =A29+1 -> 27 | B30: AP74 | C30: AP75 | D30: 0.250119 | E30: T | F30: 1 | H30: =F30-G30 -> 1 | J30: 1 | L30: =J30-K30 -> 1 | Q30: NarayanPet
A31: =A30+1 -> 28 | B31: AP75 | C31: AP76 | D31: 1.6107 | E31: M | F31: 4 | H31: =F31-G31 -> 4 | J31: 4 | L31: =J31-K31 -> 4 | Q31: NarayanPet
A32: =A31+1 -> 29 | B32: AP76 | C32: AP77 | D32: 0.19645 | E32: T | F32: 1 | H32: =F32-G32 -> 1 | J32: 1 | L32: =J32-K32 -> 1 | N32: Fs completed | Q32: NarayanPet | R32: Power Line Crossing LOC-76/0
A33: =A32+1 -> 30 | B33: AP77 | C33: AP78 | D33: 4.26058 | E33: M | F33: 11 | G33: 9 | H33: =F33-G33 -> 2 | J33: 11 | K33: 7 | L33: =J33-K33 -> 4 | Q33: NarayanPet | R33: Power Line Crossing LOC-77/0
A34: =A33+1 -> 31 | B34: AP78 | C34: AP79 | D34: 1.55509 | E34: M | F34: 4 | G34: 1 | H34: =F34-G34 -> 3 | J34: 4 | L34: =J34-K34 -> 4 | Q34: NarayanPet
A35: =A34+1 -> 32 | B35: AP79 | C35: AP80 | D35: 1.577645 | E35: M | F35: 4 | G35: 3 | H35: =F35-G35 -> 1 | J35: 4 | K35: 2 | L35: =J35-K35 -> 2 | Q35: NarayanPet
A36: =A35+1 -> 33 | B36: AP80 | C36: AP81 | D36: 2.496207 | E36: M | F36: 6 | G36: 3 | H36: =F36-G36 -> 3 | J36: 6 | K36: 2 | L36: =J36-K36 -> 4 | Q36: NarayanPet
A37: =A36+1 -> 34 | B37: AP81 | C37: AP82 | D37: 1.644295 | E37: M | F37: 4 | G37: 2 | H37: =F37-G37 -> 2 | J37: 4 | K37: 1 | L37: =J37-K37 -> 3 | Q37: NarayanPet
A38: =A37+1 -> 35 | B38: AP82 | C38: AP83 | D38: 1.280796 | E38: M | F38: 3 | G38: 1 | H38: =F38-G38 -> 2 | J38: 3 | K38: 1 | L38: =J38-K38 -> 2 | Q38: NarayanPet
A39: =A38+1 -> 36 | B39: AP83 | C39: AP84 | D39: 1.153252 | E39: M | F39: 3 | G39: 2 | H39: =F39-G39 -> 1 | J39: 3 | K39: 2 | L39: =J39-K39 -> 1 | Q39: NarayanPet
A40: =A39+1 -> 37 | B40: AP84 | C40: AP85 | D40: 2.738949 | E40: M | F40: 7 | G40: 6 | H40: =F40-G40 -> 1 | J40: 7 | K40: 5 | L40: =J40-K40 -> 2 | Q40: NarayanPet
...

Sheet Stringing Compiled
A1: S.no | B1: Sec | C1: From AP | D1: To AP | E1: Span (M) | F1: Method | G1: Section Readiness | H1: Insulator Hoisting | I1: P/O Starting Date | J1: P/O Completion Date | K1: P/O | L1: F/S Starting Date | M1: F/S/ Completion Date | N1: Jumpering | O1: Spacering | P1: Clipping | Q1: Length | R1: Status | S1: Gang Name | T1: Gang Strength | U1: Number of Fitters | V1: Hindrance | W1: Remarks
