Workbook
Name \0: #REF!
Name \0: #REF!
Name \A: #REF!
Name \A: #REF!
Name \B: #REF!
Name \B: #REF!
Name \C: #REF!
Name \c1: #REF!
Name \D: #REF!
Name \g: #REF!
Name \H: #REF!
Name \i: #REF!
Name \M: #REF!
Name \N: #REF!
Name \P: #REF!
Name \R: #REF!
Name \S: #REF!
Name \U: #REF!
Name \V: #REF!
Name \z: #REF!
Name _: "tcap"
Name _____________A65537: #REF!
Name _____________A65537: #REF!
Name ____________A655600: #REF!
Name ____________A655600: #REF!
Name ____________drg1: #REF!
Name ____________drg1: #REF!
Name ___________A65537: #REF!
Name ___________A65537: #REF!
Name ___________A655600: #REF!
Name ___________A655600: #REF!
Name ___________a655601: #REF!
Name ___________a655601: #REF!
Name __________A65537: #REF!
Name __________A65537: #REF!
Name __________A655600: #REF!
Name __________A655600: #REF!
Name __________a655601: #REF!
Name __________a655601: #REF!
Name __________a999999: #REF!
Name __________drg1: #REF!
Name __________drg1: #REF!
Name _________A65537: #REF!
Name _________A65537: #REF!
Name _________A655600: #REF!
Name _________A655600: #REF!
Name _________a655601: #REF!
Name _________a655601: #REF!
Name _________a999999: #REF!
Name ________A65537: #REF!
Name ________A65537: #REF!
Name ________A655600: #REF!
Name ________A655600: #REF!
Name ________A655600: #REF!
Name ________A655600: #REF!
Name ________A655600: #REF!
Name ________a655601: #REF!
Name ________a655601: #REF!
Name ________a655601: #REF!
Name ________a655601: #REF!

Sheet Detail Survey-220kV
A2: 220kV - Detailed Survey Progress
A3: Sl. No. | B3: LOC NO | C3: TowerType | D3: Deviation of Angle | E3: CP | F3: Leg Extension | J3: RC | K3: Chimney Extension | O3: Span Length (m) | P3: Section Length | Q3: Detail Survey completion status | T3: Detail Survey Report Submision | W3: Detail Survey Approval | Z3: Remarks
D4: DMS | E4: m | F4: A | G4: B | H4: C | I4: D | J4: m | K4: A | L4: B | M4: C | N4: D | O4: m | P4: m | Q4: Surveyed | R4: DOC | S4: Re-survey | T4: Submitted | U4: Date | V4: Re-submitted | W4: Approved | X4: Date | Y4: Re-apprpved
B5: GANTRY | C5: GANTRY | K5: 0 | L5: 0 | M5: 0 | N5: 0 | Q5: Completed
O6: 126.19 | Q6: Completed
A7: 1 | B7: 0/0 | C7: DD+0 | D7: 16° 50' 9"RT | K7: 0 | L7: 0 | M7: 0 | N7: 0 | P7: 126.19 | Q7: Completed
O8: 292 | Q8: Completed
A9: =IF(B9>0,A7+1," ") -> 2 | B9: 0/1 | C9: DA+3 | K9: 0 | L9: 0 | M9: 0 | N9: 0 | Q9: Completed
A10: =IF(B10>0,A8+1," ") | O10: 360.47 | Q10: Completed
A11: =IF(B11>0,A9+1," ") -> 3 | B11: 1/0 | C11: DC+0 | D11: 15° 52' 12"RT | K11: 0 | L11: 0 | M11: 0 | N11: 0 | P11: 652.47 | Q11: Completed
A12: =IF(B12>0,A10+1," ") | O12: 293 | Q12: Completed
A13: =IF(B13>0,A11+1," ") -> 4 | B13: 1/1 | C13: DA+0 | K13: 0 | L13: 0 | M13: 0 | N13: 0 | Q13: Completed
A14: =IF(B14>0,A12+1," ") | O14: 390.88 | Q14: Completed
A15: =IF(B15>0,A13+1," ") -> 5 | B15: 1/2 | C15: DA+3 | D15: 19° 5' 19"LT | K15: 0 | L15: 0 | M15: 0 | N15: 0 | P15: 683.88 | Q15: Completed | T15: Submitted | V15: 45533 | W15: Approved | X15: 45545
A16: =IF(B16>0,A14+1," ") | O16: 351 | Q16: Completed | T16: Submitted | V16: 45533 | W16: Approved | X16: 45545
A17: =IF(B17>0,A15+1," ") -> 6 | B17: 1A/0 | C17: DC+3 | K17: 0 | L17: 0 | M17: 0 | N17: 0 | Q17: Completed | T17: Submitted | V17: 45533 | W17: Approved | X17: 45545
A18: =IF(B18>0,A16+1," ") | O18: 258 | Q18: Completed | T18: Submitted | V18: 45533 | W18: Approved | X18: 45545
A19: =IF(B19>0,A17+1," ") -> 7 | B19: 1A/1 | C19: DA+3 | K19: 0 | L19: 0 | M19: 0 | N19: 0 | Q19: Completed | T19: Submitted | V19: 45533 | W19: Approved | X19: 45545
A20: =IF(B20>0,A18+1," ") | O20: 322.492 | Q20: Completed | T20: Submitted | V20: 45533 | W20: Approved | X20: 45545
A21: =IF(B21>0,A19+1," ") -> 8 | B21: 1A/2 | C21: DC+0 | D21: 57° 12' 54"LT | K21: 0 | L21: 0 | M21: 0 | N21: 0 | P21: 930.56 | Q21: Completed | T21: Submitted | V21: 45533 | W21: Approved | X21: 45545
A22: =IF(B22>0,A20+1," ") | O22: 248 | Q22: Completed | T22: Submitted | V22: 45533 | W22: Approved | X22: 45545
A23: =IF(B23>0,A21+1," ") -> 9 | B23: 1B/0 | C23: DD+3 | D23: 44° 32' 20"RT | K23: 0 | L23: 0 | M23: 0 | N23: 0 | P23: 249.73 | Q23: Completed | T23: Submitted | V23: 45533 | W23: Approved | X23: 45545
A24: =IF(B24>0,A22+1," ") | O24: 294 | Q24: Completed | T24: Submitted | V24: 45533 | W24: Approved | X24: 45545
A25: =IF(B25>0,A23+1," ") -> 10 | B25: 1C/0 | C25: DD+9 | K25: 0 | L25: 0 | M25: 0 | N25: 0 | Q25: Completed | T25: Submitted | V25: 45533 | W25: Approved | X25: 45545
A26: =IF(B26>0,A24+1," ") | O26: 294.431 | Q26: Completed | T26: Submitted | V26: 45533 | W26: Approved | X26: 45545
A27: =IF(B27>0,A25+1," ") -> 11 | B27: 1C/1 | C27: DA+6 | D27: 28° 26' 27"RT | K27: 0 | L27: 0 | M27: 0 | N27: 0 | P27: 588.43 | Q27: Completed | T27: Submitted | V27: 45533 | W27: Approved | X27: 45545
A28: =IF(B28>0,A26+1," ") | O28: 306 | Q28: Completed | T28: Submitted | V28: 45533 | W28: Approved | X28: 45545
A29: =IF(B29>0,A27+1," ") -> 12 | B29: 1D/0 | C29: DC+0 | K29: 0 | L29: 0 | M29: 0 | N29: 0 | Q29: Completed | T29: Submitted | V29: 45533 | W29: Approved | X29: 45545
A30: =IF(B30>0,A28+1," ") | O30: 393.921 | Q30: Completed | T30: Submitted | V30: 45533 | W30: Approved | X30: 45545
A31: =IF(B31>0,A29+1," ") -> 13 | B31: 1D/1 | C31: DA+0 | D31: 42° 49' 3"RT | K31: 0 | L31: 0 | M31: 0 | N31: 0 | P31: 699.92 | Q31: Completed | T31: Submitted | V31: 45533 | W31: Approved | X31: 45545
A32: =IF(B32>0,A30+1," ") | O32: 356.664 | Q32: Completed | T32: Submitted | V32: 45533 | W32: Approved | X32: 45545
A33: =IF(B33>0,A31+1," ") -> 14 | B33: 1E/0 | C33: DD+6 | D33: 27° 13' 43"RT | K33: 0 | L33: 0 | M33: 0 | N33: 0 | P33: 356.66 | Q33: Completed | T33: Submitted | V33: 45533 | W33: Approved | X33: 45545
A34: =IF(B34>0,A32+1," ") | O34: 174.205 | Q34: Completed | T34: Submitted | V34: 45533 | W34: Approved | X34: 45545
A35: =IF(B35>0,A33+1," ") -> 15 | B35: 2/0 | C35: DC+6 | D35: 49° 56' 13"RT | K35: 0 | L35: 0 | M35: 0 | N35: 0 | P35: 174.21 | Q35: Completed | T35: Submitted | V35: 45533 | W35: Approved | X35: 45545
A36: =IF(B36>0,A34+1," ") | O36: 229.73 | Q36: Completed | T36: Submitted | V36: 45533 | W36: Approved | X36: 45545
A37: =IF(B37>0,A35+1," ") -> 16 | B37: 3/0 | C37: DD+3 | D37: 7° 56' 47"LT | K37: 0 | L37: 0 | M37: 0 | N37: 0 | P37: 229.73 | Q37: Completed | T37: Submitted | V37: 45533 | W37: Approved | X37: 45545
A38: =IF(B38>0,A36+1," ") | O38: 391 | Q38: Completed | T38: Submitted | V38: 45533 | W38: Approved | X38: 45545
A39: =IF(B39>0,A37+1," ") -> 17 | B39: 4/0 | C39: DB+9 | K39: 0 | L39: 0 | M39: 0 | N39: 0 | Q39: Completed | T39: Submitted | V39: 45533 | W39: Approved | X39: 45545
A40: =IF(B40>0,A38+1," ") | O40: 328 | Q40: Completed | T40: Submitted | V40: 45533 | W40: Approved | X40: 45545
A41: =IF(B41>0,A39+1," ") -> 18 | B41: 4/1 | C41: DA+6 | K41: 0 | L41: 0 | M41: 0 | N41: 0 | Q41: Completed | T41: Submitted | V41: 45533 | W41: Approved | X41: 45545
...

Sheet Check Survey-220kV
A1: =+Summary!A2 -> Name of the Line: 220KV DC AL59 line from Neemuch - Chanderiya + 132KV DC ACSS Line from Chanderiya to Hindustan Zinc
A2: 220kV - Check Survey Progress
A3: Sl. No. | B3: LOC NO | C3: TowerType | D3: Deviation of Angle | E3: CP | F3: Leg Extension | J3: RC | K3: Chimney Extension | O3: Span Length (m) | P3: Section Length | Q3: Detail Survey completion status | T3: Detail Survey Report Submision | W3: Detail Survey Approval | Z3: Remarks
D4: DMS | E4: m | F4: A | G4: B | H4: C | I4: D | J4: m | K4: A | L4: B | M4: C | N4: D | O4: m | P4: m | Q4: Surveyed | R4: DOC | S4: Re-survey | T4: Submitted | U4: Date | V4: Re-submitted | W4: Approved | X4: Date | Y4: Re-apprpved
B5: GANTRY | C5: GANTRY | K5: 0 | L5: 0 | M5: 0 | N5: 0
O6: 47
A7: 1 | B7: 0/0 | C7: DD+0 | D7: 16° 50' 9"RT | K7: 0 | L7: 0 | M7: 0 | N7: 0 | P7: 126.19
O8: 196
A9: =IF(B9>0,A7+1," ") -> 2 | B9: 0/1 | C9: DA+3 | K9: 0 | L9: 0 | M9: 0 | N9: 0
A10: =IF(B10>0,A8+1," ") | O10: 196.743
A11: =IF(B11>0,A9+1," ") -> 3 | B11: 1/0 | C11: DC+0 | D11: 15° 52' 12"RT | K11: 0 | L11: 0 | M11: 0 | N11: 0 | P11: 652.47 | W11: Approved
A12: =IF(B12>0,A10+1," ") | O12: 334 | W12: Approved
A13: =IF(B13>0,A11+1," ") -> 4 | B13: 1/1 | C13: DA+0 | K13: 0 | L13: 0 | M13: 0 | N13: 0 | W13: Approved
A14: =IF(B14>0,A12+1," ") | O14: 319 | W14: Approved
B15: 1/2 | C15: DA+3
O16: 384.318
A17: =IF(B17>0,A13+1," ") -> 5 | B17: 1A/0 | C17: DC+3 | D17: 18° 59' 57"LT | K17: 0 | L17: 0 | M17: 0 | N17: 0 | P17: 683.88 | W17: Approved
A18: =IF(B18>0,A14+1," ") | O18: 329 | W18: Approved
A19: =IF(B19>0,A17+1," ") -> 6 | B19: 1A/1 | C19: DA+3 | K19: 0 | L19: 0 | M19: 0 | N19: 0 | W19: Approved
A20: =IF(B20>0,A18+1," ") | O20: 280 | W20: Approved
A21: =IF(B21>0,A19+1," ") -> 7 | B21: 1A/2 | C21: DC+0 | K21: 0 | L21: 0 | M21: 0 | N21: 0 | W21: Approved
A22: =IF(B22>0,A20+1," ") | O22: 232.098 | W22: Approved
A23: =IF(B23>0,A21+1," ") -> 8 | B23: 1B/0 | C23: DD+3 | D23: 57° 18' 17"LT | K23: 0 | L23: 0 | M23: 0 | N23: 0 | P23: 930.56 | W23: Approved
A24: =IF(B24>0,A22+1," ") | O24: 237.783 | W24: Approved
A25: =IF(B25>0,A23+1," ") -> 9 | B25: 1C/0 | C25: DD+9 | D25: 44° 32' 20"RT | K25: 0 | L25: 0 | M25: 0 | N25: 0 | P25: 249.73 | W25: Approved
A26: =IF(B26>0,A24+1," ") | O26: 334 | W26: Approved
A27: =IF(B27>0,A25+1," ") -> 10 | B27: 1C/1 | C27: DA+6 | K27: 0 | L27: 0 | M27: 0 | N27: 0 | W27: Approved
A28: =IF(B28>0,A26+1," ") | O28: 341.209 | W28: Approved
A29: =IF(B29>0,A27+1," ") -> 11 | B29: 1D/0 | C29: DC+0 | D29: 28° 26' 27"RT | K29: 0 | L29: 0 | M29: 0 | N29: 0 | P29: 588.43 | W29: Approved
A30: =IF(B30>0,A28+1," ") | O30: 306.001 | W30: Approved
A31: =IF(B31>0,A29+1," ") -> 12 | B31: 1D/1 | C31: DA+0 | K31: 0 | L31: 0 | M31: 0 | N31: 0 | W31: Approved
A32: =IF(B32>0,A30+1," ") | O32: 393.92 | W32: Approved
A33: =IF(B33>0,A31+1," ") -> 13 | B33: 1E/0 | C33: DD+6 | D33: 42° 49' 3"RT | K33: 0 | L33: 0 | M33: 0 | N33: 0 | P33: 699.92 | W33: Approved
A34: =IF(B34>0,A32+1," ") | O34: 356.664 | W34: Approved
A35: =IF(B35>0,A33+1," ") -> 14 | B35: 2/0 | C35: DC+6 | D35: 27° 13' 43"RT | K35: 0 | L35: 0 | M35: 0 | N35: 0 | P35: 356.66 | W35: Approved
A36: =IF(B36>0,A34+1," ") | O36: 174.205 | W36: Approved
A37: =IF(B37>0,A35+1," ") -> 15 | B37: 3/0 | C37: DD+3 | D37: 49° 56' 13"RT | K37: 0 | L37: 0 | M37: 0 | N37: 0 | P37: 174.21 | W37: Approved
A38: =IF(B38>0,A36+1," ") | O38: 229.73 | W38: Approved
A39: =IF(B39>0,A37+1," ") -> 16 | B39: 4/0 | C39: DB+9 | D39: 7° 56' 47"LT | K39: 0 | L39: 0 | M39: 0 | N39: 0 | P39: 229.73 | W39: Approved
A40: =IF(B40>0,A38+1," ") | O40: 391 | W40: Approved
...

Sheet Detail Survey-132kV
A1: =+Summary!A2 -> Name of the Line: 220KV DC AL59 line from Neemuch - Chanderiya + 132KV DC ACSS Line from Chanderiya to Hindustan Zinc
A2: 132kV - Detailed Survey Progress
A3: Sl. No. | B3: LOC NO | C3: TowerType | D3: Deviation of Angle | E3: CP | F3: Leg Extension | J3: RC | K3: Chimney Extension | O3: Span Length (m) | P3: Section Length | Q3: Detail Survey completion status | T3: Detail Survey Report Submision | W3: Detail Survey Approval | Z3: Remarks
D4: DMS | E4: m | F4: A | G4: B | H4: C | I4: D | J4: m | K4: A | L4: B | M4: C | N4: D | O4: m | P4: m | Q4: Surveyed | R4: DOC | S4: Re-survey | T4: Submitted | U4: Date | V4: Re-submitted | W4: Approved | X4: Date | Y4: Re-apprpved
B5: Tapping Tower | C5: DD+0 | D5: 2° 10' 33"LT | F5: 0 | G5: 0 | H5: 0 | I5: 0 | K5: 0 | L5: 0 | M5: 0 | N5: 0 | Q5: Completed
O6: 25.917 | Q6: Completed
A7: 1 | B7: DE | C7: DD+0 | D7: 44° 51' 5"RT | F7: 0 | G7: 0 | H7: 0 | I7: 0 | K7: 0 | L7: 0 | M7: 0 | N7: 0 | P7: 25.92 | Q7: Completed
O8: 261.985 | Q8: Completed
A9: =IF(B9>0,A7+1," ") -> 2 | B9: 1/0 | C9: DB+0 | D9: 6° 49' 55"RT | F9: 0 | G9: 0 | H9: 0 | I9: 0 | K9: 0 | L9: 0 | M9: 0 | N9: 0 | P9: 261.99 | Q9: Completed
A10: =IF(B10>0,A8+1," ") | O10: 339.331 | Q10: Completed
A11: =IF(B11>0,A9+1," ") -> 3 | B11: 2/0 | C11: DC+6 | D11: 26° 16' 38"LT | F11: 0 | G11: 0 | H11: 0 | I11: 0 | K11: 0 | L11: 0 | M11: 0 | N11: 0 | P11: 339.33 | Q11: Completed
A12: =IF(B12>0,A10+1," ") | O12: 379.175 | Q12: Completed
A13: =IF(B13>0,A11+1," ") -> 4 | B13: 3/0 | C13: DB+6 | D13: 13° 55' 42"RT | F13: 0 | G13: 0 | H13: 0 | I13: 0 | K13: 0 | L13: 0 | M13: 0 | N13: 0 | P13: 379.18 | Q13: Completed
A14: =IF(B14>0,A12+1," ") | O14: 238 | Q14: Completed
A15: =IF(B15>0,A13+1," ") -> 5 | B15: 3/1 | C15: DA+6 | F15: 0 | G15: 0 | H15: 0 | I15: 0 | K15: 0 | L15: 0 | M15: 0 | N15: 0 | Q15: Completed | T15: Submitted | V15: 45533 | W15: Approved | X15: 45545
A16: =IF(B16>0,A14+1," ") | O16: 260 | Q16: Completed | T16: Submitted | V16: 45533 | W16: Approved | X16: 45545
A17: =IF(B17>0,A15+1," ") -> 6 | B17: 3/2 | C17: DA+3 | F17: 0 | G17: 0 | H17: 0 | I17: 0 | K17: 0 | L17: 0 | M17: 0 | N17: 0 | Q17: Completed | T17: Submitted | V17: 45533 | W17: Approved | X17: 45545
A18: =IF(B18>0,A16+1," ") | O18: 256.018 | Q18: Completed | T18: Submitted | V18: 45533 | W18: Approved | X18: 45545
A19: =IF(B19>0,A17+1," ") -> 7 | B19: 4/0 | C19: DB+0 | D19: 2° 10' 59"RT | F19: 0 | G19: 0 | H19: 0 | I19: 0 | K19: 0 | L19: 0 | M19: 0 | N19: 0 | P19: 754.02 | Q19: Completed | T19: Submitted | V19: 45533 | W19: Approved | X19: 45545
A20: =IF(B20>0,A18+1," ") | O20: 321.753 | Q20: Completed | T20: Submitted | V20: 45533 | W20: Approved | X20: 45545
A21: =IF(B21>0,A19+1," ") -> 8 | B21: 4/1 | C21: DB+0 | F21: 0 | G21: 0 | H21: 0 | I21: 0 | K21: 0 | L21: 0 | M21: 0 | N21: 0 | P21: 321.75 | Q21: Completed | T21: Submitted | V21: 45533 | W21: Approved | X21: 45545
A22: =IF(B22>0,A20+1," ") | O22: 161.247 | Q22: Completed | T22: Submitted | V22: 45533 | W22: Approved | X22: 45545
A23: =IF(B23>0,A21+1," ") -> 9 | B23: 4/2 | C23: DA+3 | F23: 0 | G23: 0 | H23: 0 | I23: 0 | K23: 0 | L23: 0 | M23: 0 | N23: 0 | Q23: Completed | T23: Submitted | V23: 45533 | W23: Approved | X23: 45545
A24: =IF(B24>0,A22+1," ") | O24: 327.381 | Q24: Completed | T24: Submitted | V24: 45533 | W24: Approved | X24: 45545
A25: =IF(B25>0,A23+1," ") -> 10 | B25: 5/0 | C25: DD+3 | D25: 23° 16' 52"RT | F25: 0 | G25: 0 | H25: 0 | I25: 0 | K25: 0 | L25: 0 | M25: 0 | N25: 0 | P25: 488.63 | Q25: Completed | T25: Submitted | V25: 45533 | W25: Approved | X25: 45545
A26: =IF(B26>0,A24+1," ") | O26: 36.276 | Q26: Completed | T26: Submitted | V26: 45533 | W26: Approved | X26: 45545
A27: =IF(B27>0,A25+1," ") -> 11 | B27: 5/1 | C27: GANTRY UC (+2M) | F27: 0 | G27: 0 | H27: 0 | I27: 0 | K27: 0 | L27: 0 | M27: 0 | N27: 0 | P27: 29 | Q27: Completed | T27: Submitted | V27: 45533 | W27: Approved | X27: 45545
A28: =IF(B28>0,A26+1," ") | O28: 61.139 | Q28: Completed | T28: Submitted | V28: 45533 | W28: Approved | X28: 45545
A29: =IF(B29>0,A27+1," ") -> 12 | B29: 5/2 | C29: GANTRY UC (+2M) | F29: 0 | G29: 0 | H29: 0 | I29: 0 | K29: 0 | L29: 0 | M29: 0 | N29: 0 | P29: 81 | Q29: Completed | T29: Submitted | V29: 45533 | W29: Approved | X29: 45545
A30: =IF(B30>0,A28+1," ") | O30: 38.566 | Q30: Completed | T30: Submitted | V30: 45533 | W30: Approved | X30: 45545
A31: =IF(B31>0,A29+1," ") -> 13 | B31: 6/0 | C31: DD+0 | D31: 25° 0' 0"LT | F31: 0 | G31: 0 | H31: 0 | I31: 0 | K31: 0 | L31: 0 | M31: 0 | N31: 0 | P31: 25.98 | Q31: Completed | T31: Submitted | V31: 45533 | W31: Approved | X31: 45545
A32: =IF(B32>0,A30+1," ") | O32: 182.043 | Q32: Completed | T32: Submitted | V32: 45533 | W32: Approved | X32: 45545
A33: =IF(B33>0,A31+1," ") -> 14 | B33: 6A/0 | C33: DD+0 | D33: 53° 55' 29"LT | F33: 0 | G33: 0 | H33: 0 | I33: 0 | K33: 0 | L33: 0 | M33: 0 | N33: 0 | P33: 182.04 | Q33: Completed | T33: Submitted | V33: 45533 | W33: Approved | X33: 45545
A34: =IF(B34>0,A32+1," ") | O34: 204.148 | Q34: Completed | T34: Submitted | V34: 45533 | W34: Approved | X34: 45545
A35: =IF(B35>0,A33+1," ") -> 15 | B35: 7/0 | C35: DB+0 | D35: 12° 53' 30"LT | F35: 0 | G35: 0 | H35: 0 | I35: 0 | K35: 0 | L35: 0 | M35: 0 | N35: 0 | P35: 204.15 | Q35: Completed | T35: Submitted | V35: 45533 | W35: Approved | X35: 45545
A36: =IF(B36>0,A34+1," ") | O36: 254 | Q36: Completed | T36: Submitted | V36: 45533 | W36: Approved | X36: 45545
A37: =IF(B37>0,A35+1," ") -> 16 | B37: 7/1 | C37: DA+3 | F37: 0 | G37: 0 | H37: 0 | I37: 0 | K37: 0 | L37: 0 | M37: 0 | N37: 0 | Q37: Completed | T37: Submitted | V37: 45533 | W37: Approved | X37: 45545
A38: =IF(B38>0,A36+1," ") | O38: 294 | Q38: Completed | T38: Submitted | V38: 45533 | W38: Approved | X38: 45545
A39: =IF(B39>0,A37+1," ") -> 17 | B39: 7/2 | C39: DA+3 | F39: 0 | G39: 0 | H39: 0 | I39: 0 | K39: 0 | L39: 0 | M39: 0 | N39: 0 | Q39: Completed | T39: Submitted | V39: 45533 | W39: Approved | X39: 45545
A40: =IF(B40>0,A38+1," ") | O40: 249.824 | Q40: Completed | T40: Submitted | V40: 45533 | W40: Approved | X40: 45545
...

Sheet Check Survey-132kV
A1: =+Summary!A2 -> Name of the Line: 220KV DC AL59 line from Neemuch - Chanderiya + 132KV DC ACSS Line from Chanderiya to Hindustan Zinc
A2: 220kV - Check Survey Progress
A3: Sl. No. | B3: LOC NO | C3: TowerType | D3: Deviation of Angle | E3: CP | F3: Leg Extension | J3: RC | K3: Chimney Extension | O3: Span Length (m) | P3: Section Length | Q3: Detail Survey completion status | T3: Detail Survey Report Submision | W3: Detail Survey Approval | Z3: Remarks
D4: DMS | E4: m | F4: A | G4: B | H4: C | I4: D | J4: m | K4: A | L4: B | M4: C | N4: D | O4: m | P4: m | Q4: Surveyed | R4: DOC | S4: Re-survey | T4: Submitted | U4: Date | V4: Re-submitted | W4: Approved | X4: Date | Y4: Re-apprpved
B5: GANTRY | C5: GANTRY | K5: 0 | L5: 0 | M5: 0 | N5: 0
A6: =IF(B6>0,#REF!+1," ") -> #REF! | B6: 1/0 | C6: DE+0 | D6: 42° 49' 3"RT | K6: 0 | L6: 0 | M6: 0 | N6: 0 | P6: 699.92
A7: =IF(B7>0,#REF!+1," ") | O7: 230.15
A8: =IF(B8>0,A6+1," ") -> #REF! | B8: 2/0 | C8: DB+0 | D8: 27° 13' 43"RT | K8: 0 | L8: 0 | M8: 0 | N8: 0 | P8: 356.66
A9: =IF(B9>0,A7+1," ") | O9: 234.56
A10: =IF(B10>0,A8+1," ") -> #REF! | B10: 2/1 | C10: DB+6 | D10: 49° 56' 13"RT | K10: 0 | L10: 0 | M10: 0 | N10: 0 | P10: 174.21
A11: =IF(B11>0,A9+1," ") | O11: 251.12
A12: =IF(B12>0,A10+1," ") -> #REF! | B12: 3/0 | C12: DD+0 | D12: 7° 56' 47"LT | K12: 0 | L12: 0 | M12: 0 | N12: 0
A13: =IF(B13>0,A11+1," ") | O13: 183
A14: =IF(B14>0,A12+1," ") -> #REF! | B14: 3/1 | C14: DA+3 | K14: 0 | L14: 0 | M14: 0 | N14: 0 | P14: 321.75
A15: =IF(B15>0,A13+1," ") | O15: 182.07
A16: =IF(B16>0,A14+1," ") -> #REF! | B16: 4/0 | C16: DC+0 | K16: 0 | L16: 0 | M16: 0 | N16: 0
A17: =IF(B17>0,A15+1," ") | O17: 328.09
A18: =IF(B18>0,A16+1," ") -> #REF! | B18: 5/0 | C18: DD+3 | K18: 0 | L18: 0 | M18: 0 | N18: 0 | P18: 488.63 | Q18: Completed | W18: Approved
A19: =IF(B19>0,A17+1," ") | O19: 40 | Q19: Completed | W19: Approved
A20: =IF(B20>0,A18+1," ") -> #REF! | B20: 5/1 | C20: GANTRY UC (+2M) | K20: 0 | L20: 0 | M20: 0 | N20: 0 | P20: 40 | Q20: Completed | W20: Approved
A21: =IF(B21>0,A19+1," ") | O21: 57.415 | Q21: Completed | W21: Approved
A22: =IF(B22>0,A20+1," ") -> #REF! | B22: 5/2 | C22: GANTRY UC (+2M) | K22: 0 | L22: 0 | M22: 0 | N22: 0 | P22: 57.42 | Q22: Completed | W22: Approved
A23: =IF(B23>0,A21+1," ") | O23: 38.566 | Q23: Completed | W23: Approved
A24: =IF(B24>0,A22+1," ") -> #REF! | B24: 6/0 | C24: DD+0 | K24: 0 | L24: 0 | M24: 0 | N24: 0 | P24: 38.57 | Q24: Completed | W24: Approved
A25: =IF(B25>0,A23+1," ") | O25: 182.043 | Q25: Completed | W25: Approved
A26: =IF(B26>0,A24+1," ") -> #REF! | B26: 6A/0 | C26: DD+0 | K26: 0 | L26: 0 | M26: 0 | N26: 0 | P26: 182.04 | Q26: Completed | W26: Approved
A27: =IF(B27>0,A25+1," ") | O27: 204.148 | Q27: Completed | W27: Approved
A28: =IF(B28>0,A26+1," ") -> #REF! | B28: 7/0 | C28: DB+0 | K28: 0 | L28: 0 | M28: 0 | N28: 0 | P28: 204.15 | Q28: Completed | W28: Approved
A29: =IF(B29>0,A27+1," ") | O29: 230 | Q29: Completed | W29: Approved
A30: =IF(B30>0,A28+1," ") -> #REF! | B30: 7/1 | C30: DA+3 | K30: 0 | L30: 0 | M30: 0 | N30: 0 | Q30: Completed | W30: Approved
A31: =IF(B31>0,A29+1," ") | O31: 294 | Q31: Completed | W31: Approved
A32: =IF(B32>0,A30+1," ") -> #REF! | B32: 7/2 | C32: DA+3 | J32: 1 | K32: 1 | L32: 1 | M32: 1 | N32: 1 | Q32: Completed | W32: Approved
A33: =IF(B33>0,A31+1," ") | O33: 249.82 | Q33: Completed | W33: Approved
A34: =IF(B34>0,A32+1," ") -> #REF! | B34: 8/0 | C34: DD+3 | K34: 0 | L34: 0 | M34: 0 | N34: 0 | Q34: Completed | W34: Approved
A35: =IF(B35>0,A33+1," ") | O35: 329.66 | Q35: Completed | W35: Approved
A36: =IF(B36>0,A34+1," ") -> #REF! | B36: 9/0 | C36: DD+3 | K36: 0 | L36: 0 | M36: 0 | N36: 0 | Q36: Completed | W36: Approved
A37: =IF(B37>0,A35+1," ") | O37: 170 | Q37: Completed | W37: Approved
A38: =IF(B38>0,A36+1," ") -> #REF! | B38: 9/1 | C38: DA+6 | K38: 0 | L38: 0 | M38: 0 | N38: 0 | Q38: Completed | W38: Approved
A39: =IF(B39>0,A37+1," ") | O39: 312 | Q39: Completed | W39: Approved
A40: =IF(B40>0,A38+1," ") -> #REF! | B40: 9/2 | C40: DA+6 | K40: 0 | L40: 0 | M40: 0 | N40: 0 | Q40: Completed | W40: Approved
...

Sheet Summary
A1: Client: M/S STERLITE POWER TRANSMISSION LIMITED
A2: Name of the Line: 220KV DC AL59 line from Neemuch - Chanderiya + 132KV DC ACSS Line from Chanderiya to Hindustan Zinc | O2: Contractual Start Date : | R2: 45449
A3: Name of Document : Daily Progress Report (DPR) | O3: Contractual Completion Date: | R3: 45802
A4: Office: Neemuch | O4: Revised Completion Date : | R4: 46188
A5: Progress of 220kV Line | Q5: Date: | R5: 46162
A6: Sr. No. | B6: Activity | C6: UoM | D6: Total Quantity | E6: As per L2 | G6: Cumm. Progress up to last Month | I6: Progress of Current Month (May'26) | L6: Cumulative till current month | O6: Resources Status | R6: Critical Issues, if any & Remark
E7: Start Date | F7: End Date | G7: L2 | H7: Actual | I7: Plan | J7: Today | K7: Progress in Month | L7: Target (L2) | M7: Completed | N7: Balance | O7: Targeted Gang | P7: Available Gang | Q7: Shortfall Gang
A8: 1 | B8: Detailed Survey | C8: Kms | D8: 64 | E8: 45461 | F8: 45535 | G8: 64 | H8: 64.178 | I8: 0 | J8: 0 | K8: =M8-H8 -> 0 | L8: 64 | M8: 64.178 | N8: =D8-M8 -> -0.178 | O8: 0 | P8: 0 | Q8: =+O8-P8 -> 0
A9: 2 | B9: Check Survey | C9: Kms | D9: 64 | E9: 45474 | F9: 45565 | G9: 64 | H9: =H8 -> 64.178 | I9: 0 | J9: 0 | K9: =M9-H9 -> 0 | L9: 64 | M9: =M8 -> 64.178 | N9: =D9-M9 -> -0.178 | Q9: =+O9-P9 -> 0
A10: 3 | B10: Foundation | C10: Nos. | D10: 199 | E10: 45505 | F10: 45688 | G10: 199 | H10: 198 | I10: 1 | J10: 0 | K10: =M10-H10 -> 1 | L10: 199 | M10: ='Progress-220kV'!AM411 -> 199 | N10: =D10-M10 -> 0 | O10: 1 | P10: 1 | Q10: =+O10-P10 -> 0
A11: 4 | B11: Earthing | C11: Nos. | D11: 199 | E11: 45505 | F11: 45688 | G11: 199 | H11: 198 | I11: 1 | J11: 0 | K11: 1 | L11: 199 | M11: ='Progress-220kV'!AV411 -> 199 | N11: =D11-M11 -> 0
A12: 5 | B12: Tower Erection | C12: Nos. | D12: 199 | E12: 45555 | F12: 45716 | G12: 199 | H12: 195 | I12: 4 | J12: 0 | K12: =M12-H12 -> 2 | L12: 199 | M12: ='Progress-220kV'!BB411 -> 197 | N12: =D12-M12 -> 2 | O12: 2 | P12: 0 | Q12: 2 | R12: 34/0 erection under progress | AQ12: 12500
A13: 6 | B13: Tack Welding | C13: Nos. | D13: 199 | E13: 45555 | F13: 45716 | G13: 199 | H13: 194 | I13: 5 | J13: 0 | K13: =M13-H13 -> 0 | L13: 199 | M13: ='Progress-220kV'!BI411 -> 194 | N13: =D13-M13 -> 5 | O13: 0 | P13: 0 | Q13: =+O13-P13 -> 0
A14: 7 | B14: Stringing | C14: Kms | K14: =M14-H14 -> 0 | AQ14: =9 -> 9
A15: i | B15: Paying Out | C15: Kms | D15: 64 | E15: 45607 | F15: 45777 | G15: 64 | H15: 61.2 | I15: =G15-H15 -> 2.8 | J15: 0 | K15: =M15-H15 -> -0.000737 | L15: 64 | M15: ='Stringing-220kV'!I3 -> 61.199263 | N15: =D15-M15 -> 2.800737 | O15: 1 | P15: 0 | Q15: =+O15-P15 -> 1 | AQ15: 15
A16: ii | B16: Final Sag | C16: Kms | D16: 64 | E16: 45607 | F16: 45777 | G16: 64 | H16: 61.2 | I16: =G16-H16 -> 2.8 | J16: 0 | K16: =M16-H16 -> -0.000737 | L16: 64 | M16: ='Stringing-220kV'!L3 -> 61.199263 | N16: =D16-M16 -> 2.800737
A17: iii | B17: OPGW | C17: Kms | D17: 64 | E17: 45627 | F17: 45777 | G17: 64 | H17: 53.721835 | I17: =G17-H17 -> 10.278165 | J17: 0 | K17: =M17-H17 -> 8.527381 | L17: 64 | M17: ='Stringing-220kV'!X3 -> 62.249216 | N17: =D17-M17 -> 1.750784 | O17: 1 | P17: 0 | Q17: =+O17-P17 -> 1
A19: Progress of 132kV Line | Q19: Date: | R19: =+R5 -> 46162
A20: Sr. No. | B20: Activity | C20: UoM | D20: Total Quantity | E20: As per L2 | G20: Cumm. Progress up to last Month | I20: =+I6 -> Progress of Current Month (May'26) | L20: Cumulative till current month | O20: Resources Status | R20: Critical Issues, if any & Remark
E21: Start Date | F21: End Date | G21: L2 | H21: Actual | I21: Plan | J21: Today | K21: Progress in Month | L21: Target (L2) | M21: Completed | N21: Balance | O21: Targeted Gang | P21: Available Gang | Q21: Shortfall Gang
A22: 1 | B22: Detailed Survey | C22: Kms | D22: 9 | E22: 45461 | F22: 45535 | G22: 9 | H22: 9 | J22: 0 | K22: =M22-H22 -> 0 | L22: 9 | M22: 9 | N22: =D22-M22 -> 0 | Q22: =+O22-P22 -> 0
A23: 2 | B23: Check Survey | C23: Kms | D23: 9 | E23: 45474 | F23: 45565 | G23: 9 | H23: 9 | J23: 0 | K23: =M23-H23 -> 0 | L23: 9 | M23: 9 | N23: =D23-M23 -> 0 | Q23: =+O23-P23 -> 0
A24: 3 | B24: Foundation | C24: Nos. | D24: 39 | E24: 45505 | F24: 45688 | G24: 39 | H24: 34 | I24: 5 | J24: 0 | K24: =M24-H24 -> 2 | L24: 39 | M24: ='Progress-132kV'!AF89 -> 36 | N24: =D24-M24 -> 3 | O24: 1 | P24: 1 | Q24: =O24-P24 -> 0 | R24: SC-2 Excavation Under Progress
A25: 4 | B25: Earthing | C25: Nos. | D25: 39 | E25: 45505 | F25: 45688 | G25: 39 | H25: 34 | I25: 5 | J25: 0 | K25: =M25-H25 -> 2 | L25: 39 | M25: ='Progress-132kV'!AL89 -> 36 | N25: =D25-M25 -> 3 | O25: 1 | P25: 1 | Q25: 0
A26: 5 | B26: Tower Erection | C26: Nos. | D26: 39 | E26: 45555 | F26: 45716 | G26: 39 | H26: 31 | I26: 5 | J26: 0 | K26: =M26-H26 -> 0 | L26: 39 | M26: ='Progress-132kV'!AQ89 -> 31 | N26: =D26-M26 -> 8 | O26: 1 | P26: 1 | Q26: =+O26-P26 -> 0
A27: 6 | B27: Tack Welding | C27: Nos. | D27: 39 | E27: 45555 | F27: 45716 | G27: 39 | H27: 29 | I27: 0 | J27: 0 | K27: =M27-H27 -> 0 | L27: 39 | M27: ='Progress-132kV'!AV89 -> 29 | N27: =D27-M27 -> 10 | O27: 1 | P27: 0 | Q27: 0
A28: 7 | B28: Stringing
A29: i | B29: Paying Out | C29: Kms | D29: 9 | E29: 45607 | F29: 45777 | G29: 9 | H29: 5 | I29: =D29-H29 -> 4 | J29: 0 | K29: =M29-H29 -> 1.231326 | L29: 9 | M29: ='Stringing-132KV'!I3 -> 6.231326 | N29: =D29-M29 -> 2.768674 | O29: 1 | P29: 1 | Q29: =+O29-P29 -> 0 | R29: 10/0, 11/0 Jumper work done
A30: ii | B30: Final Sag | C30: Kms | D30: 9 | E30: 45607 | F30: 45777 | G30: 9 | H30: 5 | I30: =D30-H30 -> 4 | J30: 0 | K30: =M30-H30 -> 1.231326 | L30: 9 | M30: ='Stringing-132KV'!L3 -> 6.231326 | N30: =D30-M30 -> 2.768674
A31: iii | B31: OPGW | C31: Kms | D31: 9 | E31: 45627 | F31: 45777 | G31: 9 | H31: 0 | I31: =G31-H31 -> 9 | J31: 0 | K31: =M31-H31 -> 6.231326 | L31: 9 | M31: ='Stringing-132KV'!Y3 -> 6.231326 | N31: =D31-M31 -> 2.768674 | O31: 1 | P31: 0 | Q31: =+O31-P31 -> 1

Sheet Statutory
A1: =+Summary!A2 -> Name of the Line: 220KV DC AL59 line from Neemuch - Chanderiya + 132KV DC ACSS Line from Chanderiya to Hindustan Zinc
A2: SI No | B2: Name of Existing Line/Croccing | C2: Name of the owner of existing line | D2: Crossing Type | E2: Existing Crossing Span (M) | F2: Existing Tower/K MP No | G2: AP | H2: Tower Type | I2: RC if any | J2: Crossing Angle | K2: Crossing Span Length | L2: Electrical Clearance | M2: Proposal Preparation | N2: Proposal Submission to Sterlite on | O2: Submission to concerned office | P2: Joint site inspection | Q2: Submission of charges (if any) | R2: NOC Received on | S2: Remarks
A3: Statutory/Crossing Tracker - 220KV D/C Line
A4: 1 | B4: NH-27 | C4: NHAI | D4: NH | G4: 1B/0-1C/0 | H4: 1B/0(DD+3)-1C/0(DD+3) | I4: - | K4: 248
A5: 2 | B5: NH-27 | C5: NHAI | D5: NH | G5: 3/0-4/0 | H5: 3/0(DD+3)-4/0(DB+9) | I5: - | K5: 229.73
A6: 3 | B6: 220KV S/C LINE | C6: PGCIL | D6: PLC | E6: 179-180 | G6: 24/0-25/0 | H6: 24/0(DD+9)-25/0(DD+18) | I6: 3M & 2M | K6: 190.52
A7: 4 | B7: 220KV D/C RPB-CGH LINE | C7: PGCIL | D7: PLC | E7: 179-180 | G7: 26/0-27/0 | H7: 26/0(DD+18)-27/0(DD+18) | I7: 3M & 0M | K7: 142.38
A8: 5 | B8: 400KV T/L | D8: PLC | G8: 28/1-28/2 | H8: 28/1(Gantry)-28/2(Gantry) | I8: - | K8: 44
A9: 6 | B9: WATER RESERVOIR BOUNDARY | G9: 31/0-31/1 | H9: 31/0(DB+0)-31/1(DA+6) | I9: 0M & 4M | K9: 361
A11: Statutory/Crossing Tracker - 132KV D/C Line
A12: 1 | B12: Gas Pipeline | D12: Pipeline | G12: Tapping Tower -DE | H12: Tapping Tower(DD+0 ) - DE (DD+0) | I12: - | K12: 25.92
A13: 2 | B13: Pipeline, Cable | D13: Pipeline | G13: 3/1-3/2 | H13: 3/1(DA+6)-3/2(DA+3) | I13: - | K13: 260
A14: 3 | B14: River | D14: River | G14: 4/0-4/1 | H14: 4/0(DB-3)-4/1(DB-3) | I14: - | K14: 302
A15: 4 | B15: 220KV D/C LINE | D15: PLC | G15: 5/1-5/2 | H15: 5/1(Gantry)-5/2(Gantry) | I15: - | K15: 50
A16: 5 | B16: RAILWAY TRACK | D16: Railway | G16: 10/0-11/0 | H16: 10/0(DD+6)-11/0(DD+6) | I16: - | K16: 215.13
A17: 6 | B17: 220KV S/C LINE | D17: PLC | G17: 13/1-13/2 | H17: 13/1(Gantry)-13/2(Gantry) | I17: - | K17: 53
A18: 7 | B18: NH-27 | C18: NHAI | D18: NH | G18: 14/0-15/0 | H18: 14/0(DD+6)-15/0(DD-3) | I18: - | K18: 250
A22: Name of Existing Line/Croccing | B22: Name of the owner of existing line | C22: Crossing Type | D22: Section | E22: Submission | F22: JVR | G22: Remarks
A23: NH-27 | B23: NHAI | C23: NH | D23: 1B/0-1C/0 | F23: 45654 | G23: Approval Recieved
A24: NH-27 | B24: NHAI | C24: NH | D24: 3/0-4/0 | F24: 45586 | G24: Approval Recieved
A25: 220KV S/C LINE | B25: PGCIL | C25: PLC | D25: 24/0-25/0 | E25: 06-01-2025 (2nd Submission) | G25: Approval Recieved
A26: 220KV D/C RPB-CGH LINE | B26: PGCIL | C26: PLC | D26: 26/0-27/0 | E26: 06-01-2025 (2nd Submission) | G26: Approval Recieved
A27: 400KV T/L | B27: PGCIL | C27: PLC | D27: 28/1-28/2 | E27: 06-01-2025 (2nd Submission) | G27: Approval Recieved
A28: 220KV S/C RUMS Line | B28: PGCIL | C28: PLC | D28: 33/1-34/0 | G28: Proposal Submitted Awaiting for approval
A29: 132KV S/C RUMS Line | B29: PGCIL | C29: PLC | D29: 34/0-35/0 | G29: Proposal Submitted Awaiting for approval
A31: 132KV
A33: Name of Existing Line/Croccing | B33: Name of the owner of existing line | C33: Crossing Type | D33: Section | E33: Submission | F33: JVR | G33: Remarks
A34: 220KV D/C LINE | B34: PLC | D34: 4/1-4/2 | E34: 45667 | F34: 45667 | G34: Proposal will be submitted in Chittorgarh.
A35: RAILWAY TRACK | B35: Railway | D35: 10/0-11/0 | E35: 45659 | F35: 45666 | G35: Approval Recieved
A36: 220KV S/C LINE | B36: PLC | D36: 13/1-13/2 | F36: 45648 | G36: Approval Recieved
A37: 765KV S/C LINE | B37: PLC | D37: 16/1-16/2 | E37: 45637 | G37: Approval Recieved
A38: NH-27 | B38: NHAI | C38: NH | D38: 14/0-15/0 | G38: Approval Recieved

Sheet Progress-132kV
A1: =+Summary!A2 -> Name of the Line: 220KV DC AL59 line from Neemuch - Chanderiya + 132KV DC ACSS Line from Chanderiya to Hindustan Zinc
A2: =+Summary!A5 -> Progress of 220kV Line
A3: 220 KV D/C Neemuch - TS | T3: Foundation | AL3: Earthing | AQ3: Erection | AU3: Tower Checking-1 | AV3: Tack-Welding | BA3: Tower Checking-2
A4: Sl. No. | B4: LOC NO | C4: Tower Type | G4: Tower Weight | K4: Stub Weight | O4: Chimney Extension | S4: Span Length(m) | T4: Classification | U4: Excavation Volume (m3) | V4: Concreting Volume | Y4: 8mm Steel | Z4: 10mm Steel | AA4: 12mm Steel | AB4: 16mm Steel | AC4: 20mm Steel | AD4: 25mmSteel | AE4: Total Steel (MT) | AF4: Status (C/WIP) | AG4: Excavation | AI4: Concreting | AK4: Sub-Contractor Name | AL4: Status C/WIP | AM4: Type | AN4: DOS | AO4: DOC | AP4: Sub-Contractor Name | AQ4: Status C/WIP | AR4: DOS | AS4: DOC | AT4: Sub-Contractor Name | AV4: Status C/WIP | AW4: DOS | AX4: DOC | AY4: Painting | AZ4: Sub-Contractor Name
G5: HT | H5: MS | I5: BnA | J5: Total | K5: HT | L5: MS | M5: BnA | N5: Total | O5: A | P5: B | Q5: C | R5: D | S5: m | V5: M10 (1:3:6) (m3) | W5: M20 (1:1.5:3) (m3) | X5: Total | AG5: DOS | AH5: DOC | AI5: DOS | AJ5: DOC
B6: Existing Tower
B8: Sc-5 | C8: DD+9(220KV)
A10: 1 | B10: SC-4 | C10: DD+9 (220KV) | D10: 11.987 | E10: =D10*4 -> 47.948 | F10: =E10*8 -> 383.584 | G10: 6.058 | H10: 5.874 | I10: 0.0077 | J10: 0.563 | K10: =SUM(G10:J10) -> 12.5027 | L10: 0.557 | M10: 0.01 | N10: =SUM(L10:M10) -> 0.567 | T10: DFR | U10: 119.36 | V10: 2.05 | W10: 18.37 | X10: 20.42 | Y10: 157.1642 | Z10: 7858.21 | AA10: 89.9 | AC10: 1115.34 | AD10: 198.68
A12: =A10+1 -> 2 | B12: Sc-3 | C12: DD+9 (220KV) | D12: 11.987 | E12: =D12*4 -> 47.948 | F12: =E12*8 -> 383.584 | G12: 6.058 | H12: 5.874 | I12: 0.0077 | J12: 0.563 | K12: =SUM(G12:J12) -> 12.5027 | L12: 0.557 | M12: 0.01 | N12: =SUM(L12:M12) -> 0.567 | T12: DFR | U12: 119.36 | V12: 2.05 | W12: 18.37 | X12: 20.42 | Y12: 157.1642 | Z12: 7858.21 | AA12: 89.9 | AC12: 1115.34 | AD12: 198.68 | AF12: C | AL12: C | AM12: cp
A14: =A12+1 -> 3 | B14: SC-2 | C14: DD+0 | D14: 11.987 | E14: =D14*4 -> 47.948 | F14: =E14*8 -> 383.584 | G14: 6.058 | H14: 5.874 | I14: 0.0077 | J14: 0.563 | K14: =SUM(G14:J14) -> 12.5027 | L14: 0.557 | M14: 0.01 | N14: =SUM(L14:M14) -> 0.567 | T14: DFR | U14: 119.36 | V14: 2.05 | W14: 18.37 | X14: 20.42 | Y14: 157.1642 | Z14: 7858.21 | AA14: 89.9 | AC14: 1115.34 | AD14: 198.68 | AF14: U/P
A16: =A14+1 -> 4 | B16: SC-1 | C16: DD+6 | D16: 11.987 | E16: =D16*4 -> 47.948 | F16: =E16*8 -> 383.584 | G16: =4.906+4.424+0.596 -> 9.926 | H16: =0.066+1.053+0.272 -> 1.391 | I16: =0.274+0.181+0.043 -> 0.498 | J16: =SUM(G16:I16) -> 11.815 | K16: 0.532 | M16: 0.011 | N16: =K16+M16 -> 0.543 | T16: DFR | U16: 75.36 | V16: 1.35 | W16: 13.06 | X16: =V16+W16 -> 14.41 | Y16: 89.9 | AA16: 1287.27 | AB16: 193.64 | AE16: 1.571 | AF16: C | AK16: New Tech Engineer | AL16: C | AM16: CP
B18: Tapping Tower
S19: 25.92
A20: =A16+1 -> 5 | B20: 1/0 | C20: DD+0 | D20: 9.654 | E20: =D20*4 -> 38.616 | F20: =E20*8 -> 308.928 | G20: =4.906+1.456+0.596 -> 6.958 | H20: =0.066+0.717+0.272 -> 1.055 | I20: =0.274+0.083+0.043 -> 0.4 | J20: =SUM(G20:I20) -> 8.413 | K20: 0.532 | M20: 0.011 | N20: =K20+M20 -> 0.543 | T20: DFR | U20: 75.36 | V20: 1.35 | W20: 13.06 | X20: =V20+W20 -> 14.41 | Y20: 89.9 | AA20: 1287.27 | AB20: 193.64 | AE20: 1.571 | AF20: C | AK20: New Tech Engineer | AL20: C | AM20: CP
S21: 230.15
A22: =A20+1 -> 6 | B22: 2/0 | C22: DD+0 | D22: 9.654 | E22: =D22*4 -> 38.616 | F22: =E22*8 -> 308.928 | G22: =4.906+1.456+0.596 -> 6.958 | H22: =0.066+0.717+0.272 -> 1.055 | I22: =0.274+0.083+0.043 -> 0.4 | J22: =SUM(G22:I22) -> 8.413 | K22: 0.532 | M22: 0.011 | N22: =K22+M22 -> 0.543 | T22: DFR | U22: 75.36 | V22: 1.35 | W22: 13.06 | X22: =V22+W22 -> 14.41 | Y22: 89.9 | AA22: 1287.27 | AB22: 193.64 | AE22: 1.571 | AF22: C | AK22: New Tech Engineer | AL22: C | AM22: CP
S23: 234.56
A24: =A22+1 -> 7 | B24: 2/1 | C24: DD+6 | D24: 11.987 | E24: =D24*4 -> 47.948 | F24: =E24*8 -> 383.584 | G24: =4.906+4.424+0.596 -> 9.926 | H24: =0.066+1.053+0.272 -> 1.391 | I24: =0.274+0.181+0.043 -> 0.498 | J24: =SUM(G24:I24) -> 11.815 | K24: 0.532 | M24: 0.011 | N24: =K24+M24 -> 0.543 | T24: DFR | U24: 75.36 | V24: 1.35 | W24: 13.06 | X24: =V24+W24 -> 14.41 | Y24: 89.9 | AA24: 1287.27 | AB24: 193.64 | AE24: 1.571 | AF24: C | AK24: New Tech Engineer | AL24: C | AM24: CP
S25: 251.12
A26: =A24+1 -> 8 | B26: 3/0 | C26: DD+0 | D26: 9.654 | E26: =D26*4 -> 38.616 | F26: =E26*8 -> 308.928 | G26: =4.906+1.456+0.596 -> 6.958 | H26: =0.066+0.717+0.272 -> 1.055 | I26: =0.274+0.083+0.043 -> 0.4 | J26: =SUM(G26:I26) -> 8.413 | K26: 0.532 | M26: 0.011 | N26: =K26+M26 -> 0.543 | T26: DFR | U26: 75.36 | V26: 1.35 | W26: 13.06 | X26: =V26+W26 -> 14.41 | Y26: 89.9 | AA26: 1287.27 | AB26: 193.64 | AE26: 1.571 | AF26: C | AG26: 46121 | AH26: 46122 | AI26: 46124 | AJ26: 46126 | AK26: Navya Associate | AL26: C | AM26: CP | AQ26: C | AR26: 24/4/2026 | AS26: 30/4/2026 | AT26: Buriya baba
S27: 183
A28: =A26+1 -> 9 | B28: 3/1 | C28: DA+3 | D28: 6.992 | E28: =D28*4 -> 27.968 | F28: =E28*8 -> 223.744 | G28: =1.267+0.234+1.276 -> 2.777 | H28: =1.137+0.487+0.273 -> 1.897 | I28: =0.182+0.074+0.032 -> 0.288 | J28: =SUM(G28:I28) -> 4.962 | K28: 0.271 | M28: 0.007 | N28: =M28+K28 -> 0.278 | T28: DFR | U28: 41.44 | V28: 0.8 | W28: 7.73 | X28: =W28+V28 -> 8.53 | Y28: 73.75 | Z28: 235.38 | AB28: 201.4 | AE28: 0.51 | AF28: C | AG28: 46118 | AH28: 46119 | AI28: 46123 | AJ28: 46124 | AK28: Navya Associate | AL28: C | AQ28: C | AR28: 46130 | AS28: 22/4/2026 | AT28: Buriya baba
S29: 182.07
A30: =A28+1 -> 10 | B30: 4/0 | C30: DD+0 | D30: 9.654 | E30: =D30*4 -> 38.616 | F30: =E30*8 -> 308.928 | G30: =4.906+1.456+0.596 -> 6.958 | H30: =0.066+0.717+0.272 -> 1.055 | I30: =0.274+0.083+0.043 -> 0.4 | J30: =SUM(G30:I30) -> 8.413 | K30: 0.532 | M30: 0.011 | N30: =K30+M30 -> 0.543 | T30: DFR | U30: 75.36 | V30: 1.35 | W30: 13.06 | X30: =V30+W30 -> 14.41 | Y30: 89.9 | AA30: 1287.27 | AB30: 193.64 | AE30: 1.571 | AF30: C | AG30: 46082 | AH30: 46083 | AI30: 46087 | AJ30: 46089 | AK30: Yash Infra | AL30: C | AM30: CP | AQ30: C | AR30: 46097 | AS30: 46100 | AT30: Tokhan Mahto | AV30: C
S31: 328.09
A32: =A30+1 -> 11 | B32: 4/1 | C32: GANTRY UC(+2) | D32: 10.82 | E32: =D32*4 -> 43.28 | F32: =E32*8 -> 346.24 | G32: =4.906+2.484+0.596 -> 7.986 | H32: =0.066+1.044+0.272 -> 1.382 | I32: =0.274+0.132+0.043 -> 0.449 | J32: =SUM(G32:I32) -> 9.817 | K32: 0.532 | M32: 0.011 | N32: =K32+M32 -> 0.543 | T32: DFR | U32: 75.36 | V32: 1.35 | W32: 13.06 | X32: =V32+W32 -> 14.41 | Y32: 89.9 | AA32: 1287.27 | AB32: 193.64 | AE32: 1.571 | AF32: C | AI32: 46084 | AJ32: 46097 | AK32: Yash Infra | AL32: C | AM32: CP | AQ32: C | AR32: 46101 | AS32: 46103 | AT32: Tokhan Mahto | AV32: C
S33: 40
A34: =A32+1 -> 12 | B34: 4/2 | C34: GANTRY UC(+2) | F34: 54 | H34: 4.106 | I34: 0.23 | J34: =SUM(G34:I34) -> 4.336 | L34: =0.12+0.219 -> 0.339 | M34: =0.003+0.003 -> 0.006 | N34: =SUM(K34:M34) -> 0.345 | T34: DFR | U34: 315 | V34: 4.1 | W34: 42 | X34: =W34+V34 -> 46.1 | AE34: 3.95 | AF34: C | AI34: 19/2/2026 | AJ34: 46098 | AK34: Yash Infra | AL34: C | AM34: CP | AQ34: C | AR34: 46103 | AS34: 46104 | AT34: Tokhan Mahto | AV34: C
S35: 57.415
A36: =A34+1 -> 13 | B36: 5/0 | C36: DD+0 | F36: 54 | H36: 4.106 | I36: 0.23 | J36: =SUM(G36:I36) -> 4.336 | L36: =0.12+0.219 -> 0.339 | M36: =0.003+0.003 -> 0.006 | N36: =SUM(K36:M36) -> 0.345 | T36: DFR | U36: 315 | V36: 4.1 | W36: 42 | X36: =W36+V36 -> 46.1 | AE36: 3.95 | AF36: C | AG36: 46050 | AH36: 46051 | AI36: 46056 | AJ36: 46058 | AK36: Yash Infra | AL36: C | AM36: CP | AQ36: C | AR36: 46095 | AS36: 46097 | AT36: Jyoti Construction | AV36: C
S37: 38.566
A38: =A36+1 -> 14 | B38: 6/0 | C38: DD+3 | D38: 9.654 | E38: =D38*4 -> 38.616 | F38: =E38*8 -> 308.928 | G38: =4.906+1.456+0.596 -> 6.958 | H38: =0.066+0.717+0.272 -> 1.055 | I38: =0.274+0.083+0.043 -> 0.4 | J38: =SUM(G38:I38) -> 8.413 | K38: 0.532 | M38: 0.011 | N38: =K38+M38 -> 0.543 | T38: DFR | U38: 75.36 | V38: 1.35 | W38: 13.06 | X38: =V38+W38 -> 14.41 | Y38: 89.9 | AA38: 1287.27 | AB38: 193.64 | AE38: 1.571 | AF38: C | AG38: 46052 | AH38: 2/2/22026 | AI38: 46058 | AJ38: 2/8/206 | AK38: Shree Shyam Construction | AL38: C | AM38: CP | AQ38: C | AR38: 46070 | AS38: 46072 | AT38: Suman | AV38: C
S39: 182.043
A40: =A38+1 -> 15 | B40: 6/1 | C40: DA+6 | D40: 9.654 | E40: =D40*4 -> 38.616 | F40: =E40*8 -> 308.928 | G40: =4.906+1.456+0.596 -> 6.958 | H40: =0.066+0.717+0.272 -> 1.055 | I40: =0.274+0.083+0.043 -> 0.4 | J40: =SUM(G40:I40) -> 8.413 | K40: 0.532 | M40: 0.011 | N40: =K40+M40 -> 0.543 | T40: DFR | U40: 75.36 | V40: 1.35 | W40: 13.06 | X40: =V40+W40 -> 14.41 | Y40: 89.9 | AA40: 1287.27 | AB40: 193.64 | AE40: 1.571 | AF40: C | AG40: 46045 | AH40: 45681 | AI40: 46050 | AJ40: 46052 | AK40: Yash Infra | AL40: C | AM40: CP | AQ40: C | AR40: 46062 | AS40: 46064 | AT40: Suman | AV40: C
S41: 204.148
A42: =A40+1 -> 16 | B42: 6/2 | C42: DA+6 | D42: 9.654 | E42: =D42*4 -> 38.616 | F42: =E42*8 -> 308.928 | G42: =4.906+1.456+0.596 -> 6.958 | H42: =0.066+0.717+0.272 -> 1.055 | I42: =0.274+0.083+0.043 -> 0.4 | J42: =SUM(G42:I42) -> 8.413 | K42: 0.532 | M42: 0.011 | N42: =K42+M42 -> 0.543 | T42: DFR | U42: 75.36 | V42: 1.35 | W42: 13.06 | X42: =V42+W42 -> 14.41 | Y42: 89.9 | AA42: 1287.27 | AB42: 193.64 | AE42: 1.571 | AF42: C | AG42: 46043 | AH42: 46045 | AI42: 46047 | AJ42: 46049 | AK42: Shree Shyam Construction | AL42: C | AM42: CP | AQ42: C | AR42: 46097 | AS42: 46099 | AT42: Jyoti Construction | AV42: C
S43: 254
A44: =A42+1 -> 17 | B44: 6/3 | C44: DA+0 | D44: 6.992 | E44: =D44*4 -> 27.968 | F44: =E44*8 -> 223.744 | G44: =1.267+0.234+1.276 -> 2.777 | H44: =1.137+0.487+0.273 -> 1.897 | I44: =0.182+0.074+0.032 -> 0.288 | J44: =SUM(G44:I44) -> 4.962 | K44: 0.271 | M44: 0.007 | N44: =M44+K44 -> 0.278 | T44: WFR | U44: 41.44 | V44: 0.8 | W44: 7.73 | X44: =W44+V44 -> 8.53 | Y44: 73.75 | Z44: 235.38 | AB44: 201.4 | AE44: 0.51 | AF44: C | AG44: 46032 | AH44: 46038 | AI44: 1/16/206 | AJ44: 46053 | AK44: Shree Shyam Construction | AL44: C | AM44: CP | AQ44: C | AR44: 46067 | AS44: 46069 | AT44: Suman | AV44: C
S45: 294
A46: =A44+1 -> 18 | B46: 6/4 | C46: DA+3 | D46: 6.992 | E46: =D46*4 -> 27.968 | F46: =E46*8 -> 223.744 | G46: =1.267+0.234+1.276 -> 2.777 | H46: =1.137+0.487+0.273 -> 1.897 | I46: =0.182+0.074+0.032 -> 0.288 | J46: =SUM(G46:I46) -> 4.962 | K46: 0.271 | M46: 0.007 | N46: =M46+K46 -> 0.278 | T46: DFR | U46: 41.44 | V46: 0.8 | W46: 7.73 | X46: =W46+V46 -> 8.53 | Y46: 73.75 | Z46: 235.38 | AB46: 201.4 | AE46: 0.51 | AF46: C | AG46: 46089 | AH46: =AG46+3 -> 46092 | AI46: 46094 | AJ46: 46095 | AK46: Yash Infra | AL46: C | AM46: CP | AQ46: C | AR46: 46099 | AS46: 46101 | AT46: Jyoti Construction | AV46: C
...

Sheet Progress-220kV
Y1: =SUBTOTAL(109,Y9:Y410) -> 280.916 | Z1: =SUBTOTAL(109,Z9:Z410) -> 2556.335 | AA1: =SUBTOTAL(109,AA9:AA410) -> 2837.251 | AB1: =SUBTOTAL(109,AB9:AB410) -> 19254.081 | AC1: =SUBTOTAL(109,AC9:AC410) -> 850780.47 | AD1: =SUBTOTAL(109,AD9:AD410) -> 16158.37 | AE1: =SUBTOTAL(109,AE9:AE410) -> 75630.58 | AF1: =SUBTOTAL(109,AF9:AF410) -> 33623.1 | ... AK1: =SUBTOTAL(109,AK9:AK410) -> 177.82743
A2: =+Summary!A2 -> Name of the Line: 220KV DC AL59 line from Neemuch - Chanderiya + 132KV DC ACSS Line from Chanderiya to Hindustan Zinc
A3: =+Summary!A5 -> Progress of 220kV Line
A4: 220 KV D/C Neemuch - TS | H4: RC Portion | L4: Tower Weight | Q4: Stub Weight | W4: Foundation | AV4: Earthing | BB4: Erection | BI4: Tack-Welding | BN4: Remarks | BO4: Remarks
P5: =SUBTOTAL(109,P8:P410) -> 1367.3216 | S5: =SUBTOTAL(109,S8:S410) -> 72.173 | V5: =SUBTOTAL(109,V8:V410) -> 64047.149 | X5: =SUBTOTAL(109,X8:X410) -> 17952.97 | Y5: =SUBTOTAL(109,Y8:Y410) -> 280.916 | Z5: =SUBTOTAL(109,Z8:Z410) -> 2556.335 | AA5: =SUBTOTAL(109,AA8:AA410) -> 2837.251 | AB5: =SUBTOTAL(109,AB8:AB410) -> 19254.081 | AK5: =SUBTOTAL(109,AK8:AK410) -> 179.18974 | AM5: =SUBTOTAL(109,AM8:AM410) -> 0 | AV5: =SUBTOTAL(109,AV8:AV410) -> 0 | BB5: =SUBTOTAL(109,BB8:BB410) -> 0 | BI5: =SUBTOTAL(109,BI8:BI410) -> 0
A6: Sl. No. | B6: LOC NO | C6: Tower Type | H6: A | I6: B | J6: C | K6: D | L6: HT | M6: MS | N6: pack Washar | O6: BnA | P6: Total Tower Weight | Q6: HT | R6: BnA | S6: Total Stub Weight | T6: Deviation of Angle | U6: State | V6: Span Length(m) | W6: Classification | X6: Excavation Volume (m3) | Y6: Concreting Volume | AB6: Cement Required | AD6: Total Steel (Kgs) per Tower | AM6: Fnd Status (C/WIP) | AN6: Manual Checklist | AO6: JMC | AP6: Excavation | AR6: Concreting | AT6: Sub-Contractor Name | AV6: Earthing Status C/WIP | AW6: Earthing Type | AX6: DOS | AY6: DOC | AZ6: S/C | BB6: Erection Status C/WIP | BC6: Manual Checklist | BD6: JMC | BE6: DOS | BF6: DOC | BG6: S/C | BI6: Status C/WIP | BJ6: DOS | BK6: DOC | BL6: NB qty | BM6: Sub-Contractor Name
D7: B2B | E7: B2B x 4 | F7: Barbed Wire | G7: RC Portion | L7: MT | M7: MT | N7: MT | O7: MT | P7: MT | Q7: MT | R7: MT | S7: MT | T7: DMS | V7: m | Y7: M10 (1:3:6) (m3) | Z7: M20 (1:1.5:3) (m3) | AA7: Total | AB7: nos of bags | AC7: in kg | AD7: 8mm | AE7: 10mm | AF7: 12mm | AG7: 16mm | AH7: 20mm | AI7: 25mm | AJ7: Total Steel (Kgs) | AK7: Total Steel (MT) | AP7: DOS | AQ7: DOC | AR7: DOS | AS7: 9
A8: 0 | B8: GANTRY | C8: GANTRY | P8: 13 | AD8: 70.93 | AE8: 1040.06 | AG8: 98.08 | AH8: 153.24 | AJ8: 1362.31 | AK8: 1.36231
V9: 47
A10: 1 | B10: 0/0 | C10: DD+0 | D10: 9.654 | E10: =D10*4 -> 38.616 | F10: =E10*8 -> 308.928 | L10: 4.807 | M10: 4.016 | N10: 0.007 | O10: 0.431 | P10: =SUM(L10:O10) -> 9.261 | Q10: 0.557 | R10: 0.01 | S10: =SUM(Q10:R10) -> 0.567 | T10: 16° 50' 9"RT | U10: RJ | X10: 220.64 | Y10: 3.61 | Z10: 27.92 | AA10: =Y10+Z10 -> 31.53 | AB10: 241.0636 | AC10: 12053.18 | AD10: 77.93 | AF10: 1601.75 | AG10: 96.72 | AH10: 151.11 | AJ10: 1927.51 | AK10: 1.92751 | AM10: C | AN10: =AO10 -> D | AO10: D | AP10: =AQ10-1 -> 45703 | AQ10: =AR10-2 -> 45704 | AR10: =AS10-2 -> 45706 | AS10: 45708 | AT10: Ram Singh | AV10: C | AW10: CP | AX10: 45737 | AY10: =AX10 -> 45737 | AZ10: Ram Singh-1 | BB10: C | BC10: EE | BD10: D | BE10: =BF10-2 -> 45754 | BF10: 45756 | BG10: Ramesh Kumar | BI10: C | BJ10: 45824 | BK10: 45824 | BL10: 1202 | BM10: Asit Baran Pal
V11: 196 | W11: WFR
A12: =A10+1 -> 2 | B12: 0/1 | C12: DA+3 | D12: 6.992 | E12: =D12*4 -> 27.968 | F12: =E12*8 -> 223.744 | L12: 2.607 | M12: 2.657 | N12: 0.002 | O12: 0.213 | P12: =SUM(L12:O12) -> 5.479 | Q12: 0.244 | R12: 0.005 | S12: =SUM(Q12:R12) -> 0.249 | U12: RJ | X12: 121.84 | Y12: 0.8 | Z12: 7.8 | AA12: =Y12+Z12 -> 8.6 | AB12: 66.42 | AC12: 3321 | AD12: 73.73 | AE12: 301.5 | AG12: 206.46 | AJ12: 581.69 | AK12: 0.803 | AM12: C | AN12: =AO12 -> D | AO12: D | AP12: =AQ12-2 -> 45693 | AQ12: =AR12-1 -> 45695 | AR12: =AS12-1 -> 45696 | AS12: 45697 | AT12: Ram Singh | AV12: C | AW12: CP | AX12: 45709 | AY12: =AX12 -> 45709 | AZ12: Ram Singh-1 | BB12: C | BC12: EE | BD12: D | BE12: =BF12-2 -> 45749 | BF12: 45751 | BG12: Ramesh Kumar | BI12: C | BJ12: 45824 | BK12: 45824 | BL12: 1330 | BM12: Asit Baran Pal
V13: 196.743 | W13: DFR
A14: =A12+1 -> 3 | B14: 1/0 | C14: DC+0 | D14: 7.708 | E14: =D14*4 -> 30.832 | F14: =E14*8 -> 246.656 | L14: 4.057 | M14: 2.48 | N14: 0.006 | O14: 0.365 | P14: =SUM(L14:O14) -> 6.908 | Q14: 0.436 | R14: 0.01 | S14: =SUM(Q14:R14) -> 0.446 | T14: 15° 52' 12"RT | U14: RJ | X14: 75.36 | Y14: 1.35 | Z14: 12.85 | AA14: =Y14+Z14 -> 14.2 | AB14: 109.565 | AC14: 5478.25 | AD14: 81.82 | AE14: 599.6 | AG14: 201.4 | AJ14: 882.82 | AK14: 0.88282 | AM14: C | AN14: =AO14 -> D | AO14: D | AP14: =AQ14-3 -> 45736 | AQ14: =AR14-2 -> 45739 | AR14: =AS14-2 -> 45741 | AS14: 45743 | AT14: Ram Singh | AV14: C | AW14: CP | AX14: 45709 | AY14: =AX14 -> 45709 | AZ14: Ram Singh-1 | BB14: C | BC14: EE SUB | BD14: D | BE14: =BF14-2 -> 45758 | BF14: 45760 | BG14: Ramesh Kumar | BI14: C | BJ14: 45824 | BK14: 45824 | BL14: 1001 | BM14: Asit Baran Pal
V15: 334 | W15: DFR
A16: =A14+1 -> 4 | B16: 1/1 | C16: DA+0 | D16: 6.362 | E16: =D16*4 -> 25.448 | F16: =E16*8 -> 203.584 | L16: 2.25 | M16: 2.188 | N16: 0.002 | O16: 0.183 | P16: =SUM(L16:O16) -> 4.623 | Q16: 0.244 | R16: 0.005 | S16: =SUM(Q16:R16) -> 0.249 | U16: RJ | X16: 121.84 | Y16: 0.88 | Z16: 8.12 | AA16: =Y16+Z16 -> 9 | AB16: 66.42 | AC16: 3321 | AD16: 73.73 | AE16: 301.5 | AG16: 206.46 | AJ16: 581.69 | AK16: 0.803 | AM16: C | AN16: =AO16 -> D | AO16: D | AP16: =AQ16-2 -> 45706 | AQ16: =AR16-1 -> 45708 | AR16: =AS16-2 -> 45709 | AS16: 45711 | AT16: Ram Singh | AV16: C | AW16: Pipe | AX16: 45709 | AY16: =AX16 -> 45709 | AZ16: Ram Singh-1 | BB16: C | BC16: EE | BD16: D | BE16: =BF16-2 -> 45747 | BF16: 45749 | BG16: Ramesh Kumar | BI16: C | BJ16: 45825 | BK16: 45825 | BL16: 980 | BM16: Asit Baran Pal
V17: 319 | W17: Sandy Dry
A18: =A16+1 -> 5 | B18: 1/2 | C18: DA+3 | D18: 6.992 | E18: =D18*4 -> 27.968 | F18: =E18*8 -> 223.744 | L18: 2.607 | M18: 2.657 | N18: 0.002 | O18: 0.213 | P18: =SUM(L18:O18) -> 5.479 | Q18: 0.244 | R18: 0.005 | S18: =SUM(Q18:R18) -> 0.249 | U18: RJ | X18: 41.44 | Y18: 0.8 | Z18: 7.8 | AA18: =Y18+Z18 -> 8.6 | AB18: 66.42 | AC18: 3321 | AD18: 73.73 | AE18: 301.5 | AG18: 206.46 | AJ18: 581.69 | AK18: 0.58169 | AM18: C | AN18: =AO18 -> D | AO18: D | AP18: =AQ18-1 -> 45691 | AQ18: =AR18-1 -> 45692 | AR18: =AS18-1 -> 45693 | AS18: 45694 | AT18: Ram Singh | AV18: C | AW18: CP | AX18: 45709 | AY18: =AX18 -> 45709 | AZ18: Ram Singh-1 | BB18: C | BC18: EE SUB | BD18: D | BE18: =BF18-2 -> 45745 | BF18: 45747 | BG18: Ramesh Kumar | BI18: C | BJ18: 45825 | BK18: 45825 | BL18: 1330 | BM18: Asit Baran Pal
V19: 384.318 | W19: DFR
A20: =A18+1 -> 6 | B20: 1A/0 | C20: DC+3 | D20: 8.626 | E20: =D20*4 -> 34.504 | F20: =E20*8 -> 276.032 | L20: 4.538 | M20: 3.229 | N20: 0.0064 | O20: 0.429 | P20: =SUM(L20:O20) -> 8.2024 | Q20: 0.436 | R20: 0.01 | S20: =SUM(Q20:R20) -> 0.446 | T20: 18° 59' 57"LT | U20: RJ | X20: 75.36 | Y20: 1.35 | Z20: 12.85 | AA20: =Y20+Z20 -> 14.2 | AB20: 109.565 | AC20: 5478.25 | AD20: 81.82 | AE20: 599.6 | AG20: 201.4 | AJ20: 882.82 | AK20: 0.88282 | AM20: C | AN20: =AO20 -> D | AO20: D | AP20: =AQ20-3 -> 45698 | AQ20: =AR20-2 -> 45701 | AR20: =AS20-2 -> 45703 | AS20: 45705 | AT20: Ram Singh | AV20: C | AW20: CP | AX20: 45733 | AY20: =AX20 -> 45733 | AZ20: Ram Singh-1 | BB20: C | BC20: EE SUB | BD20: D | BE20: =BF20-2 -> 45768 | BF20: 45770 | BG20: Ramesh Kumar | BI20: C | BJ20: 45827 | BK20: 45827 | BL20: 1433 | BM20: Asit Baran Pal
V21: 329 | W21: DFR
A22: =A20+1 -> 7 | B22: 1A/1 | C22: DA+3 | D22: 6.992 | E22: =D22*4 -> 27.968 | F22: =E22*8 -> 223.744 | L22: 2.607 | M22: 2.657 | N22: 0.002 | O22: 0.213 | P22: =SUM(L22:O22) -> 5.479 | Q22: 0.244 | R22: 0.005 | S22: =SUM(Q22:R22) -> 0.249 | U22: RJ | X22: 41.44 | Y22: 0.8 | Z22: 7.8 | AA22: =Y22+Z22 -> 8.6 | AB22: 66.42 | AC22: 3321 | AD22: 73.73 | AE22: 301.5 | AG22: 206.46 | AJ22: 581.69 | AK22: 0.58169 | AM22: C | AN22: =AO22 -> D | AO22: D | AP22: 45688 | AQ22: =AP22+2 -> 45690 | AR22: =AS22-2 -> 45691 | AS22: 45693 | AT22: Ram Singh-1 | AV22: C | AW22: CP | AX22: 45709 | AY22: =AX22 -> 45709 | AZ22: Ram Singh-1 | BB22: C | BC22: EE | BD22: D | BE22: =BF22-2 -> 45751 | BF22: 45753 | BG22: Ramesh Kumar | BI22: C | BJ22: 45827 | BK22: 45827 | BL22: 1330 | BM22: Asit Baran Pal
V23: 280 | W23: DFR
A24: =A22+1 -> 8 | B24: 1A/2 | C24: DC+0 | D24: 7.708 | E24: =D24*4 -> 30.832 | F24: =E24*8 -> 246.656 | L24: 4.057 | M24: 2.48 | N24: 0.006 | O24: 0.365 | P24: =SUM(L24:O24) -> 6.908 | Q24: 0.436 | R24: 0.01 | S24: =SUM(Q24:R24) -> 0.446 | U24: RJ | X24: 148.8 | Y24: 2.51 | Z24: 19.47 | AA24: =Y24+Z24 -> 21.98 | AB24: 168.0726 | AC24: 8403.63 | AD24: 70.93 | AE24: 914.33 | AG24: 98.08 | AH24: 153.24 | AJ24: 1236.58 | AK24: 1.23658 | AM24: C | AN24: =AO24 -> D | AO24: D | AP24: 45681 | AQ24: =AP24+2 -> 45683 | AR24: =AS24-2 -> 45688 | AS24: 45690 | AT24: Ram Singh-1 | AV24: C | AW24: CP | AX24: 45733 | AY24: =AX24 -> 45733 | AZ24: Ram Singh-1 | BB24: C | BC24: EE SUB | BD24: D | BE24: =BF24-2 -> 45761 | BF24: 45763 | BG24: Ramesh Kumar | BI24: C | BJ24: 45830 | BK24: 45830 | BL24: 1001 | BM24: Asit Baran Pal
V25: 232.098 | W25: WFR
A26: =A24+1 -> 9 | B26: 1B/0 | C26: DD+3 | D26: 10.82 | E26: =D26*4 -> 43.28 | F26: =E26*8 -> 346.24 | L26: 5.492 | M26: 5.097 | N26: 0.0074 | O26: 0.502 | P26: =SUM(L26:O26) -> 11.0984 | Q26: 0.557 | R26: 0.01 | S26: =SUM(Q26:R26) -> 0.567 | T26: 57° 18' 17"LT | U26: RJ | X26: 220.64 | Y26: 3.61 | Z26: 27.92 | AA26: =Y26+Z26 -> 31.53 | AB26: 241.0636 | AC26: 12053.18 | AD26: 77.93 | AF26: 1601.75 | AG26: 96.72 | AH26: 151.11 | AJ26: 1927.51 | AK26: 1.92751 | AM26: C | AN26: =AO26 -> D | AO26: D | AP26: =AQ26-2 -> 45717 | AQ26: =AR26-1 -> 45719 | AR26: =AS26-1 -> 45720 | AS26: 45721 | AT26: Ram Singh-1 | AV26: C | AW26: CP | AX26: 45733 | AY26: =AX26 -> 45733 | AZ26: Ram Singh-1 | BB26: C | BC26: EE | BD26: D | BE26: =BF26-2 -> 45772 | BF26: 45774 | BG26: Ramesh Kumar | BI26: C | BJ26: 45830 | BK26: 45830 | BL26: 1552 | BM26: Asit Baran Pal
V27: 237.783 | W27: WFR
A28: =A26+1 -> 10 | B28: 1C/0 | C28: DD+9 | D28: 13.258 | E28: =D28*4 -> 53.032 | F28: =E28*8 -> 424.256 | L28: 6.059 | M28: 5.874 | N28: 0.0077 | O28: 0.563 | P28: =SUM(L28:O28) -> 12.5037 | Q28: 0.557 | R28: 0.01 | S28: =SUM(Q28:R28) -> 0.567 | T28: 44° 32' 20"RT | U28: RJ | X28: 119.36 | Y28: 2.05 | Z28: 18.37 | AA28: =Y28+Z28 -> 20.42 | AB28: 157.1642 | AC28: 7858.21 | AD28: 89.9 | AF28: 1115.34 | AG28: 198.68 | AJ28: 1403.92 | AK28: 1.40392 | AM28: C | AP28: 46057 | AQ28: 46074 | AS28: 46077 | AT28: Yash Infra | AV28: C | AW28: CP | BB28: C | BE28: 46101 | BF28: 46106 | BG28: Jyoti Construction | BI28: C | BL28: 2008 | BM28: Jai Swami
V29: 334 | W29: WFR
A30: =A28+1 -> 11 | B30: 1C/1 | C30: DA+6 | D30: 7.622 | E30: =D30*4 -> 30.488 | F30: =E30*8 -> 243.904 | L30: 2.679 | M30: 3.133 | N30: 0.0025 | O30: 0.233 | P30: =SUM(L30:O30) -> 6.0475 | Q30: 0.244 | R30: 0.005 | S30: =SUM(Q30:R30) -> 0.249 | U30: RJ | X30: 143.36 | Y30: 1.68 | Z30: 11.97 | AA30: =Y30+Z30 -> 13.65 | AB30: =+Y30*4.44+Z30*8.06 -> 103.9374 | AC30: =+AB30*50 -> 5196.87 | AD30: 63.93 | AE30: 535.23 | AG30: 100.6 | AH30: 157.18 | AJ30: 856.94 | AK30: 0.85694 | AM30: C | AN30: =AO30 -> D | AO30: D | AP30: =AQ30-2 -> 45707 | AQ30: =AR30-2 -> 45709 | AR30: =AS30-2 -> 45711 | AS30: 45713 | AT30: Shree Shyam | AV30: C | AW30: Pipe | AX30: =AY30 -> 45720 | AY30: 45720 | AZ30: Ram Singh-1 | BB30: C | BC30: EE | BD30: D | BE30: =BF30-2 -> 45794 | BF30: 45796 | BG30: Shree Karni Entp | BI30: C | BJ30: 45830 | BK30: 45830 | BL30: 1545 | BM30: Asit Baran Pal
V31: 341.209 | W31: Sandy Wet
A32: =A30+1 -> 12 | B32: 1D/0 | C32: DC+0 | D32: 7.708 | E32: =D32*4 -> 30.832 | F32: =E32*8 -> 246.656 | L32: 4.057 | M32: 2.48 | N32: 0.006 | O32: 0.365 | P32: =SUM(L32:O32) -> 6.908 | Q32: 0.436 | R32: 0.01 | S32: =SUM(Q32:R32) -> 0.446 | T32: 28° 26' 27"RT | U32: RJ | X32: 229.64 | Y32: 2.81 | Z32: 21.11 | AA32: =Y32+Z32 -> 23.92 | AB32: 182.623 | AC32: 9131.15 | AD32: 70.93 | AE32: 1040.06 | AG32: 98.08 | AH32: 153.24 | AJ32: 1362.31 | AK32: 1.36231 | AM32: C | AN32: EG | AO32: D | AP32: 45679 | AQ32: =AR32-2 -> 45684 | AR32: =AS32-2 -> 45686 | AS32: 45688 | AT32: Ram Singh-1 | AV32: C | AW32: Pipe | AX32: 45703 | AY32: 45703 | AZ32: Ram Singh-1 | BB32: C | BC32: EE | BD32: D | BE32: =BF32-1 -> 45745 | BF32: 45746 | BG32: Ramesh Kumar | BI32: C | BJ32: 45831 | BK32: 45831 | BL32: 1001 | BM32: Asit Baran Pal
V33: 306.001 | W33: Sandy Wet
A34: =A32+1 -> 13 | B34: 1D/1 | C34: DA+0 | D34: 6.362 | E34: =D34*4 -> 25.448 | F34: =E34*8 -> 203.584 | L34: 2.25 | M34: 2.188 | N34: 0.002 | O34: 0.183 | P34: =SUM(L34:O34) -> 4.623 | Q34: 0.244 | R34: 0.005 | S34: =SUM(Q34:R34) -> 0.249 | U34: RJ | X34: 143.36 | Y34: 1.68 | Z34: 11.97 | AA34: =Y34+Z34 -> 13.65 | AB34: =+Y34*4.44+Z34*8.06 -> 103.9374 | AC34: =+AB34*50 -> 5196.87 | AD34: 63.93 | AE34: 535.23 | AG34: 100.6 | AH34: 157.18 | AJ34: 856.94 | AK34: 0.85694 | AM34: C | AN34: =AO34 -> D | AO34: D | AP34: =AQ34-2 -> 45704 | AQ34: =AR34-2 -> 45706 | AR34: =AS34-2 -> 45708 | AS34: 45710 | AT34: Shree Shyam | AV34: C | AW34: Pipe | AX34: 45703 | AY34: 45703 | AZ34: Ram Singh-1 | BB34: C | BC34: EE | BD34: D | BE34: =BF34-1 -> 45743 | BF34: 45744 | BG34: Ramesh Kumar | BI34: C | BJ34: 45831 | BK34: 45831 | BL34: 980 | BM34: Asit Baran Pal
V35: 393.92 | W35: Sandy Wet
A36: =A34+1 -> 14 | B36: 1E/0 | C36: DD+6 | D36: 11.987 | E36: =D36*4 -> 47.948 | F36: =E36*8 -> 383.584 | L36: 5.904 | M36: 5.541 | N36: 0.0079 | O36: 0.535 | P36: =SUM(L36:O36) -> 11.9879 | Q36: 0.557 | R36: 0.01 | S36: =SUM(Q36:R36) -> 0.567 | T36: 42° 49' 3"RT | U36: RJ | X36: 220.64 | Y36: 3.61 | Z36: 27.92 | AA36: =Y36+Z36 -> 31.53 | AB36: 241.0636 | AC36: 12053.18 | AD36: 77.93 | AF36: 1601.75 | AG36: 96.72 | AH36: 151.11 | AJ36: 1927.51 | AK36: 1.92751 | AM36: C | AN36: D | AO36: D | AP36: =AQ36-2 -> 45731 | AQ36: =AR36-2 -> 45733 | AR36: =AS36-3 -> 45735 | AS36: 45738 | AT36: Shree Shyam | AV36: C | AW36: CP | AX36: =AY36 -> 45661 | AY36: 45661 | AZ36: Ram Singh-1 | BB36: C | BC36: EE | BD36: D | BE36: =BF36-2 -> 45802 | BF36: 45804 | BG36: Dudhnath Kumar | BI36: C | BJ36: 45837 | BK36: 45837 | BL36: 1750 | BM36: Asit Baran Pal
V37: 356.664 | W37: WFR
A38: =A36+1 -> 15 | B38: 2/0 | C38: DC+6 | D38: 9.544 | E38: =D38*4 -> 38.176 | F38: =E38*8 -> 305.408 | L38: 4.938 | M38: 3.609 | N38: 0.0063 | O38: 0.424 | P38: =SUM(L38:O38) -> 8.9773 | Q38: 0.436 | R38: 0.01 | S38: =SUM(Q38:R38) -> 0.446 | T38: 27° 13' 43"RT | U38: RJ | X38: 184.48 | Y38: 2.22 | Z38: 17.65 | AA38: =Y38+Z38 -> 19.87 | AD38: 70.93 | AE38: 848.79 | AG38: 98.08 | AH38: 153.24 | AJ38: =SUM(AD38:AH38) -> 1171.04 | AK38: 0.88282 | AM38: C | AN38: =AO38 -> D | AO38: D | AP38: 45679 | AQ38: =AP38+2 -> 45681 | AR38: =AS38-2 -> 45688 | AS38: 45690 | AT38: Shree Shyam | AV38: C | AW38: Pipe | AX38: 45703 | AY38: 45703 | AZ38: Ram Singh-1 | BB38: C | BC38: EE SUB | BD38: D | BE38: =BF38-2 -> 45766 | BF38: 45768 | BG38: Ramesh Kumar | BI38: C | BJ38: 45831 | BK38: 45831 | BL38: 1657 | BM38: Asit Baran Pal
V39: 174.205 | W39: WET
A40: =A38+1 -> 16 | B40: 3/0 | C40: DD+3 | D40: 10.82 | E40: =D40*4 -> 43.28 | F40: =E40*8 -> 346.24 | L40: 5.492 | M40: 5.097 | N40: 0.0078 | O40: 0.502 | P40: =SUM(L40:O40) -> 11.0988 | Q40: 0.557 | R40: 0.01 | S40: =SUM(Q40:R40) -> 0.567 | T40: 49° 56' 13"RT | U40: RJ | X40: 268.58 | Y40: 3.33 | Z40: 26.1 | AA40: =Y40+Z40 -> 29.43 | AB40: 225.1512 | AC40: 11257.56 | AD40: 77.93 | AF40: 1484.97 | AG40: 96.72 | AH40: 151.11 | AJ40: 1810.73 | AK40: 1.81073 | AM40: C | AN40: =AO40 -> D | AO40: D | AP40: =AQ40-2 -> 45700 | AQ40: =AR40-2 -> 45702 | AR40: =AS40-2 -> 45704 | AS40: 45706 | AT40: Shree Shyam | AV40: C | AW40: Pipe | AX40: 45703 | AY40: 45703 | AZ40: Ram Singh-1 | BB40: C | BC40: EE SUB | BD40: D | BE40: =BF40-2 -> 45778 | BF40: 45780 | BG40: Ramesh Kumar | BI40: C | BJ40: 45802 | BK40: 45802 | BL40: 1552 | BM40: Asit Baran Pal
...

Sheet Stringing-220kV
A1: =+Summary!A2 -> Name of the Line: 220KV DC AL59 line from Neemuch - Chanderiya + 132KV DC ACSS Line from Chanderiya to Hindustan Zinc
A2: =+Summary!A5 -> Progress of 220kV Line | F2: Stringing Progress (Conductor & Earthwire) | S2: OPGW Progress
A3: Stringing Section | D3: =Summary!R5 -> 46162 | E3: =SUMIF(E6:E213,"C",$D$6:$D$213)/1000 -> 61.199263 | H3: =SUMIF(G7:G213,"WIP",$D$7:$D$213)/1000 -> 0 | I3: =SUMIF(G6:G213,"C",$D$6:$D$213)/1000 -> 61.199263 | K3: =SUMIF(J7:J213,"WIP",$D$7:$D$213)/1000 -> 0 | L3: =SUMIF(J6:J213,"C",$D$6:$D$213)/1000 -> 61.199263 | T3: =SUMIF(S7:S213,"WIP",$D$7:$D$213)/1000 -> 0 | U3: =SUMIF(S7:S213,"C",$D$7:$D$213)/1000 -> 62.249216 | W3: =SUMIF(V7:V213,"WIP",$D$7:$D$213)/1000 -> 0 | X3: =SUMIF(V7:V213,"C",$D$7:$D$213)/1000 -> 62.249216
A4: Sl. No. | B4: Section | D4: Section Length (m) | E4: Stretch Readiness | F4: Insulator Hoisting | G4: Conductor Paying Out | J4: Final Sag | M4: Clipping | N4: Jumper | O4: Sub-Contractor Name | P4: MP | Q4: Remarks | S4: OPGW Paying Out | V4: OPGW Final Sag | Y4: Sub-Contractor Name
B5: From | C5: To | G5: Status | H5: DOS | I5: DOC | J5: Status | K5: DOS | L5: DOC | M5: Status | N5: Status | S5: Status | T5: DOS | U5: DOC | V5: Status | W5: DOS | X5: DOC
A6: 1 | B6: Gnty | C6: 0/0 | D6: 0.047 | E6: C | F6: C | G6: C | H6: 46053 | I6: 46055 | J6: C | K6: 46053 | L6: 46055 | O6: Harshvivek | S6: C | T6: 46147 | U6: 46149 | V6: C | W6: 46150 | X6: 46150
A7: =A6+1 -> 2 | B7: 0/0 | C7: 1/0 | D7: 439.47 | E7: C | F7: C | G7: C | H7: 45796 | I7: 45801 | J7: C | K7: 45803 | L7: =K7+2 -> 45805 | M7: C | N7: C | O7: National Construction | S7: C | T7: 46147 | U7: 46149 | V7: C | W7: 46150 | X7: 46150
A8: =A7+1 -> 3 | B8: =C7 -> 1/0 | C8: 1A/0 | D8: 1037.32 | E8: C | F8: C | G8: C | H8: 45796 | I8: 45801 | J8: C | K8: 45803 | L8: =K8+2 -> 45805 | M8: C | N8: C | O8: National Construction | S8: C | T8: 46147 | U8: 46149 | V8: C | W8: 46150 | X8: 46150
A9: =A8+1 -> 4 | B9: =C8 -> 1A/0 | C9: 1A/2 | D9: 609 | E9: C | F9: C | G9: C | H9: =I9 -> 45837 | I9: 45837 | J9: C | K9: 45838 | L9: =K9 -> 45838 | M9: C | N9: C | O9: National Construction | S9: C | T9: 46147 | U9: 46149 | V9: C | W9: 46150 | X9: 46150
A10: =A9+1 -> 5 | B10: =C9 -> 1A/2 | C10: 1B/0 | D10: 232.098 | E10: C | F10: C | G10: C | H10: =I10 -> 45837 | I10: 45837 | J10: C | K10: 45837 | L10: =K10 -> 45837 | M10: C | N10: C | O10: National Construction | S10: C | T10: 46147 | U10: 46149 | V10: C | W10: 46150 | X10: 46150
A11: =A10+1 -> 6 | B11: =C10 -> 1B/0 | C11: 1C/0 | D11: 237.783 | E11: C | F11: C | G11: C | H11: 46121 | I11: 46121 | J11: C | K11: 46122 | L11: 46122 | M11: C | N11: C | O11: National Construction | S11: C | T11: 46147 | U11: 46149 | V11: C | W11: 46150 | X11: 46150
