Workbook
Name controllable_share: '5. Idle Narrative'!$B$5

Sheet 1. Raw Inputs
A1: Gang Deployment Efficiency Inputs (Overall Block Only)
A2: Source: FY24_FY25_Erection_Summary.xlsx -> Idle Days Buckets (Overall, A:M)
A4: Gang Count
A5: Threshold | B5: 0-1 | C5: 1-2 | D5: 2-3 | E5: 3-4 | F5: 4-5 | G5: 5-6 | H5: 6-7 | I5: 7-8 | J5: 8-9 | K5: TOTAL
A6: >=1 | B6: 11 | C6: 48 | D6: 84 | E6: 115 | F6: 96 | G6: 60 | H6: 39 | I6: 25 | J6: 5 | K6: =SUM(B6:J6)
A7: >=2 | B7: 3 | C7: 30 | D7: 47 | E7: 93 | F7: 83 | G7: 50 | H7: 31 | I7: 19 | J7: 4 | K7: =SUM(B7:J7)
A8: >=3 | B8: 3 | C8: 19 | D8: 35 | E8: 78 | F8: 75 | G8: 49 | H8: 27 | I8: 18 | J8: 4 | K8: =SUM(B8:J8)
A10: Weight Erected (MT) - Daily Prod
A11: Threshold | B11: 0-1 | C11: 1-2 | D11: 2-3 | E11: 3-4 | F11: 4-5 | G11: 5-6 | H11: 6-7 | I11: 7-8 | J11: 8-9 | K11: TOTAL
A12: >=1 | B12: 783.71 | C12: 7448.76 | D12: 15649.51 | E12: 31804.35 | F12: 37825.28 | G12: 32844.98 | H12: 38660.44 | I12: 16322.87 | J12: 2049.49 | K12: =SUM(B12:J12)
A13: >=2 | B13: 481.32 | C13: 6729.73 | D13: 13752.75 | E13: 30465.39 | F13: 37189.96 | G13: 32262.26 | H13: 38183.85 | I13: 15982.88 | J13: 1983.11 | K13: =SUM(B13:J13)
A14: >=3 | B14: 481.32 | C14: 5939.23 | D14: 12320.99 | E14: 29065.73 | F14: 36331.12 | G14: 32076.42 | H14: 37740.95 | I14: 15679.55 | J14: 1983.11 | K14: =SUM(B14:J14)
A16: Deployment months (avg)
A17: Threshold | B17: 0-1 | C17: 1-2 | D17: 2-3 | E17: 3-4 | F17: 4-5 | G17: 5-6 | H17: 6-7 | I17: 7-8 | J17: 8-9 | K17: AVG
A18: >=1 | B18: 4.89 | C18: 2.91 | D18: 2.47 | E18: 2.64 | F18: 2.99 | G18: 3.19 | H18: 4.72 | I18: 2.94 | J18: 1.85 | K18: =AVERAGE(B18:J18)
A19: >=2 | B19: 6.78 | C19: 4.16 | D19: 3.86 | E19: 3.13 | F19: 3.4 | G19: 3.75 | H19: 5.86 | I19: 3.78 | J19: 2.24 | K19: =AVERAGE(B19:J19)
A20: >=3 | B20: 6.78 | C20: 5.74 | D20: 4.62 | E20: 3.54 | F20: 3.63 | G20: 3.81 | H20: 6.63 | I20: 3.92 | J20: 2.24 | K20: =AVERAGE(B20:J20)
A22: Idle days per deployment month (normalized, primary)
A23: Threshold | B23: 0-1 | C23: 1-2 | D23: 2-3 | E23: 3-4 | F23: 4-5 | G23: 5-6 | H23: 6-7 | I23: 7-8 | J23: 8-9 | K23: AVG
A24: >=1 | B24: 0 | C24: 0.96 | D24: 1.2 | E24: 2 | F24: 2.67 | G24: 1.92 | H24: 1.64 | I24: 1.97 | J24: 3.19 | K24: =AVERAGE(B24:J24)
A25: >=2 | B25: 0 | C25: 1.53 | D25: 2.15 | E25: 2.47 | F25: 3.09 | G25: 2.31 | H25: 2.06 | I25: 2.59 | J25: 3.99 | K25: =AVERAGE(B25:J25)
A26: >=3 | B26: 0 | C26: 1.45 | D26: 2.13 | E26: 2.18 | F26: 2.92 | G26: 2.36 | H26: 1.78 | I26: 2.61 | J26: 3.99 | K26: =AVERAGE(B26:J26)
A28: Idle days per month (normalized)
A29: Threshold | B29: 0-1 | C29: 1-2 | D29: 2-3 | E29: 3-4 | F29: 4-5 | G29: 5-6 | H29: 6-7 | I29: 7-8 | J29: 8-9 | K29: AVG
A30: >=1 | B30: 0 | C30: 0.88 | D30: 1.18 | E30: 1.94 | F30: 2.54 | G30: 1.86 | H30: 1.56 | I30: 1.75 | J30: 2.91 | K30: =AVERAGE(B30:J30)
A31: >=2 | B31: 0 | C31: 1.4 | D31: 2.12 | E31: 2.4 | F31: 2.94 | G31: 2.23 | H31: 1.97 | I31: 2.3 | J31: 3.63 | K31: =AVERAGE(B31:J31)
A32: >=3 | B32: 0 | C32: 1.24 | D32: 2.09 | E32: 2.09 | F32: 2.75 | G32: 2.27 | H32: 1.68 | I32: 2.31 | J32: 3.63 | K32: =AVERAGE(B32:J32)
A34: Avg max raw gap days
A35: Threshold | B35: 0-1 | C35: 1-2 | D35: 2-3 | E35: 3-4 | F35: 4-5 | G35: 5-6 | H35: 6-7 | I35: 7-8 | J35: 8-9 | K35: AVG
A36: >=1 | B36: 0 | C36: 3 | D36: 4.65 | E36: 5.28 | F36: 6.4 | G36: 4.28 | H36: 5.9 | I36: 6.04 | J36: 4.6 | K36: =AVERAGE(B36:J36)
A37: >=2 | B37: 0 | C37: 4.8 | D37: 8.32 | E37: 6.53 | F37: 7.4 | G37: 5.14 | H37: 7.42 | I37: 7.95 | J37: 5.75 | K37: =AVERAGE(B37:J37)
A38: >=3 | B38: 0 | C38: 6.74 | D38: 9.46 | E38: 6.94 | F38: 7.13 | G38: 5.24 | H38: 7.89 | I38: 8.22 | J38: 5.75 | K38: =AVERAGE(B38:J38)
A40: Scope months (avg)
A41: Threshold | B41: 0-1 | C41: 1-2 | D41: 2-3 | E41: 3-4 | F41: 4-5 | G41: 5-6 | H41: 6-7 | I41: 7-8 | J41: 8-9 | K41: AVG
A42: >=1 | B42: 4.89 | C42: 2.96 | D42: 2.66 | E42: 3.07 | F42: 3.85 | G42: 3.6 | H42: 5.69 | I42: 3.16 | J42: 2.66 | K42: =AVERAGE(B42:J42)
A43: >=2 | B43: 6.78 | C43: 4.24 | D43: 4.19 | E43: 3.67 | F43: 4.39 | G43: 4.25 | H43: 7.07 | I43: 4.08 | J43: 3.26 | K43: =AVERAGE(B43:J43)
A44: >=3 | B44: 6.78 | C44: 5.86 | D44: 5.06 | E44: 4.18 | F44: 4.74 | G44: 4.32 | H44: 8.03 | I44: 4.23 | J44: 3.26 | K44: =AVERAGE(B44:J44)
A46: Baseline MT/day Assumption (Hardcoded)
A47: Threshold | B47: 0-1 | C47: 1-2 | D47: 2-3 | E47: 3-4 | F47: 4-5 | G47: 5-6 | H47: 6-7 | I47: 7-8 | J47: 8-9 | K47: AVG
A48: >=1 | B48: 0.5 | C48: 1.5 | D48: 2.5 | E48: 3.5 | F48: 4.5 | G48: 5.5 | H48: 6.5 | I48: 7.5 | J48: 8.5 | K48: =AVERAGE(B48:J48)
...

Sheet 2. Fleet Efficiency
A1: Fleet Efficiency (Formula Driven)
A3: Section A - Fleet Coverage
A4: Gangs >=1 | B4: ='1. Raw Inputs'!$K$6
A5: Gangs >=2 | B5: ='1. Raw Inputs'!$K$7
A6: Gangs >=3 | B6: ='1. Raw Inputs'!$K$8
A7: Gangs Dropped (>=1 minus >=3) | B7: =B4-B6
A8: % of Fleet Removed | B8: =IFERROR(B7/B4,0)
A10: Section B - Throughput
A11: Total MT >=1 | B11: ='1. Raw Inputs'!$K$12
A12: Total MT >=2 | B12: ='1. Raw Inputs'!$K$13
A13: Total MT >=3 | B13: ='1. Raw Inputs'!$K$14
A14: MT per Gang >=1 | B14: =IFERROR(B11/B4,0)
A15: MT per Gang >=2 | B15: =IFERROR(B12/B5,0)
A16: MT per Gang >=3 | B16: =IFERROR(B13/B6,0)
A17: Efficiency Ratio (MT/gang >=3 vs >=1) | B17: =IFERROR(B16/B14,0)
A19: Section C - Loss and Outperformance
A20: MT Lost (>=1 minus >=3) | B20: =B11-B13
A21: % MT Lost | B21: =IFERROR(B20/B11,0)
A22: MT per Dropped Gang | B22: =IFERROR(B20/B7,0)
A23: Retained Outperformance | B23: =IFERROR(B16/B22,0)
A25: Summary KPIs
A26: % Fleet Removed | B26: =B8
A27: % MT from Marginal Gangs | B27: =B21
A28: Deployment Inefficiency Ratio | B28: =IFERROR(B26/B27,0)
A29: MT/gang retained | B29: =B16
A30: MT/gang dropped | B30: =B22
A31: Retained Outperformance | B31: =B23

Sheet 3. Idle Recovery
A1: Idle Recovery (Deployment-Month Basis)
A3: Section A - Inputs (>=3, pulled from Sheet 1)
A4: Metric | B4: 0-1 | C4: 1-2 | D4: 2-3 | E4: 3-4 | F4: 4-5 | G4: 5-6 | H4: 6-7 | I4: 7-8 | J4: 8-9 | K4: TOTAL/AVG
A5: Gang Count (>=3) | B5: ='1. Raw Inputs'!$B$8 | C5: ='1. Raw Inputs'!$C$8 | D5: ='1. Raw Inputs'!$D$8 | E5: ='1. Raw Inputs'!$E$8 | F5: ='1. Raw Inputs'!$F$8 | G5: ='1. Raw Inputs'!$G$8 | H5: ='1. Raw Inputs'!$H$8 | I5: ='1. Raw Inputs'!$I$8 | J5: ='1. Raw Inputs'!$J$8 | K5: =SUM(B5:J5)
A6: Deployment Months (>=3) | B6: ='1. Raw Inputs'!$B$20 | C6: ='1. Raw Inputs'!$C$20 | D6: ='1. Raw Inputs'!$D$20 | E6: ='1. Raw Inputs'!$E$20 | F6: ='1. Raw Inputs'!$F$20 | G6: ='1. Raw Inputs'!$G$20 | H6: ='1. Raw Inputs'!$H$20 | I6: ='1. Raw Inputs'!$I$20 | J6: ='1. Raw Inputs'!$J$20 | K6: =AVERAGE(B6:J6)
A7: Idle Days / Deployment Month (>=3) | B7: ='1. Raw Inputs'!$B$26 | C7: ='1. Raw Inputs'!$C$26 | D7: ='1. Raw Inputs'!$D$26 | E7: ='1. Raw Inputs'!$E$26 | F7: ='1. Raw Inputs'!$F$26 | G7: ='1. Raw Inputs'!$G$26 | H7: ='1. Raw Inputs'!$H$26 | I7: ='1. Raw Inputs'!$I$26 | J7: ='1. Raw Inputs'!$J$26 | K7: =AVERAGE(B7:J7)
A8: Baseline MT/day | B8: ='1. Raw Inputs'!$B$50 | C8: ='1. Raw Inputs'!$C$50 | D8: ='1. Raw Inputs'!$D$50 | E8: ='1. Raw Inputs'!$E$50 | F8: ='1. Raw Inputs'!$F$50 | G8: ='1. Raw Inputs'!$G$50 | H8: ='1. Raw Inputs'!$H$50 | I8: ='1. Raw Inputs'!$I$50 | J8: ='1. Raw Inputs'!$J$50 | K8: =AVERAGE(B8:J8)
A10: Section B - Recovery Calculation
A11: Total Idle Days | B11: =B5*B6*B7 | C11: =C5*C6*C7 | D11: =D5*D6*D7 | E11: =E5*E6*E7 | F11: =F5*F6*F7 | G11: =G5*G6*G7 | H11: =H5*H6*H7 | I11: =I5*I6*I7 | J11: =J5*J6*J7 | K11: =SUM(B11:J11)
A12: Recoverable MT | B12: =B11*B8 | C12: =C11*C8 | D12: =D11*D8 | E12: =E11*E8 | F12: =F11*F8 | G12: =G11*G8 | H12: =H11*H8 | I12: =I11*I8 | J12: =J11*J8 | K12: =SUM(B12:J12)
A14: Section C - Idle Gap Analysis
A15: 4-5 Bucket Idle Rate (>=3) | B15: =F7
A16: 6-7 Bucket Idle Rate (>=3) | B16: =H7
A17: Idle Rate Gap (4-5 minus 6-7) | B17: =MAX(B15-B16,0)
A18: Targeted Recovery MT (4-5 closes to 6-7 benchmark) | B18: =B17*F5*F6*F8
A20: Section D - Coverage Test
A21: MT Lost (from Sheet 2) | B21: ='2. Fleet Efficiency'!$B$20
A22: Recoverable MT (Section B total) | B22: =K12
A23: Net Coverage (Recoverable - Lost) | B23: =B22-B21
A24: Coverage Ratio | B24: =IFERROR(B22/B21,0)
A25: Feasibility | B25: =IF(B24>=1,"FULL SUBSTITUTION POSSIBLE","PARTIAL - gap remains")

Sheet 4. Leadership Summary
A1: Leadership Summary
A3: KPI | B3: Value
A4: Total Gangs Deployed (>=1) | B4: ='2. Fleet Efficiency'!$B$4
A5: Marginal Gangs (<3 erections) | B5: ='2. Fleet Efficiency'!$B$7
A6: % of Fleet That Was Marginal | B6: ='2. Fleet Efficiency'!$B$8
A7: MT from Marginal Gangs | B7: ='2. Fleet Efficiency'!$B$20
A8: % of Total MT from Marginal Gangs | B8: ='2. Fleet Efficiency'!$B$21
A9: Deployment Inefficiency Ratio | B9: ='2. Fleet Efficiency'!$B$28
A10: MT/gang Retained (>=3) | B10: ='2. Fleet Efficiency'!$B$16
A11: MT/gang Marginal (dropped) | B11: ='2. Fleet Efficiency'!$B$22
A12: Retained Outperformance | B12: ='2. Fleet Efficiency'!$B$23
A13: Total Idle MT Recoverable (productive >=3 gangs, deployment-month basis) | B13: ='3. Idle Recovery'!$K$12
A14: Coverage Ratio (Idle Recovery vs MT Gap) | B14: ='3. Idle Recovery'!$B$24
A15: Targeted Recovery: MT recovered if 4-5 bucket closes to 6-7 benchmark | B15: ='3. Idle Recovery'!$B$18
A18: Slide Bullets (Manual)
A19: [BULLET 1]
A20: [BULLET 2]
A21: [BULLET 3]
A22: [BULLET 4]
A23: [BULLET 5]

Sheet 5. Idle Narrative
A1: Idle Narrative (Deployment-Month Basis)
A2: Live formulas pull from '1. Raw Inputs' (>=3 rows: B8:J8, B20:J20, B26:J26, B50:J50).
A4: Section A - Assumptions
A5: Controllable idle share (Others) | B5: 0.35
A6: Uncontrollable idle share (ROW) | B6: =1-B5
A7: Productivity band - Low (MT/day) | B7: 0-4 (buckets 0-1, 1-2, 2-3, 3-4)
A8: Productivity band - Mid (MT/day) | B8: 4-6 (buckets 4-5, 5-6)
A9: Productivity band - High (MT/day) | B9: 6-10 (buckets 6-7, 7-8, 8-9)
A11: Section B - Band-level Idle Summary (Threshold >=3)
A12: Band | B12: Total Gangs | C12: Weighted Avg Idle Days / Deployment Month | D12: Weighted Avg Deployment Months | E12: Weighted Avg Baseline MT/day | F12: Total Idle Days in Scope | G12: Idle Index vs Low
A13: Low | B13: =SUM('1. Raw Inputs'!B8:E8) | C13: =IFERROR(SUMPRODUCT('1. Raw Inputs'!B8:E8,'1. Raw Inputs'!B26:E26)/B13,0) | D13: =IFERROR(SUMPRODUCT('1. Raw Inputs'!B8:E8,'1. Raw Inputs'!B20:E20)/B13,0) | E13: =IFERROR(SUMPRODUCT('1. Raw Inputs'!B8:E8,'1. Raw Inputs'!B50:E50)/B13,0) | F13: =SUMPRODUCT('1. Raw Inputs'!B8:E8,'1. Raw Inputs'!B26:E26,'1. Raw Inputs'!B20:E20) | G13: =1
A14: Mid | B14: =SUM('1. Raw Inputs'!F8:G8) | C14: =IFERROR(SUMPRODUCT('1. Raw Inputs'!F8:G8,'1. Raw Inputs'!F26:G26)/B14,0) | D14: =IFERROR(SUMPRODUCT('1. Raw Inputs'!F8:G8,'1. Raw Inputs'!F20:G20)/B14,0) | E14: =IFERROR(SUMPRODUCT('1. Raw Inputs'!F8:G8,'1. Raw Inputs'!F50:G50)/B14,0) | F14: =SUMPRODUCT('1. Raw Inputs'!F8:G8,'1. Raw Inputs'!F26:G26,'1. Raw Inputs'!F20:G20) | G14: =IFERROR(C14/$C$13,0)
A15: High | B15: =SUM('1. Raw Inputs'!H8:J8) | C15: =IFERROR(SUMPRODUCT('1. Raw Inputs'!H8:J8,'1. Raw Inputs'!H26:J26)/B15,0) | D15: =IFERROR(SUMPRODUCT('1. Raw Inputs'!H8:J8,'1. Raw Inputs'!H20:J20)/B15,0) | E15: =IFERROR(SUMPRODUCT('1. Raw Inputs'!H8:J8,'1. Raw Inputs'!H50:J50)/B15,0) | F15: =SUMPRODUCT('1. Raw Inputs'!H8:J8,'1. Raw Inputs'!H26:J26,'1. Raw Inputs'!H20:J20) | G15: =IFERROR(C15/$C$13,0)
B16: Low | C16: Mid | D16: High
A17: Idle Index = Band idle days / Low band idle days | B17: =1 | C17: =IFERROR(C14/$C$13,0) | D17: =IFERROR(C15/$C$13,0)
A19: Section C - Controllable Idle Recovery for High-productivity Gangs
A20: Total idle days in scope (High band) | B20: =F15
A21: Controllable share | B21: =B5
A22: Controllable idle days | B22: =B20*B21
A23: Baseline MT/day (High band weighted avg) | B23: =E15
A24: Recoverable MT (total, full scope) | B24: =B22*B23
A25: Weighted avg deployment months (High band) | B25: =D15
A26: Recoverable MT per month | B26: =IFERROR(B24/B25,0)
A27: Total High-band gangs | B27: =B15
A28: Recoverable MT per gang per month | B28: =IFERROR(B26/B27,0)
A30: Section D - Sensitivity (Controllable Share 20% to 50%)
A31: Controllable Share | B31: Controllable Idle Days | C31: Recoverable MT | D31: Recoverable MT / Month
A32: 0.2 | B32: =A32*$B$20 | C32: =B32*$B$23 | D32: =IFERROR(C32/$B$25,0)
A33: 0.25 | B33: =A33*$B$20 | C33: =B33*$B$23 | D33: =IFERROR(C33/$B$25,0)
A34: 0.3 | B34: =A34*$B$20 | C34: =B34*$B$23 | D34: =IFERROR(C34/$B$25,0)
A35: 0.35 | B35: =A35*$B$20 | C35: =B35*$B$23 | D35: =IFERROR(C35/$B$25,0)
A36: 0.4 | B36: =A36*$B$20 | C36: =B36*$B$23 | D36: =IFERROR(C36/$B$25,0)
A37: 0.45 | B37: =A37*$B$20 | C37: =B37*$B$23 | D37: =IFERROR(C37/$B$25,0)
A38: 0.5 | B38: =A38*$B$20 | C38: =B38*$B$23 | D38: =IFERROR(C38/$B$25,0)
A40: Section E - Narrative Output (Live Formula Callouts)
A41: ="High-productivity gangs (6-10 MT/day) idle "&TEXT($C$15,"0.0")&" days/deployment-month - "&TEXT(IFERROR($C$15/$C$13,0),"0.0")&"x more than low-productivity gangs ("&TEXT($C$13,"0.0")&" days/deployment-month)."
A43: ="At "&TEXT($B$5,"0%")&" controllable share, high-band controllable idle equals "&TEXT($B$22,"0.0")&" days and "&TEXT($B$24,"0.0")&" MT recoverable over full scope."
A45: ="Recovery opportunity is "&TEXT($B$26,"0.0")&" MT/month from high-productivity gangs under current assumptions."
A47: ="Per-gang opportunity is "&TEXT($B$28,"0.00")&" MT/gang/month for high-band crews."
